Workbook
Name ANALISTA: #REF!
Name BALANCEO: #REF!
Name ESTADO: #REF!
Name PLANTAS: #REF!
Name PRENDA: #REF!
Name PROCESO: #REF!
Name TIPO: #REF!

Sheet Resumen costos Ptar Bogotá
B3: Bogotá
B4: COSTO PLANTA DE TRATAMIENTO DE AGUA RESIDUAL | E4: EJECUTADO PTAR AÑO 2025 BOGOTÁ
B5: Clasificación | C5: Detalle | D5: Unidad | E5: Enero 2025 | F5: Febrero 2025 | G5: Marzo 2025 | H5: Abril 2025 | I5: Mayo 2025 | J5: Junio 2025 | K5: Julio 2025 | L5: Agosto 2025 | M5: Septiembre 2025 | N5: Octubre 2025 | O5: Noviembre 2025 | P5: Total general | Q5: Diferencia | R5: % Variación | S5: $/Kg | T5: Kg/Año | U5: Kg/m3
C6: ACIDO CLORHIDRICO 31,5% | D6: kg | E6: 359600 | F6: 775000 | G6: 372000 | H6: 372000 | I6: 372000 | J6: 372000 | K6: 372000 | L6: 372000 | M6: 372000 | N6: 372000 | O6: 372000 | P6: =+SUM(E6:O6) -> 4482600 | Q6: =+O6-N6 -> 0 | R6: =+IFERROR((O6-N6)/N6,0) -> 0 | S6: 1650 | T6: =P6/S6 -> 2716.7273 | U6: =T6/$V$8 -> 0.013583636
C7: SODIO BISULFITO | D7: kg | E7: 91000 | F7: 91000 | G7: 91000 | H7: 91000 | I7: 91000 | J7: 91000 | K7: 91000 | L7: 91000 | M7: 91000 | N7: 91000 | O7: 91000 | P7: =+SUM(E7:O7) -> 1001000 | Q7: =+O7-N7 -> 0 | R7: =+IFERROR((O7-N7)/N7,0) -> 0 | S7: 4200 | T7: =P7/S7 -> 238.33333 | U7: =T7/$V$8 -> 0.0011916667 | V7: =P108 -> 508614
C8: NITRATO DE PLATA | D8: kg | E8: 150800 | F8: 150800 | G8: 150800 | H8: 150800 | I8: 150800 | J8: 150800 | K8: 150800 | L8: 150800 | M8: 150800 | N8: 150800 | O8: 150800 | P8: =+SUM(E8:O8) -> 1658800 | Q8: =+O8-N8 -> 0 | R8: =+IFERROR((O8-N8)/N8,0) -> 0 | S8: 180000 | T8: =P8/S8 -> 9.2155556 | U8: =T8/$V$7 -> 1.8118958e-05 | V8: 200000
C9: INSUMOS HACH | D9: uni | E9: 0 | F9: 0 | G9: 0 | H9: 12832747 | I9: 15149313 | J9: 0 | K9: 0 | L9: 0 | M9: 0 | N9: 0 | O9: 4421528.8 | P9: =+SUM(E9:O9) -> 32403589 | Q9: =+O9-N9 -> 4421528.8 | R9: =+IFERROR((O9-N9)/N9,0) -> 0 | U9: =T9/$V$7 -> 0 | W9: 7680
C10: ACIDIFICANTE | D10: kg | E10: 48418570 | F10: 36323100 | G10: 30697300 | H10: 43917930 | I10: 46821332 | J10: 26661400 | K10: 31421316 | L10: 33429482 | M10: 31223190 | N10: 21221007 | O10: 33089488 | P10: =+SUM(E10:O10) -> 3.8322411e+08 | Q10: =+O10-N10 -> 11868481 | R10: =+IFERROR((O10-N10)/N10,0) -> 0.55927984 | S10: 2446 | T10: =P10/S10 -> 156673.8 | U10: =T10/$V$7 -> 0.30804068 | W10: =W9/V7 -> 0.01509986
C11: QUIMICO FLOCULANTE PARA TRATAMIENTO DE AGUA (Cationico) | D11: kg | E11: 7566500 | F11: 3067500 | G11: 6646250 | H11: 11554250 | I11: 8282250 | J11: 6544000 | K11: 8486750 | L11: 6646250 | M11: 12576750 | N11: 14867150 | O11: 8732150 | P11: =+SUM(E11:O11) -> 94969800 | Q11: =+O11-N11 -> -6135000 | R11: =+IFERROR((O11-N11)/N11,0) -> -0.41265475 | S11: 20450 | T11: =P11/S11 -> 4644 | U11: =T11/$V$7 -> 0.0091306964
C12: QUIMICO FLOCULANTE PARA TRATAMIENTO DE AGUA (Anionico) | D12: kg | E12: 4823610 | F12: 9236700 | G12: 4002570 | H12: 6157800 | I12: 4536246 | J12: 1334190 | K12: 7081470 | L12: 4823610 | M12: 4762032 | N12: 4018990.8 | O12: 5788332 | P12: =+SUM(E12:O12) -> 56565551 | Q12: =+O12-N12 -> 1769341.2 | R12: =+IFERROR((O12-N12)/N12,0) -> 0.44024515 | S12: 20526 | T12: =P12/S12 -> 2755.8 | U12: =T12/$V$7 -> 0.0054182543
C13: QUIMICO COAGULANTE PARA TRATAMIENTO DE AGUA (Coagulante) | D13: kg | E13: 30945388 | F13: 138960020 | G13: 53367206 | H13: 49252534 | I13: 73118530 | J13: 21907484 | K13: 53437955 | L13: 46067706 | M13: 57560488 | N13: 59429160 | O13: 34878134 | P13: =+SUM(E13:O13) -> 618924605 | Q13: =+O13-N13 -> -24551026 | R13: =+IFERROR((O13-N13)/N13,0) -> -0.41311413 | S13: 2246 | T13: =P13/S13 -> 275567.5 | U13: =T13/$V$7 -> 0.54180085
C14: QUIMICO COAGULANTE PARA TRATAMIENTO DE AGUA (Decolorante) | D14: kg | E14: 159385590 | F14: 153612160 | G14: 135150158 | H14: 164121100 | I14: 151017360 | J14: 101897796 | K14: 170270776 | L14: 109305950 | M14: 151017360 | N14: 131361750 | O14: 140404628 | P14: =+SUM(E14:O14) -> 1567544628 | Q14: =+O14-N14 -> 9042878 | R14: =+IFERROR((O14-N14)/N14,0) -> 0.068839506 | S14: 12974 | T14: =P14/S14 -> 120822 | U14: =T14/$V$7 -> 0.23755146
C15: HIPOCLORITO DE SODIO | D15: kg | E15: 1647000 | F15: 317199.99 | G15: 317199.99 | H15: 317199.99 | I15: 317199.99 | J15: 317199.99 | K15: 317199.99 | L15: 317199.99 | M15: 317199.99 | N15: 317199.99 | O15: 317199.99 | P15: =+SUM(E15:O15) -> 4818999.9 | Q15: =+O15-N15 -> 0 | R15: =+IFERROR((O15-N15)/N15,0) -> 0 | S15: 1298 | T15: =P15/S15 -> 3712.6347 | U15: =T15/$V$7 -> 0.0072995135
C16: SODA CAUSTICA LIQUI48% 90 KL | D16: kg | E16: 449331.6 | F16: 449331.6 | G16: 449331.6 | H16: 449331.6 | I16: 449331.6 | J16: 449331.6 | K16: 449331.6 | L16: 449331.6 | M16: 449331.6 | N16: 449331.6 | O16: 449331.6 | P16: =+SUM(E16:O16) -> 4942647.6 | Q16: =+O16-N16 -> 0 | R16: =+IFERROR((O16-N16)/N16,0) -> 0 | S16: 1862 | T16: =P16/S16 -> 2654.4831 | U16: =T16/$V$8 -> 0.013272416
C17: QUIMICO ANTINCRUSTANTE PARA ÓSMOSIS INVERSA | D17: kg | E17: 9068935.9 | F17: 9068935.9 | G17: 9068935.9 | H17: 9068935.9 | I17: 9068935.9 | J17: 9068935.9 | K17: 9068935.9 | L17: 9068935.9 | M17: 9068935.9 | N17: 9068935.9 | O17: 9068935.9 | P17: =+SUM(E17:O17) -> 99758295 | Q17: =+O17-N17 -> 0 | R17: =+IFERROR((O17-N17)/N17,0) -> 0 | S17: 36239 | T17: =P17/S17 -> 2752.7883 | U17: =T17/$V$8 -> 0.013763942
C18: QUIMICO PARA TRATAMIENTO CIP ALCALINO ÓSMOSIS INVERSA | D18: kg | E18: 543261.04 | F18: 543261.04 | G18: 543261.04 | H18: 543261.04 | I18: 543261.04 | J18: 543261.04 | K18: 543261.04 | L18: 543261.04 | M18: 543261.04 | N18: 543261.04 | O18: 543261.04 | P18: =+SUM(E18:O18) -> 5975871.4 | Q18: =+O18-N18 -> 0 | R18: =+IFERROR((O18-N18)/N18,0) -> 0 | S18: 32490 | T18: =P18/S18 -> 183.92956 | U18: =T18/$V$8 -> 0.00091964781
C19: QUIMICO PARA TRATAMIENTO BIODISPERSANTE ÓMOSIS INVERSA | D19: kg | E19: 6330327.6 | F19: 6330327.6 | G19: 6330327.6 | H19: 6330327.6 | I19: 6330327.6 | J19: 6330327.6 | K19: 6330327.6 | L19: 6330327.6 | M19: 6330327.6 | N19: 6330327.6 | O19: 6330327.6 | P19: =+SUM(E19:O19) -> 69633604 | Q19: =+O19-N19 -> 0 | R19: =+IFERROR((O19-N19)/N19,0) -> 0 | S19: 19160 | T19: =P19/S19 -> 3634.3217 | U19: =T19/$V$8 -> 0.018171608
C20: QUIMICO PARA TRATAMIENTO CIP ACIDO ÓMOSIS INVERSA | D20: Kg | E20: 543261.04 | F20: 543261.04 | G20: 543261.04 | H20: 543261.04 | I20: 543261.04 | J20: 543261.04 | K20: 543261.04 | L20: 543261.04 | M20: 543261.04 | N20: 543261.04 | O20: 543261.04 | P20: =+SUM(E20:O20) -> 5975871.4 | Q20: =+O20-N20 -> 0 | R20: =+IFERROR((O20-N20)/N20,0) -> 0 | S20: 34156 | T20: =P20/S20 -> 174.95818 | U20: =T20/$V$8 -> 0.00087479088
C21: ACIDO CITRICO | D21: ml | E21: 0 | F21: 0 | G21: 527415.29 | H21: 0 | I21: 0 | J21: 527415.29 | K21: 0 | L21: 0 | M21: 527415.29 | O21: 527415.29 | P21: =+SUM(E21:O21) -> 2109661.2 | Q21: =+O21-N21 -> 527415.29 | R21: =+IFERROR((O21-N21)/N21,0) -> 0 | S21: 5200 | T21: =P21/S21 -> 405.70407 | U21: =T21/$V$7 -> 0.00079766595
C22: Subtotal | E22: =SUM(E6:E21) -> 2.7032318e+08 | F22: =SUM(F6:F21) -> 3.594686e+08 | G22: =SUM(G6:G21) -> 2.4825702e+08 | H22: =SUM(H6:H21) -> 3.0570248e+08 | I22: =SUM(I6:I21) -> 3.1679115e+08 | J22: =SUM(J6:J21) -> 1.767384e+08 | K22: =SUM(K6:K21) -> 2.8856438e+08 | L22: =SUM(L6:L21) -> 2.1813912e+08 | ... O22: =SUM(O6:O21) -> 2.4570779e+08 | P22: =+SUM(E22:O22) -> 2.9539896e+09 | Q22: =+O22-N22 -> -3056381.5 | R22: =+IFERROR((O22-N22)/N22,0) -> -0.012286261
B23: Disposición | C23: DISPOSICIÓN DE LODOS | E23: 32990880 | F23: 29812080 | G23: 32990880 | H23: 32990880 | I23: 32990880 | J23: 32990880 | K23: 32990880 | L23: 32990880 | M23: 53422896 | N23: 108517008 | O23: 2530000 | P23: =+SUM(E23:O23) -> 425218144 | Q23: =+O23-N23 -> -105987008 | R23: =+IFERROR((O23-N23)/N23,0) -> -0.97668568 | S23: 96 | U23: 3.4
C24: TRANSPORTE DE LODOS | S24: 600000
C25: LAVADO DE TANQUES - CARCAMOS | E25: 28778200 | F25: 32794000 | G25: 32837500 | H25: 32837500 | I25: 32837500 | J25: 32837500 | K25: 32968000 | L25: 0 | M25: 66081000 | N25: 32939000 | O25: 33142000 | P25: =+SUM(E25:O25) -> 358052200 | Q25: =+O25-N25 -> 203000 | R25: =+IFERROR((O25-N25)/N25,0) -> 0.0061629072 | S25: 290 | T25: 1140000 | U25: 2.5
C26: Subtotal | E26: =SUM(E23:E25) -> 61769080 | F26: =SUM(F23:F25) -> 62606080 | G26: =SUM(G23:G25) -> 65828380 | H26: =SUM(H23:H25) -> 65828380 | I26: =SUM(I23:I25) -> 65828380 | J26: =SUM(J23:J25) -> 65828380 | K26: =SUM(K23:K25) -> 65958880 | L26: =SUM(L23:L25) -> 32990880 | ... O26: =SUM(O23:O25) -> 35672000 | P26: =+SUM(E26:O26) -> 783270344 | Q26: =+O26-N26 -> -105784008 | R26: =+IFERROR((O26-N26)/N26,0) -> -0.74782266
B27: Consumibles | C27: MEMBRANAS DE ÓSMOSIS INVERSA | D27: Und | E27: 0 | F27: 0 | G27: 0 | H27: 0 | I27: 150552000 | J27: 0 | K27: 0 | L27: 0 | M27: 0 | N27: 0 | O27: 0 | P27: =+SUM(E27:O27) -> 150552000 | Q27: =+O27-N27 -> 0 | R27: =+IFERROR((O27-N27)/N27,0) -> 0
C28: MEMBRANAS DE ULTRAFILTRACIÓN | D28: Und | E28: 0 | F28: 0 | G28: 0 | H28: 0 | I28: 0 | J28: 0 | K28: 0 | L28: 0 | M28: 0 | N28: 0 | O28: 0 | P28: =+SUM(E28:O28) -> 0 | Q28: =+O28-N28 -> 0 | R28: =+IFERROR((O28-N28)/N28,0) -> 0
C29: SILICA GEL | D29: Und | E29: 0 | F29: 0 | G29: 0 | H29: 0 | I29: 0 | J29: 0 | K29: 0 | L29: 0 | M29: 0 | N29: 0 | O29: 0 | P29: =+SUM(E29:O29) -> 0 | Q29: =+O29-N29 -> 0 | R29: =+IFERROR((O29-N29)/N29,0) -> 0
C30: CUBETA PARA ESPECTROFOTÓMETRO | D30: Und | E30: 0 | F30: 0 | G30: 0 | H30: 0 | I30: 0 | J30: 0 | K30: 0 | L30: 0 | M30: 0 | N30: 0 | O30: 0 | P30: =+SUM(E30:O30) -> 0 | Q30: =+O30-N30 -> 0 | R30: =+IFERROR((O30-N30)/N30,0) -> 0
C31: EMBUDO | D31: Und | E31: 0 | F31: 0 | G31: 0 | H31: 0 | I31: 0 | J31: 0 | K31: 0 | L31: 0 | M31: 0 | N31: 200000 | O31: 0 | P31: =+SUM(E31:O31) -> 200000 | Q31: =+O31-N31 -> -200000 | R31: =+IFERROR((O31-N31)/N31,0) -> -1
C32: CONO | D32: Und | E32: 0 | F32: 0 | G32: 0 | H32: 0 | I32: 0 | J32: 0 | K32: 0 | L32: 0 | M32: 0 | N32: 648000 | O32: 0 | P32: =+SUM(E32:O32) -> 648000 | Q32: =+O32-N32 -> -648000 | R32: =+IFERROR((O32-N32)/N32,0) -> -1
C33: FRASCO | D33: Und | E33: 0 | F33: 0 | G33: 0 | H33: 0 | I33: 0 | J33: 125858.29 | K33: 0 | L33: 0 | M33: 0 | N33: 0 | O33: 0 | P33: =+SUM(E33:O33) -> 125858.29 | Q33: =+O33-N33 -> 0 | R33: =+IFERROR((O33-N33)/N33,0) -> 0
C34: CARTUCHO | D34: Und | E34: 1925410 | F34: 3209016.7 | G34: 287700 | H34: 1444057.5 | I34: 1399370.1 | J34: 3498425.2 | K34: 1706617.8 | L34: 2901250.3 | M34: 6776050.6 | N34: 7623057 | O34: 5082038 | P34: =+SUM(E34:O34) -> 35852993 | Q34: =+O34-N34 -> -2541019 | R34: =+IFERROR((O34-N34)/N34,0) -> -0.33333333
C35: FILTRO | D35: Und | E35: 0 | F35: 0 | G35: 0 | H35: 143706 | I35: 0 | J35: 9813067.6 | K35: 0 | L35: 0 | M35: 1495881.6 | N35: 558000 | O35: 1834000 | P35: =+SUM(E35:O35) -> 13844655 | Q35: =+O35-N35 -> 1276000 | R35: =+IFERROR((O35-N35)/N35,0) -> 2.2867384
C36: CEPILLO GRATA EN BRONCE | D36: Und | E36: 0 | F36: 0 | G36: 0 | H36: 7800 | I36: 0 | J36: 0 | K36: 0 | L36: 0 | M36: 0 | N36: 0 | O36: 0 | P36: =+SUM(E36:O36) -> 7800 | Q36: =+O36-N36 -> 0 | R36: =+IFERROR((O36-N36)/N36,0) -> 0
C37: PIPETA | D37: Und | E37: 0 | F37: 0 | G37: 0 | H37: 0 | I37: 0 | J37: 0 | K37: 0 | L37: 0 | M37: 0 | N37: 77200 | O37: 0 | P37: =+SUM(E37:O37) -> 77200 | Q37: =+O37-N37 -> -77200 | R37: =+IFERROR((O37-N37)/N37,0) -> -1
C38: JERINGA | D38: Und | E38: 0 | F38: 0 | G38: 0 | H38: 0 | I38: 0 | J38: 0 | K38: 0 | L38: 0 | M38: 0 | N38: 0 | O38: 0 | P38: =+SUM(E38:O38) -> 0 | Q38: =+O38-N38 -> 0 | R38: =+IFERROR((O38-N38)/N38,0) -> 0
C39: CRISOL | D39: Und | E39: 0 | F39: 0 | G39: 0 | H39: 0 | I39: 0 | J39: 0 | K39: 0 | L39: 0 | M39: 0 | N39: 0 | O39: 209346 | P39: =+SUM(E39:O39) -> 209346 | Q39: =+O39-N39 -> 209346 | R39: =+IFERROR((O39-N39)/N39,0) -> 0
C40: MATERIALES VARIOS | D40: Und | E40: 0 | F40: 0 | G40: 0 | H40: 0 | I40: 0 | J40: 0 | K40: 0 | L40: 0 | M40: 0 | N40: 56100 | O40: 0 | P40: =+SUM(E40:O40) -> 56100 | Q40: =+O40-N40 -> -56100 | R40: =+IFERROR((O40-N40)/N40,0) -> -1
C41: Subtotal | E41: =SUM(E27:E40) -> 1925410 | F41: =SUM(F27:F40) -> 3209016.7 | G41: =SUM(G27:G40) -> 287700 | H41: =SUM(H27:H40) -> 1595563.5 | I41: =SUM(I27:I40) -> 1.5195137e+08 | J41: =SUM(J27:J40) -> 13437351 | K41: =SUM(K27:K40) -> 1706617.8 | L41: =SUM(L27:L40) -> 2901250.3 | ... O41: =SUM(O27:O40) -> 7125384 | P41: =+SUM(E41:O41) -> 2.0157395e+08 | Q41: =+O41-N41 -> -2036973 | R41: =+IFERROR((O41-N41)/N41,0) -> -0.22231976
B42: Análisis Laboratorio | C42: DENSIMETRO | D42: Und | E42: 0 | F42: 0 | G42: 0 | H42: 0 | I42: 0 | J42: 0 | K42: 0 | L42: 0 | M42: 0 | N42: 0 | O42: 0 | P42: =+SUM(E42:O42) -> 0 | Q42: =+O42-N42 -> 0 | R42: =+IFERROR((O42-N42)/N42,0) -> 0
...

Sheet PROYEC COSTO M3 PERMODA BOGOTA
B2: CONSUMO TOTAL (M3) PLAN MAESTRO BOGOTA - CON RECIRCULACIÓN OSMOSIS INVERSA Y PTAP (Pozo Subterraneo) | D2: Volumen requerido por Producción (M3) | E2: Porcentaje
D3: ='PLAN MAESTRO BOGOTA RECIRCU'!AG3 -> 379147.92 | E3: 1 | F3: $/m3 | G3: $ Total
B4: TRATAMIENTO DE AGUA RESIDUAL | C4: PTAR (Costo de Tratamiento hasta Fase 2 - Cumplimiento Ambiental) OPEX Con depreciación | D4: =D3 -> 379147.92 | E4: 1 | F4: ='PLAN MAESTRO BOGOTA RECIRCU'!AP4 -> 11828.253 | G4: =D4*F4 -> 4.4846576e+09
B5: FUENTES DE ABASTECIMIENTO | C5: OSMOSIS INVERSA (Costo procesamiento de agua permeada para planta de producción) | D5: =D4*0.65 -> 246446.14 | E5: =(D5/D3) -> 0.65 | F5: ='PLAN MAESTRO BOGOTA RECIRCU'!AP5 -> 3602.7536 | G5: =D5*F5 -> 8.8788474e+08
C6: PTAP - OPEX Con depreciación | D6: ='PLAN MAESTRO BOGOTA RECIRCU'!AN6 -> 95848.197 | E6: =(D6/D3) -> 0.25279896 | F6: ='PLAN MAESTRO BOGOTA RECIRCU'!AP6 -> 5622.9088 | G6: =D6*F6 -> 5.3894567e+08
C7: ACUEDUCTO | D7: =D4-D5-D6-D8 -> 34615.622 | E7: =(D7/D3) -> 0.091298464 | F7: ='PLAN MAESTRO BOGOTA RECIRCU'!AP7 -> 10763 | G7: =D7*F7 -> 3.7256794e+08
C8: CARRO TANQUES | D8: ='PLAN MAESTRO BOGOTA RECIRCU'!AN8 -> 2237.9511 | E8: =(D8/D3) -> 0.0059025805 | F8: ='PLAN MAESTRO BOGOTA RECIRCU'!AP8 -> 12700 | G8: =D8*F8 -> 28421979
F9: TOTAL | G9: =SUM(G4:G8) -> 6.312478e+09
D10: COSTO DE TRATAMIENTO DE AGUA RESIDUAL | F10: TOTAL ($/Año) | G10: =G4 -> 4.4846576e+09
D11: INDICADOR POR M3 TRATADO AGUA RESIDUAL | F11: $/M3 | G11: =G10/D4 -> 11828.253
D12: COSTO DE SUMINISTRO DE AGUA A PROCESO TEXTIL | F12: TOTAL ($/Año) | G12: =SUM(G5:G8) -> 1.8278203e+09
D13: INDICADOR POR M3 DE AGUA A PROCESO TEXTIL | F13: $/m3 | G13: =G12/D3 -> 4820.8635
D14: COSTO TOTAL M3 PERMODA (Tratado + Fuentes) | F14: TOTAL ($/Año) | G14: =G10+G12 -> 6.312478e+09
D15: INDICADOR PERMODA BOGOTA (Tratamiento + Suministro) | F15: $/M3 | G15: =G14/D3 -> 16649.117
B17: CONSUMO TOTAL (M3) PLAN MAESTRO BOGOTA - CON RECIRCULACIÓN OSMOSIS INVERSA Y SIN PTAP (Pozo Subterraneo) | D17: Volumen requerido por Producción (M3) | E17: Porcentaje
D18: =D3 -> 379147.92 | E18: 1 | F18: $/m3 | G18: $ Total
B19: TRATAMIENTO DE AGUA RESIDUAL | C19: PTAR (Costo de Tratamiento hasta Fase 2 - Cumplimiento Ambiental) OPEX Con depreciación | D19: =D18 -> 379147.92 | E19: 1 | F19: =F4 -> 11828.253 | G19: =D19*F19 -> 4.4846576e+09
B20: FUENTES DE ABASTECIMIENTO | C20: OSMOSIS INVERSA (Costo procesamiento de agua permeada para planta de producción) | D20: =D5 -> 246446.14 | E20: =(D20/D18) -> 0.65 | F20: =F5 -> 3602.7536 | G20: =D20*F20 -> 8.8788474e+08
C21: PTAP - OPEX Con depreciación | D21: ='PLAN MAESTRO BOGOTA RECIRCU'!AN21 -> 0 | E21: =(D21/D18) -> 0 | F21: =F6 -> 5622.9088 | G21: =D21*F21 -> 0
C22: ACUEDUCTO | D22: =D18-D20-D23 -> 130463.82 | E22: =(D22/D18) -> 0.34409742 | F22: =F7 -> 10763 | G22: =D22*F22 -> 1.4041821e+09
C23: CARRO TANQUES | D23: =D8 -> 2237.9511 | E23: =(D23/D18) -> 0.0059025805 | F23: =F8 -> 12700 | G23: =D23*F23 -> 28421979
F24: TOTAL | G24: =SUM(G19:G23) -> 6.8051464e+09
D25: COSTO DE TRATAMIENTO DE AGUA RESIDUAL | F25: TOTAL ($/Año) | G25: =G19 -> 4.4846576e+09
D26: INDICADOR POR M3 TRATADO AGUA RESIDUAL | F26: $/M3 | G26: =G25/D19 -> 11828.253
D27: COSTO DE SUMINISTRO DE AGUA A PROCESO TEXTIL | F27: TOTAL ($/Año) | G27: =SUM(G20:G23) -> 2.3204888e+09
D28: INDICADOR POR M3 DE AGUA A PROCESO TEXTIL | F28: $/m3 | G28: =G27/D18 -> 6120.2732
D29: COSTO TOTAL M3 PERMODA (Tratado + Fuentes) | F29: TOTAL ($/Año) | G29: =G25+G27 -> 6.8051464e+09
D30: INDICADOR PERMODA BOGOTA (Tratamiento + Suministro) | F30: $/M3 | G30: =G29/D18 -> 17948.527
B32: CONSUMO TOTAL (M3) PLAN MAESTRO BOGOTA - CON PTAP (Pozo Subterraneo) Y SIN RECIRCULACIÓN DE OSMOSIS INVERSA | D32: Volumen requerido por Producción (M3) | E32: Porcentaje
D33: =D3 -> 379147.92 | E33: 1 | F33: $/m3 | G33: $ Total
B34: TRATAMIENTO DE AGUA RESIDUAL | C34: PTAR (Costo de Tratamiento hasta Fase 2 - Cumplimiento Ambiental) OPEX Con depreciación | D34: =D33 -> 379147.92 | E34: 1 | F34: =F4 -> 11828.253 | G34: =D34*F34 -> 4.4846576e+09
B35: FUENTES DE ABASTECIMIENTO | C35: OSMOSIS INVERSA (Costo procesamiento de agua permeada para planta de producción) | D35: ='PLAN MAESTRO BOGOTA RECIRCU'!AN17 -> 0 | E35: =(D35/D33) -> 0 | F35: =F5 -> 3602.7536 | G35: =D35*F35 -> 0
C36: PTAP - OPEX Con depreciación | D36: ='PLAN MAESTRO BOGOTA RECIRCU'!AN18 -> 95848.197 | E36: =(D36/D33) -> 0.25279896 | F36: =F6 -> 5622.9088 | G36: =D36*F36 -> 5.3894567e+08
C37: ACUEDUCTO | D37: ='PLAN MAESTRO BOGOTA RECIRCU'!AN19 -> 230400 | E37: =(D37/D33) -> 0.6076784 | F37: =F7 -> 10763 | G37: =D37*F37 -> 2479795200
C38: CARRO TANQUES | D38: ='PLAN MAESTRO BOGOTA RECIRCU'!AN20 -> 52899.718 | E38: =(D38/D33) -> 0.13952264 | F38: =F8 -> 12700 | G38: =D38*F38 -> 6.7182642e+08
F39: TOTAL | G39: =SUM(G34:G38) -> 8.1752249e+09
D40: COSTO DE TRATAMIENTO DE AGUA RESIDUAL | F40: TOTAL ($/Año) | G40: =G34 -> 4.4846576e+09
D41: INDICADOR POR M3 TRATADO AGUA RESIDUAL | F41: $/M3 | G41: =G40/D34 -> 11828.253
D42: COSTO DE SUMINISTRO DE AGUA A PROCESO TEXTIL | F42: TOTAL ($/Año) | G42: =SUM(G35:G38) -> 3.6905673e+09
D43: INDICADOR POR M3 DE AGUA A PROCESO TEXTIL | F43: $/m3 | G43: =G42/D33 -> 9733.8457
...

Sheet PLAN MAESTRO BOGOTA RECIRCU
B2: PLAN MAESTRO 2026 | D2: Indicador de Consumo (Histórico 2025) | E2: Enero | F2: Consumo de Agua proyectado (m3/MES) | G2: Febrero | H2: Consumo de Agua proyectado (m3/MES) | I2: Marzo | J2: Consumo de Agua proyectado (m3/MES) | K2: Abril | L2: Consumo de Agua proyectado (m3/MES) | M2: Mayo | N2: Consumo de Agua proyectado (m3/MES) | O2: Junio | P2: Consumo de Agua proyectado (m3/MES) | Q2: Julio | R2: Consumo de Agua proyectado (m3/MES) | S2: Agosto | T2: Consumo de Agua proyectado (m3/MES) | U2: Septiembre | V2: Consumo de Agua proyectado (m3/MES) | W2: Octubre | X2: Consumo de Agua proyectado (m3/MES) | Y2: Noviembre | Z2: Consumo de Agua proyectado (m3/MES) | AA2: Diciembre | AB2: Consumo de Agua proyectado (m3/MES) | AE2: CONSUMO TOTAL (M3) PLAN MAESTRO | AG2: Volumen (M3) | AH2: Porcentaje | AL2: CONSUMO TOTAL (M3) PLAN MAESTRO | AN2: Volumen (M3) | AO2: Porcentaje
B3: Kg de Tintorería | C3: 2874043 | D3: 60 | E3: 206773 | F3: 10753 | G3: 181023.6 | H3: =($D$3*G3)/1000 -> 10861.416 | I3: 161903.52 | J3: =($D$3*I3)/1000 -> 9714.2113 | K3: 235633.98 | L3: =($D$3*K3)/1000 -> 14138.039 | M3: 235826.67 | N3: =($D$3*M3)/1000 -> 14149.6 | O3: 269355.01 | P3: =($D$3*O3)/1000 -> 16161.301 | Q3: 335661.52 | R3: =($D$3*Q3)/1000 -> 20139.691 | S3: 368144.87 | T3: =($D$3*S3)/1000 -> 22088.692 | U3: 352203.61 | V3: =($D$3*U3)/1000 -> 21132.217 | W3: 318382.77 | X3: =($D$3*W3)/1000 -> 19102.966 | Y3: 117403.25 | Z3: =($D$3*Y3)/1000 -> 7044.1949 | AA3: 108686.58 | AB3: =($D$3*AA3)/1000 -> 6521.1949 | AG3: =SUM(F5:AB5) -> 379147.92 | AH3: 1 | AI3: $/m3 | AJ3: $ Total | AN3: =AG3 -> 379147.92 | AO3: 1 | AP3: $/m3 | AQ3: $ Total
B4: Und de Lavandería | C4: 6060688 | D4: 34 | E4: 361783 | F4: 16476 | G4: 464000 | H4: =($D$4*G4)/1000 -> 15776 | I4: 460500 | J4: =($D$4*I4)/1000 -> 15657 | K4: 437000 | L4: =($D$4*K4)/1000 -> 14858 | M4: 508000 | N4: =($D$4*M4)/1000 -> 17272 | O4: 532000 | P4: =($D$4*O4)/1000 -> 18088 | Q4: 599100 | R4: =($D$4*Q4)/1000 -> 20369.4 | S4: 535200 | T4: =($D$4*S4)/1000 -> 18196.8 | U4: 657359.42 | V4: =($D$4*U4)/1000 -> 22350.22 | W4: 639859.42 | X4: =($D$4*W4)/1000 -> 21755.22 | Y4: 577690.62 | Z4: =($D$4*Y4)/1000 -> 19641.481 | AA4: 202978.55 | AB4: =($D$4*AA4)/1000 -> 6901.2705 | AE4: TRATAMIENTO DE AGUA RESIDUAL | AF4: PTAR (Costo de Tratamiento hasta Fase 2 - Cumplimiento Ambiental) OPEX SIN DEPRECIACIÓN | AG4: =AG3 -> 379147.92 | AH4: 1 | AI4: ='PROYECCIÓN INSUMOS QUÍMICOS'!V22+'PROYECCIÓN RESIDUOS Y LODOS'!U10+'PROYECCIÓN CONSUMIBLES PTAR'!U12+'PROYECCIÓN CALIBR-MANTE PTAR'!U12+'PROYECCIÓN NOMINA PTAR'!U10+'PROYECCIÓN ELECTRICIDAD PTAR'!U8 -> 10067.306 | AJ4: =AG4*AI4 -> 3.8169981e+09 | AL4: TRATAMIENTO DE AGUA RESIDUAL | AM4: PTAR (Costo de Tratamiento hasta Fase 2 - Cumplimiento Ambiental) OPEX CON DEPRECIACIÓN | AN4: =AN3 -> 379147.92 | AO4: 1 | AP4: =AI4+'PROYECCIÓN DEPRECIACIÓN PTAR'!U10 -> 11828.253 | AQ4: =AN4*AP4 -> 4.4846576e+09
B5: Consumo Total (m3/Mes) | F5: 27229 | H5: =SUM(H3:H4) -> 26637.416 | J5: =SUM(J3:J4) -> 25371.211 | L5: =SUM(L3:L4) -> 28996.039 | N5: =SUM(N3:N4) -> 31421.6 | P5: =SUM(P3:P4) -> 34249.301 | R5: =SUM(R3:R4) -> 40509.091 | T5: =SUM(T3:T4) -> 40285.492 | V5: =SUM(V3:V4) -> 43482.437 | X5: =SUM(X3:X4) -> 40858.186 | Z5: =SUM(Z3:Z4) -> 26685.676 | AB5: =SUM(AB3:AB4) -> 13422.465 | AE5: FUENTES ABASTECIMIENTO | AF5: OSMOSIS INVERSA (Costo procesar por RO - OPEX) SIN DEPRECIACIÓN | AG5: =F8+H8+J8+L8+N8+P8+R8+T8+V8+X8+Z8+AB8 -> 221583.52 | AH5: =(AG5/$AG$3) -> 0.58442501 | AI5: ='PROYECCIÓN INSUMOS QUÍMICOS'!V23+'PROYECCIÓN CONSUMIBLES PTAR'!U13+'PROYECCIÓN CALIBR-MANTE PTAR'!U13+'PROYECCIÓN NOMINA PTAR'!U11+'PROYECCIÓN ELECTRICIDAD PTAR'!U9 -> 3406.3554 | AJ5: =AG5*AI5 -> 7.5479224e+08 | AL5: FUENTES ABASTECIMIENTO | AM5: OSMOSIS INVERSA (Costo procesar por RO - OPEX) SIN DEPRECIACIÓN | AN5: =AG5 -> 221583.52 | AO5: =(AN5/$AG$3) -> 0.58442501 | AP5: =AI5+'PROYECCIÓN DEPRECIACIÓN PTAR'!U11 -> 3602.7536 | AQ5: =AN5*AP5 -> 7.9831084e+08
B6: FUENTES DE ABASTECIMIENTO | E6: % | F6: M3 | G6: % | H6: M3 | I6: % | J6: M3 | K6: % | L6: M3 | M6: % | N6: M3 | O6: % | P6: M3 | Q6: % | R6: M3 | S6: % | T6: M3 | U6: % | V6: M3 | W6: % | X6: M3 | Y6: % | Z6: M3 | AA6: % | AB6: M3 | AF6: PTAP (Costo de Tratamiento de Agua de Pozo Sin depreciación) | AG6: =F9+H9+J9+L9+N9+P9+R9+T9+V9+X9+Z9+AB9 -> 95848.197 | AH6: =(AG6/$AG$3) -> 0.25279896 | AI6: ='PROYECCIÓN INSUMOS QUÍMICOS'!V35+'PROYECCIÓN RESIDUOS Y LODOS'!U18+'PROYECCIÓN CONSUMIBLES PTAR'!U23+'PROYECCIÓN CALIBR-MANTE PTAR'!U22+'PROYECCIÓN NOMINA PTAR'!U20+'PROYECCIÓN ELECTRICIDAD PTAR'!U16+'PROYECCIÓN PAGO USO POZO'!U8 -> 5062.1281 | AJ6: =AG6*AI6 -> 4.8519585e+08 | AM6: PTAP (Costo de Tratamiento de Agua de Pozo Sin depreciación) | AN6: =AG6 -> 95848.197 | AO6: =(AN6/$AG$3) -> 0.25279896 | AP6: =AI6+'PROYECCIÓN DEPRECIACIÓN PTAR'!U19 -> 5622.9088 | AQ6: =AN6*AP6 -> 5.3894567e+08
B7: ACUEDUCTO (M3) | E7: =(F7*100%)/F5 -> 0.36519887 | F7: 9944 | G7: 0.3652 | H7: =$H$5*$G$7 -> 9727.9843 | I7: 0.3652 | J7: =$J$5*$I$7 -> 9265.5664 | K7: =100%-K8-K9-K10 -> 0.3652 | L7: =$L$5*$K$7 -> 10589.353 | M7: =100%-M8-M9-M10 -> 0.0434 | N7: =$N$5*$M$7 -> 1363.6975 | O7: =100%-O8-O9-O10 -> 0.0434 | P7: =$P$5*$O$7 -> 1486.4196 | Q7: =100%-Q8-Q9-Q10 -> 0.1034 | R7: =$R$5*$Q$7 -> 4188.6401 | S7: =100%-S8-S9-S10 -> 0.1034 | T7: =$T$5*$S$7 -> 4165.5199 | U7: =100%-U8-U9-U10 -> 0.1134 | V7: =$V$5*$U$7 -> 4930.9083 | W7: =100%-W8-W9-W10 -> 0.0934 | X7: =$X$5*$W$7 -> 3816.1546 | Y7: 0 | Z7: =$Z$5*$Y$7 -> 0 | AA7: 0 | AB7: =$AB$5*$AA$7 -> 0 | AF7: ACUEDUCTO | AG7: =F7+H7+J7+L7+N7+P7+R7+T7+V7+X7+Z7+AB7 -> 59478.244 | AH7: =(AG7/$AG$3) -> 0.15687346 | AI7: 10763 | AJ7: =AG7*AI7 -> 6.4016434e+08 | AM7: ACUEDUCTO | AN7: =AG7 -> 59478.244 | AO7: =(AN7/$AG$3) -> 0.15687346 | AP7: 10763 | AQ7: =AN7*AP7 -> 6.4016434e+08
B8: OSMOSIS INVERSA - PTAR (M3 | E8: 0.4203 | F8: 11443 | G8: 0.4203 | H8: =$H$5*$G$8 -> 11195.706 | I8: 0.4203 | J8: =$J$5*$I$8 -> 10663.52 | K8: 0.4203 | L8: =$L$5*$K$8 -> 12187.035 | M8: 0.65 | N8: =$N$5*$M$8 -> 20424.04 | O8: 0.65 | P8: =$P$5*$O$8 -> 22262.045 | Q8: 0.65 | R8: =$R$5*$Q$8 -> 26330.909 | S8: 0.65 | T8: =$T$5*$S$8 -> 26185.57 | U8: 0.65 | V8: =$V$5*$U$8 -> 28263.584 | W8: 0.65 | X8: =$X$5*$W$8 -> 26557.821 | Y8: 0.65 | Z8: =Z5*Y8 -> 17345.689 | AA8: 0.65 | AB8: =AB5-AB9 -> 8724.6025 | AF8: CARRO TANQUES | AG8: =F10+H10+J10+L10+N10+P10+R10+T10+V10+X10+Z10+AB10 -> 2237.9511 | AH8: =(AG8/$AG$3) -> 0.0059025805 | AI8: 12700 | AJ8: =AG8*AI8 -> 28421979 | AM8: CARRO TANQUES | AN8: =AG8 -> 2237.9511 | AO8: =(AN8/$AG$3) -> 0.0059025805 | AP8: 12700 | AQ8: =AN8*AP8 -> 28421979
B9: PTAP (M3) | E9: 0.2079 | F9: 5662 | G9: 0.2079 | H9: =$H$5*$G$9 -> 5537.9188 | I9: 0.2079 | J9: =$J$5*$I$9 -> 5274.6748 | K9: 0.2079 | L9: =$L$5*$K$9 -> 6028.2765 | M9: 0.3 | N9: =+N5*M9 -> 9426.4801 | O9: 0.3 | P9: =+P5*O9 -> 10274.79 | Q9: 0.24 | R9: =+R5*Q9 -> 9722.182 | S9: 0.24 | T9: =+T5*S9 -> 9668.5181 | U9: 0.23 | V9: =+V5*U9 -> 10000.96 | W9: 0.25 | X9: =+X5*W9 -> 10214.547 | Y9: 0.35 | Z9: =+Z5*Y9 -> 9339.9865 | AA9: 0.35 | AB9: =+AB5*AA9 -> 4697.8629 | AI9: TOTAL | AJ9: =SUM(AJ4:AJ8) -> 5.7255725e+09 | AP9: TOTAL | AQ9: =SUM(AQ4:AQ8) -> 6.4905005e+09
B10: CARRO TANQUES (M3) | E10: 0.0066 | F10: 180 | G10: 0.0066 | H10: =$H$5*$G$10 -> 175.80695 | I10: 0.0066 | J10: =$J$5*$I$10 -> 167.44999 | K10: 0.0066 | L10: =$L$5*$K$10 -> 191.37386 | M10: =+N10/N5 -> 0.0066 | N10: =$N$5*$E$10 -> 207.38256 | O10: 0.0066 | P10: =$P$5*$O$10 -> 226.04538 | Q10: 0.0066 | R10: =$R$5*$Q$10 -> 267.36 | S10: 0.0066 | T10: =$T$5*$S$10 -> 265.88425 | U10: 0.0066 | V10: =$V$5*$U$10 -> 286.98408 | W10: 0.0066 | X10: =$X$5*$W$10 -> 269.66403 | Y10: 0 | Z10: =$Z$5*$Y$10 -> 0 | AA10: 0 | AB10: =$AB$5*$AA$10 -> 0 | AG10: COSTO DE TRATAMIENTO DE AGUA RESIDUAL | AI10: $/M3 | AJ10: =AJ4/AG4 -> 10067.306 | AN10: COSTO DE TRATAMIENTO DE AGUA RESIDUAL | AP10: $/M3 | AQ10: =AQ4/AN4 -> 11828.253
AG11: COSTO DE SUMINISTRO DE AGUA A PROCESO | AI11: $/M3 | AJ11: =SUM(AJ5:AJ8)/AG3 -> 5033.8518 | AN11: COSTO DE SUMINISTRO DE AGUA A PROCESO | AP11: $/M3 | AQ11: =SUM(AQ5:AQ8)/AN3 -> 5290.3966
G12: Febrero | H12: Consumo de Agua proyectado (m3/MES) | AG12: COSTO TOTAL M3 PERMODA | AI12: $/M3 | AJ12: =SUM(AJ10:AJ11) -> 15101.158 | AN12: COSTO TOTAL M3 PERMODA | AP12: $/M3 | AQ12: =SUM(AQ10:AQ11) -> 17118.65
G13: 130962 | H13: =(41*G13)/1000 -> 5369.442
G14: 450288 | H14: =(45.7*G14)/1000 -> 20578.162 | AE14: CONSUMO TOTAL (M3) PLAN MAESTRO | AG14: Volumen (M3) | AH14: Porcentaje | AL14: CONSUMO TOTAL (M3) PLAN MAESTRO | AN14: Volumen (M3) | AO14: Porcentaje
H15: 26204 | AG15: =AG3 -> 379147.92 | AH15: 1 | AI15: $/m3 | AJ15: $ Total | AN15: =AN3 -> 379147.92 | AO15: 1 | AP15: $/m3 | AQ15: $ Total
B16: FUENTES DE ABASTECIMIENTO | G16: % | H16: M3 | AE16: TRATAMIENTO DE AGUA RESIDUAL | AF16: PTAR (Costo de Tratamiento hasta Fase 2 - Cumplimiento Ambiental) OPEX SIN DEPRECIACIÓN | AG16: =AG15 -> 379147.92 | AH16: 1 | AI16: =AI4 -> 10067.306 | AJ16: =AG16*AI16 -> 3.8169981e+09 | AL16: TRATAMIENTO DE AGUA RESIDUAL | AM16: PTAR (Costo de Tratamiento hasta Fase 2 - Cumplimiento Ambiental) OPEX CON DEPRECIACIÓN | AN16: =AN15 -> 379147.92 | AO16: 1 | AP16: =AP4 -> 11828.253 | AQ16: =AN16*AP16 -> 4.4846576e+09
B17: ACUEDUCTO (M3) | G17: =(H17*100%)/$H$15 -> 0.3876889 | H17: 10159 | AE17: FUENTES ABASTECIMIENTO | AF17: OSMOSIS INVERSA (Costo procesar por RO - OPEX) SIN DEPRECIACIÓN | AG17: 0 | AH17: =(AG17/$AG$3) -> 0 | AI17: 0 | AJ17: =AG17*AI17 -> 0 | AL17: FUENTES ABASTECIMIENTO | AM17: OSMOSIS INVERSA (Costo procesar por RO - OPEX) SIN DEPRECIACIÓN | AN17: 0 | AO17: =(AN17/$AG$3) -> 0 | AP17: 0 | AQ17: 0
B18: OSMOSIS INVERSA - PTAR (M3 | G18: =(H18*100%)/$H$15 -> 0.43050679 | H18: 11281 | AF18: PTAP | AG18: =AG6 -> 95848.197 | AH18: =(AG18/$AG$3) -> 0.25279896 | AI18: =AI6 -> 5062.1281 | AJ18: =AG18*AI18 -> 4.8519585e+08 | AM18: PTAP | AN18: =AN6 -> 95848.197 | AO18: =(AN18/$AG$3) -> 0.25279896 | AP18: =AP6 -> 5622.9088 | AQ18: =AN18*AP18 -> 5.3894567e+08
B19: PTAP (M3) | G19: =(H19*100%)/$H$15 -> 0.17005037 | H19: 4456 | AF19: ACUEDUCTO | AG19: 230400 | AH19: =(AG19/$AG$3) -> 0.6076784 | AI19: 10763 | AJ19: =AG19*AI19 -> 2479795200 | AM19: ACUEDUCTO | AN19: 230400 | AO19: =(AN19/$AG$3) -> 0.6076784 | AP19: 10763 | AQ19: =AN19*AP19 -> 2479795200
B20: CARRO TANQUES (M3) | G20: =(H20*100%)/$H$15 -> 0.011753931 | H20: 308 | AF20: CARRO TANQUES | AG20: =AG15-AG18-AG19 -> 52899.718 | AH20: =(AG20/$AG$3) -> 0.13952264 | AI20: 12700 | AJ20: =AG20*AI20 -> 6.7182642e+08 | AM20: CARRO TANQUES | AN20: =AN15-AN18-AN19 -> 52899.718 | AO20: =(AN20/$AG$3) -> 0.13952264 | AP20: 12700 | AQ20: =AN20*AP20 -> 6.7182642e+08
AI21: TOTAL | AJ21: =SUM(AJ16:AJ20) -> 7.4538156e+09 | AP21: TOTAL | AQ21: =SUM(AQ16:AQ20) -> 8.1752249e+09
AG22: COSTO DE TRATAMIENTO DE AGUA RESIDUAL | AI22: $/M3 | AJ22: =AJ16/AG16 -> 10067.306 | AN22: COSTO DE TRATAMIENTO DE AGUA RESIDUAL | AP22: $/M3 | AQ22: =AQ16/AN16 -> 11828.253
AG23: COSTO DE SUMINISTRO DE AGUA A PROCESO | AI23: $/M3 | AJ23: =SUM(AJ17:AJ20)/AG15 -> 9592.0809 | AN23: COSTO DE SUMINISTRO DE AGUA A PROCESO | AP23: $/M3 | AQ23: =SUM(AQ17:AQ20)/AN15 -> 9733.8457
AG24: COSTO TOTAL M3 PERMODA | AI24: $/M3 | AJ24: =SUM(AJ22:AJ23) -> 19659.387 | AN24: COSTO TOTAL M3 PERMODA | AP24: $/M3 | AQ24: =SUM(AQ22:AQ23) -> 21562.099 | AR24: =AQ24-AQ12 -> 4443.4491
AH26: PROYECCIÓN CON RECIRCULACIÓN | AJ26: =AJ9 -> 5.7255725e+09 | AO26: PROYECCIÓN CON RECIRCULACIÓN | AQ26: =AQ9 -> 6.4905005e+09
AH27: PROYECCIÓN SIN RECIRCULACIÓN | AJ27: =AJ21 -> 7.4538156e+09 | AO27: PROYECCIÓN SIN RECIRCULACIÓN | AQ27: =AQ21 -> 8.1752249e+09
AH29: AHORRO PROYECTADO RECIRCULANDO | AJ29: =AJ27-AJ26 -> 1.7282431e+09 | AO29: AHORRO PROYECTADO RECIRCULANDO | AQ29: =AQ27-AQ26 -> 1.6847245e+09
AE31: CONSUMO TOTAL (M3) PLAN MAESTRO | AG31: Volumen (M3) | AH31: Porcentaje | AL31: CONSUMO TOTAL (M3) PLAN MAESTRO | AN31: Volumen (M3) | AO31: Porcentaje
AG32: =AG15 -> 379147.92 | AH32: 1 | AI32: $/m3 | AJ32: $ Total | AN32: =AN15 -> 379147.92 | AO32: 1 | AP32: $/m3 | AQ32: $ Total
AE33: TRATAMIENTO DE AGUA RESIDUAL | AF33: PTAR (Costo de Tratamiento hasta Fase 2 - Cumplimiento Ambiental) OPEX SIN DEPRECIACIÓN | AG33: =AG32 -> 379147.92 | AH33: 1 | AI33: =AI16 -> 10067.306 | AJ33: =AG33*AI33 -> 3.8169981e+09 | AL33: TRATAMIENTO DE AGUA RESIDUAL | AM33: PTAR (Costo de Tratamiento hasta Fase 2 - Cumplimiento Ambiental) OPEX CON DEPRECIACIÓN | AN33: =AN32 -> 379147.92 | AO33: 1 | AP33: =AP16 -> 11828.253 | AQ33: =AN33*AP33 -> 4.4846576e+09
AE34: FUENTES ABASTECIMIENTO | AF34: OSMOSIS INVERSA (Costo procesar por RO - OPEX) SIN DEPRECIACIÓN | AG34: 0 | AH34: =(AG34/$AG$3) -> 0 | AI34: 0 | AJ34: =AG34*AI34 -> 0 | AL34: FUENTES ABASTECIMIENTO | AM34: OSMOSIS INVERSA (Costo procesar por RO - OPEX) SIN DEPRECIACIÓN | AN34: 0 | AO34: =(AN34/$AG$3) -> 0 | AP34: 0 | AQ34: 0
AF35: PTAP | AG35: 0 | AH35: =(AG35/$AG$3) -> 0 | AI35: 0 | AJ35: =AG35*AI35 -> 0 | AM35: PTAP | AN35: 0 | AO35: =(AN35/$AG$3) -> 0 | AP35: 0 | AQ35: =AN35*AP35 -> 0
AF36: ACUEDUCTO | AG36: 230400 | AH36: =(AG36/$AG$3) -> 0.6076784 | AI36: 10763 | AJ36: =AG36*AI36 -> 2479795200 | AM36: ACUEDUCTO | AN36: 230400 | AO36: =(AN36/$AG$3) -> 0.6076784 | AP36: 10763 | AQ36: =AN36*AP36 -> 2479795200
AF37: CARRO TANQUES | AG37: =AG32-AG35-AG36 -> 148747.92 | AH37: =(AG37/$AG$3) -> 0.3923216 | AI37: 12700 | AJ37: =AG37*AI37 -> 1.8890985e+09 | AM37: CARRO TANQUES | AN37: =AN32-AN35-AN36 -> 148747.92 | AO37: =(AN37/$AG$3) -> 0.3923216 | AP37: 12700 | AQ37: =AN37*AP37 -> 1.8890985e+09
AI38: TOTAL | AJ38: =SUM(AJ33:AJ37) -> 8.1858918e+09 | AP38: TOTAL | AQ38: =SUM(AQ33:AQ37) -> 8.8535513e+09
AG39: COSTO DE TRATAMIENTO DE AGUA RESIDUAL | AI39: $/M3 | AJ39: =AJ33/AG33 -> 10067.306 | AN39: COSTO DE TRATAMIENTO DE AGUA RESIDUAL | AP39: $/M3 | AQ39: =AQ33/AN33 -> 11828.253
AG40: COSTO DE SUMINISTRO DE AGUA A PROCESO | AI40: $/M3 | AJ40: =SUM(AJ34:AJ37)/AG32 -> 11522.927 | AN40: COSTO DE SUMINISTRO DE AGUA A PROCESO | AP40: $/M3 | AQ40: =SUM(AQ34:AQ37)/AN32 -> 11522.927
AG41: COSTO TOTAL M3 PERMODA | AI41: $/M3 | AJ41: =SUM(AJ39:AJ40) -> 21590.233 | AN41: COSTO TOTAL M3 PERMODA | AP41: $/M3 | AQ41: =SUM(AQ39:AQ40) -> 23351.18 | AR41: =AQ41-AQ12 -> 6232.5304
AH43: PROYECCIÓN CON RECIRCULACIÓN Y PTAP | AJ43: =AJ26 -> 5.7255725e+09 | AO43: PROYECCIÓN CON RECIRCULACIÓN Y PTAP | AQ43: =AQ9 -> 6.4905005e+09
AH44: PROYECCIÓN SIN RECIRCULACIÓN SIN PTAP | AJ44: =AJ38 -> 8.1858918e+09 | AO44: PROYECCIÓN SIN RECIRCULACIÓN | AQ44: =AQ21 -> 8.1752249e+09 | AR44: =AQ44-AQ43 -> 1.6847245e+09
AO45: PROYECCIÓN SIN RECIRCULACIÓN SIN PTAP | AQ45: =AQ38 -> 8.8535513e+09 | AR45: =AQ45-AQ43 -> 2.3630509e+09
...

Sheet PROYECCIÓN INSUMOS QUÍMICOS
B2: COSTO PLANTA DE TRATAMIENTO DE AGUA RESIDUAL | G2: EJECUTADO PTAR AÑO 2026 BOGOTÁ
B3: Clasificación | C3: Detalle | D3: Unidad | E3: Dosificación | G3: Enero 2026 | H3: Febrero 2026 | I3: Marzo 2026 | J3: Abril 2026 | K3: Mayo 2026 | L3: Junio 2026 | M3: Julio 2026 | N3: Agosto 2026 | O3: Septiembre 2026 | P3: Octubre 2026 | Q3: Noviembre 2026 | R3: Diciembre 2026 | S3: Total general | T3: $/Kg | U3: $ Total | V3: $/M3
E4: Kg/m3 | F4: g/m3 | G4: CAUDAL PLAN MAESTRO
G5: ='PLAN MAESTRO BOGOTA RECIRCU'!F5 -> 27229 | H5: ='PLAN MAESTRO BOGOTA RECIRCU'!H5 -> 26637.416 | I5: ='PLAN MAESTRO BOGOTA RECIRCU'!J5 -> 25371.211 | J5: ='PLAN MAESTRO BOGOTA RECIRCU'!L5 -> 28996.039 | K5: ='PLAN MAESTRO BOGOTA RECIRCU'!N5 -> 31421.6 | L5: ='PLAN MAESTRO BOGOTA RECIRCU'!P5 -> 34249.301 | M5: ='PLAN MAESTRO BOGOTA RECIRCU'!R5 -> 40509.091 | N5: ='PLAN MAESTRO BOGOTA RECIRCU'!T5 -> 40285.492 | O5: ='PLAN MAESTRO BOGOTA RECIRCU'!V5 -> 43482.437 | P5: ='PLAN MAESTRO BOGOTA RECIRCU'!X5 -> 40858.186 | Q5: ='PLAN MAESTRO BOGOTA RECIRCU'!Z5 -> 26685.676 | R5: ='PLAN MAESTRO BOGOTA RECIRCU'!AB5 -> 13422.465 | S5: =SUM(G5:R5) -> 379147.92
B6: QUIMICOS (GEM + RO) | C6: ACIDO CLORHIDRICO 31,5% | D6: kg | E6: ='Resumen costos Ptar Bogotá'!U6 -> 0.013583636 | F6: =E6*1000 -> 13.583636 | G6: =$E$6*G5 -> 369.86883 | H6: =$E$6*H5 -> 361.83297 | I6: =$E$6*I5 -> 344.63331 | J6: =$E$6*J5 -> 393.87165 | K6: =$E$6*K5 -> 426.81959 | L6: =$E$6*L5 -> 465.23004 | M6: =$E$6*M5 -> 550.26077 | N6: =$E$6*N5 -> 547.22347 | ... R6: =$E$6*R5 -> 182.32589 | S6: =+SUM(G6:R6) -> 5150.2074 | T6: 1650 | U6: =S6*T6 -> 8497842.2 | V6: =U6/$S$5 -> 22.413
C7: SODIO BISULFITO | D7: kg | E7: ='Resumen costos Ptar Bogotá'!U7 -> 0.0011916667 | F7: =E7*1000 -> 1.1916667 | G7: =$E$7*G5 -> 32.447892 | H7: =$E$7*H5 -> 31.742921 | I7: =$E$7*I5 -> 30.234027 | J7: =$E$7*J5 -> 34.553613 | K7: =$E$7*K5 -> 37.444074 | L7: =$E$7*L5 -> 40.81375 | M7: =$E$7*M5 -> 48.273334 | N7: =$E$7*N5 -> 48.006878 | ... R7: =$E$7*R5 -> 15.995105 | S7: =+SUM(G7:R7) -> 451.81793 | T7: 4200 | U7: =S7*T7 -> 1897635.3 | V7: =U7/$S$5 -> 5.005
C8: NITRATO DE PLATA | D8: kg | E8: ='Resumen costos Ptar Bogotá'!U8 -> 1.8118958e-05 | F8: =E8*1000 -> 0.018118958 | G8: =$E$8*G5 -> 0.4933611 | H8: =$E$8*H5 -> 0.48264221 | I8: =$E$8*I5 -> 0.4596999 | J8: =$E$8*J5 -> 0.525378 | K8: =$E$8*K5 -> 0.56932665 | L8: =$E$8*L5 -> 0.62056163 | M8: =$E$8*M5 -> 0.73398252 | N8: =$E$8*N5 -> 0.72993113 | ... R8: =$E$8*R5 -> 0.24320108 | S8: =+SUM(G8:R8) -> 6.869765 | T8: 180000 | U8: =S8*T8 -> 1236557.7 | V8: =U8/$S$5 -> 3.2614124
C9: ACIDIFICANTE | D9: kg | E9: ='Resumen costos Ptar Bogotá'!U10 -> 0.30804068 | F9: =E9*1000 -> 308.04068 | G9: =$E$9*G5 -> 8387.6395 | H9: =$E$9*H5 -> 8205.4076 | I9: =$E$9*I5 -> 7815.3651 | J9: =$E$9*J5 -> 8931.9594 | K9: =$E$9*K5 -> 9679.131 | L9: =$E$9*L5 -> 10550.178 | M9: =$E$9*M5 -> 12478.448 | N9: =$E$9*N5 -> 12409.57 | ... R9: =$E$9*R5 -> 4134.6653 | S9: =+SUM(G9:R9) -> 116792.98 | T9: 830 | U9: =S9*T9 -> 96938173 | V9: =U9/$S$5 -> 255.67376
C10: QUIMICO FLOCULANTE PARA TRATAMIENTO DE AGUA (Catiónico) | D10: kg | E10: ='Resumen costos Ptar Bogotá'!U11 -> 0.0091306964 | F10: =E10*1000 -> 9.1306964 | G10: =$E$10*G5 -> 248.61973 | H10: =$E$10*H5 -> 243.21816 | I10: =$E$10*I5 -> 231.65683 | J10: =$E$10*J5 -> 264.75403 | K10: =$E$10*K5 -> 286.90109 | L10: =$E$10*L5 -> 312.71996 | M10: =$E$10*M5 -> 369.87621 | N10: =$E$10*N5 -> 367.8346 | ... R10: =$E$10*R5 -> 122.55646 | S10: =+SUM(G10:R10) -> 3461.8845 | T10: 22050 | U10: =S10*T10 -> 76334553 | V10: =U10/$S$5 -> 201.33185
C11: QUIMICO FLOCULANTE PARA TRATAMIENTO DE AGUA (Aniónico) | D11: kg | E11: ='Resumen costos Ptar Bogotá'!U12 -> 0.0054182543 | F11: =E11*1000 -> 5.4182543 | G11: =$E$11*G5 -> 147.53365 | H11: =$E$11*H5 -> 144.32829 | I11: =$E$11*I5 -> 137.46768 | J11: =$E$11*J5 -> 157.10791 | K11: =$E$11*K5 -> 170.25022 | L11: =$E$11*L5 -> 185.57142 | M11: =$E$11*M5 -> 219.48856 | N11: =$E$11*N5 -> 218.27704 | ... R11: =$E$11*R5 -> 72.726331 | S11: =+SUM(G11:R11) -> 2054.3198 | T11: 19050 | U11: =S11*T11 -> 39134793 | V11: =U11/$S$5 -> 103.21774
C12: QUIMICO COAGULANTE PARA TRATAMIENTO DE AGUA (Coagulante) | D12: kg | E12: ='Resumen costos Ptar Bogotá'!U13 -> 0.54180085 | F12: =E12*1000 -> 541.80085 | G12: =$E$12*G5 -> 14752.695 | H12: =$E$12*H5 -> 14432.175 | I12: =$E$12*I5 -> 13746.144 | J12: =$E$12*J5 -> 15710.079 | K12: =$E$12*K5 -> 17024.25 | L12: =$E$12*L5 -> 18556.3 | M12: =$E$12*M5 -> 21947.86 | N12: =$E$12*N5 -> 21826.714 | ... R12: =$E$12*R5 -> 7272.3033 | S12: =+SUM(G12:R12) -> 205422.66 | T12: 2818 | U12: =S12*T12 -> 5.7888107e+08 | V12: =U12/$S$5 -> 1526.7948
C13: QUIMICO COAGULANTE PARA TRATAMIENTO DE AGUA (Decolorante) | D13: kg | E13: ='Resumen costos Ptar Bogotá'!U14 -> 0.23755146 | F13: =E13*1000 -> 237.55146 | G13: =$E$13*G5 -> 6468.2888 | H13: =$E$13*H5 -> 6327.7572 | I13: =$E$13*I5 -> 6026.9684 | J13: =$E$13*J5 -> 6888.0515 | K13: =$E$13*K5 -> 7464.2471 | L13: =$E$13*L5 -> 8135.9715 | M13: =$E$13*M5 -> 9622.994 | N13: =$E$13*N5 -> 9569.8776 | ... R13: =$E$13*R5 -> 3188.5263 | S13: =+SUM(G13:R13) -> 90067.142 | T13: 6295 | U13: =S13*T13 -> 5.6697266e+08 | V13: =U13/$S$5 -> 1495.3865 | W13: OZONO
C14: HIPOCLORITO DE SODIO | D14: kg | E14: ='Resumen costos Ptar Bogotá'!U15 -> 0.0072995135 | F14: =E14*1000 -> 7.2995135 | G14: =$E$14*G5 -> 198.75845 | H14: =$E$14*H5 -> 194.44018 | I14: =$E$14*I5 -> 185.1975 | J14: =$E$14*J5 -> 211.65698 | K14: =$E$14*K5 -> 229.36239 | L14: =$E$14*L5 -> 250.00323 | M14: =$E$14*M5 -> 295.69666 | N14: =$E$14*N5 -> 294.06449 | ... R14: =$E$14*R5 -> 97.977467 | S14: =+SUM(G14:R14) -> 2767.5953 | T14: 1298 | U14: =S14*T14 -> 3592338.7 | V14: =U14/$S$5 -> 9.4747685
C15: SODA CAUSTICA LIQUI48% 90 KL | D15: kg | E15: ='Resumen costos Ptar Bogotá'!U16 -> 0.013272416 | F15: =E15*1000 -> 13.272416 | G15: =$E$15*G5 -> 361.39461 | H15: =$E$15*H5 -> 353.54286 | I15: =$E$15*I5 -> 336.73726 | J15: =$E$15*J5 -> 384.84748 | K15: =$E$15*K5 -> 417.04054 | L15: =$E$15*L5 -> 454.57095 | M15: =$E$15*M5 -> 537.6535 | N15: =$E$15*N5 -> 534.6858 | ... R15: =$E$15*R5 -> 178.14854 | S15: =+SUM(G15:R15) -> 5032.2087 | T15: 1862 | U15: =S15*T15 -> 9369972.7 | V15: =U15/$S$5 -> 24.713238
C16: QUIMICO ANTINCRUSTANTE PARA ÓSMOSIS INVERSA | D16: kg | E16: ='Resumen costos Ptar Bogotá'!U17 -> 0.013763942 | F16: =E16*1000 -> 13.763942 | G16: =$E$16*G5 -> 374.77836 | H16: =$E$16*H5 -> 366.63584 | I16: =$E$16*I5 -> 349.20787 | J16: =$E$16*J5 -> 399.09979 | K16: =$E$16*K5 -> 432.48507 | L16: =$E$16*L5 -> 471.40537 | M16: =$E$16*M5 -> 557.56477 | N16: =$E$16*N5 -> 554.48716 | ... R16: =$E$16*R5 -> 184.74603 | S16: =+SUM(G16:R16) -> 5218.5697 | T16: 36239 | U16: =S16*T16 -> 1.8911575e+08 | V16: =U16/$S$5 -> 498.79148
C17: QUIMICO PARA TRATAMIENTO CIP ALCALINO ÓSMOSIS INVERSA | D17: kg | E17: ='Resumen costos Ptar Bogotá'!U18 -> 0.00091964781 | F17: =E17*1000 -> 0.91964781 | G17: =$E$17*G5 -> 25.04109 | H17: =$E$17*H5 -> 24.497041 | I17: =$E$17*I5 -> 23.332579 | J17: =$E$17*J5 -> 26.666144 | K17: =$E$17*K5 -> 28.896806 | L17: =$E$17*L5 -> 31.497294 | M17: =$E$17*M5 -> 37.254097 | N17: =$E$17*N5 -> 37.048464 | ... R17: =$E$17*R5 -> 12.343941 | S17: =+SUM(G17:R17) -> 348.68255 | T17: 32490 | U17: =S17*T17 -> 11328696 | V17: =U17/$S$5 -> 29.879357
C18: QUIMICO PARA TRATAMIENTO BIODISPERSANTE ÓSMOSIS INVERSA | D18: kg | E18: ='Resumen costos Ptar Bogotá'!U19 -> 0.018171608 | F18: =E18*1000 -> 18.171608 | G18: =$E$18*G5 -> 494.79473 | H18: =$E$18*H5 -> 484.04469 | I18: =$E$18*I5 -> 461.03572 | J18: =$E$18*J5 -> 526.90467 | K18: =$E$18*K5 -> 570.98102 | L18: =$E$18*L5 -> 622.36488 | M18: =$E$18*M5 -> 736.11535 | N18: =$E$18*N5 -> 732.05219 | ... R18: =$E$18*R5 -> 243.90779 | S18: =+SUM(G18:R18) -> 6889.7275 | T18: 19160 | U18: =S18*T18 -> 1.3200718e+08 | V18: =U18/$S$5 -> 348.16802 | W18: TQI
C19: QUIMICO PARA TRATAMIENTO CIP ACIDO ÓSMOSIS INVERSA | D19: Kg | E19: ='Resumen costos Ptar Bogotá'!U20 -> 0.00087479088 | F19: =E19*1000 -> 0.87479088 | G19: =$E$19*G5 -> 23.819681 | H19: =$E$19*H5 -> 23.302169 | I19: =$E$19*I5 -> 22.194504 | J19: =$E$19*J5 -> 25.36547 | K19: =$E$19*K5 -> 27.487329 | L19: =$E$19*L5 -> 29.960976 | M19: =$E$19*M5 -> 35.436984 | N19: =$E$19*N5 -> 35.241381 | ... R19: =$E$19*R5 -> 11.74185 | S19: =+SUM(G19:R19) -> 331.67514 | T19: 34156 | U19: =S19*T19 -> 11328696 | V19: =U19/$S$5 -> 29.879357
C20: ACIDO CÍTRICO | D20: Kg | E20: ='Resumen costos Ptar Bogotá'!U21 -> 0.00079766595 | F20: =E20*1000 -> 0.79766595 | G20: =$E$20*G5 -> 21.719646 | H20: =$E$20*H5 -> 21.24776 | I20: =$E$20*I5 -> 20.237751 | J20: =$E$20*J5 -> 23.129153 | K20: =$E$20*K5 -> 25.063941 | L20: =$E$20*L5 -> 27.319501 | M20: =$E$20*M5 -> 32.312723 | N20: =$E$20*N5 -> 32.134365 | ... R20: =$E$20*R5 -> 10.706644 | S20: =+SUM(G20:R20) -> 302.43338 | T20: 5200 | U20: =S20*T20 -> 1572653.6 | V20: =U20/$S$5 -> 4.1478629
C21: Subtotal | T21: Total General | U21: =SUM(U6:U20) -> 1.7282086e+09 | V21: =U21/$S$5 -> 4558.1381
S22: PTAR FASE 2 (GEM + MBR) | U22: =U8+U9+U10+U11+U12+U13+U14+U20 -> 1.3646628e+09 | V22: =U22/S5 -> 3599.2887
S23: OSMOSIS INVERSA | U23: =U6+U7+U15+U16+U17+U18+U19 -> 3.6354577e+08 | V23: =U23/S5 -> 958.84945
B25: COSTO PLANTA DE TRATAMIENTO DE AGUA DE POZO PROFUNDO | G25: EJECUTADO PTAP AÑO 2026 BOGOTÁ
B26: Clasificación | C26: Detalle | D26: Unidad | E26: Dosificación | G26: Enero 2026 | H26: Febrero 2026 | I26: Marzo 2026 | J26: Abril 2026 | K26: Mayo 2026 | L26: Junio 2026 | M26: Julio 2026 | N26: Agosto 2026 | O26: Septiembre 2026 | P26: Octubre 2026 | Q26: Noviembre 2026 | R26: Diciembre 2026 | S26: Total general | T26: $/Kg | U26: $ Total | V26: $/M3
E27: Kg/m3 | F27: g/m3 | G27: CAUDAL PLAN MAESTRO
G28: ='PLAN MAESTRO BOGOTA RECIRCU'!F9 -> 5662 | H28: ='PLAN MAESTRO BOGOTA RECIRCU'!H9 -> 5537.9188 | I28: ='PLAN MAESTRO BOGOTA RECIRCU'!J9 -> 5274.6748 | J28: ='PLAN MAESTRO BOGOTA RECIRCU'!L9 -> 6028.2765 | K28: ='PLAN MAESTRO BOGOTA RECIRCU'!N9 -> 9426.4801 | L28: ='PLAN MAESTRO BOGOTA RECIRCU'!P9 -> 10274.79 | M28: ='PLAN MAESTRO BOGOTA RECIRCU'!R9 -> 9722.182 | N28: ='PLAN MAESTRO BOGOTA RECIRCU'!T9 -> 9668.5181 | O28: ='PLAN MAESTRO BOGOTA RECIRCU'!V9 -> 10000.96 | P28: ='PLAN MAESTRO BOGOTA RECIRCU'!X9 -> 10214.547 | Q28: ='PLAN MAESTRO BOGOTA RECIRCU'!Z9 -> 9339.9865 | R28: ='PLAN MAESTRO BOGOTA RECIRCU'!AB9 -> 4697.8629 | S28: =SUM(G28:R28) -> 95848.197
B29: QUIMICOS (Clarifloculador + UF) | C29: ACIDO CLORHIDRICO 31,5% | D29: kg | E29: 0.06 | F29: =E29*1000 -> 60 | G29: =$E$29*G28 -> 339.72 | H29: =$E$29*H28 -> 332.27513 | I29: =$E$29*I28 -> 316.48049 | J29: =$E$29*J28 -> 361.69659 | K29: =$E$29*K28 -> 565.58881 | L29: =$E$29*L28 -> 616.48741 | M29: =$E$29*M28 -> 583.33092 | N29: =$E$29*N28 -> 580.11108 | ... R29: =$E$29*R28 -> 281.87177 | S29: =+SUM(G29:R29) -> 5750.8918 | T29: 1650 | U29: =S29*T29 -> 9488971.5 | V29: =U29/$S$28 -> 99
C30: ACIDIFICANTE | D30: kg | E30: 0.38 | F30: =E30*1000 -> 380 | G30: =$E$30*G28 -> 2151.56 | H30: =$E$30*H28 -> 2104.4091 | I30: =$E$30*I28 -> 2004.3764 | J30: =$E$30*J28 -> 2290.7451 | K30: =$E$30*K28 -> 3582.0624 | L30: =$E$30*L28 -> 3904.4203 | M30: =$E$30*M28 -> 3694.4291 | N30: =$E$30*N28 -> 3674.0369 | ... R30: =$E$30*R28 -> 1785.1879 | S30: =+SUM(G30:R30) -> 36422.315 | T30: 830 | U30: =S30*T30 -> 30230521 | V30: =U30/$S$28 -> 315.4
C31: QUIMICO COAGULANTE PARA TRATAMIENTO DE AGUA (Coagulante) | D31: kg | E31: 0.5426 | F31: =E31*1000 -> 542.6 | G31: =$E$31*G28 -> 3072.2012 | H31: =$E$31*H28 -> 3004.8747 | I31: =$E$31*I28 -> 2862.0386 | J31: =$E$31*J28 -> 3270.9428 | K31: =$E$31*K28 -> 5114.8081 | L31: =$E$31*L28 -> 5575.1011 | M31: =$E$31*M28 -> 5275.2559 | N31: =$E$31*N28 -> 5246.1379 | ... R31: =$E$31*R28 -> 2549.0604 | S31: =+SUM(G31:R31) -> 52007.232 | T31: 2818 | U31: =S31*T31 -> 1.4655638e+08 | V31: =U31/$S$28 -> 1529.0468
C32: QUIMICO FLOCULANTE PARA TRATAMIENTO DE AGUA (Aniónico) | D32: kg | E32: 0.0054 | F32: =E32*1000 -> 5.4 | G32: =$E$32*G28 -> 30.5748 | H32: =$E$32*H28 -> 29.904761 | I32: =$E$32*I28 -> 28.483244 | J32: =$E$32*J28 -> 32.552693 | K32: =$E$32*K28 -> 50.902993 | L32: =$E$32*L28 -> 55.483867 | M32: =$E$32*M28 -> 52.499783 | N32: =$E$32*N28 -> 52.209998 | ... R32: =$E$32*R28 -> 25.36846 | S32: =+SUM(G32:R32) -> 517.58026 | T32: 19050 | U32: =S32*T32 -> 9859904 | V32: =U32/$S$28 -> 102.87
C33: HIPOCLORITO DE SODIO | D33: kg | E33: 0.125 | F33: =E33*1000 -> 125 | G33: =$E$33*G28 -> 707.75 | H33: =$E$33*H28 -> 692.23985 | I33: =$E$33*I28 -> 659.33435 | J33: =$E$33*J28 -> 753.53456 | K33: =$E$33*K28 -> 1178.31 | L33: =$E$33*L28 -> 1284.3488 | M33: =$E$33*M28 -> 1215.2727 | N33: =$E$33*N28 -> 1208.5648 | ... R33: =$E$33*R28 -> 587.23286 | S33: =+SUM(G33:R33) -> 11981.025 | T33: 1298 | U33: =S33*T33 -> 15551370 | V33: =U33/$S$28 -> 162.25
C34: SODA CAUSTICA LIQUI48% 90 KL | D34: kg | E34: 0.037 | F34: =E34*1000 -> 37 | G34: =$E$34*G28 -> 209.494 | H34: =$E$34*H28 -> 204.903 | I34: =$E$34*I28 -> 195.16297 | J34: =$E$34*J28 -> 223.04623 | K34: =$E$34*K28 -> 348.77976 | L34: =$E$34*L28 -> 380.16724 | M34: =$E$34*M28 -> 359.72073 | N34: =$E$34*N28 -> 357.73517 | ... R34: =$E$34*R28 -> 173.82093 | S34: =+SUM(G34:R34) -> 3546.3833 | T34: 1862 | U34: =S34*T34 -> 6603365.7 | V34: =U34/$S$28 -> 68.894
C35: Subtotal | T35: Total General | U35: =SUM(U29:U34) -> 2.1829051e+08 | V35: =U35/$S$28 -> 2277.4608

Sheet PROYECCIÓN RESIDUOS Y LODOS
B2: COSTO PLANTA DE TRATAMIENTO DE AGUA RESIDUAL | F2: EJECUTADO PTAR AÑO 2026 BOGOTÁ
B3: Clasificación | C3: Detalle | D3: Unidad | E3: Generación | F3: Enero 2026 | G3: Febrero 2026 | H3: Marzo 2026 | I3: Abril 2026 | J3: Mayo 2026 | K3: Junio 2026 | L3: Julio 2026 | M3: Agosto 2026 | N3: Septiembre 2026 | O3: Octubre 2026 | P3: Noviembre 2026 | Q3: Diciembre 2026 | R3: Total general | S3: $/Kg | T3: $ Total | U3: $/M3
E4: Kg/m3 | F4: CAUDAL PLAN MAESTRO
F5: ='PLAN MAESTRO BOGOTA RECIRCU'!F5 -> 27229 | G5: ='PLAN MAESTRO BOGOTA RECIRCU'!H5 -> 26637.416 | H5: ='PLAN MAESTRO BOGOTA RECIRCU'!J5 -> 25371.211 | I5: ='PLAN MAESTRO BOGOTA RECIRCU'!L5 -> 28996.039 | J5: ='PLAN MAESTRO BOGOTA RECIRCU'!N5 -> 31421.6 | K5: ='PLAN MAESTRO BOGOTA RECIRCU'!P5 -> 34249.301 | L5: ='PLAN MAESTRO BOGOTA RECIRCU'!R5 -> 40509.091 | M5: ='PLAN MAESTRO BOGOTA RECIRCU'!T5 -> 40285.492 | N5: ='PLAN MAESTRO BOGOTA RECIRCU'!V5 -> 43482.437 | O5: ='PLAN MAESTRO BOGOTA RECIRCU'!X5 -> 40858.186 | P5: ='PLAN MAESTRO BOGOTA RECIRCU'!Z5 -> 26685.676 | Q5: ='PLAN MAESTRO BOGOTA RECIRCU'!AB5 -> 13422.465 | R5: =SUM(F5:Q5) -> 379147.92
B6: RESIDUOS Y LODOS | C6: DISPOSICIÓN DE RESIDUOS (MOTA, PIEDRA, RESIDUOS DE TELA) | D6: kg | E6: 2.8 | F6: 95500 | G6: 95200 | H6: =$E$6*H5 -> 71039.392 | I6: =$E$6*I5 -> 81188.909 | J6: =$E$6*J5 -> 87980.481 | K6: =$E$6*K5 -> 95898.042 | L6: =$E$6*L5 -> 113425.46 | M6: =$E$6*M5 -> 112799.38 | N6: =$E$6*N5 -> 121750.82 | O6: =$E$6*O5 -> 114402.92 | ... Q6: =$E$6*Q5 -> 37582.903 | R6: =+SUM(F6:Q6) -> 1101488.2 | S6: 90 | T6: =R6*S6 -> 99133938 | U6: =T6/$R$5 -> 261.46507
C7: LAVADO DE TANQUES DE 2, 15, 30 Y 60 M3 | D7: $ | E7: N/A | F7: 9985500 | G7: 9985500 | H7: 9985500 | I7: 9985500 | J7: 9985500 | K7: 9985500 | L7: 9985500 | M7: 9985500 | N7: 9985500 | O7: 9985500 | P7: 9985500 | Q7: 9985500 | R7: N/A | S7: N/A | T7: =SUM(F7:Q7) -> 119826000 | U7: =T7/$R$5 -> 316.04025
C8: DISPOSICIÓN DE LODOS DESHIDRATADOS GEM | D8: kg | E8: 3.4 | F8: =$E$8*F5 -> 92578.6 | G8: =$E$8*G5 -> 90567.214 | H8: =$E$8*H5 -> 86262.118 | I8: =$E$8*I5 -> 98586.533 | J8: =$E$8*J5 -> 106833.44 | K8: =$E$8*K5 -> 116447.62 | L8: =$E$8*L5 -> 137730.91 | M8: =$E$8*M5 -> 136970.67 | ... Q8: =$E$8*Q5 -> 45636.383 | R8: =+SUM(F8:Q8) -> 1289102.9 | S8: 50 | T8: =R8*S8 -> 64455146 | U8: =T8/$R$5 -> 170
C9: TRANSPORTE DE LODOS DESHIDRATADOS | D9: Kg/Viaje Amplirrol | E9: 5500 | F9: =F8/$E$9 -> 16.832473 | G9: =G8/$E$9 -> 16.466766 | H9: =H8/$E$9 -> 15.684022 | I9: =I8/$E$9 -> 17.924824 | J9: =J8/$E$9 -> 19.424262 | K9: =K8/$E$9 -> 21.172295 | L9: =L8/$E$9 -> 25.041984 | M9: =M8/$E$9 -> 24.903759 | ... Q9: =Q8/$E$9 -> 8.2975241 | R9: =+SUM(F9:Q9) -> 234.38235 | S9: 900000 | T9: =R9*S9 -> 2.1094411e+08 | U9: =T9/$R$5 -> 556.36364
C10: Subtotal | R10: PTAR FASE 2 | T10: =SUM(T6:T9) -> 4.943592e+08 | U10: =T10/$R$5 -> 1303.869
B12: COSTO PLANTA DE TRATAMIENTO DE AGUA DE POZO PROFUNDO | F12: EJECUTADO PTAP AÑO 2026 BOGOTÁ
B13: Clasificación | C13: Detalle | D13: Unidad | E13: Generación | F13: Enero 2026 | G13: Febrero 2026 | H13: Marzo 2026 | I13: Abril 2026 | J13: Mayo 2026 | K13: Junio 2026 | L13: Julio 2026 | M13: Agosto 2026 | N13: Septiembre 2026 | O13: Octubre 2026 | P13: Noviembre 2026 | Q13: Diciembre 2026 | R13: Total general | S13: $/Kg | T13: $ Total | U13: $/M3
E14: Kg/m3 | F14: CAUDAL PLAN MAESTRO
F15: ='PROYECCIÓN INSUMOS QUÍMICOS'!G28 -> 5662 | G15: ='PROYECCIÓN INSUMOS QUÍMICOS'!H28 -> 5537.9188 | H15: ='PROYECCIÓN INSUMOS QUÍMICOS'!I28 -> 5274.6748 | I15: ='PROYECCIÓN INSUMOS QUÍMICOS'!J28 -> 6028.2765 | J15: ='PROYECCIÓN INSUMOS QUÍMICOS'!K28 -> 9426.4801 | K15: ='PROYECCIÓN INSUMOS QUÍMICOS'!L28 -> 10274.79 | L15: ='PROYECCIÓN INSUMOS QUÍMICOS'!M28 -> 9722.182 | M15: ='PROYECCIÓN INSUMOS QUÍMICOS'!N28 -> 9668.5181 | ... Q15: ='PROYECCIÓN INSUMOS QUÍMICOS'!R28 -> 4697.8629 | R15: =SUM(F15:Q15) -> 95848.197
B16: RESIDUOS Y LODOS | C16: DISPOSICIÓN DE LODOS DESHIDRATADOS GEM PTAP | D16: kg | E16: 1.7 | F16: =$E$16*F15 -> 9625.4 | G16: =$E$16*G15 -> 9414.4619 | H16: =$E$16*H15 -> 8966.9472 | I16: =$E$16*I15 -> 10248.07 | J16: =$E$16*J15 -> 16025.016 | K16: =$E$16*K15 -> 17467.143 | L16: =$E$16*L15 -> 16527.709 | M16: =$E$16*M15 -> 16436.481 | ... Q16: =$E$16*Q15 -> 7986.3669 | R16: =+SUM(F16:Q16) -> 162941.93 | S16: 50 | T16: =R16*S16 -> 8147096.7 | U16: =T16/$R$15 -> 85
C17: TRANSPORTE DE LODOS DESHIDRATADOS | D17: Viajes | E17: 5500 | F17: =F16/$E$9 -> 1.7500727 | G17: =G16/$E$9 -> 1.7117204 | H17: =H16/$E$9 -> 1.630354 | I17: =I16/$E$9 -> 1.8632855 | J17: =J16/$E$9 -> 2.9136393 | K17: =K16/$E$9 -> 3.1758442 | L17: =L16/$E$9 -> 3.0050381 | M17: =M16/$E$9 -> 2.988451 | ... Q17: =Q16/$E$9 -> 1.4520667 | R17: =+SUM(F17:Q17) -> 29.625806 | S17: 900000 | T17: =R17*S17 -> 26663226 | U17: =T17/$R$15 -> 278.18182
C18: Subtotal | R18: PTAP | T18: =SUM(T16:T17) -> 34810322 | U18: =T18/$R$15 -> 363.18182

Sheet PROYECCIÓN CONSUMIBLES PTAR
B2: COSTO PLANTA DE TRATAMIENTO DE AGUA RESIDUAL | F2: EJECUTADO PTAR AÑO 2026 BOGOTÁ
B3: Clasificación | C3: Detalle | D3: Unidad | E3: cantidad | F3: Enero 2026 | G3: Febrero 2026 | H3: Marzo 2026 | I3: Abril 2026 | J3: Mayo 2026 | K3: Junio 2026 | L3: Julio 2026 | M3: Agosto 2026 | N3: Septiembre 2026 | O3: Octubre 2026 | P3: Noviembre 2026 | Q3: Diciembre 2026 | R3: Total general | S3: $/Und | T3: $ Total | U3: $/M3
F4: CAUDAL PLAN MAESTRO
F5: ='PLAN MAESTRO BOGOTA RECIRCU'!F5 -> 27229 | G5: ='PLAN MAESTRO BOGOTA RECIRCU'!H5 -> 26637.416 | H5: ='PLAN MAESTRO BOGOTA RECIRCU'!J5 -> 25371.211 | I5: ='PLAN MAESTRO BOGOTA RECIRCU'!L5 -> 28996.039 | J5: ='PLAN MAESTRO BOGOTA RECIRCU'!N5 -> 31421.6 | K5: ='PLAN MAESTRO BOGOTA RECIRCU'!P5 -> 34249.301 | L5: ='PLAN MAESTRO BOGOTA RECIRCU'!R5 -> 40509.091 | M5: ='PLAN MAESTRO BOGOTA RECIRCU'!T5 -> 40285.492 | N5: ='PLAN MAESTRO BOGOTA RECIRCU'!V5 -> 43482.437 | O5: ='PLAN MAESTRO BOGOTA RECIRCU'!X5 -> 40858.186 | P5: ='PLAN MAESTRO BOGOTA RECIRCU'!Z5 -> 26685.676 | Q5: ='PLAN MAESTRO BOGOTA RECIRCU'!AB5 -> 13422.465 | R5: =SUM(F5:Q5) -> 379147.92
B6: CONSUMIBLES | C6: MEMBRANAS DE RO 1 | D6: Und | E6: 72 | F6: N/A | G6: N/A | H6: N/A | I6: N/A | J6: N/A | K6: N/A | L6: N/A | M6: N/A | N6: N/A | O6: N/A | P6: N/A | Q6: N/A | R6: N/A | S6: 2359000 | T6: =(E6*S6)/3 -> 56616000 | U6: =T6/R5 -> 149.32431
C7: CARTUCHOS 5 MICRAS | D7: Und | E7: 0.018 | F7: =$E$7*F5 -> 490.122 | G7: =$E$7*G5 -> 479.47349 | H7: =$E$7*H5 -> 456.6818 | I7: =$E$7*I5 -> 521.9287 | J7: =$E$7*J5 -> 565.58881 | K7: =$E$7*K5 -> 616.48741 | L7: =$E$7*L5 -> 729.16365 | M7: =$E$7*M5 -> 725.13886 | ... Q7: =$E$7*Q5 -> 241.60438 | R7: =SUM(F7:Q7) -> 6824.6625 | S7: 20900 | T7: =R7*S7 -> 1.4263545e+08 | U7: =T7/R5 -> 376.2
C8: RESINA CATIÓNICA | D8: Global | E8: N/A | F8: N/A | G8: N/A | H8: N/A | I8: N/A | J8: N/A | K8: N/A | L8: N/A | M8: N/A | N8: N/A | O8: N/A | P8: N/A | Q8: N/A | R8: 132492000 | S8: =R8/2 -> 66246000 | T8: =S8 -> 66246000 | U8: =T8/R5 -> 174.72337
C9: REACTIVOS LAB HACH | D9: Global | E9: 1 | F9: N/A | G9: N/A | H9: N/A | I9: N/A | J9: N/A | K9: N/A | L9: N/A | M9: N/A | N9: N/A | O9: N/A | P9: N/A | Q9: N/A | R9: N/A | S9: N/A | T9: =52403589*2 -> 104807178 | U9: =T9/$R$5 -> 276.42821
C10: CONSUMIBLES LAB (Buretas, erlenmeyer, vasos precipitación) | D10: Global | E10: 1 | F10: N/A | G10: N/A | H10: N/A | I10: N/A | J10: N/A | K10: N/A | L10: N/A | M10: N/A | N10: N/A | O10: N/A | P10: N/A | Q10: N/A | R10: N/A | S10: N/A | T10: 9813068 | U10: =T10/$R$5 -> 25.881899
C11: Subtotal | S11: Total General | T11: =SUM(T6:T10) -> 3.8011769e+08 | U11: =T11/$R$5 -> 1002.5578
R12: PTAR FASE 2 (GEM + MBR) | T12: =SUM(T9:T10)*70% -> 80234172 | U12: =T12/R5 -> 211.61707
R13: ÓSMOSIS INVERSA | T13: =(SUM(T9:T10)*30%)+T6+T7+T8 -> 2.9988352e+08 | U13: =T13/R5 -> 790.94071
B15: COSTO PLANTA DE TRATAMIENTO DE AGUA DE POZO PROFUNDO | F15: EJECUTADO PTAP AÑO 2026 BOGOTÁ
B16: Clasificación | C16: Detalle | D16: Unidad | E16: Dosificación | F16: Enero 2026 | G16: Febrero 2026 | H16: Marzo 2026 | I16: Abril 2026 | J16: Mayo 2026 | K16: Junio 2026 | L16: Julio 2026 | M16: Agosto 2026 | N16: Septiembre 2026 | O16: Octubre 2026 | P16: Noviembre 2026 | Q16: Diciembre 2026 | R16: Total general | S16: $/Und | T16: $ Total | U16: $/M3
E17: Und/m3 | F17: CAUDAL PLAN MAESTRO
F18: ='PROYECCIÓN RESIDUOS Y LODOS'!F15 -> 5662 | G18: ='PROYECCIÓN RESIDUOS Y LODOS'!G15 -> 5537.9188 | H18: ='PROYECCIÓN RESIDUOS Y LODOS'!H15 -> 5274.6748 | I18: ='PROYECCIÓN RESIDUOS Y LODOS'!I15 -> 6028.2765 | J18: ='PROYECCIÓN RESIDUOS Y LODOS'!J15 -> 9426.4801 | K18: ='PROYECCIÓN RESIDUOS Y LODOS'!K15 -> 10274.79 | L18: ='PROYECCIÓN RESIDUOS Y LODOS'!L15 -> 9722.182 | M18: ='PROYECCIÓN RESIDUOS Y LODOS'!M15 -> 9668.5181 | ... Q18: ='PROYECCIÓN RESIDUOS Y LODOS'!Q15 -> 4697.8629 | R18: =SUM(F18:Q18) -> 95848.197
B20: CONSUMIBLES | C20: REACTIVOS LAB HACH | D20: Global | E20: 1 | F20: N/A | G20: N/A | H20: N/A | I20: N/A | J20: N/A | K20: N/A | L20: N/A | M20: N/A | N20: N/A | O20: N/A | P20: N/A | Q20: N/A | R20: N/A | S20: N/A | T20: =T9*5% -> 5240358.9 | U20: =T20/$R$18 -> 54.673526
C21: MEMBRANAS DUPONT UF | D21: Global | E21: 1 | F21: N/A | G21: N/A | H21: N/A | I21: N/A | J21: N/A | K21: N/A | L21: N/A | M21: N/A | N21: N/A | O21: N/A | P21: N/A | Q21: N/A | R21: 186000000 | S21: N/A | T21: =186000000/5 -> 37200000 | U21: =T21/R18 -> 388.11372
C22: FILTROS MANGA | D22: Und | E22: 0.005 | F22: =F18*$E$22 -> 28.31 | G22: =G18*$E$22 -> 27.689594 | H22: =H18*$E$22 -> 26.373374 | I22: =I18*$E$22 -> 30.141383 | J22: =J18*$E$22 -> 47.132401 | K22: =K18*$E$22 -> 51.373951 | L22: =L18*$E$22 -> 48.61091 | M22: =M18*$E$22 -> 48.34259 | ... Q22: =Q18*$E$22 -> 23.489315 | R22: =SUM(F22:Q22) -> 479.24098 | S22: 28300 | T22: =R22*S22 -> 13562520 | U22: =T22/$R$18 -> 141.5
C23: Subtotal | S23: Total General | T23: =SUM(T20:T22) -> 56002879 | U23: =T23/$R$18 -> 584.28724

Sheet PROYECCIÓN CALIBR-MANTE PTAR
B2: COSTO PLANTA DE TRATAMIENTO DE AGUA RESIDUAL | F2: EJECUTADO PTAR AÑO 2026 BOGOTÁ
B3: Clasificación | C3: Detalle | D3: Unidad | E3: cantidad | F3: Enero 2026 | G3: Febrero 2026 | H3: Marzo 2026 | I3: Abril 2026 | J3: Mayo 2026 | K3: Junio 2026 | L3: Julio 2026 | M3: Agosto 2026 | N3: Septiembre 2026 | O3: Octubre 2026 | P3: Noviembre 2026 | Q3: Diciembre 2026 | R3: Total general | S3: $/Año | T3: $ Total | U3: $/M3
F4: CAUDAL PLAN MAESTRO
F5: ='PLAN MAESTRO BOGOTA RECIRCU'!F5 -> 27229 | G5: ='PLAN MAESTRO BOGOTA RECIRCU'!H5 -> 26637.416 | H5: ='PLAN MAESTRO BOGOTA RECIRCU'!J5 -> 25371.211 | I5: ='PLAN MAESTRO BOGOTA RECIRCU'!L5 -> 28996.039 | J5: ='PLAN MAESTRO BOGOTA RECIRCU'!N5 -> 31421.6 | K5: ='PLAN MAESTRO BOGOTA RECIRCU'!P5 -> 34249.301 | L5: ='PLAN MAESTRO BOGOTA RECIRCU'!R5 -> 40509.091 | M5: ='PLAN MAESTRO BOGOTA RECIRCU'!T5 -> 40285.492 | N5: ='PLAN MAESTRO BOGOTA RECIRCU'!V5 -> 43482.437 | O5: ='PLAN MAESTRO BOGOTA RECIRCU'!X5 -> 40858.186 | P5: ='PLAN MAESTRO BOGOTA RECIRCU'!Z5 -> 26685.676 | Q5: ='PLAN MAESTRO BOGOTA RECIRCU'!AB5 -> 13422.465 | R5: =SUM(F5:Q5) -> 379147.92
B6: MANTENIMIENTO | C6: CALIBRACIONES EQUIPO LAB | D6: Global | E6: 1 | F6: 1 | G6: 1 | H6: 1 | I6: 1 | J6: 1 | K6: 1 | L6: 1 | M6: 1 | N6: 1 | O6: 1 | P6: 1 | Q6: 1 | R6: N/A | S6: 19091400 | T6: =E6*S6 -> 19091400 | U6: =T6/$R$5 -> 50.353435
C7: MANTENIMIENTOS (Herramienta, materiales de mantenimiento) | D7: Global | E7: 1 | F7: 1 | G7: 1 | H7: 1 | I7: 1 | J7: 1 | K7: 1 | L7: 1 | M7: 1 | N7: 1 | O7: 1 | P7: 1 | Q7: 1 | R7: N/A | S7: =207739008 -> 207739008 | T7: =S7 -> 207739008 | U7: =T7/$R$5 -> 547.91019
C8: Suministro e instalación de bombas dosificadoras OSMOSIS INVERSA | D8: Global | E8: 1 | F8: 1 | G8: 1 | H8: 1 | I8: 1 | J8: 1 | K8: 1 | L8: 1 | M8: 1 | N8: 1 | O8: 1 | P8: 1 | Q8: 1 | R8: 108103011 | S8: =R8/2 -> 54051506 | T8: =S8 -> 54051506 | U8: =T8/$R$5 -> 142.56047
C9: Independizar CIP de la ósmosis inversa | D9: Global | E9: 1 | F9: 1 | G9: 1 | H9: 1 | I9: 1 | J9: 1 | K9: 1 | L9: 1 | M9: 1 | N9: 1 | O9: 1 | P9: 1 | Q9: 1 | R9: 27700656 | S9: =R9/15 -> 1846710.4 | T9: =S9 -> 1846710.4 | U9: =T9/$R$5 -> 4.8706859
C10: Programación y automatización de ósmosis inversa | D10: Global | E10: 1 | F10: 1 | G10: 1 | H10: 1 | I10: 1 | J10: 1 | K10: 1 | L10: 1 | M10: 1 | N10: 1 | O10: 1 | P10: 1 | Q10: 1 | R10: 140100000 | S10: =R10/3 -> 46700000 | T10: =S10 -> 46700000 | U10: =T10/$R$5 -> 123.17093
C11: Subtotal | S11: Total General | T11: =SUM(T6:T10) -> 3.2942862e+08 | U11: =T11/$R$5 -> 868.86571
S12: PTAR FASE 2 (GEM + MBR) | T12: =(T6+T7)*80% -> 1.8146433e+08 | U12: =T12/R5 -> 478.6109
S13: ÓSMOSIS INVERSA | T13: =(T10+T9+T8)+((T6+T7)*20%) -> 1.479643e+08 | U13: =T13/R5 -> 390.25481
B15: COSTO PLANTA DE TRATAMIENTO DE AGUA DE POZO PROFUNDO | F15: EJECUTADO PTAP AÑO 2026 BOGOTÁ
B16: Clasificación | C16: Detalle | D16: Unidad | E16: Dosificación | F16: Enero 2026 | G16: Febrero 2026 | H16: Marzo 2026 | I16: Abril 2026 | J16: Mayo 2026 | K16: Junio 2026 | L16: Julio 2026 | M16: Agosto 2026 | N16: Septiembre 2026 | O16: Octubre 2026 | P16: Noviembre 2026 | Q16: Diciembre 2026 | R16: Total general | S16: $/Kg | T16: $ Total | U16: $/M3
E17: Kg/m3 | F17: CAUDAL PLAN MAESTRO
F18: ='PROYECCIÓN CONSUMIBLES PTAR'!F18 -> 5662 | G18: ='PROYECCIÓN CONSUMIBLES PTAR'!G18 -> 5537.9188 | H18: ='PROYECCIÓN CONSUMIBLES PTAR'!H18 -> 5274.6748 | I18: ='PROYECCIÓN CONSUMIBLES PTAR'!I18 -> 6028.2765 | J18: ='PROYECCIÓN CONSUMIBLES PTAR'!J18 -> 9426.4801 | K18: ='PROYECCIÓN CONSUMIBLES PTAR'!K18 -> 10274.79 | L18: ='PROYECCIÓN CONSUMIBLES PTAR'!L18 -> 9722.182 | M18: ='PROYECCIÓN CONSUMIBLES PTAR'!M18 -> 9668.5181 | ... Q18: ='PROYECCIÓN CONSUMIBLES PTAR'!Q18 -> 4697.8629 | R18: =SUM(F18:Q18) -> 95848.197
B19: MANTENIMIENTO | C19: MANTENIMIENTO POZO | D19: Global | E19: 1 | F19: N/A | G19: N/A | H19: N/A | I19: N/A | J19: N/A | K19: N/A | L19: N/A | M19: N/A | N19: N/A | O19: N/A | P19: N/A | Q19: N/A | R19: N/A | S19: N/A | T19: 15140000 | U19: =T19/R18 -> 157.95811
C20: MANTENIMIENTOS (Herramienta, materiales de mantenimiento) | D20: Global | E20: 1 | F20: 1 | G20: 1 | H20: 1 | I20: 1 | J20: 1 | K20: 1 | L20: 1 | M20: 1 | N20: 1 | O20: 1 | P20: 1 | Q20: 1 | R20: N/A | S20: =S7*5% -> 10386950 | T20: =E20*S20 -> 10386950 | U20: =T20/$R$5 -> 27.39551
