Workbook
Name SegmentaciónDeDatos_FECHA: #N/A
Name SegmentaciónDeDatos_FECHA1: #N/A
Name SegmentaciónDeDatos_FECHA2: #N/A

Sheet INVENTARIO Y CONSUMO GEM  
A1: FECHA | B1: DIA | C1: ANALISIS TURNO | D1: # TURNO | E1: DILIGENCIAR BITACORA | F1: FINAL ACIDO (L) | G1: FINAL COAGULANTE (L) | H1: FINAL DECOLORANTE (L) | I1: FINAL POL ANIONICO (KG) | J1: FINAL POL CATIONICO (KG) | K1: Lectura Horometro INICIAL (06:00) | L1: CAUDAL TOTAL TRATADO GEM | M1: CAUDAL DE TRATAMIENTO | N1: CONSUMO LITROS ACIDO (L) | O1: CONSUMO LITROS COAGULANTE (L) | P1: CONSUMO LITROS DECOLORANTE (L) | Q1: CONSUMO POL ANIONICO (KG) | R1: CONSUMO POL CATIONICO (KG) | S1: KG ACIDO | T1: KG COAGULANTE | U1: KG DECOLORANTE | V1: KG POL ANIONICO | W1: KG POL CATIONICO | X1: PPM ACIDO | Y1: PPM COAGULANTE | Z1: PPM DECOLORANTE | AA1: PPM POL ANIONICO | AB1: PPM POL CATIONICO | AC1: DENSIDAD ACIDO | AD1: DENSIDAD COAGULANTE | AE1: DENSIDAD DECOLORANTE | AF1: DENSIDAD ANIONICO | AG1: DENSIDAD CATIONICO | AH1: PRECIO (KG) ACIDO | AI1: PRECIO (KG) COAGULANTE | AJ1: PRECIO (KG) DECOLORANTE | AK1: PRECIO (KG) ANIONICO | AL1: PRECIO (KG) CATIONICO | AM1: COSTO OPERATIVO ACIDO | AN1: COSTO OPERATIVO COAGULANTE | AO1: COSTO OPERATIVO DECOLORANTE | AP1: COSTO OPERATIVO ANIONICO | AQ1: COSTO OPERATIVO CATIONICO | AR1: COSTO QUIMICA | AS1: LIMITE INDICADOR M3 | AT1: $ m3
A2: 46082 | B2: =DAY(Tabla1[[#This Row],[FECHA]]) -> 1 | C2: 1 (NOCHE) | D2: 1 | E2: FINAL TURNO 3 | F2: 480 | G2: 1700 | H2: 2090 | I2: 125 | J2: 175 | K2: 17228 | L2: =+(K3-Tabla1[[#This Row],[Lectura Horometro INICIAL (06:00)]])*Tabla1[[#This Row],[CAUDAL DE TRATAMIENTO]] -> 0 | M2: 80 | N2: =F2-F3 -> 0 | O2: =G2-G3 -> 0 | P2: =H2-H3 -> 0 | Q2: =I2-I3 -> 0 | R2: 0 | S2: =(N2*$AC$2) -> 0 | T2: =(O2*$AD$2) -> 0 | U2: =(P2*$AE$2) -> 0 | V2: =Tabla1[[#This Row],[CONSUMO POL ANIONICO (KG)]] -> 0 | W2: =Tabla1[[#This Row],[CONSUMO POL CATIONICO (KG)]] -> 0 | X2: =(S2*1000)/L2 -> #DIV/0! | Y2: =(T2*1000)/L2 -> #DIV/0! | Z2: =(U2*1000)/L2 -> #DIV/0! | AA2: =(V2*1000)/L2 -> #DIV/0! | AB2: =(W2*1000)/L2 -> #DIV/0! | AC2: 1.3 | AD2: 1.325 | AE2: 1.25 | AF2: 2500 | AG2: 2500 | AH2: 830 | AI2: 2818 | AJ2: 6295 | AK2: 19050 | AL2: 22050 | AM2: =S2*AH2 -> 0 | AN2: =T2*AI2 -> 0 | AO2: =U2*AJ2 -> 0 | AP2: =V2*AK2 -> 0 | AQ2: =W2*AL2 -> 0 | AR2: =SUM(Tabla1[[#This Row],[COSTO OPERATIVO ACIDO]:[COSTO OPERATIVO CATIONICO]]) -> 0 | AS2: 3599 | AT2: =AR2/L2 -> #DIV/0!
A3: =A2 -> 46082 | B3: =DAY(Tabla1[[#This Row],[FECHA]]) -> 1 | C3: 2 (MAÑANA) | D3: 2 | E3: FINAL TURNO 1 | F3: 480 | G3: 1700 | H3: 2090 | I3: 125 | J3: 175 | K3: 17228 | L3: =+(K4-Tabla1[[#This Row],[Lectura Horometro INICIAL (06:00)]])*Tabla1[[#This Row],[CAUDAL DE TRATAMIENTO]] -> 0 | M3: 80 | N3: =F3-F4 -> 0 | O3: =G3-G4 -> 0 | P3: =H3-H4 -> 0 | Q3: =I3-I4 -> 0 | R3: 0 | S3: =(N3*$AC$2) -> 0 | T3: =(O3*$AD$2) -> 0 | U3: =(P3*$AE$2) -> 0 | V3: =Tabla1[[#This Row],[CONSUMO POL ANIONICO (KG)]] -> 0 | W3: =Tabla1[[#This Row],[CONSUMO POL CATIONICO (KG)]] -> 0 | X3: =(S3*1000)/L3 -> #DIV/0! | Y3: =(T3*1000)/L3 -> #DIV/0! | Z3: =(U3*1000)/L3 -> #DIV/0! | AA3: =(V3*1000)/L3 -> #DIV/0! | AB3: =(W3*1000)/L3 -> #DIV/0! | AC3: 1.3 | AD3: 1.325 | AE3: 1.25 | AF3: 2500 | AG3: 2500 | AH3: 830 | AI3: 2818 | AJ3: 6295 | AK3: 19050 | AL3: 22050 | AM3: =S3*AH3 -> 0 | AN3: =T3*AI3 -> 0 | AO3: =U3*AJ3 -> 0 | AP3: =V3*AK3 -> 0 | AQ3: =W3*AL3 -> 0 | AR3: =SUM(Tabla1[[#This Row],[COSTO OPERATIVO ACIDO]:[COSTO OPERATIVO CATIONICO]]) -> 0 | AS3: 3599 | AT3: =AR3/L3 -> #DIV/0!
A4: =A3 -> 46082 | B4: =DAY(Tabla1[[#This Row],[FECHA]]) -> 1 | C4: 3(TARDE) | D4: 3 | E4: FINAL TURNO 2 | F4: 480 | G4: 1700 | H4: 2090 | I4: 125 | J4: 175 | K4: 17228 | L4: =+(K5-Tabla1[[#This Row],[Lectura Horometro INICIAL (06:00)]])*Tabla1[[#This Row],[CAUDAL DE TRATAMIENTO]] -> 240 | M4: 80 | N4: =F4-F5 -> 0 | O4: =G4-G5 -> 0 | P4: =H4-H5 -> 0 | Q4: =I4-I5 -> 0 | R4: 0 | S4: =(N4*$AC$2) -> 0 | T4: =(O4*$AD$2) -> 0 | U4: =(P4*$AE$2) -> 0 | V4: =Tabla1[[#This Row],[CONSUMO POL ANIONICO (KG)]] -> 0 | W4: =Tabla1[[#This Row],[CONSUMO POL CATIONICO (KG)]] -> 0 | X4: =(S4*1000)/L4 -> 0 | Y4: =(T4*1000)/L4 -> 0 | Z4: =(U4*1000)/L4 -> 0 | AA4: =(V4*1000)/L4 -> 0 | AB4: =(W4*1000)/L4 -> 0 | AC4: 1.3 | AD4: 1.325 | AE4: 1.25 | AF4: 2500 | AG4: 2500 | AH4: 830 | AI4: 2818 | AJ4: 6295 | AK4: 19050 | AL4: 22050 | AM4: =S4*AH4 -> 0 | AN4: =T4*AI4 -> 0 | AO4: =U4*AJ4 -> 0 | AP4: =V4*AK4 -> 0 | AQ4: =W4*AL4 -> 0 | AR4: =SUM(Tabla1[[#This Row],[COSTO OPERATIVO ACIDO]:[COSTO OPERATIVO CATIONICO]]) -> 0 | AS4: 3599 | AT4: =AR4/L4 -> 0
A5: 46083 | B5: =DAY(Tabla1[[#This Row],[FECHA]]) -> 2 | C5: 2 (NOCHE) | D5: 4 | E5: FINAL TURNO 3 | F5: 480 | G5: 1700 | H5: 2090 | I5: 125 | J5: 165 | K5: 17231 | L5: =+(K6-Tabla1[[#This Row],[Lectura Horometro INICIAL (06:00)]])*Tabla1[[#This Row],[CAUDAL DE TRATAMIENTO]] -> 480 | M5: 80 | N5: =F5-F6 -> 480 | O5: =G5-G6+2000 -> 50 | P5: =H5-H6 -> 290 | Q5: =I5-I6 -> 5 | R5: =J5-J6 -> 5 | S5: =(N5*$AC$2) -> 624 | T5: =(O5*$AD$2) -> 66.25 | U5: =(P5*$AE$2) -> 362.5 | V5: =Tabla1[[#This Row],[CONSUMO POL ANIONICO (KG)]] -> 5 | W5: =Tabla1[[#This Row],[CONSUMO POL CATIONICO (KG)]] -> 5 | X5: =(S5*1000)/L5 -> 1300 | Y5: =(T5*1000)/L5 -> 138.02083 | Z5: =(U5*1000)/L5 -> 755.20833 | AA5: =(V5*1000)/L5 -> 10.416667 | AB5: =(W5*1000)/L5 -> 10.416667 | AC5: 1.3 | AD5: 1.325 | AE5: 1.25 | AF5: 2500 | AG5: 2500 | AH5: 830 | AI5: 2818 | AJ5: 6295 | AK5: 19050 | AL5: 22050 | AM5: =S5*AH5 -> 517920 | AN5: =T5*AI5 -> 186692.5 | AO5: =U5*AJ5 -> 2281937.5 | AP5: =V5*AK5 -> 95250 | AQ5: =W5*AL5 -> 110250 | AR5: =SUM(Tabla1[[#This Row],[COSTO OPERATIVO ACIDO]:[COSTO OPERATIVO CATIONICO]]) -> 3192050 | AS5: 3599 | AT5: =AR5/L5 -> 6650.1042
A6: =A5 -> 46083 | B6: =DAY(Tabla1[[#This Row],[FECHA]]) -> 2 | C6: 3 (MAÑANA) | D6: 5 | E6: FINAL TURNO 1 | F6: 0 | G6: 3650 | H6: 1800 | I6: 120 | J6: 160 | K6: 17237 | L6: =+(K7-Tabla1[[#This Row],[Lectura Horometro INICIAL (06:00)]])*Tabla1[[#This Row],[CAUDAL DE TRATAMIENTO]] -> 560 | M6: 80 | N6: =F6-F7 -> 0 | O6: =G6-G7 -> 210 | P6: =H6-H7 -> 90 | Q6: =I6-I7 -> 5 | R6: =J6-J7 -> 5 | S6: =(N6*$AC$2) -> 0 | T6: =(O6*$AD$2) -> 278.25 | U6: =(P6*$AE$2) -> 112.5 | V6: =Tabla1[[#This Row],[CONSUMO POL ANIONICO (KG)]] -> 5 | W6: =Tabla1[[#This Row],[CONSUMO POL CATIONICO (KG)]] -> 5 | X6: =(S6*1000)/L6 -> 0 | Y6: =(T6*1000)/L6 -> 496.875 | Z6: =(U6*1000)/L6 -> 200.89286 | AA6: =(V6*1000)/L6 -> 8.9285714 | AB6: =(W6*1000)/L6 -> 8.9285714 | AC6: 1.3 | AD6: 1.325 | AE6: 1.25 | AF6: 2500 | AG6: 2500 | AH6: 830 | AI6: 2818 | AJ6: 6295 | AK6: 19050 | AL6: 22050 | AM6: =S6*AH6 -> 0 | AN6: =T6*AI6 -> 784108.5 | AO6: =U6*AJ6 -> 708187.5 | AP6: =V6*AK6 -> 95250 | AQ6: =W6*AL6 -> 110250 | AR6: =SUM(Tabla1[[#This Row],[COSTO OPERATIVO ACIDO]:[COSTO OPERATIVO CATIONICO]]) -> 1697796 | AS6: 3599 | AT6: =AR6/L6 -> 3031.7786
A7: =A6 -> 46083 | B7: =DAY(Tabla1[[#This Row],[FECHA]]) -> 2 | C7: 3(TARDE) | D7: 6 | E7: FINAL TURNO 2 | F7: 0 | G7: 3440 | H7: 1710 | I7: 115 | J7: 155 | K7: 17244 | L7: =+(K8-Tabla1[[#This Row],[Lectura Horometro INICIAL (06:00)]])*Tabla1[[#This Row],[CAUDAL DE TRATAMIENTO]] -> 560 | M7: 80 | N7: =F7-F8 -> 0 | O7: =G7-G8 -> 190 | P7: =H7-H8 -> 60 | Q7: =I7-I8 -> 0 | R7: =J7-J8 -> 5 | S7: =(N7*$AC$2) -> 0 | T7: =(O7*$AD$2) -> 251.75 | U7: =(P7*$AE$2) -> 75 | V7: =Tabla1[[#This Row],[CONSUMO POL ANIONICO (KG)]] -> 0 | W7: =Tabla1[[#This Row],[CONSUMO POL CATIONICO (KG)]] -> 5 | X7: =(S7*1000)/L7 -> 0 | Y7: =(T7*1000)/L7 -> 449.55357 | Z7: =(U7*1000)/L7 -> 133.92857 | AA7: =(V7*1000)/L7 -> 0 | AB7: =(W7*1000)/L7 -> 8.9285714 | AC7: 1.3 | AD7: 1.325 | AE7: 1.25 | AF7: 2500 | AG7: 2500 | AH7: 830 | AI7: 2818 | AJ7: 6295 | AK7: 19050 | AL7: 22050 | AM7: =S7*AH7 -> 0 | AN7: =T7*AI7 -> 709431.5 | AO7: =U7*AJ7 -> 472125 | AP7: =V7*AK7 -> 0 | AQ7: =W7*AL7 -> 110250 | AR7: =SUM(Tabla1[[#This Row],[COSTO OPERATIVO ACIDO]:[COSTO OPERATIVO CATIONICO]]) -> 1291806.5 | AS7: 3599 | AT7: =AR7/L7 -> 2306.7973
A8: 46084 | B8: =DAY(Tabla1[[#This Row],[FECHA]]) -> 3 | C8: 3 (NOCHE) | D8: 7 | E8: FINAL TURNO 3 | F8: 0 | G8: 3250 | H8: 1650 | I8: 115 | J8: 150 | K8: 17251 | L8: =+(K9-Tabla1[[#This Row],[Lectura Horometro INICIAL (06:00)]])*Tabla1[[#This Row],[CAUDAL DE TRATAMIENTO]] -> 400 | M8: 80 | N8: =F8-F9 -> 0 | O8: =G8-G9-150 -> 100 | P8: =H8-H9 -> 40 | Q8: =I8-I9 -> 5 | R8: =J8-J9 -> 5 | S8: =(N8*$AC$2) -> 0 | T8: =(O8*$AD$2) -> 132.5 | U8: =(P8*$AE$2) -> 50 | V8: =Tabla1[[#This Row],[CONSUMO POL ANIONICO (KG)]] -> 5 | W8: =Tabla1[[#This Row],[CONSUMO POL CATIONICO (KG)]] -> 5 | X8: =(S8*1000)/L8 -> 0 | Y8: =(T8*1000)/L8 -> 331.25 | Z8: =(U8*1000)/L8 -> 125 | AA8: =(V8*1000)/L8 -> 12.5 | AB8: =(W8*1000)/L8 -> 12.5 | AC8: 1.3 | AD8: 1.325 | AE8: 1.25 | AF8: 2500 | AG8: 2500 | AH8: 830 | AI8: 2818 | AJ8: 6295 | AK8: 19050 | AL8: 22050 | AM8: =S8*AH8 -> 0 | AN8: =T8*AI8 -> 373385 | AO8: =U8*AJ8 -> 314750 | AP8: =V8*AK8 -> 95250 | AQ8: =W8*AL8 -> 110250 | AR8: =SUM(Tabla1[[#This Row],[COSTO OPERATIVO ACIDO]:[COSTO OPERATIVO CATIONICO]]) -> 893635 | AS8: 3599 | AT8: =AR8/L8 -> 2234.0875
A9: =A8 -> 46084 | B9: =DAY(Tabla1[[#This Row],[FECHA]]) -> 3 | C9: 4 (MAÑANA) | D9: 8 | E9: FINAL TURNO 1 | F9: 0 | G9: 3000 | H9: 1610 | I9: 110 | J9: 145 | K9: 17256 | L9: =+(K10-Tabla1[[#This Row],[Lectura Horometro INICIAL (06:00)]])*Tabla1[[#This Row],[CAUDAL DE TRATAMIENTO]] -> 400 | M9: 80 | N9: =F9-F10 -> 0 | O9: =G9-G10 -> 150 | P9: =H9-H10 -> 60 | Q9: =I9-I10 -> 0 | R9: =J9-J10 -> 5 | S9: =(N9*$AC$2) -> 0 | T9: =(O9*$AD$2) -> 198.75 | U9: =(P9*$AE$2) -> 75 | V9: =Tabla1[[#This Row],[CONSUMO POL ANIONICO (KG)]] -> 0 | W9: =Tabla1[[#This Row],[CONSUMO POL CATIONICO (KG)]] -> 5 | X9: =(S9*1000)/L9 -> 0 | Y9: =(T9*1000)/L9 -> 496.875 | Z9: =(U9*1000)/L9 -> 187.5 | AA9: =(V9*1000)/L9 -> 0 | AB9: =(W9*1000)/L9 -> 12.5 | AC9: 1.3 | AD9: 1.325 | AE9: 1.25 | AF9: 2500 | AG9: 2500 | AH9: 830 | AI9: 2818 | AJ9: 6295 | AK9: 19050 | AL9: 22050 | AM9: =S9*AH9 -> 0 | AN9: =T9*AI9 -> 560077.5 | AO9: =U9*AJ9 -> 472125 | AP9: =V9*AK9 -> 0 | AQ9: =W9*AL9 -> 110250 | AR9: =SUM(Tabla1[[#This Row],[COSTO OPERATIVO ACIDO]:[COSTO OPERATIVO CATIONICO]]) -> 1142452.5 | AS9: 3599 | AT9: =AR9/L9 -> 2856.1312
A10: =A9 -> 46084 | B10: =DAY(Tabla1[[#This Row],[FECHA]]) -> 3 | C10: 3(TARDE) | D10: 9 | E10: FINAL TURNO 2 | F10: 0 | G10: 2850 | H10: 1550 | I10: 110 | J10: 140 | K10: 17261 | L10: =+(K11-Tabla1[[#This Row],[Lectura Horometro INICIAL (06:00)]])*Tabla1[[#This Row],[CAUDAL DE TRATAMIENTO]] -> 640 | M10: 80 | N10: =F10-F11+2000 -> 0 | O10: =G10-G11+2000 -> 100 | P10: =H10-H11+1000 -> 50 | Q10: 0 | R10: 0 | S10: =(N10*$AC$2) -> 0 | T10: =(O10*$AD$2) -> 132.5 | U10: =(P10*$AE$2) -> 62.5 | V10: =Tabla1[[#This Row],[CONSUMO POL ANIONICO (KG)]] -> 0 | W10: =Tabla1[[#This Row],[CONSUMO POL CATIONICO (KG)]] -> 0 | X10: =(S10*1000)/L10 -> 0 | Y10: =(T10*1000)/L10 -> 207.03125 | Z10: =(U10*1000)/L10 -> 97.65625 | AA10: =(V10*1000)/L10 -> 0 | AB10: =(W10*1000)/L10 -> 0 | AC10: 1.3 | AD10: 1.325 | AE10: 1.25 | AF10: 2500 | AG10: 2500 | AH10: 830 | AI10: 2818 | AJ10: 6295 | AK10: 19050 | AL10: 22050 | AM10: =S10*AH10 -> 0 | AN10: =T10*AI10 -> 373385 | AO10: =U10*AJ10 -> 393437.5 | AP10: =V10*AK10 -> 0 | AQ10: =W10*AL10 -> 0 | AR10: =SUM(Tabla1[[#This Row],[COSTO OPERATIVO ACIDO]:[COSTO OPERATIVO CATIONICO]]) -> 766822.5 | AS10: 3599 | AT10: =AR10/L10 -> 1198.1602
A11: 46085 | B11: =DAY(Tabla1[[#This Row],[FECHA]]) -> 4 | C11: 4 (NOCHE) | D11: 10 | E11: FINAL TURNO 3 | F11: 2000 | G11: 4750 | H11: 2500 | I11: 105 | J11: 135 | K11: 17269 | L11: =+(K12-Tabla1[[#This Row],[Lectura Horometro INICIAL (06:00)]])*Tabla1[[#This Row],[CAUDAL DE TRATAMIENTO]] -> 400 | M11: 80 | N11: =F11-F12 -> 130 | O11: =G11-G12-150 -> 120 | P11: =H11-H12 -> 70 | Q11: 0 | R11: 0 | S11: =(N11*$AC$2) -> 169 | T11: =(O11*$AD$2) -> 159 | U11: =(P11*$AE$2) -> 87.5 | V11: =Tabla1[[#This Row],[CONSUMO POL ANIONICO (KG)]] -> 0 | W11: =Tabla1[[#This Row],[CONSUMO POL CATIONICO (KG)]] -> 0 | X11: =(S11*1000)/L11 -> 422.5 | Y11: =(T11*1000)/L11 -> 397.5 | Z11: =(U11*1000)/L11 -> 218.75 | AA11: =(V11*1000)/L11 -> 0 | AB11: =(W11*1000)/L11 -> 0 | AC11: 1.3 | AD11: 1.325 | AE11: 1.25 | AF11: 2500 | AG11: 2500 | AH11: 830 | AI11: 2818 | AJ11: 6295 | AK11: 19050 | AL11: 22050 | AM11: =S11*AH11 -> 140270 | AN11: =T11*AI11 -> 448062 | AO11: =U11*AJ11 -> 550812.5 | AP11: =V11*AK11 -> 0 | AQ11: =W11*AL11 -> 0 | AR11: =SUM(Tabla1[[#This Row],[COSTO OPERATIVO ACIDO]:[COSTO OPERATIVO CATIONICO]]) -> 1139144.5 | AS11: 3599 | AT11: =AR11/L11 -> 2847.8612
A12: =A11 -> 46085 | B12: =DAY(Tabla1[[#This Row],[FECHA]]) -> 4 | C12: 5 (MAÑANA) | D12: 11 | E12: FINAL TURNO 1 | F12: 1870 | G12: 4480 | H12: 2430 | I12: 105 | J12: 130 | K12: 17274 | L12: =+(K13-Tabla1[[#This Row],[Lectura Horometro INICIAL (06:00)]])*Tabla1[[#This Row],[CAUDAL DE TRATAMIENTO]] -> 560 | M12: 80 | N12: =F12-F13-40 -> 180 | O12: =G12-G13 -> 180 | P12: =H12-H13 -> 110 | Q12: 0 | R12: 0 | S12: =(N12*$AC$2) -> 234 | T12: =(O12*$AD$2) -> 238.5 | U12: =(P12*$AE$2) -> 137.5 | V12: =Tabla1[[#This Row],[CONSUMO POL ANIONICO (KG)]] -> 0 | W12: =Tabla1[[#This Row],[CONSUMO POL CATIONICO (KG)]] -> 0 | X12: =(S12*1000)/L12 -> 417.85714 | Y12: =(T12*1000)/L12 -> 425.89286 | Z12: =(U12*1000)/L12 -> 245.53571 | AA12: =(V12*1000)/L12 -> 0 | AB12: =(W12*1000)/L12 -> 0 | AC12: 1.3 | AD12: 1.325 | AE12: 1.25 | AF12: 2500 | AG12: 2500 | AH12: 830 | AI12: 2818 | AJ12: 6295 | AK12: 19050 | AL12: 22050 | AM12: =S12*AH12 -> 194220 | AN12: =T12*AI12 -> 672093 | AO12: =U12*AJ12 -> 865562.5 | AP12: =V12*AK12 -> 0 | AQ12: =W12*AL12 -> 0 | AR12: =SUM(Tabla1[[#This Row],[COSTO OPERATIVO ACIDO]:[COSTO OPERATIVO CATIONICO]]) -> 1731875.5 | AS12: 3599 | AT12: =AR12/L12 -> 3092.6348
A13: =A12 -> 46085 | B13: =DAY(Tabla1[[#This Row],[FECHA]]) -> 4 | C13: 3(TARDE) | D13: 12 | E13: FINAL TURNO 2 | F13: 1650 | G13: 4300 | H13: 2320 | I13: 100 | J13: 125 | K13: 17281 | L13: =+(K14-Tabla1[[#This Row],[Lectura Horometro INICIAL (06:00)]])*Tabla1[[#This Row],[CAUDAL DE TRATAMIENTO]] -> 640 | M13: 80 | N13: =F13-F14 -> 150 | O13: =G13-G14 -> 110 | P13: =H13-H14 -> 80 | Q13: 0 | R13: 0 | S13: =(N13*$AC$2) -> 195 | T13: =(O13*$AD$2) -> 145.75 | U13: =(P13*$AE$2) -> 100 | V13: =Tabla1[[#This Row],[CONSUMO POL ANIONICO (KG)]] -> 0 | W13: =Tabla1[[#This Row],[CONSUMO POL CATIONICO (KG)]] -> 0 | X13: =(S13*1000)/L13 -> 304.6875 | Y13: =(T13*1000)/L13 -> 227.73438 | Z13: =(U13*1000)/L13 -> 156.25 | AA13: =(V13*1000)/L13 -> 0 | AB13: =(W13*1000)/L13 -> 0 | AC13: 1.3 | AD13: 1.325 | AE13: 1.25 | AF13: 2500 | AG13: 2500 | AH13: 830 | AI13: 2818 | AJ13: 6295 | AK13: 19050 | AL13: 22050 | AM13: =S13*AH13 -> 161850 | AN13: =T13*AI13 -> 410723.5 | AO13: =U13*AJ13 -> 629500 | AP13: =V13*AK13 -> 0 | AQ13: =W13*AL13 -> 0 | AR13: =SUM(Tabla1[[#This Row],[COSTO OPERATIVO ACIDO]:[COSTO OPERATIVO CATIONICO]]) -> 1202073.5 | AS13: 3599 | AT13: =AR13/L13 -> 1878.2398
A14: 46086 | B14: =DAY(Tabla1[[#This Row],[FECHA]]) -> 5 | C14: 5 (NOCHE) | D14: 13 | E14: FINAL TURNO 3 | F14: 1500 | G14: 4190 | H14: 2240 | I14: 100 | J14: 120 | K14: 17289 | L14: =+(K15-Tabla1[[#This Row],[Lectura Horometro INICIAL (06:00)]])*Tabla1[[#This Row],[CAUDAL DE TRATAMIENTO]] -> 560 | M14: 80 | N14: =F14-F15 -> 250 | O14: =G14-G15 -> 130 | P14: =H14-H15 -> 90 | Q14: 0 | R14: 0 | S14: =(N14*$AC$2) -> 325 | T14: =(O14*$AD$2) -> 172.25 | U14: =(P14*$AE$2) -> 112.5 | V14: =Tabla1[[#This Row],[CONSUMO POL ANIONICO (KG)]] -> 0 | W14: =Tabla1[[#This Row],[CONSUMO POL CATIONICO (KG)]] -> 0 | X14: =(S14*1000)/L14 -> 580.35714 | Y14: =(T14*1000)/L14 -> 307.58929 | Z14: =(U14*1000)/L14 -> 200.89286 | AA14: =(V14*1000)/L14 -> 0 | AB14: =(W14*1000)/L14 -> 0 | AC14: 1.3 | AD14: 1.325 | AE14: 1.25 | AF14: 2500 | AG14: 2500 | AH14: 830 | AI14: 2818 | AJ14: 6295 | AK14: 19050 | AL14: 22050 | AM14: =S14*AH14 -> 269750 | AN14: =T14*AI14 -> 485400.5 | AO14: =U14*AJ14 -> 708187.5 | AP14: =V14*AK14 -> 0 | AQ14: =W14*AL14 -> 0 | AR14: =SUM(Tabla1[[#This Row],[COSTO OPERATIVO ACIDO]:[COSTO OPERATIVO CATIONICO]]) -> 1463338 | AS14: 3599 | AT14: =AR14/L14 -> 2613.1036
A15: =A14 -> 46086 | B15: =DAY(Tabla1[[#This Row],[FECHA]]) -> 5 | C15: 6 (MAÑANA) | D15: 14 | E15: FINAL TURNO 1 | F15: 1250 | G15: 4060 | H15: 2150 | I15: 95 | J15: 115 | K15: 17296 | L15: =+(K16-Tabla1[[#This Row],[Lectura Horometro INICIAL (06:00)]])*Tabla1[[#This Row],[CAUDAL DE TRATAMIENTO]] -> 640 | M15: 80 | N15: =F15-F16 -> 250 | O15: =G15-G16 -> 310 | P15: =H15-H16 -> 60 | Q15: =I15-I16 -> 0 | R15: =J15-J16 -> 5 | S15: =(N15*$AC$2) -> 325 | T15: =(O15*$AD$2) -> 410.75 | U15: =(P15*$AE$2) -> 75 | V15: =Tabla1[[#This Row],[CONSUMO POL ANIONICO (KG)]] -> 0 | W15: =Tabla1[[#This Row],[CONSUMO POL CATIONICO (KG)]] -> 5 | X15: =(S15*1000)/L15 -> 507.8125 | Y15: =(T15*1000)/L15 -> 641.79688 | Z15: =(U15*1000)/L15 -> 117.1875 | AA15: =(V15*1000)/L15 -> 0 | AB15: =(W15*1000)/L15 -> 7.8125 | AC15: 1.3 | AD15: 1.325 | AE15: 1.25 | AF15: 2500 | AG15: 2500 | AH15: 830 | AI15: 2818 | AJ15: 6295 | AK15: 19050 | AL15: 22050 | AM15: =S15*AH15 -> 269750 | AN15: =T15*AI15 -> 1157493.5 | AO15: =U15*AJ15 -> 472125 | AP15: =V15*AK15 -> 0 | AQ15: =W15*AL15 -> 110250 | AR15: =SUM(Tabla1[[#This Row],[COSTO OPERATIVO ACIDO]:[COSTO OPERATIVO CATIONICO]]) -> 2009618.5 | AS15: 3599 | AT15: =AR15/L15 -> 3140.0289
A16: =A15 -> 46086 | B16: =DAY(Tabla1[[#This Row],[FECHA]]) -> 5 | C16: 3(TARDE) | D16: 15 | E16: FINAL TURNO 2 | F16: 1000 | G16: 3750 | H16: 2090 | I16: 95 | J16: 110 | K16: 17304 | L16: =+(K17-Tabla1[[#This Row],[Lectura Horometro INICIAL (06:00)]])*Tabla1[[#This Row],[CAUDAL DE TRATAMIENTO]] -> 560 | M16: 80 | N16: =F16-F17 -> 110 | O16: =G16-G17 -> 220 | P16: =H16-H17 -> 160 | Q16: =I16-I17 -> 5 | R16: =J16-J17 -> 5 | S16: =(N16*$AC$2) -> 143 | T16: =(O16*$AD$2) -> 291.5 | U16: =(P16*$AE$2) -> 200 | V16: =Tabla1[[#This Row],[CONSUMO POL ANIONICO (KG)]] -> 5 | W16: =Tabla1[[#This Row],[CONSUMO POL CATIONICO (KG)]] -> 5 | X16: =(S16*1000)/L16 -> 255.35714 | Y16: =(T16*1000)/L16 -> 520.53571 | Z16: =(U16*1000)/L16 -> 357.14286 | AA16: =(V16*1000)/L16 -> 8.9285714 | AB16: =(W16*1000)/L16 -> 8.9285714 | AC16: 1.3 | AD16: 1.325 | AE16: 1.25 | AF16: 2500 | AG16: 2500 | AH16: 830 | AI16: 2818 | AJ16: 6295 | AK16: 19050 | AL16: 22050 | AM16: =S16*AH16 -> 118690 | AN16: =T16*AI16 -> 821447 | AO16: =U16*AJ16 -> 1259000 | AP16: =V16*AK16 -> 95250 | AQ16: =W16*AL16 -> 110250 | AR16: =SUM(Tabla1[[#This Row],[COSTO OPERATIVO ACIDO]:[COSTO OPERATIVO CATIONICO]]) -> 2404637 | AS16: 3599 | AT16: =AR16/L16 -> 4293.9946
A17: 46087 | B17: =DAY(Tabla1[[#This Row],[FECHA]]) -> 6 | C17: 6 (NOCHE) | D17: 16 | E17: FINAL TURNO 3 | F17: 890 | G17: 3530 | H17: 1930 | I17: 90 | J17: 105 | K17: 17311 | L17: =+(K18-Tabla1[[#This Row],[Lectura Horometro INICIAL (06:00)]])*Tabla1[[#This Row],[CAUDAL DE TRATAMIENTO]] -> 400 | M17: 80 | N17: =F17-F18 -> 40 | O17: =G17-G18 -> 180 | P17: =H17-H18 -> 30 | Q17: =I17-I18 -> 0 | R17: =J17-J18 -> 5 | S17: =(N17*$AC$2) -> 52 | T17: =(O17*$AD$2) -> 238.5 | U17: =(P17*$AE$2) -> 37.5 | V17: =Tabla1[[#This Row],[CONSUMO POL ANIONICO (KG)]] -> 0 | W17: =Tabla1[[#This Row],[CONSUMO POL CATIONICO (KG)]] -> 5 | X17: =(S17*1000)/L17 -> 130 | Y17: =(T17*1000)/L17 -> 596.25 | Z17: =(U17*1000)/L17 -> 93.75 | AA17: =(V17*1000)/L17 -> 0 | AB17: =(W17*1000)/L17 -> 12.5 | AC17: 1.3 | AD17: 1.325 | AE17: 1.25 | AF17: 2500 | AG17: 2500 | AH17: 830 | AI17: 2818 | AJ17: 6295 | AK17: 19050 | AL17: 22050 | AM17: =S17*AH17 -> 43160 | AN17: =T17*AI17 -> 672093 | AO17: =U17*AJ17 -> 236062.5 | AP17: =V17*AK17 -> 0 | AQ17: =W17*AL17 -> 110250 | AR17: =SUM(Tabla1[[#This Row],[COSTO OPERATIVO ACIDO]:[COSTO OPERATIVO CATIONICO]]) -> 1061565.5 | AS17: 3599 | AT17: =AR17/L17 -> 2653.9138
A18: =A17 -> 46087 | B18: =DAY(Tabla1[[#This Row],[FECHA]]) -> 6 | C18: 7 (MAÑANA) | D18: 17 | E18: FINAL TURNO 1 | F18: 850 | G18: 3350 | H18: 1900 | I18: 90 | J18: 100 | K18: 17316 | L18: =+(K19-Tabla1[[#This Row],[Lectura Horometro INICIAL (06:00)]])*Tabla1[[#This Row],[CAUDAL DE TRATAMIENTO]] -> 480 | M18: 80 | N18: =F18-F19 -> 200 | O18: =G18-G19 -> 160 | P18: =H18-H19 -> 40 | Q18: =I18-I19 -> 5 | R18: =J18-J19 -> 5 | S18: =(N18*$AC$2) -> 260 | T18: =(O18*$AD$2) -> 212 | U18: =(P18*$AE$2) -> 50 | V18: =Tabla1[[#This Row],[CONSUMO POL ANIONICO (KG)]] -> 5 | W18: =Tabla1[[#This Row],[CONSUMO POL CATIONICO (KG)]] -> 5 | X18: =(S18*1000)/L18 -> 541.66667 | Y18: =(T18*1000)/L18 -> 441.66667 | Z18: =(U18*1000)/L18 -> 104.16667 | AA18: =(V18*1000)/L18 -> 10.416667 | AB18: =(W18*1000)/L18 -> 10.416667 | AC18: 1.3 | AD18: 1.325 | AE18: 1.25 | AF18: 2500 | AG18: 2500 | AH18: 830 | AI18: 2818 | AJ18: 6295 | AK18: 19050 | AL18: 22050 | AM18: =S18*AH18 -> 215800 | AN18: =T18*AI18 -> 597416 | AO18: =U18*AJ18 -> 314750 | AP18: =V18*AK18 -> 95250 | AQ18: =W18*AL18 -> 110250 | AR18: =SUM(Tabla1[[#This Row],[COSTO OPERATIVO ACIDO]:[COSTO OPERATIVO CATIONICO]]) -> 1333466 | AS18: 3599 | AT18: =AR18/L18 -> 2778.0542
A19: =A18 -> 46087 | B19: =DAY(Tabla1[[#This Row],[FECHA]]) -> 6 | C19: 3(TARDE) | D19: 18 | E19: FINAL TURNO 2 | F19: 650 | G19: 3190 | H19: 1860 | I19: 85 | J19: 95 | K19: 17322 | L19: =+(K20-Tabla1[[#This Row],[Lectura Horometro INICIAL (06:00)]])*Tabla1[[#This Row],[CAUDAL DE TRATAMIENTO]] -> 640 | M19: 80 | N19: =F19-F20+2000 -> 370 | O19: =G19-G20-120+2000 -> 320 | P19: =H19-H20+1000 -> 110 | Q19: =I19-I20 -> 0 | R19: =J19-J20+75 -> 5 | S19: =(N19*$AC$2) -> 481 | T19: =(O19*$AD$2) -> 424 | U19: =(P19*$AE$2) -> 137.5 | V19: =Tabla1[[#This Row],[CONSUMO POL ANIONICO (KG)]] -> 0 | W19: =Tabla1[[#This Row],[CONSUMO POL CATIONICO (KG)]] -> 5 | X19: =(S19*1000)/L19 -> 751.5625 | Y19: =(T19*1000)/L19 -> 662.5 | Z19: =(U19*1000)/L19 -> 214.84375 | AA19: =(V19*1000)/L19 -> 0 | AB19: =(W19*1000)/L19 -> 7.8125 | AC19: 1.3 | AD19: 1.325 | AE19: 1.25 | AF19: 2500 | AG19: 2500 | AH19: 830 | AI19: 2818 | AJ19: 6295 | AK19: 19050 | AL19: 22050 | AM19: =S19*AH19 -> 399230 | AN19: =T19*AI19 -> 1194832 | AO19: =U19*AJ19 -> 865562.5 | AP19: =V19*AK19 -> 0 | AQ19: =W19*AL19 -> 110250 | AR19: =SUM(Tabla1[[#This Row],[COSTO OPERATIVO ACIDO]:[COSTO OPERATIVO CATIONICO]]) -> 2569874.5 | AS19: 3599 | AT19: =AR19/L19 -> 4015.4289
A20: 46088 | B20: =DAY(Tabla1[[#This Row],[FECHA]]) -> 7 | C20: 7 (NOCHE) | D20: 19 | E20: FINAL TURNO 3 | F20: 2280 | G20: 4750 | H20: 2750 | I20: 85 | J20: 165 | K20: 17330 | L20: =+(K21-Tabla1[[#This Row],[Lectura Horometro INICIAL (06:00)]])*Tabla1[[#This Row],[CAUDAL DE TRATAMIENTO]] -> 480 | M20: 80 | N20: =F20-F21 -> 380 | O20: =G20-G21-150 -> 300 | P20: =H20-H21 -> 250 | Q20: =I20-I21 -> 5 | R20: =J20-J21 -> 5 | S20: =(N20*$AC$2) -> 494 | T20: =(O20*$AD$2) -> 397.5 | U20: =(P20*$AE$2) -> 312.5 | V20: =Tabla1[[#This Row],[CONSUMO POL ANIONICO (KG)]] -> 5 | W20: =Tabla1[[#This Row],[CONSUMO POL CATIONICO (KG)]] -> 5 | X20: =(S20*1000)/L20 -> 1029.1667 | Y20: =(T20*1000)/L20 -> 828.125 | Z20: =(U20*1000)/L20 -> 651.04167 | AA20: =(V20*1000)/L20 -> 10.416667 | AB20: =(W20*1000)/L20 -> 10.416667 | AC20: 1.3 | AD20: 1.325 | AE20: 1.25 | AF20: 2500 | AG20: 2500 | AH20: 830 | AI20: 2818 | AJ20: 6295 | AK20: 19050 | AL20: 22050 | AM20: =S20*AH20 -> 410020 | AN20: =T20*AI20 -> 1120155 | AO20: =U20*AJ20 -> 1967187.5 | AP20: =V20*AK20 -> 95250 | AQ20: =W20*AL20 -> 110250 | AR20: =SUM(Tabla1[[#This Row],[COSTO OPERATIVO ACIDO]:[COSTO OPERATIVO CATIONICO]]) -> 3702862.5 | AS20: 3599 | AT20: =AR20/L20 -> 7714.2969
A21: =A20 -> 46088 | B21: =DAY(Tabla1[[#This Row],[FECHA]]) -> 7 | C21: 8 (MAÑANA) | D21: 20 | E21: FINAL TURNO 1 | F21: 1900 | G21: 4300 | H21: 2500 | I21: 80 | J21: 160 | K21: 17336 | L21: =+(K22-Tabla1[[#This Row],[Lectura Horometro INICIAL (06:00)]])*Tabla1[[#This Row],[CAUDAL DE TRATAMIENTO]] -> 480 | M21: 80 | N21: =F21-F22 -> 325 | O21: =G21-G22 -> 165 | P21: =H21-H22 -> 15 | Q21: =I21-I22 -> 2.5 | R21: =J21-J22 -> 5 | S21: =(N21*$AC$2) -> 422.5 | T21: =(O21*$AD$2) -> 218.625 | U21: =(P21*$AE$2) -> 18.75 | V21: =Tabla1[[#This Row],[CONSUMO POL ANIONICO (KG)]] -> 2.5 | W21: =Tabla1[[#This Row],[CONSUMO POL CATIONICO (KG)]] -> 5 | X21: =(S21*1000)/L21 -> 880.20833 | Y21: =(T21*1000)/L21 -> 455.46875 | Z21: =(U21*1000)/L21 -> 39.0625 | AA21: =(V21*1000)/L21 -> 5.2083333 | AB21: =(W21*1000)/L21 -> 10.416667 | AC21: 1.3 | AD21: 1.325 | AE21: 1.25 | AF21: 2500 | AG21: 2500 | AH21: 830 | AI21: 2818 | AJ21: 6295 | AK21: 19050 | AL21: 22050 | AM21: =S21*AH21 -> 350675 | AN21: =T21*AI21 -> 616085.25 | AO21: =U21*AJ21 -> 118031.25 | AP21: =V21*AK21 -> 47625 | AQ21: =W21*AL21 -> 110250 | AR21: =SUM(Tabla1[[#This Row],[COSTO OPERATIVO ACIDO]:[COSTO OPERATIVO CATIONICO]]) -> 1242666.5 | AS21: 3599 | AT21: =AR21/L21 -> 2588.8885
A22: =A21 -> 46088 | B22: =DAY(Tabla1[[#This Row],[FECHA]]) -> 7 | C22: 3(TARDE) | D22: 21 | E22: FINAL TURNO 2 | F22: 1575 | G22: 4135 | H22: =+AVERAGE(H21,H23) -> 2485 | I22: 77.5 | J22: 155 | K22: 17342 | L22: =+(K23-Tabla1[[#This Row],[Lectura Horometro INICIAL (06:00)]])*Tabla1[[#This Row],[CAUDAL DE TRATAMIENTO]] -> 320 | M22: 80 | N22: =F22-F23 -> 325 | O22: =G22-G23 -> 165 | P22: =H22-H23 -> 15 | Q22: =I22-I23 -> 2.5 | R22: =J22-J23 -> 5 | S22: =(N22*$AC$2) -> 422.5 | T22: =(O22*$AD$2) -> 218.625 | U22: =(P22*$AE$2) -> 18.75 | V22: =Tabla1[[#This Row],[CONSUMO POL ANIONICO (KG)]] -> 2.5 | W22: =Tabla1[[#This Row],[CONSUMO POL CATIONICO (KG)]] -> 5 | X22: =(S22*1000)/L22 -> 1320.3125 | Y22: =(T22*1000)/L22 -> 683.20312 | Z22: =(U22*1000)/L22 -> 58.59375 | AA22: =(V22*1000)/L22 -> 7.8125 | AB22: =(W22*1000)/L22 -> 15.625 | AC22: 1.3 | AD22: 1.325 | AE22: 1.25 | AF22: 2500 | AG22: 2500 | AH22: 830 | AI22: 2818 | AJ22: 6295 | AK22: 19050 | AL22: 22050 | AM22: =S22*AH22 -> 350675 | AN22: =T22*AI22 -> 616085.25 | AO22: =U22*AJ22 -> 118031.25 | AP22: =V22*AK22 -> 47625 | AQ22: =W22*AL22 -> 110250 | AR22: =SUM(Tabla1[[#This Row],[COSTO OPERATIVO ACIDO]:[COSTO OPERATIVO CATIONICO]]) -> 1242666.5 | AS22: 3599 | AT22: =AR22/L22 -> 3883.3328
A23: 46089 | B23: =DAY(Tabla1[[#This Row],[FECHA]]) -> 8 | C23: 8 (NOCHE) | D23: 22 | E23: FINAL TURNO 3 | F23: 1250 | G23: 3970 | H23: 2470 | I23: 75 | J23: 150 | K23: 17346 | L23: =+(K24-Tabla1[[#This Row],[Lectura Horometro INICIAL (06:00)]])*Tabla1[[#This Row],[CAUDAL DE TRATAMIENTO]] -> 0 | M23: 80 | N23: =F23-F24 -> 0 | O23: =G23-G24 -> 0 | P23: =H23-H24 -> 0 | Q23: =I23-I24 -> 0 | R23: =J23-J24 -> 0 | S23: =(N23*$AC$2) -> 0 | T23: =(O23*$AD$2) -> 0 | U23: =(P23*$AE$2) -> 0 | V23: =Tabla1[[#This Row],[CONSUMO POL ANIONICO (KG)]] -> 0 | W23: =Tabla1[[#This Row],[CONSUMO POL CATIONICO (KG)]] -> 0 | X23: =(S23*1000)/L23 -> #DIV/0! | Y23: =(T23*1000)/L23 -> #DIV/0! | Z23: =(U23*1000)/L23 -> #DIV/0! | AA23: =(V23*1000)/L23 -> #DIV/0! | AB23: =(W23*1000)/L23 -> #DIV/0! | AC23: 1.3 | AD23: 1.325 | AE23: 1.25 | AF23: 2500 | AG23: 2500 | AH23: 830 | AI23: 2818 | AJ23: 6295 | AK23: 19050 | AL23: 22050 | AM23: =S23*AH23 -> 0 | AN23: =T23*AI23 -> 0 | AO23: =U23*AJ23 -> 0 | AP23: =V23*AK23 -> 0 | AQ23: =W23*AL23 -> 0 | AR23: =SUM(Tabla1[[#This Row],[COSTO OPERATIVO ACIDO]:[COSTO OPERATIVO CATIONICO]]) -> 0 | AS23: 3599 | AT23: =AR23/L23 -> #DIV/0!
A24: =A23 -> 46089 | B24: =DAY(Tabla1[[#This Row],[FECHA]]) -> 8 | C24: 9 (MAÑANA) | D24: 23 | E24: FINAL TURNO 1 | F24: 1250 | G24: 3970 | H24: 2470 | I24: 75 | J24: 150 | K24: 17346 | L24: =+(K25-Tabla1[[#This Row],[Lectura Horometro INICIAL (06:00)]])*Tabla1[[#This Row],[CAUDAL DE TRATAMIENTO]] -> 0 | M24: 80 | N24: =F24-F25 -> 0 | O24: =G24-G25 -> 0 | P24: =H24-H25 -> 0 | Q24: =I24-I25 -> 0 | R24: =J24-J25 -> 0 | S24: =(N24*$AC$2) -> 0 | T24: =(O24*$AD$2) -> 0 | U24: =(P24*$AE$2) -> 0 | V24: =Tabla1[[#This Row],[CONSUMO POL ANIONICO (KG)]] -> 0 | W24: =Tabla1[[#This Row],[CONSUMO POL CATIONICO (KG)]] -> 0 | X24: =(S24*1000)/L24 -> #DIV/0! | Y24: =(T24*1000)/L24 -> #DIV/0! | Z24: =(U24*1000)/L24 -> #DIV/0! | AA24: =(V24*1000)/L24 -> #DIV/0! | AB24: =(W24*1000)/L24 -> #DIV/0! | AC24: 1.3 | AD24: 1.325 | AE24: 1.25 | AF24: 2500 | AG24: 2500 | AH24: 830 | AI24: 2818 | AJ24: 6295 | AK24: 19050 | AL24: 22050 | AM24: =S24*AH24 -> 0 | AN24: =T24*AI24 -> 0 | AO24: =U24*AJ24 -> 0 | AP24: =V24*AK24 -> 0 | AQ24: =W24*AL24 -> 0 | AR24: =SUM(Tabla1[[#This Row],[COSTO OPERATIVO ACIDO]:[COSTO OPERATIVO CATIONICO]]) -> 0 | AS24: 3599 | AT24: =AR24/L24 -> #DIV/0!
A25: =A24 -> 46089 | B25: =DAY(Tabla1[[#This Row],[FECHA]]) -> 8 | C25: 3(TARDE) | D25: 24 | E25: FINAL TURNO 2 | F25: 1250 | G25: 3970 | H25: 2470 | I25: 75 | J25: 150 | K25: 17346 | L25: =+(K26-Tabla1[[#This Row],[Lectura Horometro INICIAL (06:00)]])*Tabla1[[#This Row],[CAUDAL DE TRATAMIENTO]] -> 0 | M25: 80 | N25: =F25-F26 -> 0 | O25: =G25-G26 -> 0 | P25: =H25-H26 -> 0 | Q25: =I25-I26 -> 0 | R25: =J25-J26 -> 0 | S25: =(N25*$AC$2) -> 0 | T25: =(O25*$AD$2) -> 0 | U25: =(P25*$AE$2) -> 0 | V25: =Tabla1[[#This Row],[CONSUMO POL ANIONICO (KG)]] -> 0 | W25: =Tabla1[[#This Row],[CONSUMO POL CATIONICO (KG)]] -> 0 | X25: =(S25*1000)/L25 -> #DIV/0! | Y25: =(T25*1000)/L25 -> #DIV/0! | Z25: =(U25*1000)/L25 -> #DIV/0! | AA25: =(V25*1000)/L25 -> #DIV/0! | AB25: =(W25*1000)/L25 -> #DIV/0! | AC25: 1.3 | AD25: 1.325 | AE25: 1.25 | AF25: 2500 | AG25: 2500 | AH25: 830 | AI25: 2818 | AJ25: 6295 | AK25: 19050 | AL25: 22050 | AM25: =S25*AH25 -> 0 | AN25: =T25*AI25 -> 0 | AO25: =U25*AJ25 -> 0 | AP25: =V25*AK25 -> 0 | AQ25: =W25*AL25 -> 0 | AR25: =SUM(Tabla1[[#This Row],[COSTO OPERATIVO ACIDO]:[COSTO OPERATIVO CATIONICO]]) -> 0 | AS25: 3599 | AT25: =AR25/L25 -> #DIV/0!
A26: 46090 | B26: =DAY(Tabla1[[#This Row],[FECHA]]) -> 9 | C26: 9 (NOCHE) | D26: 25 | E26: FINAL TURNO 3 | F26: 1250 | G26: 3970 | H26: 2470 | I26: 75 | J26: 150 | K26: 17346 | L26: =+(K27-Tabla1[[#This Row],[Lectura Horometro INICIAL (06:00)]])*Tabla1[[#This Row],[CAUDAL DE TRATAMIENTO]] -> 480 | M26: 80 | N26: =F26-F27 -> 50 | O26: =G26-G27 -> 520 | P26: =H26-H27 -> 70 | Q26: =I26-I27 -> 0 | R26: =J26-J27 -> 5 | S26: =(N26*$AC$2) -> 65 | T26: =(O26*$AD$2) -> 689 | U26: =(P26*$AE$2) -> 87.5 | V26: =Tabla1[[#This Row],[CONSUMO POL ANIONICO (KG)]] -> 0 | W26: =Tabla1[[#This Row],[CONSUMO POL CATIONICO (KG)]] -> 5 | X26: =(S26*1000)/L26 -> 135.41667 | Y26: =(T26*1000)/L26 -> 1435.4167 | Z26: =(U26*1000)/L26 -> 182.29167 | AA26: =(V26*1000)/L26 -> 0 | AB26: =(W26*1000)/L26 -> 10.416667 | AC26: 1.3 | AD26: 1.325 | AE26: 1.25 | AF26: 2500 | AG26: 2500 | AH26: 830 | AI26: 2818 | AJ26: 6295 | AK26: 19050 | AL26: 22050 | AM26: =S26*AH26 -> 53950 | AN26: =T26*AI26 -> 1941602 | AO26: =U26*AJ26 -> 550812.5 | AP26: =V26*AK26 -> 0 | AQ26: =W26*AL26 -> 110250 | AR26: =SUM(Tabla1[[#This Row],[COSTO OPERATIVO ACIDO]:[COSTO OPERATIVO CATIONICO]]) -> 2656614.5 | AS26: 3599 | AT26: =AR26/L26 -> 5534.6135
A27: =A26 -> 46090 | B27: =DAY(Tabla1[[#This Row],[FECHA]]) -> 9 | C27: 10 (MAÑANA) | D27: 26 | E27: FINAL TURNO 1 | F27: 1200 | G27: 3450 | H27: 2400 | I27: 75 | J27: 145 | K27: 17352 | L27: =+(K28-Tabla1[[#This Row],[Lectura Horometro INICIAL (06:00)]])*Tabla1[[#This Row],[CAUDAL DE TRATAMIENTO]] -> 400 | M27: 80 | N27: =F27-F28 -> 350 | O27: =G27-G28-100 -> 200 | P27: =H27-H28 -> 100 | Q27: =I27-I28 -> 0 | R27: =J27-J28 -> 5 | S27: =(N27*$AC$2) -> 455 | T27: =(O27*$AD$2) -> 265 | U27: =(P27*$AE$2) -> 125 | V27: =Tabla1[[#This Row],[CONSUMO POL ANIONICO (KG)]] -> 0 | W27: =Tabla1[[#This Row],[CONSUMO POL CATIONICO (KG)]] -> 5 | X27: =(S27*1000)/L27 -> 1137.5 | Y27: =(T27*1000)/L27 -> 662.5 | Z27: =(U27*1000)/L27 -> 312.5 | AA27: =(V27*1000)/L27 -> 0 | AB27: =(W27*1000)/L27 -> 12.5 | AC27: 1.3 | AD27: 1.325 | AE27: 1.25 | AF27: 2500 | AG27: 2500 | AH27: 830 | AI27: 2818 | AJ27: 6295 | AK27: 19050 | AL27: 22050 | AM27: =S27*AH27 -> 377650 | AN27: =T27*AI27 -> 746770 | AO27: =U27*AJ27 -> 786875 | AP27: =V27*AK27 -> 0 | AQ27: =W27*AL27 -> 110250 | AR27: =SUM(Tabla1[[#This Row],[COSTO OPERATIVO ACIDO]:[COSTO OPERATIVO CATIONICO]]) -> 2021545 | AS27: 3599 | AT27: =AR27/L27 -> 5053.8625
A28: =A27 -> 46090 | B28: =DAY(Tabla1[[#This Row],[FECHA]]) -> 9 | C28: 3(TARDE) | D28: 27 | E28: FINAL TURNO 2 | F28: 850 | G28: 3150 | H28: 2300 | I28: 75 | J28: 140 | K28: 17357 | L28: =+(K29-Tabla1[[#This Row],[Lectura Horometro INICIAL (06:00)]])*Tabla1[[#This Row],[CAUDAL DE TRATAMIENTO]] -> 640 | M28: 80 | N28: =F28-F29 -> 320 | O28: =G28-G29 -> 100 | P28: =H28-H29 -> 70 | Q28: =I28-I29 -> 5 | R28: =J28-J29 -> 5 | S28: =(N28*$AC$2) -> 416 | T28: =(O28*$AD$2) -> 132.5 | U28: =(P28*$AE$2) -> 87.5 | V28: =Tabla1[[#This Row],[CONSUMO POL ANIONICO (KG)]] -> 5 | W28: =Tabla1[[#This Row],[CONSUMO POL CATIONICO (KG)]] -> 5 | X28: =(S28*1000)/L28 -> 650 | Y28: =(T28*1000)/L28 -> 207.03125 | Z28: =(U28*1000)/L28 -> 136.71875 | AA28: =(V28*1000)/L28 -> 7.8125 | AB28: =(W28*1000)/L28 -> 7.8125 | AC28: 1.3 | AD28: 1.325 | AE28: 1.25 | AF28: 2500 | AG28: 2500 | AH28: 830 | AI28: 2818 | AJ28: 6295 | AK28: 19050 | AL28: 22050 | AM28: =S28*AH28 -> 345280 | AN28: =T28*AI28 -> 373385 | AO28: =U28*AJ28 -> 550812.5 | AP28: =V28*AK28 -> 95250 | AQ28: =W28*AL28 -> 110250 | AR28: =SUM(Tabla1[[#This Row],[COSTO OPERATIVO ACIDO]:[COSTO OPERATIVO CATIONICO]]) -> 1474977.5 | AS28: 3599 | AT28: =AR28/L28 -> 2304.6523
A29: 46091 | B29: =DAY(Tabla1[[#This Row],[FECHA]]) -> 10 | C29: 10 (NOCHE) | D29: 28 | E29: FINAL TURNO 3 | F29: 530 | G29: 3050 | H29: 2230 | I29: 70 | J29: 135 | K29: 17365 | L29: =+(K30-Tabla1[[#This Row],[Lectura Horometro INICIAL (06:00)]])*Tabla1[[#This Row],[CAUDAL DE TRATAMIENTO]] -> 640 | M29: 80 | N29: =F29-F30 -> 330 | O29: =G29-G30-150 -> 220 | P29: =H29-H30 -> 50 | Q29: =I29-I30 -> 0 | R29: =J29-J30 -> 5 | S29: =(N29*$AC$2) -> 429 | T29: =(O29*$AD$2) -> 291.5 | U29: =(P29*$AE$2) -> 62.5 | V29: =Tabla1[[#This Row],[CONSUMO POL ANIONICO (KG)]] -> 0 | W29: =Tabla1[[#This Row],[CONSUMO POL CATIONICO (KG)]] -> 5 | X29: =(S29*1000)/L29 -> 670.3125 | Y29: =(T29*1000)/L29 -> 455.46875 | Z29: =(U29*1000)/L29 -> 97.65625 | AA29: =(V29*1000)/L29 -> 0 | AB29: =(W29*1000)/L29 -> 7.8125 | AC29: 1.3 | AD29: 1.325 | AE29: 1.25 | AF29: 2500 | AG29: 2500 | AH29: 830 | AI29: 2818 | AJ29: 6295 | AK29: 19050 | AL29: 22050 | AM29: =S29*AH29 -> 356070 | AN29: =T29*AI29 -> 821447 | AO29: =U29*AJ29 -> 393437.5 | AP29: =V29*AK29 -> 0 | AQ29: =W29*AL29 -> 110250 | AR29: =SUM(Tabla1[[#This Row],[COSTO OPERATIVO ACIDO]:[COSTO OPERATIVO CATIONICO]]) -> 1681204.5 | AS29: 3599 | AT29: =AR29/L29 -> 2626.882
A30: =A29 -> 46091 | B30: =DAY(Tabla1[[#This Row],[FECHA]]) -> 10 | C30: 11 (MAÑANA) | D30: 29 | E30: FINAL TURNO 1 | F30: 200 | G30: 2680 | H30: 2180 | I30: 70 | J30: 130 | K30: 17373 | L30: =+(K31-Tabla1[[#This Row],[Lectura Horometro INICIAL (06:00)]])*Tabla1[[#This Row],[CAUDAL DE TRATAMIENTO]] -> 400 | M30: 80 | N30: =F30-F31 -> 200 | O30: =G30-G31 -> 170 | P30: =H30-H31 -> 180 | Q30: =I30-I31 -> 5 | R30: =J30-J31 -> 5 | S30: =(N30*$AC$2) -> 260 | T30: =(O30*$AD$2) -> 225.25 | U30: =(P30*$AE$2) -> 225 | V30: =Tabla1[[#This Row],[CONSUMO POL ANIONICO (KG)]] -> 5 | W30: =Tabla1[[#This Row],[CONSUMO POL CATIONICO (KG)]] -> 5 | X30: =(S30*1000)/L30 -> 650 | Y30: =(T30*1000)/L30 -> 563.125 | Z30: =(U30*1000)/L30 -> 562.5 | AA30: =(V30*1000)/L30 -> 12.5 | AB30: =(W30*1000)/L30 -> 12.5 | AC30: 1.3 | AD30: 1.325 | AE30: 1.25 | AF30: 2500 | AG30: 2500 | AH30: 830 | AI30: 2818 | AJ30: 6295 | AK30: 19050 | AL30: 22050 | AM30: =S30*AH30 -> 215800 | AN30: =T30*AI30 -> 634754.5 | AO30: =U30*AJ30 -> 1416375 | AP30: =V30*AK30 -> 95250 | AQ30: =W30*AL30 -> 110250 | AR30: =SUM(Tabla1[[#This Row],[COSTO OPERATIVO ACIDO]:[COSTO OPERATIVO CATIONICO]]) -> 2472429.5 | AS30: 3599 | AT30: =AR30/L30 -> 6181.0737
A31: =A30 -> 46091 | B31: =DAY(Tabla1[[#This Row],[FECHA]]) -> 10 | C31: 3(TARDE) | D31: 30 | E31: FINAL TURNO 2 | F31: 0 | G31: 2510 | H31: 2000 | I31: =65 -> 65 | J31: 125 | K31: 17378 | L31: =+(K32-Tabla1[[#This Row],[Lectura Horometro INICIAL (06:00)]])*Tabla1[[#This Row],[CAUDAL DE TRATAMIENTO]] -> 480 | M31: 80 | N31: =F31-F32+1000 -> 30 | O31: =G31-G32+2000 -> 210 | P31: =H31-H32+1000 -> 30 | Q31: =I31-I32+150 -> 0 | R31: =J31-J32+100 -> 5 | S31: =(N31*$AC$2) -> 39 | T31: =(O31*$AD$2) -> 278.25 | U31: =(P31*$AE$2) -> 37.5 | V31: =Tabla1[[#This Row],[CONSUMO POL ANIONICO (KG)]] -> 0 | W31: =Tabla1[[#This Row],[CONSUMO POL CATIONICO (KG)]] -> 5 | X31: =(S31*1000)/L31 -> 81.25 | Y31: =(T31*1000)/L31 -> 579.6875 | Z31: =(U31*1000)/L31 -> 78.125 | AA31: =(V31*1000)/L31 -> 0 | AB31: =(W31*1000)/L31 -> 10.416667 | AC31: 1.3 | AD31: 1.325 | AE31: 1.25 | AF31: 2500 | AG31: 2500 | AH31: 830 | AI31: 2818 | AJ31: 6295 | AK31: 19050 | AL31: 22050 | AM31: =S31*AH31 -> 32370 | AN31: =T31*AI31 -> 784108.5 | AO31: =U31*AJ31 -> 236062.5 | AP31: =V31*AK31 -> 0 | AQ31: =W31*AL31 -> 110250 | AR31: =SUM(Tabla1[[#This Row],[COSTO OPERATIVO ACIDO]:[COSTO OPERATIVO CATIONICO]]) -> 1162791 | AS31: 3599 | AT31: =AR31/L31 -> 2422.4812
A32: 46092 | B32: =DAY(Tabla1[[#This Row],[FECHA]]) -> 11 | C32: 11 (NOCHE) | D32: 31 | E32: FINAL TURNO 3 | F32: 970 | G32: 4300 | H32: 2970 | I32: =65+150 -> 215 | J32: 220 | K32: 17384 | L32: =+(K33-Tabla1[[#This Row],[Lectura Horometro INICIAL (06:00)]])*Tabla1[[#This Row],[CAUDAL DE TRATAMIENTO]] -> 480 | M32: 80 | N32: =F32-F33 -> 260 | O32: =G32-G33 -> 390 | P32: =H32-H33 -> 120 | Q32: =I32-I33 -> 5 | R32: =J32-J33 -> 5 | S32: =(N32*$AC$2) -> 338 | T32: =(O32*$AD$2) -> 516.75 | U32: =(P32*$AE$2) -> 150 | V32: =Tabla1[[#This Row],[CONSUMO POL ANIONICO (KG)]] -> 5 | W32: =Tabla1[[#This Row],[CONSUMO POL CATIONICO (KG)]] -> 5 | X32: =(S32*1000)/L32 -> 704.16667 | Y32: =(T32*1000)/L32 -> 1076.5625 | Z32: =(U32*1000)/L32 -> 312.5 | AA32: =(V32*1000)/L32 -> 10.416667 | AB32: =(W32*1000)/L32 -> 10.416667 | AC32: 1.3 | AD32: 1.325 | AE32: 1.25 | AF32: 2500 | AG32: 2500 | AH32: 830 | AI32: 2818 | AJ32: 6295 | AK32: 19050 | AL32: 22050 | AM32: =S32*AH32 -> 280540 | AN32: =T32*AI32 -> 1456201.5 | AO32: =U32*AJ32 -> 944250 | AP32: =V32*AK32 -> 95250 | AQ32: =W32*AL32 -> 110250 | AR32: =SUM(Tabla1[[#This Row],[COSTO OPERATIVO ACIDO]:[COSTO OPERATIVO CATIONICO]]) -> 2886491.5 | AS32: 3599 | AT32: =AR32/L32 -> 6013.524
A33: =A32 -> 46092 | B33: =DAY(Tabla1[[#This Row],[FECHA]]) -> 11 | C33: 12 (MAÑANA) | D33: 32 | E33: FINAL TURNO 1 | F33: 710 | G33: 3910 | H33: 2850 | I33: 210 | J33: 215 | K33: 17390 | L33: =+(K34-Tabla1[[#This Row],[Lectura Horometro INICIAL (06:00)]])*Tabla1[[#This Row],[CAUDAL DE TRATAMIENTO]] -> 400 | M33: 80 | N33: =F33-F34 -> 210 | O33: =G33-G34-150 -> 240 | P33: =H33-H34 -> 150 | Q33: =I33-I34 -> 0 | R33: =J33-J34 -> 5 | S33: =(N33*$AC$2) -> 273 | T33: =(O33*$AD$2) -> 318 | U33: =(P33*$AE$2) -> 187.5 | V33: =Tabla1[[#This Row],[CONSUMO POL ANIONICO (KG)]] -> 0 | W33: =Tabla1[[#This Row],[CONSUMO POL CATIONICO (KG)]] -> 5 | X33: =(S33*1000)/L33 -> 682.5 | Y33: =(T33*1000)/L33 -> 795 | Z33: =(U33*1000)/L33 -> 468.75 | AA33: =(V33*1000)/L33 -> 0 | AB33: =(W33*1000)/L33 -> 12.5 | AC33: 1.3 | AD33: 1.325 | AE33: 1.25 | AF33: 2500 | AG33: 2500 | AH33: 830 | AI33: 2818 | AJ33: 6295 | AK33: 19050 | AL33: 22050 | AM33: =S33*AH33 -> 226590 | AN33: =T33*AI33 -> 896124 | AO33: =U33*AJ33 -> 1180312.5 | AP33: =V33*AK33 -> 0 | AQ33: =W33*AL33 -> 110250 | AR33: =SUM(Tabla1[[#This Row],[COSTO OPERATIVO ACIDO]:[COSTO OPERATIVO CATIONICO]]) -> 2413276.5 | AS33: 3599 | AT33: =AR33/L33 -> 6033.1912
A34: =A33 -> 46092 | B34: =DAY(Tabla1[[#This Row],[FECHA]]) -> 11 | C34: 3(TARDE) | D34: 33 | E34: FINAL TURNO 2 | F34: 500 | G34: 3520 | H34: 2700 | I34: 210 | J34: 210 | K34: 17395 | L34: =+(K35-Tabla1[[#This Row],[Lectura Horometro INICIAL (06:00)]])*Tabla1[[#This Row],[CAUDAL DE TRATAMIENTO]] -> 400 | M34: 80 | N34: =F34-F35 -> 170 | O34: =G34-G35 -> 310 | P34: =H34-H35 -> 0 | Q34: =I34-I35 -> 5 | R34: =J34-J35 -> 5 | S34: =(N34*$AC$2) -> 221 | T34: =(O34*$AD$2) -> 410.75 | U34: =(P34*$AE$2) -> 0 | V34: =Tabla1[[#This Row],[CONSUMO POL ANIONICO (KG)]] -> 5 | W34: =Tabla1[[#This Row],[CONSUMO POL CATIONICO (KG)]] -> 5 | X34: =(S34*1000)/L34 -> 552.5 | Y34: =(T34*1000)/L34 -> 1026.875 | Z34: =(U34*1000)/L34 -> 0 | AA34: =(V34*1000)/L34 -> 12.5 | AB34: =(W34*1000)/L34 -> 12.5 | AC34: 1.3 | AD34: 1.325 | AE34: 1.25 | AF34: 2500 | AG34: 2500 | AH34: 830 | AI34: 2818 | AJ34: 6295 | AK34: 19050 | AL34: 22050 | AM34: =S34*AH34 -> 183430 | AN34: =T34*AI34 -> 1157493.5 | AO34: =U34*AJ34 -> 0 | AP34: =V34*AK34 -> 95250 | AQ34: =W34*AL34 -> 110250 | AR34: =SUM(Tabla1[[#This Row],[COSTO OPERATIVO ACIDO]:[COSTO OPERATIVO CATIONICO]]) -> 1546423.5 | AS34: 3599 | AT34: =AR34/L34 -> 3866.0588
A35: 46093 | B35: =DAY(Tabla1[[#This Row],[FECHA]]) -> 12 | C35: 12 (NOCHE) | D35: 34 | E35: FINAL TURNO 3 | F35: 330 | G35: 3210 | H35: 2700 | I35: 205 | J35: 205 | K35: 17400 | L35: =+(K36-Tabla1[[#This Row],[Lectura Horometro INICIAL (06:00)]])*Tabla1[[#This Row],[CAUDAL DE TRATAMIENTO]] -> 480 | M35: 80 | N35: =F35-F36 -> 20 | O35: =G35-G36 -> 310 | P35: =H35-H36 -> 100 | Q35: =I35-I36 -> 0 | R35: =J35-J36 -> 5 | S35: =(N35*$AC$2) -> 26 | T35: =(O35*$AD$2) -> 410.75 | U35: =(P35*$AE$2) -> 125 | V35: =Tabla1[[#This Row],[CONSUMO POL ANIONICO (KG)]] -> 0 | W35: =Tabla1[[#This Row],[CONSUMO POL CATIONICO (KG)]] -> 5 | X35: =(S35*1000)/L35 -> 54.166667 | Y35: =(T35*1000)/L35 -> 855.72917 | Z35: =(U35*1000)/L35 -> 260.41667 | AA35: =(V35*1000)/L35 -> 0 | AB35: =(W35*1000)/L35 -> 10.416667 | AC35: 1.3 | AD35: 1.325 | AE35: 1.25 | AF35: 2500 | AG35: 2500 | AH35: 830 | AI35: 2818 | AJ35: 6295 | AK35: 19050 | AL35: 22050 | AM35: =S35*AH35 -> 21580 | AN35: =T35*AI35 -> 1157493.5 | AO35: =U35*AJ35 -> 786875 | AP35: =V35*AK35 -> 0 | AQ35: =W35*AL35 -> 110250 | AR35: =SUM(Tabla1[[#This Row],[COSTO OPERATIVO ACIDO]:[COSTO OPERATIVO CATIONICO]]) -> 2076198.5 | AS35: 3599 | AT35: =AR35/L35 -> 4325.4135
A36: =A35 -> 46093 | B36: =DAY(Tabla1[[#This Row],[FECHA]]) -> 12 | C36: 13 (MAÑANA) | D36: 35 | E36: FINAL TURNO 1 | F36: 310 | G36: 2900 | H36: 2600 | I36: 205 | J36: 200 | K36: 17406 | L36: =+(K37-Tabla1[[#This Row],[Lectura Horometro INICIAL (06:00)]])*Tabla1[[#This Row],[CAUDAL DE TRATAMIENTO]] -> 400 | M36: 80 | N36: =F36-F37-20 -> 190 | O36: =G36-G37 -> 300 | P36: =H36-H37 -> 170 | Q36: =I36-I37 -> 5 | R36: =J36-J37 -> 5 | S36: =(N36*$AC$2) -> 247 | T36: =(O36*$AD$2) -> 397.5 | U36: =(P36*$AE$2) -> 212.5 | V36: =Tabla1[[#This Row],[CONSUMO POL ANIONICO (KG)]] -> 5 | W36: =Tabla1[[#This Row],[CONSUMO POL CATIONICO (KG)]] -> 5 | X36: =(S36*1000)/L36 -> 617.5 | Y36: =(T36*1000)/L36 -> 993.75 | Z36: =(U36*1000)/L36 -> 531.25 | AA36: =(V36*1000)/L36 -> 12.5 | AB36: =(W36*1000)/L36 -> 12.5 | AC36: 1.3 | AD36: 1.325 | AE36: 1.25 | AF36: 2500 | AG36: 2500 | AH36: 830 | AI36: 2818 | AJ36: 6295 | AK36: 19050 | AL36: 22050 | AM36: =S36*AH36 -> 205010 | AN36: =T36*AI36 -> 1120155 | AO36: =U36*AJ36 -> 1337687.5 | AP36: =V36*AK36 -> 95250 | AQ36: =W36*AL36 -> 110250 | AR36: =SUM(Tabla1[[#This Row],[COSTO OPERATIVO ACIDO]:[COSTO OPERATIVO CATIONICO]]) -> 2868352.5 | AS36: 3599 | AT36: =AR36/L36 -> 7170.8813
A37: =A36 -> 46093 | B37: =DAY(Tabla1[[#This Row],[FECHA]]) -> 12 | C37: 3(TARDE) | D37: 36 | E37: FINAL TURNO 2 | F37: 100 | G37: 2600 | H37: 2430 | I37: 200 | J37: 195 | K37: 17411 | L37: =+(K38-Tabla1[[#This Row],[Lectura Horometro INICIAL (06:00)]])*Tabla1[[#This Row],[CAUDAL DE TRATAMIENTO]] -> 640 | M37: 80 | N37: =F37-F38+1000 -> 130 | O37: =G37-G38-150 -> 230 | P37: =H37-H38 -> 30 | Q37: =I37-I38 -> 0 | R37: =J37-J38 -> 5 | S37: =(N37*$AC$2) -> 169 | T37: =(O37*$AD$2) -> 304.75 | U37: =(P37*$AE$2) -> 37.5 | V37: =Tabla1[[#This Row],[CONSUMO POL ANIONICO (KG)]] -> 0 | W37: =Tabla1[[#This Row],[CONSUMO POL CATIONICO (KG)]] -> 5 | X37: =(S37*1000)/L37 -> 264.0625 | Y37: =(T37*1000)/L37 -> 476.17188 | Z37: =(U37*1000)/L37 -> 58.59375 | AA37: =(V37*1000)/L37 -> 0 | AB37: =(W37*1000)/L37 -> 7.8125 | AC37: 1.3 | AD37: 1.325 | AE37: 1.25 | AF37: 2500 | AG37: 2500 | AH37: 830 | AI37: 2818 | AJ37: 6295 | AK37: 19050 | AL37: 22050 | AM37: =S37*AH37 -> 140270 | AN37: =T37*AI37 -> 858785.5 | AO37: =U37*AJ37 -> 236062.5 | AP37: =V37*AK37 -> 0 | AQ37: =W37*AL37 -> 110250 | AR37: =SUM(Tabla1[[#This Row],[COSTO OPERATIVO ACIDO]:[COSTO OPERATIVO CATIONICO]]) -> 1345368 | AS37: 3599 | AT37: =AR37/L37 -> 2102.1375
A38: 46094 | B38: =DAY(Tabla1[[#This Row],[FECHA]]) -> 13 | C38: 13 (NOCHE) | D38: 37 | E38: FINAL TURNO 3 | F38: 970 | G38: 2220 | H38: 2400 | I38: 200 | J38: 190 | K38: 17419 | L38: =+(K39-Tabla1[[#This Row],[Lectura Horometro INICIAL (06:00)]])*Tabla1[[#This Row],[CAUDAL DE TRATAMIENTO]] -> 480 | M38: 80 | N38: =F38-F39 -> 80 | O38: =G38-G39 -> 220 | Q38: =I38-I39 -> 5 | R38: =J38-J39 -> 5 | S38: =(N38*$AC$2) -> 104 | T38: =(O38*$AD$2) -> 291.5 | U38: =(P38*$AE$2) -> 0 | V38: =Tabla1[[#This Row],[CONSUMO POL ANIONICO (KG)]] -> 5 | W38: =Tabla1[[#This Row],[CONSUMO POL CATIONICO (KG)]] -> 5 | X38: =(S38*1000)/L38 -> 216.66667 | Y38: =(T38*1000)/L38 -> 607.29167 | Z38: =(U38*1000)/L38 -> 0 | AA38: =(V38*1000)/L38 -> 10.416667 | AB38: =(W38*1000)/L38 -> 10.416667 | AC38: 1.3 | AD38: 1.325 | AE38: 1.25 | AF38: 2500 | AG38: 2500 | AH38: 830 | AI38: 2818 | AJ38: 6295 | AK38: 19050 | AL38: 22050 | AM38: =S38*AH38 -> 86320 | AN38: =T38*AI38 -> 821447 | AO38: =U38*AJ38 -> 0 | AP38: =V38*AK38 -> 95250 | AQ38: =W38*AL38 -> 110250 | AR38: =SUM(Tabla1[[#This Row],[COSTO OPERATIVO ACIDO]:[COSTO OPERATIVO CATIONICO]]) -> 1113267 | AS38: 3599 | AT38: =AR38/L38 -> 2319.3063
A39: =A38 -> 46094 | B39: =DAY(Tabla1[[#This Row],[FECHA]]) -> 13 | C39: 14 (MAÑANA) | D39: 38 | E39: FINAL TURNO 1 | F39: 890 | G39: 2000 | H39: 2300 | I39: 195 | J39: 185 | K39: 17425 | L39: =+(K40-Tabla1[[#This Row],[Lectura Horometro INICIAL (06:00)]])*Tabla1[[#This Row],[CAUDAL DE TRATAMIENTO]] -> 240 | M39: 80 | N39: =F39-F40 -> 160 | O39: =G39-G40 -> 110 | P39: =H39-H40 -> 10 | Q39: =I39-I40 -> 0 | R39: =J39-J40 -> 5 | S39: =(N39*$AC$2) -> 208 | T39: =(O39*$AD$2) -> 145.75 | U39: =(P39*$AE$2) -> 12.5 | V39: =Tabla1[[#This Row],[CONSUMO POL ANIONICO (KG)]] -> 0 | W39: =Tabla1[[#This Row],[CONSUMO POL CATIONICO (KG)]] -> 5 | X39: =(S39*1000)/L39 -> 866.66667 | Y39: =(T39*1000)/L39 -> 607.29167 | Z39: =(U39*1000)/L39 -> 52.083333 | AA39: =(V39*1000)/L39 -> 0 | AB39: =(W39*1000)/L39 -> 20.833333 | AC39: 1.3 | AD39: 1.325 | AE39: 1.25 | AF39: 2500 | AG39: 2500 | AH39: 830 | AI39: 2818 | AJ39: 6295 | AK39: 19050 | AL39: 22050 | AM39: =S39*AH39 -> 172640 | AN39: =T39*AI39 -> 410723.5 | AO39: =U39*AJ39 -> 78687.5 | AP39: =V39*AK39 -> 0 | AQ39: =W39*AL39 -> 110250 | AR39: =SUM(Tabla1[[#This Row],[COSTO OPERATIVO ACIDO]:[COSTO OPERATIVO CATIONICO]]) -> 772301 | AS39: 3599 | AT39: =AR39/L39 -> 3217.9208
A40: =A39 -> 46094 | B40: =DAY(Tabla1[[#This Row],[FECHA]]) -> 13 | C40: 3(TARDE) | D40: 39 | E40: FINAL TURNO 2 | F40: 730 | G40: 1890 | H40: 2290 | I40: 195 | J40: 180 | K40: 17428 | L40: =+(K41-Tabla1[[#This Row],[Lectura Horometro INICIAL (06:00)]])*Tabla1[[#This Row],[CAUDAL DE TRATAMIENTO]] -> 560 | M40: 80 | N40: =F40-F41 -> 120 | O40: =G40-G41 -> 140 | P40: =H40-H41 -> 190 | Q40: =I40-I41 -> 5 | R40: =J40-J41 -> 5 | S40: =(N40*$AC$2) -> 156 | T40: =(O40*$AD$2) -> 185.5 | U40: =(P40*$AE$2) -> 237.5 | V40: =Tabla1[[#This Row],[CONSUMO POL ANIONICO (KG)]] -> 5 | W40: =Tabla1[[#This Row],[CONSUMO POL CATIONICO (KG)]] -> 5 | X40: =(S40*1000)/L40 -> 278.57143 | Y40: =(T40*1000)/L40 -> 331.25 | Z40: =(U40*1000)/L40 -> 424.10714 | AA40: =(V40*1000)/L40 -> 8.9285714 | AB40: =(W40*1000)/L40 -> 8.9285714 | AC40: 1.3 | AD40: 1.325 | AE40: 1.25 | AF40: 2500 | AG40: 2500 | AH40: 830 | AI40: 2818 | AJ40: 6295 | AK40: 19050 | AL40: 22050 | AM40: =S40*AH40 -> 129480 | AN40: =T40*AI40 -> 522739 | AO40: =U40*AJ40 -> 1495062.5 | AP40: =V40*AK40 -> 95250 | AQ40: =W40*AL40 -> 110250 | AR40: =SUM(Tabla1[[#This Row],[COSTO OPERATIVO ACIDO]:[COSTO OPERATIVO CATIONICO]]) -> 2352781.5 | AS40: 3599 | AT40: =AR40/L40 -> 4201.3955
...

Sheet DB QUIMICA
A1: CONSUMO DE QUIMICO | M1: TABLA GRAFICA 1 Y 2 . CONSUMO QUIMICO DETALLADO | U1: TABLA GRAFICA 2. COSTO CONSUMO QUIMICO VS $M3 | AA1: TABLA GRAFICA 3. RO COSTO CONSUMO QUIMICO VS $M3 | AG1: TABLA GRAFICA 4. RO PPM CONSUMO QUIMICO
A2: GEM
B3: CONSUMO QUIMICO PPM
L4: FECHA | M4: CAUDAL TOTAL TRATADO GEM | N4: COF 235 - PPM COAGULANTE | O4: COF 255 - PPM DECOLORANTE | P4: COF 280 - PPM ACIDO | Q4: COF 440 - PPM POL ANIONICO | R4: COF 494 - PPM POL CATIONICO | U4: DIA | V4: CAUDAL TOTAL TRATADO GEM | W4: INDICADOR $m3 | X4: 2024-2 $m3 GEM | Y4: 2024 $m3 GEM | AA4: DÍA | AB4: VOLUMEN ENVIADO A RO (m3) | AC4: LIMITE INDICADOR M3 | AD4: INDICADOR $m3 RO | AG4: DÍA | AH4: VOLUMEN ENVIADO A RO (m3) | AI4: PPM HCL | AJ4: PPM KURIVERTER | AK4: PPM VITEC | AL4: PPM BISULFITO
L5: (en blanco) | M5: -1409760 | N5: -5.3760924 | O5: -3.7949722 | P5: -2.5635569 | Q5: -0.13619339 | R5: -0.088667575 | U5: 1 | V5: 240 | W5: 0 | X5: 3599 | Y5: 4909 | AA5: 1 | AB5: 0 | AC5: 1000 | AD5: 0 | AG5: 1 | AH5: 0 | AI5: 0 | AJ5: 0 | AK5: 0 | AL5: 0
L6: 46082 | M6: 240 | N6: 0 | O6: 0 | P6: 0 | Q6: 0 | R6: 0 | U6: 2 | V6: 1600 | W6: 3863.5328 | X6: 3599 | Y6: 4909 | AA6: 2 | AB6: 463.75 | AC6: 1000 | AD6: 0 | AG6: 2 | AH6: 463.75 | AI6: 0 | AJ6: 0 | AK6: 0 | AL6: 0
L7: 46083 | M7: 1600 | N7: 372.65625 | O7: 343.75 | P7: 390 | Q7: 6.25 | R7: 9.375 | U7: 3 | V7: 1440 | W7: 1946.4653 | X7: 3599 | Y7: 4909 | AA7: 3 | AB7: 1090.694 | AC7: 1000 | AD7: 0 | AG7: 3 | AH7: 1090.694 | AI7: 0 | AJ7: 0 | AK7: 0 | AL7: 0
L8: 46084 | M8: 1440 | N8: 322.04861 | O8: 130.20833 | P8: 0 | Q8: 3.4722222 | R8: 6.9444444 | U8: 4 | V8: 1600 | W8: 2545.6834 | X8: 3599 | Y8: 4909 | AA8: 4 | AB8: 972.35 | AC8: 1000 | AD8: 610.7563 | AG8: 4 | AH8: 972.35 | AI8: 0 | AJ8: 704.38863 | AK8: 281.46677 | AL8: 0
L9: 46085 | M9: 1600 | N9: 339.53125 | O9: 203.125 | P9: 373.75 | Q9: 0 | R9: 0 | U9: 5 | V9: 1760 | W9: 3339.5418 | X9: 3599 | Y9: 4909 | AA9: 5 | AB9: 920.28 | AC9: 1000 | AD9: 1163.0228 | AG9: 5 | AH9: 920.28 | AI9: 0 | AJ9: 378.22204 | AK9: 674.85182 | AL9: 0
L10: 46086 | M10: 1760 | N10: 496.875 | O10: 220.17045 | P10: 450.56818 | Q10: 2.8409091 | R10: 5.6818182 | U10: 6 | V10: 1520 | W10: 3266.3855 | X10: 3599 | Y10: 4909 | AA10: 6 | AB10: 972.565 | AC10: 1000 | AD10: 691.61925 | AG10: 6 | AH10: 972.565 | AI10: 0 | AJ10: 380.97846 | AK10: 378.81381 | AL10: 0
L11: 46087 | M11: 1520 | N11: 575.32895 | O11: 148.02632 | P11: 521.71053 | Q11: 3.2894737 | R11: 9.8684211 | U11: 7 | V11: 1280 | W11: 4834.5277 | X11: 3599 | Y11: 4909 | AA11: 7 | AB11: 544.536 | AC11: 1000 | AD11: 0 | AG11: 7 | AH11: 544.536 | AI11: 0 | AJ11: 0 | AK11: 0 | AL11: 0
L12: 46088 | M12: 1280 | N12: 652.14844 | O12: 273.4375 | P12: 1046.0938 | Q12: 7.8125 | R12: 11.71875 | U12: 8 | V12: 0 | W12: 0 | X12: 3599 | Y12: 4909 | AA12: 8 | AB12: 0 | AC12: 1000 | AD12: 0 | AG12: 8 | AH12: 0 | AI12: 0 | AJ12: 0 | AK12: 0 | AL12: 0
L13: 46089 | M13: 0 | N13: 0 | O13: 0 | P13: 0 | Q13: 0 | R13: 0 | U13: 9 | V13: 1520 | W13: 4048.1164 | X13: 3599 | Y13: 4909 | AA13: 9 | AB13: 908.007 | AC13: 1000 | AD13: 83.885604 | AG13: 9 | AH13: 908.007 | AI13: 0 | AJ13: 123.65621 | AK13: 34.778308 | AL13: 0
L14: 46090 | M14: 1520 | N14: 714.80263 | O14: 197.36842 | P14: 615.78947 | Q14: 3.2894737 | R14: 9.8684211 | U14: 10 | V14: 1520 | W14: 3497.648 | X14: 3599 | Y14: 4909 | AA14: 10 | AB14: 877.677 | AC14: 1000 | AD14: 542.80077 | AG14: 10 | AH14: 877.677 | AI14: 0 | AJ14: 281.4447 | AK14: 299.83456 | AL14: 0
L15: 46091 | M15: 1520 | N15: 523.02632 | O15: 213.81579 | P15: 478.94737 | Q15: 3.2894737 | R15: 9.8684211 | U15: 11 | V15: 1280 | W15: 5348.5871 | X15: 3599 | Y15: 4909 | AA15: 11 | AB15: 822.903 | AC15: 1000 | AD15: 804.85603 | AG15: 11 | AH15: 822.903 | AI15: 0 | AJ15: 395.68945 | AK15: 447.70897 | AL15: 0
L16: 46092 | M16: 1280 | N16: 973.04688 | O16: 263.67188 | P16: 650 | Q16: 7.8125 | R16: 11.71875 | U16: 12 | V16: 1520 | W16: 4138.1046 | X16: 3599 | Y16: 4909 | AA16: 12 | AB16: 791.274 | AC16: 1000 | AD16: 791.33097 | AG16: 12 | AH16: 791.274 | AI16: 0 | AJ16: 581.78441 | AK16: 412.39291 | AL16: 0
L17: 46093 | M17: 1520 | N17: 732.23684 | O17: 246.71053 | P17: 290.78947 | Q17: 3.2894737 | R17: 9.8684211 | U17: 13 | V17: 1280 | W17: 3311.2105 | X17: 3599 | Y17: 4909 | AA17: 13 | AB17: 714.389 | AC17: 1000 | AD17: 558.43525 | AG17: 13 | AH17: 714.389 | AI17: 0 | AJ17: 282.90646 | AK17: 309.42894 | AL17: 0
... L27: 46103 | M27: 0 | N27: 0 | O27: 0 | P27: 0 | Q27: 0 | R27: 0 | U27: 23 | V27: 720 | W27: 2306.0451 | X27: 3599 | Y27: 4909 | AA27: 23 | AB27: 466.818 | AC27: 1000 | AD27: 1059.245 | AG27: 23 | AH27: 466.818 | AI27: 0 | AJ27: 697.51817 | AK27: 563.72697 | AL27: 0
B28: COSTO TTO - CAUDAL TRATADP GEM Vs $M3 | L28: 46104 | M28: 720 | N28: 276.04167 | O28: 173.61111 | P28: 180.55556 | Q28: 6.9444444 | R28: 6.9444444 | U28: 24 | V28: 1295 | W28: 1779.271 | X28: 3599 | Y28: 4909 | AA28: 24 | AB28: 989.193 | AC28: 1000 | AD28: 335.41885 | AG28: 24 | AH28: 989.193 | AI28: 0 | AJ28: 351.87287 | AK28: 159.61975 | AL28: 0
L29: 46105 | M29: 1295 | N29: 266.02317 | O29: 96.525097 | P29: 120.46332 | Q29: 6.1776062 | R29: 9.2664093 | U29: 25 | V29: 1200 | W29: 2688.2196 | X29: 3599 | Y29: 4909 | AA29: 25 | AB29: 936.422 | AC29: 1000 | AD29: 27.568317 | AG29: 25 | AH29: 936.422 | AI29: 0 | AJ29: 119.90396 | AK29: 0 | AL29: 0
L30: 46106 | M30: 1200 | N30: 342.29167 | O30: 125 | P30: 303.33333 | Q30: 16.666667 | R30: 16.666667 | U30: 26 | V30: 1360 | W30: 1857.4879 | X30: 3599 | Y30: 4909 | AA30: 26 | AB30: 873.699 | AC30: 1000 | AD30: 88.642355 | AG30: 26 | AH30: 873.699 | AI30: 0 | AJ30: 385.53564 | AK30: 0 | AL30: 0
L31: 46107 | M31: 1360 | N31: 204.59559 | O31: 91.911765 | P31: 286.76471 | Q31: 7.3529412 | R31: 14.705882 | U31: 27 | V31: 1120 | W31: 2451.2125 | X31: 3599 | Y31: 4909 | AA31: 27 | AB31: 841.701 | AC31: 1000 | AD31: 64.40852 | AG31: 27 | AH31: 841.701 | AI31: 0 | AJ31: 280.13448 | AK31: 0 | AL31: 0
L32: 46108 | M32: 1120 | N32: 390.40179 | O32: 145.08929 | P32: 290.17857 | Q32: 0 | R32: 8.9285714 | U32: 28 | V32: 1520 | W32: 2768.4122 | X32: 3599 | Y32: 4909 | AA32: 28 | AB32: 368.133 | AC32: 1000 | AD32: 56.100548 | AG32: 28 | AH32: 368.133 | AI32: 0 | AJ32: 244.0003 | AK32: 0 | AL32: 0
L33: 46109 | M33: 1520 | N33: 427.13816 | O33: 131.57895 | P33: 299.34211 | Q33: 6.5789474 | R33: 16.447368 | U33: 29 | V33: 480 | W33: 1060.8865 | X33: 3599 | Y33: 4909 | AA33: 29 | AB33: 0 | AC33: 1000 | AD33: 0 | AG33: 29 | AH33: 0 | AI33: 0 | AJ33: 0 | AK33: 0 | AL33: 0
L34: 46110 | M34: 480 | N34: 220.83333 | O34: 26.041667 | P34: 54.166667 | Q34: 0 | R34: 10.416667 | U34: 30 | V34: 0 | W34: 0 | X34: 3599 | Y34: 4909 | AA34: 30 | AB34: 0 | AC34: 1000 | AD34: 0 | AG34: 30 | AH34: 0 | AI34: 0 | AJ34: 0 | AK34: 0 | AL34: 0
L35: 46111 | M35: 0 | N35: 0 | O35: 0 | P35: 0 | Q35: 0 | R35: 0 | U35: 31 | V35: 0 | W35: 0 | X35: 3599 | Y35: 4909 | AA35: 31 | AB35: 0 | AC35: 1000 | AD35: 0 | AG35: 31 | AH35: 0 | AI35: 0 | AJ35: 0 | AK35: 0 | AL35: 0
L36: 46112 | M36: 0 | N36: 0 | O36: 0 | P36: 0 | Q36: 0 | R36: 0 | U36: Total general | V36: 32829 | W36: 3119.2261 | X36: 3599 | Y36: 4909 | AA36: Total general | AB36: 18998.49 | AC36: 1000 | AD36: 504.39461 | AG36: 0 | AH36: 0 | AI36: 0 | AJ36: 0 | AK36: 0 | AL36: 0
L37: Total general | M37: -1376931 | N37: -16.91697 | O37: -8.1612659 | P37: -11.688313 | Q37: -0.26145101 | R37: -0.33770755 | AG37: Total general | AH37: 18998.49 | AI37: 0 | AJ37: 334.03209 | AK37: 268.16536 | AL37: 0
B51: CONSOLIDADO COSTO TTO - CAUDAL TRATADP GEM Vs $M3 | F51: CONSOLIDADO COSTO TTO - CAUDAL TRATADP RO Vs $M3
B53: ACUMULADO CAUDAL TRATADO GEM | D53: =+'INVENTARIO Y CONSUMO GEM '!AR98 -> 1.0240107e+08 | F53: ACUMULADO CAUDAL TRATADO RO | H53: =+Tabla2[[#Totals],[COSTO QUIMICA ]] -> 9582735.9
B54: TOTAL CAUDAL TRATADO GEM | C54: $m3 | D54: 114996411 | F54: TOTAL CAUDAL TRATADO RO | G54: $m3 | H54: 2515885.2
A55: GEM | B55: =+GETPIVOTDATA(" CAUDAL TOTAL TRATADO GEM ",$U$4) -> 32829 | C55: =+D53/B55 -> 3119.2261 | D55: =C55*B55 -> 1.0240107e+08 | F55: =+GETPIVOTDATA(" VOLUMEN ENVIADO A RO (m3)",$AA$4) -> 18998.49 | G55: =H53/F55 -> 504.39461 | H55: =G55*F55 -> 9582735.9
A56: TH | B56: 13239 | C56: =+D53/B56 -> 7734.8043
A58: OSMOSIS INVERSA
B81: CONSUMO QUIMICO PPM

Sheet CONSUMO QUÍMICA-CAUDALES GEM  
A1: CONSOLIDADO CONSUMO DIARIO QUÍMICA (Litros)
B2: DIAS
A3: PRODUCTOS QUÍMICOS | B3: 1 | C3: 2 | D3: 3 | E3: 4 | F3: 5 | G3: 6 | H3: 7 | I3: 8 | J3: 9 | K3: 10 | L3: 11 | M3: 12 | N3: 13 | O3: 14 | P3: 15 | Q3: 16 | R3: 17 | S3: 18 | T3: 19 | U3: 20 | V3: 21 | W3: 22 | X3: 23 | Y3: 24 | Z3: 25 | AA3: 26 | AB3: 27 | AC3: 28 | AD3: 29 | AE3: 30 | AF3: 31 | AG3: (en blanco) | AH3: Total general
A4: COF 280 ACIDO (L) | B4: 0 | C4: 480 | D4: 0 | E4: 460 | F4: 610 | G4: 610 | H4: 1030 | I4: 0 | J4: 720 | K4: 560 | L4: 640 | M4: 340 | N4: 360 | O4: 210 | P4: 0 | Q4: 300 | R4: 420 | S4: 680 | T4: 290 | U4: 130 | V4: 340 | W4: 0 | X4: 100 | Y4: 120 | Z4: 280 | AA4: 300 | AB4: 250 | AC4: 350 | AD4: 20 | AE4: 0 | AF4: 0 | AG4: 2780 | AH4: 12380
A5: COF 235 COAGULANTE (L) | B5: 0 | C5: 450 | D5: 350 | E5: 410 | F5: 660 | G5: 660 | H5: 630 | I5: 0 | J5: 820 | K5: 600 | L5: 940 | M5: 840 | N5: 470 | O5: 340 | P5: 0 | Q5: 800 | R5: 510 | S5: 460 | T5: 330 | U5: 440 | V5: 320 | W5: 0 | X5: 150 | Y5: 260 | Z5: 310 | AA5: 210 | AB5: 330 | AC5: 490 | AD5: 80 | AE5: 0 | AF5: 0 | AG5: 5720 | AH5: 17580
A6: COF 255 DECOLORANTE (L) | B6: 0 | C6: 440 | D6: 150 | E6: 260 | F6: 310 | G6: 180 | H6: 280 | I6: 0 | J6: 240 | K6: 260 | L6: 270 | M6: 300 | N6: 200 | O6: 100 | P6: 0 | Q6: 150 | R6: 190 | S6: 170 | T6: 140 | U6: 240 | V6: 110 | W6: 0 | X6: 100 | Y6: 100 | Z6: 120 | AA6: 100 | AB6: 130 | AC6: 160 | AD6: 10 | AE6: 0 | AF6: 0 | AG6: 4280 | AH6: 8990
A7: COF 440 POL ANIONICO (KG) | B7: 0 | C7: 10 | D7: 5 | E7: 0 | F7: 5 | G7: 5 | H7: 10 | I7: 0 | J7: 5 | K7: 5 | L7: 10 | M7: 5 | N7: 10 | O7: 5 | P7: 0 | Q7: 10 | R7: 5 | S7: 8 | T7: 7 | U7: 5 | V7: 5 | W7: 0 | X7: 5 | Y7: 8 | Z7: 20 | AA7: 10 | AB7: 0 | AC7: 10 | AD7: 0 | AE7: 0 | AF7: 0 | AG7: 192 | AH7: 360
A8: COF 494 POL CATIONICO (KG) | B8: 0 | C8: 15 | D8: 10 | E8: 0 | F8: 10 | G8: 15 | H8: 15 | I8: 0 | J8: 15 | K8: 15 | L8: 15 | M8: 15 | N8: 15 | O8: 15 | P8: 15 | Q8: 15 | R8: 15 | S8: 18 | T8: 15 | U8: 5 | V8: 5 | W8: 0 | X8: 5 | Y8: 12 | Z8: 20 | AA8: 20 | AB8: 10 | AC8: 25 | AD8: 5 | AE8: 0 | AF8: 0 | AG8: 125 | AH8: 465
A10: CONSOLIDADO CONSUMO DIARIO QUÍMICA (Kg)
B11: DIAS
A12: PRODUCTOS QUÍMICOS | B12: 1 | C12: 2 | D12: 3 | E12: 4 | F12: 5 | G12: 6 | H12: 7 | I12: 8 | J12: 9 | K12: 10 | L12: 11 | M12: 12 | N12: 13 | O12: 14 | P12: 15 | Q12: 16 | R12: 17 | S12: 18 | T12: 19 | U12: 20 | V12: 21 | W12: 22 | X12: 23 | Y12: 24 | Z12: 25 | AA12: 26 | AB12: 27 | AC12: 28 | AD12: 29 | AE12: 30 | AF12: 31 | AG12: (en blanco) | AH12: Total general
A13: COF 280 - KG ACIDO | B13: 0 | C13: 624 | D13: 0 | E13: 598 | F13: 793 | G13: 793 | H13: 1339 | I13: 0 | J13: 936 | K13: 728 | L13: 832 | M13: 442 | N13: 468 | O13: 273 | P13: 0 | Q13: 390 | R13: 546 | S13: 884 | T13: 377 | U13: 169 | V13: 442 | W13: 0 | X13: 130 | Y13: 156 | Z13: 364 | AA13: 390 | AB13: 325 | AC13: 455 | AD13: 26 | AE13: 0 | AF13: 0 | AG13: 3614 | AH13: 16094
A14: COF 235 - KG COAGULANTE | B14: 0 | C14: 596.25 | D14: 463.75 | E14: 543.25 | F14: 874.5 | G14: 874.5 | H14: 834.75 | I14: 0 | J14: 1086.5 | K14: 795 | L14: 1245.5 | M14: 1113 | N14: 622.75 | O14: 450.5 | P14: 0 | Q14: 1060 | R14: 675.75 | S14: 609.5 | T14: 437.25 | U14: 583 | V14: 424 | W14: 0 | X14: 198.75 | Y14: 344.5 | Z14: 410.75 | AA14: 278.25 | AB14: 437.25 | AC14: 649.25 | AD14: 106 | AE14: 0 | AF14: 0 | AG14: 7579 | AH14: 23293.5
A15: COF 255 - KG DECOLORANTE | B15: 0 | C15: 550 | D15: 187.5 | E15: 325 | F15: 387.5 | G15: 225 | H15: 350 | I15: 0 | J15: 300 | K15: 325 | L15: 337.5 | M15: 375 | N15: 250 | O15: 125 | P15: 0 | Q15: 187.5 | R15: 237.5 | S15: 212.5 | T15: 175 | U15: 300 | V15: 137.5 | W15: 0 | X15: 125 | Y15: 125 | Z15: 150 | AA15: 125 | AB15: 162.5 | AC15: 200 | AD15: 12.5 | AE15: 0 | AF15: 0 | AG15: 5350 | AH15: 11237.5
A16: COF 440 - KG POL ANIONICO | B16: 0 | C16: 10 | D16: 5 | E16: 0 | F16: 5 | G16: 5 | H16: 10 | I16: 0 | J16: 5 | K16: 5 | L16: 10 | M16: 5 | N16: 10 | O16: 5 | P16: 0 | Q16: 10 | R16: 5 | S16: 8 | T16: 7 | U16: 5 | V16: 5 | W16: 0 | X16: 5 | Y16: 8 | Z16: 20 | AA16: 10 | AB16: 0 | AC16: 10 | AD16: 0 | AE16: 0 | AF16: 0 | AG16: 192 | AH16: 360
