Workbook
Name SegmentaciónDeDatos_FECHA: #N/A
Name SegmentaciónDeDatos_FECHA1: #N/A
Name SegmentaciónDeDatos_FECHA2: #N/A

Sheet INVENTARIO Y CONSUMO GEM  
A1: FECHA | B1: DIA | C1: ANALISIS TURNO | D1: # TURNO | E1: DILIGENCIAR BITACORA | F1: FINAL ACIDO (L) | G1: FINAL COAGULANTE (L) | H1: FINAL DECOLORANTE (L) | I1: FINAL POL ANIONICO (KG) | J1: FINAL POL CATIONICO (KG) | K1: Lectura Horometro INICIAL (06:00) | L1: CAUDAL TOTAL TRATADO GEM | M1: CAUDAL DE TRATAMIENTO | N1: CONSUMO LITROS ACIDO (L) | O1: CONSUMO LITROS COAGULANTE (L) | P1: CONSUMO LITROS DECOLORANTE (L) | Q1: CONSUMO POL ANIONICO (KG) | R1: CONSUMO POL CATIONICO (KG) | S1: KG ACIDO | T1: KG COAGULANTE | U1: KG DECOLORANTE | V1: KG POL ANIONICO | W1: KG POL CATIONICO | X1: PPM ACIDO | Y1: PPM COAGULANTE | Z1: PPM DECOLORANTE | AA1: PPM POL ANIONICO | AB1: PPM POL CATIONICO | AC1: DENSIDAD ACIDO | AD1: DENSIDAD COAGULANTE | AE1: DENSIDAD DECOLORANTE | AF1: DENSIDAD ANIONICO | AG1: DENSIDAD CATIONICO | AH1: PRECIO (KG) ACIDO | AI1: PRECIO (KG) COAGULANTE | AJ1: PRECIO (KG) DECOLORANTE | AK1: PRECIO (KG) ANIONICO | AL1: PRECIO (KG) CATIONICO | AM1: COSTO OPERATIVO ACIDO | AN1: COSTO OPERATIVO COAGULANTE | AO1: COSTO OPERATIVO DECOLORANTE | AP1: COSTO OPERATIVO ANIONICO | AQ1: COSTO OPERATIVO CATIONICO | AR1: COSTO QUIMICA | AS1: LIMITE INDICADOR M3 | AT1: $ m3
A2: 46054 | B2: =DAY(Tabla1[[#This Row],[FECHA]]) -> 1 | C2: 1 (NOCHE) | D2: 1 | E2: FINAL TURNO 3 | F2: 4360 | G2: 6480 | H2: 1510 | I2: 165 | J2: 60 | K2: 16839 | L2: =+(K3-Tabla1[[#This Row],[Lectura Horometro INICIAL (06:00)]])*Tabla1[[#This Row],[CAUDAL DE TRATAMIENTO]] -> 0 | M2: 75 | N2: =F2-F3 -> 0 | O2: =G2-G3 -> 0 | P2: =H2-H3 -> 0 | Q2: =I2-I3 -> 0 | R2: 0 | S2: =(N2*$AC$2) -> 0 | T2: =(O2*$AD$2) -> 0 | U2: =(P2*$AE$2) -> 0 | V2: =Tabla1[[#This Row],[CONSUMO POL ANIONICO (KG)]] -> 0 | W2: =Tabla1[[#This Row],[CONSUMO POL CATIONICO (KG)]] -> 0 | X2: =(S2*1000)/L2 -> #DIV/0! | Y2: =(T2*1000)/L2 -> #DIV/0! | Z2: =(U2*1000)/L2 -> #DIV/0! | AA2: =(V2*1000)/L2 -> #DIV/0! | AB2: =(W2*1000)/L2 -> #DIV/0! | AC2: 1.3 | AD2: 1.325 | AE2: 1.25 | AF2: 2500 | AG2: 2500 | AH2: 830 | AI2: 2900 | AJ2: 6295 | AK2: 19050 | AL2: 22050 | AM2: =S2*AH2 -> 0 | AN2: =T2*AI2 -> 0 | AO2: =U2*AJ2 -> 0 | AP2: =V2*AK2 -> 0 | AQ2: =W2*AL2 -> 0 | AR2: =SUM(Tabla1[[#This Row],[COSTO OPERATIVO ACIDO]:[COSTO OPERATIVO CATIONICO]]) -> 0 | AS2: 5250 | AT2: =AR2/L2 -> #DIV/0!
A3: =A2 -> 46054 | B3: =DAY(Tabla1[[#This Row],[FECHA]]) -> 1 | C3: 2 (MAÑANA) | D3: 2 | E3: FINAL TURNO 1 | F3: 4360 | G3: 6480 | H3: 1510 | I3: 165 | J3: 60 | K3: 16839 | L3: =+(K4-Tabla1[[#This Row],[Lectura Horometro INICIAL (06:00)]])*Tabla1[[#This Row],[CAUDAL DE TRATAMIENTO]] -> 0 | M3: 75 | N3: =F3-F4 -> 0 | O3: =G3-G4 -> 0 | P3: =H3-H4 -> 0 | Q3: =I3-I4 -> 0 | R3: 0 | S3: =(N3*$AC$2) -> 0 | T3: =(O3*$AD$2) -> 0 | U3: =(P3*$AE$2) -> 0 | V3: =Tabla1[[#This Row],[CONSUMO POL ANIONICO (KG)]] -> 0 | W3: =Tabla1[[#This Row],[CONSUMO POL CATIONICO (KG)]] -> 0 | X3: =(S3*1000)/L3 -> #DIV/0! | Y3: =(T3*1000)/L3 -> #DIV/0! | Z3: =(U3*1000)/L3 -> #DIV/0! | AA3: =(V3*1000)/L3 -> #DIV/0! | AB3: =(W3*1000)/L3 -> #DIV/0! | AC3: 1.3 | AD3: 1.325 | AE3: 1.25 | AF3: 2500 | AG3: 2500 | AH3: 830 | AI3: 2900 | AJ3: 6295 | AK3: 19050 | AL3: 22050 | AM3: =S3*AH3 -> 0 | AN3: =T3*AI3 -> 0 | AO3: =U3*AJ3 -> 0 | AP3: =V3*AK3 -> 0 | AQ3: =W3*AL3 -> 0 | AR3: =SUM(Tabla1[[#This Row],[COSTO OPERATIVO ACIDO]:[COSTO OPERATIVO CATIONICO]]) -> 0 | AS3: 5250 | AT3: =AR3/L3 -> #DIV/0!
A4: =A3 -> 46054 | B4: =DAY(Tabla1[[#This Row],[FECHA]]) -> 1 | C4: 3(TARDE) | D4: 3 | E4: FINAL TURNO 2 | F4: 4360 | G4: 6480 | H4: 1510 | I4: 165 | J4: 60 | K4: 16839 | L4: =+(K5-Tabla1[[#This Row],[Lectura Horometro INICIAL (06:00)]])*Tabla1[[#This Row],[CAUDAL DE TRATAMIENTO]] -> 0 | M4: 75 | N4: =F4-F5 -> 0 | O4: =G4-G5 -> 0 | P4: =H4-H5 -> 0 | Q4: =I4-I5 -> 0 | R4: 0 | S4: =(N4*$AC$2) -> 0 | T4: =(O4*$AD$2) -> 0 | U4: =(P4*$AE$2) -> 0 | V4: =Tabla1[[#This Row],[CONSUMO POL ANIONICO (KG)]] -> 0 | W4: =Tabla1[[#This Row],[CONSUMO POL CATIONICO (KG)]] -> 0 | X4: =(S4*1000)/L4 -> #DIV/0! | Y4: =(T4*1000)/L4 -> #DIV/0! | Z4: =(U4*1000)/L4 -> #DIV/0! | AA4: =(V4*1000)/L4 -> #DIV/0! | AB4: =(W4*1000)/L4 -> #DIV/0! | AC4: 1.3 | AD4: 1.325 | AE4: 1.25 | AF4: 2500 | AG4: 2500 | AH4: 830 | AI4: 2900 | AJ4: 6295 | AK4: 19050 | AL4: 22050 | AM4: =S4*AH4 -> 0 | AN4: =T4*AI4 -> 0 | AO4: =U4*AJ4 -> 0 | AP4: =V4*AK4 -> 0 | AQ4: =W4*AL4 -> 0 | AR4: =SUM(Tabla1[[#This Row],[COSTO OPERATIVO ACIDO]:[COSTO OPERATIVO CATIONICO]]) -> 0 | AS4: 5250 | AT4: =AR4/L4 -> #DIV/0!
A5: 46055 | B5: =DAY(Tabla1[[#This Row],[FECHA]]) -> 2 | C5: 2 (NOCHE) | D5: 4 | E5: FINAL TURNO 3 | F5: 4360 | G5: 6480 | H5: 1510 | I5: 165 | J5: 60 | K5: 16839 | L5: =+(K6-Tabla1[[#This Row],[Lectura Horometro INICIAL (06:00)]])*Tabla1[[#This Row],[CAUDAL DE TRATAMIENTO]] -> 225 | M5: 75 | N5: =F5-F6 -> 70 | O5: =G5-G6 -> 300 | P5: =H5-H6 -> 30 | Q5: =I5-I6 -> 0 | R5: =J5-J6 -> 5 | S5: =(N5*$AC$2) -> 91 | T5: =(O5*$AD$2) -> 397.5 | U5: =(P5*$AE$2) -> 37.5 | V5: =Tabla1[[#This Row],[CONSUMO POL ANIONICO (KG)]] -> 0 | W5: =Tabla1[[#This Row],[CONSUMO POL CATIONICO (KG)]] -> 5 | X5: =(S5*1000)/L5 -> 404.44444 | Y5: =(T5*1000)/L5 -> 1766.6667 | Z5: =(U5*1000)/L5 -> 166.66667 | AA5: =(V5*1000)/L5 -> 0 | AB5: =(W5*1000)/L5 -> 22.222222 | AC5: 1.3 | AD5: 1.325 | AE5: 1.25 | AF5: 2500 | AG5: 2500 | AH5: 830 | AI5: 2900 | AJ5: 6295 | AK5: 19050 | AL5: 22050 | AM5: =S5*AH5 -> 75530 | AN5: =T5*AI5 -> 1152750 | AO5: =U5*AJ5 -> 236062.5 | AP5: =V5*AK5 -> 0 | AQ5: =W5*AL5 -> 110250 | AR5: =SUM(Tabla1[[#This Row],[COSTO OPERATIVO ACIDO]:[COSTO OPERATIVO CATIONICO]]) -> 1574592.5 | AS5: 5250 | AT5: =AR5/L5 -> 6998.1889
A6: =A5 -> 46055 | B6: =DAY(Tabla1[[#This Row],[FECHA]]) -> 2 | C6: 3 (MAÑANA) | D6: 5 | E6: FINAL TURNO 1 | F6: 4290 | G6: 6180 | H6: 1480 | I6: 165 | J6: 55 | K6: 16842 | L6: =+(K7-Tabla1[[#This Row],[Lectura Horometro INICIAL (06:00)]])*Tabla1[[#This Row],[CAUDAL DE TRATAMIENTO]] -> 300 | M6: 75 | N6: =F6-F7 -> 340 | O6: =G6-G7 -> 340 | P6: =H6-H7 -> 100 | Q6: =I6-I7 -> 0 | R6: =J6-J7 -> 5 | S6: =(N6*$AC$2) -> 442 | T6: =(O6*$AD$2) -> 450.5 | U6: =(P6*$AE$2) -> 125 | V6: =Tabla1[[#This Row],[CONSUMO POL ANIONICO (KG)]] -> 0 | W6: =Tabla1[[#This Row],[CONSUMO POL CATIONICO (KG)]] -> 5 | X6: =(S6*1000)/L6 -> 1473.3333 | Y6: =(T6*1000)/L6 -> 1501.6667 | Z6: =(U6*1000)/L6 -> 416.66667 | AA6: =(V6*1000)/L6 -> 0 | AB6: =(W6*1000)/L6 -> 16.666667 | AC6: 1.3 | AD6: 1.325 | AE6: 1.25 | AF6: 2500 | AG6: 2500 | AH6: 830 | AI6: 2900 | AJ6: 6295 | AK6: 19050 | AL6: 22050 | AM6: =S6*AH6 -> 366860 | AN6: =T6*AI6 -> 1306450 | AO6: =U6*AJ6 -> 786875 | AP6: =V6*AK6 -> 0 | AQ6: =W6*AL6 -> 110250 | AR6: =SUM(Tabla1[[#This Row],[COSTO OPERATIVO ACIDO]:[COSTO OPERATIVO CATIONICO]]) -> 2570435 | AS6: 5250 | AT6: =AR6/L6 -> 8568.1167
A7: =A6 -> 46055 | B7: =DAY(Tabla1[[#This Row],[FECHA]]) -> 2 | C7: 3(TARDE) | D7: 6 | E7: FINAL TURNO 2 | F7: 3950 | G7: 5840 | H7: 1380 | I7: 165 | J7: 50 | K7: 16846 | L7: =+(K8-Tabla1[[#This Row],[Lectura Horometro INICIAL (06:00)]])*Tabla1[[#This Row],[CAUDAL DE TRATAMIENTO]] -> 600 | M7: 75 | N7: =F7-F8 -> 30 | O7: =G7-G8 -> 180 | P7: =H7-H8 -> 40 | Q7: =I7-I8 -> 2.5 | R7: =J7-J8 -> 5 | S7: =(N7*$AC$2) -> 39 | T7: =(O7*$AD$2) -> 238.5 | U7: =(P7*$AE$2) -> 50 | V7: =Tabla1[[#This Row],[CONSUMO POL ANIONICO (KG)]] -> 2.5 | W7: =Tabla1[[#This Row],[CONSUMO POL CATIONICO (KG)]] -> 5 | X7: =(S7*1000)/L7 -> 65 | Y7: =(T7*1000)/L7 -> 397.5 | Z7: =(U7*1000)/L7 -> 83.333333 | AA7: =(V7*1000)/L7 -> 4.1666667 | AB7: =(W7*1000)/L7 -> 8.3333333 | AC7: 1.3 | AD7: 1.325 | AE7: 1.25 | AF7: 2500 | AG7: 2500 | AH7: 830 | AI7: 2900 | AJ7: 6295 | AK7: 19050 | AL7: 22050 | AM7: =S7*AH7 -> 32370 | AN7: =T7*AI7 -> 691650 | AO7: =U7*AJ7 -> 314750 | AP7: =V7*AK7 -> 47625 | AQ7: =W7*AL7 -> 110250 | AR7: =SUM(Tabla1[[#This Row],[COSTO OPERATIVO ACIDO]:[COSTO OPERATIVO CATIONICO]]) -> 1196645 | AS7: 5250 | AT7: =AR7/L7 -> 1994.4083
A8: 46056 | B8: =DAY(Tabla1[[#This Row],[FECHA]]) -> 3 | C8: 3 (NOCHE) | D8: 7 | E8: FINAL TURNO 3 | F8: =+AVERAGE(F7,F9) -> 3920 | G8: =+AVERAGE(G7,G9) -> 5660 | H8: =+AVERAGE(H7,H9) -> 1340 | I8: =+AVERAGE(I7,I9) -> 162.5 | J8: =+AVERAGE(J7,J9) -> 45 | K8: 16854 | L8: =+(K9-Tabla1[[#This Row],[Lectura Horometro INICIAL (06:00)]])*Tabla1[[#This Row],[CAUDAL DE TRATAMIENTO]] -> 600 | M8: 75 | N8: =F8-F9 -> 30 | O8: =G8-G9 -> 180 | P8: =H8-H9 -> 40 | Q8: =I8-I9 -> 2.5 | R8: =J8-J9 -> 5 | S8: =(N8*$AC$2) -> 39 | T8: =(O8*$AD$2) -> 238.5 | U8: =(P8*$AE$2) -> 50 | V8: =Tabla1[[#This Row],[CONSUMO POL ANIONICO (KG)]] -> 2.5 | W8: =Tabla1[[#This Row],[CONSUMO POL CATIONICO (KG)]] -> 5 | X8: =(S8*1000)/L8 -> 65 | Y8: =(T8*1000)/L8 -> 397.5 | Z8: =(U8*1000)/L8 -> 83.333333 | AA8: =(V8*1000)/L8 -> 4.1666667 | AB8: =(W8*1000)/L8 -> 8.3333333 | AC8: 1.3 | AD8: 1.325 | AE8: 1.25 | AF8: 2500 | AG8: 2500 | AH8: 830 | AI8: 2900 | AJ8: 6295 | AK8: 19050 | AL8: 22050 | AM8: =S8*AH8 -> 32370 | AN8: =T8*AI8 -> 691650 | AO8: =U8*AJ8 -> 314750 | AP8: =V8*AK8 -> 47625 | AQ8: =W8*AL8 -> 110250 | AR8: =SUM(Tabla1[[#This Row],[COSTO OPERATIVO ACIDO]:[COSTO OPERATIVO CATIONICO]]) -> 1196645 | AS8: 5250 | AT8: =AR8/L8 -> 1994.4083
A9: =A8 -> 46056 | B9: =DAY(Tabla1[[#This Row],[FECHA]]) -> 3 | C9: 4 (MAÑANA) | D9: 8 | E9: FINAL TURNO 1 | F9: 3890 | G9: 5480 | H9: 1300 | I9: 160 | J9: 40 | K9: 16862 | L9: =+(K10-Tabla1[[#This Row],[Lectura Horometro INICIAL (06:00)]])*Tabla1[[#This Row],[CAUDAL DE TRATAMIENTO]] -> 525 | M9: 75 | N9: =F9-F10 -> 210 | O9: =G9-G10 -> 340 | P9: =H9-H10 -> 120 | Q9: =I9-I10 -> 5 | R9: =J9-J10 -> 5 | S9: =(N9*$AC$2) -> 273 | T9: =(O9*$AD$2) -> 450.5 | U9: =(P9*$AE$2) -> 150 | V9: =Tabla1[[#This Row],[CONSUMO POL ANIONICO (KG)]] -> 5 | W9: =Tabla1[[#This Row],[CONSUMO POL CATIONICO (KG)]] -> 5 | X9: =(S9*1000)/L9 -> 520 | Y9: =(T9*1000)/L9 -> 858.09524 | Z9: =(U9*1000)/L9 -> 285.71429 | AA9: =(V9*1000)/L9 -> 9.5238095 | AB9: =(W9*1000)/L9 -> 9.5238095 | AC9: 1.3 | AD9: 1.325 | AE9: 1.25 | AF9: 2500 | AG9: 2500 | AH9: 830 | AI9: 2900 | AJ9: 6295 | AK9: 19050 | AL9: 22050 | AM9: =S9*AH9 -> 226590 | AN9: =T9*AI9 -> 1306450 | AO9: =U9*AJ9 -> 944250 | AP9: =V9*AK9 -> 95250 | AQ9: =W9*AL9 -> 110250 | AR9: =SUM(Tabla1[[#This Row],[COSTO OPERATIVO ACIDO]:[COSTO OPERATIVO CATIONICO]]) -> 2682790 | AS9: 5250 | AT9: =AR9/L9 -> 5110.0762
A10: =A9 -> 46056 | B10: =DAY(Tabla1[[#This Row],[FECHA]]) -> 3 | C10: 3(TARDE) | D10: 9 | E10: FINAL TURNO 2 | F10: 3680 | G10: 5140 | H10: 1180 | I10: 155 | J10: 35 | K10: 16869 | L10: =+(K11-Tabla1[[#This Row],[Lectura Horometro INICIAL (06:00)]])*Tabla1[[#This Row],[CAUDAL DE TRATAMIENTO]] -> 525 | M10: 75 | N10: =F10-F11 -> 310 | O10: =G10-G11 -> 240 | P10: =H10-H11 -> 130 | Q10: 0 | R10: 0 | S10: =(N10*$AC$2) -> 403 | T10: =(O10*$AD$2) -> 318 | U10: =(P10*$AE$2) -> 162.5 | V10: =Tabla1[[#This Row],[CONSUMO POL ANIONICO (KG)]] -> 0 | W10: =Tabla1[[#This Row],[CONSUMO POL CATIONICO (KG)]] -> 0 | X10: =(S10*1000)/L10 -> 767.61905 | Y10: =(T10*1000)/L10 -> 605.71429 | Z10: =(U10*1000)/L10 -> 309.52381 | AA10: =(V10*1000)/L10 -> 0 | AB10: =(W10*1000)/L10 -> 0 | AC10: 1.3 | AD10: 1.325 | AE10: 1.25 | AF10: 2500 | AG10: 2500 | AH10: 830 | AI10: 2900 | AJ10: 6295 | AK10: 19050 | AL10: 22050 | AM10: =S10*AH10 -> 334490 | AN10: =T10*AI10 -> 922200 | AO10: =U10*AJ10 -> 1022937.5 | AP10: =V10*AK10 -> 0 | AQ10: =W10*AL10 -> 0 | AR10: =SUM(Tabla1[[#This Row],[COSTO OPERATIVO ACIDO]:[COSTO OPERATIVO CATIONICO]]) -> 2279627.5 | AS10: 5250 | AT10: =AR10/L10 -> 4342.1476
A11: 46057 | B11: =DAY(Tabla1[[#This Row],[FECHA]]) -> 4 | C11: 4 (NOCHE) | D11: 10 | E11: FINAL TURNO 3 | F11: 3370 | G11: 4900 | H11: 1050 | I11: 155 | J11: 30 | K11: 16876 | L11: =+(K12-Tabla1[[#This Row],[Lectura Horometro INICIAL (06:00)]])*Tabla1[[#This Row],[CAUDAL DE TRATAMIENTO]] -> 525 | M11: 75 | N11: =F11-F12 -> 280 | O11: =G11-G12 -> 210 | P11: =H11-H12 -> 110 | Q11: 0 | R11: 0 | S11: =(N11*$AC$2) -> 364 | T11: =(O11*$AD$2) -> 278.25 | U11: =(P11*$AE$2) -> 137.5 | V11: =Tabla1[[#This Row],[CONSUMO POL ANIONICO (KG)]] -> 0 | W11: =Tabla1[[#This Row],[CONSUMO POL CATIONICO (KG)]] -> 0 | X11: =(S11*1000)/L11 -> 693.33333 | Y11: =(T11*1000)/L11 -> 530 | Z11: =(U11*1000)/L11 -> 261.90476 | AA11: =(V11*1000)/L11 -> 0 | AB11: =(W11*1000)/L11 -> 0 | AC11: 1.3 | AD11: 1.325 | AE11: 1.25 | AF11: 2500 | AG11: 2500 | AH11: 830 | AI11: 2900 | AJ11: 6295 | AK11: 19050 | AL11: 22050 | AM11: =S11*AH11 -> 302120 | AN11: =T11*AI11 -> 806925 | AO11: =U11*AJ11 -> 865562.5 | AP11: =V11*AK11 -> 0 | AQ11: =W11*AL11 -> 0 | AR11: =SUM(Tabla1[[#This Row],[COSTO OPERATIVO ACIDO]:[COSTO OPERATIVO CATIONICO]]) -> 1974607.5 | AS11: 5250 | AT11: =AR11/L11 -> 3761.1571
A12: =A11 -> 46057 | B12: =DAY(Tabla1[[#This Row],[FECHA]]) -> 4 | C12: 5 (MAÑANA) | D12: 11 | E12: FINAL TURNO 1 | F12: 3090 | G12: 4690 | H12: 940 | I12: 150 | J12: 25 | K12: 16883 | L12: =+(K13-Tabla1[[#This Row],[Lectura Horometro INICIAL (06:00)]])*Tabla1[[#This Row],[CAUDAL DE TRATAMIENTO]] -> 525 | M12: 75 | N12: =F12-F13 -> 280 | O12: =G12-G13 -> 280 | P12: =H12-H13 -> 40 | Q12: 0 | R12: 0 | S12: =(N12*$AC$2) -> 364 | T12: =(O12*$AD$2) -> 371 | U12: =(P12*$AE$2) -> 50 | V12: =Tabla1[[#This Row],[CONSUMO POL ANIONICO (KG)]] -> 0 | W12: =Tabla1[[#This Row],[CONSUMO POL CATIONICO (KG)]] -> 0 | X12: =(S12*1000)/L12 -> 693.33333 | Y12: =(T12*1000)/L12 -> 706.66667 | Z12: =(U12*1000)/L12 -> 95.238095 | AA12: =(V12*1000)/L12 -> 0 | AB12: =(W12*1000)/L12 -> 0 | AC12: 1.3 | AD12: 1.325 | AE12: 1.25 | AF12: 2500 | AG12: 2500 | AH12: 830 | AI12: 2900 | AJ12: 6295 | AK12: 19050 | AL12: 22050 | AM12: =S12*AH12 -> 302120 | AN12: =T12*AI12 -> 1075900 | AO12: =U12*AJ12 -> 314750 | AP12: =V12*AK12 -> 0 | AQ12: =W12*AL12 -> 0 | AR12: =SUM(Tabla1[[#This Row],[COSTO OPERATIVO ACIDO]:[COSTO OPERATIVO CATIONICO]]) -> 1692770 | AS12: 5250 | AT12: =AR12/L12 -> 3224.3238
A13: =A12 -> 46057 | B13: =DAY(Tabla1[[#This Row],[FECHA]]) -> 4 | C13: 3(TARDE) | D13: 12 | E13: FINAL TURNO 2 | F13: 2810 | G13: 4410 | H13: 900 | I13: 150 | J13: 65 | K13: 16890 | L13: =+(K14-Tabla1[[#This Row],[Lectura Horometro INICIAL (06:00)]])*Tabla1[[#This Row],[CAUDAL DE TRATAMIENTO]] -> 525 | M13: 75 | N13: =F13-F14 -> 310 | O13: =G13-G14 -> 290 | P13: =H13-H14 -> 100 | Q13: 0 | R13: 0 | S13: =(N13*$AC$2) -> 403 | T13: =(O13*$AD$2) -> 384.25 | U13: =(P13*$AE$2) -> 125 | V13: =Tabla1[[#This Row],[CONSUMO POL ANIONICO (KG)]] -> 0 | W13: =Tabla1[[#This Row],[CONSUMO POL CATIONICO (KG)]] -> 0 | X13: =(S13*1000)/L13 -> 767.61905 | Y13: =(T13*1000)/L13 -> 731.90476 | Z13: =(U13*1000)/L13 -> 238.09524 | AA13: =(V13*1000)/L13 -> 0 | AB13: =(W13*1000)/L13 -> 0 | AC13: 1.3 | AD13: 1.325 | AE13: 1.25 | AF13: 2500 | AG13: 2500 | AH13: 830 | AI13: 2900 | AJ13: 6295 | AK13: 19050 | AL13: 22050 | AM13: =S13*AH13 -> 334490 | AN13: =T13*AI13 -> 1114325 | AO13: =U13*AJ13 -> 786875 | AP13: =V13*AK13 -> 0 | AQ13: =W13*AL13 -> 0 | AR13: =SUM(Tabla1[[#This Row],[COSTO OPERATIVO ACIDO]:[COSTO OPERATIVO CATIONICO]]) -> 2235690 | AS13: 5250 | AT13: =AR13/L13 -> 4258.4571
A14: 46058 | B14: =DAY(Tabla1[[#This Row],[FECHA]]) -> 5 | C14: 5 (NOCHE) | D14: 13 | E14: FINAL TURNO 3 | F14: 2500 | G14: 4120 | H14: 800 | I14: 145 | J14: 60 | K14: 16897 | L14: =+(K15-Tabla1[[#This Row],[Lectura Horometro INICIAL (06:00)]])*Tabla1[[#This Row],[CAUDAL DE TRATAMIENTO]] -> 600 | M14: 75 | N14: =F14-F15 -> 110 | O14: =G14-G15 -> 120 | P14: =H14-H15 -> 80 | Q14: 0 | R14: 0 | S14: =(N14*$AC$2) -> 143 | T14: =(O14*$AD$2) -> 159 | U14: =(P14*$AE$2) -> 100 | V14: =Tabla1[[#This Row],[CONSUMO POL ANIONICO (KG)]] -> 0 | W14: =Tabla1[[#This Row],[CONSUMO POL CATIONICO (KG)]] -> 0 | X14: =(S14*1000)/L14 -> 238.33333 | Y14: =(T14*1000)/L14 -> 265 | Z14: =(U14*1000)/L14 -> 166.66667 | AA14: =(V14*1000)/L14 -> 0 | AB14: =(W14*1000)/L14 -> 0 | AC14: 1.3 | AD14: 1.325 | AE14: 1.25 | AF14: 2500 | AG14: 2500 | AH14: 830 | AI14: 2900 | AJ14: 6295 | AK14: 19050 | AL14: 22050 | AM14: =S14*AH14 -> 118690 | AN14: =T14*AI14 -> 461100 | AO14: =U14*AJ14 -> 629500 | AP14: =V14*AK14 -> 0 | AQ14: =W14*AL14 -> 0 | AR14: =SUM(Tabla1[[#This Row],[COSTO OPERATIVO ACIDO]:[COSTO OPERATIVO CATIONICO]]) -> 1209290 | AS14: 5250 | AT14: =AR14/L14 -> 2015.4833
A15: =A14 -> 46058 | B15: =DAY(Tabla1[[#This Row],[FECHA]]) -> 5 | C15: 6 (MAÑANA) | D15: 14 | E15: FINAL TURNO 1 | F15: 2390 | G15: 4000 | H15: 720 | I15: 145 | J15: 55 | K15: 16905 | L15: =+(K16-Tabla1[[#This Row],[Lectura Horometro INICIAL (06:00)]])*Tabla1[[#This Row],[CAUDAL DE TRATAMIENTO]] -> 525 | M15: 75 | N15: =F15-F16 -> 90 | O15: =G15-G16 -> 260 | P15: =H15-H16 -> 70 | Q15: =I15-I16 -> 5 | R15: =J15-J16 -> 5 | S15: =(N15*$AC$2) -> 117 | T15: =(O15*$AD$2) -> 344.5 | U15: =(P15*$AE$2) -> 87.5 | V15: =Tabla1[[#This Row],[CONSUMO POL ANIONICO (KG)]] -> 5 | W15: =Tabla1[[#This Row],[CONSUMO POL CATIONICO (KG)]] -> 5 | X15: =(S15*1000)/L15 -> 222.85714 | Y15: =(T15*1000)/L15 -> 656.19048 | Z15: =(U15*1000)/L15 -> 166.66667 | AA15: =(V15*1000)/L15 -> 9.5238095 | AB15: =(W15*1000)/L15 -> 9.5238095 | AC15: 1.3 | AD15: 1.325 | AE15: 1.25 | AF15: 2500 | AG15: 2500 | AH15: 830 | AI15: 2900 | AJ15: 6295 | AK15: 19050 | AL15: 22050 | AM15: =S15*AH15 -> 97110 | AN15: =T15*AI15 -> 999050 | AO15: =U15*AJ15 -> 550812.5 | AP15: =V15*AK15 -> 95250 | AQ15: =W15*AL15 -> 110250 | AR15: =SUM(Tabla1[[#This Row],[COSTO OPERATIVO ACIDO]:[COSTO OPERATIVO CATIONICO]]) -> 1852472.5 | AS15: 5250 | AT15: =AR15/L15 -> 3528.519
A16: =A15 -> 46058 | B16: =DAY(Tabla1[[#This Row],[FECHA]]) -> 5 | C16: 3(TARDE) | D16: 15 | E16: FINAL TURNO 2 | F16: 2300 | G16: 3740 | H16: 650 | I16: 140 | J16: 50 | K16: 16912 | L16: =+(K17-Tabla1[[#This Row],[Lectura Horometro INICIAL (06:00)]])*Tabla1[[#This Row],[CAUDAL DE TRATAMIENTO]] -> 375 | M16: 75 | N16: =F16-F17 -> 100 | O16: =G16-G17 -> 150 | P16: =H16-H17 -> 50 | Q16: =I16-I17 -> 5 | R16: =J16-J17 -> 5 | S16: =(N16*$AC$2) -> 130 | T16: =(O16*$AD$2) -> 198.75 | U16: =(P16*$AE$2) -> 62.5 | V16: =Tabla1[[#This Row],[CONSUMO POL ANIONICO (KG)]] -> 5 | W16: =Tabla1[[#This Row],[CONSUMO POL CATIONICO (KG)]] -> 5 | X16: =(S16*1000)/L16 -> 346.66667 | Y16: =(T16*1000)/L16 -> 530 | Z16: =(U16*1000)/L16 -> 166.66667 | AA16: =(V16*1000)/L16 -> 13.333333 | AB16: =(W16*1000)/L16 -> 13.333333 | AC16: 1.3 | AD16: 1.325 | AE16: 1.25 | AF16: 2500 | AG16: 2500 | AH16: 830 | AI16: 2900 | AJ16: 6295 | AK16: 19050 | AL16: 22050 | AM16: =S16*AH16 -> 107900 | AN16: =T16*AI16 -> 576375 | AO16: =U16*AJ16 -> 393437.5 | AP16: =V16*AK16 -> 95250 | AQ16: =W16*AL16 -> 110250 | AR16: =SUM(Tabla1[[#This Row],[COSTO OPERATIVO ACIDO]:[COSTO OPERATIVO CATIONICO]]) -> 1283212.5 | AS16: 5250 | AT16: =AR16/L16 -> 3421.9
A17: 46059 | B17: =DAY(Tabla1[[#This Row],[FECHA]]) -> 6 | C17: 6 (NOCHE) | D17: 16 | E17: FINAL TURNO 3 | F17: 2200 | G17: 3590 | H17: 600 | I17: 135 | J17: 45 | K17: 16917 | L17: =+(K18-Tabla1[[#This Row],[Lectura Horometro INICIAL (06:00)]])*Tabla1[[#This Row],[CAUDAL DE TRATAMIENTO]] -> 525 | M17: 75 | N17: =F17-F18 -> 50 | O17: =G17-G18 -> 340 | P17: =H17-H18 -> 90 | Q17: =I17-I18 -> 0 | R17: =J17-J18 -> 10 | S17: =(N17*$AC$2) -> 65 | T17: =(O17*$AD$2) -> 450.5 | U17: =(P17*$AE$2) -> 112.5 | V17: =Tabla1[[#This Row],[CONSUMO POL ANIONICO (KG)]] -> 0 | W17: =Tabla1[[#This Row],[CONSUMO POL CATIONICO (KG)]] -> 10 | X17: =(S17*1000)/L17 -> 123.80952 | Y17: =(T17*1000)/L17 -> 858.09524 | Z17: =(U17*1000)/L17 -> 214.28571 | AA17: =(V17*1000)/L17 -> 0 | AB17: =(W17*1000)/L17 -> 19.047619 | AC17: 1.3 | AD17: 1.325 | AE17: 1.25 | AF17: 2500 | AG17: 2500 | AH17: 830 | AI17: 2900 | AJ17: 6295 | AK17: 19050 | AL17: 22050 | AM17: =S17*AH17 -> 53950 | AN17: =T17*AI17 -> 1306450 | AO17: =U17*AJ17 -> 708187.5 | AP17: =V17*AK17 -> 0 | AQ17: =W17*AL17 -> 220500 | AR17: =SUM(Tabla1[[#This Row],[COSTO OPERATIVO ACIDO]:[COSTO OPERATIVO CATIONICO]]) -> 2289087.5 | AS17: 5250 | AT17: =AR17/L17 -> 4360.1667
A18: =A17 -> 46059 | B18: =DAY(Tabla1[[#This Row],[FECHA]]) -> 6 | C18: 7 (MAÑANA) | D18: 17 | E18: FINAL TURNO 1 | F18: 2150 | G18: 3250 | H18: 510 | I18: 135 | J18: 35 | K18: 16924 | L18: =+(K19-Tabla1[[#This Row],[Lectura Horometro INICIAL (06:00)]])*Tabla1[[#This Row],[CAUDAL DE TRATAMIENTO]] -> 450 | M18: 75 | N18: =F18-F19 -> 50 | O18: =G18-G19 -> 240 | P18: =H18-H19 -> 70 | Q18: =I18-I19 -> 5 | R18: =J18-J19 -> 5 | S18: =(N18*$AC$2) -> 65 | T18: =(O18*$AD$2) -> 318 | U18: =(P18*$AE$2) -> 87.5 | V18: =Tabla1[[#This Row],[CONSUMO POL ANIONICO (KG)]] -> 5 | W18: =Tabla1[[#This Row],[CONSUMO POL CATIONICO (KG)]] -> 5 | X18: =(S18*1000)/L18 -> 144.44444 | Y18: =(T18*1000)/L18 -> 706.66667 | Z18: =(U18*1000)/L18 -> 194.44444 | AA18: =(V18*1000)/L18 -> 11.111111 | AB18: =(W18*1000)/L18 -> 11.111111 | AC18: 1.3 | AD18: 1.325 | AE18: 1.25 | AF18: 2500 | AG18: 2500 | AH18: 830 | AI18: 2900 | AJ18: 6295 | AK18: 19050 | AL18: 22050 | AM18: =S18*AH18 -> 53950 | AN18: =T18*AI18 -> 922200 | AO18: =U18*AJ18 -> 550812.5 | AP18: =V18*AK18 -> 95250 | AQ18: =W18*AL18 -> 110250 | AR18: =SUM(Tabla1[[#This Row],[COSTO OPERATIVO ACIDO]:[COSTO OPERATIVO CATIONICO]]) -> 1732462.5 | AS18: 5250 | AT18: =AR18/L18 -> 3849.9167
A19: =A18 -> 46059 | B19: =DAY(Tabla1[[#This Row],[FECHA]]) -> 6 | C19: 3(TARDE) | D19: 18 | E19: FINAL TURNO 2 | F19: 2100 | G19: 3010 | H19: 440 | I19: 130 | J19: 30 | K19: 16930 | L19: =+(K20-Tabla1[[#This Row],[Lectura Horometro INICIAL (06:00)]])*Tabla1[[#This Row],[CAUDAL DE TRATAMIENTO]] -> 375 | M19: 75 | N19: =F19-F20 -> 100 | O19: =G19-G20+4000 -> 210 | P19: =H19-H20 -> 50 | Q19: =I19-I20 -> 0 | R19: =J19-J20+100 -> 5 | S19: =(N19*$AC$2) -> 130 | T19: =(O19*$AD$2) -> 278.25 | U19: =(P19*$AE$2) -> 62.5 | V19: =Tabla1[[#This Row],[CONSUMO POL ANIONICO (KG)]] -> 0 | W19: =Tabla1[[#This Row],[CONSUMO POL CATIONICO (KG)]] -> 5 | X19: =(S19*1000)/L19 -> 346.66667 | Y19: =(T19*1000)/L19 -> 742 | Z19: =(U19*1000)/L19 -> 166.66667 | AA19: =(V19*1000)/L19 -> 0 | AB19: =(W19*1000)/L19 -> 13.333333 | AC19: 1.3 | AD19: 1.325 | AE19: 1.25 | AF19: 2500 | AG19: 2500 | AH19: 830 | AI19: 2900 | AJ19: 6295 | AK19: 19050 | AL19: 22050 | AM19: =S19*AH19 -> 107900 | AN19: =T19*AI19 -> 806925 | AO19: =U19*AJ19 -> 393437.5 | AP19: =V19*AK19 -> 0 | AQ19: =W19*AL19 -> 110250 | AR19: =SUM(Tabla1[[#This Row],[COSTO OPERATIVO ACIDO]:[COSTO OPERATIVO CATIONICO]]) -> 1418512.5 | AS19: 5250 | AT19: =AR19/L19 -> 3782.7
A20: 46060 | B20: =DAY(Tabla1[[#This Row],[FECHA]]) -> 7 | C20: 7 (NOCHE) | D20: 19 | E20: FINAL TURNO 3 | F20: 2000 | G20: 6800 | H20: 390 | I20: 130 | J20: 125 | K20: 16935 | L20: =+(K21-Tabla1[[#This Row],[Lectura Horometro INICIAL (06:00)]])*Tabla1[[#This Row],[CAUDAL DE TRATAMIENTO]] -> 600 | M20: 75 | N20: =F20-F21 -> 250 | O20: =G20-G21 -> 500 | P20: =H20-H21 -> 60 | Q20: =I20-I21 -> 5 | R20: =J20-J21 -> 5 | S20: =(N20*$AC$2) -> 325 | T20: =(O20*$AD$2) -> 662.5 | U20: =(P20*$AE$2) -> 75 | V20: =Tabla1[[#This Row],[CONSUMO POL ANIONICO (KG)]] -> 5 | W20: =Tabla1[[#This Row],[CONSUMO POL CATIONICO (KG)]] -> 5 | X20: =(S20*1000)/L20 -> 541.66667 | Y20: =(T20*1000)/L20 -> 1104.1667 | Z20: =(U20*1000)/L20 -> 125 | AA20: =(V20*1000)/L20 -> 8.3333333 | AB20: =(W20*1000)/L20 -> 8.3333333 | AC20: 1.3 | AD20: 1.325 | AE20: 1.25 | AF20: 2500 | AG20: 2500 | AH20: 830 | AI20: 2900 | AJ20: 6295 | AK20: 19050 | AL20: 22050 | AM20: =S20*AH20 -> 269750 | AN20: =T20*AI20 -> 1921250 | AO20: =U20*AJ20 -> 472125 | AP20: =V20*AK20 -> 95250 | AQ20: =W20*AL20 -> 110250 | AR20: =SUM(Tabla1[[#This Row],[COSTO OPERATIVO ACIDO]:[COSTO OPERATIVO CATIONICO]]) -> 2868625 | AS20: 5250 | AT20: =AR20/L20 -> 4781.0417
A21: =A20 -> 46060 | B21: =DAY(Tabla1[[#This Row],[FECHA]]) -> 7 | C21: 8 (MAÑANA) | D21: 20 | E21: FINAL TURNO 1 | F21: 1750 | G21: 6300 | H21: 330 | I21: 125 | J21: 120 | K21: 16943 | L21: =+(K22-Tabla1[[#This Row],[Lectura Horometro INICIAL (06:00)]])*Tabla1[[#This Row],[CAUDAL DE TRATAMIENTO]] -> 300 | M21: 75 | N21: =F21-F22 -> 0 | O21: =G21-G22 -> 0 | P21: =H21-H22 -> 0 | Q21: =I21-I22 -> 5 | R21: =J21-J22 -> 5 | S21: =(N21*$AC$2) -> 0 | T21: =(O21*$AD$2) -> 0 | U21: =(P21*$AE$2) -> 0 | V21: =Tabla1[[#This Row],[CONSUMO POL ANIONICO (KG)]] -> 5 | W21: =Tabla1[[#This Row],[CONSUMO POL CATIONICO (KG)]] -> 5 | X21: =(S21*1000)/L21 -> 0 | Y21: =(T21*1000)/L21 -> 0 | Z21: =(U21*1000)/L21 -> 0 | AA21: =(V21*1000)/L21 -> 16.666667 | AB21: =(W21*1000)/L21 -> 16.666667 | AC21: 1.3 | AD21: 1.325 | AE21: 1.25 | AF21: 2500 | AG21: 2500 | AH21: 830 | AI21: 2900 | AJ21: 6295 | AK21: 19050 | AL21: 22050 | AM21: =S21*AH21 -> 0 | AN21: =T21*AI21 -> 0 | AO21: =U21*AJ21 -> 0 | AP21: =V21*AK21 -> 95250 | AQ21: =W21*AL21 -> 110250 | AR21: =SUM(Tabla1[[#This Row],[COSTO OPERATIVO ACIDO]:[COSTO OPERATIVO CATIONICO]]) -> 205500 | AS21: 5250 | AT21: =AR21/L21 -> 685
A22: =A21 -> 46060 | B22: =DAY(Tabla1[[#This Row],[FECHA]]) -> 7 | C22: 3(TARDE) | D22: 21 | E22: FINAL TURNO 2 | F22: 1750 | G22: 6300 | H22: 330 | I22: 120 | J22: 115 | K22: 16947 | L22: =+(K23-Tabla1[[#This Row],[Lectura Horometro INICIAL (06:00)]])*Tabla1[[#This Row],[CAUDAL DE TRATAMIENTO]] -> 0 | M22: 75 | N22: =F22-F23 -> 0 | O22: =G22-G23 -> 0 | P22: =H22-H23 -> 0 | Q22: =I22-I23 -> 0 | R22: =J22-J23 -> 0 | S22: =(N22*$AC$2) -> 0 | T22: =(O22*$AD$2) -> 0 | U22: =(P22*$AE$2) -> 0 | V22: =Tabla1[[#This Row],[CONSUMO POL ANIONICO (KG)]] -> 0 | W22: =Tabla1[[#This Row],[CONSUMO POL CATIONICO (KG)]] -> 0 | X22: =(S22*1000)/L22 -> #DIV/0! | Y22: =(T22*1000)/L22 -> #DIV/0! | Z22: =(U22*1000)/L22 -> #DIV/0! | AA22: =(V22*1000)/L22 -> #DIV/0! | AB22: =(W22*1000)/L22 -> #DIV/0! | AC22: 1.3 | AD22: 1.325 | AE22: 1.25 | AF22: 2500 | AG22: 2500 | AH22: 830 | AI22: 2900 | AJ22: 6295 | AK22: 19050 | AL22: 22050 | AM22: =S22*AH22 -> 0 | AN22: =T22*AI22 -> 0 | AO22: =U22*AJ22 -> 0 | AP22: =V22*AK22 -> 0 | AQ22: =W22*AL22 -> 0 | AR22: =SUM(Tabla1[[#This Row],[COSTO OPERATIVO ACIDO]:[COSTO OPERATIVO CATIONICO]]) -> 0 | AS22: 5250 | AT22: =AR22/L22 -> #DIV/0!
A23: 46061 | B23: =DAY(Tabla1[[#This Row],[FECHA]]) -> 8 | C23: 8 (NOCHE) | D23: 22 | E23: FINAL TURNO 3 | F23: 1750 | G23: 6300 | H23: 330 | I23: 120 | J23: 115 | K23: 16947 | L23: =+(K24-Tabla1[[#This Row],[Lectura Horometro INICIAL (06:00)]])*Tabla1[[#This Row],[CAUDAL DE TRATAMIENTO]] -> 0 | M23: 75 | N23: =F23-F24 -> 0 | O23: =G23-G24 -> 0 | P23: =H23-H24 -> 0 | Q23: =I23-I24 -> 0 | R23: =J23-J24 -> 0 | S23: =(N23*$AC$2) -> 0 | T23: =(O23*$AD$2) -> 0 | U23: =(P23*$AE$2) -> 0 | V23: =Tabla1[[#This Row],[CONSUMO POL ANIONICO (KG)]] -> 0 | W23: =Tabla1[[#This Row],[CONSUMO POL CATIONICO (KG)]] -> 0 | X23: =(S23*1000)/L23 -> #DIV/0! | Y23: =(T23*1000)/L23 -> #DIV/0! | Z23: =(U23*1000)/L23 -> #DIV/0! | AA23: =(V23*1000)/L23 -> #DIV/0! | AB23: =(W23*1000)/L23 -> #DIV/0! | AC23: 1.3 | AD23: 1.325 | AE23: 1.25 | AF23: 2500 | AG23: 2500 | AH23: 830 | AI23: 2900 | AJ23: 6295 | AK23: 19050 | AL23: 22050 | AM23: =S23*AH23 -> 0 | AN23: =T23*AI23 -> 0 | AO23: =U23*AJ23 -> 0 | AP23: =V23*AK23 -> 0 | AQ23: =W23*AL23 -> 0 | AR23: =SUM(Tabla1[[#This Row],[COSTO OPERATIVO ACIDO]:[COSTO OPERATIVO CATIONICO]]) -> 0 | AS23: 5250 | AT23: =AR23/L23 -> #DIV/0!
A24: =A23 -> 46061 | B24: =DAY(Tabla1[[#This Row],[FECHA]]) -> 8 | C24: 9 (MAÑANA) | D24: 23 | E24: FINAL TURNO 1 | F24: 1750 | G24: 6300 | H24: 330 | I24: 120 | J24: 115 | K24: 16947 | L24: =+(K25-Tabla1[[#This Row],[Lectura Horometro INICIAL (06:00)]])*Tabla1[[#This Row],[CAUDAL DE TRATAMIENTO]] -> 0 | M24: 75 | N24: =F24-F25 -> 0 | O24: =G24-G25 -> 0 | P24: =H24-H25 -> 0 | Q24: =I24-I25 -> 5 | R24: =J24-J25 -> 0 | S24: =(N24*$AC$2) -> 0 | T24: =(O24*$AD$2) -> 0 | U24: =(P24*$AE$2) -> 0 | V24: =Tabla1[[#This Row],[CONSUMO POL ANIONICO (KG)]] -> 5 | W24: =Tabla1[[#This Row],[CONSUMO POL CATIONICO (KG)]] -> 0 | X24: =(S24*1000)/L24 -> #DIV/0! | Y24: =(T24*1000)/L24 -> #DIV/0! | Z24: =(U24*1000)/L24 -> #DIV/0! | AA24: =(V24*1000)/L24 -> #DIV/0! | AB24: =(W24*1000)/L24 -> #DIV/0! | AC24: 1.3 | AD24: 1.325 | AE24: 1.25 | AF24: 2500 | AG24: 2500 | AH24: 830 | AI24: 2900 | AJ24: 6295 | AK24: 19050 | AL24: 22050 | AM24: =S24*AH24 -> 0 | AN24: =T24*AI24 -> 0 | AO24: =U24*AJ24 -> 0 | AP24: =V24*AK24 -> 95250 | AQ24: =W24*AL24 -> 0 | AR24: =SUM(Tabla1[[#This Row],[COSTO OPERATIVO ACIDO]:[COSTO OPERATIVO CATIONICO]]) -> 95250 | AS24: 5250 | AT24: =AR24/L24 -> #DIV/0!
A25: =A24 -> 46061 | B25: =DAY(Tabla1[[#This Row],[FECHA]]) -> 8 | C25: 3(TARDE) | D25: 24 | E25: FINAL TURNO 2 | F25: 1750 | G25: 6300 | H25: 330 | I25: 115 | J25: 115 | K25: 16947 | L25: =+(K26-Tabla1[[#This Row],[Lectura Horometro INICIAL (06:00)]])*Tabla1[[#This Row],[CAUDAL DE TRATAMIENTO]] -> 0 | M25: 75 | N25: =F25-F26 -> 0 | O25: =G25-G26 -> 0 | P25: =H25-H26 -> 0 | Q25: =I25-I26 -> 0 | R25: =J25-J26 -> 0 | S25: =(N25*$AC$2) -> 0 | T25: =(O25*$AD$2) -> 0 | U25: =(P25*$AE$2) -> 0 | V25: =Tabla1[[#This Row],[CONSUMO POL ANIONICO (KG)]] -> 0 | W25: =Tabla1[[#This Row],[CONSUMO POL CATIONICO (KG)]] -> 0 | X25: =(S25*1000)/L25 -> #DIV/0! | Y25: =(T25*1000)/L25 -> #DIV/0! | Z25: =(U25*1000)/L25 -> #DIV/0! | AA25: =(V25*1000)/L25 -> #DIV/0! | AB25: =(W25*1000)/L25 -> #DIV/0! | AC25: 1.3 | AD25: 1.325 | AE25: 1.25 | AF25: 2500 | AG25: 2500 | AH25: 830 | AI25: 2900 | AJ25: 6295 | AK25: 19050 | AL25: 22050 | AM25: =S25*AH25 -> 0 | AN25: =T25*AI25 -> 0 | AO25: =U25*AJ25 -> 0 | AP25: =V25*AK25 -> 0 | AQ25: =W25*AL25 -> 0 | AR25: =SUM(Tabla1[[#This Row],[COSTO OPERATIVO ACIDO]:[COSTO OPERATIVO CATIONICO]]) -> 0 | AS25: 5250 | AT25: =AR25/L25 -> #DIV/0!
A26: 46062 | B26: =DAY(Tabla1[[#This Row],[FECHA]]) -> 9 | C26: 9 (NOCHE) | D26: 25 | E26: FINAL TURNO 3 | F26: 1750 | G26: 6300 | H26: 330 | I26: 115 | J26: 115 | K26: 16947 | L26: =+(K27-Tabla1[[#This Row],[Lectura Horometro INICIAL (06:00)]])*Tabla1[[#This Row],[CAUDAL DE TRATAMIENTO]] -> 525 | M26: 75 | N26: =F26-F27+1000 -> 80 | O26: =G26-G27 -> 370 | P26: =H26-H27+2000 -> 80 | Q26: =I26-I27+50 -> 5 | R26: =J26-J27 -> 5 | S26: =(N26*$AC$2) -> 104 | T26: =(O26*$AD$2) -> 490.25 | U26: =(P26*$AE$2) -> 100 | V26: =Tabla1[[#This Row],[CONSUMO POL ANIONICO (KG)]] -> 5 | W26: =Tabla1[[#This Row],[CONSUMO POL CATIONICO (KG)]] -> 5 | X26: =(S26*1000)/L26 -> 198.09524 | Y26: =(T26*1000)/L26 -> 933.80952 | Z26: =(U26*1000)/L26 -> 190.47619 | AA26: =(V26*1000)/L26 -> 9.5238095 | AB26: =(W26*1000)/L26 -> 9.5238095 | AC26: 1.3 | AD26: 1.325 | AE26: 1.25 | AF26: 2500 | AG26: 2500 | AH26: 830 | AI26: 2900 | AJ26: 6295 | AK26: 19050 | AL26: 22050 | AM26: =S26*AH26 -> 86320 | AN26: =T26*AI26 -> 1421725 | AO26: =U26*AJ26 -> 629500 | AP26: =V26*AK26 -> 95250 | AQ26: =W26*AL26 -> 110250 | AR26: =SUM(Tabla1[[#This Row],[COSTO OPERATIVO ACIDO]:[COSTO OPERATIVO CATIONICO]]) -> 2343045 | AS26: 5250 | AT26: =AR26/L26 -> 4462.9429
A27: =A26 -> 46062 | B27: =DAY(Tabla1[[#This Row],[FECHA]]) -> 9 | C27: 10 (MAÑANA) | D27: 26 | E27: FINAL TURNO 1 | F27: 2670 | G27: 5930 | H27: 2250 | I27: 160 | J27: 110 | K27: 16954 | L27: =+(K28-Tabla1[[#This Row],[Lectura Horometro INICIAL (06:00)]])*Tabla1[[#This Row],[CAUDAL DE TRATAMIENTO]] -> 525 | M27: 75 | N27: =F27-F28 -> 0 | O27: =G27-G28 -> 130 | P27: =H27-H28 -> 20 | Q27: =I27-I28 -> 0 | R27: =J27-J28 -> 5 | S27: =(N27*$AC$2) -> 0 | T27: =(O27*$AD$2) -> 172.25 | U27: =(P27*$AE$2) -> 25 | V27: =Tabla1[[#This Row],[CONSUMO POL ANIONICO (KG)]] -> 0 | W27: =Tabla1[[#This Row],[CONSUMO POL CATIONICO (KG)]] -> 5 | X27: =(S27*1000)/L27 -> 0 | Y27: =(T27*1000)/L27 -> 328.09524 | Z27: =(U27*1000)/L27 -> 47.619048 | AA27: =(V27*1000)/L27 -> 0 | AB27: =(W27*1000)/L27 -> 9.5238095 | AC27: 1.3 | AD27: 1.325 | AE27: 1.25 | AF27: 2500 | AG27: 2500 | AH27: 830 | AI27: 2900 | AJ27: 6295 | AK27: 19050 | AL27: 22050 | AM27: =S27*AH27 -> 0 | AN27: =T27*AI27 -> 499525 | AO27: =U27*AJ27 -> 157375 | AP27: =V27*AK27 -> 0 | AQ27: =W27*AL27 -> 110250 | AR27: =SUM(Tabla1[[#This Row],[COSTO OPERATIVO ACIDO]:[COSTO OPERATIVO CATIONICO]]) -> 767150 | AS27: 5250 | AT27: =AR27/L27 -> 1461.2381
A28: =A27 -> 46062 | B28: =DAY(Tabla1[[#This Row],[FECHA]]) -> 9 | C28: 3(TARDE) | D28: 27 | E28: FINAL TURNO 2 | F28: 2670 | G28: 5800 | H28: 2230 | I28: 160 | J28: 105 | K28: 16961 | L28: =+(K29-Tabla1[[#This Row],[Lectura Horometro INICIAL (06:00)]])*Tabla1[[#This Row],[CAUDAL DE TRATAMIENTO]] -> 300 | M28: 75 | N28: =F28-F29 -> 70 | O28: =G28-G29 -> 200 | P28: =H28-H29 -> 40 | Q28: =I28-I29 -> 5 | R28: =J28-J29 -> 5 | S28: =(N28*$AC$2) -> 91 | T28: =(O28*$AD$2) -> 265 | U28: =(P28*$AE$2) -> 50 | V28: =Tabla1[[#This Row],[CONSUMO POL ANIONICO (KG)]] -> 5 | W28: =Tabla1[[#This Row],[CONSUMO POL CATIONICO (KG)]] -> 5 | X28: =(S28*1000)/L28 -> 303.33333 | Y28: =(T28*1000)/L28 -> 883.33333 | Z28: =(U28*1000)/L28 -> 166.66667 | AA28: =(V28*1000)/L28 -> 16.666667 | AB28: =(W28*1000)/L28 -> 16.666667 | AC28: 1.3 | AD28: 1.325 | AE28: 1.25 | AF28: 2500 | AG28: 2500 | AH28: 830 | AI28: 2900 | AJ28: 6295 | AK28: 19050 | AL28: 22050 | AM28: =S28*AH28 -> 75530 | AN28: =T28*AI28 -> 768500 | AO28: =U28*AJ28 -> 314750 | AP28: =V28*AK28 -> 95250 | AQ28: =W28*AL28 -> 110250 | AR28: =SUM(Tabla1[[#This Row],[COSTO OPERATIVO ACIDO]:[COSTO OPERATIVO CATIONICO]]) -> 1364280 | AS28: 5250 | AT28: =AR28/L28 -> 4547.6
A29: 46063 | B29: =DAY(Tabla1[[#This Row],[FECHA]]) -> 10 | C29: 10 (NOCHE) | D29: 28 | E29: FINAL TURNO 3 | F29: 2600 | G29: 5600 | H29: 2190 | I29: 155 | J29: 100 | K29: 16965 | L29: =+(K30-Tabla1[[#This Row],[Lectura Horometro INICIAL (06:00)]])*Tabla1[[#This Row],[CAUDAL DE TRATAMIENTO]] -> 525 | M29: 75 | N29: =F29-F30 -> 20 | O29: =G29-G30 -> 20 | P29: =H29-H30 -> 10 | Q29: =I29-I30 -> 0 | R29: =J29-J30 -> 5 | S29: =(N29*$AC$2) -> 26 | T29: =(O29*$AD$2) -> 26.5 | U29: =(P29*$AE$2) -> 12.5 | V29: =Tabla1[[#This Row],[CONSUMO POL ANIONICO (KG)]] -> 0 | W29: =Tabla1[[#This Row],[CONSUMO POL CATIONICO (KG)]] -> 5 | X29: =(S29*1000)/L29 -> 49.52381 | Y29: =(T29*1000)/L29 -> 50.47619 | Z29: =(U29*1000)/L29 -> 23.809524 | AA29: =(V29*1000)/L29 -> 0 | AB29: =(W29*1000)/L29 -> 9.5238095 | AC29: 1.3 | AD29: 1.325 | AE29: 1.25 | AF29: 2500 | AG29: 2500 | AH29: 830 | AI29: 2900 | AJ29: 6295 | AK29: 19050 | AL29: 22050 | AM29: =S29*AH29 -> 21580 | AN29: =T29*AI29 -> 76850 | AO29: =U29*AJ29 -> 78687.5 | AP29: =V29*AK29 -> 0 | AQ29: =W29*AL29 -> 110250 | AR29: =SUM(Tabla1[[#This Row],[COSTO OPERATIVO ACIDO]:[COSTO OPERATIVO CATIONICO]]) -> 287367.5 | AS29: 5250 | AT29: =AR29/L29 -> 547.36667
A30: =A29 -> 46063 | B30: =DAY(Tabla1[[#This Row],[FECHA]]) -> 10 | C30: 11 (MAÑANA) | D30: 29 | E30: FINAL TURNO 1 | F30: 2580 | G30: 5580 | H30: 2180 | I30: 155 | J30: 95 | K30: 16972 | L30: =+(K31-Tabla1[[#This Row],[Lectura Horometro INICIAL (06:00)]])*Tabla1[[#This Row],[CAUDAL DE TRATAMIENTO]] -> 300 | M30: 75 | N30: =F30-F31 -> 80 | O30: =G30-G31 -> 170 | P30: =H30-H31 -> 20 | Q30: =I30-I31 -> 5 | R30: =J30-J31 -> 5 | S30: =(N30*$AC$2) -> 104 | T30: =(O30*$AD$2) -> 225.25 | U30: =(P30*$AE$2) -> 25 | V30: =Tabla1[[#This Row],[CONSUMO POL ANIONICO (KG)]] -> 5 | W30: =Tabla1[[#This Row],[CONSUMO POL CATIONICO (KG)]] -> 5 | X30: =(S30*1000)/L30 -> 346.66667 | Y30: =(T30*1000)/L30 -> 750.83333 | Z30: =(U30*1000)/L30 -> 83.333333 | AA30: =(V30*1000)/L30 -> 16.666667 | AB30: =(W30*1000)/L30 -> 16.666667 | AC30: 1.3 | AD30: 1.325 | AE30: 1.25 | AF30: 2500 | AG30: 2500 | AH30: 830 | AI30: 2900 | AJ30: 6295 | AK30: 19050 | AL30: 22050 | AM30: =S30*AH30 -> 86320 | AN30: =T30*AI30 -> 653225 | AO30: =U30*AJ30 -> 157375 | AP30: =V30*AK30 -> 95250 | AQ30: =W30*AL30 -> 110250 | AR30: =SUM(Tabla1[[#This Row],[COSTO OPERATIVO ACIDO]:[COSTO OPERATIVO CATIONICO]]) -> 1102420 | AS30: 5250 | AT30: =AR30/L30 -> 3674.7333
A31: =A30 -> 46063 | B31: =DAY(Tabla1[[#This Row],[FECHA]]) -> 10 | C31: 3(TARDE) | D31: 30 | E31: FINAL TURNO 2 | F31: 2500 | G31: 5410 | H31: 2160 | I31: 150 | J31: 90 | K31: 16976 | L31: =+(K32-Tabla1[[#This Row],[Lectura Horometro INICIAL (06:00)]])*Tabla1[[#This Row],[CAUDAL DE TRATAMIENTO]] -> 600 | M31: 75 | N31: =F31-F32 -> 170 | O31: =G31-G32 -> 140 | P31: =H31-H32 -> 50 | Q31: =I31-I32 -> 0 | R31: =J31-J32 -> 5 | S31: =(N31*$AC$2) -> 221 | T31: =(O31*$AD$2) -> 185.5 | U31: =(P31*$AE$2) -> 62.5 | V31: =Tabla1[[#This Row],[CONSUMO POL ANIONICO (KG)]] -> 0 | W31: =Tabla1[[#This Row],[CONSUMO POL CATIONICO (KG)]] -> 5 | X31: =(S31*1000)/L31 -> 368.33333 | Y31: =(T31*1000)/L31 -> 309.16667 | Z31: =(U31*1000)/L31 -> 104.16667 | AA31: =(V31*1000)/L31 -> 0 | AB31: =(W31*1000)/L31 -> 8.3333333 | AC31: 1.3 | AD31: 1.325 | AE31: 1.25 | AF31: 2500 | AG31: 2500 | AH31: 830 | AI31: 2900 | AJ31: 6295 | AK31: 19050 | AL31: 22050 | AM31: =S31*AH31 -> 183430 | AN31: =T31*AI31 -> 537950 | AO31: =U31*AJ31 -> 393437.5 | AP31: =V31*AK31 -> 0 | AQ31: =W31*AL31 -> 110250 | AR31: =SUM(Tabla1[[#This Row],[COSTO OPERATIVO ACIDO]:[COSTO OPERATIVO CATIONICO]]) -> 1225067.5 | AS31: 5250 | AT31: =AR31/L31 -> 2041.7792
A32: 46064 | B32: =DAY(Tabla1[[#This Row],[FECHA]]) -> 11 | C32: 11 (NOCHE) | D32: 31 | E32: FINAL TURNO 3 | F32: 2330 | G32: 5270 | H32: 2110 | I32: 150 | J32: 85 | K32: 16984 | L32: =+(K33-Tabla1[[#This Row],[Lectura Horometro INICIAL (06:00)]])*Tabla1[[#This Row],[CAUDAL DE TRATAMIENTO]] -> 225 | M32: 75 | N32: =F32-F33 -> 130 | O32: =G32-G33 -> 90 | P32: =H32-H33 -> 10 | Q32: =I32-I33 -> 5 | R32: =J32-J33 -> 5 | S32: =(N32*$AC$2) -> 169 | T32: =(O32*$AD$2) -> 119.25 | U32: =(P32*$AE$2) -> 12.5 | V32: =Tabla1[[#This Row],[CONSUMO POL ANIONICO (KG)]] -> 5 | W32: =Tabla1[[#This Row],[CONSUMO POL CATIONICO (KG)]] -> 5 | X32: =(S32*1000)/L32 -> 751.11111 | Y32: =(T32*1000)/L32 -> 530 | Z32: =(U32*1000)/L32 -> 55.555556 | AA32: =(V32*1000)/L32 -> 22.222222 | AB32: =(W32*1000)/L32 -> 22.222222 | AC32: 1.3 | AD32: 1.325 | AE32: 1.25 | AF32: 2500 | AG32: 2500 | AH32: 830 | AI32: 2900 | AJ32: 6295 | AK32: 19050 | AL32: 22050 | AM32: =S32*AH32 -> 140270 | AN32: =T32*AI32 -> 345825 | AO32: =U32*AJ32 -> 78687.5 | AP32: =V32*AK32 -> 95250 | AQ32: =W32*AL32 -> 110250 | AR32: =SUM(Tabla1[[#This Row],[COSTO OPERATIVO ACIDO]:[COSTO OPERATIVO CATIONICO]]) -> 770282.5 | AS32: 5250 | AT32: =AR32/L32 -> 3423.4778
A33: =A32 -> 46064 | B33: =DAY(Tabla1[[#This Row],[FECHA]]) -> 11 | C33: 12 (MAÑANA) | D33: 32 | E33: FINAL TURNO 1 | F33: 2200 | G33: 5180 | H33: 2100 | I33: 145 | J33: 80 | K33: 16987 | L33: =+(K34-Tabla1[[#This Row],[Lectura Horometro INICIAL (06:00)]])*Tabla1[[#This Row],[CAUDAL DE TRATAMIENTO]] -> 450 | M33: 75 | N33: =F33-F34 -> 100 | O33: =G33-G34-150 -> 120 | P33: =H33-H34 -> 30 | Q33: =I33-I34 -> 5 | R33: =J33-J34 -> 5 | S33: =(N33*$AC$2) -> 130 | T33: =(O33*$AD$2) -> 159 | U33: =(P33*$AE$2) -> 37.5 | V33: =Tabla1[[#This Row],[CONSUMO POL ANIONICO (KG)]] -> 5 | W33: =Tabla1[[#This Row],[CONSUMO POL CATIONICO (KG)]] -> 5 | X33: =(S33*1000)/L33 -> 288.88889 | Y33: =(T33*1000)/L33 -> 353.33333 | Z33: =(U33*1000)/L33 -> 83.333333 | AA33: =(V33*1000)/L33 -> 11.111111 | AB33: =(W33*1000)/L33 -> 11.111111 | AC33: 1.3 | AD33: 1.325 | AE33: 1.25 | AF33: 2500 | AG33: 2500 | AH33: 830 | AI33: 2900 | AJ33: 6295 | AK33: 19050 | AL33: 22050 | AM33: =S33*AH33 -> 107900 | AN33: =T33*AI33 -> 461100 | AO33: =U33*AJ33 -> 236062.5 | AP33: =V33*AK33 -> 95250 | AQ33: =W33*AL33 -> 110250 | AR33: =SUM(Tabla1[[#This Row],[COSTO OPERATIVO ACIDO]:[COSTO OPERATIVO CATIONICO]]) -> 1010562.5 | AS33: 5250 | AT33: =AR33/L33 -> 2245.6944
A34: =A33 -> 46064 | B34: =DAY(Tabla1[[#This Row],[FECHA]]) -> 11 | C34: 3(TARDE) | D34: 33 | E34: FINAL TURNO 2 | F34: 2100 | G34: 4910 | H34: 2070 | I34: 140 | J34: 75 | K34: 16993 | L34: =+(K35-Tabla1[[#This Row],[Lectura Horometro INICIAL (06:00)]])*Tabla1[[#This Row],[CAUDAL DE TRATAMIENTO]] -> 600 | M34: 75 | N34: =F34-F35 -> 70 | O34: =G34-G35 -> 110 | P34: =H34-H35 -> 70 | Q34: =I34-I35 -> 0 | R34: =J34-J35 -> 5 | S34: =(N34*$AC$2) -> 91 | T34: =(O34*$AD$2) -> 145.75 | U34: =(P34*$AE$2) -> 87.5 | V34: =Tabla1[[#This Row],[CONSUMO POL ANIONICO (KG)]] -> 0 | W34: =Tabla1[[#This Row],[CONSUMO POL CATIONICO (KG)]] -> 5 | X34: =(S34*1000)/L34 -> 151.66667 | Y34: =(T34*1000)/L34 -> 242.91667 | Z34: =(U34*1000)/L34 -> 145.83333 | AA34: =(V34*1000)/L34 -> 0 | AB34: =(W34*1000)/L34 -> 8.3333333 | AC34: 1.3 | AD34: 1.325 | AE34: 1.25 | AF34: 2500 | AG34: 2500 | AH34: 830 | AI34: 2900 | AJ34: 6295 | AK34: 19050 | AL34: 22050 | AM34: =S34*AH34 -> 75530 | AN34: =T34*AI34 -> 422675 | AO34: =U34*AJ34 -> 550812.5 | AP34: =V34*AK34 -> 0 | AQ34: =W34*AL34 -> 110250 | AR34: =SUM(Tabla1[[#This Row],[COSTO OPERATIVO ACIDO]:[COSTO OPERATIVO CATIONICO]]) -> 1159267.5 | AS34: 5250 | AT34: =AR34/L34 -> 1932.1125
A35: 46065 | B35: =DAY(Tabla1[[#This Row],[FECHA]]) -> 12 | C35: 12 (NOCHE) | D35: 34 | E35: FINAL TURNO 3 | F35: 2030 | G35: 4800 | H35: 2000 | I35: 140 | J35: 70 | K35: 17001 | L35: =+(K36-Tabla1[[#This Row],[Lectura Horometro INICIAL (06:00)]])*Tabla1[[#This Row],[CAUDAL DE TRATAMIENTO]] -> 375 | M35: 75 | N35: =F35-F36 -> 100 | O35: =G35-G36 -> 120 | P35: =H35-H36 -> 0 | Q35: =I35-I36 -> 5 | R35: =J35-J36 -> 5 | S35: =(N35*$AC$2) -> 130 | T35: =(O35*$AD$2) -> 159 | U35: =(P35*$AE$2) -> 0 | V35: =Tabla1[[#This Row],[CONSUMO POL ANIONICO (KG)]] -> 5 | W35: =Tabla1[[#This Row],[CONSUMO POL CATIONICO (KG)]] -> 5 | X35: =(S35*1000)/L35 -> 346.66667 | Y35: =(T35*1000)/L35 -> 424 | Z35: =(U35*1000)/L35 -> 0 | AA35: =(V35*1000)/L35 -> 13.333333 | AB35: =(W35*1000)/L35 -> 13.333333 | AC35: 1.3 | AD35: 1.325 | AE35: 1.25 | AF35: 2500 | AG35: 2500 | AH35: 830 | AI35: 2900 | AJ35: 6295 | AK35: 19050 | AL35: 22050 | AM35: =S35*AH35 -> 107900 | AN35: =T35*AI35 -> 461100 | AO35: =U35*AJ35 -> 0 | AP35: =V35*AK35 -> 95250 | AQ35: =W35*AL35 -> 110250 | AR35: =SUM(Tabla1[[#This Row],[COSTO OPERATIVO ACIDO]:[COSTO OPERATIVO CATIONICO]]) -> 774500 | AS35: 5250 | AT35: =AR35/L35 -> 2065.3333
A36: =A35 -> 46065 | B36: =DAY(Tabla1[[#This Row],[FECHA]]) -> 12 | C36: 13 (MAÑANA) | D36: 35 | E36: FINAL TURNO 1 | F36: 1930 | G36: 4680 | H36: 2000 | I36: 135 | J36: 65 | K36: 17006 | L36: =+(K37-Tabla1[[#This Row],[Lectura Horometro INICIAL (06:00)]])*Tabla1[[#This Row],[CAUDAL DE TRATAMIENTO]] -> 225 | M36: 75 | N36: =F36-F37 -> 130 | O36: =G36-G37 -> 170 | P36: =H36-H37 -> 30 | Q36: =I36-I37 -> 0 | R36: =J36-J37 -> 5 | S36: =(N36*$AC$2) -> 169 | T36: =(O36*$AD$2) -> 225.25 | U36: =(P36*$AE$2) -> 37.5 | V36: =Tabla1[[#This Row],[CONSUMO POL ANIONICO (KG)]] -> 0 | W36: =Tabla1[[#This Row],[CONSUMO POL CATIONICO (KG)]] -> 5 | X36: =(S36*1000)/L36 -> 751.11111 | Y36: =(T36*1000)/L36 -> 1001.1111 | Z36: =(U36*1000)/L36 -> 166.66667 | AA36: =(V36*1000)/L36 -> 0 | AB36: =(W36*1000)/L36 -> 22.222222 | AC36: 1.3 | AD36: 1.325 | AE36: 1.25 | AF36: 2500 | AG36: 2500 | AH36: 830 | AI36: 2900 | AJ36: 6295 | AK36: 19050 | AL36: 22050 | AM36: =S36*AH36 -> 140270 | AN36: =T36*AI36 -> 653225 | AO36: =U36*AJ36 -> 236062.5 | AP36: =V36*AK36 -> 0 | AQ36: =W36*AL36 -> 110250 | AR36: =SUM(Tabla1[[#This Row],[COSTO OPERATIVO ACIDO]:[COSTO OPERATIVO CATIONICO]]) -> 1139807.5 | AS36: 5250 | AT36: =AR36/L36 -> 5065.8111
A37: =A36 -> 46065 | B37: =DAY(Tabla1[[#This Row],[FECHA]]) -> 12 | C37: 3(TARDE) | D37: 36 | E37: FINAL TURNO 2 | F37: 1800 | G37: 4510 | H37: 1970 | I37: 135 | J37: 60 | K37: 17009 | L37: =+(K38-Tabla1[[#This Row],[Lectura Horometro INICIAL (06:00)]])*Tabla1[[#This Row],[CAUDAL DE TRATAMIENTO]] -> 600 | M37: 75 | N37: =F37-F38 -> 100 | O37: =G37-G38 -> 110 | P37: =H37-H38 -> 20 | Q37: =I37-I38 -> 5 | R37: =J37-J38 -> 5 | S37: =(N37*$AC$2) -> 130 | T37: =(O37*$AD$2) -> 145.75 | U37: =(P37*$AE$2) -> 25 | V37: =Tabla1[[#This Row],[CONSUMO POL ANIONICO (KG)]] -> 5 | W37: =Tabla1[[#This Row],[CONSUMO POL CATIONICO (KG)]] -> 5 | X37: =(S37*1000)/L37 -> 216.66667 | Y37: =(T37*1000)/L37 -> 242.91667 | Z37: =(U37*1000)/L37 -> 41.666667 | AA37: =(V37*1000)/L37 -> 8.3333333 | AB37: =(W37*1000)/L37 -> 8.3333333 | AC37: 1.3 | AD37: 1.325 | AE37: 1.25 | AF37: 2500 | AG37: 2500 | AH37: 830 | AI37: 2900 | AJ37: 6295 | AK37: 19050 | AL37: 22050 | AM37: =S37*AH37 -> 107900 | AN37: =T37*AI37 -> 422675 | AO37: =U37*AJ37 -> 157375 | AP37: =V37*AK37 -> 95250 | AQ37: =W37*AL37 -> 110250 | AR37: =SUM(Tabla1[[#This Row],[COSTO OPERATIVO ACIDO]:[COSTO OPERATIVO CATIONICO]]) -> 893450 | AS37: 5250 | AT37: =AR37/L37 -> 1489.0833
A38: 46066 | B38: =DAY(Tabla1[[#This Row],[FECHA]]) -> 13 | C38: 13 (NOCHE) | D38: 37 | E38: FINAL TURNO 3 | F38: 1700 | G38: 4400 | H38: 1950 | I38: 130 | J38: 55 | K38: 17017 | L38: =+(K39-Tabla1[[#This Row],[Lectura Horometro INICIAL (06:00)]])*Tabla1[[#This Row],[CAUDAL DE TRATAMIENTO]] -> 375 | M38: 75 | N38: =F38-F39 -> 100 | O38: =G38-G39 -> 200 | P38: =H38-H39 -> 40 | Q38: =I38-I39 -> 0 | R38: =J38-J39 -> 5 | S38: =(N38*$AC$2) -> 130 | T38: =(O38*$AD$2) -> 265 | U38: =(P38*$AE$2) -> 50 | V38: =Tabla1[[#This Row],[CONSUMO POL ANIONICO (KG)]] -> 0 | W38: =Tabla1[[#This Row],[CONSUMO POL CATIONICO (KG)]] -> 5 | X38: =(S38*1000)/L38 -> 346.66667 | Y38: =(T38*1000)/L38 -> 706.66667 | Z38: =(U38*1000)/L38 -> 133.33333 | AA38: =(V38*1000)/L38 -> 0 | AB38: =(W38*1000)/L38 -> 13.333333 | AC38: 1.3 | AD38: 1.325 | AE38: 1.25 | AF38: 2500 | AG38: 2500 | AH38: 830 | AI38: 2900 | AJ38: 6295 | AK38: 19050 | AL38: 22050 | AM38: =S38*AH38 -> 107900 | AN38: =T38*AI38 -> 768500 | AO38: =U38*AJ38 -> 314750 | AP38: =V38*AK38 -> 0 | AQ38: =W38*AL38 -> 110250 | AR38: =SUM(Tabla1[[#This Row],[COSTO OPERATIVO ACIDO]:[COSTO OPERATIVO CATIONICO]]) -> 1301400 | AS38: 5250 | AT38: =AR38/L38 -> 3470.4
A39: =A38 -> 46066 | B39: =DAY(Tabla1[[#This Row],[FECHA]]) -> 13 | C39: 14 (MAÑANA) | D39: 38 | E39: FINAL TURNO 1 | F39: 1600 | G39: 4200 | H39: 1910 | I39: 130 | J39: 50 | K39: 17022 | L39: =+(K40-Tabla1[[#This Row],[Lectura Horometro INICIAL (06:00)]])*Tabla1[[#This Row],[CAUDAL DE TRATAMIENTO]] -> 450 | M39: 75 | N39: =F39-F40 -> 110 | O39: =G39-G40 -> 230 | P39: =H39-H40 -> 60 | Q39: =I39-I40 -> 5 | R39: =J39-J40 -> 5 | S39: =(N39*$AC$2) -> 143 | T39: =(O39*$AD$2) -> 304.75 | U39: =(P39*$AE$2) -> 75 | V39: =Tabla1[[#This Row],[CONSUMO POL ANIONICO (KG)]] -> 5 | W39: =Tabla1[[#This Row],[CONSUMO POL CATIONICO (KG)]] -> 5 | X39: =(S39*1000)/L39 -> 317.77778 | Y39: =(T39*1000)/L39 -> 677.22222 | Z39: =(U39*1000)/L39 -> 166.66667 | AA39: =(V39*1000)/L39 -> 11.111111 | AB39: =(W39*1000)/L39 -> 11.111111 | AC39: 1.3 | AD39: 1.325 | AE39: 1.25 | AF39: 2500 | AG39: 2500 | AH39: 830 | AI39: 2900 | AJ39: 6295 | AK39: 19050 | AL39: 22050 | AM39: =S39*AH39 -> 118690 | AN39: =T39*AI39 -> 883775 | AO39: =U39*AJ39 -> 472125 | AP39: =V39*AK39 -> 95250 | AQ39: =W39*AL39 -> 110250 | AR39: =SUM(Tabla1[[#This Row],[COSTO OPERATIVO ACIDO]:[COSTO OPERATIVO CATIONICO]]) -> 1680090 | AS39: 5250 | AT39: =AR39/L39 -> 3733.5333
A40: =A39 -> 46066 | B40: =DAY(Tabla1[[#This Row],[FECHA]]) -> 13 | C40: 3(TARDE) | D40: 39 | E40: FINAL TURNO 2 | F40: 1490 | G40: 3970 | H40: 1850 | I40: 125 | J40: 45 | K40: 17028 | L40: =+(K41-Tabla1[[#This Row],[Lectura Horometro INICIAL (06:00)]])*Tabla1[[#This Row],[CAUDAL DE TRATAMIENTO]] -> 300 | M40: 75 | N40: =F40-F41 -> 100 | O40: =G40-G41 -> 70 | P40: =H40-H41 -> 50 | Q40: =I40-I41 -> 0 | R40: =J40-J41 -> 5 | S40: =(N40*$AC$2) -> 130 | T40: =(O40*$AD$2) -> 92.75 | U40: =(P40*$AE$2) -> 62.5 | V40: =Tabla1[[#This Row],[CONSUMO POL ANIONICO (KG)]] -> 0 | W40: =Tabla1[[#This Row],[CONSUMO POL CATIONICO (KG)]] -> 5 | X40: =(S40*1000)/L40 -> 433.33333 | Y40: =(T40*1000)/L40 -> 309.16667 | Z40: =(U40*1000)/L40 -> 208.33333 | AA40: =(V40*1000)/L40 -> 0 | AB40: =(W40*1000)/L40 -> 16.666667 | AC40: 1.3 | AD40: 1.325 | AE40: 1.25 | AF40: 2500 | AG40: 2500 | AH40: 830 | AI40: 2900 | AJ40: 6295 | AK40: 19050 | AL40: 22050 | AM40: =S40*AH40 -> 107900 | AN40: =T40*AI40 -> 268975 | AO40: =U40*AJ40 -> 393437.5 | AP40: =V40*AK40 -> 0 | AQ40: =W40*AL40 -> 110250 | AR40: =SUM(Tabla1[[#This Row],[COSTO OPERATIVO ACIDO]:[COSTO OPERATIVO CATIONICO]]) -> 880562.5 | AS40: 5250 | AT40: =AR40/L40 -> 2935.2083
...

Sheet DB QUIMICA
A1: CONSUMO DE QUIMICO | M1: TABLA GRAFICA 1 Y 2 . CONSUMO QUIMICO DETALLADO | U1: TABLA GRAFICA 2. COSTO CONSUMO QUIMICO VS $M3 | AA1: TABLA GRAFICA 3. RO COSTO CONSUMO QUIMICO VS $M3 | AG1: TABLA GRAFICA 4. RO PPM CONSUMO QUIMICO
A2: GEM
B3: CONSUMO QUIMICO PPM
L4: FECHA | M4: CAUDAL TOTAL TRATADO GEM | N4: COF 235 - PPM COAGULANTE | O4: COF 255 - PPM DECOLORANTE | P4: COF 280 - PPM ACIDO | Q4: COF 440 - PPM POL ANIONICO | R4: COF 494 - PPM POL CATIONICO | U4: DIA | V4: CAUDAL TOTAL TRATADO GEM | W4: INDICADOR $m3 | X4: 2024-2 $m3 GEM | Y4: 2024 $m3 GEM | AA4: DÍA | AB4: VOLUMEN ENVIADO A RO (m3) | AC4: LIMITE INDICADOR M3 | AD4: INDICADOR $m3 RO | AG4: DÍA | AH4: VOLUMEN ENVIADO A RO (m3) | AI4: PPM HCL | AJ4: PPM KURIVERTER | AK4: PPM VITEC | AL4: PPM BISULFITO
L5: (en blanco) | M5: 0 | N5: 0 | O5: 0 | P5: 0 | Q5: 0 | R5: 0 | U5: 1 | V5: 0 | W5: 0 | X5: 5250 | Y5: 4909 | AA5: 1 | AB5: 0 | AC5: 1000 | AD5: 0 | AG5: 1 | AH5: 0 | AI5: 0 | AJ5: 0 | AK5: 0 | AL5: 0
L6: 46054 | M6: 0 | N6: 0 | O6: 0 | P6: 0 | Q6: 0 | R6: 0 | U6: 2 | V6: 1125 | W6: 4748.1533 | X6: 5250 | Y6: 4909 | AA6: 2 | AB6: 837.584 | AC6: 1000 | AD6: 0 | AG6: 2 | AH6: 837.584 | AI6: 0 | AJ6: 0 | AK6: 0 | AL6: 0
L7: 46055 | M7: 1125 | N7: 965.77778 | O7: 188.88889 | P7: 508.44444 | Q7: 2.2222222 | R7: 13.333333 | U7: 3 | V7: 1650 | W7: 3732.7652 | X7: 5250 | Y7: 4909 | AA7: 3 | AB7: 1099.659 | AC7: 1000 | AD7: 436.75388 | AG7: 3 | AH7: 1099.659 | AI7: 0 | AJ7: 173.57853 | AK7: 248.88098 | AL7: 0
L8: 46056 | M8: 1650 | N8: 610.30303 | O8: 219.69697 | P8: 433.33333 | Q8: 4.5454545 | R8: 6.0606061 | U8: 4 | V8: 1575 | W8: 3747.9794 | X8: 5250 | Y8: 4909 | AA8: 4 | AB8: 697.483 | AC8: 1000 | AD8: 183.25448 | AG8: 4 | AH8: 697.483 | AI8: 0 | AJ8: 64.391936 | AK8: 105.64302 | AL8: 0
L9: 46057 | M9: 1575 | N9: 656.19048 | O9: 198.4127 | P9: 718.09524 | Q9: 0 | R9: 0 | U9: 5 | V9: 1500 | W9: 2896.65 | X9: 5250 | Y9: 4909 | AA9: 5 | AB9: 891.009 | AC9: 1000 | AD9: 210.6845 | AG9: 5 | AH9: 891.009 | AI9: 0 | AJ9: 97.031725 | AK9: 118.13928 | AL9: 0
L10: 46058 | M10: 1500 | N10: 468.16667 | O10: 166.66667 | P10: 260 | Q10: 6.6666667 | R10: 6.6666667 | U10: 6 | V10: 1350 | W10: 4029.6759 | X10: 5250 | Y10: 4909 | AA10: 6 | AB10: 940.076 | AC10: 1000 | AD10: 136.5934 | AG10: 6 | AH10: 940.076 | AI10: 0 | AJ10: 95.550319 | AK10: 71.886685 | AL10: 0
L11: 46059 | M11: 1350 | N11: 775.37037 | O11: 194.44444 | P11: 192.59259 | Q11: 3.7037037 | R11: 14.814815 | U11: 7 | V11: 900 | W11: 3415.6944 | X11: 5250 | Y11: 4909 | AA11: 7 | AB11: 0 | AC11: 1000 | AD11: 0 | AG11: 7 | AH11: 0 | AI11: 0 | AJ11: 0 | AK11: 0 | AL11: 0
L12: 46060 | M12: 900 | N12: 736.11111 | O12: 83.333333 | P12: 361.11111 | Q12: 11.111111 | R12: 11.111111 | U12: 8 | V12: 0 | W12: 0 | X12: 5250 | Y12: 4909 | AA12: 8 | AB12: 0 | AC12: 1000 | AD12: 0 | AG12: 8 | AH12: 0 | AI12: 0 | AJ12: 0 | AK12: 0 | AL12: 0
L13: 46061 | M13: 0 | N13: 0 | O13: 0 | P13: 0 | Q13: 0 | R13: 0 | U13: 9 | V13: 1350 | W13: 3314.4259 | X13: 5250 | Y13: 4909 | AA13: 9 | AB13: 257 | AC13: 1000 | AD13: 681.20798 | AG13: 9 | AH13: 257 | AI13: 0 | AJ13: 235.92054 | AK13: 393.2009 | AL13: 0
L14: 46062 | M14: 1350 | N14: 687.03704 | O14: 129.62963 | P14: 144.44444 | Q14: 7.4074074 | R14: 11.111111 | U14: 10 | V14: 1425 | W14: 1834.986 | X14: 5250 | Y14: 4909 | AA14: 10 | AB14: 758.194 | AC14: 1000 | AD14: 98.763891 | AG14: 10 | AH14: 758.194 | AI14: 0 | AJ14: 44.426902 | AK14: 55.533627 | AL14: 0
L15: 46063 | M15: 1425 | N15: 306.84211 | O15: 70.175439 | P15: 246.31579 | Q15: 3.5087719 | R15: 10.526316 | U15: 11 | V15: 1275 | W15: 2305.9706 | X15: 5250 | Y15: 4909 | AA15: 11 | AB15: 547.272 | AC15: 1000 | AD15: 434.07 | AG15: 11 | AH15: 547.272 | AI15: 0 | AJ15: 287.23008 | AK15: 230.80989 | AL15: 0
L16: 46064 | M16: 1275 | N16: 332.54902 | O16: 107.84314 | P16: 305.88235 | Q16: 7.8431373 | R16: 11.764706 | U16: 12 | V16: 1200 | W16: 2339.7979 | X16: 5250 | Y16: 4909 | AA16: 12 | AB16: 859.353 | AC16: 1000 | AD16: 214.86777 | AG16: 12 | AH16: 859.353 | AI16: 0 | AJ16: 134.31566 | AK16: 115.38669 | AL16: 0
L17: 46065 | M17: 1200 | N17: 441.66667 | O17: 52.083333 | P17: 357.5 | Q17: 8.3333333 | R17: 12.5 | U17: 13 | V17: 1125 | W17: 3432.9356 | X17: 5250 | Y17: 4909 | AA17: 13 | AB17: 651.494 | AC17: 1000 | AD17: 269.49051 | AG17: 13 | AH17: 651.494 | AI17: 0 | AJ17: 499.79591 | AK17: 96.943172 | AL17: 0
... L27: 46075 | M27: 0 | N27: 0 | O27: 0 | P27: 0 | Q27: 0 | R27: 0 | U27: 23 | V27: 720 | W27: 4786.7604 | X27: 5250 | Y27: 4909 | AA27: 23 | AB27: 79.931 | AC27: 1000 | AD27: 0 | AG27: 23 | AH27: 79.931 | AI27: 0 | AJ27: 0 | AK27: 0 | AL27: 0
B28: COSTO TTO - CAUDAL TRATADP GEM Vs $M3 | L28: 46076 | M28: 720 | N28: 717.70833 | O28: 190.97222 | P28: 938.88889 | Q28: 13.888889 | R28: 20.833333 | U28: 24 | V28: 1120 | W28: 4312.2946 | X28: 5250 | Y28: 4909 | AA28: 24 | AB28: 570.72 | AC28: 1000 | AD28: 131.83979 | AG28: 24 | AH28: 570.72 | AI28: 0 | AJ28: 61.774846 | AK28: 73.775692 | AL28: 0
L29: 46077 | M29: 1120 | N29: 828.125 | O29: 223.21429 | P29: 150.89286 | Q29: 4.4642857 | R29: 13.392857 | U29: 25 | V29: 1440 | W29: 3124.6493 | X29: 5250 | Y29: 4909 | AA29: 25 | AB29: 517.128 | AC29: 1000 | AD29: 401.95501 | AG29: 25 | AH29: 517.128 | AI29: 0 | AJ29: 195.41126 | AK29: 223.90873 | AL29: 0
L30: 46078 | M30: 1440 | N30: 717.70833 | O30: 86.805556 | P30: 162.5 | Q30: 6.9444444 | R30: 10.416667 | U30: 26 | V30: 1760 | W30: 2749.6989 | X30: 5250 | Y30: 4909 | AA30: 26 | AB30: 523.891 | AC30: 1000 | AD30: 450.98662 | AG30: 26 | AH30: 523.891 | AI30: 0 | AJ30: 150.02451 | AK30: 261.20339 | AL30: 0
L31: 46079 | M31: 1760 | N31: 391.47727 | O31: 142.04545 | P31: 576.13636 | Q31: 2.8409091 | R31: 8.5227273 | U31: 27 | V31: 1440 | W31: 3432.7483 | X31: 5250 | Y31: 4909 | AA31: 27 | AB31: 689.869 | AC31: 1000 | AD31: 696.20296 | AG31: 27 | AH31: 689.869 | AI31: 0 | AJ31: 65.102622 | AK31: 427.23596 | AL31: 0
L32: 46080 | M32: 1440 | N32: 552.08333 | O32: 182.29167 | P32: 388.19444 | Q32: 6.9444444 | R32: 10.416667 | U32: 28 | V32: 960 | W32: 4258.4714 | X32: 5250 | Y32: 4909 | AA32: 28 | AB32: 748.371 | AC32: 1000 | AD32: 707.33226 | AG32: 28 | AH32: 748.371 | AI32: 0 | AJ32: 150.03348 | AK32: 421.96915 | AL32: 0
L33: 46081 | M33: 960 | N33: 690.10417 | O33: 247.39583 | P33: 446.875 | Q33: 5.2083333 | R33: 10.416667 | U33: Total general | V33: 30080 | W33: 3239.6917 | X33: 5250 | Y33: 4909 | AA33: Total general | AB33: 14053.279 | AC33: 1000 | AD33: 425.38438 | AG33: Total general | AH33: 14053.279 | AI33: 0 | AJ33: 177.38059 | AK33: 241.20237 | AL33: 0
L34: 46082 | M34: 0 | N34: 0 | O34: 0 | P34: 0 | Q34: 0 | R34: 0
L35: 46083 | M35: -1378240 | N35: 0 | O35: 0 | P35: 0 | Q35: 0 | R35: 0
L36: 46084 | M36: 0 | N36: 0 | O36: 0 | P36: 0 | Q36: 0 | R36: 0
L37: Total general | M37: -1348160 | N37: -16.884865 | O37: -5.108815 | P37: -8.0613577 | Q37: -0.1520591 | R37: -0.35604083
B51: CONSOLIDADO COSTO TTO - CAUDAL TRATADP GEM Vs $M3 | F51: CONSOLIDADO COSTO TTO - CAUDAL TRATADP RO Vs $M3
B53: ACUMULADO CAUDAL TRATADO GEM | D53: 97449928 | F53: ACUMULADO CAUDAL TRATADO RO | H53: 6078804.1
B54: TOTAL CAUDAL TRATADO GEM | C54: $m3 | D54: 114996411 | F54: TOTAL CAUDAL TRATADO RO | G54: $m3 | H54: 2515885.2
A55: GEM | B55: =+GETPIVOTDATA(" CAUDAL TOTAL TRATADO GEM ",$U$4) -> 30080 | C55: =+D53/B55 -> 3239.6917 | D55: =C55*B55 -> 97449928 | F55: =+GETPIVOTDATA(" VOLUMEN ENVIADO A RO (m3)",$AA$4) -> 14053.279 | G55: =H53/F55 -> 432.55415 | H55: =G55*F55 -> 6078804.1
A56: TH | B56: 13239 | C56: =+D53/B56 -> 7360.8224
A58: OSMOSIS INVERSA
B81: CONSUMO QUIMICO PPM

Sheet CONSUMO QUÍMICA-CAUDALES GEM  
A1: CONSOLIDADO CONSUMO DIARIO QUÍMICA (Litros)
B2: DIAS
A3: PRODUCTOS QUÍMICOS | B3: 1 | C3: 2 | D3: 3 | E3: 4 | F3: 5 | G3: 6 | H3: 7 | I3: 8 | J3: 9 | K3: 10 | L3: 11 | M3: 12 | N3: 13 | O3: 14 | P3: 15 | Q3: 16 | R3: 17 | S3: 18 | T3: 19 | U3: 20 | V3: 21 | W3: 22 | X3: 23 | Y3: 24 | Z3: 25 | AA3: 26 | AB3: 27 | AC3: 28 | AD3: (en blanco) | AE3: Total general
A4: COF 280 ACIDO (L) | B4: 150 | C4: 440 | D4: 550 | E4: 870 | F4: 300 | G4: 200 | H4: 250 | I4: 0 | J4: 150 | K4: 270 | L4: 300 | M4: 330 | N4: 310 | O4: 90 | P4: 0 | Q4: 400 | R4: 250 | S4: 280 | T4: 320 | U4: 250 | V4: 280 | W4: 0 | X4: 520 | Y4: 130 | Z4: 180 | AA4: 780 | AB4: 430 | AC4: 330 | AD4: 0 | AE4: 8360
A5: COF 235 COAGULANTE (L) | B5: 4200 | C5: 820 | D5: 760 | E5: 780 | F5: 530 | G5: 790 | H5: 500 | I5: 0 | J5: 700 | K5: 330 | L5: 320 | M5: 400 | N5: 500 | O5: 490 | P5: 0 | Q5: 860 | R5: 300 | S5: 0 | T5: 370 | U5: 380 | V5: 500 | W5: 160 | X5: 390 | Y5: 700 | Z5: 780 | AA5: 520 | AB5: 600 | AC5: 500 | AD5: 0 | AE5: 17180
A6: COF 255 DECOLORANTE (L) | B6: 1900 | C6: 170 | D6: 290 | E6: 250 | F6: 200 | G6: 210 | H6: 60 | I6: 0 | J6: 140 | K6: 80 | L6: 110 | M6: 50 | N6: 150 | O6: 20 | P6: 0 | Q6: 180 | R6: 110 | S6: 200 | T6: 140 | U6: 110 | V6: 130 | W6: 0 | X6: 110 | Y6: 200 | Z6: 100 | AA6: 200 | AB6: 210 | AC6: 190 | AD6: 0 | AE6: 5510
A7: COF 440 POL ANIONICO (KG) | B7: 40 | C7: 2.5 | D7: 7.5 | E7: 0 | F7: 10 | G7: 5 | H7: 10 | I7: 5 | J7: 10 | K7: 5 | L7: 10 | M7: 10 | N7: 5 | O7: 10 | P7: 0 | Q7: 5 | R7: 5 | S7: 5 | T7: 5 | U7: 5 | V7: 5 | W7: 0 | X7: 10 | Y7: 5 | Z7: 10 | AA7: 5 | AB7: 10 | AC7: 5 | AD7: 0 | AE7: 205
A8: COF 494 POL CATIONICO (KG) | B8: 155 | C8: 15 | D8: 10 | E8: 0 | F8: 10 | G8: 20 | H8: 10 | I8: 0 | J8: 15 | K8: 15 | L8: 15 | M8: 15 | N8: 15 | O8: 10 | P8: 0 | Q8: 15 | R8: 15 | S8: 15 | T8: 15 | U8: 15 | V8: 15 | W8: 0 | X8: 15 | Y8: 15 | Z8: 15 | AA8: 15 | AB8: 15 | AC8: 10 | AD8: 0 | AE8: 480
A10: CONSOLIDADO CONSUMO DIARIO QUÍMICA (Kg)
B11: DIAS
A12: PRODUCTOS QUÍMICOS | B12: 1 | C12: 2 | D12: 3 | E12: 4 | F12: 5 | G12: 6 | H12: 7 | I12: 8 | J12: 9 | K12: 10 | L12: 11 | M12: 12 | N12: 13 | O12: 14 | P12: 15 | Q12: 16 | R12: 17 | S12: 18 | T12: 19 | U12: 20 | V12: 21 | W12: 22 | X12: 23 | Y12: 24 | Z12: 25 | AA12: 26 | AB12: 27 | AC12: 28 | AD12: (en blanco) | AE12: Total general
A13: COF 280 - KG ACIDO | B13: 195 | C13: 572 | D13: 715 | E13: 1131 | F13: 390 | G13: 260 | H13: 325 | I13: 0 | J13: 195 | K13: 351 | L13: 390 | M13: 429 | N13: 403 | O13: 117 | P13: 0 | Q13: 520 | R13: 325 | S13: 364 | T13: 416 | U13: 325 | V13: 364 | W13: 0 | X13: 676 | Y13: 169 | Z13: 234 | AA13: 1014 | AB13: 559 | AC13: 429 | AD13: 0 | AE13: 10868
A14: COF 235 - KG COAGULANTE | B14: 5565 | C14: 1086.5 | D14: 1007 | E14: 1033.5 | F14: 702.25 | G14: 1046.75 | H14: 662.5 | I14: 0 | J14: 927.5 | K14: 437.25 | L14: 424 | M14: 530 | N14: 662.5 | O14: 649.25 | P14: 0 | Q14: 1139.5 | R14: 397.5 | S14: 0 | T14: 490.25 | U14: 503.5 | V14: 662.5 | W14: 212 | X14: 516.75 | Y14: 927.5 | Z14: 1033.5 | AA14: 689 | AB14: 795 | AC14: 662.5 | AD14: 0 | AE14: 22763.5
A15: COF 255 - KG DECOLORANTE | B15: 2375 | C15: 212.5 | D15: 362.5 | E15: 312.5 | F15: 250 | G15: 262.5 | H15: 75 | I15: 0 | J15: 175 | K15: 100 | L15: 137.5 | M15: 62.5 | N15: 187.5 | O15: 25 | P15: 0 | Q15: 225 | R15: 137.5 | S15: 250 | T15: 175 | U15: 137.5 | V15: 162.5 | W15: 0 | X15: 137.5 | Y15: 250 | Z15: 125 | AA15: 250 | AB15: 262.5 | AC15: 237.5 | AD15: 0 | AE15: 6887.5
A16: COF 440 - KG POL ANIONICO | B16: 40 | C16: 2.5 | D16: 7.5 | E16: 0 | F16: 10 | G16: 5 | H16: 10 | I16: 5 | J16: 10 | K16: 5 | L16: 10 | M16: 10 | N16: 5 | O16: 10 | P16: 0 | Q16: 5 | R16: 5 | S16: 5 | T16: 5 | U16: 5 | V16: 5 | W16: 0 | X16: 10 | Y16: 5 | Z16: 10 | AA16: 5 | AB16: 10 | AC16: 5 | AD16: 0 | AE16: 205
A17: COF 494 - KG POL CATIONICO | B17: 155 | C17: 15 | D17: 10 | E17: 0 | F17: 10 | G17: 20 | H17: 10 | I17: 0 | J17: 15 | K17: 15 | L17: 15 | M17: 15 | N17: 15 | O17: 10 | P17: 0 | Q17: 15 | R17: 15 | S17: 15 | T17: 15 | U17: 15 | V17: 15 | W17: 0 | X17: 15 | Y17: 15 | Z17: 15 | AA17: 15 | AB17: 15 | AC17: 10 | AD17: 0 | AE17: 480
A19: CONSOLIDADO DOSIFICACIÓN QUÍMICA PPM (mg/L)
B20: DIAS
A21: PRODUCTOS QUÍMICOS | B21: 1 | C21: 2 | D21: 3 | E21: 4 | F21: 5 | G21: 6 | H21: 7 | I21: 8 | J21: 9 | K21: 10 | L21: 11 | M21: 12 | N21: 13 | O21: 14 | P21: 15 | Q21: 16 | R21: 17 | S21: 18 | T21: 19 | U21: 20 | V21: 21 | W21: 22 | X21: 23 | Y21: 24 | Z21: 25 | AA21: 26 | AB21: 27 | AC21: 28 | AD21: (en blanco)
