Workbook
Name SegmentaciónDeDatos_FECHA: #N/A
Name SegmentaciónDeDatos_FECHA1: #N/A
Name SegmentaciónDeDatos_FECHA2: #N/A

Sheet INVENTARIO Y CONSUMO GEM  
A1: FECHA | B1: DIA | C1: ANALISIS TURNO | D1: # TURNO | E1: DILIGENCIAR BITACORA | F1: FINAL ACIDO (L) | G1: FINAL COAGULANTE (L) | H1: FINAL DECOLORANTE (L) | I1: FINAL POL ANIONICO (KG) | J1: FINAL POL CATIONICO (KG) | K1: Lectura Horometro INICIAL (06:00) | L1: CAUDAL TOTAL TRATADO GEM | M1: CAUDAL DE TRATAMIENTO | N1: CAUDAL 2 | O1: CONSUMO LITROS ACIDO (L) | P1: CONSUMO LITROS COAGULANTE (L) | Q1: CONSUMO LITROS DECOLORANTE (L) | R1: CONSUMO POL ANIONICO (KG) | S1: CONSUMO POL CATIONICO (KG) | T1: KG ACIDO | U1: KG COAGULANTE | V1: KG DECOLORANTE | W1: KG POL ANIONICO | X1: KG POL CATIONICO | Y1: PPM ACIDO | Z1: PPM COAGULANTE | AA1: PPM DECOLORANTE | AB1: PPM POL ANIONICO | AC1: PPM POL CATIONICO | AD1: DENSIDAD ACIDO | AE1: DENSIDAD COAGULANTE | AF1: DENSIDAD DECOLORANTE | AG1: DENSIDAD ANIONICO | AH1: DENSIDAD CATIONICO | AI1: PRECIO (KG) ACIDO | AJ1: PRECIO (KG) COAGULANTE | AK1: PRECIO (KG) DECOLORANTE | AL1: PRECIO (KG) ANIONICO | AM1: PRECIO (KG) CATIONICO | AN1: COSTO OPERATIVO ACIDO | AO1: COSTO OPERATIVO COAGULANTE | AP1: COSTO OPERATIVO DECOLORANTE | AQ1: COSTO OPERATIVO ANIONICO | AR1: COSTO OPERATIVO CATIONICO | AS1: COSTO QUIMICA | AT1: LIMITE INDICADOR M3 | AU1: $ m3
A2: 46023 | B2: =DAY(Tabla1[[#This Row],[FECHA]]) -> 1 | C2: 1 (NOCHE) | D2: 1 | E2: FINAL TURNO 3 | F2: 2160 | G2: 2100 | H2: 1670 | I2: 250 | J2: 185 | K2: 16502 | L2: 0 | M2: 80 | N2: =+Tabla1[[#This Row],[CAUDAL DE TRATAMIENTO]]+$M$102 -> 88.462687 | O2: =F2-F3 -> 0 | P2: =G2-G3 -> 0 | Q2: =H2-H3 -> 0 | R2: =I2-I3 -> 0 | S2: 0 | T2: =(O2*$AD$2) -> 0 | U2: =(P2*$AE$2) -> 0 | V2: =(Q2*$AF$2) -> 0 | W2: =Tabla1[[#This Row],[CONSUMO POL ANIONICO (KG)]] -> 0 | X2: =Tabla1[[#This Row],[CONSUMO POL CATIONICO (KG)]] -> 0 | Y2: =(T2*1000)/L2 -> #DIV/0! | Z2: =(U2*1000)/L2 -> #DIV/0! | AA2: =(V2*1000)/L2 -> #DIV/0! | AB2: =(W2*1000)/L2 -> #DIV/0! | AC2: =(X2*1000)/L2 -> #DIV/0! | AD2: 1.3 | AE2: 1.325 | AF2: 1.25 | AG2: 2500 | AH2: 2500 | AI2: 830 | AJ2: 2900 | AK2: 6295 | AL2: 19050 | AM2: 22050 | AN2: =T2*AI2 -> 0 | AO2: =U2*AJ2 -> 0 | AP2: =V2*AK2 -> 0 | AQ2: =W2*AL2 -> 0 | AR2: =X2*AM2 -> 0 | AS2: =SUM(Tabla1[[#This Row],[COSTO OPERATIVO ACIDO]:[COSTO OPERATIVO CATIONICO]]) -> 0 | AT2: 5250 | AU2: =AS2/L2 -> #DIV/0!
A3: =A2 -> 46023 | B3: =DAY(Tabla1[[#This Row],[FECHA]]) -> 1 | C3: 2 (MAÑANA) | D3: 2 | E3: FINAL TURNO 1 | F3: 2160 | G3: 2100 | H3: 1670 | I3: 250 | J3: 185 | K3: 16502 | L3: 0 | M3: 80 | N3: =+Tabla1[[#This Row],[CAUDAL DE TRATAMIENTO]]+$M$102 -> 88.462687 | O3: =F3-F4 -> 0 | P3: =G3-G4 -> 0 | Q3: =H3-H4 -> 0 | R3: =I3-I4 -> 0 | S3: 0 | T3: =(O3*$AD$2) -> 0 | U3: =(P3*$AE$2) -> 0 | V3: =(Q3*$AF$2) -> 0 | W3: =Tabla1[[#This Row],[CONSUMO POL ANIONICO (KG)]] -> 0 | X3: =Tabla1[[#This Row],[CONSUMO POL CATIONICO (KG)]] -> 0 | Y3: =(T3*1000)/L3 -> #DIV/0! | Z3: =(U3*1000)/L3 -> #DIV/0! | AA3: =(V3*1000)/L3 -> #DIV/0! | AB3: =(W3*1000)/L3 -> #DIV/0! | AC3: =(X3*1000)/L3 -> #DIV/0! | AD3: 1.3 | AE3: 1.325 | AF3: 1.25 | AG3: 2500 | AH3: 2500 | AI3: 830 | AJ3: 2900 | AK3: 6295 | AL3: 19050 | AM3: 22050 | AN3: =T3*AI3 -> 0 | AO3: =U3*AJ3 -> 0 | AP3: =V3*AK3 -> 0 | AQ3: =W3*AL3 -> 0 | AR3: =X3*AM3 -> 0 | AS3: =SUM(Tabla1[[#This Row],[COSTO OPERATIVO ACIDO]:[COSTO OPERATIVO CATIONICO]]) -> 0 | AT3: 5250 | AU3: =AS3/L3 -> #DIV/0!
A4: =A3 -> 46023 | B4: =DAY(Tabla1[[#This Row],[FECHA]]) -> 1 | C4: 3(TARDE) | D4: 3 | E4: FINAL TURNO 2 | F4: 2160 | G4: 2100 | H4: 1670 | I4: 250 | J4: 185 | K4: 16502 | L4: 0 | M4: 80 | N4: =+Tabla1[[#This Row],[CAUDAL DE TRATAMIENTO]]+$M$102 -> 88.462687 | O4: =F4-F5 -> 0 | P4: =G4-G5 -> 0 | Q4: =H4-H5 -> 0 | R4: =I4-I5 -> 0 | S4: 0 | T4: =(O4*$AD$2) -> 0 | U4: =(P4*$AE$2) -> 0 | V4: =(Q4*$AF$2) -> 0 | W4: =Tabla1[[#This Row],[CONSUMO POL ANIONICO (KG)]] -> 0 | X4: =Tabla1[[#This Row],[CONSUMO POL CATIONICO (KG)]] -> 0 | Y4: =(T4*1000)/L4 -> #DIV/0! | Z4: =(U4*1000)/L4 -> #DIV/0! | AA4: =(V4*1000)/L4 -> #DIV/0! | AB4: =(W4*1000)/L4 -> #DIV/0! | AC4: =(X4*1000)/L4 -> #DIV/0! | AD4: 1.3 | AE4: 1.325 | AF4: 1.25 | AG4: 2500 | AH4: 2500 | AI4: 830 | AJ4: 2900 | AK4: 6295 | AL4: 19050 | AM4: 22050 | AN4: =T4*AI4 -> 0 | AO4: =U4*AJ4 -> 0 | AP4: =V4*AK4 -> 0 | AQ4: =W4*AL4 -> 0 | AR4: =X4*AM4 -> 0 | AS4: =SUM(Tabla1[[#This Row],[COSTO OPERATIVO ACIDO]:[COSTO OPERATIVO CATIONICO]]) -> 0 | AT4: 5250 | AU4: =AS4/L4 -> #DIV/0!
A5: 46024 | B5: =DAY(Tabla1[[#This Row],[FECHA]]) -> 2 | C5: 2 (NOCHE) | D5: 4 | E5: FINAL TURNO 3 | F5: 2160 | G5: 2100 | H5: 1670 | I5: 250 | J5: 185 | K5: 16502 | L5: 0 | M5: 80 | N5: =+Tabla1[[#This Row],[CAUDAL DE TRATAMIENTO]]+$M$102 -> 88.462687 | O5: =F5-F6 -> 0 | P5: =G5-G6 -> 0 | Q5: =H5-H6 -> 0 | R5: =I5-I6 -> 0 | S5: =J5-J6 -> 0 | T5: =(O5*$AD$2) -> 0 | U5: =(P5*$AE$2) -> 0 | V5: =(Q5*$AF$2) -> 0 | W5: =Tabla1[[#This Row],[CONSUMO POL ANIONICO (KG)]] -> 0 | X5: =Tabla1[[#This Row],[CONSUMO POL CATIONICO (KG)]] -> 0 | Y5: =(T5*1000)/L5 -> #DIV/0! | Z5: =(U5*1000)/L5 -> #DIV/0! | AA5: =(V5*1000)/L5 -> #DIV/0! | AB5: =(W5*1000)/L5 -> #DIV/0! | AC5: =(X5*1000)/L5 -> #DIV/0! | AD5: 1.3 | AE5: 1.325 | AF5: 1.25 | AG5: 2500 | AH5: 2500 | AI5: 830 | AJ5: 2900 | AK5: 6295 | AL5: 19050 | AM5: 22050 | AN5: =T5*AI5 -> 0 | AO5: =U5*AJ5 -> 0 | AP5: =V5*AK5 -> 0 | AQ5: =W5*AL5 -> 0 | AR5: =X5*AM5 -> 0 | AS5: =SUM(Tabla1[[#This Row],[COSTO OPERATIVO ACIDO]:[COSTO OPERATIVO CATIONICO]]) -> 0 | AT5: 5250 | AU5: =AS5/L5 -> #DIV/0!
A6: =A5 -> 46024 | B6: =DAY(Tabla1[[#This Row],[FECHA]]) -> 2 | C6: 3 (MAÑANA) | D6: 5 | E6: FINAL TURNO 1 | F6: 2160 | G6: 2100 | H6: 1670 | I6: 250 | J6: 185 | K6: 16502 | L6: 640.23881 | M6: 83 | N6: =+Tabla1[[#This Row],[CAUDAL DE TRATAMIENTO]]+$M$102 -> 91.462687 | O6: =F6-F7 -> 80 | P6: =G6-G7 -> 150 | Q6: =H6-H7 -> 70 | R6: =I6-I7 -> 5 | S6: =J6-J7 -> 5 | T6: =(O6*$AD$2) -> 104 | U6: =(P6*$AE$2) -> 198.75 | V6: =(Q6*$AF$2) -> 87.5 | W6: =Tabla1[[#This Row],[CONSUMO POL ANIONICO (KG)]] -> 5 | X6: =Tabla1[[#This Row],[CONSUMO POL CATIONICO (KG)]] -> 5 | Y6: =(T6*1000)/L6 -> 162.43939 | Z6: =(U6*1000)/L6 -> 310.43104 | AA6: =(V6*1000)/L6 -> 136.66775 | AB6: =(W6*1000)/L6 -> 7.809586 | AC6: =(X6*1000)/L6 -> 7.809586 | AD6: 1.3 | AE6: 1.325 | AF6: 1.25 | AG6: 2500 | AH6: 2500 | AI6: 830 | AJ6: 2900 | AK6: 6295 | AL6: 19050 | AM6: 22050 | AN6: =T6*AI6 -> 86320 | AO6: =U6*AJ6 -> 576375 | AP6: =V6*AK6 -> 550812.5 | AQ6: =W6*AL6 -> 95250 | AR6: =X6*AM6 -> 110250 | AS6: =SUM(Tabla1[[#This Row],[COSTO OPERATIVO ACIDO]:[COSTO OPERATIVO CATIONICO]]) -> 1419007.5 | AT6: 5250 | AU6: =AS6/L6 -> 2216.3722
A7: =A6 -> 46024 | B7: =DAY(Tabla1[[#This Row],[FECHA]]) -> 2 | C7: 3(TARDE) | D7: 6 | E7: FINAL TURNO 2 | F7: 2080 | G7: 1950 | H7: 1600 | I7: 245 | J7: 180 | K7: 16509 | L7: 174.92537 | M7: 79 | N7: =+Tabla1[[#This Row],[CAUDAL DE TRATAMIENTO]]+$M$102 -> 87.462687 | O7: =F7-F8 -> 80 | P7: =G7-G8-150 -> 50 | Q7: =H7-H8 -> 50 | R7: =I7-I8 -> 5 | S7: =J7-J8 -> 5 | T7: =(O7*$AD$2) -> 104 | U7: =(P7*$AE$2) -> 66.25 | V7: =(Q7*$AF$2) -> 62.5 | W7: =Tabla1[[#This Row],[CONSUMO POL ANIONICO (KG)]] -> 5 | X7: =Tabla1[[#This Row],[CONSUMO POL CATIONICO (KG)]] -> 5 | Y7: =(T7*1000)/L7 -> 594.53925 | Z7: =(U7*1000)/L7 -> 378.73294 | AA7: =(V7*1000)/L7 -> 357.29522 | AB7: =(W7*1000)/L7 -> 28.583618 | AC7: =(X7*1000)/L7 -> 28.583618 | AD7: 1.3 | AE7: 1.325 | AF7: 1.25 | AG7: 2500 | AH7: 2500 | AI7: 830 | AJ7: 2900 | AK7: 6295 | AL7: 19050 | AM7: 22050 | AN7: =T7*AI7 -> 86320 | AO7: =U7*AJ7 -> 192125 | AP7: =V7*AK7 -> 393437.5 | AQ7: =W7*AL7 -> 95250 | AR7: =X7*AM7 -> 110250 | AS7: =SUM(Tabla1[[#This Row],[COSTO OPERATIVO ACIDO]:[COSTO OPERATIVO CATIONICO]]) -> 877382.5 | AT7: 5250 | AU7: =AS7/L7 -> 5015.7532
A8: 46025 | B8: =DAY(Tabla1[[#This Row],[FECHA]]) -> 3 | C8: 3 (NOCHE) | D8: 7 | E8: FINAL TURNO 3 | F8: 2000 | G8: 1750 | H8: 1550 | I8: 240 | J8: 175 | K8: 16511 | L8: 0 | M8: 0 | N8: =+Tabla1[[#This Row],[CAUDAL DE TRATAMIENTO]]+$M$102 -> 8.4626866 | O8: =F8-F9 -> 40 | P8: =G8-G9 -> 80 | Q8: =H8-H9 -> 25 | R8: =I8-I9 -> 0 | S8: =J8-J9 -> 0 | T8: =(O8*$AD$2) -> 52 | U8: =(P8*$AE$2) -> 106 | V8: =(Q8*$AF$2) -> 31.25 | W8: =Tabla1[[#This Row],[CONSUMO POL ANIONICO (KG)]] -> 0 | X8: =Tabla1[[#This Row],[CONSUMO POL CATIONICO (KG)]] -> 0 | Y8: =(T8*1000)/L8 -> #DIV/0! | Z8: =(U8*1000)/L8 -> #DIV/0! | AA8: =(V8*1000)/L8 -> #DIV/0! | AB8: =(W8*1000)/L8 -> #DIV/0! | AC8: =(X8*1000)/L8 -> #DIV/0! | AD8: 1.3 | AE8: 1.325 | AF8: 1.25 | AG8: 2500 | AH8: 2500 | AI8: 830 | AJ8: 2900 | AK8: 6295 | AL8: 19050 | AM8: 22050 | AN8: =T8*AI8 -> 43160 | AO8: =U8*AJ8 -> 307400 | AP8: =V8*AK8 -> 196718.75 | AQ8: =W8*AL8 -> 0 | AR8: =X8*AM8 -> 0 | AS8: =SUM(Tabla1[[#This Row],[COSTO OPERATIVO ACIDO]:[COSTO OPERATIVO CATIONICO]]) -> 547278.75 | AT8: 5250 | AU8: =AS8/L8 -> #DIV/0!
A9: =A8 -> 46025 | B9: =DAY(Tabla1[[#This Row],[FECHA]]) -> 3 | C9: 4 (MAÑANA) | D9: 8 | E9: FINAL TURNO 1 | F9: =+AVERAGE(F8,F10) -> 1960 | G9: =+AVERAGE(G8,G10) -> 1670 | H9: =+AVERAGE(H8,H10) -> 1525 | I9: 240 | J9: 175 | K9: 16511 | L9: 268.38806 | M9: 81 | N9: =+Tabla1[[#This Row],[CAUDAL DE TRATAMIENTO]]+$M$102 -> 89.462687 | O9: =F9-F10 -> 40 | P9: =G9-G10 -> 80 | Q9: =H9-H10 -> 25 | R9: =I9-I10 -> 0 | S9: =J9-J10 -> 0 | T9: =(O9*$AD$2) -> 52 | U9: =(P9*$AE$2) -> 106 | V9: =(Q9*$AF$2) -> 31.25 | W9: =Tabla1[[#This Row],[CONSUMO POL ANIONICO (KG)]] -> 0 | X9: =Tabla1[[#This Row],[CONSUMO POL CATIONICO (KG)]] -> 0 | Y9: =(T9*1000)/L9 -> 193.7493 | Z9: =(U9*1000)/L9 -> 394.95051 | AA9: =(V9*1000)/L9 -> 116.43588 | AB9: =(W9*1000)/L9 -> 0 | AC9: =(X9*1000)/L9 -> 0 | AD9: 1.3 | AE9: 1.325 | AF9: 1.25 | AG9: 2500 | AH9: 2500 | AI9: 830 | AJ9: 2900 | AK9: 6295 | AL9: 19050 | AM9: 22050 | AN9: =T9*AI9 -> 43160 | AO9: =U9*AJ9 -> 307400 | AP9: =V9*AK9 -> 196718.75 | AQ9: =W9*AL9 -> 0 | AR9: =X9*AM9 -> 0 | AS9: =SUM(Tabla1[[#This Row],[COSTO OPERATIVO ACIDO]:[COSTO OPERATIVO CATIONICO]]) -> 547278.75 | AT9: 5250 | AU9: =AS9/L9 -> 2039.1323
A10: =A9 -> 46025 | B10: =DAY(Tabla1[[#This Row],[FECHA]]) -> 3 | C10: 3(TARDE) | D10: 9 | E10: FINAL TURNO 2 | F10: 1920 | G10: 1590 | H10: 1500 | I10: 240 | J10: 175 | K10: 16514 | L10: 0 | M10: 0 | N10: =+Tabla1[[#This Row],[CAUDAL DE TRATAMIENTO]]+$M$102 -> 8.4626866 | O10: =F10-F11 -> 0 | P10: =G10-G11 -> 0 | Q10: =H10-H11 -> 0 | R10: 0 | S10: 0 | T10: =(O10*$AD$2) -> 0 | U10: =(P10*$AE$2) -> 0 | V10: =(Q10*$AF$2) -> 0 | W10: =Tabla1[[#This Row],[CONSUMO POL ANIONICO (KG)]] -> 0 | X10: =Tabla1[[#This Row],[CONSUMO POL CATIONICO (KG)]] -> 0 | Y10: =(T10*1000)/L10 -> #DIV/0! | Z10: =(U10*1000)/L10 -> #DIV/0! | AA10: =(V10*1000)/L10 -> #DIV/0! | AB10: =(W10*1000)/L10 -> #DIV/0! | AC10: =(X10*1000)/L10 -> #DIV/0! | AD10: 1.3 | AE10: 1.325 | AF10: 1.25 | AG10: 2500 | AH10: 2500 | AI10: 830 | AJ10: 2900 | AK10: 6295 | AL10: 19050 | AM10: 22050 | AN10: =T10*AI10 -> 0 | AO10: =U10*AJ10 -> 0 | AP10: =V10*AK10 -> 0 | AQ10: =W10*AL10 -> 0 | AR10: =X10*AM10 -> 0 | AS10: =SUM(Tabla1[[#This Row],[COSTO OPERATIVO ACIDO]:[COSTO OPERATIVO CATIONICO]]) -> 0 | AT10: 5250 | AU10: =AS10/L10 -> #DIV/0!
A11: 46026 | B11: =DAY(Tabla1[[#This Row],[FECHA]]) -> 4 | C11: 4 (NOCHE) | D11: 10 | E11: FINAL TURNO 3 | F11: 1920 | G11: 1590 | H11: 1500 | I11: 240 | J11: 175 | K11: 16514 | L11: 0 | M11: 0 | N11: =+Tabla1[[#This Row],[CAUDAL DE TRATAMIENTO]]+$M$102 -> 8.4626866 | O11: =F11-F12 -> 0 | P11: =G11-G12 -> 0 | Q11: =H11-H12 -> 0 | R11: 0 | S11: 0 | T11: =(O11*$AD$2) -> 0 | U11: =(P11*$AE$2) -> 0 | V11: =(Q11*$AF$2) -> 0 | W11: =Tabla1[[#This Row],[CONSUMO POL ANIONICO (KG)]] -> 0 | X11: =Tabla1[[#This Row],[CONSUMO POL CATIONICO (KG)]] -> 0 | Y11: =(T11*1000)/L11 -> #DIV/0! | Z11: =(U11*1000)/L11 -> #DIV/0! | AA11: =(V11*1000)/L11 -> #DIV/0! | AB11: =(W11*1000)/L11 -> #DIV/0! | AC11: =(X11*1000)/L11 -> #DIV/0! | AD11: 1.3 | AE11: 1.325 | AF11: 1.25 | AG11: 2500 | AH11: 2500 | AI11: 830 | AJ11: 2900 | AK11: 6295 | AL11: 19050 | AM11: 22050 | AN11: =T11*AI11 -> 0 | AO11: =U11*AJ11 -> 0 | AP11: =V11*AK11 -> 0 | AQ11: =W11*AL11 -> 0 | AR11: =X11*AM11 -> 0 | AS11: =SUM(Tabla1[[#This Row],[COSTO OPERATIVO ACIDO]:[COSTO OPERATIVO CATIONICO]]) -> 0 | AT11: 5250 | AU11: =AS11/L11 -> #DIV/0!
A12: =A11 -> 46026 | B12: =DAY(Tabla1[[#This Row],[FECHA]]) -> 4 | C12: 5 (MAÑANA) | D12: 11 | E12: FINAL TURNO 1 | F12: 1920 | G12: 1590 | H12: 1500 | I12: 240 | J12: 175 | K12: 16514 | L12: 0 | M12: 0 | N12: =+Tabla1[[#This Row],[CAUDAL DE TRATAMIENTO]]+$M$102 -> 8.4626866 | O12: =F12-F13 -> 0 | P12: =G12-G13 -> 0 | Q12: =H12-H13 -> 0 | R12: 0 | S12: 0 | T12: =(O12*$AD$2) -> 0 | U12: =(P12*$AE$2) -> 0 | V12: =(Q12*$AF$2) -> 0 | W12: =Tabla1[[#This Row],[CONSUMO POL ANIONICO (KG)]] -> 0 | X12: =Tabla1[[#This Row],[CONSUMO POL CATIONICO (KG)]] -> 0 | Y12: =(T12*1000)/L12 -> #DIV/0! | Z12: =(U12*1000)/L12 -> #DIV/0! | AA12: =(V12*1000)/L12 -> #DIV/0! | AB12: =(W12*1000)/L12 -> #DIV/0! | AC12: =(X12*1000)/L12 -> #DIV/0! | AD12: 1.3 | AE12: 1.325 | AF12: 1.25 | AG12: 2500 | AH12: 2500 | AI12: 830 | AJ12: 2900 | AK12: 6295 | AL12: 19050 | AM12: 22050 | AN12: =T12*AI12 -> 0 | AO12: =U12*AJ12 -> 0 | AP12: =V12*AK12 -> 0 | AQ12: =W12*AL12 -> 0 | AR12: =X12*AM12 -> 0 | AS12: =SUM(Tabla1[[#This Row],[COSTO OPERATIVO ACIDO]:[COSTO OPERATIVO CATIONICO]]) -> 0 | AT12: 5250 | AU12: =AS12/L12 -> #DIV/0!
A13: =A12 -> 46026 | B13: =DAY(Tabla1[[#This Row],[FECHA]]) -> 4 | C13: 3(TARDE) | D13: 12 | E13: FINAL TURNO 2 | F13: 1920 | G13: 1590 | H13: 1500 | I13: 240 | J13: 175 | K13: 16514 | L13: 0 | M13: 0 | N13: =+Tabla1[[#This Row],[CAUDAL DE TRATAMIENTO]]+$M$102 -> 8.4626866 | O13: =F13-F14 -> 0 | P13: =G13-G14 -> 0 | Q13: =H13-H14 -> 0 | R13: 0 | S13: 0 | T13: =(O13*$AD$2) -> 0 | U13: =(P13*$AE$2) -> 0 | V13: =(Q13*$AF$2) -> 0 | W13: =Tabla1[[#This Row],[CONSUMO POL ANIONICO (KG)]] -> 0 | X13: =Tabla1[[#This Row],[CONSUMO POL CATIONICO (KG)]] -> 0 | Y13: =(T13*1000)/L13 -> #DIV/0! | Z13: =(U13*1000)/L13 -> #DIV/0! | AA13: =(V13*1000)/L13 -> #DIV/0! | AB13: =(W13*1000)/L13 -> #DIV/0! | AC13: =(X13*1000)/L13 -> #DIV/0! | AD13: 1.3 | AE13: 1.325 | AF13: 1.25 | AG13: 2500 | AH13: 2500 | AI13: 830 | AJ13: 2900 | AK13: 6295 | AL13: 19050 | AM13: 22050 | AN13: =T13*AI13 -> 0 | AO13: =U13*AJ13 -> 0 | AP13: =V13*AK13 -> 0 | AQ13: =W13*AL13 -> 0 | AR13: =X13*AM13 -> 0 | AS13: =SUM(Tabla1[[#This Row],[COSTO OPERATIVO ACIDO]:[COSTO OPERATIVO CATIONICO]]) -> 0 | AT13: 5250 | AU13: =AS13/L13 -> #DIV/0!
A14: 46027 | B14: =DAY(Tabla1[[#This Row],[FECHA]]) -> 5 | C14: 5 (NOCHE) | D14: 13 | E14: FINAL TURNO 3 | F14: 1920 | G14: 1590 | H14: 1500 | I14: 240 | J14: 175 | K14: 16514 | L14: 89.462687 | M14: 81 | N14: =+Tabla1[[#This Row],[CAUDAL DE TRATAMIENTO]]+$M$102 -> 89.462687 | O14: =F14-F15 -> 0 | P14: =G14-G15-100 -> 50 | Q14: =H14-H15 -> 0 | R14: 0 | S14: 0 | T14: =(O14*$AD$2) -> 0 | U14: =(P14*$AE$2) -> 66.25 | V14: =(Q14*$AF$2) -> 0 | W14: =Tabla1[[#This Row],[CONSUMO POL ANIONICO (KG)]] -> 0 | X14: =Tabla1[[#This Row],[CONSUMO POL CATIONICO (KG)]] -> 0 | Y14: =(T14*1000)/L14 -> 0 | Z14: =(U14*1000)/L14 -> 740.5322 | AA14: =(V14*1000)/L14 -> 0 | AB14: =(W14*1000)/L14 -> 0 | AC14: =(X14*1000)/L14 -> 0 | AD14: 1.3 | AE14: 1.325 | AF14: 1.25 | AG14: 2500 | AH14: 2500 | AI14: 830 | AJ14: 2900 | AK14: 6295 | AL14: 19050 | AM14: 22050 | AN14: =T14*AI14 -> 0 | AO14: =U14*AJ14 -> 192125 | AP14: =V14*AK14 -> 0 | AQ14: =W14*AL14 -> 0 | AR14: =X14*AM14 -> 0 | AS14: =SUM(Tabla1[[#This Row],[COSTO OPERATIVO ACIDO]:[COSTO OPERATIVO CATIONICO]]) -> 192125 | AT14: 5250 | AU14: =AS14/L14 -> 2147.5434
A15: =A14 -> 46027 | B15: =DAY(Tabla1[[#This Row],[FECHA]]) -> 5 | C15: 6 (MAÑANA) | D15: 14 | E15: FINAL TURNO 1 | F15: 1920 | G15: 1440 | H15: 1500 | I15: 250 | J15: 170 | K15: 16515 | L15: 341.85075 | M15: 77 | N15: =+Tabla1[[#This Row],[CAUDAL DE TRATAMIENTO]]+$M$102 -> 85.462687 | O15: =F15-F16 -> 70 | P15: =G15-G16 -> 40 | Q15: =H15-H16 -> 50 | R15: =I15-I16 -> 0 | S15: =J15-J16 -> 5 | T15: =(O15*$AD$2) -> 91 | U15: =(P15*$AE$2) -> 53 | V15: =(Q15*$AF$2) -> 62.5 | W15: =Tabla1[[#This Row],[CONSUMO POL ANIONICO (KG)]] -> 0 | X15: =Tabla1[[#This Row],[CONSUMO POL CATIONICO (KG)]] -> 5 | Y15: =(T15*1000)/L15 -> 266.19804 | Z15: =(U15*1000)/L15 -> 155.03842 | AA15: =(V15*1000)/L15 -> 182.82833 | AB15: =(W15*1000)/L15 -> 0 | AC15: =(X15*1000)/L15 -> 14.626266 | AD15: 1.3 | AE15: 1.325 | AF15: 1.25 | AG15: 2500 | AH15: 2500 | AI15: 830 | AJ15: 2900 | AK15: 6295 | AL15: 19050 | AM15: 22050 | AN15: =T15*AI15 -> 75530 | AO15: =U15*AJ15 -> 153700 | AP15: =V15*AK15 -> 393437.5 | AQ15: =W15*AL15 -> 0 | AR15: =X15*AM15 -> 110250 | AS15: =SUM(Tabla1[[#This Row],[COSTO OPERATIVO ACIDO]:[COSTO OPERATIVO CATIONICO]]) -> 732917.5 | AT15: 5250 | AU15: =AS15/L15 -> 2143.9693
A16: =A15 -> 46027 | B16: =DAY(Tabla1[[#This Row],[FECHA]]) -> 5 | C16: 3(TARDE) | D16: 15 | E16: FINAL TURNO 2 | F16: 1850 | G16: 1400 | H16: 1450 | I16: 250 | J16: 165 | K16: 16519 | L16: 437.31343 | M16: 79 | N16: =+Tabla1[[#This Row],[CAUDAL DE TRATAMIENTO]]+$M$102 -> 87.462687 | O16: =F16-F17-100 -> 40 | P16: =G16-G17 -> 100 | Q16: =H16-H17 -> 50 | R16: =I16-I17 -> 0 | S16: =J16-J17 -> 5 | T16: =(O16*$AD$2) -> 52 | U16: =(P16*$AE$2) -> 132.5 | V16: =(Q16*$AF$2) -> 62.5 | W16: =Tabla1[[#This Row],[CONSUMO POL ANIONICO (KG)]] -> 0 | X16: =Tabla1[[#This Row],[CONSUMO POL CATIONICO (KG)]] -> 5 | Y16: =(T16*1000)/L16 -> 118.90785 | Z16: =(U16*1000)/L16 -> 302.98635 | AA16: =(V16*1000)/L16 -> 142.91809 | AB16: =(W16*1000)/L16 -> 0 | AC16: =(X16*1000)/L16 -> 11.433447 | AD16: 1.3 | AE16: 1.325 | AF16: 1.25 | AG16: 2500 | AH16: 2500 | AI16: 830 | AJ16: 2900 | AK16: 6295 | AL16: 19050 | AM16: 22050 | AN16: =T16*AI16 -> 43160 | AO16: =U16*AJ16 -> 384250 | AP16: =V16*AK16 -> 393437.5 | AQ16: =W16*AL16 -> 0 | AR16: =X16*AM16 -> 110250 | AS16: =SUM(Tabla1[[#This Row],[COSTO OPERATIVO ACIDO]:[COSTO OPERATIVO CATIONICO]]) -> 931097.5 | AT16: 5250 | AU16: =AS16/L16 -> 2129.1308
A17: 46028 | B17: =DAY(Tabla1[[#This Row],[FECHA]]) -> 6 | C17: 6 (NOCHE) | D17: 16 | E17: FINAL TURNO 3 | F17: 1710 | G17: 1300 | H17: 1400 | I17: 250 | J17: 160 | K17: 16524 | L17: 271.38806 | M17: 82 | N17: =+Tabla1[[#This Row],[CAUDAL DE TRATAMIENTO]]+$M$102 -> 90.462687 | O17: =F17-F18 -> 60 | P17: =G17-G18-150 -> 150 | Q17: =H17-H18 -> 30 | R17: =I17-I18 -> 5 | S17: =J17-J18 -> 5 | T17: =(O17*$AD$2) -> 78 | U17: =(P17*$AE$2) -> 198.75 | V17: =(Q17*$AF$2) -> 37.5 | W17: =Tabla1[[#This Row],[CONSUMO POL ANIONICO (KG)]] -> 5 | X17: =Tabla1[[#This Row],[CONSUMO POL CATIONICO (KG)]] -> 5 | Y17: =(T17*1000)/L17 -> 287.41132 | Z17: =(U17*1000)/L17 -> 732.34615 | AA17: =(V17*1000)/L17 -> 138.17852 | AB17: =(W17*1000)/L17 -> 18.423802 | AC17: =(X17*1000)/L17 -> 18.423802 | AD17: 1.3 | AE17: 1.325 | AF17: 1.25 | AG17: 2500 | AH17: 2500 | AI17: 830 | AJ17: 2900 | AK17: 6295 | AL17: 19050 | AM17: 22050 | AN17: =T17*AI17 -> 64740 | AO17: =U17*AJ17 -> 576375 | AP17: =V17*AK17 -> 236062.5 | AQ17: =W17*AL17 -> 95250 | AR17: =X17*AM17 -> 110250 | AS17: =SUM(Tabla1[[#This Row],[COSTO OPERATIVO ACIDO]:[COSTO OPERATIVO CATIONICO]]) -> 1082677.5 | AT17: 5250 | AU17: =AS17/L17 -> 3989.4073
A18: =A17 -> 46028 | B18: =DAY(Tabla1[[#This Row],[FECHA]]) -> 6 | C18: 7 (MAÑANA) | D18: 17 | E18: FINAL TURNO 1 | F18: 1650 | G18: 1000 | H18: 1370 | I18: 245 | J18: 155 | K18: 16527 | L18: 280.38806 | M18: 85 | N18: =+Tabla1[[#This Row],[CAUDAL DE TRATAMIENTO]]+$M$102 -> 93.462687 | O18: =F18-F19 -> 200 | P18: =G18-G19 -> 200 | Q18: =H18-H19 -> 90 | R18: =I18-I19 -> 0 | S18: =J18-J19 -> 0 | T18: =(O18*$AD$2) -> 260 | U18: =(P18*$AE$2) -> 265 | V18: =(Q18*$AF$2) -> 112.5 | W18: =Tabla1[[#This Row],[CONSUMO POL ANIONICO (KG)]] -> 0 | X18: =Tabla1[[#This Row],[CONSUMO POL CATIONICO (KG)]] -> 0 | Y18: =(T18*1000)/L18 -> 927.28628 | Z18: =(U18*1000)/L18 -> 945.11871 | AA18: =(V18*1000)/L18 -> 401.22964 | AB18: =(W18*1000)/L18 -> 0 | AC18: =(X18*1000)/L18 -> 0 | AD18: 1.3 | AE18: 1.325 | AF18: 1.25 | AG18: 2500 | AH18: 2500 | AI18: 830 | AJ18: 2900 | AK18: 6295 | AL18: 19050 | AM18: 22050 | AN18: =T18*AI18 -> 215800 | AO18: =U18*AJ18 -> 768500 | AP18: =V18*AK18 -> 708187.5 | AQ18: =W18*AL18 -> 0 | AR18: =X18*AM18 -> 0 | AS18: =SUM(Tabla1[[#This Row],[COSTO OPERATIVO ACIDO]:[COSTO OPERATIVO CATIONICO]]) -> 1692487.5 | AT18: 5250 | AU18: =AS18/L18 -> 6036.2324
A19: =A18 -> 46028 | B19: =DAY(Tabla1[[#This Row],[FECHA]]) -> 6 | C19: 3(TARDE) | D19: 18 | E19: FINAL TURNO 2 | F19: 1450 | G19: 800 | H19: 1280 | I19: 245 | J19: 155 | K19: 16530 | L19: 530.77612 | M19: 80 | N19: =+Tabla1[[#This Row],[CAUDAL DE TRATAMIENTO]]+$M$102 -> 88.462687 | O19: =F19-F20+3000 -> 160 | P19: =G19-G20+2000 -> 150 | Q19: =H19-H20 -> 80 | R19: =I19-I20 -> 0 | S19: =J19-J20+25 -> 5 | T19: =(O19*$AD$2) -> 208 | U19: =(P19*$AE$2) -> 198.75 | V19: =(Q19*$AF$2) -> 100 | W19: =Tabla1[[#This Row],[CONSUMO POL ANIONICO (KG)]] -> 0 | X19: =Tabla1[[#This Row],[CONSUMO POL CATIONICO (KG)]] -> 5 | Y19: =(T19*1000)/L19 -> 391.87897 | Z19: =(U19*1000)/L19 -> 374.45166 | AA19: =(V19*1000)/L19 -> 188.40335 | AB19: =(W19*1000)/L19 -> 0 | AC19: =(X19*1000)/L19 -> 9.4201676 | AD19: 1.3 | AE19: 1.325 | AF19: 1.25 | AG19: 2500 | AH19: 2500 | AI19: 830 | AJ19: 2900 | AK19: 6295 | AL19: 19050 | AM19: 22050 | AN19: =T19*AI19 -> 172640 | AO19: =U19*AJ19 -> 576375 | AP19: =V19*AK19 -> 629500 | AQ19: =W19*AL19 -> 0 | AR19: =X19*AM19 -> 110250 | AS19: =SUM(Tabla1[[#This Row],[COSTO OPERATIVO ACIDO]:[COSTO OPERATIVO CATIONICO]]) -> 1488765 | AT19: 5250 | AU19: =AS19/L19 -> 2804.8832
A20: 46029 | B20: =DAY(Tabla1[[#This Row],[FECHA]]) -> 7 | C20: 7 (NOCHE) | D20: 19 | E20: FINAL TURNO 3 | F20: 4290 | G20: 2650 | H20: 1200 | I20: 245 | J20: 175 | K20: 16536 | L20: 262.38806 | M20: 79 | N20: =+Tabla1[[#This Row],[CAUDAL DE TRATAMIENTO]]+$M$102 -> 87.462687 | O20: =F20-F21 -> 50 | P20: =G20-G21 -> 350 | Q20: =H20-H21 -> 50 | R20: =I20-I21 -> 5 | S20: =J20-J21 -> 5 | T20: =(O20*$AD$2) -> 65 | U20: =(P20*$AE$2) -> 463.75 | V20: =(Q20*$AF$2) -> 62.5 | W20: =Tabla1[[#This Row],[CONSUMO POL ANIONICO (KG)]] -> 5 | X20: =Tabla1[[#This Row],[CONSUMO POL CATIONICO (KG)]] -> 5 | Y20: =(T20*1000)/L20 -> 247.72469 | Z20: =(U20*1000)/L20 -> 1767.4204 | AA20: =(V20*1000)/L20 -> 238.19681 | AB20: =(W20*1000)/L20 -> 19.055745 | AC20: =(X20*1000)/L20 -> 19.055745 | AD20: 1.3 | AE20: 1.325 | AF20: 1.25 | AG20: 2500 | AH20: 2500 | AI20: 830 | AJ20: 2900 | AK20: 6295 | AL20: 19050 | AM20: 22050 | AN20: =T20*AI20 -> 53950 | AO20: =U20*AJ20 -> 1344875 | AP20: =V20*AK20 -> 393437.5 | AQ20: =W20*AL20 -> 95250 | AR20: =X20*AM20 -> 110250 | AS20: =SUM(Tabla1[[#This Row],[COSTO OPERATIVO ACIDO]:[COSTO OPERATIVO CATIONICO]]) -> 1997762.5 | AT20: 5250 | AU20: =AS20/L20 -> 7613.7706
A21: =A20 -> 46029 | B21: =DAY(Tabla1[[#This Row],[FECHA]]) -> 7 | C21: 8 (MAÑANA) | D21: 20 | E21: FINAL TURNO 1 | F21: 4240 | G21: 2300 | H21: 1150 | I21: 240 | J21: 170 | K21: 16539 | L21: 180.92537 | M21: 82 | N21: =+Tabla1[[#This Row],[CAUDAL DE TRATAMIENTO]]+$M$102 -> 90.462687 | O21: =F21-F22 -> 90 | P21: =G21-G22-150 -> 150 | Q21: =H21-H22 -> 50 | R21: =I21-I22 -> 0 | S21: =J21-J22 -> 5 | T21: =(O21*$AD$2) -> 117 | U21: =(P21*$AE$2) -> 198.75 | V21: =(Q21*$AF$2) -> 62.5 | W21: =Tabla1[[#This Row],[CONSUMO POL ANIONICO (KG)]] -> 0 | X21: =Tabla1[[#This Row],[CONSUMO POL CATIONICO (KG)]] -> 5 | Y21: =(T21*1000)/L21 -> 646.67547 | Z21: =(U21*1000)/L21 -> 1098.5192 | AA21: =(V21*1000)/L21 -> 345.4463 | AB21: =(W21*1000)/L21 -> 0 | AC21: =(X21*1000)/L21 -> 27.635704 | AD21: 1.3 | AE21: 1.325 | AF21: 1.25 | AG21: 2500 | AH21: 2500 | AI21: 830 | AJ21: 2900 | AK21: 6295 | AL21: 19050 | AM21: 22050 | AN21: =T21*AI21 -> 97110 | AO21: =U21*AJ21 -> 576375 | AP21: =V21*AK21 -> 393437.5 | AQ21: =W21*AL21 -> 0 | AR21: =X21*AM21 -> 110250 | AS21: =SUM(Tabla1[[#This Row],[COSTO OPERATIVO ACIDO]:[COSTO OPERATIVO CATIONICO]]) -> 1177172.5 | AT21: 5250 | AU21: =AS21/L21 -> 6506.3981
A22: =A21 -> 46029 | B22: =DAY(Tabla1[[#This Row],[FECHA]]) -> 7 | C22: 3(TARDE) | D22: 21 | E22: FINAL TURNO 2 | F22: 4150 | G22: 2000 | H22: 1100 | I22: 240 | J22: 165 | K22: 16541 | L22: 432.31343 | M22: 78 | N22: =+Tabla1[[#This Row],[CAUDAL DE TRATAMIENTO]]+$M$102 -> 86.462687 | O22: =F22-F23 -> 120 | P22: =G22-G23+1000 -> 200 | Q22: =H22-H23 -> 40 | R22: =I22-I23 -> 0 | S22: =J22-J23 -> 5 | T22: =(O22*$AD$2) -> 156 | U22: =(P22*$AE$2) -> 265 | V22: =(Q22*$AF$2) -> 50 | W22: =Tabla1[[#This Row],[CONSUMO POL ANIONICO (KG)]] -> 0 | X22: =Tabla1[[#This Row],[CONSUMO POL CATIONICO (KG)]] -> 5 | Y22: =(T22*1000)/L22 -> 360.8493 | Z22: =(U22*1000)/L22 -> 612.98118 | AA22: =(V22*1000)/L22 -> 115.65683 | AB22: =(W22*1000)/L22 -> 0 | AC22: =(X22*1000)/L22 -> 11.565683 | AD22: 1.3 | AE22: 1.325 | AF22: 1.25 | AG22: 2500 | AH22: 2500 | AI22: 830 | AJ22: 2900 | AK22: 6295 | AL22: 19050 | AM22: 22050 | AN22: =T22*AI22 -> 129480 | AO22: =U22*AJ22 -> 768500 | AP22: =V22*AK22 -> 314750 | AQ22: =W22*AL22 -> 0 | AR22: =X22*AM22 -> 110250 | AS22: =SUM(Tabla1[[#This Row],[COSTO OPERATIVO ACIDO]:[COSTO OPERATIVO CATIONICO]]) -> 1322980 | AT22: 5250 | AU22: =AS22/L22 -> 3060.2334
A23: 46030 | B23: =DAY(Tabla1[[#This Row],[FECHA]]) -> 8 | C23: 8 (NOCHE) | D23: 22 | E23: FINAL TURNO 3 | F23: 4030 | G23: 2800 | H23: 1060 | I23: 240 | J23: 160 | K23: 16546 | L23: 217.38806 | M23: 64 | N23: =+Tabla1[[#This Row],[CAUDAL DE TRATAMIENTO]]+$M$102 -> 72.462687 | O23: =F23-F24 -> 80 | P23: =G23-G24 -> 260 | Q23: =H23-H24 -> 20 | R23: =I23-I24 -> 5 | S23: =J23-J24 -> 5 | T23: =(O23*$AD$2) -> 104 | U23: =(P23*$AE$2) -> 344.5 | V23: =(Q23*$AF$2) -> 25 | W23: =Tabla1[[#This Row],[CONSUMO POL ANIONICO (KG)]] -> 5 | X23: =Tabla1[[#This Row],[CONSUMO POL CATIONICO (KG)]] -> 5 | Y23: =(T23*1000)/L23 -> 478.40714 | Z23: =(U23*1000)/L23 -> 1584.7237 | AA23: =(V23*1000)/L23 -> 115.00172 | AB23: =(W23*1000)/L23 -> 23.000343 | AC23: =(X23*1000)/L23 -> 23.000343 | AD23: 1.3 | AE23: 1.325 | AF23: 1.25 | AG23: 2500 | AH23: 2500 | AI23: 830 | AJ23: 2900 | AK23: 6295 | AL23: 19050 | AM23: 22050 | AN23: =T23*AI23 -> 86320 | AO23: =U23*AJ23 -> 999050 | AP23: =V23*AK23 -> 157375 | AQ23: =W23*AL23 -> 95250 | AR23: =X23*AM23 -> 110250 | AS23: =SUM(Tabla1[[#This Row],[COSTO OPERATIVO ACIDO]:[COSTO OPERATIVO CATIONICO]]) -> 1448245 | AT23: 5250 | AU23: =AS23/L23 -> 6662.0264
A24: =A23 -> 46030 | B24: =DAY(Tabla1[[#This Row],[FECHA]]) -> 8 | C24: 9 (MAÑANA) | D24: 23 | E24: FINAL TURNO 1 | F24: 3950 | G24: 2540 | H24: 1040 | I24: 235 | J24: 155 | K24: 16549 | L24: 305.85075 | M24: 68 | N24: =+Tabla1[[#This Row],[CAUDAL DE TRATAMIENTO]]+$M$102 -> 76.462687 | O24: =F24-F25 -> 220 | P24: =G24-G25 -> 100 | Q24: =H24-H25 -> 70 | R24: =I24-I25 -> 0 | S24: =J24-J25 -> 5 | T24: =(O24*$AD$2) -> 286 | U24: =(P24*$AE$2) -> 132.5 | V24: =(Q24*$AF$2) -> 87.5 | W24: =Tabla1[[#This Row],[CONSUMO POL ANIONICO (KG)]] -> 0 | X24: =Tabla1[[#This Row],[CONSUMO POL CATIONICO (KG)]] -> 5 | Y24: =(T24*1000)/L24 -> 935.09662 | Z24: =(U24*1000)/L24 -> 433.21784 | AA24: =(V24*1000)/L24 -> 286.08725 | AB24: =(W24*1000)/L24 -> 0 | AC24: =(X24*1000)/L24 -> 16.347843 | AD24: 1.3 | AE24: 1.325 | AF24: 1.25 | AG24: 2500 | AH24: 2500 | AI24: 830 | AJ24: 2900 | AK24: 6295 | AL24: 19050 | AM24: 22050 | AN24: =T24*AI24 -> 237380 | AO24: =U24*AJ24 -> 384250 | AP24: =V24*AK24 -> 550812.5 | AQ24: =W24*AL24 -> 0 | AR24: =X24*AM24 -> 110250 | AS24: =SUM(Tabla1[[#This Row],[COSTO OPERATIVO ACIDO]:[COSTO OPERATIVO CATIONICO]]) -> 1282692.5 | AT24: 5250 | AU24: =AS24/L24 -> 4193.8511
A25: =A24 -> 46030 | B25: =DAY(Tabla1[[#This Row],[FECHA]]) -> 8 | C25: 3(TARDE) | D25: 24 | E25: FINAL TURNO 2 | F25: 3730 | G25: 2440 | H25: 970 | I25: 235 | J25: 150 | K25: 16553 | L25: 434.77612 | M25: 64 | N25: =+Tabla1[[#This Row],[CAUDAL DE TRATAMIENTO]]+$M$102 -> 72.462687 | O25: =F25-F26 -> 30 | P25: =G25-G26-150 -> 190 | Q25: =H25-H26 -> 70 | R25: =I25-I26 -> 0 | S25: =J25-J26 -> 5 | T25: =(O25*$AD$2) -> 39 | U25: =(P25*$AE$2) -> 251.75 | V25: =(Q25*$AF$2) -> 87.5 | W25: =Tabla1[[#This Row],[CONSUMO POL ANIONICO (KG)]] -> 0 | X25: =Tabla1[[#This Row],[CONSUMO POL CATIONICO (KG)]] -> 5 | Y25: =(T25*1000)/L25 -> 89.701339 | Z25: =(U25*1000)/L25 -> 579.03364 | AA25: =(V25*1000)/L25 -> 201.253 | AB25: =(W25*1000)/L25 -> 0 | AC25: =(X25*1000)/L25 -> 11.500172 | AD25: 1.3 | AE25: 1.325 | AF25: 1.25 | AG25: 2500 | AH25: 2500 | AI25: 830 | AJ25: 2900 | AK25: 6295 | AL25: 19050 | AM25: 22050 | AN25: =T25*AI25 -> 32370 | AO25: =U25*AJ25 -> 730075 | AP25: =V25*AK25 -> 550812.5 | AQ25: =W25*AL25 -> 0 | AR25: =X25*AM25 -> 110250 | AS25: =SUM(Tabla1[[#This Row],[COSTO OPERATIVO ACIDO]:[COSTO OPERATIVO CATIONICO]]) -> 1423507.5 | AT25: 5250 | AU25: =AS25/L25 -> 3274.1161
A26: 46031 | B26: =DAY(Tabla1[[#This Row],[FECHA]]) -> 9 | C26: 9 (NOCHE) | D26: 25 | E26: FINAL TURNO 3 | F26: 3700 | G26: 2100 | H26: 900 | I26: 235 | J26: 145 | K26: 16559 | L26: 235.38806 | M26: 70 | N26: =+Tabla1[[#This Row],[CAUDAL DE TRATAMIENTO]]+$M$102 -> 78.462687 | O26: =F26-F27 -> 60 | P26: =G26-G27 -> 180 | Q26: =H26-H27 -> 50 | R26: =I26-I27 -> 5 | S26: =J26-J27 -> 5 | T26: =(O26*$AD$2) -> 78 | U26: =(P26*$AE$2) -> 238.5 | V26: =(Q26*$AF$2) -> 62.5 | W26: =Tabla1[[#This Row],[CONSUMO POL ANIONICO (KG)]] -> 5 | X26: =Tabla1[[#This Row],[CONSUMO POL CATIONICO (KG)]] -> 5 | Y26: =(T26*1000)/L26 -> 331.3677 | Z26: =(U26*1000)/L26 -> 1013.2205 | AA26: =(V26*1000)/L26 -> 265.51899 | AB26: =(W26*1000)/L26 -> 21.241519 | AC26: =(X26*1000)/L26 -> 21.241519 | AD26: 1.3 | AE26: 1.325 | AF26: 1.25 | AG26: 2500 | AH26: 2500 | AI26: 830 | AJ26: 2900 | AK26: 6295 | AL26: 19050 | AM26: 22050 | AN26: =T26*AI26 -> 64740 | AO26: =U26*AJ26 -> 691650 | AP26: =V26*AK26 -> 393437.5 | AQ26: =W26*AL26 -> 95250 | AR26: =X26*AM26 -> 110250 | AS26: =SUM(Tabla1[[#This Row],[COSTO OPERATIVO ACIDO]:[COSTO OPERATIVO CATIONICO]]) -> 1355327.5 | AT26: 5250 | AU26: =AS26/L26 -> 5757.843
A27: =A26 -> 46031 | B27: =DAY(Tabla1[[#This Row],[FECHA]]) -> 9 | C27: 10 (MAÑANA) | D27: 26 | E27: FINAL TURNO 1 | F27: 3640 | G27: 1920 | H27: 850 | I27: 230 | J27: 140 | K27: 16562 | L27: 250.38806 | M27: 75 | N27: =+Tabla1[[#This Row],[CAUDAL DE TRATAMIENTO]]+$M$102 -> 83.462687 | O27: =F27-F28 -> 75 | P27: =G27-G28-150 -> 105 | Q27: =H27-H28 -> 70 | R27: =I27-I28 -> 0 | S27: =J27-J28 -> 5 | T27: =(O27*$AD$2) -> 97.5 | U27: =(P27*$AE$2) -> 139.125 | V27: =(Q27*$AF$2) -> 87.5 | W27: =Tabla1[[#This Row],[CONSUMO POL ANIONICO (KG)]] -> 0 | X27: =Tabla1[[#This Row],[CONSUMO POL CATIONICO (KG)]] -> 5 | Y27: =(T27*1000)/L27 -> 389.39557 | Z27: =(U27*1000)/L27 -> 555.63752 | AA27: =(V27*1000)/L27 -> 349.45756 | AB27: =(W27*1000)/L27 -> 0 | AC27: =(X27*1000)/L27 -> 19.969003 | AD27: 1.3 | AE27: 1.325 | AF27: 1.25 | AG27: 2500 | AH27: 2500 | AI27: 830 | AJ27: 2900 | AK27: 6295 | AL27: 19050 | AM27: 22050 | AN27: =T27*AI27 -> 80925 | AO27: =U27*AJ27 -> 403462.5 | AP27: =V27*AK27 -> 550812.5 | AQ27: =W27*AL27 -> 0 | AR27: =X27*AM27 -> 110250 | AS27: =SUM(Tabla1[[#This Row],[COSTO OPERATIVO ACIDO]:[COSTO OPERATIVO CATIONICO]]) -> 1145450 | AT27: 5250 | AU27: =AS27/L27 -> 4574.699
A28: =A27 -> 46031 | B28: =DAY(Tabla1[[#This Row],[FECHA]]) -> 9 | C28: 3(TARDE) | D28: 27 | E28: FINAL TURNO 2 | F28: =+AVERAGE(F27,F29) -> 3565 | G28: =+AVERAGE(G27,G29) -> 1665 | H28: =+AVERAGE(H27,H29) -> 780 | I28: 230 | J28: 135 | K28: 16565 | L28: 488.77612 | M28: 73 | N28: =+Tabla1[[#This Row],[CAUDAL DE TRATAMIENTO]]+$M$102 -> 81.462687 | O28: =F28-F29 -> 75 | P28: =G28-G29 -> 255 | Q28: =H28-H29 -> 70 | R28: =I28-I29 -> 0 | S28: =J28-J29 -> 5 | T28: =(O28*$AD$2) -> 97.5 | U28: =(P28*$AE$2) -> 337.875 | V28: =(Q28*$AF$2) -> 87.5 | W28: =Tabla1[[#This Row],[CONSUMO POL ANIONICO (KG)]] -> 0 | X28: =Tabla1[[#This Row],[CONSUMO POL CATIONICO (KG)]] -> 5 | Y28: =(T28*1000)/L28 -> 199.47783 | Z28: =(U28*1000)/L28 -> 691.26741 | AA28: =(V28*1000)/L28 -> 179.01857 | AB28: =(W28*1000)/L28 -> 0 | AC28: =(X28*1000)/L28 -> 10.229632 | AD28: 1.3 | AE28: 1.325 | AF28: 1.25 | AG28: 2500 | AH28: 2500 | AI28: 830 | AJ28: 2900 | AK28: 6295 | AL28: 19050 | AM28: 22050 | AN28: =T28*AI28 -> 80925 | AO28: =U28*AJ28 -> 979837.5 | AP28: =V28*AK28 -> 550812.5 | AQ28: =W28*AL28 -> 0 | AR28: =X28*AM28 -> 110250 | AS28: =SUM(Tabla1[[#This Row],[COSTO OPERATIVO ACIDO]:[COSTO OPERATIVO CATIONICO]]) -> 1721825 | AT28: 5250 | AU28: =AS28/L28 -> 3522.7273
A29: 46032 | B29: =DAY(Tabla1[[#This Row],[FECHA]]) -> 10 | C29: 10 (NOCHE) | D29: 28 | E29: FINAL TURNO 3 | F29: 3490 | G29: 1410 | H29: 710 | I29: 230 | J29: 130 | K29: 16571 | L29: 417.31343 | M29: 75 | N29: =+Tabla1[[#This Row],[CAUDAL DE TRATAMIENTO]]+$M$102 -> 83.462687 | O29: =F29-F30-100 -> 40 | P29: =G29-G30 -> 160 | Q29: =H29-H30 -> 80 | R29: =I29-I30 -> 5 | S29: =J29-J30 -> 5 | T29: =(O29*$AD$2) -> 52 | U29: =(P29*$AE$2) -> 212 | V29: =(Q29*$AF$2) -> 100 | W29: =Tabla1[[#This Row],[CONSUMO POL ANIONICO (KG)]] -> 5 | X29: =Tabla1[[#This Row],[CONSUMO POL CATIONICO (KG)]] -> 5 | Y29: =(T29*1000)/L29 -> 124.60658 | Z29: =(U29*1000)/L29 -> 508.01144 | AA29: =(V29*1000)/L29 -> 239.62804 | AB29: =(W29*1000)/L29 -> 11.981402 | AC29: =(X29*1000)/L29 -> 11.981402 | AD29: 1.3 | AE29: 1.325 | AF29: 1.25 | AG29: 2500 | AH29: 2500 | AI29: 830 | AJ29: 2900 | AK29: 6295 | AL29: 19050 | AM29: 22050 | AN29: =T29*AI29 -> 43160 | AO29: =U29*AJ29 -> 614800 | AP29: =V29*AK29 -> 629500 | AQ29: =W29*AL29 -> 95250 | AR29: =X29*AM29 -> 110250 | AS29: =SUM(Tabla1[[#This Row],[COSTO OPERATIVO ACIDO]:[COSTO OPERATIVO CATIONICO]]) -> 1492960 | AT29: 5250 | AU29: =AS29/L29 -> 3577.5508
A30: =A29 -> 46032 | B30: =DAY(Tabla1[[#This Row],[FECHA]]) -> 10 | C30: 11 (MAÑANA) | D30: 29 | E30: FINAL TURNO 1 | F30: 3350 | G30: 1250 | H30: 630 | I30: 225 | J30: 125 | K30: 16576 | L30: 176.92537 | M30: 80 | N30: =+Tabla1[[#This Row],[CAUDAL DE TRATAMIENTO]]+$M$102 -> 88.462687 | O30: =F30-F31 -> 0 | P30: =G30-G31 -> 0 | Q30: =H30-H31 -> 0 | R30: =I30-I31 -> 0 | S30: =J30-J31 -> 0 | T30: =(O30*$AD$2) -> 0 | U30: =(P30*$AE$2) -> 0 | V30: =(Q30*$AF$2) -> 0 | W30: =Tabla1[[#This Row],[CONSUMO POL ANIONICO (KG)]] -> 0 | X30: =Tabla1[[#This Row],[CONSUMO POL CATIONICO (KG)]] -> 0 | Y30: =(T30*1000)/L30 -> 0 | Z30: =(U30*1000)/L30 -> 0 | AA30: =(V30*1000)/L30 -> 0 | AB30: =(W30*1000)/L30 -> 0 | AC30: =(X30*1000)/L30 -> 0 | AD30: 1.3 | AE30: 1.325 | AF30: 1.25 | AG30: 2500 | AH30: 2500 | AI30: 830 | AJ30: 2900 | AK30: 6295 | AL30: 19050 | AM30: 22050 | AN30: =T30*AI30 -> 0 | AO30: =U30*AJ30 -> 0 | AP30: =V30*AK30 -> 0 | AQ30: =W30*AL30 -> 0 | AR30: =X30*AM30 -> 0 | AS30: =SUM(Tabla1[[#This Row],[COSTO OPERATIVO ACIDO]:[COSTO OPERATIVO CATIONICO]]) -> 0 | AT30: 5250 | AU30: =AS30/L30 -> 0
A31: =A30 -> 46032 | B31: =DAY(Tabla1[[#This Row],[FECHA]]) -> 10 | C31: 3(TARDE) | D31: 30 | E31: FINAL TURNO 2 | F31: 3350 | G31: 1250 | H31: 630 | I31: 225 | J31: 125 | K31: 16578 | L31: 0 | M31: 0 | N31: =+Tabla1[[#This Row],[CAUDAL DE TRATAMIENTO]]+$M$102 -> 8.4626866 | O31: =F31-F32 -> 0 | P31: =G31-G32 -> 0 | Q31: =H31-H32 -> 0 | R31: =I31-I32 -> 0 | S31: =J31-J32 -> 0 | T31: =(O31*$AD$2) -> 0 | U31: =(P31*$AE$2) -> 0 | V31: =(Q31*$AF$2) -> 0 | W31: =Tabla1[[#This Row],[CONSUMO POL ANIONICO (KG)]] -> 0 | X31: =Tabla1[[#This Row],[CONSUMO POL CATIONICO (KG)]] -> 0 | Y31: =(T31*1000)/L31 -> #DIV/0! | Z31: =(U31*1000)/L31 -> #DIV/0! | AA31: =(V31*1000)/L31 -> #DIV/0! | AB31: =(W31*1000)/L31 -> #DIV/0! | AC31: =(X31*1000)/L31 -> #DIV/0! | AD31: 1.3 | AE31: 1.325 | AF31: 1.25 | AG31: 2500 | AH31: 2500 | AI31: 830 | AJ31: 2900 | AK31: 6295 | AL31: 19050 | AM31: 22050 | AN31: =T31*AI31 -> 0 | AO31: =U31*AJ31 -> 0 | AP31: =V31*AK31 -> 0 | AQ31: =W31*AL31 -> 0 | AR31: =X31*AM31 -> 0 | AS31: =SUM(Tabla1[[#This Row],[COSTO OPERATIVO ACIDO]:[COSTO OPERATIVO CATIONICO]]) -> 0 | AT31: 5250 | AU31: =AS31/L31 -> #DIV/0!
A32: 46033 | B32: =DAY(Tabla1[[#This Row],[FECHA]]) -> 11 | C32: 11 (NOCHE) | D32: 31 | E32: FINAL TURNO 3 | F32: 3350 | G32: 1250 | H32: 630 | I32: 225 | J32: 125 | K32: 16578 | L32: 0 | M32: 0 | N32: =+Tabla1[[#This Row],[CAUDAL DE TRATAMIENTO]]+$M$102 -> 8.4626866 | O32: =F32-F33 -> 0 | P32: =G32-G33 -> 0 | Q32: =H32-H33 -> 0 | R32: =I32-I33 -> 0 | S32: =J32-J33 -> 0 | T32: =(O32*$AD$2) -> 0 | U32: =(P32*$AE$2) -> 0 | V32: =(Q32*$AF$2) -> 0 | W32: =Tabla1[[#This Row],[CONSUMO POL ANIONICO (KG)]] -> 0 | X32: =Tabla1[[#This Row],[CONSUMO POL CATIONICO (KG)]] -> 0 | Y32: =(T32*1000)/L32 -> #DIV/0! | Z32: =(U32*1000)/L32 -> #DIV/0! | AA32: =(V32*1000)/L32 -> #DIV/0! | AB32: =(W32*1000)/L32 -> #DIV/0! | AC32: =(X32*1000)/L32 -> #DIV/0! | AD32: 1.3 | AE32: 1.325 | AF32: 1.25 | AG32: 2500 | AH32: 2500 | AI32: 830 | AJ32: 2900 | AK32: 6295 | AL32: 19050 | AM32: 22050 | AN32: =T32*AI32 -> 0 | AO32: =U32*AJ32 -> 0 | AP32: =V32*AK32 -> 0 | AQ32: =W32*AL32 -> 0 | AR32: =X32*AM32 -> 0 | AS32: =SUM(Tabla1[[#This Row],[COSTO OPERATIVO ACIDO]:[COSTO OPERATIVO CATIONICO]]) -> 0 | AT32: 5250 | AU32: =AS32/L32 -> #DIV/0!
A33: =A32 -> 46033 | B33: =DAY(Tabla1[[#This Row],[FECHA]]) -> 11 | C33: 12 (MAÑANA) | D33: 32 | E33: FINAL TURNO 1 | F33: 3350 | G33: 1250 | H33: 630 | I33: 225 | J33: 125 | K33: 16578 | L33: 0 | M33: 0 | N33: =+Tabla1[[#This Row],[CAUDAL DE TRATAMIENTO]]+$M$102 -> 8.4626866 | O33: =F33-F34 -> 0 | P33: =G33-G34 -> 0 | Q33: =H33-H34 -> 0 | R33: =I33-I34 -> 0 | S33: =J33-J34 -> 0 | T33: =(O33*$AD$2) -> 0 | U33: =(P33*$AE$2) -> 0 | V33: =(Q33*$AF$2) -> 0 | W33: =Tabla1[[#This Row],[CONSUMO POL ANIONICO (KG)]] -> 0 | X33: =Tabla1[[#This Row],[CONSUMO POL CATIONICO (KG)]] -> 0 | Y33: =(T33*1000)/L33 -> #DIV/0! | Z33: =(U33*1000)/L33 -> #DIV/0! | AA33: =(V33*1000)/L33 -> #DIV/0! | AB33: =(W33*1000)/L33 -> #DIV/0! | AC33: =(X33*1000)/L33 -> #DIV/0! | AD33: 1.3 | AE33: 1.325 | AF33: 1.25 | AG33: 2500 | AH33: 2500 | AI33: 830 | AJ33: 2900 | AK33: 6295 | AL33: 19050 | AM33: 22050 | AN33: =T33*AI33 -> 0 | AO33: =U33*AJ33 -> 0 | AP33: =V33*AK33 -> 0 | AQ33: =W33*AL33 -> 0 | AR33: =X33*AM33 -> 0 | AS33: =SUM(Tabla1[[#This Row],[COSTO OPERATIVO ACIDO]:[COSTO OPERATIVO CATIONICO]]) -> 0 | AT33: 5250 | AU33: =AS33/L33 -> #DIV/0!
A34: =A33 -> 46033 | B34: =DAY(Tabla1[[#This Row],[FECHA]]) -> 11 | C34: 3(TARDE) | D34: 33 | E34: FINAL TURNO 2 | F34: 3350 | G34: 1250 | H34: 630 | I34: 225 | J34: 125 | K34: 16578 | L34: 0 | M34: 0 | N34: =+Tabla1[[#This Row],[CAUDAL DE TRATAMIENTO]]+$M$102 -> 8.4626866 | O34: =F34-F35 -> 0 | P34: =G34-G35 -> 0 | Q34: =H34-H35 -> 0 | R34: =I34-I35 -> 0 | S34: =J34-J35 -> 0 | T34: =(O34*$AD$2) -> 0 | U34: =(P34*$AE$2) -> 0 | V34: =(Q34*$AF$2) -> 0 | W34: =Tabla1[[#This Row],[CONSUMO POL ANIONICO (KG)]] -> 0 | X34: =Tabla1[[#This Row],[CONSUMO POL CATIONICO (KG)]] -> 0 | Y34: =(T34*1000)/L34 -> #DIV/0! | Z34: =(U34*1000)/L34 -> #DIV/0! | AA34: =(V34*1000)/L34 -> #DIV/0! | AB34: =(W34*1000)/L34 -> #DIV/0! | AC34: =(X34*1000)/L34 -> #DIV/0! | AD34: 1.3 | AE34: 1.325 | AF34: 1.25 | AG34: 2500 | AH34: 2500 | AI34: 830 | AJ34: 2900 | AK34: 6295 | AL34: 19050 | AM34: 22050 | AN34: =T34*AI34 -> 0 | AO34: =U34*AJ34 -> 0 | AP34: =V34*AK34 -> 0 | AQ34: =W34*AL34 -> 0 | AR34: =X34*AM34 -> 0 | AS34: =SUM(Tabla1[[#This Row],[COSTO OPERATIVO ACIDO]:[COSTO OPERATIVO CATIONICO]]) -> 0 | AT34: 5250 | AU34: =AS34/L34 -> #DIV/0!
A35: 46034 | B35: =DAY(Tabla1[[#This Row],[FECHA]]) -> 12 | C35: 12 (NOCHE) | D35: 34 | E35: FINAL TURNO 3 | F35: 3350 | G35: 1250 | H35: 630 | I35: 225 | J35: 125 | K35: 16578 | L35: 0 | M35: 0 | N35: =+Tabla1[[#This Row],[CAUDAL DE TRATAMIENTO]]+$M$102 -> 8.4626866 | O35: =F35-F36 -> 0 | P35: =G35-G36 -> 0 | Q35: =H35-H36 -> 0 | R35: =I35-I36 -> 0 | S35: =J35-J36 -> 0 | T35: =(O35*$AD$2) -> 0 | U35: =(P35*$AE$2) -> 0 | V35: =(Q35*$AF$2) -> 0 | W35: =Tabla1[[#This Row],[CONSUMO POL ANIONICO (KG)]] -> 0 | X35: =Tabla1[[#This Row],[CONSUMO POL CATIONICO (KG)]] -> 0 | Y35: =(T35*1000)/L35 -> #DIV/0! | Z35: =(U35*1000)/L35 -> #DIV/0! | AA35: =(V35*1000)/L35 -> #DIV/0! | AB35: =(W35*1000)/L35 -> #DIV/0! | AC35: =(X35*1000)/L35 -> #DIV/0! | AD35: 1.3 | AE35: 1.325 | AF35: 1.25 | AG35: 2500 | AH35: 2500 | AI35: 830 | AJ35: 2900 | AK35: 6295 | AL35: 19050 | AM35: 22050 | AN35: =T35*AI35 -> 0 | AO35: =U35*AJ35 -> 0 | AP35: =V35*AK35 -> 0 | AQ35: =W35*AL35 -> 0 | AR35: =X35*AM35 -> 0 | AS35: =SUM(Tabla1[[#This Row],[COSTO OPERATIVO ACIDO]:[COSTO OPERATIVO CATIONICO]]) -> 0 | AT35: 5250 | AU35: =AS35/L35 -> #DIV/0!
A36: =A35 -> 46034 | B36: =DAY(Tabla1[[#This Row],[FECHA]]) -> 12 | C36: 13 (MAÑANA) | D36: 35 | E36: FINAL TURNO 1 | F36: 3350 | G36: 1250 | H36: 630 | I36: 225 | J36: 125 | K36: 16578 | L36: 0 | M36: 0 | N36: =+Tabla1[[#This Row],[CAUDAL DE TRATAMIENTO]]+$M$102 -> 8.4626866 | O36: =F36-F37 -> 0 | P36: =G36-G37 -> 0 | Q36: =H36-H37 -> 0 | R36: =I36-I37 -> 0 | S36: =J36-J37 -> 0 | T36: =(O36*$AD$2) -> 0 | U36: =(P36*$AE$2) -> 0 | V36: =(Q36*$AF$2) -> 0 | W36: =Tabla1[[#This Row],[CONSUMO POL ANIONICO (KG)]] -> 0 | X36: =Tabla1[[#This Row],[CONSUMO POL CATIONICO (KG)]] -> 0 | Y36: =(T36*1000)/L36 -> #DIV/0! | Z36: =(U36*1000)/L36 -> #DIV/0! | AA36: =(V36*1000)/L36 -> #DIV/0! | AB36: =(W36*1000)/L36 -> #DIV/0! | AC36: =(X36*1000)/L36 -> #DIV/0! | AD36: 1.3 | AE36: 1.325 | AF36: 1.25 | AG36: 2500 | AH36: 2500 | AI36: 830 | AJ36: 2900 | AK36: 6295 | AL36: 19050 | AM36: 22050 | AN36: =T36*AI36 -> 0 | AO36: =U36*AJ36 -> 0 | AP36: =V36*AK36 -> 0 | AQ36: =W36*AL36 -> 0 | AR36: =X36*AM36 -> 0 | AS36: =SUM(Tabla1[[#This Row],[COSTO OPERATIVO ACIDO]:[COSTO OPERATIVO CATIONICO]]) -> 0 | AT36: 5250 | AU36: =AS36/L36 -> #DIV/0!
A37: =A36 -> 46034 | B37: =DAY(Tabla1[[#This Row],[FECHA]]) -> 12 | C37: 3(TARDE) | D37: 36 | E37: FINAL TURNO 2 | F37: 3350 | G37: 1250 | H37: 630 | I37: 225 | J37: 125 | K37: 16578 | L37: 0 | M37: 0 | N37: =+Tabla1[[#This Row],[CAUDAL DE TRATAMIENTO]]+$M$102 -> 8.4626866 | O37: =F37-F38 -> 0 | P37: =G37-G38 -> 0 | Q37: =H37-H38 -> 0 | R37: =I37-I38 -> 0 | S37: =J37-J38 -> 0 | T37: =(O37*$AD$2) -> 0 | U37: =(P37*$AE$2) -> 0 | V37: =(Q37*$AF$2) -> 0 | W37: =Tabla1[[#This Row],[CONSUMO POL ANIONICO (KG)]] -> 0 | X37: =Tabla1[[#This Row],[CONSUMO POL CATIONICO (KG)]] -> 0 | Y37: =(T37*1000)/L37 -> #DIV/0! | Z37: =(U37*1000)/L37 -> #DIV/0! | AA37: =(V37*1000)/L37 -> #DIV/0! | AB37: =(W37*1000)/L37 -> #DIV/0! | AC37: =(X37*1000)/L37 -> #DIV/0! | AD37: 1.3 | AE37: 1.325 | AF37: 1.25 | AG37: 2500 | AH37: 2500 | AI37: 830 | AJ37: 2900 | AK37: 6295 | AL37: 19050 | AM37: 22050 | AN37: =T37*AI37 -> 0 | AO37: =U37*AJ37 -> 0 | AP37: =V37*AK37 -> 0 | AQ37: =W37*AL37 -> 0 | AR37: =X37*AM37 -> 0 | AS37: =SUM(Tabla1[[#This Row],[COSTO OPERATIVO ACIDO]:[COSTO OPERATIVO CATIONICO]]) -> 0 | AT37: 5250 | AU37: =AS37/L37 -> #DIV/0!
A38: 46035 | B38: =DAY(Tabla1[[#This Row],[FECHA]]) -> 13 | C38: 13 (NOCHE) | D38: 37 | E38: FINAL TURNO 3 | F38: 3350 | G38: 1250 | H38: 630 | I38: 225 | J38: 125 | K38: 16578 | L38: 241.38806 | M38: 72 | N38: =+Tabla1[[#This Row],[CAUDAL DE TRATAMIENTO]]+$M$102 -> 80.462687 | O38: =F38-F39 -> 180 | P38: =G38-G39+3000-150 -> 160 | Q38: =H38-H39 -> 80 | R38: =I38-I39 -> 0 | S38: =J38-J39 -> 0 | T38: =(O38*$AD$2) -> 234 | U38: =(P38*$AE$2) -> 212 | V38: =(Q38*$AF$2) -> 100 | W38: =Tabla1[[#This Row],[CONSUMO POL ANIONICO (KG)]] -> 0 | X38: =Tabla1[[#This Row],[CONSUMO POL CATIONICO (KG)]] -> 0 | Y38: =(T38*1000)/L38 -> 969.39343 | Z38: =(U38*1000)/L38 -> 878.25388 | AA38: =(V38*1000)/L38 -> 414.2707 | AB38: =(W38*1000)/L38 -> 0 | AC38: =(X38*1000)/L38 -> 0 | AD38: 1.3 | AE38: 1.325 | AF38: 1.25 | AG38: 2500 | AH38: 2500 | AI38: 830 | AJ38: 2900 | AK38: 6295 | AL38: 19050 | AM38: 22050 | AN38: =T38*AI38 -> 194220 | AO38: =U38*AJ38 -> 614800 | AP38: =V38*AK38 -> 629500 | AQ38: =W38*AL38 -> 0 | AR38: =X38*AM38 -> 0 | AS38: =SUM(Tabla1[[#This Row],[COSTO OPERATIVO ACIDO]:[COSTO OPERATIVO CATIONICO]]) -> 1438520 | AT38: 5250 | AU38: =AS38/L38 -> 5959.3668
A39: =A38 -> 46035 | B39: =DAY(Tabla1[[#This Row],[FECHA]]) -> 13 | C39: 14 (MAÑANA) | D39: 38 | E39: FINAL TURNO 1 | F39: 3170 | G39: 3940 | H39: 550 | I39: 225 | J39: 125 | K39: 16581 | L39: 530.77612 | M39: 80 | N39: =+Tabla1[[#This Row],[CAUDAL DE TRATAMIENTO]]+$M$102 -> 88.462687 | O39: =F39-F40 -> 100 | P39: =G39-G40 -> 170 | Q39: =H39-H40 -> 50 | R39: =I39-I40 -> 0 | S39: =J39-J40 -> 5 | T39: =(O39*$AD$2) -> 130 | U39: =(P39*$AE$2) -> 225.25 | V39: =(Q39*$AF$2) -> 62.5 | W39: =Tabla1[[#This Row],[CONSUMO POL ANIONICO (KG)]] -> 0 | X39: =Tabla1[[#This Row],[CONSUMO POL CATIONICO (KG)]] -> 5 | Y39: =(T39*1000)/L39 -> 244.92436 | Z39: =(U39*1000)/L39 -> 424.37855 | AA39: =(V39*1000)/L39 -> 117.75209 | AB39: =(W39*1000)/L39 -> 0 | AC39: =(X39*1000)/L39 -> 9.4201676 | AD39: 1.3 | AE39: 1.325 | AF39: 1.25 | AG39: 2500 | AH39: 2500 | AI39: 830 | AJ39: 2900 | AK39: 6295 | AL39: 19050 | AM39: 22050 | AN39: =T39*AI39 -> 107900 | AO39: =U39*AJ39 -> 653225 | AP39: =V39*AK39 -> 393437.5 | AQ39: =W39*AL39 -> 0 | AR39: =X39*AM39 -> 110250 | AS39: =SUM(Tabla1[[#This Row],[COSTO OPERATIVO ACIDO]:[COSTO OPERATIVO CATIONICO]]) -> 1264812.5 | AT39: 5250 | AU39: =AS39/L39 -> 2382.9491
A40: =A39 -> 46035 | B40: =DAY(Tabla1[[#This Row],[FECHA]]) -> 13 | C40: 3(TARDE) | D40: 39 | E40: FINAL TURNO 2 | F40: 3070 | G40: 3770 | H40: 500 | I40: 225 | J40: 120 | K40: 16587 | L40: 707.70149 | M40: 80 | N40: =+Tabla1[[#This Row],[CAUDAL DE TRATAMIENTO]]+$M$102 -> 88.462687 | O40: =F40-F41-100 -> 190 | P40: =G40-G41 -> 320 | Q40: =H40-H41+610 -> 110 | R40: =I40-I41 -> 5 | S40: =J40-J41 -> 5 | T40: =(O40*$AD$2) -> 247 | U40: =(P40*$AE$2) -> 424 | V40: =(Q40*$AF$2) -> 137.5 | W40: =Tabla1[[#This Row],[CONSUMO POL ANIONICO (KG)]] -> 5 | X40: =Tabla1[[#This Row],[CONSUMO POL CATIONICO (KG)]] -> 5 | Y40: =(T40*1000)/L40 -> 349.01721 | Z40: =(U40*1000)/L40 -> 599.12266 | AA40: =(V40*1000)/L40 -> 194.29096 | AB40: =(W40*1000)/L40 -> 7.0651257 | AC40: =(X40*1000)/L40 -> 7.0651257 | AD40: 1.3 | AE40: 1.325 | AF40: 1.25 | AG40: 2500 | AH40: 2500 | AI40: 830 | AJ40: 2900 | AK40: 6295 | AL40: 19050 | AM40: 22050 | AN40: =T40*AI40 -> 205010 | AO40: =U40*AJ40 -> 1229600 | AP40: =V40*AK40 -> 865562.5 | AQ40: =W40*AL40 -> 95250 | AR40: =X40*AM40 -> 110250 | AS40: =SUM(Tabla1[[#This Row],[COSTO OPERATIVO ACIDO]:[COSTO OPERATIVO CATIONICO]]) -> 2505672.5 | AT40: 5250 | AU40: =AS40/L40 -> 3540.5782
...

Sheet DB QUIMICA
A1: CONSUMO DE QUIMICO | M1: TABLA GRAFICA 1 Y 2 . CONSUMO QUIMICO DETALLADO | U1: TABLA GRAFICA 2. COSTO CONSUMO QUIMICO VS $M3 | AA1: TABLA GRAFICA 3. RO COSTO CONSUMO QUIMICO VS $M3 | AG1: TABLA GRAFICA 4. RO PPM CONSUMO QUIMICO
A2: GEM
B3: CONSUMO QUIMICO PPM
L4: FECHA | M4: CAUDAL TOTAL TRATADO GEM | N4: COF 235 - PPM COAGULANTE | O4: COF 255 - PPM DECOLORANTE | P4: COF 280 - PPM ACIDO | Q4: COF 440 - PPM POL ANIONICO | R4: COF 494 - PPM POL CATIONICO | U4: DIA | V4: CAUDAL TOTAL TRATADO GEM | W4: INDICADOR $m3 | X4: 2024-2 $m3 GEM | Y4: 2024 $m3 GEM | AA4: DÍA | AB4: VOLUMEN ENVIADO A RO (m3) | AC4: LIMITE INDICADOR M3 | AD4: INDICADOR $m3 RO | AG4: DÍA | AH4: VOLUMEN ENVIADO A RO (m3) | AI4: PPM HCL | AJ4: PPM KURIVERTER | AK4: PPM VITEC | AL4: PPM BISULFITO
L5: 46023 | M5: 0 | N5: 0 | O5: 0 | P5: 0 | Q5: 0 | R5: 0 | U5: 1 | V5: 0 | W5: 0 | X5: 5250 | Y5: 4909 | AA5: 1 | AB5: 0 | AC5: 1000 | AD5: 0 | AG5: 1 | AH5: 0 | AI5: 0 | AJ5: 0 | AK5: 0 | AL5: 0
L6: 46024 | M6: 815.16418 | N6: 325.08789 | O6: 184.01201 | P6: 255.16332 | Q6: 12.267467 | R6: 12.267467 | U6: 2 | V6: 815.16418 | W6: 2817.0889 | X6: 5250 | Y6: 4909 | AA6: 2 | AB6: 257.449 | AC6: 1000 | AD6: 0 | AG6: 2 | AH6: 257.449 | AI6: 0 | AJ6: 0 | AK6: 0 | AL6: 0
L7: 46025 | M7: 268.38806 | N7: 789.90101 | O7: 232.87176 | P7: 387.49861 | Q7: 0 | R7: 0 | U7: 3 | V7: 268.38806 | W7: 4078.2645 | X7: 5250 | Y7: 4909 | AA7: 3 | AB7: 0 | AC7: 1000 | AD7: 0 | AG7: 3 | AH7: 0 | AI7: 0 | AJ7: 0 | AK7: 0 | AL7: 0
L8: 46026 | M8: 0 | N8: 0 | O8: 0 | P8: 0 | Q8: 0 | R8: 0 | U8: 4 | V8: 0 | W8: 0 | X8: 5250 | Y8: 4909 | AA8: 4 | AB8: 0 | AC8: 1000 | AD8: 0 | AG8: 4 | AH8: 0 | AI8: 0 | AJ8: 0 | AK8: 0 | AL8: 0
L9: 46027 | M9: 868.62687 | N9: 289.82525 | O9: 143.90529 | P9: 164.62765 | Q9: 0 | R9: 11.512423 | U9: 5 | V9: 868.62687 | W9: 2136.8669 | X9: 5250 | Y9: 4909 | AA9: 5 | AB9: 278.223 | AC9: 1000 | AD9: 0 | AG9: 5 | AH9: 278.223 | AI9: 0 | AJ9: 0 | AK9: 0 | AL9: 0
L10: 46028 | M10: 1082.5522 | N10: 611.97971 | O10: 230.93574 | P10: 504.36365 | Q10: 4.6187148 | R10: 9.2374295 | U10: 6 | V10: 1082.5522 | W10: 3938.7753 | X10: 5250 | Y10: 4909 | AA10: 6 | AB10: 579.819 | AC10: 1000 | AD10: 8.9047027 | AG10: 6 | AH10: 579.819 | AI10: 0 | AJ10: 38.72957 | AK10: 0 | AL10: 0
L11: 46029 | M11: 875.62687 | N11: 1059.2411 | O11: 199.85682 | P11: 386.00917 | Q11: 5.7101948 | R11: 17.130584 | U11: 7 | V11: 875.62687 | W11: 5136.7942 | X11: 5250 | Y11: 4909 | AA11: 7 | AB11: 293.519 | AC11: 1000 | AD11: 539.26448 | AG11: 7 | AH11: 293.519 | AI11: 0 | AJ11: 306.02639 | AK11: 294.07224 | AL11: 0
L12: 46030 | M12: 958.01493 | N12: 760.68752 | O12: 208.76501 | P12: 447.80096 | Q12: 5.2191254 | R12: 15.657376 | U12: 8 | V12: 958.01493 | W12: 4336.5139 | X12: 5250 | Y12: 4909 | AA12: 8 | AB12: 560.618 | AC12: 1000 | AD12: 128.96595 | AG12: 8 | AH12: 560.618 | AI12: 0 | AJ12: 40.056046 | AK12: 75.105086 | AL12: 0
L13: 46031 | M13: 974.55224 | N13: 734.18332 | O13: 243.70166 | P13: 280.12865 | Q13: 5.1305613 | R13: 15.391684 | U13: 9 | V13: 974.55224 | W13: 4332.8642 | X13: 5250 | Y13: 4909 | AA13: 9 | AB13: 346.269 | AC13: 1000 | AD13: 357.88154 | AG13: 9 | AH13: 346.269 | AI13: 0 | AJ13: 1134.9051 | AK13: 60.798488 | AL13: 0
L14: 46032 | M14: 594.23881 | N14: 356.75893 | O14: 168.28251 | P14: 87.506907 | Q14: 8.4141257 | R14: 8.4141257 | U14: 10 | V14: 594.23881 | W14: 2512.3906 | X14: 5250 | Y14: 4909 | AA14: 10 | AB14: 256.667 | AC14: 1000 | AD14: 261.5744 | AG14: 10 | AH14: 256.667 | AI14: 0 | AJ14: 0 | AK14: 164.04627 | AL14: 0
L15: 46033 | M15: 0 | N15: 0 | O15: 0 | P15: 0 | Q15: 0 | R15: 0 | U15: 11 | V15: 0 | W15: 0 | X15: 5250 | Y15: 4909 | AA15: 11 | AB15: 0 | AC15: 1000 | AD15: 0 | AG15: 11 | AH15: 0 | AI15: 0 | AJ15: 0 | AK15: 0 | AL15: 0
L16: 46034 | M16: 0 | N16: 0 | O16: 0 | P16: 0 | Q16: 0 | R16: 0 | U16: 12 | V16: 0 | W16: 0 | X16: 5250 | Y16: 4909 | AA16: 12 | AB16: 0 | AC16: 1000 | AD16: 0 | AG16: 12 | AH16: 0 | AI16: 0 | AJ16: 0 | AK16: 0 | AL16: 0
... L27: 46045 | M27: 973.08955 | N27: 953.14968 | O27: 141.30251 | P27: 26.719021 | Q27: 10.276546 | R27: 15.41482 | U27: 23 | V27: 973.08955 | W27: 4211.4752 | X27: 5250 | Y27: 4909 | AA27: 23 | AB27: 576.231 | AC27: 1000 | AD27: 0 | AG27: 23 | AH27: 576.231 | AI27: 0 | AJ27: 0 | AK27: 0 | AL27: 0
B28: COSTO TTO - CAUDAL TRATADP GEM Vs $M3 | L28: 46046 | M28: 796.16418 | N28: 249.63444 | O28: 62.801117 | P28: 48.984871 | Q28: 6.2801117 | R28: 6.2801117 | U28: 24 | V28: 796.16418 | W28: 1418.0429 | X28: 5250 | Y28: 4909 | AA28: 24 | AB28: 0 | AC28: 1000 | AD28: 0 | AG28: 24 | AH28: 0 | AI28: 0 | AJ28: 0 | AK28: 0 | AL28: 0
L29: 46047 | M29: 0 | N29: 0 | O29: 0 | P29: 0 | Q29: 0 | R29: 0 | U29: 25 | V29: 0 | W29: 0 | X29: 5250 | Y29: 4909 | AA29: 25 | AB29: 0 | AC29: 1000 | AD29: 0 | AG29: 25 | AH29: 0 | AI29: 0 | AJ29: 0 | AK29: 0 | AL29: 0
L30: 46048 | M30: 884.62687 | N30: 584.14459 | O30: 226.08402 | P30: 205.73646 | Q30: 5.6521006 | R30: 11.304201 | U30: 26 | V30: 884.62687 | W30: 3644.9097 | X30: 5250 | Y30: 4909 | AA30: 26 | AB30: 442.12 | AC30: 1000 | AD30: 0 | AG30: 26 | AH30: 442.12 | AI30: 0 | AJ30: 0 | AK30: 0 | AL30: 0
L31: 46049 | M31: 1061.5522 | N31: 449.34199 | O31: 141.30251 | P31: 146.95461 | Q31: 9.4201676 | R31: 14.130251 | U31: 27 | V31: 1061.5522 | W31: 2805.5897 | X31: 5250 | Y31: 4909 | AA31: 27 | AB31: 640.018 | AC31: 1000 | AD31: 0 | AG31: 27 | AH31: 640.018 | AI31: 0 | AJ31: 0 | AK31: 0 | AL31: 0
L32: 46050 | M32: 1238.4776 | N32: 160.47928 | O32: 80.744294 | P32: 136.45786 | Q32: 4.0372147 | R32: 12.111644 | U32: 28 | V32: 1238.4776 | W32: 1430.906 | X32: 5250 | Y32: 4909 | AA32: 28 | AB32: 1038.94 | AC32: 1000 | AD32: 0 | AG32: 28 | AH32: 1038.94 | AI32: 0 | AJ32: 0 | AK32: 0 | AL32: 0
L33: 46051 | M33: 1326.9403 | N33: 639.06417 | O33: 113.04201 | P33: 274.31528 | Q33: 3.768067 | R33: 11.304201 | U33: 29 | V33: 1326.9403 | W33: 3113.6065 | X33: 5250 | Y33: 4909 | AA33: 29 | AB33: 1064.713 | AC33: 1000 | AD33: 0 | AG33: 29 | AH33: 1064.713 | AI33: 0 | AJ33: 0 | AK33: 0 | AL33: 0
L34: 46052 | M34: 1326.9403 | N34: 509.25426 | O34: 160.14285 | P34: 284.11225 | Q34: 7.5361341 | R34: 11.304201 | U34: 30 | V34: 1326.9403 | W34: 3113.5707 | X34: 5250 | Y34: 4909 | AA34: 30 | AB34: 1257.157 | AC34: 1000 | AD34: 0 | AG34: 30 | AH34: 1257.157 | AI34: 0 | AJ34: 0 | AK34: 0 | AL34: 0
L35: 46053 | M35: 973.08955 | N35: 571.88981 | O35: 256.91366 | P35: 360.70678 | Q35: 5.1382732 | R35: 5.1382732 | U35: 31 | V35: 973.08955 | W35: 3786.3216 | X35: 5250 | Y35: 4909 | AA35: 31 | AB35: 665.323 | AC35: 1000 | AD35: 0 | AG35: 31 | AH35: 665.323 | AI35: 0 | AJ35: 0 | AK35: 0 | AL35: 0
L36: (en blanco) | M36: -1489446.3 | N36: -5.7645585 | O36: -1.2672495 | P36: -3.8054411 | Q36: -0.11077943 | R36: -0.040283427 | U36: Total general | V36: 29325 | W36: 3042.8393 | X36: 5250 | Y36: 4909 | AA36: Total general | AB36: 14633.579 | AC36: 1000 | AD36: 158.26983 | AG36: Total general | AH36: 14633.579 | AI36: 0 | AJ36: 71.67941 | AK36: 88.923097 | AL36: 0
L37: Total general | M37: -1460121.3 | N37: -16.43408 | O37: -4.5201725 | P37: -8.5116219 | Q37: -0.21231113 | R37: -0.24313049
B51: CONSOLIDADO COSTO TTO - CAUDAL TRATADP GEM Vs $M3 | F51: CONSOLIDADO COSTO TTO - CAUDAL TRATADP RO Vs $M3
B53: ACUMULADO CAUDAL TRATADO GEM | D53: =Tabla1[[#Totals],[COSTO QUIMICA ]] -> 89231262 | F53: ACUMULADO CAUDAL TRATADO RO | H53: 2355067.6
B54: TOTAL CAUDAL TRATADO GEM | C54: $m3 | F54: TOTAL CAUDAL TRATADO RO | G54: $m3 | H54: 2515885.2
B55: =GETPIVOTDATA(" CAUDAL TOTAL TRATADO GEM ",$U$4) -> 29325 | C55: =+D53/B55 -> 3042.8393 | F55: =+GETPIVOTDATA(" VOLUMEN ENVIADO A RO (m3)",$AA$4) -> 14633.579 | G55: =H53/F55 -> 160.93586 | H55: =G55*F55 -> 2355067.6
B56: 29051 | C56: =+D53/B56 -> 3071.5384
A58: OSMOSIS INVERSA
B81: CONSUMO QUIMICO PPM

Sheet CONSUMO QUÍMICA-CAUDALES GEM  
A1: CONSOLIDADO CONSUMO DIARIO QUÍMICA (Litros)
B2: DIAS
A3: PRODUCTOS QUÍMICOS | B3: 1 | C3: 2 | D3: 3 | E3: 4 | F3: 5 | G3: 6 | H3: 7 | I3: 8 | J3: 9 | K3: 10 | L3: 11 | M3: 12 | N3: 13 | O3: 14 | P3: 15 | Q3: 16 | R3: 17 | S3: 18 | T3: 19 | U3: 20 | V3: 21 | W3: 22 | X3: 23 | Y3: 24 | Z3: 25 | AA3: 26 | AB3: 27 | AC3: 28 | AD3: 29 | AE3: 30 | AF3: 31 | AG3: (en blanco) | AH3: Total general
A4: COF 280 ACIDO (L) | B4: 0 | C4: 160 | D4: 80 | E4: 0 | F4: 110 | G4: 420 | H4: 260 | I4: 330 | J4: 210 | K4: 40 | L4: 0 | M4: 0 | N4: 470 | O4: 280 | P4: 200 | Q4: 210 | R4: 190 | S4: 0 | T4: 300 | U4: 300 | V4: 200 | W4: 160 | X4: 20 | Y4: 30 | Z4: 0 | AA4: 140 | AB4: 120 | AC4: 130 | AD4: 280 | AE4: 290 | AF4: 270 | AG4: 4360 | AH4: 9560
A5: COF 235 COAGULANTE (L) | B5: 0 | C5: 200 | D5: 160 | E5: 0 | F5: 190 | G5: 500 | H5: 700 | I5: 550 | J5: 540 | K5: 160 | L5: 0 | M5: 0 | N5: 650 | O5: 680 | P5: 610 | Q5: 600 | R5: 160 | S5: 0 | T5: 610 | U5: 700 | V5: 500 | W5: 800 | X5: 700 | Y5: 150 | Z5: 0 | AA5: 390 | AB5: 360 | AC5: 150 | AD5: 640 | AE5: 510 | AF5: 420 | AG5: 6480 | AH5: 18110
A6: COF 255 DECOLORANTE (L) | B6: 0 | C6: 120 | D6: 50 | E6: 0 | F6: 100 | G6: 200 | H6: 140 | I6: 160 | J6: 190 | K6: 80 | L6: 0 | M6: 0 | N6: 240 | O6: 350 | P6: 150 | Q6: 190 | R6: 60 | S6: 0 | T6: 250 | U6: 40 | V6: 210 | W6: 240 | X6: 110 | Y6: 40 | Z6: 0 | AA6: 160 | AB6: 120 | AC6: 80 | AD6: 120 | AE6: 170 | AF6: 200 | AG6: 1510 | AH6: 5280
A7: COF 440 POL ANIONICO (KG) | B7: 0 | C7: 10 | D7: 0 | E7: 0 | F7: 0 | G7: 5 | H7: 5 | I7: 5 | J7: 5 | K7: 5 | L7: 0 | M7: 0 | N7: 5 | O7: 5 | P7: 5 | Q7: 5 | R7: 5 | S7: 0 | T7: 5 | U7: 10 | V7: 10 | W7: 5 | X7: 10 | Y7: 5 | Z7: 0 | AA7: 5 | AB7: 10 | AC7: 5 | AD7: 5 | AE7: 10 | AF7: 5 | AG7: 165 | AH7: 310
A8: COF 494 POL CATIONICO (KG) | B8: 0 | C8: 10 | D8: 0 | E8: 0 | F8: 10 | G8: 10 | H8: 15 | I8: 15 | J8: 15 | K8: 5 | L8: 0 | M8: 0 | N8: 10 | O8: 15 | P8: 15 | Q8: 15 | R8: 10 | S8: 0 | T8: 15 | U8: 10 | V8: 15 | W8: 15 | X8: 15 | Y8: 5 | Z8: 0 | AA8: 10 | AB8: 15 | AC8: 15 | AD8: 15 | AE8: 15 | AF8: 5 | AG8: 60 | AH8: 355
A10: CONSOLIDADO CONSUMO DIARIO QUÍMICA (Kg)
B11: DIAS
A12: PRODUCTOS QUÍMICOS | B12: 1 | C12: 2 | D12: 3 | E12: 4 | F12: 5 | G12: 6 | H12: 7 | I12: 8 | J12: 9 | K12: 10 | L12: 11 | M12: 12 | N12: 13 | O12: 14 | P12: 15 | Q12: 16 | R12: 17 | S12: 18 | T12: 19 | U12: 20 | V12: 21 | W12: 22 | X12: 23 | Y12: 24 | Z12: 25 | AA12: 26 | AB12: 27 | AC12: 28 | AD12: 29 | AE12: 30 | AF12: 31 | AG12: (en blanco) | AH12: Total general
A13: COF 280 - KG ACIDO | B13: 0 | C13: 208 | D13: 104 | E13: 0 | F13: 143 | G13: 546 | H13: 338 | I13: 429 | J13: 273 | K13: 52 | L13: 0 | M13: 0 | N13: 611 | O13: 364 | P13: 260 | Q13: 273 | R13: 247 | S13: 0 | T13: 390 | U13: 390 | V13: 260 | W13: 208 | X13: 26 | Y13: 39 | Z13: 0 | AA13: 182 | AB13: 156 | AC13: 169 | AD13: 364 | AE13: 377 | AF13: 351 | AG13: 5668 | AH13: 12428
A14: COF 235 - KG COAGULANTE | B14: 0 | C14: 265 | D14: 212 | E14: 0 | F14: 251.75 | G14: 662.5 | H14: 927.5 | I14: 728.75 | J14: 715.5 | K14: 212 | L14: 0 | M14: 0 | N14: 861.25 | O14: 901 | P14: 808.25 | Q14: 795 | R14: 212 | S14: 0 | T14: 808.25 | U14: 927.5 | V14: 662.5 | W14: 1060 | X14: 927.5 | Y14: 198.75 | Z14: 0 | AA14: 516.75 | AB14: 477 | AC14: 198.75 | AD14: 848 | AE14: 675.75 | AF14: 556.5 | AG14: 8586 | AH14: 23995.75
A15: COF 255 - KG DECOLORANTE | B15: 0 | C15: 150 | D15: 62.5 | E15: 0 | F15: 125 | G15: 250 | H15: 175 | I15: 200 | J15: 237.5 | K15: 100 | L15: 0 | M15: 0 | N15: 300 | O15: 437.5 | P15: 187.5 | Q15: 237.5 | R15: 75 | S15: 0 | T15: 312.5 | U15: 50 | V15: 262.5 | W15: 300 | X15: 137.5 | Y15: 50 | Z15: 0 | AA15: 200 | AB15: 150 | AC15: 100 | AD15: 150 | AE15: 212.5 | AF15: 250 | AG15: 1887.5 | AH15: 6600
A16: COF 440 - KG POL ANIONICO | B16: 0 | C16: 10 | D16: 0 | E16: 0 | F16: 0 | G16: 5 | H16: 5 | I16: 5 | J16: 5 | K16: 5 | L16: 0 | M16: 0 | N16: 5 | O16: 5 | P16: 5 | Q16: 5 | R16: 5 | S16: 0 | T16: 5 | U16: 10 | V16: 10 | W16: 5 | X16: 10 | Y16: 5 | Z16: 0 | AA16: 5 | AB16: 10 | AC16: 5 | AD16: 5 | AE16: 10 | AF16: 5 | AG16: 165 | AH16: 310
A17: COF 494 - KG POL CATIONICO | B17: 0 | C17: 10 | D17: 0 | E17: 0 | F17: 10 | G17: 10 | H17: 15 | I17: 15 | J17: 15 | K17: 5 | L17: 0 | M17: 0 | N17: 10 | O17: 15 | P17: 15 | Q17: 15 | R17: 10 | S17: 0 | T17: 15 | U17: 10 | V17: 15 | W17: 15 | X17: 15 | Y17: 5 | Z17: 0 | AA17: 10 | AB17: 15 | AC17: 15 | AD17: 15 | AE17: 15 | AF17: 5 | AG17: 60 | AH17: 355
A19: CONSOLIDADO DOSIFICACIÓN QUÍMICA PPM (mg/L)
B20: DIAS
A21: PRODUCTOS QUÍMICOS | B21: 1 | C21: 2 | D21: 3 | E21: 4 | F21: 5 | G21: 6 | H21: 7 | I21: 8 | J21: 9 | K21: 10 | L21: 11 | M21: 12 | N21: 13 | O21: 14 | P21: 15 | Q21: 16 | R21: 17 | S21: 18 | T21: 19 | U21: 20 | V21: 21 | W21: 22 | X21: 23 | Y21: 24 | Z21: 25 | AA21: 26 | AB21: 27 | AC21: 28 | AD21: 29 | AE21: 30 | AF21: 31 | AG21: (en blanco)
A22: COF 280 - PPM ACIDO | B22: #DIV/0! | C22: 255.16332 | D22: 387.49861 | E22: #DIV/0! | F22: 164.62765 | G22: 504.36365 | H22: 386.00917 | I22: 447.80096 | J22: 280.12865 | K22: 87.506907 | L22: #DIV/0! | M22: #DIV/0! | N22: 412.87531 | O22: 205.73646 | P22: 146.95461 | Q22: 190.72197 | R22: 202.04869 | S22: #DIV/0! | T22: 209.93516 | U22: 244.92436 | V22: 163.2829 | W22: 130.62632 | X22: 26.719021 | Y22: 48.984871 | Z22: #DIV/0! | AA22: 205.73646 | AB22: 146.95461 | AC22: 136.45786 | AD22: 274.31528 | AE22: 284.11225 | AF22: 360.70678 | AG22: -3.8054411
A23: COF 235 - PPM COAGULANTE | B23: #DIV/0! | C23: 325.08789 | D23: 789.90101 | E23: #DIV/0! | F23: 289.82525 | G23: 611.97971 | H23: 1059.2411 | I23: 760.68752 | J23: 734.18332 | K23: 356.75893 | L23: #DIV/0! | M23: #DIV/0! | N23: 581.9785 | O23: 509.25426 | P23: 456.83103 | Q23: 555.39915 | R23: 173.41831 | S23: #DIV/0! | T23: 435.07717 | U23: 582.48036 | V23: 416.0574 | W23: 665.69184 | X23: 953.14968 | Y23: 249.63444 | Z23: #DIV/0! | AA23: 584.14459 | AB23: 449.34199 | AC23: 160.47928 | AD23: 639.06417 | AE23: 509.25426 | AF23: 571.88981 | AG23: -5.7645585
