Workbook
Name ANALISTA: #REF!
Name BALANCEO: #REF!
Name ESTADO: #REF!
Name PLANTAS: #REF!
Name PRENDA: #REF!
Name PROCESO: #REF!
Name SegmentaciónDeDatos_DIA: #N/A
Name SegmentaciónDeDatos_FECHA1: #N/A
Name SegmentaciónDeDatos_FECHA2: #N/A
Name TIPO: #REF!

Sheet PROYECCIÓN INSUMOS QUÍMICO
B2: COSTO PLANTA DE TRATAMIENTO DE AGUA RESIDUAL
B3: Clasificación | C3: Detalle | D3: Unidad | E3: Dosificación | F3: ABRIL 2026 | G3: ABRIL REAL | H3: Abril 2026 | I3: Mayo 2026 | J3: Junio 2026 | K3: Julio 2026 | L3: Agosto 2026 | M3: Septiembre 2026 | N3: Octubre 2026 | O3: Noviembre 2026 | P3: Diciembre 2026 | Q3: Total general | R3: kg/m3 PROYECCION | S3: Kg/m3 REAL | T3: % CONSUMO Kg/m3 | U3: $/Kg | V3: $ Total PROYECCIÓN | W3: $ Total REAL | X3: % CONSUMO $Total | Y3: $/M3 PROYECCIÓN | Z3: $/M3 REAL | AA3: DIFERENCIAL $/M3
E4: Kg/m3
F5: 28996.039 | G5: ='DB QUIMICA'!Z8 -> 32414 | H5: ='[1]PLAN MAESTRO BOGOTA RECIRCU'!L5 -> 28996.039 | I5: ='[1]PLAN MAESTRO BOGOTA RECIRCU'!N5 -> 31421.6 | J5: ='[1]PLAN MAESTRO BOGOTA RECIRCU'!P5 -> 34249.301 | K5: ='[1]PLAN MAESTRO BOGOTA RECIRCU'!R5 -> 40509.091 | L5: ='[1]PLAN MAESTRO BOGOTA RECIRCU'!T5 -> 40285.492 | M5: ='[1]PLAN MAESTRO BOGOTA RECIRCU'!V5 -> 43482.437 | N5: ='[1]PLAN MAESTRO BOGOTA RECIRCU'!X5 -> 40858.186 | O5: ='[1]PLAN MAESTRO BOGOTA RECIRCU'!Z5 -> 26685.676 | P5: ='[1]PLAN MAESTRO BOGOTA RECIRCU'!AB5 -> 13422.465 | Q5: =SUM(F5:P5) -> 361320.33
B6: QUIMICOS (GEM + RO) | C6: ACIDO CLORHIDRICO 31,5% | D6: kg | E6: 0.013583636 | F6: 393.87165 | G6: =19*2 -> 38 | H6: =$E$6*H5 -> 393.87165 | I6: =$E$6*I5 -> 426.81959 | J6: =$E$6*J5 -> 465.23004 | K6: =$E$6*K5 -> 550.26077 | L6: =$E$6*L5 -> 547.22347 | M6: =$E$6*M5 -> 590.64961 | N6: =$E$6*N5 -> 555.00275 | O6: =$E$6*O5 -> 362.48852 | P6: =$E$6*P5 -> 182.32589 | Q6: =+SUM(F6:P6) -> 4505.7439 | R6: =F6/$F$5 -> 0.013583636 | S6: =G6/$G$5 -> 0.0011723329 | T6: =1-S6/R6 -> 0.91369521 | U6: 1650 | V6: =F6*U6 -> 649888.22 | W6: =G6*U6 -> 62700 | X6: =1-W6/V6 -> 0.90352187 | Y6: =V6/$F$5 -> 22.413 | Z6: =W6/$G$5 -> 1.9343494 | AA6: =Y6-Z6 -> 20.478651 | AC6: Por cada CIP son 19 Kg de acido aprox
C7: SODIO BISULFITO | D7: kg | E7: 0.0011916667 | F7: 34.553613 | G7: 0 | H7: =$E$7*H5 -> 34.553613 | I7: =$E$7*I5 -> 37.444074 | J7: =$E$7*J5 -> 40.81375 | K7: =$E$7*K5 -> 48.273334 | L7: =$E$7*L5 -> 48.006878 | M7: =$E$7*M5 -> 51.816571 | N7: =$E$7*N5 -> 48.689339 | O7: =$E$7*O5 -> 31.80043 | P7: =$E$7*P5 -> 15.995105 | Q7: =+SUM(F7:P7) -> 391.94671 | R7: =F7/$F$5 -> 0.0011916667 | S7: =G7/$G$5 -> 0 | T7: =1-S7/R7 -> 1 | U7: 4200 | V7: =F7*U7 -> 145125.18 | W7: =G7*U7 -> 0 | X7: =1-W7/V7 -> 1 | Y7: =V7/$F$5 -> 5.005 | Z7: =W7/$G$5 -> 0 | AA7: =Y7-Z7 -> 5.005
C8: NITRATO DE PLATA | D8: kg | E8: 1.8118958e-05 | F8: 0.525378 | G8: =120*1/1000 -> 0.12 | H8: =$E$8*H5 -> 0.525378 | I8: =$E$8*I5 -> 0.56932665 | J8: =$E$8*J5 -> 0.62056163 | K8: =$E$8*K5 -> 0.73398252 | L8: =$E$8*L5 -> 0.72993113 | M8: =$E$8*M5 -> 0.78785643 | N8: =$E$8*N5 -> 0.74030775 | O8: =$E$8*O5 -> 0.48351663 | P8: =$E$8*P5 -> 0.24320108 | Q8: =+SUM(F8:P8) -> 6.0794398 | R8: =F8/$F$5 -> 1.8118958e-05 | S8: =G8/$G$5 -> 3.702104e-06 | T8: =1-S8/R8 -> 0.79567787 | U8: 180000 | V8: =F8*U8 -> 94568.041 | W8: =G8*U8 -> 21600 | X8: =1-W8/V8 -> 0.77159303 | Y8: =V8/$F$5 -> 3.2614124 | Z8: =W8/$G$5 -> 0.66637873 | AA8: =Y8-Z8 -> 2.5950337 | AC8: 40 mL dia * 3 dias a la semana
C9: ACIDIFICANTE | D9: kg | E9: 0.30804068 | F9: 8931.9594 | G9: =GRAFICAS!S32 -> 9321 | H9: =$E$9*H5 -> 8931.9594 | I9: =$E$9*I5 -> 9679.131 | J9: =$E$9*J5 -> 10550.178 | K9: =$E$9*K5 -> 12478.448 | L9: =$E$9*L5 -> 12409.57 | M9: =$E$9*M5 -> 13394.359 | N9: =$E$9*N5 -> 12585.983 | O9: =$E$9*O5 -> 8220.2736 | P9: =$E$9*P5 -> 4134.6653 | Q9: =+SUM(F9:P9) -> 110637.53 | R9: =F9/$F$5 -> 0.30804068 | S9: =G9/$G$5 -> 0.28756093 | T9: =1-S9/R9 -> 0.066483898 | U9: 830 | V9: =F9*U9 -> 7413526.3 | W9: =G9*U9 -> 7736430 | X9: =1-W9/V9 -> -0.043556016 | Y9: =V9/$F$5 -> 255.67376 | Z9: =W9/$G$5 -> 238.67557 | AA9: =Y9-Z9 -> 16.998188
C10: QUIMICO FLOCULANTE PARA TRATAMIENTO DE AGUA (Catiónico) | D10: kg | E10: 0.0091306964 | F10: 264.75403 | G10: =GRAFICAS!R55 -> 355 | H10: =$E$10*H5 -> 264.75403 | I10: =$E$10*I5 -> 286.90109 | J10: =$E$10*J5 -> 312.71996 | K10: =$E$10*K5 -> 369.87621 | L10: =$E$10*L5 -> 367.8346 | M10: =$E$10*M5 -> 397.02493 | N10: =$E$10*N5 -> 373.06369 | O10: =$E$10*O5 -> 243.6588 | P10: =$E$10*P5 -> 122.55646 | Q10: =+SUM(F10:P10) -> 3358.1438 | R10: =F10/$F$5 -> 0.0091306964 | S10: =G10/$G$5 -> 0.010952058 | T10: =1-S10/R10 -> -0.19947672 | U10: 22050 | V10: =F10*U10 -> 5837826.3 | W10: =G10*U10 -> 7827750 | X10: =1-W10/V10 -> -0.34086723 | Y10: =V10/$F$5 -> 201.33185 | Z10: =W10/$G$5 -> 241.49287 | AA10: =Y10-Z10 -> -40.161019
C11: QUIMICO FLOCULANTE PARA TRATAMIENTO DE AGUA (Aniónico) | D11: kg | E11: 0.0054182543 | F11: 157.10791 | G11: =GRAFICAS!R44 -> 195 | H11: =$E$11*H5 -> 157.10791 | I11: =$E$11*I5 -> 170.25022 | J11: =$E$11*J5 -> 185.57142 | K11: =$E$11*K5 -> 219.48856 | L11: =$E$11*L5 -> 218.27704 | M11: =$E$11*M5 -> 235.5989 | N11: =$E$11*N5 -> 221.38004 | O11: =$E$11*O5 -> 144.58978 | P11: =$E$11*P5 -> 72.726331 | Q11: =+SUM(F11:P11) -> 1977.0981 | R11: =F11/$F$5 -> 0.0054182543 | S11: =G11/$G$5 -> 0.006015919 | T11: =1-S11/R11 -> -0.11030577 | U11: 19050 | V11: =F11*U11 -> 2992905.8 | W11: =G11*U11 -> 3714750 | X11: =1-W11/V11 -> -0.24118509 | Y11: =V11/$F$5 -> 103.21774 | Z11: =W11/$G$5 -> 114.60326 | AA11: =Y11-Z11 -> -11.385513
C12: QUIMICO COAGULANTE PARA TRATAMIENTO DE AGUA (Coagulante) | D12: kg | E12: 0.54180085 | F12: 15710.079 | G12: =GRAFICAS!S20 -> 13024.75 | H12: =$E$12*H5 -> 15710.079 | I12: =$E$12*I5 -> 17024.25 | J12: =$E$12*J5 -> 18556.3 | K12: =$E$12*K5 -> 21947.86 | L12: =$E$12*L5 -> 21826.714 | M12: =$E$12*M5 -> 23558.821 | N12: =$E$12*N5 -> 22137 | O12: =$E$12*O5 -> 14458.322 | P12: =$E$12*P5 -> 7272.3033 | Q12: =+SUM(F12:P12) -> 191226.48 | R12: =F12/$F$5 -> 0.54180085 | S12: =G12/$G$5 -> 0.40182483 | T12: =1-S12/R12 -> 0.25835328 | U12: 2818 | V12: =F12*U12 -> 44271002 | W12: =G12*U12 -> 36703746 | X12: =1-W12/V12 -> 0.17093032 | Y12: =V12/$F$5 -> 1526.7948 | Z12: =W12/$G$5 -> 1132.3424 | AA12: =Y12-Z12 -> 394.45244
C13: QUIMICO COAGULANTE PARA TRATAMIENTO DE AGUA (Decolorante) | D13: kg | E13: 0.23755146 | F13: 6888.0515 | G13: =GRAFICAS!S13 -> 4800 | H13: =$E$13*H5 -> 6888.0515 | I13: =$E$13*I5 -> 7464.2471 | J13: =$E$13*J5 -> 8135.9715 | K13: =$E$13*K5 -> 9622.994 | L13: =$E$13*L5 -> 9569.8776 | M13: =$E$13*M5 -> 10329.317 | N13: =$E$13*N5 -> 9705.922 | O13: =$E$13*O5 -> 6339.2213 | P13: =$E$13*P5 -> 3188.5263 | Q13: =+SUM(F13:P13) -> 82932.179 | R13: =F13/$F$5 -> 0.23755146 | S13: =G13/$G$5 -> 0.14808416 | T13: =1-S13/R13 -> 0.37662282 | U13: 6295 | V13: =F13*U13 -> 43360284 | W13: =G13*U13 -> 30216000 | X13: =1-W13/V13 -> 0.3031411 | Y13: =V13/$F$5 -> 1495.3865 | Z13: =W13/$G$5 -> 932.18979 | AA13: =Y13-Z13 -> 563.19667
C14: HIPOCLORITO DE SODIO | D14: kg | E14: 0.0072995135 | F14: 211.65698 | G14: 1000 | H14: =$E$14*H5 -> 211.65698 | I14: =$E$14*I5 -> 229.36239 | J14: =$E$14*J5 -> 250.00323 | K14: =$E$14*K5 -> 295.69666 | L14: =$E$14*L5 -> 294.06449 | M14: =$E$14*M5 -> 317.40063 | N14: =$E$14*N5 -> 298.24488 | O14: =$E$14*O5 -> 194.79245 | P14: =$E$14*P5 -> 97.977467 | Q14: =+SUM(F14:P14) -> 3400.8562 | R14: =F14/$F$5 -> 0.0072995135 | S14: =G14/$G$5 -> 0.030850867 | T14: =1-S14/R14 -> -3.2264278 | U14: 1298 | V14: =F14*U14 -> 274730.76 | W14: =G14*U14 -> 1298000 | X14: =1-W14/V14 -> -3.7246257 | Y14: =V14/$F$5 -> 9.4747685 | Z14: =W14/$G$5 -> 40.044425 | AA14: =Y14-Z14 -> -30.569657
C15: SODA CAUSTICA LIQUI48% 90 KL | D15: kg | E15: 0.013272416 | F15: 384.84748 | G15: 90 | H15: =$E$15*H5 -> 384.84748 | I15: =$E$15*I5 -> 417.04054 | J15: =$E$15*J5 -> 454.57095 | K15: =$E$15*K5 -> 537.6535 | L15: =$E$15*L5 -> 534.6858 | M15: =$E$15*M5 -> 577.11698 | N15: =$E$15*N5 -> 542.28683 | O15: =$E$15*O5 -> 354.18338 | P15: =$E$15*P5 -> 178.14854 | Q15: =+SUM(F15:P15) -> 4455.3815 | R15: =F15/$F$5 -> 0.013272416 | S15: =G15/$G$5 -> 0.002776578 | T15: =1-S15/R15 -> 0.79080085 | U15: 1862 | V15: =F15*U15 -> 716586.01 | W15: =G15*U15 -> 167580 | X15: =1-W15/V15 -> 0.76614112 | Y15: =V15/$F$5 -> 24.713238 | Z15: =W15/$G$5 -> 5.1699883 | AA15: =Y15-Z15 -> 19.54325 | AC15: Por cada CIP 30 Kg de soda
C16: QUIMICO ANTINCRUSTANTE PARA ÓSMOSIS INVERSA | D16: kg | E16: 0.013763942 | F16: 399.09979 | G16: 60 | H16: =$E$16*H5 -> 399.09979 | I16: =$E$16*I5 -> 432.48507 | J16: =$E$16*J5 -> 471.40537 | K16: =$E$16*K5 -> 557.56477 | L16: =$E$16*L5 -> 554.48716 | M16: =$E$16*M5 -> 598.48972 | N16: =$E$16*N5 -> 562.36969 | O16: =$E$16*O5 -> 367.30008 | P16: =$E$16*P5 -> 184.74603 | Q16: =+SUM(F16:P16) -> 4587.0475 | R16: =F16/$F$5 -> 0.013763942 | S16: =G16/$G$5 -> 0.001851052 | T16: =1-S16/R16 -> 0.86551439 | U16: 36239 | V16: =F16*U16 -> 14462977 | W16: =G16*U16 -> 2174340 | X16: =1-W16/V16 -> 0.84966166 | Y16: =V16/$F$5 -> 498.79148 | Z16: =W16/$G$5 -> 67.080274 | AA16: =Y16-Z16 -> 431.7112
C17: QUIMICO PARA TRATAMIENTO CIP ALCALINO ÓSMOSIS INVERSA | D17: kg | E17: 0.00091964781 | F17: 26.666144 | G17: 0 | H17: =$E$17*H5 -> 26.666144 | I17: =$E$17*I5 -> 28.896806 | J17: =$E$17*J5 -> 31.497294 | K17: =$E$17*K5 -> 37.254097 | L17: =$E$17*L5 -> 37.048464 | M17: =$E$17*M5 -> 39.988528 | N17: =$E$17*N5 -> 37.575141 | O17: =$E$17*O5 -> 24.541423 | P17: =$E$17*P5 -> 12.343941 | Q17: =+SUM(F17:P17) -> 302.47798 | R17: =F17/$F$5 -> 0.00091964781 | S17: =G17/$G$5 -> 0 | T17: =1-S17/R17 -> 1 | U17: 32490 | V17: =F17*U17 -> 866383.01 | W17: =G17*U17 -> 0 | X17: =1-W17/V17 -> 1 | Y17: =V17/$F$5 -> 29.879357 | Z17: =W17/$G$5 -> 0 | AA17: =Y17-Z17 -> 29.879357
C18: QUIMICO PARA TRATAMIENTO BIODISPERSANTE ÓMOSIS INVERSA | D18: kg | E18: 0.018171608 | F18: 526.90467 | G18: 80 | H18: =$E$18*H5 -> 526.90467 | I18: =$E$18*I5 -> 570.98102 | J18: =$E$18*J5 -> 622.36488 | K18: =$E$18*K5 -> 736.11535 | L18: =$E$18*L5 -> 732.05219 | M18: =$E$18*M5 -> 790.14582 | N18: =$E$18*N5 -> 742.45896 | O18: =$E$18*O5 -> 484.92165 | P18: =$E$18*P5 -> 243.90779 | Q18: =+SUM(F18:P18) -> 6056.757 | R18: =F18/$F$5 -> 0.018171608 | S18: =G18/$G$5 -> 0.0024680694 | T18: =1-S18/R18 -> 0.86417992 | U18: 19160 | V18: =F18*U18 -> 10095493 | W18: =G18*U18 -> 1532800 | X18: =1-W18/V18 -> 0.84816988 | Y18: =V18/$F$5 -> 348.16802 | Z18: =W18/$G$5 -> 47.288209 | AA18: =Y18-Z18 -> 300.87981
C19: QUIMICO PARA TRATAMIENTO CIP ACIDO ÓSMOSIS INVERSA | D19: Kg | E19: 0.00087479088 | F19: 25.36547 | G19: 0 | H19: =$E$19*H5 -> 25.36547 | I19: =$E$19*I5 -> 27.487329 | J19: =$E$19*J5 -> 29.960976 | K19: =$E$19*K5 -> 35.436984 | L19: =$E$19*L5 -> 35.241381 | M19: =$E$19*M5 -> 38.038039 | N19: =$E$19*N5 -> 35.742369 | O19: =$E$19*O5 -> 23.344386 | P19: =$E$19*P5 -> 11.74185 | Q19: =+SUM(F19:P19) -> 287.72425 | R19: =F19/$F$5 -> 0.00087479088 | S19: =G19/$G$5 -> 0 | T19: =1-S19/R19 -> 1 | U19: 34156 | V19: =F19*U19 -> 866383.01 | W19: =G19*U19 -> 0 | X19: =1-W19/V19 -> 1 | Y19: =V19/$F$5 -> 29.879357 | Z19: =W19/$G$5 -> 0 | AA19: =Y19-Z19 -> 29.879357
C20: ACIDO CÍTRICO | D20: Kg | E20: 0.00079766595 | F20: 23.129153 | G20: 0 | H20: =$E$20*H5 -> 23.129153 | I20: =$E$20*I5 -> 25.063941 | J20: =$E$20*J5 -> 27.319501 | K20: =$E$20*K5 -> 32.312723 | L20: =$E$20*L5 -> 32.134365 | M20: =$E$20*M5 -> 34.684459 | N20: =$E$20*N5 -> 32.591184 | O20: =$E$20*O5 -> 21.286255 | P20: =$E$20*P5 -> 10.706644 | Q20: =+SUM(F20:P20) -> 262.35738 | R20: =F20/$F$5 -> 0.00079766595 | S20: =G20/$G$5 -> 0 | T20: =1-S20/R20 -> 1 | U20: 5200 | V20: =F20*U20 -> 120271.6 | W20: =G20*U20 -> 0 | X20: =1-W20/V20 -> 1 | Y20: =V20/$F$5 -> 4.1478629 | Z20: =W20/$G$5 -> 0 | AA20: =Y20-Z20 -> 4.1478629
C21: Subtotal | V21: =F21*U21 -> 0 | W21: =G21*U21 -> 0
Q22: OSMOSIS INVERSA | V22: =F22*U22 -> 0 | W22: =G22*U22 -> 0
Q23: PTAR FASE 2 | V23: =F23*U23 -> 0 | W23: =G23*U23 -> 0
B25: COSTO PLANTA DE TRATAMIENTO DE AGUA DE POZO PROFUNDO
B26: Clasificación | C26: Detalle | D26: Unidad | E26: Dosificación | F26: Marzo 2026 | H26: Abril 2026 | I26: Mayo 2026 | J26: Junio 2026 | K26: Julio 2026 | L26: Agosto 2026 | M26: Septiembre 2026 | N26: Octubre 2026 | O26: Noviembre 2026 | P26: Diciembre 2026 | Q26: Total general | U26: $/Kg | V26: $ Total | W26: $/M3
E27: Kg/m3
F28: ='[1]PLAN MAESTRO BOGOTA RECIRCU'!J9 -> 5274.6748 | H28: ='[1]PLAN MAESTRO BOGOTA RECIRCU'!L9 -> 6028.2765 | I28: ='[1]PLAN MAESTRO BOGOTA RECIRCU'!N9 -> 10800 | J28: ='[1]PLAN MAESTRO BOGOTA RECIRCU'!P9 -> 10800 | K28: ='[1]PLAN MAESTRO BOGOTA RECIRCU'!R9 -> 10800 | L28: ='[1]PLAN MAESTRO BOGOTA RECIRCU'!T9 -> 10800 | M28: ='[1]PLAN MAESTRO BOGOTA RECIRCU'!V9 -> 10800 | N28: ='[1]PLAN MAESTRO BOGOTA RECIRCU'!X9 -> 10800 | O28: ='[1]PLAN MAESTRO BOGOTA RECIRCU'!Z9 -> 10800 | P28: ='[1]PLAN MAESTRO BOGOTA RECIRCU'!AB9 -> 10800 | Q28: =SUM(F28:P28) -> 97702.951
B29: QUIMICOS (GEM + RO) | C29: ACIDO CLORHIDRICO 31,5% | D29: kg | E29: 0.06 | F29: =$E$29*F28 -> 316.48049 | H29: =$E$29*H28 -> 361.69659 | I29: =$E$29*I28 -> 648 | J29: =$E$29*J28 -> 648 | K29: =$E$29*K28 -> 648 | L29: =$E$29*L28 -> 648 | M29: =$E$29*M28 -> 648 | N29: =$E$29*N28 -> 648 | O29: =$E$29*O28 -> 648 | P29: =$E$29*P28 -> 648 | Q29: =+SUM(F29:P29) -> 5862.1771 | U29: 1650 | V29: =Q29*U29 -> 9672592.2 | W29: =V29/$Q$28 -> 99
C30: ACIDIFICANTE | D30: kg | E30: 0.38 | F30: =$E$30*F28 -> 2004.3764 | H30: =$E$30*H28 -> 2290.7451 | I30: =$E$30*I28 -> 4104 | J30: =$E$30*J28 -> 4104 | K30: =$E$30*K28 -> 4104 | L30: =$E$30*L28 -> 4104 | M30: =$E$30*M28 -> 4104 | N30: =$E$30*N28 -> 4104 | O30: =$E$30*O28 -> 4104 | P30: =$E$30*P28 -> 4104 | Q30: =+SUM(F30:P30) -> 37127.122 | U30: 830 | V30: =Q30*U30 -> 30815511 | W30: =V30/$Q$28 -> 315.4
C31: QUIMICO COAGULANTE PARA TRATAMIENTO DE AGUA (Coagulante) | D31: kg | E31: 0.5426 | F31: =$E$31*F28 -> 2862.0386 | H31: =$E$31*H28 -> 3270.9428 | I31: =$E$31*I28 -> 5860.08 | J31: =$E$31*J28 -> 5860.08 | K31: =$E$31*K28 -> 5860.08 | L31: =$E$31*L28 -> 5860.08 | M31: =$E$31*M28 -> 5860.08 | N31: =$E$31*N28 -> 5860.08 | O31: =$E$31*O28 -> 5860.08 | P31: =$E$31*P28 -> 5860.08 | Q31: =+SUM(F31:P31) -> 53013.621 | U31: 2900 | V31: =Q31*U31 -> 1.537395e+08 | W31: =V31/$Q$28 -> 1573.54
C32: QUIMICO FLOCULANTE PARA TRATAMIENTO DE AGUA (Aniónico) | D32: kg | E32: 0.0054 | F32: =$E$32*F28 -> 28.483244 | H32: =$E$32*H28 -> 32.552693 | I32: =$E$32*I28 -> 58.32 | J32: =$E$32*J28 -> 58.32 | K32: =$E$32*K28 -> 58.32 | L32: =$E$32*L28 -> 58.32 | M32: =$E$32*M28 -> 58.32 | N32: =$E$32*N28 -> 58.32 | O32: =$E$32*O28 -> 58.32 | P32: =$E$32*P28 -> 58.32 | Q32: =+SUM(F32:P32) -> 527.59594 | U32: 19050 | V32: =Q32*U32 -> 10050703 | W32: =V32/$Q$28 -> 102.87
C33: HIPOCLORITO DE SODIO | D33: kg | E33: 0.125 | F33: =$E$33*F28 -> 659.33435 | H33: =$E$33*H28 -> 753.53456 | I33: =$E$33*I28 -> 1350 | J33: =$E$33*J28 -> 1350 | K33: =$E$33*K28 -> 1350 | L33: =$E$33*L28 -> 1350 | M33: =$E$33*M28 -> 1350 | N33: =$E$33*N28 -> 1350 | O33: =$E$33*O28 -> 1350 | P33: =$E$33*P28 -> 1350 | Q33: =+SUM(F33:P33) -> 12212.869 | U33: 1298 | V33: =Q33*U33 -> 15852304 | W33: =V33/$Q$28 -> 162.25
C34: SODA CAUSTICA LIQUI48% 90 KL | D34: kg | E34: 0.037 | F34: =$E$34*F28 -> 195.16297 | H34: =$E$34*H28 -> 223.04623 | I34: =$E$34*I28 -> 399.6 | J34: =$E$34*J28 -> 399.6 | K34: =$E$34*K28 -> 399.6 | L34: =$E$34*L28 -> 399.6 | M34: =$E$34*M28 -> 399.6 | N34: =$E$34*N28 -> 399.6 | O34: =$E$34*O28 -> 399.6 | P34: =$E$34*P28 -> 399.6 | Q34: =+SUM(F34:P34) -> 3615.0092 | U34: 1862 | V34: =Q34*U34 -> 6731147.1 | W34: =V34/$Q$28 -> 68.894
C35: Subtotal | Q35: PTAP | V35: =SUM(V29:V34) -> 2.2686176e+08 | W35: =V35/$Q$28 -> 2321.954

Sheet INVENTARIO Y CONSUMO GEM  
A1: FECHA | B1: DIA | C1: ANALISIS TURNO | D1: # TURNO | E1: DILIGENCIAR BITACORA | F1: FINAL ACIDO (L) | G1: FINAL COAGULANTE (L) | H1: FINAL DECOLORANTE (L) | I1: FINAL POL ANIONICO (KG) | J1: FINAL POL CATIONICO (KG) | K1: Lectura Horometro INICIAL (06:00) | L1: CAUDAL TOTAL TRATADO GEM | M1: CAUDAL DE TRATAMIENTO | N1: CONSUMO LITROS ACIDO (L) | O1: CONSUMO LITROS COAGULANTE (L) | P1: CONSUMO LITROS DECOLORANTE (L) | Q1: CONSUMO POL ANIONICO (KG) | R1: CONSUMO POL CATIONICO (KG) | S1: KG ACIDO | T1: KG COAGULANTE | U1: KG DECOLORANTE | V1: KG POL ANIONICO | W1: KG POL CATIONICO | X1: PPM ACIDO | Y1: PPM COAGULANTE | Z1: PPM DECOLORANTE | AA1: PPM POL ANIONICO | AB1: PPM POL CATIONICO | AC1: DENSIDAD ACIDO | AD1: DENSIDAD COAGULANTE | AE1: DENSIDAD DECOLORANTE | AF1: DENSIDAD ANIONICO | AG1: DENSIDAD CATIONICO | AH1: PRECIO (KG) ACIDO | AI1: PRECIO (KG) COAGULANTE | AJ1: PRECIO (KG) DECOLORANTE | AK1: PRECIO (KG) ANIONICO | AL1: PRECIO (KG) CATIONICO | AM1: COSTO OPERATIVO ACIDO | AN1: COSTO OPERATIVO COAGULANTE | AO1: COSTO OPERATIVO DECOLORANTE | AP1: COSTO OPERATIVO ANIONICO | AQ1: COSTO OPERATIVO CATIONICO | AR1: COSTO QUIMICA | AS1: LIMITE INDICADOR M3 | AT1: $ m3 | AU1: HORAS DE OPERACIÓN
A2: 46113 | B2: 1 | C2: 1 (NOCHE) | D2: 1 | E2: FINAL TURNO 3 | F2: 2780 | G2: 5720 | H2: 4280 | I2: 275 | J2: 450 | K2: 17622 | L2: =(K3-K2)*M2 -> 0 | M2: 80 | N2: =F2-F3 -> 0 | O2: =G2-G3 -> 0 | P2: =H2-H3 -> 0 | Q2: =I2-I3 -> 0 | R2: =J2-J3 -> 0 | S2: =(N2*$AC$2) -> 0 | T2: =(O2*$AD$2) -> 0 | U2: =(P2*$AE$2) -> 0 | V2: =Tabla1[[#This Row],[CONSUMO POL ANIONICO (KG)]] -> 0 | W2: =Tabla1[[#This Row],[CONSUMO POL CATIONICO (KG)]] -> 0 | X2: =(S2*1000)/L2 -> #DIV/0! | Y2: =(T2*1000)/L2 -> #DIV/0! | Z2: =(U2*1000)/L2 -> #DIV/0! | AA2: =(V2*1000)/L2 -> #DIV/0! | AB2: =(W2*1000)/L2 -> #DIV/0! | AC2: 1.3 | AD2: 1.325 | AE2: 1.25 | AF2: 2500 | AG2: 2500 | AH2: 830 | AI2: 2818 | AJ2: 6295 | AK2: 19050 | AL2: 22050 | AM2: =S2*AH2 -> 0 | AN2: =T2*AI2 -> 0 | AO2: =U2*AJ2 -> 0 | AP2: =V2*AK2 -> 0 | AQ2: =W2*AL2 -> 0 | AR2: =SUM(Tabla1[[#This Row],[COSTO OPERATIVO ACIDO]:[COSTO OPERATIVO CATIONICO]]) -> 0 | AS2: 3599 | AT2: =AR2/L2 -> #DIV/0! | AU2: =IFERROR(Tabla1[[#This Row],[CAUDAL TOTAL TRATADO GEM ]]/Tabla1[[#This Row],[CAUDAL DE TRATAMIENTO]],0) -> 0
A3: =A2 -> 46113 | B3: 1 | C3: 2 (MAÑANA) | D3: 2 | E3: FINAL TURNO 1 | F3: 2780 | G3: 5720 | H3: 4280 | I3: =+I2-0 -> 275 | J3: =+J2-0 -> 450 | K3: 17622 | L3: =(K4-K3)*M3 -> 0 | M3: 80 | N3: =F3-F4 -> 0 | O3: =G3-G4 -> 0 | P3: =H3-H4 -> 0 | Q3: =I3-I4 -> 0 | R3: =J3-J4 -> 0 | S3: =(N3*$AC$2) -> 0 | T3: =(O3*$AD$2) -> 0 | U3: =(P3*$AE$2) -> 0 | V3: =Tabla1[[#This Row],[CONSUMO POL ANIONICO (KG)]] -> 0 | W3: =Tabla1[[#This Row],[CONSUMO POL CATIONICO (KG)]] -> 0 | X3: =(S3*1000)/L3 -> #DIV/0! | Y3: =(T3*1000)/L3 -> #DIV/0! | Z3: =(U3*1000)/L3 -> #DIV/0! | AA3: =(V3*1000)/L3 -> #DIV/0! | AB3: =(W3*1000)/L3 -> #DIV/0! | AC3: 1.3 | AD3: 1.325 | AE3: 1.25 | AF3: 2500 | AG3: 2500 | AH3: 830 | AI3: 2818 | AJ3: 6295 | AK3: 19050 | AL3: 22050 | AM3: =S3*AH3 -> 0 | AN3: =T3*AI3 -> 0 | AO3: =U3*AJ3 -> 0 | AP3: =V3*AK3 -> 0 | AQ3: =W3*AL3 -> 0 | AR3: =SUM(Tabla1[[#This Row],[COSTO OPERATIVO ACIDO]:[COSTO OPERATIVO CATIONICO]]) -> 0 | AS3: 3599 | AT3: =AR3/L3 -> #DIV/0! | AU3: =IFERROR(Tabla1[[#This Row],[CAUDAL TOTAL TRATADO GEM ]]/Tabla1[[#This Row],[CAUDAL DE TRATAMIENTO]],0) -> 0
A4: =+A3 -> 46113 | B4: 1 | C4: 3(TARDE) | D4: 3 | E4: FINAL TURNO 2 | F4: 2780 | G4: 5720 | H4: 4280 | I4: =+I3-0 -> 275 | J4: =+J3-0 -> 450 | K4: 17622 | L4: =(K5-K4)*M4 -> 0 | M4: 80 | N4: =F4-F5 -> 0 | O4: =G4-G5 -> 0 | P4: =H4-H5 -> 0 | Q4: =I4-I5 -> 0 | R4: =J4-J5 -> 0 | S4: =(N4*$AC$2) -> 0 | T4: =(O4*$AD$2) -> 0 | U4: =(P4*$AE$2) -> 0 | V4: =Tabla1[[#This Row],[CONSUMO POL ANIONICO (KG)]] -> 0 | W4: =Tabla1[[#This Row],[CONSUMO POL CATIONICO (KG)]] -> 0 | X4: =(S4*1000)/L4 -> #DIV/0! | Y4: =(T4*1000)/L4 -> #DIV/0! | Z4: =(U4*1000)/L4 -> #DIV/0! | AA4: =(V4*1000)/L4 -> #DIV/0! | AB4: =(W4*1000)/L4 -> #DIV/0! | AC4: 1.3 | AD4: 1.325 | AE4: 1.25 | AF4: 2500 | AG4: 2500 | AH4: 830 | AI4: 2818 | AJ4: 6295 | AK4: 19050 | AL4: 22050 | AM4: =S4*AH4 -> 0 | AN4: =T4*AI4 -> 0 | AO4: =U4*AJ4 -> 0 | AP4: =V4*AK4 -> 0 | AQ4: =W4*AL4 -> 0 | AR4: =SUM(Tabla1[[#This Row],[COSTO OPERATIVO ACIDO]:[COSTO OPERATIVO CATIONICO]]) -> 0 | AS4: 3599 | AT4: =AR4/L4 -> #DIV/0! | AU4: =IFERROR(Tabla1[[#This Row],[CAUDAL TOTAL TRATADO GEM ]]/Tabla1[[#This Row],[CAUDAL DE TRATAMIENTO]],0) -> 0
A5: =+A4+1 -> 46114 | B5: 2 | C5: 2 (NOCHE) | D5: 4 | E5: FINAL TURNO 3 | F5: 2780 | G5: 5720 | H5: 4280 | I5: =+I4-0 -> 275 | J5: =+J4-0 -> 450 | K5: 17622 | L5: =(K6-K5)*M5 -> 480 | M5: 80 | N5: =F5-F6 -> 80 | O5: =G5-G6 -> 20 | P5: =H5-H6 -> 80 | Q5: =I5-I6 -> 5 | R5: =J5-J6 -> 5 | S5: =(N5*$AC$2) -> 104 | T5: =(O5*$AD$2) -> 26.5 | U5: =(P5*$AE$2) -> 100 | V5: =Tabla1[[#This Row],[CONSUMO POL ANIONICO (KG)]] -> 5 | W5: =Tabla1[[#This Row],[CONSUMO POL CATIONICO (KG)]] -> 5 | X5: =(S5*1000)/L5 -> 216.66667 | Y5: =(T5*1000)/L5 -> 55.208333 | Z5: =(U5*1000)/L5 -> 208.33333 | AA5: =(V5*1000)/L5 -> 10.416667 | AB5: =(W5*1000)/L5 -> 10.416667 | AC5: 1.3 | AD5: 1.325 | AE5: 1.25 | AF5: 2500 | AG5: 2500 | AH5: 830 | AI5: 2818 | AJ5: 6295 | AK5: 19050 | AL5: 22050 | AM5: =S5*AH5 -> 86320 | AN5: =T5*AI5 -> 74677 | AO5: =U5*AJ5 -> 629500 | AP5: =V5*AK5 -> 95250 | AQ5: =W5*AL5 -> 110250 | AR5: =SUM(Tabla1[[#This Row],[COSTO OPERATIVO ACIDO]:[COSTO OPERATIVO CATIONICO]]) -> 995997 | AS5: 3599 | AT5: =AR5/L5 -> 2074.9938 | AU5: =IFERROR(Tabla1[[#This Row],[CAUDAL TOTAL TRATADO GEM ]]/Tabla1[[#This Row],[CAUDAL DE TRATAMIENTO]],0) -> 6
A6: =+A5 -> 46114 | B6: 2 | C6: 3 (MAÑANA) | D6: 5 | E6: FINAL TURNO 1 | F6: 2700 | G6: 5700 | H6: 4200 | I6: =+I5-5 -> 270 | J6: =+J5-5 -> 445 | K6: 17628 | L6: =(K7-K6)*M6 -> 400 | M6: 80 | N6: =F6-F7 -> 100 | O6: =G6-G7 -> 100 | P6: =H6-H7 -> 10 | Q6: =I6-I7 -> 5 | R6: =J6-J7 -> 5 | S6: =(N6*$AC$2) -> 130 | T6: =(O6*$AD$2) -> 132.5 | U6: =(P6*$AE$2) -> 12.5 | V6: =Tabla1[[#This Row],[CONSUMO POL ANIONICO (KG)]] -> 5 | W6: =Tabla1[[#This Row],[CONSUMO POL CATIONICO (KG)]] -> 5 | X6: =(S6*1000)/L6 -> 325 | Y6: =(T6*1000)/L6 -> 331.25 | Z6: =(U6*1000)/L6 -> 31.25 | AA6: =(V6*1000)/L6 -> 12.5 | AB6: =(W6*1000)/L6 -> 12.5 | AC6: 1.3 | AD6: 1.325 | AE6: 1.25 | AF6: 2500 | AG6: 2500 | AH6: 830 | AI6: 2818 | AJ6: 6295 | AK6: 19050 | AL6: 22050 | AM6: =S6*AH6 -> 107900 | AN6: =T6*AI6 -> 373385 | AO6: =U6*AJ6 -> 78687.5 | AP6: =V6*AK6 -> 95250 | AQ6: =W6*AL6 -> 110250 | AR6: =SUM(Tabla1[[#This Row],[COSTO OPERATIVO ACIDO]:[COSTO OPERATIVO CATIONICO]]) -> 765472.5 | AS6: 3599 | AT6: =AR6/L6 -> 1913.6813 | AU6: =IFERROR(Tabla1[[#This Row],[CAUDAL TOTAL TRATADO GEM ]]/Tabla1[[#This Row],[CAUDAL DE TRATAMIENTO]],0) -> 5
A7: =+A6 -> 46114 | B7: 2 | C7: 3(TARDE) | D7: 6 | E7: FINAL TURNO 2 | F7: 2600 | G7: 5600 | H7: 4190 | I7: =+I6-5 -> 265 | J7: =+J6-5 -> 440 | K7: 17633 | L7: =(K8-K7)*M7 -> 0 | M7: 80 | N7: =F7-F8 -> 0 | O7: =G7-G8 -> 0 | P7: =H7-H8 -> 0 | Q7: =I7-I8 -> 0 | R7: =J7-J8 -> 0 | S7: =(N7*$AC$2) -> 0 | T7: =(O7*$AD$2) -> 0 | U7: =(P7*$AE$2) -> 0 | V7: =Tabla1[[#This Row],[CONSUMO POL ANIONICO (KG)]] -> 0 | W7: =Tabla1[[#This Row],[CONSUMO POL CATIONICO (KG)]] -> 0 | X7: =(S7*1000)/L7 -> #DIV/0! | Y7: =(T7*1000)/L7 -> #DIV/0! | Z7: =(U7*1000)/L7 -> #DIV/0! | AA7: =(V7*1000)/L7 -> #DIV/0! | AB7: =(W7*1000)/L7 -> #DIV/0! | AC7: 1.3 | AD7: 1.325 | AE7: 1.25 | AF7: 2500 | AG7: 2500 | AH7: 830 | AI7: 2818 | AJ7: 6295 | AK7: 19050 | AL7: 22050 | AM7: =S7*AH7 -> 0 | AN7: =T7*AI7 -> 0 | AO7: =U7*AJ7 -> 0 | AP7: =V7*AK7 -> 0 | AQ7: =W7*AL7 -> 0 | AR7: =SUM(Tabla1[[#This Row],[COSTO OPERATIVO ACIDO]:[COSTO OPERATIVO CATIONICO]]) -> 0 | AS7: 3599 | AT7: =AR7/L7 -> #DIV/0! | AU7: =IFERROR(Tabla1[[#This Row],[CAUDAL TOTAL TRATADO GEM ]]/Tabla1[[#This Row],[CAUDAL DE TRATAMIENTO]],0) -> 0
A8: =+A7+1 -> 46115 | B8: 3 | C8: 3 (NOCHE) | D8: 7 | E8: FINAL TURNO 3 | F8: 2600 | G8: 5600 | H8: 4190 | I8: =+I7-0 -> 265 | J8: =+J7-0 -> 440 | K8: 17633 | L8: =(K9-K8)*M8 -> 0 | M8: 80 | N8: =F8-F9 -> 0 | O8: =G8-G9 -> 0 | P8: =H8-H9 -> 0 | Q8: =I8-I9 -> 0 | R8: =J8-J9 -> 0 | S8: =(N8*$AC$2) -> 0 | T8: =(O8*$AD$2) -> 0 | U8: =(P8*$AE$2) -> 0 | V8: =Tabla1[[#This Row],[CONSUMO POL ANIONICO (KG)]] -> 0 | W8: =Tabla1[[#This Row],[CONSUMO POL CATIONICO (KG)]] -> 0 | X8: =(S8*1000)/L8 -> #DIV/0! | Y8: =(T8*1000)/L8 -> #DIV/0! | Z8: =(U8*1000)/L8 -> #DIV/0! | AA8: =(V8*1000)/L8 -> #DIV/0! | AB8: =(W8*1000)/L8 -> #DIV/0! | AC8: 1.3 | AD8: 1.325 | AE8: 1.25 | AF8: 2500 | AG8: 2500 | AH8: 830 | AI8: 2818 | AJ8: 6295 | AK8: 19050 | AL8: 22050 | AM8: =S8*AH8 -> 0 | AN8: =T8*AI8 -> 0 | AO8: =U8*AJ8 -> 0 | AP8: =V8*AK8 -> 0 | AQ8: =W8*AL8 -> 0 | AR8: =SUM(Tabla1[[#This Row],[COSTO OPERATIVO ACIDO]:[COSTO OPERATIVO CATIONICO]]) -> 0 | AS8: 3599 | AT8: =AR8/L8 -> #DIV/0! | AU8: =IFERROR(Tabla1[[#This Row],[CAUDAL TOTAL TRATADO GEM ]]/Tabla1[[#This Row],[CAUDAL DE TRATAMIENTO]],0) -> 0
A9: =+A8 -> 46115 | B9: 3 | C9: 4 (MAÑANA) | D9: 8 | E9: FINAL TURNO 1 | F9: 2600 | G9: 5600 | H9: 4190 | I9: =+I8-0 -> 265 | J9: =+J8-0 -> 440 | K9: 17633 | L9: =(K10-K9)*M9 -> 0 | M9: 80 | N9: =F9-F10 -> 0 | O9: =G9-G10 -> 0 | P9: =H9-H10 -> 0 | Q9: =I9-I10 -> 0 | R9: =J9-J10 -> 0 | S9: =(N9*$AC$2) -> 0 | T9: =(O9*$AD$2) -> 0 | U9: =(P9*$AE$2) -> 0 | V9: =Tabla1[[#This Row],[CONSUMO POL ANIONICO (KG)]] -> 0 | W9: =Tabla1[[#This Row],[CONSUMO POL CATIONICO (KG)]] -> 0 | X9: =(S9*1000)/L9 -> #DIV/0! | Y9: =(T9*1000)/L9 -> #DIV/0! | Z9: =(U9*1000)/L9 -> #DIV/0! | AA9: =(V9*1000)/L9 -> #DIV/0! | AB9: =(W9*1000)/L9 -> #DIV/0! | AC9: 1.3 | AD9: 1.325 | AE9: 1.25 | AF9: 2500 | AG9: 2500 | AH9: 830 | AI9: 2818 | AJ9: 6295 | AK9: 19050 | AL9: 22050 | AM9: =S9*AH9 -> 0 | AN9: =T9*AI9 -> 0 | AO9: =U9*AJ9 -> 0 | AP9: =V9*AK9 -> 0 | AQ9: =W9*AL9 -> 0 | AR9: =SUM(Tabla1[[#This Row],[COSTO OPERATIVO ACIDO]:[COSTO OPERATIVO CATIONICO]]) -> 0 | AS9: 3599 | AT9: =AR9/L9 -> #DIV/0! | AU9: =IFERROR(Tabla1[[#This Row],[CAUDAL TOTAL TRATADO GEM ]]/Tabla1[[#This Row],[CAUDAL DE TRATAMIENTO]],0) -> 0
A10: =+A9 -> 46115 | B10: 3 | C10: 3(TARDE) | D10: 9 | E10: FINAL TURNO 2 | F10: 2600 | G10: 5600 | H10: 4190 | I10: =+I9-0 -> 265 | J10: =+J9-0 -> 440 | K10: 17633 | L10: =(K11-K10)*M10 -> 0 | M10: 80 | N10: =F10-F11 -> 0 | O10: =G10-G11 -> 0 | P10: =H10-H11 -> 0 | Q10: =I10-I11 -> 0 | R10: =J10-J11 -> 0 | S10: =(N10*$AC$2) -> 0 | T10: =(O10*$AD$2) -> 0 | U10: =(P10*$AE$2) -> 0 | V10: =Tabla1[[#This Row],[CONSUMO POL ANIONICO (KG)]] -> 0 | W10: =Tabla1[[#This Row],[CONSUMO POL CATIONICO (KG)]] -> 0 | X10: =(S10*1000)/L10 -> #DIV/0! | Y10: =(T10*1000)/L10 -> #DIV/0! | Z10: =(U10*1000)/L10 -> #DIV/0! | AA10: =(V10*1000)/L10 -> #DIV/0! | AB10: =(W10*1000)/L10 -> #DIV/0! | AC10: 1.3 | AD10: 1.325 | AE10: 1.25 | AF10: 2500 | AG10: 2500 | AH10: 830 | AI10: 2818 | AJ10: 6295 | AK10: 19050 | AL10: 22050 | AM10: =S10*AH10 -> 0 | AN10: =T10*AI10 -> 0 | AO10: =U10*AJ10 -> 0 | AP10: =V10*AK10 -> 0 | AQ10: =W10*AL10 -> 0 | AR10: =SUM(Tabla1[[#This Row],[COSTO OPERATIVO ACIDO]:[COSTO OPERATIVO CATIONICO]]) -> 0 | AS10: 3599 | AT10: =AR10/L10 -> #DIV/0! | AU10: =IFERROR(Tabla1[[#This Row],[CAUDAL TOTAL TRATADO GEM ]]/Tabla1[[#This Row],[CAUDAL DE TRATAMIENTO]],0) -> 0
A11: =+A10+1 -> 46116 | B11: 4 | C11: 4 (NOCHE) | D11: 10 | E11: FINAL TURNO 3 | F11: 2600 | G11: 5600 | H11: 4190 | I11: =+I10-0 -> 265 | J11: =+J10-0 -> 440 | K11: 17633 | L11: =(K12-K11)*M11 -> 0 | M11: 80 | N11: =F11-F12 -> 0 | O11: =G11-G12 -> 0 | P11: =H11-H12 -> 0 | Q11: =I11-I12 -> 0 | R11: =J11-J12 -> 0 | S11: =(N11*$AC$2) -> 0 | T11: =(O11*$AD$2) -> 0 | U11: =(P11*$AE$2) -> 0 | V11: =Tabla1[[#This Row],[CONSUMO POL ANIONICO (KG)]] -> 0 | W11: =Tabla1[[#This Row],[CONSUMO POL CATIONICO (KG)]] -> 0 | X11: =(S11*1000)/L11 -> #DIV/0! | Y11: =(T11*1000)/L11 -> #DIV/0! | Z11: =(U11*1000)/L11 -> #DIV/0! | AA11: =(V11*1000)/L11 -> #DIV/0! | AB11: =(W11*1000)/L11 -> #DIV/0! | AC11: 1.3 | AD11: 1.325 | AE11: 1.25 | AF11: 2500 | AG11: 2500 | AH11: 830 | AI11: 2818 | AJ11: 6295 | AK11: 19050 | AL11: 22050 | AM11: =S11*AH11 -> 0 | AN11: =T11*AI11 -> 0 | AO11: =U11*AJ11 -> 0 | AP11: =V11*AK11 -> 0 | AQ11: =W11*AL11 -> 0 | AR11: =SUM(Tabla1[[#This Row],[COSTO OPERATIVO ACIDO]:[COSTO OPERATIVO CATIONICO]]) -> 0 | AS11: 3599 | AT11: =AR11/L11 -> #DIV/0! | AU11: =IFERROR(Tabla1[[#This Row],[CAUDAL TOTAL TRATADO GEM ]]/Tabla1[[#This Row],[CAUDAL DE TRATAMIENTO]],0) -> 0
A12: =+A11 -> 46116 | B12: 4 | C12: 5 (MAÑANA) | D12: 11 | E12: FINAL TURNO 1 | F12: 2600 | G12: 5600 | H12: 4190 | I12: =+I11-0 -> 265 | J12: =+J11-0 -> 440 | K12: 17633 | L12: =(K13-K12)*M12 -> 0 | M12: 80 | N12: =F12-F13 -> 0 | O12: =G12-G13 -> 0 | P12: =H12-H13 -> 0 | Q12: =I12-I13 -> 0 | R12: =J12-J13 -> 0 | S12: =(N12*$AC$2) -> 0 | T12: =(O12*$AD$2) -> 0 | U12: =(P12*$AE$2) -> 0 | V12: =Tabla1[[#This Row],[CONSUMO POL ANIONICO (KG)]] -> 0 | W12: =Tabla1[[#This Row],[CONSUMO POL CATIONICO (KG)]] -> 0 | X12: =(S12*1000)/L12 -> #DIV/0! | Y12: =(T12*1000)/L12 -> #DIV/0! | Z12: =(U12*1000)/L12 -> #DIV/0! | AA12: =(V12*1000)/L12 -> #DIV/0! | AB12: =(W12*1000)/L12 -> #DIV/0! | AC12: 1.3 | AD12: 1.325 | AE12: 1.25 | AF12: 2500 | AG12: 2500 | AH12: 830 | AI12: 2818 | AJ12: 6295 | AK12: 19050 | AL12: 22050 | AM12: =S12*AH12 -> 0 | AN12: =T12*AI12 -> 0 | AO12: =U12*AJ12 -> 0 | AP12: =V12*AK12 -> 0 | AQ12: =W12*AL12 -> 0 | AR12: =SUM(Tabla1[[#This Row],[COSTO OPERATIVO ACIDO]:[COSTO OPERATIVO CATIONICO]]) -> 0 | AS12: 3599 | AT12: =AR12/L12 -> #DIV/0! | AU12: =IFERROR(Tabla1[[#This Row],[CAUDAL TOTAL TRATADO GEM ]]/Tabla1[[#This Row],[CAUDAL DE TRATAMIENTO]],0) -> 0
A13: =+A12 -> 46116 | B13: 4 | C13: 3(TARDE) | D13: 12 | E13: FINAL TURNO 2 | F13: 2600 | G13: 5600 | H13: 4190 | I13: =+I12-0 -> 265 | J13: =+J12-0 -> 440 | K13: 17633 | L13: =(K14-K13)*M13 -> 0 | M13: 80 | N13: =F13-F14 -> 0 | O13: =G13-G14 -> 0 | P13: =H13-H14 -> 0 | Q13: =I13-I14 -> 0 | R13: =J13-J14 -> 0 | S13: =(N13*$AC$2) -> 0 | T13: =(O13*$AD$2) -> 0 | U13: =(P13*$AE$2) -> 0 | V13: =Tabla1[[#This Row],[CONSUMO POL ANIONICO (KG)]] -> 0 | W13: =Tabla1[[#This Row],[CONSUMO POL CATIONICO (KG)]] -> 0 | X13: =(S13*1000)/L13 -> #DIV/0! | Y13: =(T13*1000)/L13 -> #DIV/0! | Z13: =(U13*1000)/L13 -> #DIV/0! | AA13: =(V13*1000)/L13 -> #DIV/0! | AB13: =(W13*1000)/L13 -> #DIV/0! | AC13: 1.3 | AD13: 1.325 | AE13: 1.25 | AF13: 2500 | AG13: 2500 | AH13: 830 | AI13: 2818 | AJ13: 6295 | AK13: 19050 | AL13: 22050 | AM13: =S13*AH13 -> 0 | AN13: =T13*AI13 -> 0 | AO13: =U13*AJ13 -> 0 | AP13: =V13*AK13 -> 0 | AQ13: =W13*AL13 -> 0 | AR13: =SUM(Tabla1[[#This Row],[COSTO OPERATIVO ACIDO]:[COSTO OPERATIVO CATIONICO]]) -> 0 | AS13: 3599 | AT13: =AR13/L13 -> #DIV/0! | AU13: =IFERROR(Tabla1[[#This Row],[CAUDAL TOTAL TRATADO GEM ]]/Tabla1[[#This Row],[CAUDAL DE TRATAMIENTO]],0) -> 0
A14: =+A13+1 -> 46117 | B14: 5 | C14: 5 (NOCHE) | D14: 13 | E14: FINAL TURNO 3 | F14: 2600 | G14: 5600 | H14: 4190 | I14: =+I13-0 -> 265 | J14: =+J13-0 -> 440 | K14: 17633 | L14: =(K15-K14)*M14 -> 0 | M14: 80 | N14: =F14-F15 -> 0 | O14: =G14-G15 -> 0 | P14: =H14-H15 -> 0 | Q14: =I14-I15 -> 0 | R14: =J14-J15 -> 0 | S14: =(N14*$AC$2) -> 0 | T14: =(O14*$AD$2) -> 0 | U14: =(P14*$AE$2) -> 0 | V14: =Tabla1[[#This Row],[CONSUMO POL ANIONICO (KG)]] -> 0 | W14: =Tabla1[[#This Row],[CONSUMO POL CATIONICO (KG)]] -> 0 | X14: =(S14*1000)/L14 -> #DIV/0! | Y14: =(T14*1000)/L14 -> #DIV/0! | Z14: =(U14*1000)/L14 -> #DIV/0! | AA14: =(V14*1000)/L14 -> #DIV/0! | AB14: =(W14*1000)/L14 -> #DIV/0! | AC14: 1.3 | AD14: 1.325 | AE14: 1.25 | AF14: 2500 | AG14: 2500 | AH14: 830 | AI14: 2818 | AJ14: 6295 | AK14: 19050 | AL14: 22050 | AM14: =S14*AH14 -> 0 | AN14: =T14*AI14 -> 0 | AO14: =U14*AJ14 -> 0 | AP14: =V14*AK14 -> 0 | AQ14: =W14*AL14 -> 0 | AR14: =SUM(Tabla1[[#This Row],[COSTO OPERATIVO ACIDO]:[COSTO OPERATIVO CATIONICO]]) -> 0 | AS14: 3599 | AT14: =AR14/L14 -> #DIV/0! | AU14: =IFERROR(Tabla1[[#This Row],[CAUDAL TOTAL TRATADO GEM ]]/Tabla1[[#This Row],[CAUDAL DE TRATAMIENTO]],0) -> 0
A15: =+A14 -> 46117 | B15: 5 | C15: 6 (MAÑANA) | D15: 14 | E15: FINAL TURNO 1 | F15: 2600 | G15: 5600 | H15: 4190 | I15: =+I14-0 -> 265 | J15: =+J14-0 -> 440 | K15: 17633 | L15: =(K16-K15)*M15 -> 0 | M15: 80 | N15: =F15-F16 -> 0 | O15: =G15-G16 -> 0 | P15: =H15-H16 -> 0 | Q15: =I15-I16 -> 0 | R15: =J15-J16 -> 0 | S15: =(N15*$AC$2) -> 0 | T15: =(O15*$AD$2) -> 0 | U15: =(P15*$AE$2) -> 0 | V15: =Tabla1[[#This Row],[CONSUMO POL ANIONICO (KG)]] -> 0 | W15: =Tabla1[[#This Row],[CONSUMO POL CATIONICO (KG)]] -> 0 | X15: =(S15*1000)/L15 -> #DIV/0! | Y15: =(T15*1000)/L15 -> #DIV/0! | Z15: =(U15*1000)/L15 -> #DIV/0! | AA15: =(V15*1000)/L15 -> #DIV/0! | AB15: =(W15*1000)/L15 -> #DIV/0! | AC15: 1.3 | AD15: 1.325 | AE15: 1.25 | AF15: 2500 | AG15: 2500 | AH15: 830 | AI15: 2818 | AJ15: 6295 | AK15: 19050 | AL15: 22050 | AM15: =S15*AH15 -> 0 | AN15: =T15*AI15 -> 0 | AO15: =U15*AJ15 -> 0 | AP15: =V15*AK15 -> 0 | AQ15: =W15*AL15 -> 0 | AR15: =SUM(Tabla1[[#This Row],[COSTO OPERATIVO ACIDO]:[COSTO OPERATIVO CATIONICO]]) -> 0 | AS15: 3599 | AT15: =AR15/L15 -> #DIV/0! | AU15: =IFERROR(Tabla1[[#This Row],[CAUDAL TOTAL TRATADO GEM ]]/Tabla1[[#This Row],[CAUDAL DE TRATAMIENTO]],0) -> 0
A16: =+A15 -> 46117 | B16: 5 | C16: 3(TARDE) | D16: 15 | E16: FINAL TURNO 2 | F16: 2600 | G16: 5600 | H16: 4190 | I16: =+I15-0 -> 265 | J16: =J15-0 -> 440 | K16: 17633 | L16: =(K17-K16)*M16 -> 0 | M16: 80 | N16: =F16-F17 -> 0 | O16: =G16-G17 -> 0 | P16: =H16-H17 -> 0 | Q16: =I16-I17 -> 0 | R16: =J16-J17 -> 0 | S16: =(N16*$AC$2) -> 0 | T16: =(O16*$AD$2) -> 0 | U16: =(P16*$AE$2) -> 0 | V16: =Tabla1[[#This Row],[CONSUMO POL ANIONICO (KG)]] -> 0 | W16: =Tabla1[[#This Row],[CONSUMO POL CATIONICO (KG)]] -> 0 | X16: =(S16*1000)/L16 -> #DIV/0! | Y16: =(T16*1000)/L16 -> #DIV/0! | Z16: =(U16*1000)/L16 -> #DIV/0! | AA16: =(V16*1000)/L16 -> #DIV/0! | AB16: =(W16*1000)/L16 -> #DIV/0! | AC16: 1.3 | AD16: 1.325 | AE16: 1.25 | AF16: 2500 | AG16: 2500 | AH16: 830 | AI16: 2818 | AJ16: 6295 | AK16: 19050 | AL16: 22050 | AM16: =S16*AH16 -> 0 | AN16: =T16*AI16 -> 0 | AO16: =U16*AJ16 -> 0 | AP16: =V16*AK16 -> 0 | AQ16: =W16*AL16 -> 0 | AR16: =SUM(Tabla1[[#This Row],[COSTO OPERATIVO ACIDO]:[COSTO OPERATIVO CATIONICO]]) -> 0 | AS16: 3599 | AT16: =AR16/L16 -> #DIV/0! | AU16: =IFERROR(Tabla1[[#This Row],[CAUDAL TOTAL TRATADO GEM ]]/Tabla1[[#This Row],[CAUDAL DE TRATAMIENTO]],0) -> 0
A17: =+A16+1 -> 46118 | B17: 6 | C17: 6 (NOCHE) | D17: 16 | E17: FINAL TURNO 3 | F17: 2600 | G17: 5600 | H17: 4190 | I17: =+I16-0 -> 265 | J17: =+J16-0 -> 440 | K17: 17633 | L17: =(K18-K17)*M17 -> 160 | M17: 80 | N17: =F17-F18 -> 20 | O17: =G17-G18+4000 -> 110 | P17: =H17-H18 -> 0 | Q17: =I17-I18 -> 0 | R17: =J17-J18 -> 0 | S17: =(N17*$AC$2) -> 26 | T17: =(O17*$AD$2) -> 145.75 | U17: =(P17*$AE$2) -> 0 | V17: =Tabla1[[#This Row],[CONSUMO POL ANIONICO (KG)]] -> 0 | W17: =Tabla1[[#This Row],[CONSUMO POL CATIONICO (KG)]] -> 0 | X17: =(S17*1000)/L17 -> 162.5 | Y17: =(T17*1000)/L17 -> 910.9375 | Z17: =(U17*1000)/L17 -> 0 | AA17: =(V17*1000)/L17 -> 0 | AB17: =(W17*1000)/L17 -> 0 | AC17: 1.3 | AD17: 1.325 | AE17: 1.25 | AF17: 2500 | AG17: 2500 | AH17: 830 | AI17: 2818 | AJ17: 6295 | AK17: 19050 | AL17: 22050 | AM17: =S17*AH17 -> 21580 | AN17: =T17*AI17 -> 410723.5 | AO17: =U17*AJ17 -> 0 | AP17: =V17*AK17 -> 0 | AQ17: =W17*AL17 -> 0 | AR17: =SUM(Tabla1[[#This Row],[COSTO OPERATIVO ACIDO]:[COSTO OPERATIVO CATIONICO]]) -> 432303.5 | AS17: 3599 | AT17: =AR17/L17 -> 2701.8969 | AU17: =IFERROR(Tabla1[[#This Row],[CAUDAL TOTAL TRATADO GEM ]]/Tabla1[[#This Row],[CAUDAL DE TRATAMIENTO]],0) -> 2
A18: =+A17 -> 46118 | B18: 6 | C18: 7 (MAÑANA) | D18: 17 | E18: FINAL TURNO 1 | F18: 2580 | G18: 9490 | H18: 4190 | I18: =+I17-0 -> 265 | J18: =+J17-0 -> 440 | K18: 17635 | L18: =(K19-K18)*M18 -> 480 | M18: 80 | N18: =F18-F19 -> 20 | O18: =G18-G19-150 -> 140 | P18: =H18-H19 -> 40 | Q18: =I18-I19 -> 5 | R18: =J18-J19 -> 10 | S18: =(N18*$AC$2) -> 26 | T18: =(O18*$AD$2) -> 185.5 | U18: =(P18*$AE$2) -> 50 | V18: =Tabla1[[#This Row],[CONSUMO POL ANIONICO (KG)]] -> 5 | W18: =Tabla1[[#This Row],[CONSUMO POL CATIONICO (KG)]] -> 10 | X18: =(S18*1000)/L18 -> 54.166667 | Y18: =(T18*1000)/L18 -> 386.45833 | Z18: =(U18*1000)/L18 -> 104.16667 | AA18: =(V18*1000)/L18 -> 10.416667 | AB18: =(W18*1000)/L18 -> 20.833333 | AC18: 1.3 | AD18: 1.325 | AE18: 1.25 | AF18: 2500 | AG18: 2500 | AH18: 830 | AI18: 2818 | AJ18: 6295 | AK18: 19050 | AL18: 22050 | AM18: =S18*AH18 -> 21580 | AN18: =T18*AI18 -> 522739 | AO18: =U18*AJ18 -> 314750 | AP18: =V18*AK18 -> 95250 | AQ18: =W18*AL18 -> 220500 | AR18: =SUM(Tabla1[[#This Row],[COSTO OPERATIVO ACIDO]:[COSTO OPERATIVO CATIONICO]]) -> 1174819 | AS18: 3599 | AT18: =AR18/L18 -> 2447.5396 | AU18: =IFERROR(Tabla1[[#This Row],[CAUDAL TOTAL TRATADO GEM ]]/Tabla1[[#This Row],[CAUDAL DE TRATAMIENTO]],0) -> 6
A19: =+A18 -> 46118 | B19: 6 | C19: 3(TARDE) | D19: 18 | E19: FINAL TURNO 2 | F19: 2560 | G19: 9200 | H19: 4150 | I19: =+I18-5 -> 260 | J19: =+J18-10 -> 430 | K19: 17641 | L19: =(K20-K19)*M19 -> 400 | M19: 80 | N19: =F19-F20 -> 110 | O19: =G19-G20 -> 180 | P19: =H19-H20 -> 30 | Q19: =I19-I20 -> 0 | R19: =J19-J20 -> 5 | S19: =(N19*$AC$2) -> 143 | T19: =(O19*$AD$2) -> 238.5 | U19: =(P19*$AE$2) -> 37.5 | V19: =Tabla1[[#This Row],[CONSUMO POL ANIONICO (KG)]] -> 0 | W19: =Tabla1[[#This Row],[CONSUMO POL CATIONICO (KG)]] -> 5 | X19: =(S19*1000)/L19 -> 357.5 | Y19: =(T19*1000)/L19 -> 596.25 | Z19: =(U19*1000)/L19 -> 93.75 | AA19: =(V19*1000)/L19 -> 0 | AB19: =(W19*1000)/L19 -> 12.5 | AC19: 1.3 | AD19: 1.325 | AE19: 1.25 | AF19: 2500 | AG19: 2500 | AH19: 830 | AI19: 2818 | AJ19: 6295 | AK19: 19050 | AL19: 22050 | AM19: =S19*AH19 -> 118690 | AN19: =T19*AI19 -> 672093 | AO19: =U19*AJ19 -> 236062.5 | AP19: =V19*AK19 -> 0 | AQ19: =W19*AL19 -> 110250 | AR19: =SUM(Tabla1[[#This Row],[COSTO OPERATIVO ACIDO]:[COSTO OPERATIVO CATIONICO]]) -> 1137095.5 | AS19: 3599 | AT19: =AR19/L19 -> 2842.7387 | AU19: =IFERROR(Tabla1[[#This Row],[CAUDAL TOTAL TRATADO GEM ]]/Tabla1[[#This Row],[CAUDAL DE TRATAMIENTO]],0) -> 5
A20: =+A19+1 -> 46119 | B20: 7 | C20: 7 (NOCHE) | D20: 19 | E20: FINAL TURNO 3 | F20: 2450 | G20: 9020 | H20: 4120 | I20: =+I19-0 -> 260 | J20: =+J19-5 -> 425 | K20: 17646 | L20: =(K21-K20)*M20 -> 498 | M20: 83 | N20: =F20-F21 -> 50 | O20: =G20-G21 -> 90 | P20: =H20-H21 -> 20 | Q20: =I20-I21 -> 0 | R20: =J20-J21 -> 0 | S20: =(N20*$AC$2) -> 65 | T20: =(O20*$AD$2) -> 119.25 | U20: =(P20*$AE$2) -> 25 | V20: =Tabla1[[#This Row],[CONSUMO POL ANIONICO (KG)]] -> 0 | W20: =Tabla1[[#This Row],[CONSUMO POL CATIONICO (KG)]] -> 0 | X20: =(S20*1000)/L20 -> 130.52209 | Y20: =(T20*1000)/L20 -> 239.45783 | Z20: =(U20*1000)/L20 -> 50.200803 | AA20: =(V20*1000)/L20 -> 0 | AB20: =(W20*1000)/L20 -> 0 | AC20: 1.3 | AD20: 1.325 | AE20: 1.25 | AF20: 2500 | AG20: 2500 | AH20: 830 | AI20: 2818 | AJ20: 6295 | AK20: 19050 | AL20: 22050 | AM20: =S20*AH20 -> 53950 | AN20: =T20*AI20 -> 336046.5 | AO20: =U20*AJ20 -> 157375 | AP20: =V20*AK20 -> 0 | AQ20: =W20*AL20 -> 0 | AR20: =SUM(Tabla1[[#This Row],[COSTO OPERATIVO ACIDO]:[COSTO OPERATIVO CATIONICO]]) -> 547371.5 | AS20: 3599 | AT20: =AR20/L20 -> 1099.1396 | AU20: =IFERROR(Tabla1[[#This Row],[CAUDAL TOTAL TRATADO GEM ]]/Tabla1[[#This Row],[CAUDAL DE TRATAMIENTO]],0) -> 6
A21: =+A20 -> 46119 | B21: 7 | C21: 8 (MAÑANA) | D21: 20 | E21: FINAL TURNO 1 | F21: 2400 | G21: 8930 | H21: 4100 | I21: =+I20-0 -> 260 | J21: =+J20-0 -> 425 | K21: 17652 | L21: =(K22-K21)*M21 -> 249 | M21: 83 | N21: =F21-F22 -> 0 | O21: =G21-G22 -> 170 | P21: =H21-H22 -> 30 | Q21: =I21-I22 -> 0 | R21: =J21-J22 -> 5 | S21: =(N21*$AC$2) -> 0 | T21: =(O21*$AD$2) -> 225.25 | U21: =(P21*$AE$2) -> 37.5 | V21: =Tabla1[[#This Row],[CONSUMO POL ANIONICO (KG)]] -> 0 | W21: =Tabla1[[#This Row],[CONSUMO POL CATIONICO (KG)]] -> 5 | X21: =(S21*1000)/L21 -> 0 | Y21: =(T21*1000)/L21 -> 904.61847 | Z21: =(U21*1000)/L21 -> 150.60241 | AA21: =(V21*1000)/L21 -> 0 | AB21: =(W21*1000)/L21 -> 20.080321 | AC21: 1.3 | AD21: 1.325 | AE21: 1.25 | AF21: 2500 | AG21: 2500 | AH21: 830 | AI21: 2818 | AJ21: 6295 | AK21: 19050 | AL21: 22050 | AM21: =S21*AH21 -> 0 | AN21: =T21*AI21 -> 634754.5 | AO21: =U21*AJ21 -> 236062.5 | AP21: =V21*AK21 -> 0 | AQ21: =W21*AL21 -> 110250 | AR21: =SUM(Tabla1[[#This Row],[COSTO OPERATIVO ACIDO]:[COSTO OPERATIVO CATIONICO]]) -> 981067 | AS21: 3599 | AT21: =AR21/L21 -> 3940.0281 | AU21: =IFERROR(Tabla1[[#This Row],[CAUDAL TOTAL TRATADO GEM ]]/Tabla1[[#This Row],[CAUDAL DE TRATAMIENTO]],0) -> 3
A22: =+A21 -> 46119 | B22: 7 | C22: 3(TARDE) | D22: 21 | E22: FINAL TURNO 2 | F22: 2400 | G22: 8760 | H22: 4070 | I22: =+I21-0 -> 260 | J22: =+J21-5 -> 420 | K22: 17655 | L22: =(K23-K22)*M22 -> 332 | M22: 83 | N22: =F22-F23 -> 100 | O22: =G22-G23-150 -> 160 | P22: =H22-H23 -> 70 | Q22: =I22-I23 -> 5 | R22: =J22-J23 -> 5 | S22: =(N22*$AC$2) -> 130 | T22: =(O22*$AD$2) -> 212 | U22: =(P22*$AE$2) -> 87.5 | V22: =Tabla1[[#This Row],[CONSUMO POL ANIONICO (KG)]] -> 5 | W22: =Tabla1[[#This Row],[CONSUMO POL CATIONICO (KG)]] -> 5 | X22: =(S22*1000)/L22 -> 391.56627 | Y22: =(T22*1000)/L22 -> 638.55422 | Z22: =(U22*1000)/L22 -> 263.55422 | AA22: =(V22*1000)/L22 -> 15.060241 | AB22: =(W22*1000)/L22 -> 15.060241 | AC22: 1.3 | AD22: 1.325 | AE22: 1.25 | AF22: 2500 | AG22: 2500 | AH22: 830 | AI22: 2818 | AJ22: 6295 | AK22: 19050 | AL22: 22050 | AM22: =S22*AH22 -> 107900 | AN22: =T22*AI22 -> 597416 | AO22: =U22*AJ22 -> 550812.5 | AP22: =V22*AK22 -> 95250 | AQ22: =W22*AL22 -> 110250 | AR22: =SUM(Tabla1[[#This Row],[COSTO OPERATIVO ACIDO]:[COSTO OPERATIVO CATIONICO]]) -> 1461628.5 | AS22: 3599 | AT22: =AR22/L22 -> 4402.4955 | AU22: =IFERROR(Tabla1[[#This Row],[CAUDAL TOTAL TRATADO GEM ]]/Tabla1[[#This Row],[CAUDAL DE TRATAMIENTO]],0) -> 4
A23: =+A22+1 -> 46120 | B23: 8 | C23: 8 (NOCHE) | D23: 22 | E23: FINAL TURNO 3 | F23: 2300 | G23: 8450 | H23: 4000 | I23: =+I22-5 -> 255 | J23: =+J22-5 -> 415 | K23: 17659 | L23: =(K24-K23)*M23 -> 400 | M23: 80 | N23: =F23-F24 -> 150 | O23: =G23-G24 -> 110 | P23: =H23-H24 -> 60 | Q23: =I23-I24 -> 0 | R23: =J23-J24 -> 0 | S23: =(N23*$AC$2) -> 195 | T23: =(O23*$AD$2) -> 145.75 | U23: =(P23*$AE$2) -> 75 | V23: =Tabla1[[#This Row],[CONSUMO POL ANIONICO (KG)]] -> 0 | W23: =Tabla1[[#This Row],[CONSUMO POL CATIONICO (KG)]] -> 0 | X23: =(S23*1000)/L23 -> 487.5 | Y23: =(T23*1000)/L23 -> 364.375 | Z23: =(U23*1000)/L23 -> 187.5 | AA23: =(V23*1000)/L23 -> 0 | AB23: =(W23*1000)/L23 -> 0 | AC23: 1.3 | AD23: 1.325 | AE23: 1.25 | AF23: 2500 | AG23: 2500 | AH23: 830 | AI23: 2818 | AJ23: 6295 | AK23: 19050 | AL23: 22050 | AM23: =S23*AH23 -> 161850 | AN23: =T23*AI23 -> 410723.5 | AO23: =U23*AJ23 -> 472125 | AP23: =V23*AK23 -> 0 | AQ23: =W23*AL23 -> 0 | AR23: =SUM(Tabla1[[#This Row],[COSTO OPERATIVO ACIDO]:[COSTO OPERATIVO CATIONICO]]) -> 1044698.5 | AS23: 3599 | AT23: =AR23/L23 -> 2611.7463 | AU23: =IFERROR(Tabla1[[#This Row],[CAUDAL TOTAL TRATADO GEM ]]/Tabla1[[#This Row],[CAUDAL DE TRATAMIENTO]],0) -> 5
A24: =+A23 -> 46120 | B24: 8 | C24: 9 (MAÑANA) | D24: 23 | E24: FINAL TURNO 1 | F24: 2150 | G24: =+AVERAGE(G23,G25) -> 8340 | H24: 3940 | I24: =+I23-0 -> 255 | J24: =J23-0 -> 415 | K24: 17664 | L24: =(K25-K24)*M24 -> 240 | M24: 80 | N24: =F24-F25+2000 -> 130 | O24: =G24-G25 -> 110 | P24: =H24-H25+1000 -> 10 | Q24: =I24-I25 -> 0 | R24: =J24-J25 -> 5 | S24: =(N24*$AC$2) -> 169 | T24: =(O24*$AD$2) -> 145.75 | U24: =(P24*$AE$2) -> 12.5 | V24: =Tabla1[[#This Row],[CONSUMO POL ANIONICO (KG)]] -> 0 | W24: =Tabla1[[#This Row],[CONSUMO POL CATIONICO (KG)]] -> 5 | X24: =(S24*1000)/L24 -> 704.16667 | Y24: =(T24*1000)/L24 -> 607.29167 | Z24: =(U24*1000)/L24 -> 52.083333 | AA24: =(V24*1000)/L24 -> 0 | AB24: =(W24*1000)/L24 -> 20.833333 | AC24: 1.3 | AD24: 1.325 | AE24: 1.25 | AF24: 2500 | AG24: 2500 | AH24: 830 | AI24: 2818 | AJ24: 6295 | AK24: 19050 | AL24: 22050 | AM24: =S24*AH24 -> 140270 | AN24: =T24*AI24 -> 410723.5 | AO24: =U24*AJ24 -> 78687.5 | AP24: =V24*AK24 -> 0 | AQ24: =W24*AL24 -> 110250 | AR24: =SUM(Tabla1[[#This Row],[COSTO OPERATIVO ACIDO]:[COSTO OPERATIVO CATIONICO]]) -> 739931 | AS24: 3599 | AT24: =AR24/L24 -> 3083.0458 | AU24: =IFERROR(Tabla1[[#This Row],[CAUDAL TOTAL TRATADO GEM ]]/Tabla1[[#This Row],[CAUDAL DE TRATAMIENTO]],0) -> 3
A25: =+A24 -> 46120 | B25: 8 | C25: 3(TARDE) | D25: 24 | E25: FINAL TURNO 2 | F25: 4020 | G25: 8230 | H25: 4930 | I25: =+I24-0 -> 255 | J25: =+J24-5 -> 410 | K25: 17667 | L25: =(K26-K25)*M25 -> 560 | M25: 80 | N25: =F25-F26 -> 90 | O25: =G25-G26 -> 120 | P25: =H25-H26 -> 30 | Q25: =I25-I26 -> 5 | R25: =J25-J26 -> 5 | S25: =(N25*$AC$2) -> 117 | T25: =(O25*$AD$2) -> 159 | U25: =(P25*$AE$2) -> 37.5 | V25: =Tabla1[[#This Row],[CONSUMO POL ANIONICO (KG)]] -> 5 | W25: =Tabla1[[#This Row],[CONSUMO POL CATIONICO (KG)]] -> 5 | X25: =(S25*1000)/L25 -> 208.92857 | Y25: =(T25*1000)/L25 -> 283.92857 | Z25: =(U25*1000)/L25 -> 66.964286 | AA25: =(V25*1000)/L25 -> 8.9285714 | AB25: =(W25*1000)/L25 -> 8.9285714 | AC25: 1.3 | AD25: 1.325 | AE25: 1.25 | AF25: 2500 | AG25: 2500 | AH25: 830 | AI25: 2818 | AJ25: 6295 | AK25: 19050 | AL25: 22050 | AM25: =S25*AH25 -> 97110 | AN25: =T25*AI25 -> 448062 | AO25: =U25*AJ25 -> 236062.5 | AP25: =V25*AK25 -> 95250 | AQ25: =W25*AL25 -> 110250 | AR25: =SUM(Tabla1[[#This Row],[COSTO OPERATIVO ACIDO]:[COSTO OPERATIVO CATIONICO]]) -> 986734.5 | AS25: 3599 | AT25: =AR25/L25 -> 1762.0259 | AU25: =IFERROR(Tabla1[[#This Row],[CAUDAL TOTAL TRATADO GEM ]]/Tabla1[[#This Row],[CAUDAL DE TRATAMIENTO]],0) -> 7
A26: =+A25+1 -> 46121 | B26: 9 | C26: 9 (NOCHE) | D26: 25 | E26: FINAL TURNO 3 | F26: 3930 | G26: 8110 | H26: 4900 | I26: =+I25-5 -> 250 | J26: =+J25-5 -> 405 | K26: 17674 | L26: =(K27-K26)*M26 -> 560 | M26: 80 | N26: =F26-F27 -> 70 | O26: =G26-G27 -> 100 | P26: =H26-H27 -> 10 | Q26: =I26-I27 -> 5 | R26: =J26-J27 -> 5 | S26: =(N26*$AC$2) -> 91 | T26: =(O26*$AD$2) -> 132.5 | U26: =(P26*$AE$2) -> 12.5 | V26: =Tabla1[[#This Row],[CONSUMO POL ANIONICO (KG)]] -> 5 | W26: =Tabla1[[#This Row],[CONSUMO POL CATIONICO (KG)]] -> 5 | X26: =(S26*1000)/L26 -> 162.5 | Y26: =(T26*1000)/L26 -> 236.60714 | Z26: =(U26*1000)/L26 -> 22.321429 | AA26: =(V26*1000)/L26 -> 8.9285714 | AB26: =(W26*1000)/L26 -> 8.9285714 | AC26: 1.3 | AD26: 1.325 | AE26: 1.25 | AF26: 2500 | AG26: 2500 | AH26: 830 | AI26: 2818 | AJ26: 6295 | AK26: 19050 | AL26: 22050 | AM26: =S26*AH26 -> 75530 | AN26: =T26*AI26 -> 373385 | AO26: =U26*AJ26 -> 78687.5 | AP26: =V26*AK26 -> 95250 | AQ26: =W26*AL26 -> 110250 | AR26: =SUM(Tabla1[[#This Row],[COSTO OPERATIVO ACIDO]:[COSTO OPERATIVO CATIONICO]]) -> 733102.5 | AS26: 3599 | AT26: =AR26/L26 -> 1309.1116 | AU26: =IFERROR(Tabla1[[#This Row],[CAUDAL TOTAL TRATADO GEM ]]/Tabla1[[#This Row],[CAUDAL DE TRATAMIENTO]],0) -> 7
A27: =+A26 -> 46121 | B27: 9 | C27: 10 (MAÑANA) | D27: 26 | E27: FINAL TURNO 1 | F27: 3860 | G27: 8010 | H27: 4890 | I27: =+I26-5 -> 245 | J27: =+J26-5 -> 400 | K27: 17681 | L27: =(K28-K27)*M27 -> 240 | M27: 80 | N27: =F27-F28 -> 160 | O27: =G27-G28-50 -> 60 | P27: =H27-H28 -> 30 | Q27: =I27-I28 -> 5 | R27: =J27-J28 -> 5 | S27: =(N27*$AC$2) -> 208 | T27: =(O27*$AD$2) -> 79.5 | U27: =(P27*$AE$2) -> 37.5 | V27: =Tabla1[[#This Row],[CONSUMO POL ANIONICO (KG)]] -> 5 | W27: =Tabla1[[#This Row],[CONSUMO POL CATIONICO (KG)]] -> 5 | X27: =(S27*1000)/L27 -> 866.66667 | Y27: =(T27*1000)/L27 -> 331.25 | Z27: =(U27*1000)/L27 -> 156.25 | AA27: =(V27*1000)/L27 -> 20.833333 | AB27: =(W27*1000)/L27 -> 20.833333 | AC27: 1.3 | AD27: 1.325 | AE27: 1.25 | AF27: 2500 | AG27: 2500 | AH27: 830 | AI27: 2818 | AJ27: 6295 | AK27: 19050 | AL27: 22050 | AM27: =S27*AH27 -> 172640 | AN27: =T27*AI27 -> 224031 | AO27: =U27*AJ27 -> 236062.5 | AP27: =V27*AK27 -> 95250 | AQ27: =W27*AL27 -> 110250 | AR27: =SUM(Tabla1[[#This Row],[COSTO OPERATIVO ACIDO]:[COSTO OPERATIVO CATIONICO]]) -> 838233.5 | AS27: 3599 | AT27: =AR27/L27 -> 3492.6396 | AU27: =IFERROR(Tabla1[[#This Row],[CAUDAL TOTAL TRATADO GEM ]]/Tabla1[[#This Row],[CAUDAL DE TRATAMIENTO]],0) -> 3
A28: =+A27 -> 46121 | B28: 9 | C28: 3(TARDE) | D28: 27 | E28: FINAL TURNO 2 | F28: 3700 | G28: 7900 | H28: 4860 | I28: =+I27-5 -> 240 | J28: =+J27-5 -> 395 | K28: 17684 | L28: =(K29-K28)*M28 -> 480 | M28: 80 | N28: =F28-F29 -> 200 | O28: =G28-G29-50 -> 50 | P28: =H28-H29 -> 30 | Q28: =I28-I29 -> 0 | R28: =J28-J29 -> 5 | S28: =(N28*$AC$2) -> 260 | T28: =(O28*$AD$2) -> 66.25 | U28: =(P28*$AE$2) -> 37.5 | V28: =Tabla1[[#This Row],[CONSUMO POL ANIONICO (KG)]] -> 0 | W28: =Tabla1[[#This Row],[CONSUMO POL CATIONICO (KG)]] -> 5 | X28: =(S28*1000)/L28 -> 541.66667 | Y28: =(T28*1000)/L28 -> 138.02083 | Z28: =(U28*1000)/L28 -> 78.125 | AA28: =(V28*1000)/L28 -> 0 | AB28: =(W28*1000)/L28 -> 10.416667 | AC28: 1.3 | AD28: 1.325 | AE28: 1.25 | AF28: 2500 | AG28: 2500 | AH28: 830 | AI28: 2818 | AJ28: 6295 | AK28: 19050 | AL28: 22050 | AM28: =S28*AH28 -> 215800 | AN28: =T28*AI28 -> 186692.5 | AO28: =U28*AJ28 -> 236062.5 | AP28: =V28*AK28 -> 0 | AQ28: =W28*AL28 -> 110250 | AR28: =SUM(Tabla1[[#This Row],[COSTO OPERATIVO ACIDO]:[COSTO OPERATIVO CATIONICO]]) -> 748805 | AS28: 3599 | AT28: =AR28/L28 -> 1560.0104 | AU28: =IFERROR(Tabla1[[#This Row],[CAUDAL TOTAL TRATADO GEM ]]/Tabla1[[#This Row],[CAUDAL DE TRATAMIENTO]],0) -> 6
A29: =+A28+1 -> 46122 | B29: 10 | C29: 10 (NOCHE) | D29: 28 | E29: FINAL TURNO 3 | F29: 3500 | G29: 7800 | H29: 4830 | I29: =+I28-0 -> 240 | J29: =+J28-5 -> 390 | K29: 17690 | L29: =(K30-K29)*M29 -> 480 | M29: 80 | N29: =F29-F30 -> 10 | O29: =G29-G30 -> 10 | P29: =H29-H30 -> 60 | Q29: =I29-I30 -> 5 | R29: =J29-J30 -> 5 | S29: =(N29*$AC$2) -> 13 | T29: =(O29*$AD$2) -> 13.25 | U29: =(P29*$AE$2) -> 75 | V29: =Tabla1[[#This Row],[CONSUMO POL ANIONICO (KG)]] -> 5 | W29: =Tabla1[[#This Row],[CONSUMO POL CATIONICO (KG)]] -> 5 | X29: =(S29*1000)/L29 -> 27.083333 | Y29: =(T29*1000)/L29 -> 27.604167 | Z29: =(U29*1000)/L29 -> 156.25 | AA29: =(V29*1000)/L29 -> 10.416667 | AB29: =(W29*1000)/L29 -> 10.416667 | AC29: 1.3 | AD29: 1.325 | AE29: 1.25 | AF29: 2500 | AG29: 2500 | AH29: 830 | AI29: 2818 | AJ29: 6295 | AK29: 19050 | AL29: 22050 | AM29: =S29*AH29 -> 10790 | AN29: =T29*AI29 -> 37338.5 | AO29: =U29*AJ29 -> 472125 | AP29: =V29*AK29 -> 95250 | AQ29: =W29*AL29 -> 110250 | AR29: =SUM(Tabla1[[#This Row],[COSTO OPERATIVO ACIDO]:[COSTO OPERATIVO CATIONICO]]) -> 725753.5 | AS29: 3599 | AT29: =AR29/L29 -> 1511.9865 | AU29: =IFERROR(Tabla1[[#This Row],[CAUDAL TOTAL TRATADO GEM ]]/Tabla1[[#This Row],[CAUDAL DE TRATAMIENTO]],0) -> 6
A30: =+A29 -> 46122 | B30: 10 | C30: 11 (MAÑANA) | D30: 29 | E30: FINAL TURNO 1 | F30: 3490 | G30: 7790 | H30: 4770 | I30: =+I29-5 -> 235 | J30: =+J29-5 -> 385 | K30: 17696 | L30: =(K31-K30)*M30 -> 400 | M30: 80 | N30: =F30-F31-70 -> 80 | O30: =G30-G31 -> 190 | P30: =H30-H31 -> 20 | Q30: =I30-I31 -> 0 | R30: =J30-J31 -> 5 | S30: =(N30*$AC$2) -> 104 | T30: =(O30*$AD$2) -> 251.75 | U30: =(P30*$AE$2) -> 25 | V30: =Tabla1[[#This Row],[CONSUMO POL ANIONICO (KG)]] -> 0 | W30: =Tabla1[[#This Row],[CONSUMO POL CATIONICO (KG)]] -> 5 | X30: =(S30*1000)/L30 -> 260 | Y30: =(T30*1000)/L30 -> 629.375 | Z30: =(U30*1000)/L30 -> 62.5 | AA30: =(V30*1000)/L30 -> 0 | AB30: =(W30*1000)/L30 -> 12.5 | AC30: 1.3 | AD30: 1.325 | AE30: 1.25 | AF30: 2500 | AG30: 2500 | AH30: 830 | AI30: 2818 | AJ30: 6295 | AK30: 19050 | AL30: 22050 | AM30: =S30*AH30 -> 86320 | AN30: =T30*AI30 -> 709431.5 | AO30: =U30*AJ30 -> 157375 | AP30: =V30*AK30 -> 0 | AQ30: =W30*AL30 -> 110250 | AR30: =SUM(Tabla1[[#This Row],[COSTO OPERATIVO ACIDO]:[COSTO OPERATIVO CATIONICO]]) -> 1063376.5 | AS30: 3599 | AT30: =AR30/L30 -> 2658.4412 | AU30: =IFERROR(Tabla1[[#This Row],[CAUDAL TOTAL TRATADO GEM ]]/Tabla1[[#This Row],[CAUDAL DE TRATAMIENTO]],0) -> 5
A31: =+A30 -> 46122 | B31: 10 | C31: 3(TARDE) | D31: 30 | E31: FINAL TURNO 2 | F31: 3340 | G31: 7600 | H31: 4750 | I31: =+I30-0 -> 235 | J31: =+J30-5 -> 380 | K31: 17701 | L31: =(K32-K31)*M31 -> 640 | M31: 80 | N31: =F31-F32 -> 110 | O31: =G31-G32-210 -> 220 | P31: =H31-H32 -> 60 | Q31: =I31-I32 -> 5 | R31: =J31-J32 -> 5 | S31: =(N31*$AC$2) -> 143 | T31: =(O31*$AD$2) -> 291.5 | U31: =(P31*$AE$2) -> 75 | V31: =Tabla1[[#This Row],[CONSUMO POL ANIONICO (KG)]] -> 5 | W31: =Tabla1[[#This Row],[CONSUMO POL CATIONICO (KG)]] -> 5 | X31: =(S31*1000)/L31 -> 223.4375 | Y31: =(T31*1000)/L31 -> 455.46875 | Z31: =(U31*1000)/L31 -> 117.1875 | AA31: =(V31*1000)/L31 -> 7.8125 | AB31: =(W31*1000)/L31 -> 7.8125 | AC31: 1.3 | AD31: 1.325 | AE31: 1.25 | AF31: 2500 | AG31: 2500 | AH31: 830 | AI31: 2818 | AJ31: 6295 | AK31: 19050 | AL31: 22050 | AM31: =S31*AH31 -> 118690 | AN31: =T31*AI31 -> 821447 | AO31: =U31*AJ31 -> 472125 | AP31: =V31*AK31 -> 95250 | AQ31: =W31*AL31 -> 110250 | AR31: =SUM(Tabla1[[#This Row],[COSTO OPERATIVO ACIDO]:[COSTO OPERATIVO CATIONICO]]) -> 1617762 | AS31: 3599 | AT31: =AR31/L31 -> 2527.7531 | AU31: =IFERROR(Tabla1[[#This Row],[CAUDAL TOTAL TRATADO GEM ]]/Tabla1[[#This Row],[CAUDAL DE TRATAMIENTO]],0) -> 8
A32: =+A31+1 -> 46123 | B32: 11 | C32: 11 (NOCHE) | D32: 31 | E32: FINAL TURNO 3 | F32: 3230 | G32: 7170 | H32: 4690 | I32: =+I31-5 -> 230 | J32: =+J31-5 -> 375 | K32: 17709 | L32: =(K33-K32)*M32 -> 400 | M32: 80 | N32: =F32-F33 -> 110 | O32: =G32-G33 -> 100 | P32: =H32-H33 -> 90 | Q32: =I32-I33 -> 0 | R32: =J32-J33 -> 5 | S32: =(N32*$AC$2) -> 143 | T32: =(O32*$AD$2) -> 132.5 | U32: =(P32*$AE$2) -> 112.5 | V32: =Tabla1[[#This Row],[CONSUMO POL ANIONICO (KG)]] -> 0 | W32: =Tabla1[[#This Row],[CONSUMO POL CATIONICO (KG)]] -> 5 | X32: =(S32*1000)/L32 -> 357.5 | Y32: =(T32*1000)/L32 -> 331.25 | Z32: =(U32*1000)/L32 -> 281.25 | AA32: =(V32*1000)/L32 -> 0 | AB32: =(W32*1000)/L32 -> 12.5 | AC32: 1.3 | AD32: 1.325 | AE32: 1.25 | AF32: 2500 | AG32: 2500 | AH32: 830 | AI32: 2818 | AJ32: 6295 | AK32: 19050 | AL32: 22050 | AM32: =S32*AH32 -> 118690 | AN32: =T32*AI32 -> 373385 | AO32: =U32*AJ32 -> 708187.5 | AP32: =V32*AK32 -> 0 | AQ32: =W32*AL32 -> 110250 | AR32: =SUM(Tabla1[[#This Row],[COSTO OPERATIVO ACIDO]:[COSTO OPERATIVO CATIONICO]]) -> 1310512.5 | AS32: 3599 | AT32: =AR32/L32 -> 3276.2812 | AU32: =IFERROR(Tabla1[[#This Row],[CAUDAL TOTAL TRATADO GEM ]]/Tabla1[[#This Row],[CAUDAL DE TRATAMIENTO]],0) -> 5
A33: =+A32 -> 46123 | B33: 11 | C33: 12 (MAÑANA) | D33: 32 | E33: FINAL TURNO 1 | F33: 3120 | G33: 7070 | H33: 4600 | I33: =+I32-0 -> 230 | J33: =+J32-5 -> 370 | K33: 17714 | L33: =(K34-K33)*M33 -> 320 | M33: 80 | N33: =F33-F34 -> 20 | O33: =G33-G34 -> 170 | P33: =H33-H34 -> 50 | Q33: =I33-I34 -> 0 | R33: =J33-J34 -> 0 | S33: =(N33*$AC$2) -> 26 | T33: =(O33*$AD$2) -> 225.25 | U33: =(P33*$AE$2) -> 62.5 | V33: =Tabla1[[#This Row],[CONSUMO POL ANIONICO (KG)]] -> 0 | W33: =Tabla1[[#This Row],[CONSUMO POL CATIONICO (KG)]] -> 0 | X33: =(S33*1000)/L33 -> 81.25 | Y33: =(T33*1000)/L33 -> 703.90625 | Z33: =(U33*1000)/L33 -> 195.3125 | AA33: =(V33*1000)/L33 -> 0 | AB33: =(W33*1000)/L33 -> 0 | AC33: 1.3 | AD33: 1.325 | AE33: 1.25 | AF33: 2500 | AG33: 2500 | AH33: 830 | AI33: 2818 | AJ33: 6295 | AK33: 19050 | AL33: 22050 | AM33: =S33*AH33 -> 21580 | AN33: =T33*AI33 -> 634754.5 | AO33: =U33*AJ33 -> 393437.5 | AP33: =V33*AK33 -> 0 | AQ33: =W33*AL33 -> 0 | AR33: =SUM(Tabla1[[#This Row],[COSTO OPERATIVO ACIDO]:[COSTO OPERATIVO CATIONICO]]) -> 1049772 | AS33: 3599 | AT33: =AR33/L33 -> 3280.5375 | AU33: =IFERROR(Tabla1[[#This Row],[CAUDAL TOTAL TRATADO GEM ]]/Tabla1[[#This Row],[CAUDAL DE TRATAMIENTO]],0) -> 4
A34: =+A33 -> 46123 | B34: 11 | C34: 3(TARDE) | D34: 33 | E34: FINAL TURNO 2 | F34: 3100 | G34: 6900 | H34: 4550 | I34: =+I33-0 -> 230 | J34: =+J33-0 -> 370 | K34: 17718 | L34: =(K35-K34)*M34 -> 320 | M34: 80 | N34: =F34-F35 -> 50 | O34: =G34-G35 -> 100 | P34: =H34-H35 -> 50 | Q34: =I34-I35 -> 0 | R34: =J34-J35 -> 5 | S34: =(N34*$AC$2) -> 65 | T34: =(O34*$AD$2) -> 132.5 | U34: =(P34*$AE$2) -> 62.5 | V34: =Tabla1[[#This Row],[CONSUMO POL ANIONICO (KG)]] -> 0 | W34: =Tabla1[[#This Row],[CONSUMO POL CATIONICO (KG)]] -> 5 | X34: =(S34*1000)/L34 -> 203.125 | Y34: =(T34*1000)/L34 -> 414.0625 | Z34: =(U34*1000)/L34 -> 195.3125 | AA34: =(V34*1000)/L34 -> 0 | AB34: =(W34*1000)/L34 -> 15.625 | AC34: 1.3 | AD34: 1.325 | AE34: 1.25 | AF34: 2500 | AG34: 2500 | AH34: 830 | AI34: 2818 | AJ34: 6295 | AK34: 19050 | AL34: 22050 | AM34: =S34*AH34 -> 53950 | AN34: =T34*AI34 -> 373385 | AO34: =U34*AJ34 -> 393437.5 | AP34: =V34*AK34 -> 0 | AQ34: =W34*AL34 -> 110250 | AR34: =SUM(Tabla1[[#This Row],[COSTO OPERATIVO ACIDO]:[COSTO OPERATIVO CATIONICO]]) -> 931022.5 | AS34: 3599 | AT34: =AR34/L34 -> 2909.4453 | AU34: =IFERROR(Tabla1[[#This Row],[CAUDAL TOTAL TRATADO GEM ]]/Tabla1[[#This Row],[CAUDAL DE TRATAMIENTO]],0) -> 4
A35: =+A34+1 -> 46124 | B35: 12 | C35: 12 (NOCHE) | D35: 34 | E35: FINAL TURNO 3 | F35: 3050 | G35: 6800 | H35: 4500 | I35: =+I34-0 -> 230 | J35: =+J34-5 -> 365 | K35: 17722 | L35: =(K36-K35)*M35 -> 0 | M35: 80 | N35: =F35-F36 -> 0 | O35: =G35-G36 -> 0 | P35: =H35-H36 -> 0 | Q35: =I35-I36 -> 0 | R35: =J35-J36 -> 0 | S35: =(N35*$AC$2) -> 0 | T35: =(O35*$AD$2) -> 0 | U35: =(P35*$AE$2) -> 0 | V35: =Tabla1[[#This Row],[CONSUMO POL ANIONICO (KG)]] -> 0 | W35: =Tabla1[[#This Row],[CONSUMO POL CATIONICO (KG)]] -> 0 | X35: =(S35*1000)/L35 -> #DIV/0! | Y35: =(T35*1000)/L35 -> #DIV/0! | Z35: =(U35*1000)/L35 -> #DIV/0! | AA35: =(V35*1000)/L35 -> #DIV/0! | AB35: =(W35*1000)/L35 -> #DIV/0! | AC35: 1.3 | AD35: 1.325 | AE35: 1.25 | AF35: 2500 | AG35: 2500 | AH35: 830 | AI35: 2818 | AJ35: 6295 | AK35: 19050 | AL35: 22050 | AM35: =S35*AH35 -> 0 | AN35: =T35*AI35 -> 0 | AO35: =U35*AJ35 -> 0 | AP35: =V35*AK35 -> 0 | AQ35: =W35*AL35 -> 0 | AR35: =SUM(Tabla1[[#This Row],[COSTO OPERATIVO ACIDO]:[COSTO OPERATIVO CATIONICO]]) -> 0 | AS35: 3599 | AT35: =AR35/L35 -> #DIV/0! | AU35: =IFERROR(Tabla1[[#This Row],[CAUDAL TOTAL TRATADO GEM ]]/Tabla1[[#This Row],[CAUDAL DE TRATAMIENTO]],0) -> 0
A36: =+A35 -> 46124 | B36: 12 | C36: 13 (MAÑANA) | D36: 35 | E36: FINAL TURNO 1 | F36: 3050 | G36: 6800 | H36: 4500 | I36: =+I35-0 -> 230 | J36: =+J35-0 -> 365 | K36: 17722 | L36: =(K37-K36)*M36 -> 0 | M36: 80 | N36: =F36-F37 -> 0 | O36: =G36-G37 -> 0 | P36: =H36-H37 -> 0 | Q36: =I36-I37 -> 0 | R36: =J36-J37 -> 0 | S36: =(N36*$AC$2) -> 0 | T36: =(O36*$AD$2) -> 0 | U36: =(P36*$AE$2) -> 0 | V36: =Tabla1[[#This Row],[CONSUMO POL ANIONICO (KG)]] -> 0 | W36: =Tabla1[[#This Row],[CONSUMO POL CATIONICO (KG)]] -> 0 | X36: =(S36*1000)/L36 -> #DIV/0! | Y36: =(T36*1000)/L36 -> #DIV/0! | Z36: =(U36*1000)/L36 -> #DIV/0! | AA36: =(V36*1000)/L36 -> #DIV/0! | AB36: =(W36*1000)/L36 -> #DIV/0! | AC36: 1.3 | AD36: 1.325 | AE36: 1.25 | AF36: 2500 | AG36: 2500 | AH36: 830 | AI36: 2818 | AJ36: 6295 | AK36: 19050 | AL36: 22050 | AM36: =S36*AH36 -> 0 | AN36: =T36*AI36 -> 0 | AO36: =U36*AJ36 -> 0 | AP36: =V36*AK36 -> 0 | AQ36: =W36*AL36 -> 0 | AR36: =SUM(Tabla1[[#This Row],[COSTO OPERATIVO ACIDO]:[COSTO OPERATIVO CATIONICO]]) -> 0 | AS36: 3599 | AT36: =AR36/L36 -> #DIV/0! | AU36: =IFERROR(Tabla1[[#This Row],[CAUDAL TOTAL TRATADO GEM ]]/Tabla1[[#This Row],[CAUDAL DE TRATAMIENTO]],0) -> 0
A37: =+A36 -> 46124 | B37: 12 | C37: 3(TARDE) | D37: 36 | E37: FINAL TURNO 2 | F37: 3050 | G37: 6800 | H37: 4500 | I37: =+I36-0 -> 230 | J37: =+J36-0 -> 365 | K37: 17722 | L37: =(K38-K37)*M37 -> 0 | M37: 80 | N37: =F37-F38 -> 0 | O37: =G37-G38 -> 0 | P37: =H37-H38 -> 0 | Q37: =I37-I38 -> 0 | R37: =J37-J38 -> 0 | S37: =(N37*$AC$2) -> 0 | T37: =(O37*$AD$2) -> 0 | U37: =(P37*$AE$2) -> 0 | V37: =Tabla1[[#This Row],[CONSUMO POL ANIONICO (KG)]] -> 0 | W37: =Tabla1[[#This Row],[CONSUMO POL CATIONICO (KG)]] -> 0 | X37: =(S37*1000)/L37 -> #DIV/0! | Y37: =(T37*1000)/L37 -> #DIV/0! | Z37: =(U37*1000)/L37 -> #DIV/0! | AA37: =(V37*1000)/L37 -> #DIV/0! | AB37: =(W37*1000)/L37 -> #DIV/0! | AC37: 1.3 | AD37: 1.325 | AE37: 1.25 | AF37: 2500 | AG37: 2500 | AH37: 830 | AI37: 2818 | AJ37: 6295 | AK37: 19050 | AL37: 22050 | AM37: =S37*AH37 -> 0 | AN37: =T37*AI37 -> 0 | AO37: =U37*AJ37 -> 0 | AP37: =V37*AK37 -> 0 | AQ37: =W37*AL37 -> 0 | AR37: =SUM(Tabla1[[#This Row],[COSTO OPERATIVO ACIDO]:[COSTO OPERATIVO CATIONICO]]) -> 0 | AS37: 3599 | AT37: =AR37/L37 -> #DIV/0! | AU37: =IFERROR(Tabla1[[#This Row],[CAUDAL TOTAL TRATADO GEM ]]/Tabla1[[#This Row],[CAUDAL DE TRATAMIENTO]],0) -> 0
