Workbook
Name SegmentaciónDeDatos_DIA: #N/A
Name SegmentaciónDeDatos_FECHA1: #N/A
Name SegmentaciónDeDatos_FECHA2: #N/A

Sheet INVENTARIO Y CONSUMO GEM  
A1: FECHA | B1: DIA | C1: ANALISIS TURNO | D1: # TURNO | E1: DILIGENCIAR BITACORA | F1: FINAL ACIDO (L) | G1: FINAL COAGULANTE (L) | H1: FINAL DECOLORANTE (L) | I1: FINAL POL ANIONICO (KG) | J1: FINAL POL CATIONICO (KG) | K1: Lectura Horometro INICIAL (06:00) | L1: CAUDAL TOTAL TRATADO GEM | M1: CAUDAL DE TRATAMIENTO | N1: CONSUMO LITROS ACIDO (L) | O1: CONSUMO LITROS COAGULANTE (L) | P1: CONSUMO LITROS DECOLORANTE (L) | Q1: CONSUMO POL ANIONICO (KG) | R1: CONSUMO POL CATIONICO (KG) | S1: KG ACIDO | T1: KG COAGULANTE | U1: KG DECOLORANTE | V1: KG POL ANIONICO | W1: KG POL CATIONICO | X1: PPM ACIDO | Y1: PPM COAGULANTE | Z1: PPM DECOLORANTE | AA1: PPM POL ANIONICO | AB1: PPM POL CATIONICO | AC1: DENSIDAD ACIDO | AD1: DENSIDAD COAGULANTE | AE1: DENSIDAD DECOLORANTE | AF1: DENSIDAD ANIONICO | AG1: DENSIDAD CATIONICO | AH1: PRECIO (KG) ACIDO | AI1: PRECIO (KG) COAGULANTE | AJ1: PRECIO (KG) DECOLORANTE | AK1: PRECIO (KG) ANIONICO | AL1: PRECIO (KG) CATIONICO | AM1: COSTO OPERATIVO ACIDO | AN1: COSTO OPERATIVO COAGULANTE | AO1: COSTO OPERATIVO DECOLORANTE | AP1: COSTO OPERATIVO ANIONICO | AQ1: COSTO OPERATIVO CATIONICO | AR1: COSTO QUIMICA | AS1: LIMITE INDICADOR M3 | AT1: $ m3 | AU1: HORAS DE OPERACIÓN
A2: 46054 | B2: 1 | C2: 1 (NOCHE) | D2: 1 | E2: FINAL TURNO 3 | F2: 4360 | G2: 6480 | H2: 1510 | I2: 165 | J2: 60 | K2: 16839 | L2: 0 | M2: 75 | N2: 0 | O2: 0 | P2: 0 | Q2: 0 | R2: 0 | S2: 0 | T2: 0 | U2: 0 | V2: 0 | W2: 0 | X2: #DIV/0! | Y2: #DIV/0! | Z2: #DIV/0! | AA2: #DIV/0! | AB2: #DIV/0! | AC2: 1.3 | AD2: 1.325 | AE2: 1.25 | AF2: 2500 | AG2: 2500 | AH2: 830 | AI2: 2900 | AJ2: 6295 | AK2: 19050 | AL2: 22050 | AM2: 0 | AN2: 0 | AO2: 0 | AP2: 0 | AQ2: 0 | AR2: 0 | AS2: 5250 | AT2: #DIV/0! | AU2: =IFERROR(Tabla1[[#This Row],[CAUDAL TOTAL TRATADO GEM ]]/Tabla1[[#This Row],[CAUDAL DE TRATAMIENTO]],0) -> 0
A3: 46054 | B3: 1 | C3: 2 (MAÑANA) | D3: 2 | E3: FINAL TURNO 1 | F3: 4360 | G3: 6480 | H3: 1510 | I3: 165 | J3: 60 | K3: 16839 | L3: 0 | M3: 75 | N3: 0 | O3: 0 | P3: 0 | Q3: 0 | R3: 0 | S3: 0 | T3: 0 | U3: 0 | V3: 0 | W3: 0 | X3: #DIV/0! | Y3: #DIV/0! | Z3: #DIV/0! | AA3: #DIV/0! | AB3: #DIV/0! | AC3: 1.3 | AD3: 1.325 | AE3: 1.25 | AF3: 2500 | AG3: 2500 | AH3: 830 | AI3: 2900 | AJ3: 6295 | AK3: 19050 | AL3: 22050 | AM3: 0 | AN3: 0 | AO3: 0 | AP3: 0 | AQ3: 0 | AR3: 0 | AS3: 5250 | AT3: #DIV/0! | AU3: =IFERROR(Tabla1[[#This Row],[CAUDAL TOTAL TRATADO GEM ]]/Tabla1[[#This Row],[CAUDAL DE TRATAMIENTO]],0) -> 0
A4: 46054 | B4: 1 | C4: 3(TARDE) | D4: 3 | E4: FINAL TURNO 2 | F4: 4360 | G4: 6480 | H4: 1510 | I4: 165 | J4: 60 | K4: 16839 | L4: 0 | M4: 75 | N4: 0 | O4: 0 | P4: 0 | Q4: 0 | R4: 0 | S4: 0 | T4: 0 | U4: 0 | V4: 0 | W4: 0 | X4: #DIV/0! | Y4: #DIV/0! | Z4: #DIV/0! | AA4: #DIV/0! | AB4: #DIV/0! | AC4: 1.3 | AD4: 1.325 | AE4: 1.25 | AF4: 2500 | AG4: 2500 | AH4: 830 | AI4: 2900 | AJ4: 6295 | AK4: 19050 | AL4: 22050 | AM4: 0 | AN4: 0 | AO4: 0 | AP4: 0 | AQ4: 0 | AR4: 0 | AS4: 5250 | AT4: #DIV/0! | AU4: =IFERROR(Tabla1[[#This Row],[CAUDAL TOTAL TRATADO GEM ]]/Tabla1[[#This Row],[CAUDAL DE TRATAMIENTO]],0) -> 0
A5: 46055 | B5: 2 | C5: 2 (NOCHE) | D5: 4 | E5: FINAL TURNO 3 | F5: 4360 | G5: 6480 | H5: 1510 | I5: 165 | J5: 60 | K5: 16839 | L5: 225 | M5: 75 | N5: 70 | O5: 300 | P5: 30 | Q5: 0 | R5: 5 | S5: 91 | T5: 397.5 | U5: 37.5 | V5: 0 | W5: 5 | X5: 404.44444 | Y5: 1766.6667 | Z5: 166.66667 | AA5: 0 | AB5: 22.222222 | AC5: 1.3 | AD5: 1.325 | AE5: 1.25 | AF5: 2500 | AG5: 2500 | AH5: 830 | AI5: 2900 | AJ5: 6295 | AK5: 19050 | AL5: 22050 | AM5: 75530 | AN5: 1152750 | AO5: 236062.5 | AP5: 0 | AQ5: 110250 | AR5: 1574592.5 | AS5: 5250 | AT5: 6998.1889 | AU5: =IFERROR(Tabla1[[#This Row],[CAUDAL TOTAL TRATADO GEM ]]/Tabla1[[#This Row],[CAUDAL DE TRATAMIENTO]],0) -> 3
A6: 46055 | B6: 2 | C6: 3 (MAÑANA) | D6: 5 | E6: FINAL TURNO 1 | F6: 4290 | G6: 6180 | H6: 1480 | I6: 165 | J6: 55 | K6: 16842 | L6: 300 | M6: 75 | N6: 340 | O6: 340 | P6: 100 | Q6: 0 | R6: 5 | S6: 442 | T6: 450.5 | U6: 125 | V6: 0 | W6: 5 | X6: 1473.3333 | Y6: 1501.6667 | Z6: 416.66667 | AA6: 0 | AB6: 16.666667 | AC6: 1.3 | AD6: 1.325 | AE6: 1.25 | AF6: 2500 | AG6: 2500 | AH6: 830 | AI6: 2900 | AJ6: 6295 | AK6: 19050 | AL6: 22050 | AM6: 366860 | AN6: 1306450 | AO6: 786875 | AP6: 0 | AQ6: 110250 | AR6: 2570435 | AS6: 5250 | AT6: 8568.1167 | AU6: =IFERROR(Tabla1[[#This Row],[CAUDAL TOTAL TRATADO GEM ]]/Tabla1[[#This Row],[CAUDAL DE TRATAMIENTO]],0) -> 4
A7: 46055 | B7: 2 | C7: 3(TARDE) | D7: 6 | E7: FINAL TURNO 2 | F7: 3950 | G7: 5840 | H7: 1380 | I7: 165 | J7: 50 | K7: 16846 | L7: 600 | M7: 75 | N7: 30 | O7: 180 | P7: 40 | Q7: 2.5 | R7: 5 | S7: 39 | T7: 238.5 | U7: 50 | V7: 2.5 | W7: 5 | X7: 65 | Y7: 397.5 | Z7: 83.333333 | AA7: 4.1666667 | AB7: 8.3333333 | AC7: 1.3 | AD7: 1.325 | AE7: 1.25 | AF7: 2500 | AG7: 2500 | AH7: 830 | AI7: 2900 | AJ7: 6295 | AK7: 19050 | AL7: 22050 | AM7: 32370 | AN7: 691650 | AO7: 314750 | AP7: 47625 | AQ7: 110250 | AR7: 1196645 | AS7: 5250 | AT7: 1994.4083 | AU7: =IFERROR(Tabla1[[#This Row],[CAUDAL TOTAL TRATADO GEM ]]/Tabla1[[#This Row],[CAUDAL DE TRATAMIENTO]],0) -> 8
A8: 46056 | B8: 3 | C8: 3 (NOCHE) | D8: 7 | E8: FINAL TURNO 3 | F8: 3920 | G8: 5660 | H8: 1340 | I8: 162.5 | J8: 45 | K8: 16854 | L8: 600 | M8: 75 | N8: 30 | O8: 180 | P8: 40 | Q8: 2.5 | R8: 5 | S8: 39 | T8: 238.5 | U8: 50 | V8: 2.5 | W8: 5 | X8: 65 | Y8: 397.5 | Z8: 83.333333 | AA8: 4.1666667 | AB8: 8.3333333 | AC8: 1.3 | AD8: 1.325 | AE8: 1.25 | AF8: 2500 | AG8: 2500 | AH8: 830 | AI8: 2900 | AJ8: 6295 | AK8: 19050 | AL8: 22050 | AM8: 32370 | AN8: 691650 | AO8: 314750 | AP8: 47625 | AQ8: 110250 | AR8: 1196645 | AS8: 5250 | AT8: 1994.4083 | AU8: =IFERROR(Tabla1[[#This Row],[CAUDAL TOTAL TRATADO GEM ]]/Tabla1[[#This Row],[CAUDAL DE TRATAMIENTO]],0) -> 8
A9: 46056 | B9: 3 | C9: 4 (MAÑANA) | D9: 8 | E9: FINAL TURNO 1 | F9: 3890 | G9: 5480 | H9: 1300 | I9: 160 | J9: 40 | K9: 16862 | L9: 525 | M9: 75 | N9: 210 | O9: 340 | P9: 120 | Q9: 5 | R9: 5 | S9: 273 | T9: 450.5 | U9: 150 | V9: 5 | W9: 5 | X9: 520 | Y9: 858.09524 | Z9: 285.71429 | AA9: 9.5238095 | AB9: 9.5238095 | AC9: 1.3 | AD9: 1.325 | AE9: 1.25 | AF9: 2500 | AG9: 2500 | AH9: 830 | AI9: 2900 | AJ9: 6295 | AK9: 19050 | AL9: 22050 | AM9: 226590 | AN9: 1306450 | AO9: 944250 | AP9: 95250 | AQ9: 110250 | AR9: 2682790 | AS9: 5250 | AT9: 5110.0762 | AU9: =IFERROR(Tabla1[[#This Row],[CAUDAL TOTAL TRATADO GEM ]]/Tabla1[[#This Row],[CAUDAL DE TRATAMIENTO]],0) -> 7
A10: 46056 | B10: 3 | C10: 3(TARDE) | D10: 9 | E10: FINAL TURNO 2 | F10: 3680 | G10: 5140 | H10: 1180 | I10: 155 | J10: 35 | K10: 16869 | L10: 525 | M10: 75 | N10: 310 | O10: 240 | P10: 130 | Q10: 0 | R10: 0 | S10: 403 | T10: 318 | U10: 162.5 | V10: 0 | W10: 0 | X10: 767.61905 | Y10: 605.71429 | Z10: 309.52381 | AA10: 0 | AB10: 0 | AC10: 1.3 | AD10: 1.325 | AE10: 1.25 | AF10: 2500 | AG10: 2500 | AH10: 830 | AI10: 2900 | AJ10: 6295 | AK10: 19050 | AL10: 22050 | AM10: 334490 | AN10: 922200 | AO10: 1022937.5 | AP10: 0 | AQ10: 0 | AR10: 2279627.5 | AS10: 5250 | AT10: 4342.1476 | AU10: =IFERROR(Tabla1[[#This Row],[CAUDAL TOTAL TRATADO GEM ]]/Tabla1[[#This Row],[CAUDAL DE TRATAMIENTO]],0) -> 7
A11: 46057 | B11: 4 | C11: 4 (NOCHE) | D11: 10 | E11: FINAL TURNO 3 | F11: 3370 | G11: 4900 | H11: 1050 | I11: 155 | J11: 30 | K11: 16876 | L11: 525 | M11: 75 | N11: 280 | O11: 210 | P11: 110 | Q11: 0 | R11: 0 | S11: 364 | T11: 278.25 | U11: 137.5 | V11: 0 | W11: 0 | X11: 693.33333 | Y11: 530 | Z11: 261.90476 | AA11: 0 | AB11: 0 | AC11: 1.3 | AD11: 1.325 | AE11: 1.25 | AF11: 2500 | AG11: 2500 | AH11: 830 | AI11: 2900 | AJ11: 6295 | AK11: 19050 | AL11: 22050 | AM11: 302120 | AN11: 806925 | AO11: 865562.5 | AP11: 0 | AQ11: 0 | AR11: 1974607.5 | AS11: 5250 | AT11: 3761.1571 | AU11: =IFERROR(Tabla1[[#This Row],[CAUDAL TOTAL TRATADO GEM ]]/Tabla1[[#This Row],[CAUDAL DE TRATAMIENTO]],0) -> 7
A12: 46057 | B12: 4 | C12: 5 (MAÑANA) | D12: 11 | E12: FINAL TURNO 1 | F12: 3090 | G12: 4690 | H12: 940 | I12: 150 | J12: 25 | K12: 16883 | L12: 525 | M12: 75 | N12: 280 | O12: 280 | P12: 40 | Q12: 0 | R12: 0 | S12: 364 | T12: 371 | U12: 50 | V12: 0 | W12: 0 | X12: 693.33333 | Y12: 706.66667 | Z12: 95.238095 | AA12: 0 | AB12: 0 | AC12: 1.3 | AD12: 1.325 | AE12: 1.25 | AF12: 2500 | AG12: 2500 | AH12: 830 | AI12: 2900 | AJ12: 6295 | AK12: 19050 | AL12: 22050 | AM12: 302120 | AN12: 1075900 | AO12: 314750 | AP12: 0 | AQ12: 0 | AR12: 1692770 | AS12: 5250 | AT12: 3224.3238 | AU12: =IFERROR(Tabla1[[#This Row],[CAUDAL TOTAL TRATADO GEM ]]/Tabla1[[#This Row],[CAUDAL DE TRATAMIENTO]],0) -> 7
A13: 46057 | B13: 4 | C13: 3(TARDE) | D13: 12 | E13: FINAL TURNO 2 | F13: 2810 | G13: 4410 | H13: 900 | I13: 150 | J13: 65 | K13: 16890 | L13: 525 | M13: 75 | N13: 310 | O13: 290 | P13: 100 | Q13: 0 | R13: 0 | S13: 403 | T13: 384.25 | U13: 125 | V13: 0 | W13: 0 | X13: 767.61905 | Y13: 731.90476 | Z13: 238.09524 | AA13: 0 | AB13: 0 | AC13: 1.3 | AD13: 1.325 | AE13: 1.25 | AF13: 2500 | AG13: 2500 | AH13: 830 | AI13: 2900 | AJ13: 6295 | AK13: 19050 | AL13: 22050 | AM13: 334490 | AN13: 1114325 | AO13: 786875 | AP13: 0 | AQ13: 0 | AR13: 2235690 | AS13: 5250 | AT13: 4258.4571 | AU13: =IFERROR(Tabla1[[#This Row],[CAUDAL TOTAL TRATADO GEM ]]/Tabla1[[#This Row],[CAUDAL DE TRATAMIENTO]],0) -> 7
A14: 46058 | B14: 5 | C14: 5 (NOCHE) | D14: 13 | E14: FINAL TURNO 3 | F14: 2500 | G14: 4120 | H14: 800 | I14: 145 | J14: 60 | K14: 16897 | L14: 600 | M14: 75 | N14: 110 | O14: 120 | P14: 80 | Q14: 0 | R14: 0 | S14: 143 | T14: 159 | U14: 100 | V14: 0 | W14: 0 | X14: 238.33333 | Y14: 265 | Z14: 166.66667 | AA14: 0 | AB14: 0 | AC14: 1.3 | AD14: 1.325 | AE14: 1.25 | AF14: 2500 | AG14: 2500 | AH14: 830 | AI14: 2900 | AJ14: 6295 | AK14: 19050 | AL14: 22050 | AM14: 118690 | AN14: 461100 | AO14: 629500 | AP14: 0 | AQ14: 0 | AR14: 1209290 | AS14: 5250 | AT14: 2015.4833 | AU14: =IFERROR(Tabla1[[#This Row],[CAUDAL TOTAL TRATADO GEM ]]/Tabla1[[#This Row],[CAUDAL DE TRATAMIENTO]],0) -> 8
A15: 46058 | B15: 5 | C15: 6 (MAÑANA) | D15: 14 | E15: FINAL TURNO 1 | F15: 2390 | G15: 4000 | H15: 720 | I15: 145 | J15: 55 | K15: 16905 | L15: 525 | M15: 75 | N15: 90 | O15: 260 | P15: 70 | Q15: 5 | R15: 5 | S15: 117 | T15: 344.5 | U15: 87.5 | V15: 5 | W15: 5 | X15: 222.85714 | Y15: 656.19048 | Z15: 166.66667 | AA15: 9.5238095 | AB15: 9.5238095 | AC15: 1.3 | AD15: 1.325 | AE15: 1.25 | AF15: 2500 | AG15: 2500 | AH15: 830 | AI15: 2900 | AJ15: 6295 | AK15: 19050 | AL15: 22050 | AM15: 97110 | AN15: 999050 | AO15: 550812.5 | AP15: 95250 | AQ15: 110250 | AR15: 1852472.5 | AS15: 5250 | AT15: 3528.519 | AU15: =IFERROR(Tabla1[[#This Row],[CAUDAL TOTAL TRATADO GEM ]]/Tabla1[[#This Row],[CAUDAL DE TRATAMIENTO]],0) -> 7
A16: 46058 | B16: 5 | C16: 3(TARDE) | D16: 15 | E16: FINAL TURNO 2 | F16: 2300 | G16: 3740 | H16: 650 | I16: 140 | J16: 50 | K16: 16912 | L16: 375 | M16: 75 | N16: 100 | O16: 150 | P16: 50 | Q16: 5 | R16: 5 | S16: 130 | T16: 198.75 | U16: 62.5 | V16: 5 | W16: 5 | X16: 346.66667 | Y16: 530 | Z16: 166.66667 | AA16: 13.333333 | AB16: 13.333333 | AC16: 1.3 | AD16: 1.325 | AE16: 1.25 | AF16: 2500 | AG16: 2500 | AH16: 830 | AI16: 2900 | AJ16: 6295 | AK16: 19050 | AL16: 22050 | AM16: 107900 | AN16: 576375 | AO16: 393437.5 | AP16: 95250 | AQ16: 110250 | AR16: 1283212.5 | AS16: 5250 | AT16: 3421.9 | AU16: =IFERROR(Tabla1[[#This Row],[CAUDAL TOTAL TRATADO GEM ]]/Tabla1[[#This Row],[CAUDAL DE TRATAMIENTO]],0) -> 5
... A21: 46060 | B21: 7 | C21: 8 (MAÑANA) | D21: 20 | E21: FINAL TURNO 1 | F21: 1750 | G21: 6300 | H21: 330 | I21: 125 | J21: 120 | K21: 16943 | L21: 300 | M21: 75 | N21: 0 | O21: 0 | P21: 0 | Q21: 5 | R21: 5 | S21: 0 | T21: 0 | U21: 0 | V21: 5 | W21: 5 | X21: 0 | Y21: 0 | Z21: 0 | AA21: 16.666667 | AB21: 16.666667 | AC21: 1.3 | AD21: 1.325 | AE21: 1.25 | AF21: 2500 | AG21: 2500 | AH21: 830 | AI21: 2900 | AJ21: 6295 | AK21: 19050 | AL21: 22050 | AM21: 0 | AN21: 0 | AO21: 0 | AP21: 95250 | AQ21: 110250 | AR21: 205500 | AS21: 5250 | AT21: 685 | AU21: =IFERROR(Tabla1[[#This Row],[CAUDAL TOTAL TRATADO GEM ]]/Tabla1[[#This Row],[CAUDAL DE TRATAMIENTO]],0) -> 4
A22: 46060 | B22: 7 | C22: 3(TARDE) | D22: 21 | E22: FINAL TURNO 2 | F22: 1750 | G22: 6300 | H22: 330 | I22: 120 | J22: 115 | K22: 16947 | L22: 0 | M22: 75 | N22: 0 | O22: 0 | P22: 0 | Q22: 0 | R22: 0 | S22: 0 | T22: 0 | U22: 0 | V22: 0 | W22: 0 | X22: #DIV/0! | Y22: #DIV/0! | Z22: #DIV/0! | AA22: #DIV/0! | AB22: #DIV/0! | AC22: 1.3 | AD22: 1.325 | AE22: 1.25 | AF22: 2500 | AG22: 2500 | AH22: 830 | AI22: 2900 | AJ22: 6295 | AK22: 19050 | AL22: 22050 | AM22: 0 | AN22: 0 | AO22: 0 | AP22: 0 | AQ22: 0 | AR22: 0 | AS22: 5250 | AT22: #DIV/0! | AU22: =IFERROR(Tabla1[[#This Row],[CAUDAL TOTAL TRATADO GEM ]]/Tabla1[[#This Row],[CAUDAL DE TRATAMIENTO]],0) -> 0
A23: 46061 | B23: 8 | C23: 8 (NOCHE) | D23: 22 | E23: FINAL TURNO 3 | F23: 1750 | G23: 6300 | H23: 330 | I23: 120 | J23: 115 | K23: 16947 | L23: 0 | M23: 75 | N23: 0 | O23: 0 | P23: 0 | Q23: 0 | R23: 0 | S23: 0 | T23: 0 | U23: 0 | V23: 0 | W23: 0 | X23: #DIV/0! | Y23: #DIV/0! | Z23: #DIV/0! | AA23: #DIV/0! | AB23: #DIV/0! | AC23: 1.3 | AD23: 1.325 | AE23: 1.25 | AF23: 2500 | AG23: 2500 | AH23: 830 | AI23: 2900 | AJ23: 6295 | AK23: 19050 | AL23: 22050 | AM23: 0 | AN23: 0 | AO23: 0 | AP23: 0 | AQ23: 0 | AR23: 0 | AS23: 5250 | AT23: #DIV/0! | AU23: =IFERROR(Tabla1[[#This Row],[CAUDAL TOTAL TRATADO GEM ]]/Tabla1[[#This Row],[CAUDAL DE TRATAMIENTO]],0) -> 0
A24: 46061 | B24: 8 | C24: 9 (MAÑANA) | D24: 23 | E24: FINAL TURNO 1 | F24: 1750 | G24: 6300 | H24: 330 | I24: 120 | J24: 115 | K24: 16947 | L24: 0 | M24: 75 | N24: 0 | O24: 0 | P24: 0 | Q24: 5 | R24: 0 | S24: 0 | T24: 0 | U24: 0 | V24: 5 | W24: 0 | X24: #DIV/0! | Y24: #DIV/0! | Z24: #DIV/0! | AA24: #DIV/0! | AB24: #DIV/0! | AC24: 1.3 | AD24: 1.325 | AE24: 1.25 | AF24: 2500 | AG24: 2500 | AH24: 830 | AI24: 2900 | AJ24: 6295 | AK24: 19050 | AL24: 22050 | AM24: 0 | AN24: 0 | AO24: 0 | AP24: 95250 | AQ24: 0 | AR24: 95250 | AS24: 5250 | AT24: #DIV/0! | AU24: =IFERROR(Tabla1[[#This Row],[CAUDAL TOTAL TRATADO GEM ]]/Tabla1[[#This Row],[CAUDAL DE TRATAMIENTO]],0) -> 0
A25: 46061 | B25: 8 | C25: 3(TARDE) | D25: 24 | E25: FINAL TURNO 2 | F25: 1750 | G25: 6300 | H25: 330 | I25: 115 | J25: 115 | K25: 16947 | L25: 0 | M25: 75 | N25: 0 | O25: 0 | P25: 0 | Q25: 0 | R25: 0 | S25: 0 | T25: 0 | U25: 0 | V25: 0 | W25: 0 | X25: #DIV/0! | Y25: #DIV/0! | Z25: #DIV/0! | AA25: #DIV/0! | AB25: #DIV/0! | AC25: 1.3 | AD25: 1.325 | AE25: 1.25 | AF25: 2500 | AG25: 2500 | AH25: 830 | AI25: 2900 | AJ25: 6295 | AK25: 19050 | AL25: 22050 | AM25: 0 | AN25: 0 | AO25: 0 | AP25: 0 | AQ25: 0 | AR25: 0 | AS25: 5250 | AT25: #DIV/0! | AU25: =IFERROR(Tabla1[[#This Row],[CAUDAL TOTAL TRATADO GEM ]]/Tabla1[[#This Row],[CAUDAL DE TRATAMIENTO]],0) -> 0
A26: 46062 | B26: 9 | C26: 9 (NOCHE) | D26: 25 | E26: FINAL TURNO 3 | F26: 1750 | G26: 6300 | H26: 330 | I26: 115 | J26: 115 | K26: 16947 | L26: 525 | M26: 75 | N26: 80 | O26: 370 | P26: 80 | Q26: 5 | R26: 5 | S26: 104 | T26: 490.25 | U26: 100 | V26: 5 | W26: 5 | X26: 198.09524 | Y26: 933.80952 | Z26: 190.47619 | AA26: 9.5238095 | AB26: 9.5238095 | AC26: 1.3 | AD26: 1.325 | AE26: 1.25 | AF26: 2500 | AG26: 2500 | AH26: 830 | AI26: 2900 | AJ26: 6295 | AK26: 19050 | AL26: 22050 | AM26: 86320 | AN26: 1421725 | AO26: 629500 | AP26: 95250 | AQ26: 110250 | AR26: 2343045 | AS26: 5250 | AT26: 4462.9429 | AU26: =IFERROR(Tabla1[[#This Row],[CAUDAL TOTAL TRATADO GEM ]]/Tabla1[[#This Row],[CAUDAL DE TRATAMIENTO]],0) -> 7
A27: 46062 | B27: 9 | C27: 10 (MAÑANA) | D27: 26 | E27: FINAL TURNO 1 | F27: 2670 | G27: 5930 | H27: 2250 | I27: 160 | J27: 110 | K27: 16954 | L27: 525 | M27: 75 | N27: 0 | O27: 130 | P27: 20 | Q27: 0 | R27: 5 | S27: 0 | T27: 172.25 | U27: 25 | V27: 0 | W27: 5 | X27: 0 | Y27: 328.09524 | Z27: 47.619048 | AA27: 0 | AB27: 9.5238095 | AC27: 1.3 | AD27: 1.325 | AE27: 1.25 | AF27: 2500 | AG27: 2500 | AH27: 830 | AI27: 2900 | AJ27: 6295 | AK27: 19050 | AL27: 22050 | AM27: 0 | AN27: 499525 | AO27: 157375 | AP27: 0 | AQ27: 110250 | AR27: 767150 | AS27: 5250 | AT27: 1461.2381 | AU27: =IFERROR(Tabla1[[#This Row],[CAUDAL TOTAL TRATADO GEM ]]/Tabla1[[#This Row],[CAUDAL DE TRATAMIENTO]],0) -> 7
A28: 46062 | B28: 9 | C28: 3(TARDE) | D28: 27 | E28: FINAL TURNO 2 | F28: 2670 | G28: 5800 | H28: 2230 | I28: 160 | J28: 105 | K28: 16961 | L28: 300 | M28: 75 | N28: 70 | O28: 200 | P28: 40 | Q28: 5 | R28: 5 | S28: 91 | T28: 265 | U28: 50 | V28: 5 | W28: 5 | X28: 303.33333 | Y28: 883.33333 | Z28: 166.66667 | AA28: 16.666667 | AB28: 16.666667 | AC28: 1.3 | AD28: 1.325 | AE28: 1.25 | AF28: 2500 | AG28: 2500 | AH28: 830 | AI28: 2900 | AJ28: 6295 | AK28: 19050 | AL28: 22050 | AM28: 75530 | AN28: 768500 | AO28: 314750 | AP28: 95250 | AQ28: 110250 | AR28: 1364280 | AS28: 5250 | AT28: 4547.6 | AU28: =IFERROR(Tabla1[[#This Row],[CAUDAL TOTAL TRATADO GEM ]]/Tabla1[[#This Row],[CAUDAL DE TRATAMIENTO]],0) -> 4
A29: 46063 | B29: 10 | C29: 10 (NOCHE) | D29: 28 | E29: FINAL TURNO 3 | F29: 2600 | G29: 5600 | H29: 2190 | I29: 155 | J29: 100 | K29: 16965 | L29: 525 | M29: 75 | N29: 20 | O29: 20 | P29: 10 | Q29: 0 | R29: 5 | S29: 26 | T29: 26.5 | U29: 12.5 | V29: 0 | W29: 5 | X29: 49.52381 | Y29: 50.47619 | Z29: 23.809524 | AA29: 0 | AB29: 9.5238095 | AC29: 1.3 | AD29: 1.325 | AE29: 1.25 | AF29: 2500 | AG29: 2500 | AH29: 830 | AI29: 2900 | AJ29: 6295 | AK29: 19050 | AL29: 22050 | AM29: 21580 | AN29: 76850 | AO29: 78687.5 | AP29: 0 | AQ29: 110250 | AR29: 287367.5 | AS29: 5250 | AT29: 547.36667 | AU29: =IFERROR(Tabla1[[#This Row],[CAUDAL TOTAL TRATADO GEM ]]/Tabla1[[#This Row],[CAUDAL DE TRATAMIENTO]],0) -> 7
A30: 46063 | B30: 10 | C30: 11 (MAÑANA) | D30: 29 | E30: FINAL TURNO 1 | F30: 2580 | G30: 5580 | H30: 2180 | I30: 155 | J30: 95 | K30: 16972 | L30: 300 | M30: 75 | N30: 80 | O30: 170 | P30: 20 | Q30: 5 | R30: 5 | S30: 104 | T30: 225.25 | U30: 25 | V30: 5 | W30: 5 | X30: 346.66667 | Y30: 750.83333 | Z30: 83.333333 | AA30: 16.666667 | AB30: 16.666667 | AC30: 1.3 | AD30: 1.325 | AE30: 1.25 | AF30: 2500 | AG30: 2500 | AH30: 830 | AI30: 2900 | AJ30: 6295 | AK30: 19050 | AL30: 22050 | AM30: 86320 | AN30: 653225 | AO30: 157375 | AP30: 95250 | AQ30: 110250 | AR30: 1102420 | AS30: 5250 | AT30: 3674.7333 | AU30: =IFERROR(Tabla1[[#This Row],[CAUDAL TOTAL TRATADO GEM ]]/Tabla1[[#This Row],[CAUDAL DE TRATAMIENTO]],0) -> 4
A31: 46063 | B31: 10 | C31: 3(TARDE) | D31: 30 | E31: FINAL TURNO 2 | F31: 2500 | G31: 5410 | H31: 2160 | I31: 150 | J31: 90 | K31: 16976 | L31: 600 | M31: 75 | N31: 170 | O31: 140 | P31: 50 | Q31: 0 | R31: 5 | S31: 221 | T31: 185.5 | U31: 62.5 | V31: 0 | W31: 5 | X31: 368.33333 | Y31: 309.16667 | Z31: 104.16667 | AA31: 0 | AB31: 8.3333333 | AC31: 1.3 | AD31: 1.325 | AE31: 1.25 | AF31: 2500 | AG31: 2500 | AH31: 830 | AI31: 2900 | AJ31: 6295 | AK31: 19050 | AL31: 22050 | AM31: 183430 | AN31: 537950 | AO31: 393437.5 | AP31: 0 | AQ31: 110250 | AR31: 1225067.5 | AS31: 5250 | AT31: 2041.7792 | AU31: =IFERROR(Tabla1[[#This Row],[CAUDAL TOTAL TRATADO GEM ]]/Tabla1[[#This Row],[CAUDAL DE TRATAMIENTO]],0) -> 8
A32: 46064 | B32: 11 | C32: 11 (NOCHE) | D32: 31 | E32: FINAL TURNO 3 | F32: 2330 | G32: 5270 | H32: 2110 | I32: 150 | J32: 85 | K32: 16984 | L32: 225 | M32: 75 | N32: 130 | O32: 90 | P32: 10 | Q32: 5 | R32: 5 | S32: 169 | T32: 119.25 | U32: 12.5 | V32: 5 | W32: 5 | X32: 751.11111 | Y32: 530 | Z32: 55.555556 | AA32: 22.222222 | AB32: 22.222222 | AC32: 1.3 | AD32: 1.325 | AE32: 1.25 | AF32: 2500 | AG32: 2500 | AH32: 830 | AI32: 2900 | AJ32: 6295 | AK32: 19050 | AL32: 22050 | AM32: 140270 | AN32: 345825 | AO32: 78687.5 | AP32: 95250 | AQ32: 110250 | AR32: 770282.5 | AS32: 5250 | AT32: 3423.4778 | AU32: =IFERROR(Tabla1[[#This Row],[CAUDAL TOTAL TRATADO GEM ]]/Tabla1[[#This Row],[CAUDAL DE TRATAMIENTO]],0) -> 3
A33: 46064 | B33: 11 | C33: 12 (MAÑANA) | D33: 32 | E33: FINAL TURNO 1 | F33: 2200 | G33: 5180 | H33: 2100 | I33: 145 | J33: 80 | K33: 16987 | L33: 450 | M33: 75 | N33: 100 | O33: 120 | P33: 30 | Q33: 5 | R33: 5 | S33: 130 | T33: 159 | U33: 37.5 | V33: 5 | W33: 5 | X33: 288.88889 | Y33: 353.33333 | Z33: 83.333333 | AA33: 11.111111 | AB33: 11.111111 | AC33: 1.3 | AD33: 1.325 | AE33: 1.25 | AF33: 2500 | AG33: 2500 | AH33: 830 | AI33: 2900 | AJ33: 6295 | AK33: 19050 | AL33: 22050 | AM33: 107900 | AN33: 461100 | AO33: 236062.5 | AP33: 95250 | AQ33: 110250 | AR33: 1010562.5 | AS33: 5250 | AT33: 2245.6944 | AU33: =IFERROR(Tabla1[[#This Row],[CAUDAL TOTAL TRATADO GEM ]]/Tabla1[[#This Row],[CAUDAL DE TRATAMIENTO]],0) -> 6
A34: 46064 | B34: 11 | C34: 3(TARDE) | D34: 33 | E34: FINAL TURNO 2 | F34: 2100 | G34: 4910 | H34: 2070 | I34: 140 | J34: 75 | K34: 16993 | L34: 600 | M34: 75 | N34: 70 | O34: 110 | P34: 70 | Q34: 0 | R34: 5 | S34: 91 | T34: 145.75 | U34: 87.5 | V34: 0 | W34: 5 | X34: 151.66667 | Y34: 242.91667 | Z34: 145.83333 | AA34: 0 | AB34: 8.3333333 | AC34: 1.3 | AD34: 1.325 | AE34: 1.25 | AF34: 2500 | AG34: 2500 | AH34: 830 | AI34: 2900 | AJ34: 6295 | AK34: 19050 | AL34: 22050 | AM34: 75530 | AN34: 422675 | AO34: 550812.5 | AP34: 0 | AQ34: 110250 | AR34: 1159267.5 | AS34: 5250 | AT34: 1932.1125 | AU34: =IFERROR(Tabla1[[#This Row],[CAUDAL TOTAL TRATADO GEM ]]/Tabla1[[#This Row],[CAUDAL DE TRATAMIENTO]],0) -> 8
A35: 46065 | B35: 12 | C35: 12 (NOCHE) | D35: 34 | E35: FINAL TURNO 3 | F35: 2030 | G35: 4800 | H35: 2000 | I35: 140 | J35: 70 | K35: 17001 | L35: 375 | M35: 75 | N35: 100 | O35: 120 | P35: 0 | Q35: 5 | R35: 5 | S35: 130 | T35: 159 | U35: 0 | V35: 5 | W35: 5 | X35: 346.66667 | Y35: 424 | Z35: 0 | AA35: 13.333333 | AB35: 13.333333 | AC35: 1.3 | AD35: 1.325 | AE35: 1.25 | AF35: 2500 | AG35: 2500 | AH35: 830 | AI35: 2900 | AJ35: 6295 | AK35: 19050 | AL35: 22050 | AM35: 107900 | AN35: 461100 | AO35: 0 | AP35: 95250 | AQ35: 110250 | AR35: 774500 | AS35: 5250 | AT35: 2065.3333 | AU35: =IFERROR(Tabla1[[#This Row],[CAUDAL TOTAL TRATADO GEM ]]/Tabla1[[#This Row],[CAUDAL DE TRATAMIENTO]],0) -> 5
A36: 46065 | B36: 12 | C36: 13 (MAÑANA) | D36: 35 | E36: FINAL TURNO 1 | F36: 1930 | G36: 4680 | H36: 2000 | I36: 135 | J36: 65 | K36: 17006 | L36: 225 | M36: 75 | N36: 130 | O36: 170 | P36: 30 | Q36: 0 | R36: 5 | S36: 169 | T36: 225.25 | U36: 37.5 | V36: 0 | W36: 5 | X36: 751.11111 | Y36: 1001.1111 | Z36: 166.66667 | AA36: 0 | AB36: 22.222222 | AC36: 1.3 | AD36: 1.325 | AE36: 1.25 | AF36: 2500 | AG36: 2500 | AH36: 830 | AI36: 2900 | AJ36: 6295 | AK36: 19050 | AL36: 22050 | AM36: 140270 | AN36: 653225 | AO36: 236062.5 | AP36: 0 | AQ36: 110250 | AR36: 1139807.5 | AS36: 5250 | AT36: 5065.8111 | AU36: =IFERROR(Tabla1[[#This Row],[CAUDAL TOTAL TRATADO GEM ]]/Tabla1[[#This Row],[CAUDAL DE TRATAMIENTO]],0) -> 3
A37: 46065 | B37: 12 | C37: 3(TARDE) | D37: 36 | E37: FINAL TURNO 2 | F37: 1800 | G37: 4510 | H37: 1970 | I37: 135 | J37: 60 | K37: 17009 | L37: 600 | M37: 75 | N37: 100 | O37: 110 | P37: 20 | Q37: 5 | R37: 5 | S37: 130 | T37: 145.75 | U37: 25 | V37: 5 | W37: 5 | X37: 216.66667 | Y37: 242.91667 | Z37: 41.666667 | AA37: 8.3333333 | AB37: 8.3333333 | AC37: 1.3 | AD37: 1.325 | AE37: 1.25 | AF37: 2500 | AG37: 2500 | AH37: 830 | AI37: 2900 | AJ37: 6295 | AK37: 19050 | AL37: 22050 | AM37: 107900 | AN37: 422675 | AO37: 157375 | AP37: 95250 | AQ37: 110250 | AR37: 893450 | AS37: 5250 | AT37: 1489.0833 | AU37: =IFERROR(Tabla1[[#This Row],[CAUDAL TOTAL TRATADO GEM ]]/Tabla1[[#This Row],[CAUDAL DE TRATAMIENTO]],0) -> 8
... A43: 46067 | B43: 14 | C43: 3(TARDE) | D43: 42 | E43: FINAL TURNO 2 | F43: 1300 | G43: 3260 | H43: 1780 | I43: 120 | J43: 30 | K43: 17043 | L43: 300 | M43: 75 | N43: 0 | O43: 0 | P43: 0 | Q43: 5 | R43: 0 | S43: 0 | T43: 0 | U43: 0 | V43: 5 | W43: 0 | X43: 0 | Y43: 0 | Z43: 0 | AA43: 16.666667 | AB43: 0 | AC43: 1.3 | AD43: 1.325 | AE43: 1.25 | AF43: 2500 | AG43: 2500 | AH43: 830 | AI43: 2900 | AJ43: 6295 | AK43: 19050 | AL43: 22050 | AM43: 0 | AN43: 0 | AO43: 0 | AP43: 95250 | AQ43: 0 | AR43: 95250 | AS43: 5250 | AT43: 317.5 | AU43: =IFERROR(Tabla1[[#This Row],[CAUDAL TOTAL TRATADO GEM ]]/Tabla1[[#This Row],[CAUDAL DE TRATAMIENTO]],0) -> 4
A44: 46068 | B44: 15 | C44: 15 (NOCHE) | D44: 43 | E44: FINAL TURNO 3 | F44: 1300 | G44: 3260 | H44: 1780 | I44: 115 | J44: 30 | K44: 17047 | L44: 0 | M44: 75 | N44: 0 | O44: 0 | P44: 0 | Q44: 0 | R44: 0 | S44: 0 | T44: 0 | U44: 0 | V44: 0 | W44: 0 | X44: #DIV/0! | Y44: #DIV/0! | Z44: #DIV/0! | AA44: #DIV/0! | AB44: #DIV/0! | AC44: 1.3 | AD44: 1.325 | AE44: 1.25 | AF44: 2500 | AG44: 2500 | AH44: 830 | AI44: 2900 | AJ44: 6295 | AK44: 19050 | AL44: 22050 | AM44: 0 | AN44: 0 | AO44: 0 | AP44: 0 | AQ44: 0 | AR44: 0 | AS44: 5250 | AT44: #DIV/0! | AU44: =IFERROR(Tabla1[[#This Row],[CAUDAL TOTAL TRATADO GEM ]]/Tabla1[[#This Row],[CAUDAL DE TRATAMIENTO]],0) -> 0
A45: 46068 | B45: 15 | C45: 16 (MAÑANA) | D45: 44 | E45: FINAL TURNO 1 | F45: 1300 | G45: 3260 | H45: 1780 | I45: 115 | J45: 30 | K45: 17047 | L45: 0 | M45: 75 | N45: 0 | O45: 0 | P45: 0 | Q45: 0 | R45: 0 | S45: 0 | T45: 0 | U45: 0 | V45: 0 | W45: 0 | X45: #DIV/0! | Y45: #DIV/0! | Z45: #DIV/0! | AA45: #DIV/0! | AB45: #DIV/0! | AC45: 1.3 | AD45: 1.325 | AE45: 1.25 | AF45: 2500 | AG45: 2500 | AH45: 830 | AI45: 2900 | AJ45: 6295 | AK45: 19050 | AL45: 22050 | AM45: 0 | AN45: 0 | AO45: 0 | AP45: 0 | AQ45: 0 | AR45: 0 | AS45: 5250 | AT45: #DIV/0! | AU45: =IFERROR(Tabla1[[#This Row],[CAUDAL TOTAL TRATADO GEM ]]/Tabla1[[#This Row],[CAUDAL DE TRATAMIENTO]],0) -> 0
A46: 46068 | B46: 15 | C46: 3(TARDE) | D46: 45 | E46: FINAL TURNO 2 | F46: 1300 | G46: 3260 | H46: 1780 | I46: 115 | J46: 30 | K46: 17047 | L46: 0 | M46: 75 | N46: 0 | O46: 0 | P46: 0 | Q46: 0 | R46: 0 | S46: 0 | T46: 0 | U46: 0 | V46: 0 | W46: 0 | X46: #DIV/0! | Y46: #DIV/0! | Z46: #DIV/0! | AA46: #DIV/0! | AB46: #DIV/0! | AC46: 1.3 | AD46: 1.325 | AE46: 1.25 | AF46: 2500 | AG46: 2500 | AH46: 830 | AI46: 2900 | AJ46: 6295 | AK46: 19050 | AL46: 22050 | AM46: 0 | AN46: 0 | AO46: 0 | AP46: 0 | AQ46: 0 | AR46: 0 | AS46: 5250 | AT46: #DIV/0! | AU46: =IFERROR(Tabla1[[#This Row],[CAUDAL TOTAL TRATADO GEM ]]/Tabla1[[#This Row],[CAUDAL DE TRATAMIENTO]],0) -> 0
A47: 46069 | B47: 16 | C47: 16 (NOCHE) | D47: 46 | E47: FINAL TURNO 3 | F47: 1300 | G47: 3260 | H47: 1780 | I47: 115 | J47: 30 | K47: 17047 | L47: 480 | M47: 80 | N47: 200 | O47: 380 | P47: 80 | Q47: 5 | R47: 5 | S47: 260 | T47: 503.5 | U47: 100 | V47: 5 | W47: 5 | X47: 541.66667 | Y47: 1048.9583 | Z47: 208.33333 | AA47: 10.416667 | AB47: 10.416667 | AC47: 1.3 | AD47: 1.325 | AE47: 1.25 | AF47: 2500 | AG47: 2500 | AH47: 830 | AI47: 2900 | AJ47: 6295 | AK47: 19050 | AL47: 22050 | AM47: 215800 | AN47: 1460150 | AO47: 629500 | AP47: 95250 | AQ47: 110250 | AR47: 2510950 | AS47: 5250 | AT47: 5231.1458 | AU47: =IFERROR(Tabla1[[#This Row],[CAUDAL TOTAL TRATADO GEM ]]/Tabla1[[#This Row],[CAUDAL DE TRATAMIENTO]],0) -> 6
A48: 46069 | B48: 16 | C48: 17 (MAÑANA) | D48: 47 | E48: FINAL TURNO 1 | F48: 1100 | G48: 2880 | H48: 1700 | I48: 110 | J48: 25 | K48: 17053 | L48: 320 | M48: 80 | N48: 100 | O48: 240 | P48: 60 | Q48: 0 | R48: 5 | S48: 130 | T48: 318 | U48: 75 | V48: 0 | W48: 5 | X48: 406.25 | Y48: 993.75 | Z48: 234.375 | AA48: 0 | AB48: 15.625 | AC48: 1.3 | AD48: 1.325 | AE48: 1.25 | AF48: 2500 | AG48: 2500 | AH48: 830 | AI48: 2900 | AJ48: 6295 | AK48: 19050 | AL48: 22050 | AM48: 107900 | AN48: 922200 | AO48: 472125 | AP48: 0 | AQ48: 110250 | AR48: 1612475 | AS48: 5250 | AT48: 5038.9844 | AU48: =IFERROR(Tabla1[[#This Row],[CAUDAL TOTAL TRATADO GEM ]]/Tabla1[[#This Row],[CAUDAL DE TRATAMIENTO]],0) -> 4
A49: 46069 | B49: 16 | C49: 3(TARDE) | D49: 48 | E49: FINAL TURNO 2 | F49: 1000 | G49: 2640 | H49: 1640 | I49: 110 | J49: 20 | K49: 17057 | L49: 640 | M49: 80 | N49: 100 | O49: 240 | P49: 40 | Q49: 0 | R49: 5 | S49: 130 | T49: 318 | U49: 50 | V49: 0 | W49: 5 | X49: 203.125 | Y49: 496.875 | Z49: 78.125 | AA49: 0 | AB49: 7.8125 | AC49: 1.3 | AD49: 1.325 | AE49: 1.25 | AF49: 2500 | AG49: 2500 | AH49: 830 | AI49: 2900 | AJ49: 6295 | AK49: 19050 | AL49: 22050 | AM49: 107900 | AN49: 922200 | AO49: 314750 | AP49: 0 | AQ49: 110250 | AR49: 1455100 | AS49: 5250 | AT49: 2273.5938 | AU49: =IFERROR(Tabla1[[#This Row],[CAUDAL TOTAL TRATADO GEM ]]/Tabla1[[#This Row],[CAUDAL DE TRATAMIENTO]],0) -> 8
...

Sheet DB QUIMICA
A1: CONSUMO DE QUIMICO | AJ1: TABLA GRAFICA 2. COSTO CONSUMO QUIMICO VS $M3 | AT1: TABLA GRAFICA 3. RO COSTO CONSUMO QUIMICO VS $M3
A2: GEM | B2: COSTO TTO - CAUDAL TRATADP GEM Vs $M3
Z4: CONSOLIDADO COSTO TTO - CAUDAL TRATADP GEM Vs $M3 | AJ4: DIA | AK4: CAUDAL TOTAL TRATADO GEM | AL4: INDICADOR $m3 | AM4: 2025 $m3 GEM | AP4: DIA | AQ4: VOLUMEN TRATADO GEM (m3) | AR4: HORAS DE OPERACIÓN | AT4: DÍA | AU4: VOLUMEN ENVIADO A RO (m3) | AV4: LIMITE INDICADOR M3 | AW4: INDICADOR $m3 RO | AY4: Etiquetas de fila | AZ4: VOLUMEN ENVIADO A RO (m3) | BA4: TIEMPO DE OPERACIÓN | BC4: Etiquetas de fila | BD4: VOLUMEN ENVIADO A RO (m3) | BE4: TIEMPO DE OPERACIÓN | BF4: COSTO QUIMICA | BH4: DIA | BI4: VOLUMEN TRATADO GEM (m3) | BJ4: COSTO QUIMICA GEM
AJ5: 1 | AK5: 0 | AL5: 0 | AM5: 5250 | AP5: 1 | AQ5: 0 | AR5: 0 | AT5: 1 | AU5: 0 | AV5: 1000 | AW5: 0 | AY5: 1 | AZ5: 0 | BA5: 0 | BC5: 1 | BD5: 0 | BE5: 0 | BF5: 0 | BH5: 1 | BI5: 0 | BJ5: 0
Z6: PANORAMA OPERATIVO GEM | AJ6: 2 | AK6: 1125 | AL6: 4748.1533 | AM6: 5250 | AP6: 2 | AQ6: 1125 | AR6: 15 | AT6: 2 | AU6: 257.449 | AV6: 1000 | AW6: 91 | AY6: 2 | AZ6: 257.449 | BA6: 4.6808909 | BC6: 2 | BD6: 257.449 | BE6: 4.6808909 | BF6: 23427.859 | BH6: 2 | BI6: 1125 | BJ6: 5341672.5
Z7: VOLUMEN TRATADO GEM (m3) | AA7: $m3 | AB7: HORAS | AC7: $ HORA DE TRATAMIENTO GEM | AD7: $ CONSOLIDADO | AJ7: 3 | AK7: 1650 | AL7: 3732.7652 | AM7: 5250 | AP7: 3 | AQ7: 1650 | AR7: 22 | AT7: 3 | AU7: 0 | AV7: 1000 | AW7: 0 | AY7: 3 | AZ7: 0 | BA7: 0 | BC7: 3 | BD7: 0 | BE7: 0 | BF7: 0 | BH7: 3 | BI7: 1650 | BJ7: 6159062.5
Z8: =GETPIVOTDATA(" CAUDAL TOTAL TRATADO GEM ",$AJ$4) -> 30080 | AA8: =AD8/Z8 -> 3239.6917 | AB8: =Z8/80 -> 376 | AC8: =AD8/AB8 -> 259175.34 | AD8: =GETPIVOTDATA("COSTO QUIMICA GEM",$BH$4) -> 97449928 | AJ8: 4 | AK8: 1575 | AL8: 3747.9794 | AM8: 5250 | AP8: 4 | AQ8: 1575 | AR8: 21 | AT8: 4 | AU8: 0 | AV8: 1000 | AW8: 0 | AY8: 4 | AZ8: 0 | BA8: 0 | BC8: 4 | BD8: 0 | BE8: 0 | BF8: 0 | BH8: 4 | BI8: 1575 | BJ8: 5903067.5
AJ9: 5 | AK9: 1500 | AL9: 2896.65 | AM9: 5250 | AP9: 5 | AQ9: 1500 | AR9: 20 | AT9: 5 | AU9: 278.223 | AV9: 1000 | AW9: 91 | AY9: 5 | AZ9: 278.223 | BA9: 5.0586 | BC9: 5 | BD9: 278.223 | BE9: 5.0586 | BF9: 25318.293 | BH9: 5 | BI9: 1500 | BJ9: 4344975
AJ10: 6 | AK10: 1350 | AL10: 4029.6759 | AM10: 5250 | AP10: 6 | AQ10: 1350 | AR10: 18 | AT10: 6 | AU10: 579.819 | AV10: 1000 | AW10: 139.02467 | AY10: 6 | AZ10: 579.819 | BA10: 10.542164 | BC10: 6 | BD10: 579.819 | BE10: 10.542164 | BF10: 80609.143 | BH10: 6 | BI10: 1350 | BJ10: 5440062.5
AJ11: 7 | AK11: 900 | AL11: 3415.6944 | AM11: 5250 | AP11: 7 | AQ11: 900 | AR11: 12 | AT11: 7 | AU11: 293.519 | AV11: 1000 | AW11: 539.15154 | AY11: 7 | AZ11: 293.519 | BA11: 5.3367091 | BC11: 7 | BD11: 293.519 | BE11: 5.3367091 | BF11: 158251.22 | BH11: 7 | BI11: 900 | BJ11: 3074125
AJ12: 8 | AK12: 0 | AL12: 0 | AM12: 5250 | AP12: 8 | AQ12: 0 | AR12: 0 | AT12: 8 | AU12: 560.618 | AV12: 1000 | AW12: 158.20984 | AY12: 8 | AZ12: 560.618 | BA12: 10.193055 | BC12: 8 | BD12: 560.618 | BE12: 10.193055 | BF12: 88695.284 | BH12: 8 | BI12: 0 | BJ12: 95250
AJ13: 9 | AK13: 1350 | AL13: 3314.4259 | AM13: 5250 | AP13: 9 | AQ13: 1350 | AR13: 18 | AT13: 9 | AU13: 346.269 | AV13: 1000 | AW13: 1512.4815 | AY13: 9 | AZ13: 346.269 | BA13: 6.2958 | BC13: 9 | BD13: 346.269 | BE13: 6.2958 | BF13: 523725.44 | BH13: 9 | BI13: 1350 | BJ13: 4474475
AJ14: 10 | AK14: 1425 | AL14: 1834.986 | AM14: 5250 | AP14: 10 | AQ14: 1425 | AR14: 19 | AT14: 10 | AU14: 256.667 | AV14: 1000 | AW14: 129.31202 | AY14: 10 | AZ14: 256.667 | BA14: 4.6666727 | BC14: 10 | BD14: 256.667 | BE14: 4.6666727 | BF14: 33190.129 | BH14: 10 | BI14: 1425 | BJ14: 2614855
AJ15: 11 | AK15: 1275 | AL15: 2305.9706 | AM15: 5250 | AP15: 11 | AQ15: 1275 | AR15: 17 | AT15: 11 | AU15: 0 | AV15: 1000 | AW15: 0 | AY15: 11 | AZ15: 0 | BA15: 0 | BC15: 11 | BD15: 0 | BE15: 0 | BF15: 105709.39 | BH15: 11 | BI15: 1275 | BJ15: 2940112.5
AJ16: 12 | AK16: 1200 | AL16: 2339.7979 | AM16: 5250 | AP16: 12 | AQ16: 1200 | AR16: 16 | AT16: 12 | AU16: 0 | AV16: 1000 | AW16: 0 | AY16: 12 | AZ16: 0 | BA16: 0 | BC16: 12 | BD16: 0 | BE16: 0 | BF16: 40151.584 | BH16: 12 | BI16: 1200 | BJ16: 2807757.5
AJ17: 13 | AK17: 1125 | AL17: 3432.9356 | AM17: 5250 | AP17: 13 | AQ17: 1125 | AR17: 15 | AT17: 13 | AU17: 153.402 | AV17: 1000 | AW17: 945.2869 | AY17: 13 | AZ17: 153.402 | BA17: 2.7891273 | BC17: 13 | BD17: 153.402 | BE17: 2.7891273 | BF17: 145008.9 | BH17: 13 | BI17: 1125 | BJ17: 3862052.5
AJ18: 14 | AK18: 1125 | AL18: 2265.1644 | AM18: 5250 | AP18: 14 | AQ18: 1125 | AR18: 15 | AT18: 14 | AU18: 933.478 | AV18: 1000 | AW18: 332.63945 | AY18: 14 | AZ18: 933.478 | BA18: 16.972327 | BC18: 14 | BD18: 933.478 | BE18: 16.972327 | BF18: 310511.61 | BH18: 14 | BI18: 1125 | BJ18: 2548310
A19: OSMOSIS INVERSA | AJ19: 15 | AK19: 0 | AL19: 0 | AM19: 5250 | AP19: 15 | AQ19: 0 | AR19: 0 | AT19: 15 | AU19: 1344.463 | AV19: 1000 | AW19: 234.16839 | AY19: 15 | AZ19: 1344.463 | BA19: 24.444782 | BC19: 15 | BD19: 1344.463 | BE19: 24.444782 | BF19: 314830.74 | BH19: 15 | BI19: 0 | BJ19: 0
AJ20: 16 | AK20: 1440 | AL20: 3873.9757 | AM20: 5250 | AP20: 16 | AQ20: 1440 | AR20: 18 | AT20: 16 | AU20: 841.253 | AV20: 1000 | AW20: 213.67856 | AY20: 16 | AZ20: 841.253 | BA20: 15.295509 | BC20: 16 | BD20: 841.253 | BE20: 15.295509 | BF20: 179757.73 | BH20: 16 | BI20: 1440 | BJ20: 5578525
Z21: CONSOLIDADO COSTO TTO - CAUDAL TRATADP RO Vs $M3 | AJ21: 17 | AK21: 1200 | AL21: 2261.7188 | AM21: 5250 | AP21: 17 | AQ21: 1200 | AR21: 15 | AT21: 17 | AU21: 463.256 | AV21: 1000 | AW21: 221.83035 | AY21: 17 | AZ21: 463.256 | BA21: 8.4228364 | BC21: 17 | BD21: 463.256 | BE21: 8.4228364 | BF21: 102764.24 | BH21: 17 | BI21: 1200 | BJ21: 2714062.5
AJ22: 18 | AK22: 960 | AL22: 2397.7812 | AM22: 5250 | AP22: 18 | AQ22: 960 | AR22: 12 | AT22: 18 | AU22: 0 | AV22: 1000 | AW22: 0 | AY22: 18 | AZ22: 0 | BA22: 0 | BC22: 18 | BD22: 0 | BE22: 0 | BF22: 4916.7158 | BH22: 18 | BI22: 960 | BJ22: 2301870
Z23: PANORAMA OPERATIVO RO | AJ23: 19 | AK23: 1200 | AL23: 2745.525 | AM23: 5250 | AP23: 19 | AQ23: 1200 | AR23: 15 | AT23: 19 | AU23: 257.335 | AV23: 1000 | AW23: 91 | AY23: 19 | AZ23: 257.335 | BA23: 4.6788182 | BC23: 19 | BD23: 257.335 | BE23: 4.6788182 | BF23: 23417.485 | BH23: 19 | BI23: 1200 | BJ23: 3294630
Z24: TOTAL CAUDAL TRATADO RO | AA24: $m3 | AB24: HORAS | AC24: $ HORA DE TRATAMIENTO RO | AD24: $ CONSOLIDADO | AJ24: 20 | AK24: 1360 | AL24: 2221.6636 | AM24: 5250 | AP24: 20 | AQ24: 1360 | AR24: 17 | AT24: 20 | AU24: 596.75 | AV24: 1000 | AW24: 91 | AY24: 20 | AZ24: 596.75 | BA24: 10.85 | BC24: 20 | BD24: 596.75 | BE24: 10.85 | BF24: 54304.25 | BH24: 20 | BI24: 1360 | BJ24: 3021462.5
Z25: =+GETPIVOTDATA(" VOLUMEN ENVIADO A RO (m3)",$AT$4) -> 14633.579 | AA25: =+AD25/Z25 -> 200.64992 | AB25: =GETPIVOTDATA("TIEMPO DE OPERACIÓN",$AY$4) -> 257.42341 | AC25: =AD25/AB25 -> 11406.214 | AD25: =GETPIVOTDATA("COSTO QUIMICA ",$BC$4) -> 2936226.5 | AJ25: 21 | AK25: 880 | AL25: 4173.0767 | AM25: 5250 | AP25: 21 | AQ25: 880 | AR25: 11 | AT25: 21 | AU25: 907.615 | AV25: 1000 | AW25: 137.01998 | AY25: 21 | AZ25: 907.615 | BA25: 16.502091 | BC25: 21 | BD25: 907.615 | BE25: 16.502091 | BF25: 124361.39 | BH25: 21 | BI25: 880 | BJ25: 3672307.5
AJ26: 22 | AK26: 0 | AL26: 0 | AM26: 5250 | AP26: 22 | AQ26: 0 | AR26: 0 | AT26: 22 | AU26: 878.961 | AV26: 1000 | AW26: 91 | AY26: 22 | AZ26: 878.961 | BA26: 15.981109 | BC26: 22 | BD26: 878.961 | BE26: 15.981109 | BF26: 79985.451 | BH26: 22 | BI26: 0 | BJ26: 614800
AJ27: 23 | AK27: 720 | AL27: 4786.7604 | AM27: 5250 | AP27: 23 | AQ27: 720 | AR27: 9 | AT27: 23 | AU27: 576.231 | AV27: 1000 | AW27: 91 | AY27: 23 | AZ27: 576.231 | BA27: 10.476927 | BC27: 23 | BD27: 576.231 | BE27: 10.476927 | BF27: 52437.021 | BH27: 23 | BI27: 720 | BJ27: 3446467.5
AJ28: 24 | AK28: 1120 | AL28: 4312.2946 | AM28: 5250 | AP28: 24 | AQ28: 1120 | AR28: 14 | AT28: 24 | AU28: 0 | AV28: 1000 | AW28: 0 | AY28: 24 | AZ28: 0 | BA28: 0 | BC28: 24 | BD28: 0 | BE28: 0 | BF28: 0 | BH28: 24 | BI28: 1120 | BJ28: 4829770
AJ29: 25 | AK29: 1440 | AL29: 3124.6493 | AM29: 5250 | AP29: 25 | AQ29: 1440 | AR29: 18 | AT29: 25 | AU29: 0 | AV29: 1000 | AW29: 0 | AY29: 25 | AZ29: 0 | BA29: 0 | BC29: 25 | BD29: 0 | BE29: 0 | BF29: 0 | BH29: 25 | BI29: 1440 | BJ29: 4499495
AJ30: 26 | AK30: 1760 | AL30: 2749.6989 | AM30: 5250 | AP30: 26 | AQ30: 1760 | AR30: 22 | AT30: 26 | AU30: 442.12 | AV30: 1000 | AW30: 91 | AY30: 26 | AZ30: 442.12 | BA30: 6.316 | BC30: 26 | BD30: 442.12 | BE30: 6.316 | BF30: 40232.92 | BH30: 26 | BI30: 1760 | BJ30: 4839470
AJ31: 27 | AK31: 1440 | AL31: 3432.7483 | AM31: 5250 | AP31: 27 | AQ31: 1440 | AR31: 18 | AT31: 27 | AU31: 640.018 | AV31: 1000 | AW31: 91 | AY31: 27 | AZ31: 640.018 | BA31: 9.6972424 | BC31: 27 | BD31: 640.018 | BE31: 9.6972424 | BF31: 58241.638 | BH31: 27 | BI31: 1440 | BJ31: 4943157.5
AJ32: 28 | AK32: 960 | AL32: 4258.4714 | AM32: 5250 | AP32: 28 | AQ32: 960 | AR32: 12 | AT32: 28 | AU32: 1038.94 | AV32: 1000 | AW32: 91 | AY32: 28 | AZ32: 1038.94 | BA32: 15.983692 | BC32: 28 | BD32: 1038.94 | BE32: 15.983692 | BF32: 94543.54 | BH32: 28 | BI32: 960 | BJ32: 4088132.5
AJ33: Total general | AK33: 30080 | AL33: 3239.6917 | AM33: 5250 | AP33: Total general | AQ33: 30080 | AR33: 389 | AT33: 29 | AU33: 1064.713 | AV33: 1000 | AW33: 91 | AY33: 29 | AZ33: 1064.713 | BA33: 18.728119 | BC33: 29 | BD33: 1064.713 | BE33: 18.728119 | BF33: 96888.883 | BH33: Total general | BI33: 30080 | BJ33: 97449928
AT34: 30 | AU34: 1257.157 | AV34: 1000 | AW34: 91 | AY34: 30 | AZ34: 1257.157 | BA34: 20.952617 | BC34: 30 | BD34: 1257.157 | BE34: 20.952617 | BF34: 114401.29
AT35: 31 | AU35: 665.323 | AV35: 1000 | AW35: 91 | AY35: 31 | AZ35: 665.323 | BA35: 12.55832 | BC35: 31 | BD35: 665.323 | BE35: 12.55832 | BF35: 60544.393
AT36: Total general | AU36: 14633.579 | AV36: 1000 | AW36: 200.64992 | AY36: Total general | AZ36: 14633.579 | BA36: 257.42341 | BC36: Total general | BD36: 14633.579 | BE36: 257.42341 | BF36: 2936226.5

Sheet GRAFICAS
V1: FECHA | W1: (Varios elementos) | AD1: FECHA | AE1: (Varios elementos) | AL1: FECHA | AM1: (Varios elementos) | AV1: PRECIO (KG) ACIDO | AW1: PRECIO (KG) COAGULANTE | AX1: PRECIO (KG) DECOLORANTE | AY1: PRECIO (KG) ANIONICO | AZ1: PRECIO (KG) CATIONICO
AV2: 830 | AW2: 2900 | AX2: 6295 | AY2: 19050 | AZ2: 22050
V3: DIA | W3: COF 494 - PPM POL CATIONICO | X3: COF 440 - PPM POL ANIONICO | Y3: COF 280 - PPM ACIDO | Z3: COF 235 - PPM COAGULANTE | AA3: COF 255 - PPM DECOLORANTE | AB3: INDICADOR $m3 | AD3: DIA | AE3: CONSUMO POL CATIONICO (KG) | AF3: CONSUMO POL ANIONICO (KG) | AG3: CONSUMO LITROS ACIDO (L) | AH3: CONSUMO LITROS COAGULANTE (L) | AI3: CONSUMO LITROS DECOLORANTE (L) | AJ3: INDICADOR $m3 | AL3: DIA | AM3: KG POL CATIONICO | AN3: KG POL ANIONICO | AO3: KG ACIDO | AP3: KG COAGULANTE | AQ3: KG DECOLORANTE | AR3: INDICADOR $m3 | AT3: DIA | AU3: INDICADOR $m3 | AV3: INDICADOR $ACIDO/M3 | AW3: INDICADOR $COAGULANTE/M3 | AX3: INDICADOR $DECOLORANTE/M3 | AY3: INDICADOR $POL ANIONICO/ M3 | AZ3: INDICADOR $POL CATIONICO / M3
P4: COF 255 - DECOLORANTE | V4: 1 | W4: 0 | X4: 0 | Y4: 0 | Z4: 0 | AA4: 0 | AB4: 0 | AD4: 1 | AE4: 0 | AF4: 0 | AG4: 0 | AH4: 0 | AI4: 0 | AJ4: 0 | AL4: 1 | AM4: 0 | AN4: 0 | AO4: 0 | AP4: 0 | AQ4: 0 | AR4: 0 | AT4: 1 | AU4: 0 | AV4: 0 | AW4: 0 | AX4: 0 | AY4: 0 | AZ4: 0
Q5: PPM | R5: L/DIA | S5: KG/DIA | T5: $ | V5: 2 | W5: 3.3333333 | X5: 0.55555556 | Y5: 391.11111 | Z5: 728.88889 | AA5: 151.11111 | AB5: 4748.1533 | AD5: 2 | AE5: 15 | AF5: 2.5 | AG5: 440 | AH5: 820 | AI5: 170 | AJ5: 4748.1533 | AL5: 2 | AM5: 15 | AN5: 2.5 | AO5: 572 | AP5: 1086.5 | AQ5: 212.5 | AR5: 4748.1533 | AT5: 2 | AU5: 4748.1533 | AV5: 422.00889 | AW5: 2800.7556 | AX5: 1189.0556 | AY5: 42.333333 | AZ5: 294
P6: MINIMO | Q6: =_xlfn.MINIFS(AA4:AA23,AA4:AA23,"<>0") -> 17.777778 | R6: =_xlfn.MINIFS(AI4:AI23,AI4:AI23,"<>0") -> 20 | S6: =_xlfn.MINIFS(AQ4:AQ23,AQ4:AQ23,"<>0") -> 25 | T6: =_xlfn.MINIFS(AX4:AX23,AX4:AX23,"<>0") -> 139.88889 | V6: 3 | W6: 1.5151515 | X6: 1.1363636 | Y6: 333.33333 | Z6: 460.60606 | AA6: 175.75758 | AB6: 3732.7652 | AD6: 3 | AE6: 10 | AF6: 7.5 | AG6: 550 | AH6: 760 | AI6: 290 | AJ6: 3732.7652 | AL6: 3 | AM6: 10 | AN6: 7.5 | AO6: 715 | AP6: 1007 | AQ6: 362.5 | AR6: 3732.7652 | AT6: 3 | AU6: 3732.7652 | AV6: 359.66667 | AW6: 1769.8788 | AX6: 1382.9924 | AY6: 86.590909 | AZ6: 133.63636
P7: MAXIMO | Q7: =MAX(AA4:AA23) -> 208.33333 | R7: =MAX(AI4:AI23) -> 290 | S7: =MAX(AQ4:AQ23) -> 362.5 | T7: =MAX(AX4:AX23) -> 1639.3229 | V7: 4 | W7: 0 | X7: 0 | Y7: 552.38095 | Z7: 495.2381 | AA7: 158.73016 | AB7: 3747.9794 | AD7: 4 | AE7: 0 | AF7: 0 | AG7: 870 | AH7: 780 | AI7: 250 | AJ7: 3747.9794 | AL7: 4 | AM7: 0 | AN7: 0 | AO7: 1131 | AP7: 1033.5 | AQ7: 312.5 | AR7: 3747.9794 | AT7: 4 | AU7: 3747.9794 | AV7: 596.01905 | AW7: 1902.9524 | AX7: 1249.0079 | AY7: 0 | AZ7: 0
P8: PROMEDIO | Q8: =AVERAGEIF(AA4:AA23,"<>0") -> 111.91763 | R8: =AVERAGEIF(AI4:AI23,"<>0") -> 145.29412 | S8: =AVERAGEIF(AQ4:AQ23,"<>0") -> 181.61765 | T8: =AVERAGEIF(AX4:AX23,"<>0") -> 880.65188 | V8: 5 | W8: 1.6666667 | X8: 1.6666667 | Y8: 200 | Z8: 353.33333 | AA8: 133.33333 | AB8: 2896.65 | AD8: 5 | AE8: 10 | AF8: 10 | AG8: 300 | AH8: 530 | AI8: 200 | AJ8: 2896.65 | AL8: 5 | AM8: 10 | AN8: 10 | AO8: 390 | AP8: 702.25 | AQ8: 250 | AR8: 2896.65 | AT8: 5 | AU8: 2896.65 | AV8: 215.8 | AW8: 1357.6833 | AX8: 1049.1667 | AY8: 127 | AZ8: 147
P9: TOTAL CONSUMIDO | R9: =GETPIVOTDATA("CONSUMO LITROS DECOLORANTE (L) ",$AD$3) -> 3610 | S9: =GETPIVOTDATA("KG DECOLORANTE ",$AL$3) -> 4512.5 | T9: =S9*AX2 -> 28406188 | V9: 6 | W9: 3.7037037 | X9: 0.92592593 | Y9: 148.14815 | Z9: 585.18519 | AA9: 155.55556 | AB9: 4029.6759 | AD9: 6 | AE9: 20 | AF9: 5 | AG9: 200 | AH9: 790 | AI9: 210 | AJ9: 4029.6759 | AL9: 6 | AM9: 20 | AN9: 5 | AO9: 260 | AP9: 1046.75 | AQ9: 262.5 | AR9: 4029.6759 | AT9: 6 | AU9: 4029.6759 | AV9: 159.85185 | AW9: 2248.5741 | AX9: 1224.0278 | AY9: 70.555556 | AZ9: 326.66667
V10: 7 | W10: 2.7777778 | X10: 2.7777778 | Y10: 277.77778 | Z10: 555.55556 | AA10: 66.666667 | AB10: 3415.6944 | AD10: 7 | AE10: 10 | AF10: 10 | AG10: 250 | AH10: 500 | AI10: 60 | AJ10: 3415.6944 | AL10: 7 | AM10: 10 | AN10: 10 | AO10: 325 | AP10: 662.5 | AQ10: 75 | AR10: 3415.6944 | AT10: 7 | AU10: 3415.6944 | AV10: 299.72222 | AW10: 2134.7222 | AX10: 524.58333 | AY10: 211.66667 | AZ10: 245
P11: COF 235 - COAGULANTE | V11: 8 | W11: 0 | X11: 0 | Y11: 0 | Z11: 0 | AA11: 0 | AB11: 0 | AD11: 8 | AE11: 0 | AF11: 5 | AG11: 0 | AH11: 0 | AI11: 0 | AJ11: 0 | AL11: 8 | AM11: 0 | AN11: 5 | AO11: 0 | AP11: 0 | AQ11: 0 | AR11: 0 | AT11: 8 | AU11: 0 | AV11: 0 | AW11: 0 | AX11: 0 | AY11: 0 | AZ11: 0
Q12: PPM | R12: L/DIA | S12: KG/DIA | T12: $ | V12: 9 | W12: 2.7777778 | X12: 1.8518519 | Y12: 111.11111 | Z12: 518.51852 | AA12: 103.7037 | AB12: 3314.4259 | AD12: 9 | AE12: 15 | AF12: 10 | AG12: 150 | AH12: 700 | AI12: 140 | AJ12: 3314.4259 | AL12: 9 | AM12: 15 | AN12: 10 | AO12: 195 | AP12: 927.5 | AQ12: 175 | AR12: 3314.4259 | AT12: 9 | AU12: 3314.4259 | AV12: 119.88889 | AW12: 1992.4074 | AX12: 816.01852 | AY12: 141.11111 | AZ12: 245
P13: MINIMO | Q13: =_xlfn.MINIFS(Z4:Z23,Z4:Z23,"<>0") -> 231.57895 | R13: =_xlfn.MINIFS(AH4:AH23,AH4:AH23,"<>0") -> 300 | S13: =_xlfn.MINIFS(AP4:AP23,AP4:AP23,"<>0") -> 397.5 | T13: =_xlfn.MINIFS(AW4:AW23,AW4:AW23,"<>0") -> 889.84211 | V13: 10 | W13: 2.6315789 | X13: 0.87719298 | Y13: 189.47368 | Z13: 231.57895 | AA13: 56.140351 | AB13: 1834.986 | AD13: 10 | AE13: 15 | AF13: 5 | AG13: 270 | AH13: 330 | AI13: 80 | AJ13: 1834.986 | AL13: 10 | AM13: 15 | AN13: 5 | AO13: 351 | AP13: 437.25 | AQ13: 100 | AR13: 1834.986 | AT13: 10 | AU13: 1834.986 | AV13: 204.44211 | AW13: 889.84211 | AX13: 441.75439 | AY13: 66.842105 | AZ13: 232.10526
P14: MAXIMO | Q14: =MAX(Z4:Z23) -> 728.88889 | R14: =MAX(AH4:AH23) -> 860 | S14: =MAX(AP4:AP23) -> 1139.5 | T14: =MAX(AW4:AW23) -> 2800.7556 | V14: 11 | W14: 2.9411765 | X14: 1.9607843 | Y14: 235.29412 | Z14: 250.98039 | AA14: 86.27451 | AB14: 2305.9706 | AD14: 11 | AE14: 15 | AF14: 10 | AG14: 300 | AH14: 320 | AI14: 110 | AJ14: 2305.9706 | AL14: 11 | AM14: 15 | AN14: 10 | AO14: 390 | AP14: 424 | AQ14: 137.5 | AR14: 2305.9706 | AT14: 11 | AU14: 2305.9706 | AV14: 253.88235 | AW14: 964.39216 | AX14: 678.87255 | AY14: 149.41176 | AZ14: 259.41176
P15: PROMEDIO | Q15: =AVERAGEIF(Z4:Z23,"<>0") -> 426.7616 | R15: =AVERAGEIF(AH4:AH23,"<>0") -> 551.875 | S15: =AVERAGEIF(AP4:AP23,"<>0") -> 731.23438 | T15: =AVERAGEIF(AW4:AW23,"<>0") -> 1639.8315 | V15: 12 | W15: 3.125 | X15: 2.0833333 | Y15: 275 | Z15: 333.33333 | AA15: 41.666667 | AB15: 2339.7979 | AD15: 12 | AE15: 15 | AF15: 10 | AG15: 330 | AH15: 400 | AI15: 50 | AJ15: 2339.7979 | AL15: 12 | AM15: 15 | AN15: 10 | AO15: 429 | AP15: 530 | AQ15: 62.5 | AR15: 2339.7979 | AT15: 12 | AU15: 2339.7979 | AV15: 296.725 | AW15: 1280.8333 | AX15: 327.86458 | AY15: 158.75 | AZ15: 275.625
P16: TOTAL CONSUMIDO | R16: =GETPIVOTDATA("CONSUMO LITROS COAGULANTE (L) ",$AD$3) -> 12980 | S16: =GETPIVOTDATA("KG COAGULANTE ",$AL$3) -> 17198.5 | T16: =S16*AW2 -> 49875650 | V16: 13 | W16: 3.3333333 | X16: 1.1111111 | Y16: 275.55556 | Z16: 444.44444 | AA16: 133.33333 | AB16: 3432.9356 | AD16: 13 | AE16: 15 | AF16: 5 | AG16: 310 | AH16: 500 | AI16: 150 | AJ16: 3432.9356 | AL16: 13 | AM16: 15 | AN16: 5 | AO16: 403 | AP16: 662.5 | AQ16: 187.5 | AR16: 3432.9356 | AT16: 13 | AU16: 3432.9356 | AV16: 297.32444 | AW16: 1707.7778 | AX16: 1049.1667 | AY16: 84.666667 | AZ16: 294
V17: 14 | W17: 2.2222222 | X17: 2.2222222 | Y17: 80 | Z17: 435.55556 | AA17: 17.777778 | AB17: 2265.1644 | AD17: 14 | AE17: 10 | AF17: 10 | AG17: 90 | AH17: 490 | AI17: 20 | AJ17: 2265.1644 | AL17: 14 | AM17: 10 | AN17: 10 | AO17: 117 | AP17: 649.25 | AQ17: 25 | AR17: 2265.1644 | AT17: 14 | AU17: 2265.1644 | AV17: 86.32 | AW17: 1673.6222 | AX17: 139.88889 | AY17: 169.33333 | AZ17: 196
P18: COF 280 - ACIDIFICANTE | V18: 15 | W18: 0 | X18: 0 | Y18: 0 | Z18: 0 | AA18: 0 | AB18: 0 | AD18: 15 | AE18: 0 | AF18: 0 | AG18: 0 | AH18: 0 | AI18: 0 | AJ18: 0 | AL18: 15 | AM18: 0 | AN18: 0 | AO18: 0 | AP18: 0 | AQ18: 0 | AR18: 0 | AT18: 15 | AU18: 0 | AV18: 0 | AW18: 0 | AX18: 0 | AY18: 0 | AZ18: 0
Q19: PPM | R19: L/DIA | S19: KG/DIA | T19: $ | V19: 16 | W19: 2.6041667 | X19: 0.86805556 | Y19: 277.77778 | Z19: 597.22222 | AA19: 125 | AB19: 3873.9757 | AD19: 16 | AE19: 15 | AF19: 5 | AG19: 400 | AH19: 860 | AI19: 180 | AJ19: 3873.9757 | AL19: 16 | AM19: 15 | AN19: 5 | AO19: 520 | AP19: 1139.5 | AQ19: 225 | AR19: 3873.9757 | AT19: 16 | AU19: 3873.9757 | AV19: 299.72222 | AW19: 2294.8264 | AX19: 983.59375 | AY19: 66.145833 | AZ19: 229.6875
P20: MINIMO | Q20: =_xlfn.MINIFS(Y4:Y23,Y4:Y23,"<>0") -> 80 | R20: =_xlfn.MINIFS(AG4:AG23,AG4:AG23,"<>0") -> 90 | S20: =_xlfn.MINIFS(AO4:AO23,AO4:AO23,"<>0") -> 117 | T20: =_xlfn.MINIFS(AV4:AV23,AV4:AV23,"<>0") -> 86.32 | V20: 17 | W20: 3.125 | X20: 1.0416667 | Y20: 208.33333 | Z20: 250 | AA20: 91.666667 | AB20: 2261.7188 | AD20: 17 | AE20: 15 | AF20: 5 | AG20: 250 | AH20: 300 | AI20: 110 | AJ20: 2261.7188 | AL20: 17 | AM20: 15 | AN20: 5 | AO20: 325 | AP20: 397.5 | AQ20: 137.5 | AR20: 2261.7188 | AT20: 17 | AU20: 2261.7188 | AV20: 224.79167 | AW20: 960.625 | AX20: 721.30208 | AY20: 79.375 | AZ20: 275.625
P21: MAXIMO | Q21: =MAX(Y4:Y23) -> 552.38095 | R21: =MAX(AG4:AG23) -> 870 | S21: =MAX(AO4:AO23) -> 1131 | T21: =MAX(AV4:AV23) -> 596.01905 | V21: 18 | W21: 3.90625 | X21: 1.3020833 | Y21: 291.66667 | Z21: 0 | AA21: 208.33333 | AB21: 2397.7812 | AD21: 18 | AE21: 15 | AF21: 5 | AG21: 280 | AH21: 0 | AI21: 200 | AJ21: 2397.7812 | AL21: 18 | AM21: 15 | AN21: 5 | AO21: 364 | AP21: 0 | AQ21: 250 | AR21: 2397.7812 | AT21: 18 | AU21: 2397.7812 | AV21: 314.70833 | AW21: 0 | AX21: 1639.3229 | AY21: 99.21875 | AZ21: 344.53125
P22: PROMEDIO | Q22: =AVERAGEIF(Y4:Y23,"<>0") -> 252.7914 | R22: =AVERAGEIF(AG4:AG23,"<>0") -> 327.05882 | S22: =AVERAGEIF(AO4:AO23,"<>0") -> 425.17647 | T22: =AVERAGEIF(AV4:AV23,"<>0") -> 272.76192 | V22: 19 | W22: 3.125 | X22: 1.0416667 | Y22: 266.66667 | Z22: 308.33333 | AA22: 116.66667 | AB22: 2745.525 | AD22: 19 | AE22: 15 | AF22: 5 | AG22: 320 | AH22: 370 | AI22: 140 | AJ22: 2745.525 | AL22: 19 | AM22: 15 | AN22: 5 | AO22: 416 | AP22: 490.25 | AQ22: 175 | AR22: 2745.525 | AT22: 19 | AU22: 2745.525 | AV22: 287.73333 | AW22: 1184.7708 | AX22: 918.02083 | AY22: 79.375 | AZ22: 275.625
P23: TOTAL CONSUMIDO | R23: =GETPIVOTDATA("CONSUMO LITROS ACIDO (L) ",$AD$3) -> 8210 | S23: =GETPIVOTDATA("KG ACIDO ",$AL$3) -> 10673 | T23: =AV2*S23 -> 8858590 | V23: 20 | W23: 2.7573529 | X23: 0.91911765 | Y23: 183.82353 | Z23: 279.41176 | AA23: 80.882353 | AB23: 2221.6636 | AD23: 20 | AE23: 15 | AF23: 5 | AG23: 250 | AH23: 380 | AI23: 110 | AJ23: 2221.6636 | AL23: 20 | AM23: 15 | AN23: 5 | AO23: 325 | AP23: 503.5 | AQ23: 137.5 | AR23: 2221.6636 | AT23: 20 | AU23: 2221.6636 | AV23: 198.34559 | AW23: 1073.6397 | AX23: 636.44301 | AY23: 70.036765 | AZ23: 243.19853
V24: 21 | W24: 4.2613636 | X24: 1.4204545 | Y24: 318.18182 | Z24: 568.18182 | AA24: 147.72727 | AB24: 4173.0767 | AD24: 21 | AE24: 15 | AF24: 5 | AG24: 280 | AH24: 500 | AI24: 130 | AJ24: 4173.0767 | AL24: 21 | AM24: 15 | AN24: 5 | AO24: 364 | AP24: 662.5 | AQ24: 162.5 | AR24: 4173.0767 | AT24: 21 | AU24: 4173.0767 | AV24: 343.31818 | AW24: 2183.2386 | AX24: 1162.429 | AY24: 108.23864 | AZ24: 375.85227
P25: COF 440 - POLIMERO ANIONICO | V25: 22 | W25: 0 | X25: 0 | Y25: 0 | Z25: 0 | AA25: 0 | AB25: 0 | AD25: 22 | AE25: 0 | AF25: 0 | AG25: 0 | AH25: 160 | AI25: 0 | AJ25: 0 | AL25: 22 | AM25: 0 | AN25: 0 | AO25: 0 | AP25: 212 | AQ25: 0 | AR25: 0 | AT25: 22 | AU25: 0 | AV25: 0 | AW25: 0 | AX25: 0 | AY25: 0 | AZ25: 0
Q26: PPM | R26: KG/DIA | S26: $ | V26: 23 | W26: 5.2083333 | X26: 3.4722222 | Y26: 722.22222 | Z26: 541.66667 | AA26: 152.77778 | AB26: 4786.7604 | AD26: 23 | AE26: 15 | AF26: 10 | AG26: 520 | AH26: 390 | AI26: 110 | AJ26: 4786.7604 | AL26: 23 | AM26: 15 | AN26: 10 | AO26: 676 | AP26: 516.75 | AQ26: 137.5 | AR26: 4786.7604 | AT26: 23 | AU26: 4786.7604 | AV26: 779.27778 | AW26: 2081.3542 | AX26: 1202.1701 | AY26: 264.58333 | AZ26: 459.375
P27: MINIMO | Q27: =_xlfn.MINIFS(X4:X23,X4:X23,"<>0") -> 0.55555556 | R27: =_xlfn.MINIFS(AN4:AN23,AN4:AN23,"<>0") -> 2.5 | S27: =_xlfn.MINIFS(AY4:AY23,AY4:AY23,"<>0") -> 42.333333 | V27: 24 | W27: 3.3482143 | X27: 1.1160714 | Y27: 116.07143 | Z27: 625 | AA27: 178.57143 | AB27: 4312.2946 | AD27: 24 | AE27: 15 | AF27: 5 | AG27: 130 | AH27: 700 | AI27: 200 | AJ27: 4312.2946 | AL27: 24 | AM27: 15 | AN27: 5 | AO27: 169 | AP27: 927.5 | AQ27: 250 | AR27: 4312.2946 | AT27: 24 | AU27: 4312.2946 | AV27: 125.24107 | AW27: 2401.5625 | AX27: 1405.1339 | AY27: 85.044643 | AZ27: 295.3125
P28: MAXIMO | Q28: =MAX(X4:X23) -> 2.7777778 | R28: =MAX(AN4:AN23) -> 10 | S28: =MAX(AY4:AY23) -> 211.66667 | V28: 25 | W28: 2.6041667 | X28: 1.7361111 | Y28: 125 | Z28: 541.66667 | AA28: 69.444444 | AB28: 3124.6493 | AD28: 25 | AE28: 15 | AF28: 10 | AG28: 180 | AH28: 780 | AI28: 100 | AJ28: 3124.6493 | AL28: 25 | AM28: 15 | AN28: 10 | AO28: 234 | AP28: 1033.5 | AQ28: 125 | AR28: 3124.6493 | AT28: 25 | AU28: 3124.6493 | AV28: 134.875 | AW28: 2081.3542 | AX28: 546.44097 | AY28: 132.29167 | AZ28: 229.6875
P29: PROMEDIO | Q29: =AVERAGEIF(X4:X23,"<>0") -> 1.396336 | R29: =AVERAGEIF(AN4:AN23,"<>0") -> 6.7647059 | S29: =AVERAGEIF(AY4:AY23,"<>0") -> 106.4008 | V29: 26 | W29: 2.1306818 | X29: 0.71022727 | Y29: 443.18182 | Z29: 295.45455 | AA29: 113.63636 | AB29: 2749.6989 | AD29: 26 | AE29: 15 | AF29: 5 | AG29: 780 | AH29: 520 | AI29: 200 | AJ29: 2749.6989 | AL29: 26 | AM29: 15 | AN29: 5 | AO29: 1014 | AP29: 689 | AQ29: 250 | AR29: 2749.6989 | AT29: 26 | AU29: 2749.6989 | AV29: 478.19318 | AW29: 1135.2841 | AX29: 894.17614 | AY29: 54.119318 | AZ29: 187.92614
P30: TOTAL CONSUMIDO | R30: =GETPIVOTDATA("KG POL ANIONICO ",$AL$3) -> 165 | S30: =R30*AY2 -> 3143250 | V30: 27 | W30: 2.6041667 | X30: 1.7361111 | Y30: 298.61111 | Z30: 416.66667 | AA30: 145.83333 | AB30: 3432.7483 | AD30: 27 | AE30: 15 | AF30: 10 | AG30: 430 | AH30: 600 | AI30: 210 | AJ30: 3432.7483 | AL30: 27 | AM30: 15 | AN30: 10 | AO30: 559 | AP30: 795 | AQ30: 262.5 | AR30: 3432.7483 | AT30: 27 | AU30: 3432.7483 | AV30: 322.20139 | AW30: 1601.0417 | AX30: 1147.526 | AY30: 132.29167 | AZ30: 229.6875
V31: 28 | W31: 2.6041667 | X31: 1.3020833 | Y31: 343.75 | Z31: 520.83333 | AA31: 197.91667 | AB31: 4258.4714 | AD31: 28 | AE31: 10 | AF31: 5 | AG31: 330 | AH31: 500 | AI31: 190 | AJ31: 4258.4714 | AL31: 28 | AM31: 10 | AN31: 5 | AO31: 429 | AP31: 662.5 | AQ31: 237.5 | AR31: 4258.4714 | AT31: 28 | AU31: 4258.4714 | AV31: 370.90625 | AW31: 2001.3021 | AX31: 1557.3568 | AY31: 99.21875 | AZ31: 229.6875
P32: COF 494 - POLIMERO CATIONICO | V32: Total general | W32: 2.7011303 | X32: 1.3713431 | Y32: 272.93883 | Z32: 431.51596 | AA32: 120.0133 | AB32: 3239.6917 | AD32: Total general | AE32: 325 | AF32: 165 | AG32: 8210 | AH32: 12980 | AI32: 3610 | AJ32: 3239.6917 | AL32: Total general | AM32: 325 | AN32: 165 | AO32: 10673 | AP32: 17198.5 | AQ32: 4512.5 | AR32: 3239.6917 | AT32: Total general | AU32: 3239.6917 | AV32: 294.501 | AW32: 1658.1001 | AX32: 944.35464 | AY32: 104.49634 | AZ32: 238.23969
Q33: PPM | R33: KG/DIA | S33: $
P34: MINIMO | Q34: =_xlfn.MINIFS(W4:W23,W4:W23,"<>0") -> 1.5151515 | R34: =_xlfn.MINIFS(AM4:AM23,AM4:AM23,"<>0") -> 10 | S34: =_xlfn.MINIFS(AZ4:AZ23,AZ4:AZ23,"<>0") -> 133.63636
P35: MAXIMO | Q35: =MAX(W4:W23) -> 3.90625 | R35: =MAX(AM4:AM23) -> 20 | S35: =MAX(AZ4:AZ23) -> 344.53125
P36: PROMEDIO | Q36: =AVERAGEIF(W4:W23,"<>0") -> 2.8465932 | R36: =AVERAGEIF(AM4:AM23,"<>0") -> 14.0625 | S36: =AVERAGEIF(AZ4:AZ23,"<>0") -> 251.06952
P37: TOTAL CONSUMIDO | R37: =GETPIVOTDATA("KG POL CATIONICO ",$AL$3) -> 325 | S37: =R37*AZ2 -> 7166250
B80: REMOCIÓN DQO mg/L
B81: DQO INICIAL (mg/L) | C81: DQO SALIDA (mg/L) | D81: DQO REMOMOVIDA (mg/L) | E81: KG REMOVIDOS DQO / M3 | F81: M3 TRATADOS | G81: TOTAL KG DQO REMOVIDOS | H81: $TRATAMIENTO | I81: $ REMOVER KG DQO
B82: =E97 -> 1414 | C82: =F97 -> 659 | D82: =+B82-C82 -> 755 | E82: =(D82/1000000)*1000 -> 0.755 | F82: ='DB QUIMICA'!Z8 -> 30080 | G82: =+F82*E82 -> 22710.4 | H82: ='DB QUIMICA'!AD8 -> 97449928 | I82: =H82/G82 -> 4290.9824
...

Sheet INFORME CALIDAD
A1: CALIDAD DE AGUA Vs COSTOS
A2: PANORAMA OPERATIVO
A13: PANORAMA OPERATIVO
A24: 1. COSTO Vs CONSUMO DE PRODUCTOS QUIMICOS
A68: CALIDAD DE AGUA
A86: CALIDAD DE AGUA
A104: $ REMOCIÓN DQO

Sheet CONSUMO QUÍMICA-CAUDALES GEM  
A1: CONSOLIDADO CONSUMO DIARIO QUÍMICA (Litros)
B2: DIAS
A3: PRODUCTOS QUÍMICOS | B3: 1 | C3: 2 | D3: 3 | E3: 4 | F3: 5 | G3: 6 | H3: 7 | I3: 8 | J3: 9 | K3: 10 | L3: 11 | M3: 12 | N3: 13 | O3: 14 | P3: 15 | Q3: 16 | R3: 17 | S3: 18 | T3: 19 | U3: 20 | V3: 21 | W3: 22 | X3: 23 | Y3: 24 | Z3: 25 | AA3: 26 | AB3: 27 | AC3: 28 | AD3: Total general
A4: COF 280 ACIDO (L) | B4: 0 | C4: 440 | D4: 550 | E4: 870 | F4: 300 | G4: 200 | H4: 250 | I4: 0 | J4: 150 | K4: 270 | L4: 300 | M4: 330 | N4: 310 | O4: 90 | P4: 0 | Q4: 400 | R4: 250 | S4: 280 | T4: 320 | U4: 250 | V4: 280 | W4: 0 | X4: 520 | Y4: 130 | Z4: 180 | AA4: 780 | AB4: 430 | AC4: 330 | AD4: 8210
A5: COF 235 COAGULANTE (L) | B5: 0 | C5: 820 | D5: 760 | E5: 780 | F5: 530 | G5: 790 | H5: 500 | I5: 0 | J5: 700 | K5: 330 | L5: 320 | M5: 400 | N5: 500 | O5: 490 | P5: 0 | Q5: 860 | R5: 300 | S5: 0 | T5: 370 | U5: 380 | V5: 500 | W5: 160 | X5: 390 | Y5: 700 | Z5: 780 | AA5: 520 | AB5: 600 | AC5: 500 | AD5: 12980
A6: COF 255 DECOLORANTE (L) | B6: 0 | C6: 170 | D6: 290 | E6: 250 | F6: 200 | G6: 210 | H6: 60 | I6: 0 | J6: 140 | K6: 80 | L6: 110 | M6: 50 | N6: 150 | O6: 20 | P6: 0 | Q6: 180 | R6: 110 | S6: 200 | T6: 140 | U6: 110 | V6: 130 | W6: 0 | X6: 110 | Y6: 200 | Z6: 100 | AA6: 200 | AB6: 210 | AC6: 190 | AD6: 3610
A7: COF 440 POL ANIONICO (KG) | B7: 0 | C7: 2.5 | D7: 7.5 | E7: 0 | F7: 10 | G7: 5 | H7: 10 | I7: 5 | J7: 10 | K7: 5 | L7: 10 | M7: 10 | N7: 5 | O7: 10 | P7: 0 | Q7: 5 | R7: 5 | S7: 5 | T7: 5 | U7: 5 | V7: 5 | W7: 0 | X7: 10 | Y7: 5 | Z7: 10 | AA7: 5 | AB7: 10 | AC7: 5 | AD7: 165
A8: COF 494 POL CATIONICO (KG) | B8: 0 | C8: 15 | D8: 10 | E8: 0 | F8: 10 | G8: 20 | H8: 10 | I8: 0 | J8: 15 | K8: 15 | L8: 15 | M8: 15 | N8: 15 | O8: 10 | P8: 0 | Q8: 15 | R8: 15 | S8: 15 | T8: 15 | U8: 15 | V8: 15 | W8: 0 | X8: 15 | Y8: 15 | Z8: 15 | AA8: 15 | AB8: 15 | AC8: 10 | AD8: 325
A9: CAUDAL TOTAL TRATADO GEM | B9: 0 | C9: 1125 | D9: 1650 | E9: 1575 | F9: 1500 | G9: 1350 | H9: 900 | I9: 0 | J9: 1350 | K9: 1425 | L9: 1275 | M9: 1200 | N9: 1125 | O9: 1125 | P9: 0 | Q9: 1440 | R9: 1200 | S9: 960 | T9: 1200 | U9: 1360 | V9: 880 | W9: 0 | X9: 720 | Y9: 1120 | Z9: 1440 | AA9: 1760 | AB9: 1440 | AC9: 960 | AD9: 30080
A10: INDICADOR $m3 | B10: 0 | C10: 4748.1533 | D10: 3732.7652 | E10: 3747.9794 | F10: 2896.65 | G10: 4029.6759 | H10: 3415.6944 | I10: 0 | J10: 3314.4259 | K10: 1834.986 | L10: 2305.9706 | M10: 2339.7979 | N10: 3432.9356 | O10: 2265.1644 | P10: 0 | Q10: 3873.9757 | R10: 2261.7188 | S10: 2397.7812 | T10: 2745.525 | U10: 2221.6636 | V10: 4173.0767 | W10: 0 | X10: 4786.7604 | Y10: 4312.2946 | Z10: 3124.6493 | AA10: 2749.6989 | AB10: 3432.7483 | AC10: 4258.4714 | AD10: 3239.6917
A12: CONSOLIDADO CONSUMO DIARIO QUÍMICA (Kg)
B13: DIAS
A14: PRODUCTOS QUÍMICOS | B14: 1 | C14: 2 | D14: 3 | E14: 4 | F14: 5 | G14: 6 | H14: 7 | I14: 8 | J14: 9 | K14: 10 | L14: 11 | M14: 12 | N14: 13 | O14: 14 | P14: 15 | Q14: 16 | R14: 17 | S14: 18 | T14: 19 | U14: 20 | V14: 21 | W14: 22 | X14: 23 | Y14: 24 | Z14: 25 | AA14: 26 | AB14: 27 | AC14: 28 | AD14: Total general
A15: COF 280 - KG ACIDO | B15: 0 | C15: 572 | D15: 715 | E15: 1131 | F15: 390 | G15: 260 | H15: 325 | I15: 0 | J15: 195 | K15: 351 | L15: 390 | M15: 429 | N15: 403 | O15: 117 | P15: 0 | Q15: 520 | R15: 325 | S15: 364 | T15: 416 | U15: 325 | V15: 364 | W15: 0 | X15: 676 | Y15: 169 | Z15: 234 | AA15: 1014 | AB15: 559 | AC15: 429 | AD15: 10673
A16: COF 235 - KG COAGULANTE | B16: 0 | C16: 1086.5 | D16: 1007 | E16: 1033.5 | F16: 702.25 | G16: 1046.75 | H16: 662.5 | I16: 0 | J16: 927.5 | K16: 437.25 | L16: 424 | M16: 530 | N16: 662.5 | O16: 649.25 | P16: 0 | Q16: 1139.5 | R16: 397.5 | S16: 0 | T16: 490.25 | U16: 503.5 | V16: 662.5 | W16: 212 | X16: 516.75 | Y16: 927.5 | Z16: 1033.5 | AA16: 689 | AB16: 795 | AC16: 662.5 | AD16: 17198.5
A17: COF 255 - KG DECOLORANTE | B17: 0 | C17: 212.5 | D17: 362.5 | E17: 312.5 | F17: 250 | G17: 262.5 | H17: 75 | I17: 0 | J17: 175 | K17: 100 | L17: 137.5 | M17: 62.5 | N17: 187.5 | O17: 25 | P17: 0 | Q17: 225 | R17: 137.5 | S17: 250 | T17: 175 | U17: 137.5 | V17: 162.5 | W17: 0 | X17: 137.5 | Y17: 250 | Z17: 125 | AA17: 250 | AB17: 262.5 | AC17: 237.5 | AD17: 4512.5
A18: COF 440 - KG POL ANIONICO | B18: 0 | C18: 2.5 | D18: 7.5 | E18: 0 | F18: 10 | G18: 5 | H18: 10 | I18: 5 | J18: 10 | K18: 5 | L18: 10 | M18: 10 | N18: 5 | O18: 10 | P18: 0 | Q18: 5 | R18: 5 | S18: 5 | T18: 5 | U18: 5 | V18: 5 | W18: 0 | X18: 10 | Y18: 5 | Z18: 10 | AA18: 5 | AB18: 10 | AC18: 5 | AD18: 165
A19: COF 494 - KG POL CATIONICO | B19: 0 | C19: 15 | D19: 10 | E19: 0 | F19: 10 | G19: 20 | H19: 10 | I19: 0 | J19: 15 | K19: 15 | L19: 15 | M19: 15 | N19: 15 | O19: 10 | P19: 0 | Q19: 15 | R19: 15 | S19: 15 | T19: 15 | U19: 15 | V19: 15 | W19: 0 | X19: 15 | Y19: 15 | Z19: 15 | AA19: 15 | AB19: 15 | AC19: 10 | AD19: 325
A20: CAUDAL TOTAL TRATADO GEM | B20: 0 | C20: 1125 | D20: 1650 | E20: 1575 | F20: 1500 | G20: 1350 | H20: 900 | I20: 0 | J20: 1350 | K20: 1425 | L20: 1275 | M20: 1200 | N20: 1125 | O20: 1125 | P20: 0 | Q20: 1440 | R20: 1200 | S20: 960 | T20: 1200 | U20: 1360 | V20: 880 | W20: 0 | X20: 720 | Y20: 1120 | Z20: 1440 | AA20: 1760 | AB20: 1440 | AC20: 960 | AD20: 30080
A21: INDICADOR $m3 | B21: #DIV/0! | C21: 4748.1533 | D21: 3732.7652 | E21: 3747.9794 | F21: 2896.65 | G21: 4029.6759 | H21: 3415.6944 | I21: #DIV/0! | J21: 3314.4259 | K21: 1834.986 | L21: 2305.9706 | M21: 2339.7979 | N21: 3432.9356 | O21: 2265.1644 | P21: #DIV/0! | Q21: 3873.9757 | R21: 2261.7188 | S21: 2397.7812 | T21: 2745.525 | U21: 2221.6636 | V21: 4173.0767 | W21: #DIV/0! | X21: 4786.7604 | Y21: 4312.2946 | Z21: 3124.6493 | AA21: 2749.6989 | AB21: 3432.7483 | AC21: 4258.4714 | AD21: 3239.6917
