Workbook
Name _2_02_2024: #REF!
Name Actual_T2_PROMEDIO: #REF!
Name Actual_T3_PROMEDIO: #REF!
Name Alcalinidad: #REF!
Name Cloruros: #REF!
Name Color: #REF!
Name Color_real_436_nm__Absorbancia: #REF!
Name Color_real_525_nm__Absorbancia: #REF!
Name Color_real_620_nm__Absorbancia: #REF!
Name Conductividad: #REF!
Name Demanda_Bioquímica_de_oxígeno: #REF!
Name Demanda_química_de_oxígeno: #REF!
Name Dureza_Cálcica: #REF!
Name Dureza_Total: #REF!
Name Filtros_Intercambio_Iónico__Entrada__MAX: #REF!
Name Filtros_Intercambio_Iónico__Entrada__MIN: #REF!
Name Filtros_Intercambio_Iónico__Entrada__PROMEDIO: #REF!
Name Filtros_Intercambio_Iónico__Salida__MAX: #REF!
Name Filtros_Intercambio_Iónico__Salida__MIN: #REF!
Name Filtros_Intercambio_Iónico__Salida__PROMEDIO: #REF!
Name Fósforo_Total: #REF!
Name GEM__Salida__MAX: #REF!
Name GEM__Salida__MIN: #REF!
Name GEM__Salida__PROMEDIO: #REF!
Name Grasas___Aceites: #REF!
Name MAXIMOT2: '[1]Tabla datos 1'!#REF!
Name MAXIMOT3: '[1]Tabla datos 1'!#REF!
Name MINIMOT2: '[1]Tabla datos 1'!#REF!
Name MINIMOT3: '[1]Tabla datos 1'!#REF!
Name Nitrógeno_Amoniacal: #REF!
Name Nitrógeno_Total: #REF!
Name Oxígeno_Disuelto: #REF!
Name PARAMETRO: #REF!
Name pH: #REF!
Name pH__Unidades_de_pH: #REF!
Name Reactor_Anóxico__Interna__MAX: #REF!
Name Reactor_Anóxico__Interna__MIN: #REF!
Name Reactor_Anóxico__Interna__PROMEDIO: #REF!
Name Reactor_MBBR__Interno__MAX: #REF!
Name Reactor_MBBR__Interno__MIN: #REF!
Name Reactor_MBBR__Interno__PROMEDIO: #REF!
Name Reactor_MBR_1__Interno__MAX: #REF!
Name Reactor_MBR_1__Interno__MIN: #REF!
Name Reactor_MBR_1__Interno__PROMEDIO: #REF!
Name Reactor_MBR_1__Permeado__MAX: #REF!
Name Reactor_MBR_1__Permeado__MIN: #REF!
Name Reactor_MBR_1__Permeado__PROMEDIO: #REF!
Name Reactor_MBR_2__Interno___MAX: #REF!
Name Reactor_MBR_2__Interno___MIN: #REF!
Name Reactor_MBR_2__Interno___PROMEDIO: #REF!
Name Reactor_MBR_2__Permeado__MAX: #REF!
Name Reactor_MBR_2__Permeado__MIN: #REF!
Name Reactor_MBR_2__Permeado__PROMEDIO: #REF!
Name Sólidos_Disueltos_Totales: #REF!
Name Sólidos_Sedimentables: #REF!
Name Sólidos_Suspendidos_Totales: #REF!
Name Sulfatos: #REF!
Name Tanque_Homogeneizador__Entrada_GEM__MAX: #REF!
Name Tanque_Homogeneizador__Entrada_GEM__MIN: #REF!
Name Tanque_Homogeneizador__Entrada_GEM__PROMEDIO: #REF!

Sheet Balance
A1: FECHA | B1: DIA | C1: ANALISIS TURNO | D1: # TURNO | E1: DILIGENCIAR BITACORA | F1: FINAL COAGULANTE (L) | G1: HORAS DE OPERACIÓN | H1: VOLUMEN TOTAL TRATADO PTAP | I1: VOLUMEN ENVIADO A TK RECIRCULACIÓN | J1: CONSUMO LITROS COAGULANTE (L) | K1: CONSUMO LITROS PERÓXIDO (L) | L1: CONSUMO LITROS ACIDO SULFÚRICO (L) | M1: KG COAGULANTE | N1: KG POL ANIONICO | O1: KG POL CATIONICO | P1: PPM COAGULANTE | Q1: KG PERÓXIDO | R1: KG ÁCIDO | S1: DENSIDAD COAGULANTE | T1: DENSIDAD PERÓXIDO | U1: DENSIDAD ÁCIDO | V1: PRECIO (KG) COAGULANTE | W1: PRECIO (KG) PERÓXIDO | X1: PRECIO (KG) ácido sulfurico | Y1: COSTO OPERATIVO COAGULANTE | Z1: COSTO OPERATIVO PERÓXIDO | AA1: COSTO OPERATIVO ÁCIDO | AB1: COSTO QUIMICA | AC1: LIMITE INDICADOR M3 | AD1: $ m3 tratado | AE1: $ m3 enviado
A2: 45992 | B2: =DAY(A2) -> 1 | C2: 1 (NOCHE) | D2: 1 | E2: FINAL TURNO 3 | F2: 400 | G2: 0 | M2: =(J2*$S$2) -> 0 | N2: =(M2*$S$2)/1000000 -> 0 | O2: =(N2*$S$2)/1000000 -> 0 | P2: =(O2*$S$2)/1000000 -> 0 | Q2: =(K2*$T$2) -> 0 | R2: =(L2*$U$2) -> 0 | S2: 1.325 | T2: 1.2 | U2: 1.3 | V2: 2498 | W2: 2881 | X2: 2446 | Y2: =M2*V2 -> 0 | Z2: =Q2*W2 -> 0 | AA2: =R2*X2 -> 0 | AB2: =+Y2+Z2+AA2 -> 0 | AC2: 1500 | AD2: =AB2/H2 -> #DIV/0! | AE2: =+AB2/I2 -> #DIV/0!
A3: =A2 -> 45992 | B3: =DAY(A3) -> 1 | C3: 2 (MAÑANA) | D3: 2 | E3: FINAL TURNO 1 | F3: 210 | G3: 0 | M3: =(J3*$S$2) -> 0 | N3: =[2]!Tabla1[[#This Row],[CONSUMO POL ANIONICO (KG)]] -> #REF! | O3: =[2]!Tabla1[[#This Row],[CONSUMO POL CATIONICO (KG)]] -> #REF! | P3: =(M3*1000)/H3 -> #DIV/0! | Q3: =(K3*$T$2) -> 0 | R3: =(L3*$U$2) -> 0 | S3: 1.325 | T3: 1200 | U3: 1.3 | V3: 2498 | W3: 2881 | X3: 2446 | Y3: =M3*V3 -> 0 | Z3: =Q3*W3 -> 0 | AA3: =R3*X3 -> 0 | AB3: =+Y3+Z3+AA3 -> 0 | AC3: 1500 | AD3: =AB3/H3 -> #DIV/0! | AE3: =+AB3/I3 -> #DIV/0!
A4: =A3 -> 45992 | B4: =DAY(A4) -> 1 | C4: 3(TARDE) | D4: 3 | E4: FINAL TURNO 2 | F4: 0 | G4: 8 | M4: =(J4*$S$2) -> 0 | N4: =[2]!Tabla1[[#This Row],[CONSUMO POL ANIONICO (KG)]] -> #REF! | O4: =[2]!Tabla1[[#This Row],[CONSUMO POL CATIONICO (KG)]] -> #REF! | P4: =(M4*1000)/H4 -> #DIV/0! | Q4: =(K4*$T$2) -> 0 | R4: =(L4*$U$2) -> 0 | S4: 1.325 | T4: 1200 | U4: 1.3 | V4: 2498 | W4: 2881 | X4: 2446 | Y4: =M4*V4 -> 0 | Z4: =Q4*W4 -> 0 | AA4: =R4*X4 -> 0 | AB4: =+Y4+Z4+AA4 -> 0 | AC4: 1500 | AD4: =AB4/H4 -> #DIV/0! | AE4: =+AB4/I4 -> #DIV/0!
A5: =A4+1 -> 45993 | B5: =DAY(A5) -> 2 | C5: 1 (NOCHE) | D5: 1 | E5: FINAL TURNO 3 | F5: 7000 | G5: 6 | M5: =(J5*$S$2) -> 0 | N5: =[2]!Tabla1[[#This Row],[CONSUMO POL ANIONICO (KG)]] -> #REF! | O5: =[2]!Tabla1[[#This Row],[CONSUMO POL CATIONICO (KG)]] -> #REF! | P5: =(M5*1000)/H5 -> #DIV/0! | Q5: =(K5*$T$2) -> 0 | R5: =(L5*$U$2) -> 0 | S5: 1.325 | T5: 1200 | U5: 1.3 | V5: 2498 | W5: 2881 | X5: 2446 | Y5: =M5*V5 -> 0 | Z5: =Q5*W5 -> 0 | AA5: =R5*X5 -> 0 | AB5: =+Y5+Z5+AA5 -> 0 | AC5: 1500 | AD5: =AB5/H5 -> #DIV/0! | AE5: =+AB5/I5 -> #DIV/0!
A6: =A5 -> 45993 | B6: =DAY(A6) -> 2 | C6: 2 (MAÑANA) | D6: 2 | E6: FINAL TURNO 1 | F6: 6690 | G6: 7 | M6: =(J6*$S$2) -> 0 | N6: =[2]!Tabla1[[#This Row],[CONSUMO POL ANIONICO (KG)]] -> #REF! | O6: =[2]!Tabla1[[#This Row],[CONSUMO POL CATIONICO (KG)]] -> #REF! | P6: =(M6*1000)/H6 -> #DIV/0! | Q6: =(K6*$T$2) -> 0 | R6: =(L6*$U$2) -> 0 | S6: 1.325 | T6: 1200 | U6: 1.3 | V6: 2498 | W6: 2881 | X6: 2446 | Y6: =M6*V6 -> 0 | Z6: =Q6*W6 -> 0 | AA6: =R6*X6 -> 0 | AB6: =+Y6+Z6+AA6 -> 0 | AC6: 1500 | AD6: =AB6/H6 -> #DIV/0! | AE6: =+AB6/I6 -> #DIV/0!
A7: =A6 -> 45993 | B7: =DAY(A7) -> 2 | C7: 3(TARDE) | D7: 3 | E7: FINAL TURNO 2 | F7: 6600 | G7: 8 | M7: =(J7*$S$2) -> 0 | N7: =[2]!Tabla1[[#This Row],[CONSUMO POL ANIONICO (KG)]] -> #REF! | O7: =[2]!Tabla1[[#This Row],[CONSUMO POL CATIONICO (KG)]] -> #REF! | P7: =(M7*1000)/H7 -> #DIV/0! | Q7: =(K7*$T$2) -> 0 | R7: =(L7*$U$2) -> 0 | S7: 1.325 | T7: 1200 | U7: 1.3 | V7: 2498 | W7: 2881 | X7: 2446 | Y7: =M7*V7 -> 0 | Z7: =Q7*W7 -> 0 | AA7: =R7*X7 -> 0 | AB7: =+Y7+Z7+AA7 -> 0 | AC7: 1500 | AD7: =AB7/H7 -> #DIV/0! | AE7: =+AB7/I7 -> #DIV/0!
A8: =A7+1 -> 45994 | B8: =DAY(A8) -> 3 | C8: 1 (NOCHE) | D8: 1 | E8: FINAL TURNO 3 | F8: 6300 | G8: 8 | M8: =(J8*$S$2) -> 0 | N8: =[2]!Tabla1[[#This Row],[CONSUMO POL ANIONICO (KG)]] -> #REF! | O8: =[2]!Tabla1[[#This Row],[CONSUMO POL CATIONICO (KG)]] -> #REF! | P8: =(M8*1000)/H8 -> #DIV/0! | Q8: =(K8*$T$2) -> 0 | R8: =(L8*$U$2) -> 0 | S8: 1.325 | T8: 1200 | U8: 1.3 | V8: 2498 | W8: 2881 | X8: 2446 | Y8: =M8*V8 -> 0 | Z8: =Q8*W8 -> 0 | AA8: =R8*X8 -> 0 | AB8: =+Y8+Z8+AA8 -> 0 | AC8: 1500 | AD8: =AB8/H8 -> #DIV/0! | AE8: =+AB8/I8 -> #DIV/0!
A9: =A8 -> 45994 | B9: =DAY(A9) -> 3 | C9: 2 (MAÑANA) | D9: 2 | E9: FINAL TURNO 1 | F9: 6030 | G9: 6 | M9: =(J9*$S$2) -> 0 | N9: =[2]!Tabla1[[#This Row],[CONSUMO POL ANIONICO (KG)]] -> #REF! | O9: =[2]!Tabla1[[#This Row],[CONSUMO POL CATIONICO (KG)]] -> #REF! | P9: =(M9*1000)/H9 -> #DIV/0! | Q9: =(K9*$T$2) -> 0 | R9: =(L9*$U$2) -> 0 | S9: 1.325 | T9: 1200 | U9: 1.3 | V9: 2498 | W9: 2881 | X9: 2446 | Y9: =M9*V9 -> 0 | Z9: =Q9*W9 -> 0 | AA9: =R9*X9 -> 0 | AB9: =+Y9+Z9+AA9 -> 0 | AC9: 1500 | AD9: =AB9/H9 -> #DIV/0! | AE9: =+AB9/I9 -> #DIV/0!
A10: =A9 -> 45994 | B10: =DAY(A10) -> 3 | C10: 3(TARDE) | D10: 3 | E10: FINAL TURNO 2 | F10: 5750 | G10: 7 | M10: =(J10*$S$2) -> 0 | N10: =[2]!Tabla1[[#This Row],[CONSUMO POL ANIONICO (KG)]] -> #REF! | O10: =[2]!Tabla1[[#This Row],[CONSUMO POL CATIONICO (KG)]] -> #REF! | P10: =(M10*1000)/H10 -> #DIV/0! | Q10: =(K10*$T$2) -> 0 | R10: =(L10*$U$2) -> 0 | S10: 1.325 | T10: 1200 | U10: 1.3 | V10: 2498 | W10: 2881 | X10: 2446 | Y10: =M10*V10 -> 0 | Z10: =Q10*W10 -> 0 | AA10: =R10*X10 -> 0 | AB10: =+Y10+Z10+AA10 -> 0 | AC10: 1500 | AD10: =AB10/H10 -> #DIV/0! | AE10: =+AB10/I10 -> #DIV/0!
A11: =A10+1 -> 45995 | B11: =DAY(A11) -> 4 | C11: 1 (NOCHE) | D11: 1 | E11: FINAL TURNO 3 | F11: 5590 | G11: 8 | M11: =(J11*$S$2) -> 0 | N11: =[2]!Tabla1[[#This Row],[CONSUMO POL ANIONICO (KG)]] -> #REF! | O11: =[2]!Tabla1[[#This Row],[CONSUMO POL CATIONICO (KG)]] -> #REF! | P11: =(M11*1000)/H11 -> #DIV/0! | Q11: =(K11*$T$2) -> 0 | R11: =(L11*$U$2) -> 0 | S11: 1.325 | T11: 1200 | U11: 1.3 | V11: 2498 | W11: 2881 | X11: 2446 | Y11: =M11*V11 -> 0 | Z11: =Q11*W11 -> 0 | AA11: =R11*X11 -> 0 | AB11: =+Y11+Z11+AA11 -> 0 | AC11: 1500 | AD11: =AB11/H11 -> #DIV/0! | AE11: =+AB11/I11 -> #DIV/0!
A12: =A11 -> 45995 | B12: =DAY(A12) -> 4 | C12: 2 (MAÑANA) | D12: 2 | E12: FINAL TURNO 1 | F12: 5250 | G12: 7 | M12: =(J12*$S$2) -> 0 | N12: =[2]!Tabla1[[#This Row],[CONSUMO POL ANIONICO (KG)]] -> #REF! | O12: =[2]!Tabla1[[#This Row],[CONSUMO POL CATIONICO (KG)]] -> #REF! | P12: =(M12*1000)/H12 -> #DIV/0! | Q12: =(K12*$T$2) -> 0 | R12: =(L12*$U$2) -> 0 | S12: 1.325 | T12: 1200 | U12: 1.3 | V12: 2498 | W12: 2881 | X12: 2446 | Y12: =M12*V12 -> 0 | Z12: =Q12*W12 -> 0 | AA12: =R12*X12 -> 0 | AB12: =+Y12+Z12+AA12 -> 0 | AC12: 1500 | AD12: =AB12/H12 -> #DIV/0! | AE12: =+AB12/I12 -> #DIV/0!
A13: =A12 -> 45995 | B13: =DAY(A13) -> 4 | C13: 3(TARDE) | D13: 3 | E13: FINAL TURNO 2 | F13: 4590 | G13: 7 | M13: =(J13*$S$2) -> 0 | N13: =[2]!Tabla1[[#This Row],[CONSUMO POL ANIONICO (KG)]] -> #REF! | O13: =[2]!Tabla1[[#This Row],[CONSUMO POL CATIONICO (KG)]] -> #REF! | P13: =(M13*1000)/H13 -> #DIV/0! | Q13: =(K13*$T$2) -> 0 | R13: =(L13*$U$2) -> 0 | S13: 1.325 | T13: 1200 | U13: 1.3 | V13: 2498 | W13: 2881 | X13: 2446 | Y13: =M13*V13 -> 0 | Z13: =Q13*W13 -> 0 | AA13: =R13*X13 -> 0 | AB13: =+Y13+Z13+AA13 -> 0 | AC13: 1500 | AD13: =AB13/H13 -> #DIV/0! | AE13: =+AB13/I13 -> #DIV/0!
A14: =A13+1 -> 45996 | B14: =DAY(A14) -> 5 | C14: 1 (NOCHE) | D14: 1 | E14: FINAL TURNO 3 | F14: 4200 | G14: 8 | M14: =(J14*$S$2) -> 0 | N14: =[2]!Tabla1[[#This Row],[CONSUMO POL ANIONICO (KG)]] -> #REF! | O14: =[2]!Tabla1[[#This Row],[CONSUMO POL CATIONICO (KG)]] -> #REF! | P14: =(M14*1000)/H14 -> #DIV/0! | Q14: =(K14*$T$2) -> 0 | R14: =(L14*$U$2) -> 0 | S14: 1.325 | T14: 1200 | U14: 1.3 | V14: 2498 | W14: 2881 | X14: 2446 | Y14: =M14*V14 -> 0 | Z14: =Q14*W14 -> 0 | AA14: =R14*X14 -> 0 | AB14: =+Y14+Z14+AA14 -> 0 | AC14: 1500 | AD14: =AB14/H14 -> #DIV/0! | AE14: =+AB14/I14 -> #DIV/0!
A15: =A14 -> 45996 | B15: =DAY(A15) -> 5 | C15: 2 (MAÑANA) | D15: 2 | E15: FINAL TURNO 1 | F15: 3910 | G15: 8 | M15: =(J15*$S$2) -> 0 | N15: =[2]!Tabla1[[#This Row],[CONSUMO POL ANIONICO (KG)]] -> #REF! | O15: =[2]!Tabla1[[#This Row],[CONSUMO POL CATIONICO (KG)]] -> #REF! | P15: =(M15*1000)/H15 -> #DIV/0! | Q15: =(K15*$T$2) -> 0 | R15: =(L15*$U$2) -> 0 | S15: 1.325 | T15: 1200 | U15: 1.3 | V15: 2498 | W15: 2881 | X15: 2446 | Y15: =M15*V15 -> 0 | Z15: =Q15*W15 -> 0 | AA15: =R15*X15 -> 0 | AB15: =+Y15+Z15+AA15 -> 0 | AC15: 1500 | AD15: =AB15/H15 -> #DIV/0! | AE15: =+AB15/I15 -> #DIV/0!
A16: =A15 -> 45996 | B16: =DAY(A16) -> 5 | C16: 3(TARDE) | D16: 3 | E16: FINAL TURNO 2 | F16: 3650 | G16: 4 | M16: =(J16*$S$2) -> 0 | N16: =[2]!Tabla1[[#This Row],[CONSUMO POL ANIONICO (KG)]] -> #REF! | O16: =[2]!Tabla1[[#This Row],[CONSUMO POL CATIONICO (KG)]] -> #REF! | P16: =(M16*1000)/H16 -> #DIV/0! | Q16: =(K16*$T$2) -> 0 | R16: =(L16*$U$2) -> 0 | S16: 1.325 | T16: 1200 | U16: 1.3 | V16: 2498 | W16: 2881 | X16: 2446 | Y16: =M16*V16 -> 0 | Z16: =Q16*W16 -> 0 | AA16: =R16*X16 -> 0 | AB16: =+Y16+Z16+AA16 -> 0 | AC16: 1500 | AD16: =AB16/H16 -> #DIV/0! | AE16: =+AB16/I16 -> #DIV/0!
A17: =A16+1 -> 45997 | B17: =DAY(A17) -> 6 | C17: 1 (NOCHE) | D17: 1 | E17: FINAL TURNO 3 | F17: 3350 | G17: 5 | M17: =(J17*$S$2) -> 0 | N17: =[2]!Tabla1[[#This Row],[CONSUMO POL ANIONICO (KG)]] -> #REF! | O17: =[2]!Tabla1[[#This Row],[CONSUMO POL CATIONICO (KG)]] -> #REF! | P17: =(M17*1000)/H17 -> #DIV/0! | Q17: =(K17*$T$2) -> 0 | R17: =(L17*$U$2) -> 0 | S17: 1.325 | T17: 1200 | U17: 1.3 | V17: 2498 | W17: 2881 | X17: 2446 | Y17: =M17*V17 -> 0 | Z17: =Q17*W17 -> 0 | AA17: =R17*X17 -> 0 | AB17: =+Y17+Z17+AA17 -> 0 | AC17: 1500 | AD17: =AB17/H17 -> #DIV/0! | AE17: =+AB17/I17 -> #DIV/0!
A18: =A17 -> 45997 | B18: =DAY(A18) -> 6 | C18: 2 (MAÑANA) | D18: 2 | E18: FINAL TURNO 1 | F18: 3205 | G18: 3 | M18: =(J18*$S$2) -> 0 | N18: =[2]!Tabla1[[#This Row],[CONSUMO POL ANIONICO (KG)]] -> #REF! | O18: =[2]!Tabla1[[#This Row],[CONSUMO POL CATIONICO (KG)]] -> #REF! | P18: =(M18*1000)/H18 -> #DIV/0! | Q18: =(K18*$T$2) -> 0 | R18: =(L18*$U$2) -> 0 | S18: 1.325 | T18: 1200 | U18: 1.3 | V18: 2498 | W18: 2881 | X18: 2446 | Y18: =M18*V18 -> 0 | Z18: =Q18*W18 -> 0 | AA18: =R18*X18 -> 0 | AB18: =+Y18+Z18+AA18 -> 0 | AC18: 1500 | AD18: =AB18/H18 -> #DIV/0! | AE18: =+AB18/I18 -> #DIV/0!
A19: =A18 -> 45997 | B19: =DAY(A19) -> 6 | C19: 3(TARDE) | D19: 3 | E19: FINAL TURNO 2 | F19: =+AVERAGE(F18,F20) -> 2982.5 | G19: 8 | M19: =(J19*$S$2) -> 0 | N19: =[2]!Tabla1[[#This Row],[CONSUMO POL ANIONICO (KG)]] -> #REF! | O19: =[2]!Tabla1[[#This Row],[CONSUMO POL CATIONICO (KG)]] -> #REF! | P19: =(M19*1000)/H19 -> #DIV/0! | Q19: =(K19*$T$2) -> 0 | R19: =(L19*$U$2) -> 0 | S19: 1.325 | T19: 1200 | U19: 1.3 | V19: 2498 | W19: 2881 | X19: 2446 | Y19: =M19*V19 -> 0 | Z19: =Q19*W19 -> 0 | AA19: =R19*X19 -> 0 | AB19: =+Y19+Z19+AA19 -> 0 | AC19: 1500 | AD19: =AB19/H19 -> #DIV/0! | AE19: =+AB19/I19 -> #DIV/0!
A20: =A19+1 -> 45998 | B20: =DAY(A20) -> 7 | C20: 1 (NOCHE) | D20: 1 | E20: FINAL TURNO 3 | F20: 2760 | G20: 8 | M20: =(J20*$S$2) -> 0 | N20: =[2]!Tabla1[[#This Row],[CONSUMO POL ANIONICO (KG)]] -> #REF! | O20: =[2]!Tabla1[[#This Row],[CONSUMO POL CATIONICO (KG)]] -> #REF! | P20: =(M20*1000)/H20 -> #DIV/0! | Q20: =(K20*$T$2) -> 0 | R20: =(L20*$U$2) -> 0 | S20: 1.325 | T20: 1200 | U20: 1.3 | V20: 2498 | W20: 2881 | X20: 2446 | Y20: =M20*V20 -> 0 | Z20: =Q20*W20 -> 0 | AA20: =R20*X20 -> 0 | AB20: =+Y20+Z20+AA20 -> 0 | AC20: 1500 | AD20: =AB20/H20 -> #DIV/0! | AE20: =+AB20/I20 -> #DIV/0!
A21: =A20 -> 45998 | B21: =DAY(A21) -> 7 | C21: 2 (MAÑANA) | D21: 2 | E21: FINAL TURNO 1 | F21: 2530 | G21: 6 | M21: =(J21*$S$2) -> 0 | N21: =[2]!Tabla1[[#This Row],[CONSUMO POL ANIONICO (KG)]] -> #REF! | O21: =[2]!Tabla1[[#This Row],[CONSUMO POL CATIONICO (KG)]] -> #REF! | P21: =(M21*1000)/H21 -> #DIV/0! | Q21: =(K21*$T$2) -> 0 | R21: =(L21*$U$2) -> 0 | S21: 1.325 | T21: 1200 | U21: 1.3 | V21: 2498 | W21: 2881 | X21: 2446 | Y21: =M21*V21 -> 0 | Z21: =Q21*W21 -> 0 | AA21: =R21*X21 -> 0 | AB21: =+Y21+Z21+AA21 -> 0 | AC21: 1500 | AD21: =AB21/H21 -> #DIV/0! | AE21: =+AB21/I21 -> #DIV/0!
A22: =A21 -> 45998 | B22: =DAY(A22) -> 7 | C22: 3(TARDE) | D22: 3 | E22: FINAL TURNO 2 | F22: 2200 | G22: 7 | M22: =(J22*$S$2) -> 0 | N22: =[2]!Tabla1[[#This Row],[CONSUMO POL ANIONICO (KG)]] -> #REF! | O22: =[2]!Tabla1[[#This Row],[CONSUMO POL CATIONICO (KG)]] -> #REF! | P22: =(M22*1000)/H22 -> #DIV/0! | Q22: =(K22*$T$2) -> 0 | R22: =(L22*$U$2) -> 0 | S22: 1.325 | T22: 1200 | U22: 1.3 | V22: 2498 | W22: 2881 | X22: 2446 | Y22: =M22*V22 -> 0 | Z22: =Q22*W22 -> 0 | AA22: =R22*X22 -> 0 | AB22: =+Y22+Z22+AA22 -> 0 | AC22: 1500 | AD22: =AB22/H22 -> #DIV/0! | AE22: =+AB22/I22 -> #DIV/0!
A23: =A22+1 -> 45999 | B23: =DAY(A23) -> 8 | C23: 1 (NOCHE) | D23: 1 | E23: FINAL TURNO 3 | F23: 5900 | G23: 8 | M23: =(J23*$S$2) -> 0 | N23: =[2]!Tabla1[[#This Row],[CONSUMO POL ANIONICO (KG)]] -> #REF! | O23: =[2]!Tabla1[[#This Row],[CONSUMO POL CATIONICO (KG)]] -> #REF! | P23: =(M23*1000)/H23 -> #DIV/0! | Q23: =(K23*$T$2) -> 0 | R23: =(L23*$U$2) -> 0 | S23: 1.325 | T23: 1200 | U23: 1.3 | V23: 2498 | W23: 2881 | X23: 2446 | Y23: =M23*V23 -> 0 | Z23: =Q23*W23 -> 0 | AA23: =R23*X23 -> 0 | AB23: =+Y23+Z23+AA23 -> 0 | AC23: 1500 | AD23: =AB23/H23 -> #DIV/0! | AE23: =+AB23/I23 -> #DIV/0!
A24: =A23 -> 45999 | B24: =DAY(A24) -> 8 | C24: 2 (MAÑANA) | D24: 2 | E24: FINAL TURNO 1 | F24: 5590 | G24: 6 | M24: =(J24*$S$2) -> 0 | N24: =[2]!Tabla1[[#This Row],[CONSUMO POL ANIONICO (KG)]] -> #REF! | O24: =[2]!Tabla1[[#This Row],[CONSUMO POL CATIONICO (KG)]] -> #REF! | P24: =(M24*1000)/H24 -> #DIV/0! | Q24: =(K24*$T$2) -> 0 | R24: =(L24*$U$2) -> 0 | S24: 1.325 | T24: 1200 | U24: 1.3 | V24: 2498 | W24: 2881 | X24: 2446 | Y24: =M24*V24 -> 0 | Z24: =Q24*W24 -> 0 | AA24: =R24*X24 -> 0 | AB24: =+Y24+Z24+AA24 -> 0 | AC24: 1500 | AD24: =AB24/H24 -> #DIV/0! | AE24: =+AB24/I24 -> #DIV/0!
A25: =A24 -> 45999 | B25: =DAY(A25) -> 8 | C25: 3(TARDE) | D25: 3 | E25: FINAL TURNO 2 | F25: 5150 | G25: 7 | M25: =(J25*$S$2) -> 0 | N25: =[2]!Tabla1[[#This Row],[CONSUMO POL ANIONICO (KG)]] -> #REF! | O25: =[2]!Tabla1[[#This Row],[CONSUMO POL CATIONICO (KG)]] -> #REF! | P25: =(M25*1000)/H25 -> #DIV/0! | Q25: =(K25*$T$2) -> 0 | R25: =(L25*$U$2) -> 0 | S25: 1.325 | T25: 1200 | U25: 1.3 | V25: 2498 | W25: 2881 | X25: 2446 | Y25: =M25*V25 -> 0 | Z25: =Q25*W25 -> 0 | AA25: =R25*X25 -> 0 | AB25: =+Y25+Z25+AA25 -> 0 | AC25: 1500 | AD25: =AB25/H25 -> #DIV/0! | AE25: =+AB25/I25 -> #DIV/0!
A26: =A25+1 -> 46000 | B26: =DAY(A26) -> 9 | C26: 1 (NOCHE) | D26: 1 | E26: FINAL TURNO 3 | F26: 4980 | G26: 3 | M26: =(J26*$S$2) -> 0 | N26: =[2]!Tabla1[[#This Row],[CONSUMO POL ANIONICO (KG)]] -> #REF! | O26: =[2]!Tabla1[[#This Row],[CONSUMO POL CATIONICO (KG)]] -> #REF! | P26: =(M26*1000)/H26 -> #DIV/0! | Q26: =(K26*$T$2) -> 0 | R26: =(L26*$U$2) -> 0 | S26: 1.325 | T26: 1200 | U26: 1.3 | V26: 2498 | W26: 2881 | X26: 2446 | Y26: =M26*V26 -> 0 | Z26: =Q26*W26 -> 0 | AA26: =R26*X26 -> 0 | AB26: =+Y26+Z26+AA26 -> 0 | AC26: 1500 | AD26: =AB26/H26 -> #DIV/0! | AE26: =+AB26/I26 -> #DIV/0!
A27: =A26 -> 46000 | B27: =DAY(A27) -> 9 | C27: 2 (MAÑANA) | D27: 2 | E27: FINAL TURNO 1 | F27: 4980 | G27: 0 | M27: =(J27*$S$2) -> 0 | N27: =[2]!Tabla1[[#This Row],[CONSUMO POL ANIONICO (KG)]] -> #REF! | O27: =[2]!Tabla1[[#This Row],[CONSUMO POL CATIONICO (KG)]] -> #REF! | P27: =(M27*1000)/H27 -> #DIV/0! | Q27: =(K27*$T$2) -> 0 | R27: =(L27*$U$2) -> 0 | S27: 1.325 | T27: 1200 | U27: 1.3 | V27: 2498 | W27: 2881 | X27: 2446 | Y27: =M27*V27 -> 0 | Z27: =Q27*W27 -> 0 | AA27: =R27*X27 -> 0 | AB27: =+Y27+Z27+AA27 -> 0 | AC27: 1500 | AD27: =AB27/H27 -> #DIV/0! | AE27: =+AB27/I27 -> #DIV/0!
A28: =A27 -> 46000 | B28: =DAY(A28) -> 9 | C28: 3(TARDE) | D28: 3 | E28: FINAL TURNO 2 | F28: 4980 | G28: 0 | M28: =(J28*$S$2) -> 0 | N28: 0 | O28: =[2]!Tabla1[[#This Row],[CONSUMO POL CATIONICO (KG)]] -> #REF! | P28: =(M28*1000)/H28 -> #DIV/0! | Q28: =(K28*$T$2) -> 0 | R28: =(L28*$U$2) -> 0 | S28: 1.325 | T28: 1200 | U28: 1.3 | V28: 2498 | W28: 2881 | X28: 2446 | Y28: =M28*V28 -> 0 | Z28: =Q28*W28 -> 0 | AA28: =R28*X28 -> 0 | AB28: =+Y28+Z28+AA28 -> 0 | AC28: 1500 | AD28: =AB28/H28 -> #DIV/0! | AE28: =+AB28/I28 -> #DIV/0!
A29: =A28+1 -> 46001 | B29: =DAY(A29) -> 10 | C29: 1 (NOCHE) | D29: 1 | E29: FINAL TURNO 3 | F29: 4980 | G29: 3 | M29: =(J29*$S$2) -> 0 | N29: =[2]!Tabla1[[#This Row],[CONSUMO POL ANIONICO (KG)]] -> #REF! | O29: =[2]!Tabla1[[#This Row],[CONSUMO POL CATIONICO (KG)]] -> #REF! | P29: =(M29*1000)/H29 -> #DIV/0! | Q29: =(K29*$T$2) -> 0 | R29: =(L29*$U$2) -> 0 | S29: 1.325 | T29: 1200 | U29: 1.3 | V29: 2498 | W29: 2881 | X29: 2446 | Y29: =M29*V29 -> 0 | Z29: =Q29*W29 -> 0 | AA29: =R29*X29 -> 0 | AB29: =+Y29+Z29+AA29 -> 0 | AC29: 1500 | AD29: =AB29/H29 -> #DIV/0! | AE29: =+AB29/I29 -> #DIV/0!
A30: =A29 -> 46001 | B30: =DAY(A30) -> 10 | C30: 2 (MAÑANA) | D30: 2 | E30: FINAL TURNO 1 | F30: 4750 | G30: 8 | M30: =(J30*$S$2) -> 0 | N30: =[2]!Tabla1[[#This Row],[CONSUMO POL ANIONICO (KG)]] -> #REF! | O30: =[2]!Tabla1[[#This Row],[CONSUMO POL CATIONICO (KG)]] -> #REF! | P30: =(M30*1000)/H30 -> #DIV/0! | Q30: =(K30*$T$2) -> 0 | R30: =(L30*$U$2) -> 0 | S30: 1.325 | T30: 1200 | U30: 1.3 | V30: 2498 | W30: 2881 | X30: 2446 | Y30: =M30*V30 -> 0 | Z30: =Q30*W30 -> 0 | AA30: =R30*X30 -> 0 | AB30: =+Y30+Z30+AA30 -> 0 | AC30: 1500 | AD30: =AB30/H30 -> #DIV/0! | AE30: =+AB30/I30 -> #DIV/0!
A31: =A30 -> 46001 | B31: =DAY(A31) -> 10 | C31: 3(TARDE) | D31: 3 | E31: FINAL TURNO 2 | F31: 4330 | G31: 6 | M31: =(J31*$S$2) -> 0 | N31: =[2]!Tabla1[[#This Row],[CONSUMO POL ANIONICO (KG)]] -> #REF! | O31: =[2]!Tabla1[[#This Row],[CONSUMO POL CATIONICO (KG)]] -> #REF! | P31: =(M31*1000)/H31 -> #DIV/0! | Q31: =(K31*$T$2) -> 0 | R31: =(L31*$U$2) -> 0 | S31: 1.325 | T31: 1200 | U31: 1.3 | V31: 2498 | W31: 2881 | X31: 2446 | Y31: =M31*V31 -> 0 | Z31: =Q31*W31 -> 0 | AA31: =R31*X31 -> 0 | AB31: =+Y31+Z31+AA31 -> 0 | AC31: 1500 | AD31: =AB31/H31 -> #DIV/0! | AE31: =+AB31/I31 -> #DIV/0!
A32: =A31+1 -> 46002 | B32: =DAY(A32) -> 11 | C32: 1 (NOCHE) | D32: 1 | E32: FINAL TURNO 3 | F32: 4100 | G32: 6 | M32: =(J32*$S$2) -> 0 | N32: =[2]!Tabla1[[#This Row],[CONSUMO POL ANIONICO (KG)]] -> #REF! | O32: =[2]!Tabla1[[#This Row],[CONSUMO POL CATIONICO (KG)]] -> #REF! | P32: =(M32*1000)/H32 -> #DIV/0! | Q32: =(K32*$T$2) -> 0 | R32: =(L32*$U$2) -> 0 | S32: 1.325 | T32: 1200 | U32: 1.3 | V32: 2498 | W32: 2881 | X32: 2446 | Y32: =M32*V32 -> 0 | Z32: =Q32*W32 -> 0 | AA32: =R32*X32 -> 0 | AB32: =+Y32+Z32+AA32 -> 0 | AC32: 1500 | AD32: =AB32/H32 -> #DIV/0! | AE32: =+AB32/I32 -> #DIV/0!
A33: =A32 -> 46002 | B33: =DAY(A33) -> 11 | C33: 2 (MAÑANA) | D33: 2 | E33: FINAL TURNO 1 | F33: 3840 | G33: 8 | M33: =(J33*$S$2) -> 0 | N33: =[2]!Tabla1[[#This Row],[CONSUMO POL ANIONICO (KG)]] -> #REF! | O33: =[2]!Tabla1[[#This Row],[CONSUMO POL CATIONICO (KG)]] -> #REF! | P33: =(M33*1000)/H33 -> #DIV/0! | Q33: =(K33*$T$2) -> 0 | R33: =(L33*$U$2) -> 0 | S33: 1.325 | T33: 1200 | U33: 1.3 | V33: 2498 | W33: 2881 | X33: 2446 | Y33: =M33*V33 -> 0 | Z33: =Q33*W33 -> 0 | AA33: =R33*X33 -> 0 | AB33: =+Y33+Z33+AA33 -> 0 | AC33: 1500 | AD33: =AB33/H33 -> #DIV/0! | AE33: =+AB33/I33 -> #DIV/0!
A34: =A33 -> 46002 | B34: =DAY(A34) -> 11 | C34: 3(TARDE) | D34: 3 | E34: FINAL TURNO 2 | F34: 3110 | G34: 6 | M34: =(J34*$S$2) -> 0 | N34: =[2]!Tabla1[[#This Row],[CONSUMO POL ANIONICO (KG)]] -> #REF! | O34: =[2]!Tabla1[[#This Row],[CONSUMO POL CATIONICO (KG)]] -> #REF! | P34: =(M34*1000)/H34 -> #DIV/0! | Q34: =(K34*$T$2) -> 0 | R34: =(L34*$U$2) -> 0 | S34: 1.325 | T34: 1200 | U34: 1.3 | V34: 2498 | W34: 2881 | X34: 2446 | Y34: =M34*V34 -> 0 | Z34: =Q34*W34 -> 0 | AA34: =R34*X34 -> 0 | AB34: =+Y34+Z34+AA34 -> 0 | AC34: 1500 | AD34: =AB34/H34 -> #DIV/0! | AE34: =+AB34/I34 -> #DIV/0!
A35: =A34+1 -> 46003 | B35: =DAY(A35) -> 12 | C35: 1 (NOCHE) | D35: 1 | E35: FINAL TURNO 3 | F35: 3110 | G35: 6 | M35: =(J35*$S$2) -> 0 | N35: =[2]!Tabla1[[#This Row],[CONSUMO POL ANIONICO (KG)]] -> #REF! | O35: =[2]!Tabla1[[#This Row],[CONSUMO POL CATIONICO (KG)]] -> #REF! | P35: =(M35*1000)/H35 -> #DIV/0! | Q35: =(K35*$T$2) -> 0 | R35: =(L35*$U$2) -> 0 | S35: 1.325 | T35: 1200 | U35: 1.3 | V35: 2498 | W35: 2881 | X35: 2446 | Y35: =M35*V35 -> 0 | Z35: =Q35*W35 -> 0 | AA35: =R35*X35 -> 0 | AB35: =+Y35+Z35+AA35 -> 0 | AC35: 1500 | AD35: =AB35/H35 -> #DIV/0! | AE35: =+AB35/I35 -> #DIV/0!
A36: =A35 -> 46003 | B36: =DAY(A36) -> 12 | C36: 2 (MAÑANA) | D36: 2 | E36: FINAL TURNO 1 | F36: 2730 | G36: 6 | M36: =(J36*$S$2) -> 0 | N36: =[2]!Tabla1[[#This Row],[CONSUMO POL ANIONICO (KG)]] -> #REF! | O36: =[2]!Tabla1[[#This Row],[CONSUMO POL CATIONICO (KG)]] -> #REF! | P36: =(M36*1000)/H36 -> #DIV/0! | Q36: =(K36*$T$2) -> 0 | R36: =(L36*$U$2) -> 0 | S36: 1.325 | T36: 1200 | U36: 1.3 | V36: 2498 | W36: 2881 | X36: 2446 | Y36: =M36*V36 -> 0 | Z36: =Q36*W36 -> 0 | AA36: =R36*X36 -> 0 | AB36: =+Y36+Z36+AA36 -> 0 | AC36: 1500 | AD36: =AB36/H36 -> #DIV/0! | AE36: =+AB36/I36 -> #DIV/0!
A37: =A36 -> 46003 | B37: =DAY(A37) -> 12 | C37: 3(TARDE) | D37: 3 | E37: FINAL TURNO 2 | F37: 2400 | G37: 4 | M37: =(J37*$S$2) -> 0 | N37: =[2]!Tabla1[[#This Row],[CONSUMO POL ANIONICO (KG)]] -> #REF! | O37: =[2]!Tabla1[[#This Row],[CONSUMO POL CATIONICO (KG)]] -> #REF! | P37: =(M37*1000)/H37 -> #DIV/0! | Q37: =(K37*$T$2) -> 0 | R37: =(L37*$U$2) -> 0 | S37: 1.325 | T37: 1200 | U37: 1.3 | V37: 2498 | W37: 2881 | X37: 2446 | Y37: =M37*V37 -> 0 | Z37: =Q37*W37 -> 0 | AA37: =R37*X37 -> 0 | AB37: =+Y37+Z37+AA37 -> 0 | AC37: 1500 | AD37: =AB37/H37 -> #DIV/0! | AE37: =+AB37/I37 -> #DIV/0!
A38: =A37+1 -> 46004 | B38: =DAY(A38) -> 13 | C38: 1 (NOCHE) | D38: 1 | E38: FINAL TURNO 3 | F38: 1860 | G38: 4 | M38: =(J38*$S$2) -> 0 | N38: =[2]!Tabla1[[#This Row],[CONSUMO POL ANIONICO (KG)]] -> #REF! | O38: =[2]!Tabla1[[#This Row],[CONSUMO POL CATIONICO (KG)]] -> #REF! | P38: =(M38*1000)/H38 -> #DIV/0! | Q38: =(K38*$T$2) -> 0 | R38: =(L38*$U$2) -> 0 | S38: 1.325 | T38: 1200 | U38: 1.3 | V38: 2498 | W38: 2881 | X38: 2446 | Y38: =M38*V38 -> 0 | Z38: =Q38*W38 -> 0 | AA38: =R38*X38 -> 0 | AB38: =+Y38+Z38+AA38 -> 0 | AC38: 1500 | AD38: =AB38/H38 -> #DIV/0! | AE38: =+AB38/I38 -> #DIV/0!
A39: =A38 -> 46004 | B39: =DAY(A39) -> 13 | C39: 2 (MAÑANA) | D39: 2 | E39: FINAL TURNO 1 | F39: 1540 | G39: 8 | M39: =(J39*$S$2) -> 0 | N39: =[2]!Tabla1[[#This Row],[CONSUMO POL ANIONICO (KG)]] -> #REF! | O39: =[2]!Tabla1[[#This Row],[CONSUMO POL CATIONICO (KG)]] -> #REF! | P39: =(M39*1000)/H39 -> #DIV/0! | Q39: =(K39*$T$2) -> 0 | R39: =(L39*$U$2) -> 0 | S39: 1.325 | T39: 1200 | U39: 1.3 | V39: 2498 | W39: 2881 | X39: 2446 | Y39: =M39*V39 -> 0 | Z39: =Q39*W39 -> 0 | AA39: =R39*X39 -> 0 | AB39: =+Y39+Z39+AA39 -> 0 | AC39: 1500 | AD39: =AB39/H39 -> #DIV/0! | AE39: =+AB39/I39 -> #DIV/0!
A40: =A39 -> 46004 | B40: =DAY(A40) -> 13 | C40: 3(TARDE) | D40: 3 | E40: FINAL TURNO 2 | F40: 1300 | G40: 7 | M40: =(J40*$S$2) -> 0 | N40: =[2]!Tabla1[[#This Row],[CONSUMO POL ANIONICO (KG)]] -> #REF! | O40: =[2]!Tabla1[[#This Row],[CONSUMO POL CATIONICO (KG)]] -> #REF! | P40: =(M40*1000)/H40 -> #DIV/0! | Q40: =(K40*$T$2) -> 0 | R40: =(L40*$U$2) -> 0 | S40: 1.325 | T40: 1200 | U40: 1.3 | V40: 2498 | W40: 2881 | X40: 2446 | Y40: =M40*V40 -> 0 | Z40: =Q40*W40 -> 0 | AA40: =R40*X40 -> 0 | AB40: =+Y40+Z40+AA40 -> 0 | AC40: 1500 | AD40: =AB40/H40 -> #DIV/0! | AE40: =+AB40/I40 -> #DIV/0!
...

Sheet Gráfica
A1: DÍA | B1: VOLUMEN TOTAL TRATADO PTAP | C1: LIMITE INDICADOR M3 | D1: $ M3 PTAP | E1: VOLUMEN ENVIADO A TK RECIRCULACIÓN | F1: AGUA DE RETROLAVADOS
A2: 1 | B2: 275 | C2: 1500 | D2: 6524.8259 | E2: 195 | F2: =+B2-E2 -> 80
A3: 2 | B3: 367 | C3: 1500 | D3: 6805.1884 | E3: 272 | F3: =+B3-E3 -> 95
A4: 3 | B4: 393 | C4: 1500 | D4: 4541.3606 | E4: 291 | F4: =+B4-E4 -> 102
A5: 4 | B5: 376 | C5: 1500 | D5: 4031.5544 | E5: 276 | F5: =+B5-E5 -> 100
A6: 5 | B6: 361 | C6: 1500 | D6: 794.56178 | E6: 259 | F6: =+B6-E6 -> 102
A7: 6 | B7: 374 | C7: 1500 | D7: 4748.5087 | E7: 276 | F7: =+B7-E7 -> 98
A8: 7 | B8: 68 | C8: 1500 | D8: #DIV/0! | E8: 51 | F8: =+B8-E8 -> 17
A9: 8 | B9: 0 | C9: 1500 | D9: #DIV/0! | E9: 0 | F9: =+B9-E9 -> 0
A10: 9 | B10: 307 | C10: 1500 | D10: 4894.615 | E10: 220 | F10: =+B10-E10 -> 87
A11: 10 | B11: 366 | C11: 1500 | D11: 0 | E11: 254 | F11: =+B11-E11 -> 112
A12: 11 | B12: 270 | C12: 1500 | D12: 0 | E12: 192 | F12: =+B12-E12 -> 78
A13: 12 | B13: 301 | C13: 1500 | D13: 0 | E13: 208 | F13: =+B13-E13 -> 93
A14: 13 | B14: 336 | C14: 1500 | D14: 5440.8943 | E14: 239 | F14: =+B14-E14 -> 97
A15: 14 | B15: 398 | C15: 1500 | D15: 4468.541 | E15: 273 | F15: =+B15-E15 -> 125
A16: 15 | B16: 347 | C16: 1500 | D16: #DIV/0! | E16: 236 | F16: =+B16-E16 -> 111
A17: 16 | B17: 262 | C17: 1500 | D17: 6289.8931 | E17: 168 | F17: =+B17-E17 -> 94
A18: 17 | B18: 354 | C18: 1500 | D18: 5032.4161 | E18: 226 | F18: =+B18-E18 -> 128
A19: 18 | B19: 304 | C19: 1500 | D19: 5842.4041 | E19: 210 | F19: =+B19-E19 -> 94
A20: 19 | B20: 346 | C20: 1500 | D20: 0 | E20: 248 | F20: =+B20-E20 -> 98
A21: 20 | B21: 348 | C21: 1500 | D21: 0 | E21: 246 | F21: =+B21-E21 -> 102
A22: 21 | B22: 97 | C22: 1500 | D22: #DIV/0! | E22: 71 | F22: =+B22-E22 -> 26
A23: 22 | B23: 254 | C23: 1500 | D23: #DIV/0! | E23: 184 | F23: =+B23-E23 -> 70
A24: 23 | B24: 382 | C24: 1500 | D24: 3905.9548 | E24: 280 | F24: =+B24-E24 -> 102
A25: 24 | B25: 223 | C25: 1500 | D25: #DIV/0! | E25: 160 | F25: =+B25-E25 -> 63
A26: 25 | B26: 0 | C26: 1500 | D26: #DIV/0! | E26: 0 | F26: =+B26-E26 -> 0
A27: 26 | B27: 154 | C27: 1500 | D27: #DIV/0! | E27: 115 | F27: =+B27-E27 -> 39
A28: 27 | B28: 301 | C28: 1500 | D28: 5931.3364 | E28: 223 | F28: =+B28-E28 -> 78
A29: 28 | B29: 224 | C29: 1500 | D29: #DIV/0! | E29: 167 | F29: =+B29-E29 -> 57
A30: 29 | B30: 249 | C30: 1500 | D30: #DIV/0! | E30: 186 | F30: =+B30-E30 -> 63
A31: 30 | B31: 267.5 | C31: 1500 | D31: 0 | E31: 198.5 | F31: =+B31-E31 -> 69
A32: 31 | B32: 58.5 | C32: 1500 | D32: #DIV/0! | E32: 43.5 | F32: =+B32-E32 -> 15
B33: =+SUM(B2:B32) -> 8363 | C33: =+SUM(C2:C32) -> 46500 | D33: =+SUM(D2:D32) -> #DIV/0! | E33: =+SUM(E2:E32) -> 5968 | F33: =+SUM(F2:F32) -> 2395
B36: BALANCE PTAP | L36: =+Balance!AB95 -> 0
B37: Volumen Total tratado (m3) | C37: Volumen enviado a Tanque de Reciculación (m3) | D37: $/m3 tratado | E37: $/m3 enviado | F37: Mín. enviado a tk de recirculación (m3) | G37: Máx. enviado a tk de recirculación (m3) | H37: Promedio tratado (m3) | I37: Promedio enviado a tk de recirculación (m3) | J37: Eficiencia UF % | K37: Caudal puntual mensual L/s
B38: =+B33 -> 8363 | C38: =+E33 -> 5968 | D38: =+L36/B38 -> 0 | E38: =+L36/C38 -> 0 | F38: =+MIN(E2:E5,E7:E12,E14:E19,E21:E32) -> 0 | G38: =+MAX(E2:E5,E7:E12,E14:E19,E21:E32) -> 291 | H38: =+AVERAGE(B2:B5,B7:B12,B14:B19,B21:B32) -> 262.67857 | I38: =+AVERAGE(E2:E5,E7:E12,E14:E19,E21:E32) -> 187.60714 | J38: =+I38/H38*100 -> 71.420802 | K38: =+I38/3.6/24 -> 2.171379

Sheet Base de datos
A1: Día | B1: VOL. ENVIADO A TK RECIRCULACIÓN (m3) | C1: VOL. TOTAL TRATADO PTAP (m3) | D1: Promedio de LIMITE INDICADOR M3 | E1: Suma de $ m3 tratado
A2: 1 | B2: 195 | C2: 275 | D2: 1500 | E2: 6524.8259
A3: 2 | B3: 272 | C3: 367 | D3: 1500 | E3: 6805.1884 | G3: =+MIN(B2:B5,B7) -> 195
A4: 3 | B4: 291 | C4: 393 | D4: 1500 | E4: 4541.3606 | G4: =+MAX(B2:B5,B7) -> 291
A5: 4 | B5: 276 | C5: 376 | D5: 1500 | E5: 4031.5544 | G5: =+AVERAGE(B2:B5,B7) -> 262
A6: 5 | B6: 259 | C6: 361 | D6: 1500 | E6: 794.56178
A7: 6 | B7: 276 | C7: 374 | D7: 1500 | E7: 4748.5087
A8: 7 | B8: 51 | C8: 68 | D8: 1500 | E8: #DIV/0!
A9: 8 | B9: 0 | C9: 0 | D9: 1500 | E9: #DIV/0!
A10: 9 | B10: 220 | C10: 307 | D10: 1500 | E10: 4894.615
A11: 10 | B11: 254 | C11: 366 | D11: 1500 | E11: 0
A12: 11 | B12: 192 | C12: 270 | D12: 1500 | E12: 0
A13: 12 | B13: 208 | C13: 301 | D13: 1500 | E13: 0
A14: 13 | B14: 239 | C14: 336 | D14: 1500 | E14: 5440.8943
A15: 14 | B15: 273 | C15: 398 | D15: 1500 | E15: 4468.541
A16: 15 | B16: 236 | C16: 347 | D16: 1500 | E16: #DIV/0!
A17: 16 | B17: 168 | C17: 262 | D17: 1500 | E17: 6289.8931
A18: 17 | B18: 226 | C18: 354 | D18: 1500 | E18: 5032.4161
A19: 18 | B19: 210 | C19: 304 | D19: 1500 | E19: 5842.4041
A20: 19 | B20: 248 | C20: 346 | D20: 1500 | E20: 0
A21: 20 | B21: 246 | C21: 348 | D21: 1500 | E21: 0
A22: 21 | B22: 71 | C22: 97 | D22: 1500 | E22: #DIV/0!
A23: 22 | B23: 184 | C23: 254 | D23: 1500 | E23: #DIV/0!
A24: 23 | B24: 280 | C24: 382 | D24: 1500 | E24: 3905.9548
A25: 24 | B25: 160 | C25: 223 | D25: 1500 | E25: #DIV/0!
A26: 25 | B26: 0 | C26: 0 | D26: 1500 | E26: #DIV/0!
A27: 26 | B27: 115 | C27: 154 | D27: 1500 | E27: #DIV/0!
A28: 27 | B28: 223 | C28: 301 | D28: 1500 | E28: 5931.3364
A29: 28 | B29: 167 | C29: 224 | D29: 1500 | E29: #DIV/0!
A30: 29 | B30: 186 | C30: 249 | D30: 1500 | E30: #DIV/0!
A31: 30 | B31: 198.5 | C31: 267.5 | D31: 1500 | E31: 0
A32: 31 | B32: 43.5 | C32: 58.5 | D32: 1500 | E32: #DIV/0!
A33: Total general | B33: 5968 | C33: 8363 | D33: 1500 | E33: #DIV/0!
B34: =+MIN(B2:B5,B7:B12,B14:B19,B21:B32) -> 0 | C34: =+MIN(C2:C5,C7:C12,C14:C19,C21:C32) -> 0 | D34: =+MIN(D2:D5,D7:D12,D14:D19,D21:D32) -> 1500 | E34: =+MIN(E2:E5,E7:E12,E14:E19,E21:E32) -> #DIV/0!
B35: =+MAX(B2:B5,B7:B12,B14:B19,B21:B32) -> 291 | C35: =+MAX(C2:C5,C7:C12,C14:C19,C21:C32) -> 398 | D35: =+MAX(D2:D5,D7:D12,D14:D19,D21:D32) -> 1500 | E35: =+MAX(E2:E5,E7:E12,E14:E19,E21:E32) -> #DIV/0!
B36: =+AVERAGE(B2:B5,B7:B12,B14:B19,B21:B32) -> 187.60714 | C36: =+AVERAGE(C2:C5,C7:C12,C14:C19,C21:C32) -> 262.67857 | D36: =+AVERAGE(D2:D5,D7:D12,D14:D19,D21:D32) -> 1500 | E36: =+AVERAGE(E2:E5,E7:E12,E14:E19,E21:E32) -> #DIV/0!

Sheet Desglose químico
A1: PRODUCTO QUÍMICO | B1: KG CONSUMIDOS MES | C1: KG PROMEDIO DIÁRIO | D1: COSTO MES | E1: $ PROMEDIO DIÁRIO
A2: ÁCIDO | B2: =+Balance!R95 -> 0 | C2: =+B2/24 -> 0 | D2: =+Balance!AA95 -> 0 | E2: =+D2/28 -> 0
A3: COAGULANTE | B3: =+Balance!M95 -> 0 | C3: =+B3/24 -> 0 | D3: =+Balance!Y95 -> 0 | E3: =+D3/28 -> 0
A4: PERÓXIDO | B4: =+Balance!Q95 -> 0 | C4: =+B4/24 -> 0 | D4: =+Balance!Z95 -> 0 | E4: =+D4/28 -> 0
A5: SODA | C5: =+B5/24 -> 0 | E5: =+D5/24 -> 0
A6: FILTROS BOLSA | B6: 16 | C6: =+B6/24 -> 0.66666667 | D6: =29000*B6 -> 464000 | E6: =+D6/28 -> 16571.429
A7: TOTAL | D7: =+SUM(D2:D6) -> 464000
A8: Volumen tratado m3 | D8: =+GETPIVOTDATA("VOL. TOTAL TRATADO PTAP (m3)",'Base de datos'!$A$1) -> 8363
A9: Volumen enviado a tanque de recirculación m3 | D9: =+GETPIVOTDATA("VOL. ENVIADO A TK RECIRCULACIÓN (m3)",'Base de datos'!$A$1) -> 5968
A10: Indicador agua tratada | D10: =+D7/D8 -> 55.482482
A11: Indicador agua enviada a tanque de recirculación | D11: =+D7/D9 -> 77.747989

Sheet Pedido Química
A1: OC | B1: Kg COF 235 | C1: Kg 280
A2: PED00370579 REQ00110574 SI25R4(NR-10981) | B2: 11925 | C2: 2600
A5: Fecha de solicitud | B5: 45968
A6: Kg COF 235 | B6: 5300
A7: Kg COF 280

Sheet CHARACTERIZATION
A1: FECHA | B1: TURNO | C1: PH IN | D1: TEMP IN | E1: TURBIDEZ IN | F1: COLOR IN | G1: TDS IN | H1: CONDU IN | I1: SST IN | J1: DUREZA IN | K1: HIERRO IN | L1: PH OUT | M1: TEMP OUT | N1: TURBIDEZ OUT | O1: COLOR OUT | P1: TDS OUT | Q1: CONDU OUT | R1: SST OUT | S1: DUREZA OUT | T1: HIERRO OUT
A2: 45558 | B2: Turno 1
A3: 45558 | B3: Turno 2
A4: 45558 | B4: Turno 3
A5: 45559 | B5: Turno 1
A6: 45559 | B6: Turno 2
A7: 45559 | B7: Turno 3
A8: 45560
A9: 45560
A10: 45560
A11: 45561
A12: 45561
A13: 45561
A14: 45562
A15: 45562
A16: 45562
A17: 45563
A18: 45563
A19: 45563
... A25: 45565

Sheet INVENTARIO
A3: COAG | B3: =+#REF!-#REF! -> #REF!
A4: FLOC | B4: =+#REF!-#REF! -> #REF!
A5: PEROX | B5: =+#REF!-#REF! -> #REF!
A8: Coagulante COF-235 | B8: 2498 | C8: 1.32
A9: Floculante COFN-440 | B9: 23.8 | C9: 2.5
A10: Peroxido de hidrogeno | B10: 2800
