Workbook

Sheet CODIGO (2)
A1: FECHA | B1: VIAJE | C1: HOROMETRO INICIAL | D1: HOROMETRO FINAL | E1: HORAS DE OPERACIÓN | F1: Q TRATAMIENTO | G1: VOLUMEN TRATADO | H1: KG GENERADOS | I1: $ Kg | J1: $ TRANSPORTE | K1: $ / KG | L1: $ AMPLIRROL | M1: META FACTOR ($/KG) | N1: FACTOR ($/KG | O1: FACTOR 2024 KG/M3 | P1: FACTOR GENERACIÓN KG/M3 | Q1: $/ M3 | R1: VOL TRATADO DIA | S1: $/M3
E2: =D2-C2 -> 0 | F2: 84 | G2: =E2*F2 -> 0 | I2: 96 | J2: 750000 | K2: =H2*I2 -> 0 | L2: =K2+J2 -> 750000 | M2: =L2/H2 -> #DIV/0! | N2: 267 | O2: 2.3 | P2: =H2/G2 -> #DIV/0! | Q2: =L2/G2 -> #DIV/0! | R2: 2000 | S2: =L2/R2 -> 375
E3: =D3-C3 -> 0 | F3: 84 | G3: =E3*F3 -> 0 | I3: 96 | J3: 750000 | K3: =H3*I3 -> 0 | L3: =K3+J3 -> 750000 | M3: =L3/H3 -> #DIV/0! | N3: 267 | O3: 2.3 | P3: =H3/G3 -> #DIV/0! | Q3: =L3/G3 -> #DIV/0! | R3: 2000 | S3: =L3/R3 -> 375
E4: =D4-C4 -> 0 | F4: 84 | G4: =E4*F4 -> 0 | I4: 96 | J4: 750000 | K4: =H4*I4 -> 0 | L4: =K4+J4 -> 750000 | M4: =L4/H4 -> #DIV/0! | N4: 267 | O4: =+O3 -> 2.3 | P4: =H4/G4 -> #DIV/0! | Q4: =L4/G4 -> #DIV/0! | R4: 2000 | S4: =L4/R4 -> 375
E5: =D5-C5 -> 0 | F5: 84 | G5: =E5*F5 -> 0 | I5: 96 | J5: 750000 | K5: =H5*I5 -> 0 | L5: =K5+J5 -> 750000 | M5: =L5/H5 -> #DIV/0! | N5: 267 | O5: =+O4 -> 2.3 | P5: =H5/G5 -> #DIV/0! | Q5: =L5/G5 -> #DIV/0! | R5: 2000 | S5: =L5/R5 -> 375
E6: =D6-C6 -> 0 | F6: 84 | G6: =E6*F6 -> 0 | I6: 96 | J6: 750000 | K6: =H6*I6 -> 0 | L6: =K6+J6 -> 750000 | M6: =L6/H6 -> #DIV/0! | N6: 267 | O6: =+O5 -> 2.3 | P6: =H6/G6 -> #DIV/0! | Q6: =L6/G6 -> #DIV/0! | R6: 2000 | S6: =L6/R6 -> 375
E7: =D7-C7 -> 0 | F7: 84 | G7: =E7*F7 -> 0 | I7: 96 | J7: 750000 | K7: =H7*I7 -> 0 | L7: =K7+J7 -> 750000 | M7: =L7/H7 -> #DIV/0! | N7: 267 | O7: =+O6 -> 2.3 | P7: =H7/G7 -> #DIV/0! | Q7: =L7/G7 -> #DIV/0! | R7: 2000 | S7: =L7/R7 -> 375
E8: =D8-C8 -> 0 | F8: 84 | G8: =E8*F8 -> 0 | I8: 96 | J8: 750000 | K8: =H8*I8 -> 0 | L8: =K8+J8 -> 750000 | M8: =L8/H8 -> #DIV/0! | N8: 267 | O8: =+O7 -> 2.3 | P8: =H8/G8 -> #DIV/0! | Q8: =L8/G8 -> #DIV/0! | R8: 2000 | S8: =L8/R8 -> 375
E9: =D9-C9 -> 0 | F9: 84 | G9: =E9*F9 -> 0 | I9: 96 | J9: 750000 | K9: =H9*I9 -> 0 | L9: =K9+J9 -> 750000 | M9: =L9/H9 -> #DIV/0! | N9: 267 | O9: =+O8 -> 2.3 | P9: =H9/G9 -> #DIV/0! | Q9: =L9/G9 -> #DIV/0! | R9: 2000 | S9: =L9/R9 -> 375

Sheet Balance Agua Trata Vs Lodo Gene
B1: AÑO 2024 | C1: Agua Tratada PTAR | D1: Lodos Generados | E1: Valor Disposición de Lodo (SIN IVA) | F1: Valor Transporte | G1: Costo Total Servicio (Transporte + Disposición)(SIN IVA) | H1: Indicador Global (Generado: Disposición+Transporte) | I1: Indicador Disposición de Lodos Generados PTAR ($/m3) | J1: Indicador Total (Transporte + Disposición Final) | K1: Indicador de Generación
B2: MES | C2: (m3) | D2: (Kg) | E2: ($) | F2: ($) | G2: ($) | H2: ($/Kg) | I2: Valor ($/m3 Tratado) | J2: Valor ($/m3 de Agua Tratada) | K2: Kg/m3
B3: ENE | C3: ='[1]Modelo de Consumo - Graficas '!P4+'[1]Modelo de Consumo - Graficas '!$M$4 -> 43573.271 | D3: ='Costo Disposición Lodos - PTAR'!K31 -> #REF! | E3: ='Costo Disposición Lodos - PTAR'!M31 -> #REF! | F3: ='Costo Disposición Lodos - PTAR'!O31 -> 20540000 | G3: =SUM(Tabla2[[#This Row],[Valor Transporte]]+Tabla2[[#This Row],[Valor Disposición de Lodo (SIN IVA)]]) -> #REF! | H3: =Tabla2[[#This Row],[Costo Total Servicio (Transporte + Disposición)(SIN IVA)]]/Tabla2[[#This Row],[Lodos Generados ]] -> #REF! | I3: =#REF!/C3 -> #REF! | J3: =Tabla2[[#This Row],[Costo Total Servicio (Transporte + Disposición)(SIN IVA)]]/Tabla2[[#This Row],[Agua Tratada PTAR ]] -> #REF! | K3: =D3/C3 -> #REF!
B4: FEB | C4: 48224.5 | D4: ='Costo Disposición Lodos - PTAR'!K60 -> #REF! | E4: ='Costo Disposición Lodos - PTAR'!M60 -> #REF! | F4: ='Costo Disposición Lodos - PTAR'!O60 -> 16500000 | G4: =SUM(Tabla2[[#This Row],[Valor Transporte]]+Tabla2[[#This Row],[Valor Disposición de Lodo (SIN IVA)]]) -> #REF! | H4: =Tabla2[[#This Row],[Costo Total Servicio (Transporte + Disposición)(SIN IVA)]]/Tabla2[[#This Row],[Lodos Generados ]] -> #REF! | I4: =#REF!/C4 -> #REF! | J4: =Tabla2[[#This Row],[Costo Total Servicio (Transporte + Disposición)(SIN IVA)]]/Tabla2[[#This Row],[Agua Tratada PTAR ]] -> #REF! | K4: =D4/C4 -> #REF!
B5: MAR
B6: ABR
B7: MAY
B8: JUN
B9: JUL
B10: AGO
B11: SEP
B12: OCT
B13: NOV
B14: DIC
B15: Consolidado Anual | C15: =SUM(C3:C13) -> 91797.771 | D15: =+SUM(D3:D13) -> #REF! | E15: =SUM(E3:E13) -> #REF! | F15: =SUM(F3:F13) -> 37040000 | G15: =SUM(G3:G13) -> #REF! | H15: =Tabla2[[#This Row],[Costo Total Servicio (Transporte + Disposición)(SIN IVA)]]/Tabla2[[#This Row],[Lodos Generados ]] -> #REF! | I15: =Tabla2[[#This Row],[Valor Disposición de Lodo (SIN IVA)]]/Tabla2[[#This Row],[Agua Tratada PTAR ]] -> #REF! | J15: =Tabla2[[#This Row],[Costo Total Servicio (Transporte + Disposición)(SIN IVA)]]/Tabla2[[#This Row],[Agua Tratada PTAR ]] -> #REF! | K15: =Tabla2[[#This Row],[Lodos Generados ]]/Tabla2[[#This Row],[Agua Tratada PTAR ]] -> #REF!
M22: ACUMULADO LODOS SEP
M23: Caudal | N23: Gene kg/m3 | O23: costo /m3
M24: 8400 | N24: =D11/C11 -> #DIV/0! | O24: 250.8862
C73: BALANCE DE LODOS
C74: Agua Tratada GEM (m3) | D74: Lodos Generados (Kg) | E74: Valor Disposición de Lodo (SIN IVA) $ | F74: Valor Transporte $ | G74: Costo Total Servicio (Transporte + Disposición)(SIN IVA) $ | H74: Indicador costo disposición ($/Kg) | I74: Indicador costo tratamiento ($/m3) | J74: Indicador de Generación (Kg/m3) | K74: Indicador costo disposición ($/m3)
C75: 54264 | D75: 146650 | E75: 14078400 | F75: 24000000 | G75: =+E75+F75 -> 38078400 | H75: =+G75/D75 -> 259.65496 | I75: =+G75/C75 -> 701.7249 | J75: =+D75/C75 -> 2.7025284 | K75: =+G75/C75 -> 701.7249

Sheet Costo Disposición Lodos - PTAR
A1: MES | B1: Remisión | C1: Fecha | D1: Cantidad Lodos Generados (Kg) | E1: Precio Unitario Disposición ($) | F1: Valor Disposición Kg ($) | G1: Costo Total + IVA | H1: Cantidad de Viajes | I1: Costo Viaje ($) | J1: Costo total (SIN IVA) | K1: Cantidad Total de Lodo Generado (Kg) | L1: Cantidad Total de Viajes | M1: Valor Total de Disposición Lodo ($) SIN IVA | N1: IVA (Disposición) | O1: Valor Total Viajes ($) | P1: COSTO TOTAL ($) (SIN IVA) | Q1: COSTO TOTAL ($) + IVA | R1: INDICADOR FINAL ($/KG)
A2: DICIEMBRE | B2: =#REF! -> #REF! | C2: =+#REF! -> #REF! | D2: =+#REF! -> #REF! | E2: 96 | F2: =+Tabla5[[#This Row],[Cantidad Lodos Generados (Kg) ]]*Tabla5[[#This Row],[Precio Unitario Disposición ($)]] -> #REF! | G2: =Tabla5[[#This Row],[Valor Disposición Kg ($)]]*1.19 -> #REF! | H2: 1 | I2: 750000 | J2: =Tabla5[[#This Row],[Valor Disposición Kg ($)]]+(Tabla5[[#This Row],[Cantidad de Viajes ]]*Tabla5[[#This Row],[Costo Viaje ($)]]) -> #REF! | K2: =SUM(D2:D83) -> #REF! | L2: =SUM(H2:H30) -> 29 | M2: =SUM(F2:F30) -> #REF! | N2: =M2*19% -> #REF! | O2: =SUM(I2:I30) -> 20830000 | P2: =M2+O2 -> #REF! | Q2: =SUM(M2+N2+O2) -> #REF! | R2: =P2/K2 -> #REF!
B3: =#REF! -> #REF! | C3: =+#REF! -> #REF! | D3: =+#REF! -> #REF! | E3: 96 | F3: =+Tabla5[[#This Row],[Cantidad Lodos Generados (Kg) ]]*Tabla5[[#This Row],[Precio Unitario Disposición ($)]] -> #REF! | G3: =Tabla5[[#This Row],[Valor Disposición Kg ($)]]*1.19 -> #REF! | H3: 1 | I3: 750000 | J3: =Tabla5[[#This Row],[Valor Disposición Kg ($)]]+(Tabla5[[#This Row],[Cantidad de Viajes ]]*Tabla5[[#This Row],[Costo Viaje ($)]]) -> #REF!
B4: =#REF! -> #REF! | C4: =+#REF! -> #REF! | D4: =+#REF! -> #REF! | E4: 96 | F4: =+Tabla5[[#This Row],[Cantidad Lodos Generados (Kg) ]]*Tabla5[[#This Row],[Precio Unitario Disposición ($)]] -> #REF! | G4: =Tabla5[[#This Row],[Valor Disposición Kg ($)]]*1.19 -> #REF! | H4: 1 | I4: 750000 | J4: =Tabla5[[#This Row],[Valor Disposición Kg ($)]]+(Tabla5[[#This Row],[Cantidad de Viajes ]]*Tabla5[[#This Row],[Costo Viaje ($)]]) -> #REF!
B5: =#REF! -> #REF! | C5: =+#REF! -> #REF! | D5: =+#REF! -> #REF! | E5: 96 | F5: =+Tabla5[[#This Row],[Cantidad Lodos Generados (Kg) ]]*Tabla5[[#This Row],[Precio Unitario Disposición ($)]] -> #REF! | G5: =Tabla5[[#This Row],[Valor Disposición Kg ($)]]*1.19 -> #REF! | H5: 1 | I5: 750000 | J5: =Tabla5[[#This Row],[Valor Disposición Kg ($)]]+(Tabla5[[#This Row],[Cantidad de Viajes ]]*Tabla5[[#This Row],[Costo Viaje ($)]]) -> #REF!
B6: =#REF! -> #REF! | C6: =+#REF! -> #REF! | D6: =+#REF! -> #REF! | E6: 96 | F6: =+Tabla5[[#This Row],[Cantidad Lodos Generados (Kg) ]]*Tabla5[[#This Row],[Precio Unitario Disposición ($)]] -> #REF! | G6: =Tabla5[[#This Row],[Valor Disposición Kg ($)]]*1.19 -> #REF! | H6: 1 | I6: 750000 | J6: =Tabla5[[#This Row],[Valor Disposición Kg ($)]]+(Tabla5[[#This Row],[Cantidad de Viajes ]]*Tabla5[[#This Row],[Costo Viaje ($)]]) -> #REF!
B7: =#REF! -> #REF! | C7: =+#REF! -> #REF! | D7: =+#REF! -> #REF! | E7: 96 | F7: =+Tabla5[[#This Row],[Cantidad Lodos Generados (Kg) ]]*Tabla5[[#This Row],[Precio Unitario Disposición ($)]] -> #REF! | G7: =Tabla5[[#This Row],[Valor Disposición Kg ($)]]*1.19 -> #REF! | H7: 1 | I7: 750000 | J7: =Tabla5[[#This Row],[Valor Disposición Kg ($)]]+(Tabla5[[#This Row],[Cantidad de Viajes ]]*Tabla5[[#This Row],[Costo Viaje ($)]]) -> #REF!
B8: =#REF! -> #REF! | C8: =+#REF! -> #REF! | D8: =+#REF! -> #REF! | E8: 96 | F8: =+Tabla5[[#This Row],[Cantidad Lodos Generados (Kg) ]]*Tabla5[[#This Row],[Precio Unitario Disposición ($)]] -> #REF! | G8: =Tabla5[[#This Row],[Valor Disposición Kg ($)]]*1.19 -> #REF! | H8: 1 | I8: 750000 | J8: =Tabla5[[#This Row],[Valor Disposición Kg ($)]]+(Tabla5[[#This Row],[Cantidad de Viajes ]]*Tabla5[[#This Row],[Costo Viaje ($)]]) -> #REF!
B9: =#REF! -> #REF! | C9: =+#REF! -> #REF! | D9: =+#REF! -> #REF! | E9: 96 | F9: =+Tabla5[[#This Row],[Cantidad Lodos Generados (Kg) ]]*Tabla5[[#This Row],[Precio Unitario Disposición ($)]] -> #REF! | G9: =Tabla5[[#This Row],[Valor Disposición Kg ($)]]*1.19 -> #REF! | H9: 1 | I9: 750000 | J9: =Tabla5[[#This Row],[Valor Disposición Kg ($)]]+(Tabla5[[#This Row],[Cantidad de Viajes ]]*Tabla5[[#This Row],[Costo Viaje ($)]]) -> #REF!
B10: =#REF! -> #REF! | C10: =+#REF! -> #REF! | D10: =+#REF! -> #REF! | E10: 96 | F10: =+Tabla5[[#This Row],[Cantidad Lodos Generados (Kg) ]]*Tabla5[[#This Row],[Precio Unitario Disposición ($)]] -> #REF! | G10: =Tabla5[[#This Row],[Valor Disposición Kg ($)]]*1.19 -> #REF! | H10: 1 | I10: 750000 | J10: =Tabla5[[#This Row],[Valor Disposición Kg ($)]]+(Tabla5[[#This Row],[Cantidad de Viajes ]]*Tabla5[[#This Row],[Costo Viaje ($)]]) -> #REF!
B11: =#REF! -> #REF! | C11: =+#REF! -> #REF! | D11: =+#REF! -> #REF! | E11: 96 | F11: =+Tabla5[[#This Row],[Cantidad Lodos Generados (Kg) ]]*Tabla5[[#This Row],[Precio Unitario Disposición ($)]] -> #REF! | G11: =Tabla5[[#This Row],[Valor Disposición Kg ($)]]*1.19 -> #REF! | H11: 1 | I11: 750000 | J11: =Tabla5[[#This Row],[Valor Disposición Kg ($)]]+(Tabla5[[#This Row],[Cantidad de Viajes ]]*Tabla5[[#This Row],[Costo Viaje ($)]]) -> #REF!
B12: =#REF! -> #REF! | C12: =+#REF! -> #REF! | D12: =+#REF! -> #REF! | E12: 96 | F12: =+Tabla5[[#This Row],[Cantidad Lodos Generados (Kg) ]]*Tabla5[[#This Row],[Precio Unitario Disposición ($)]] -> #REF! | G12: =Tabla5[[#This Row],[Valor Disposición Kg ($)]]*1.19 -> #REF! | H12: 1 | I12: 750000 | J12: =Tabla5[[#This Row],[Valor Disposición Kg ($)]]+(Tabla5[[#This Row],[Cantidad de Viajes ]]*Tabla5[[#This Row],[Costo Viaje ($)]]) -> #REF!
B13: =#REF! -> #REF! | C13: =+#REF! -> #REF! | D13: =+#REF! -> #REF! | E13: 96 | F13: =+Tabla5[[#This Row],[Cantidad Lodos Generados (Kg) ]]*Tabla5[[#This Row],[Precio Unitario Disposición ($)]] -> #REF! | G13: =Tabla5[[#This Row],[Valor Disposición Kg ($)]]*1.19 -> #REF! | H13: 1 | I13: 750000 | J13: =Tabla5[[#This Row],[Valor Disposición Kg ($)]]+(Tabla5[[#This Row],[Cantidad de Viajes ]]*Tabla5[[#This Row],[Costo Viaje ($)]]) -> #REF!
B14: =#REF! -> #REF! | C14: =+#REF! -> #REF! | D14: =+#REF! -> #REF! | E14: 96 | F14: =+Tabla5[[#This Row],[Cantidad Lodos Generados (Kg) ]]*Tabla5[[#This Row],[Precio Unitario Disposición ($)]] -> #REF! | G14: =Tabla5[[#This Row],[Valor Disposición Kg ($)]]*1.19 -> #REF! | H14: 1 | I14: 750000 | J14: =Tabla5[[#This Row],[Valor Disposición Kg ($)]]+(Tabla5[[#This Row],[Cantidad de Viajes ]]*Tabla5[[#This Row],[Costo Viaje ($)]]) -> #REF!
... B30: =#REF! -> #REF! | C30: =+#REF! -> #REF! | D30: =+#REF! -> #REF! | E30: 96 | F30: =+Tabla5[[#This Row],[Cantidad Lodos Generados (Kg) ]]*Tabla5[[#This Row],[Precio Unitario Disposición ($)]] -> #REF! | G30: =Tabla5[[#This Row],[Valor Disposición Kg ($)]]*1.19 -> #REF! | H30: 1 | I30: 750000 | J30: =Tabla5[[#This Row],[Valor Disposición Kg ($)]]+(Tabla5[[#This Row],[Cantidad de Viajes ]]*Tabla5[[#This Row],[Costo Viaje ($)]]) -> #REF!
A31: ENERO | B31: =#REF! -> #REF! | C31: =+#REF! -> #REF! | D31: =+#REF! -> #REF! | E31: 96 | F31: =+Tabla5[[#This Row],[Cantidad Lodos Generados (Kg) ]]*Tabla5[[#This Row],[Precio Unitario Disposición ($)]] -> #REF! | G31: =Tabla5[[#This Row],[Valor Disposición Kg ($)]]*1.19 -> #REF! | H31: 1 | I31: 750000 | J31: =Tabla5[[#This Row],[Valor Disposición Kg ($)]]+(Tabla5[[#This Row],[Cantidad de Viajes ]]*Tabla5[[#This Row],[Costo Viaje ($)]]) -> #REF! | K31: =SUM(D31:D59) -> #REF! | L31: =SUM(H31:H59) -> 28 | M31: =SUM(F31:F59) -> #REF! | N31: =M31*19% -> #REF! | O31: =SUM(I31:I59) -> 20540000 | P31: =M31+O31 -> #REF! | Q31: =SUM(M31+N31+O31) -> #REF! | R31: =P31/K31 -> #REF!
B32: =#REF! -> #REF! | C32: =+#REF! -> #REF! | D32: =+#REF! -> #REF! | E32: 96 | F32: =+Tabla5[[#This Row],[Cantidad Lodos Generados (Kg) ]]*Tabla5[[#This Row],[Precio Unitario Disposición ($)]] -> #REF! | G32: =Tabla5[[#This Row],[Valor Disposición Kg ($)]]*1.19 -> #REF! | H32: 1 | I32: 750000 | J32: =Tabla5[[#This Row],[Valor Disposición Kg ($)]]+(Tabla5[[#This Row],[Cantidad de Viajes ]]*Tabla5[[#This Row],[Costo Viaje ($)]]) -> #REF!
B33: =#REF! -> #REF! | C33: =+#REF! -> #REF! | D33: =+#REF! -> #REF! | E33: 96 | F33: =+Tabla5[[#This Row],[Cantidad Lodos Generados (Kg) ]]*Tabla5[[#This Row],[Precio Unitario Disposición ($)]] -> #REF! | G33: =Tabla5[[#This Row],[Valor Disposición Kg ($)]]*1.19 -> #REF! | H33: 1 | I33: 750000 | J33: =Tabla5[[#This Row],[Valor Disposición Kg ($)]]+(Tabla5[[#This Row],[Cantidad de Viajes ]]*Tabla5[[#This Row],[Costo Viaje ($)]]) -> #REF!
B34: =#REF! -> #REF! | C34: =+#REF! -> #REF! | D34: =+#REF! -> #REF! | E34: 96 | F34: =+Tabla5[[#This Row],[Cantidad Lodos Generados (Kg) ]]*Tabla5[[#This Row],[Precio Unitario Disposición ($)]] -> #REF! | G34: =Tabla5[[#This Row],[Valor Disposición Kg ($)]]*1.19 -> #REF! | H34: 1 | I34: 750000 | J34: =Tabla5[[#This Row],[Valor Disposición Kg ($)]]+(Tabla5[[#This Row],[Cantidad de Viajes ]]*Tabla5[[#This Row],[Costo Viaje ($)]]) -> #REF!
B35: =#REF! -> #REF! | C35: =+#REF! -> #REF! | D35: =+#REF! -> #REF! | E35: 96 | F35: =+Tabla5[[#This Row],[Cantidad Lodos Generados (Kg) ]]*Tabla5[[#This Row],[Precio Unitario Disposición ($)]] -> #REF! | G35: =Tabla5[[#This Row],[Valor Disposición Kg ($)]]*1.19 -> #REF! | H35: 1 | I35: 750000 | J35: =Tabla5[[#This Row],[Valor Disposición Kg ($)]]+(Tabla5[[#This Row],[Cantidad de Viajes ]]*Tabla5[[#This Row],[Costo Viaje ($)]]) -> #REF!
B36: =#REF! -> #REF! | C36: =+#REF! -> #REF! | D36: =+#REF! -> #REF! | E36: 96 | F36: =+Tabla5[[#This Row],[Cantidad Lodos Generados (Kg) ]]*Tabla5[[#This Row],[Precio Unitario Disposición ($)]] -> #REF! | G36: =Tabla5[[#This Row],[Valor Disposición Kg ($)]]*1.19 -> #REF! | H36: 1 | I36: 750000 | J36: =Tabla5[[#This Row],[Valor Disposición Kg ($)]]+(Tabla5[[#This Row],[Cantidad de Viajes ]]*Tabla5[[#This Row],[Costo Viaje ($)]]) -> #REF!
B37: =#REF! -> #REF! | C37: =+#REF! -> #REF! | D37: =+#REF! -> #REF! | E37: 96 | F37: =+Tabla5[[#This Row],[Cantidad Lodos Generados (Kg) ]]*Tabla5[[#This Row],[Precio Unitario Disposición ($)]] -> #REF! | G37: =Tabla5[[#This Row],[Valor Disposición Kg ($)]]*1.19 -> #REF! | H37: 1 | I37: 750000 | J37: =Tabla5[[#This Row],[Valor Disposición Kg ($)]]+(Tabla5[[#This Row],[Cantidad de Viajes ]]*Tabla5[[#This Row],[Costo Viaje ($)]]) -> #REF!
B38: =#REF! -> #REF! | C38: =+#REF! -> #REF! | D38: =+#REF! -> #REF! | E38: 96 | F38: =+Tabla5[[#This Row],[Cantidad Lodos Generados (Kg) ]]*Tabla5[[#This Row],[Precio Unitario Disposición ($)]] -> #REF! | G38: =Tabla5[[#This Row],[Valor Disposición Kg ($)]]*1.19 -> #REF! | H38: 1 | I38: 290000 | J38: =Tabla5[[#This Row],[Valor Disposición Kg ($)]]+(Tabla5[[#This Row],[Cantidad de Viajes ]]*Tabla5[[#This Row],[Costo Viaje ($)]]) -> #REF!
B39: =#REF! -> #REF! | C39: =+#REF! -> #REF! | D39: =+#REF! -> #REF! | E39: 96 | F39: =+Tabla5[[#This Row],[Cantidad Lodos Generados (Kg) ]]*Tabla5[[#This Row],[Precio Unitario Disposición ($)]] -> #REF! | G39: =Tabla5[[#This Row],[Valor Disposición Kg ($)]]*1.19 -> #REF! | H39: 1 | I39: 750000 | J39: =Tabla5[[#This Row],[Valor Disposición Kg ($)]]+(Tabla5[[#This Row],[Cantidad de Viajes ]]*Tabla5[[#This Row],[Costo Viaje ($)]]) -> #REF!
B40: =#REF! -> #REF! | C40: =+#REF! -> #REF! | D40: =+#REF! -> #REF! | E40: 96 | F40: =+Tabla5[[#This Row],[Cantidad Lodos Generados (Kg) ]]*Tabla5[[#This Row],[Precio Unitario Disposición ($)]] -> #REF! | G40: =Tabla5[[#This Row],[Valor Disposición Kg ($)]]*1.19 -> #REF! | H40: 1 | I40: 750000 | J40: =Tabla5[[#This Row],[Valor Disposición Kg ($)]]+(Tabla5[[#This Row],[Cantidad de Viajes ]]*Tabla5[[#This Row],[Costo Viaje ($)]]) -> #REF!
B41: =#REF! -> #REF! | C41: =+#REF! -> #REF! | D41: =+#REF! -> #REF! | E41: 96 | F41: =+Tabla5[[#This Row],[Cantidad Lodos Generados (Kg) ]]*Tabla5[[#This Row],[Precio Unitario Disposición ($)]] -> #REF! | G41: =Tabla5[[#This Row],[Valor Disposición Kg ($)]]*1.19 -> #REF! | H41: 1 | I41: 750000 | J41: =Tabla5[[#This Row],[Valor Disposición Kg ($)]]+(Tabla5[[#This Row],[Cantidad de Viajes ]]*Tabla5[[#This Row],[Costo Viaje ($)]]) -> #REF!
B42: =#REF! -> #REF! | C42: =+#REF! -> #REF! | D42: =+#REF! -> #REF! | E42: 96 | F42: =+Tabla5[[#This Row],[Cantidad Lodos Generados (Kg) ]]*Tabla5[[#This Row],[Precio Unitario Disposición ($)]] -> #REF! | G42: =Tabla5[[#This Row],[Valor Disposición Kg ($)]]*1.19 -> #REF! | H42: 1 | I42: 750000 | J42: =Tabla5[[#This Row],[Valor Disposición Kg ($)]]+(Tabla5[[#This Row],[Cantidad de Viajes ]]*Tabla5[[#This Row],[Costo Viaje ($)]]) -> #REF!
B43: =#REF! -> #REF! | C43: =+#REF! -> #REF! | D43: =+#REF! -> #REF! | E43: 96 | F43: =+Tabla5[[#This Row],[Cantidad Lodos Generados (Kg) ]]*Tabla5[[#This Row],[Precio Unitario Disposición ($)]] -> #REF! | G43: =Tabla5[[#This Row],[Valor Disposición Kg ($)]]*1.19 -> #REF! | H43: 1 | I43: 750000 | J43: =Tabla5[[#This Row],[Valor Disposición Kg ($)]]+(Tabla5[[#This Row],[Cantidad de Viajes ]]*Tabla5[[#This Row],[Costo Viaje ($)]]) -> #REF!
... B59: =#REF! -> #REF! | C59: =+#REF! -> #REF! | D59: =+#REF! -> #REF! | E59: 96 | F59: =+Tabla5[[#This Row],[Cantidad Lodos Generados (Kg) ]]*Tabla5[[#This Row],[Precio Unitario Disposición ($)]] -> #REF! | G59: =Tabla5[[#This Row],[Valor Disposición Kg ($)]]*1.19 -> #REF! | H59: 1 | I59: 750000 | J59: =Tabla5[[#This Row],[Valor Disposición Kg ($)]]+(Tabla5[[#This Row],[Cantidad de Viajes ]]*Tabla5[[#This Row],[Costo Viaje ($)]]) -> #REF!
A60: FEBRERO | B60: =#REF! -> #REF! | C60: =+#REF! -> #REF! | D60: =+#REF! -> #REF! | E60: 96 | F60: =+Tabla5[[#This Row],[Cantidad Lodos Generados (Kg) ]]*Tabla5[[#This Row],[Precio Unitario Disposición ($)]] -> #REF! | G60: =Tabla5[[#This Row],[Valor Disposición Kg ($)]]*1.19 -> #REF! | H60: 1 | I60: 750000 | J60: =Tabla5[[#This Row],[Valor Disposición Kg ($)]]+(Tabla5[[#This Row],[Cantidad de Viajes ]]*Tabla5[[#This Row],[Costo Viaje ($)]]) -> #REF! | K60: =SUM(D60:D83) -> #REF! | L60: =SUM(H60:H83) -> 22 | M60: =SUM(F60:F83) -> #REF! | N60: =M60*19% -> #REF! | O60: =SUM(I60:I83) -> 16500000 | P60: =M60+O60 -> #REF! | Q60: =SUM(M60+N60+O60) -> #REF! | R60: =P60/K60 -> #REF!
B61: =#REF! -> #REF! | C61: =+#REF! -> #REF! | D61: =+#REF! -> #REF! | E61: 96 | F61: =+Tabla5[[#This Row],[Cantidad Lodos Generados (Kg) ]]*Tabla5[[#This Row],[Precio Unitario Disposición ($)]] -> #REF! | G61: =Tabla5[[#This Row],[Valor Disposición Kg ($)]]*1.19 -> #REF! | H61: 1 | I61: 750000 | J61: =Tabla5[[#This Row],[Valor Disposición Kg ($)]]+(Tabla5[[#This Row],[Cantidad de Viajes ]]*Tabla5[[#This Row],[Costo Viaje ($)]]) -> #REF!
B62: =#REF! -> #REF! | C62: =+#REF! -> #REF! | D62: =+#REF! -> #REF! | E62: 96 | F62: =+Tabla5[[#This Row],[Cantidad Lodos Generados (Kg) ]]*Tabla5[[#This Row],[Precio Unitario Disposición ($)]] -> #REF! | G62: =Tabla5[[#This Row],[Valor Disposición Kg ($)]]*1.19 -> #REF! | H62: 1 | I62: 750000 | J62: =Tabla5[[#This Row],[Valor Disposición Kg ($)]]+(Tabla5[[#This Row],[Cantidad de Viajes ]]*Tabla5[[#This Row],[Costo Viaje ($)]]) -> #REF!
B63: =#REF! -> #REF! | C63: =+#REF! -> #REF! | D63: =+#REF! -> #REF! | E63: 96 | F63: =+Tabla5[[#This Row],[Cantidad Lodos Generados (Kg) ]]*Tabla5[[#This Row],[Precio Unitario Disposición ($)]] -> #REF! | G63: =Tabla5[[#This Row],[Valor Disposición Kg ($)]]*1.19 -> #REF! | H63: 1 | I63: 750000 | J63: =Tabla5[[#This Row],[Valor Disposición Kg ($)]]+(Tabla5[[#This Row],[Cantidad de Viajes ]]*Tabla5[[#This Row],[Costo Viaje ($)]]) -> #REF!
B65: =#REF! -> #REF! | C65: =+#REF! -> #REF! | D65: =+#REF! -> #REF! | E65: 96 | F65: =+Tabla5[[#This Row],[Cantidad Lodos Generados (Kg) ]]*Tabla5[[#This Row],[Precio Unitario Disposición ($)]] -> #REF! | G65: =Tabla5[[#This Row],[Valor Disposición Kg ($)]]*1.19 -> #REF! | H65: 1 | I65: 750000 | J65: =Tabla5[[#This Row],[Valor Disposición Kg ($)]]+(Tabla5[[#This Row],[Cantidad de Viajes ]]*Tabla5[[#This Row],[Costo Viaje ($)]]) -> #REF!
B66: =#REF! -> #REF! | C66: =+#REF! -> #REF! | D66: =+#REF! -> #REF! | E66: 96 | F66: =+Tabla5[[#This Row],[Cantidad Lodos Generados (Kg) ]]*Tabla5[[#This Row],[Precio Unitario Disposición ($)]] -> #REF! | G66: =Tabla5[[#This Row],[Valor Disposición Kg ($)]]*1.19 -> #REF! | H66: 1 | I66: 750000 | J66: =Tabla5[[#This Row],[Valor Disposición Kg ($)]]+(Tabla5[[#This Row],[Cantidad de Viajes ]]*Tabla5[[#This Row],[Costo Viaje ($)]]) -> #REF!
B67: =#REF! -> #REF! | C67: =+#REF! -> #REF! | D67: =+#REF! -> #REF! | E67: 96 | F67: =+Tabla5[[#This Row],[Cantidad Lodos Generados (Kg) ]]*Tabla5[[#This Row],[Precio Unitario Disposición ($)]] -> #REF! | G67: =Tabla5[[#This Row],[Valor Disposición Kg ($)]]*1.19 -> #REF! | H67: 1 | I67: 750000 | J67: =Tabla5[[#This Row],[Valor Disposición Kg ($)]]+(Tabla5[[#This Row],[Cantidad de Viajes ]]*Tabla5[[#This Row],[Costo Viaje ($)]]) -> #REF!
B68: =#REF! -> #REF! | C68: =+#REF! -> #REF! | D68: =+#REF! -> #REF! | E68: 96 | F68: =+Tabla5[[#This Row],[Cantidad Lodos Generados (Kg) ]]*Tabla5[[#This Row],[Precio Unitario Disposición ($)]] -> #REF! | G68: =Tabla5[[#This Row],[Valor Disposición Kg ($)]]*1.19 -> #REF! | H68: 1 | I68: 750000 | J68: =Tabla5[[#This Row],[Valor Disposición Kg ($)]]+(Tabla5[[#This Row],[Cantidad de Viajes ]]*Tabla5[[#This Row],[Costo Viaje ($)]]) -> #REF!
B69: =#REF! -> #REF! | C69: =+#REF! -> #REF! | D69: =+#REF! -> #REF! | E69: 96 | F69: =+Tabla5[[#This Row],[Cantidad Lodos Generados (Kg) ]]*Tabla5[[#This Row],[Precio Unitario Disposición ($)]] -> #REF! | G69: =Tabla5[[#This Row],[Valor Disposición Kg ($)]]*1.19 -> #REF! | H69: 1 | I69: 750000 | J69: =Tabla5[[#This Row],[Valor Disposición Kg ($)]]+(Tabla5[[#This Row],[Cantidad de Viajes ]]*Tabla5[[#This Row],[Costo Viaje ($)]]) -> #REF!
B70: =#REF! -> #REF! | C70: =+#REF! -> #REF! | D70: =+#REF! -> #REF! | E70: 96 | F70: =+Tabla5[[#This Row],[Cantidad Lodos Generados (Kg) ]]*Tabla5[[#This Row],[Precio Unitario Disposición ($)]] -> #REF! | G70: =Tabla5[[#This Row],[Valor Disposición Kg ($)]]*1.19 -> #REF! | H70: 1 | I70: 750000 | J70: =Tabla5[[#This Row],[Valor Disposición Kg ($)]]+(Tabla5[[#This Row],[Cantidad de Viajes ]]*Tabla5[[#This Row],[Costo Viaje ($)]]) -> #REF!
B71: =#REF! -> #REF! | C71: =+#REF! -> #REF! | D71: =+#REF! -> #REF! | E71: 96 | F71: =+Tabla5[[#This Row],[Cantidad Lodos Generados (Kg) ]]*Tabla5[[#This Row],[Precio Unitario Disposición ($)]] -> #REF! | G71: =Tabla5[[#This Row],[Valor Disposición Kg ($)]]*1.19 -> #REF! | H71: 1 | I71: 750000 | J71: =Tabla5[[#This Row],[Valor Disposición Kg ($)]]+(Tabla5[[#This Row],[Cantidad de Viajes ]]*Tabla5[[#This Row],[Costo Viaje ($)]]) -> #REF!
...

Sheet Disposición Lodos Díario- PTAR
A1: 2026 | B1: MF | C1: Fecha | D1: Sede | E1: Ciudad | F1: Tpo de Residuo | G1: Manejo Final | H1: Empresa Transportadora | I1: Empresa de Gestión Final | J1: Cantidad Lodos Generados (Kg) | K1: Precio Unitario Disposición ($) | L1: Valor Disposición Kg ($) | M1: Costo Total + IVA | N1: Servicio
A2: ENERO | B2: 47581 | C2: 2026-01-03 | D2: PTAR | E2: Bogotá | F2: Lodos PTAR | G2: Disposición Final | H2: PLANETA SAS ESP | I2: Planeta S.A.S | J2: 6100 | K2: 96 | L2: =+Tabla52[[#This Row],[Cantidad Lodos Generados (Kg) ]]*Tabla52[[#This Row],[Precio Unitario Disposición ($)]] -> 585600 | M2: =Tabla52[[#This Row],[Valor Disposición Kg ($)]]*1.19 -> 696864 | N2: Contenedor
B3: 47664 | C3: 2026-01-06 | D3: PTAR | E3: Bogotá | F3: Lodos PTAR | G3: Disposición Final | H3: PLANETA SAS ESP | I3: Planeta S.A.S | J3: 5830 | K3: 96 | L3: =+Tabla52[[#This Row],[Cantidad Lodos Generados (Kg) ]]*Tabla52[[#This Row],[Precio Unitario Disposición ($)]] -> 559680 | M3: =Tabla52[[#This Row],[Valor Disposición Kg ($)]]*1.19 -> 666019.2 | N3: Contenedor
B4: 47769 | C4: 2026-01-08 | D4: PTAR | E4: Bogotá | F4: Lodos PTAR | G4: Disposición Final | H4: PLANETA SAS ESP | I4: Planeta S.A.S | J4: 5630 | K4: 96 | L4: =+Tabla52[[#This Row],[Cantidad Lodos Generados (Kg) ]]*Tabla52[[#This Row],[Precio Unitario Disposición ($)]] -> 540480 | M4: =Tabla52[[#This Row],[Valor Disposición Kg ($)]]*1.19 -> 643171.2 | N4: Contenedor
B5: 47975 | C5: 2026-01-12 | D5: PTAR | E5: Bogotá | F5: Lodos PTAR | G5: Disposición Final | H5: PLANETA SAS ESP | I5: Planeta S.A.S | J5: 3730 | K5: 96 | L5: =+Tabla52[[#This Row],[Cantidad Lodos Generados (Kg) ]]*Tabla52[[#This Row],[Precio Unitario Disposición ($)]] -> 358080 | M5: =Tabla52[[#This Row],[Valor Disposición Kg ($)]]*1.19 -> 426115.2 | N5: Contenedor
B6: 47911 | C6: 2026-01-13 | D6: PTAR | E6: Bogotá | F6: Lodos PTAR | G6: Disposición Final | H6: PLANETA SAS ESP | I6: Planeta S.A.S | J6: 5320 | K6: 96 | L6: =+Tabla52[[#This Row],[Cantidad Lodos Generados (Kg) ]]*Tabla52[[#This Row],[Precio Unitario Disposición ($)]] -> 510720 | M6: =Tabla52[[#This Row],[Valor Disposición Kg ($)]]*1.19 -> 607756.8 | N6: Contenedor
B7: 48064 | C7: 2026-01-14 | D7: PTAR | E7: Bogotá | F7: Lodos PTAR | G7: Disposición Final | H7: PLANETA SAS ESP | I7: Planeta S.A.S | J7: 4390 | K7: 96 | L7: =+Tabla52[[#This Row],[Cantidad Lodos Generados (Kg) ]]*Tabla52[[#This Row],[Precio Unitario Disposición ($)]] -> 421440 | M7: =Tabla52[[#This Row],[Valor Disposición Kg ($)]]*1.19 -> 501513.6 | N7: Contenedor
B8: 48009 | C8: 2026-01-14 | D8: PTAR | E8: Bogotá | F8: Lodos PTAR | G8: Disposición Final | H8: PLANETA SAS ESP | I8: Planeta S.A.S | J8: 2787.2 | K8: 96 | L8: =+Tabla52[[#This Row],[Cantidad Lodos Generados (Kg) ]]*Tabla52[[#This Row],[Precio Unitario Disposición ($)]] -> 267571.2 | M8: =Tabla52[[#This Row],[Valor Disposición Kg ($)]]*1.19 -> 318409.73 | N8: Canecas
B9: 47993 | C9: 2026-01-14 | D9: PTAR | E9: Bogotá | F9: Lodos PTAR | G9: Disposición Final | H9: PLANETA SAS ESP | I9: Planeta S.A.S | J9: 5800 | K9: 96 | L9: =+Tabla52[[#This Row],[Cantidad Lodos Generados (Kg) ]]*Tabla52[[#This Row],[Precio Unitario Disposición ($)]] -> 556800 | M9: =Tabla52[[#This Row],[Valor Disposición Kg ($)]]*1.19 -> 662592 | N9: Contenedor
B10: 48054 | C10: 2026-01-15 | D10: PTAR | E10: Bogotá | F10: Lodos PTAR | G10: Disposición Final | H10: PLANETA SAS ESP | I10: Planeta S.A.S | J10: 5190 | K10: 96 | L10: =+Tabla52[[#This Row],[Cantidad Lodos Generados (Kg) ]]*Tabla52[[#This Row],[Precio Unitario Disposición ($)]] -> 498240 | M10: =Tabla52[[#This Row],[Valor Disposición Kg ($)]]*1.19 -> 592905.6 | N10: Contenedor
B11: 48103 | C11: 2026-01-16 | D11: PTAR | E11: Bogotá | F11: Lodos PTAR | G11: Disposición Final | H11: PLANETA SAS ESP | I11: Planeta S.A.S | J11: 3560 | K11: 96 | L11: =+Tabla52[[#This Row],[Cantidad Lodos Generados (Kg) ]]*Tabla52[[#This Row],[Precio Unitario Disposición ($)]] -> 341760 | M11: =Tabla52[[#This Row],[Valor Disposición Kg ($)]]*1.19 -> 406694.4 | N11: Contenedor
B12: 48170 | C12: 2026-01-17 | D12: PTAR | E12: Bogotá | F12: Lodos PTAR | G12: Disposición Final | H12: PLANETA SAS ESP | I12: Planeta S.A.S | J12: 3970 | K12: 96 | L12: =+Tabla52[[#This Row],[Cantidad Lodos Generados (Kg) ]]*Tabla52[[#This Row],[Precio Unitario Disposición ($)]] -> 381120 | M12: =Tabla52[[#This Row],[Valor Disposición Kg ($)]]*1.19 -> 453532.8 | N12: Contenedor
B13: 48251 | C13: 2026-01-19 | D13: PTAR | E13: Bogotá | F13: Lodos PTAR | G13: Disposición Final | H13: PLANETA SAS ESP | I13: Planeta S.A.S | J13: 7920 | K13: 96 | L13: =+Tabla52[[#This Row],[Cantidad Lodos Generados (Kg) ]]*Tabla52[[#This Row],[Precio Unitario Disposición ($)]] -> 760320 | M13: =Tabla52[[#This Row],[Valor Disposición Kg ($)]]*1.19 -> 904780.8 | N13: Contenedor
B14: 48203 | C14: 2026-01-19 | D14: PTAR | E14: Bogotá | F14: Lodos PTAR | G14: Disposición Final | H14: PLANETA SAS ESP | I14: Planeta S.A.S | J14: 4600 | K14: 96 | L14: =+Tabla52[[#This Row],[Cantidad Lodos Generados (Kg) ]]*Tabla52[[#This Row],[Precio Unitario Disposición ($)]] -> 441600 | M14: =Tabla52[[#This Row],[Valor Disposición Kg ($)]]*1.19 -> 525504 | N14: Contenedor
... B21: 48743 | C21: 2026-01-29 | D21: PTAR | E21: Bogotá | F21: Lodos PTAR | G21: Disposición Final | H21: PLANETA SAS ESP | I21: Planeta S.A.S | J21: 5670 | K21: 96 | L21: =+Tabla52[[#This Row],[Cantidad Lodos Generados (Kg) ]]*Tabla52[[#This Row],[Precio Unitario Disposición ($)]] -> 544320 | M21: =Tabla52[[#This Row],[Valor Disposición Kg ($)]]*1.19 -> 647740.8 | N21: Contenedor
B22: 48843 | C22: 2026-01-30 | D22: PTAR | E22: Bogotá | F22: Lodos PTAR | G22: Disposición Final | H22: PLANETA SAS ESP | I22: Planeta S.A.S | J22: 4100 | K22: 96 | L22: =+Tabla52[[#This Row],[Cantidad Lodos Generados (Kg) ]]*Tabla52[[#This Row],[Precio Unitario Disposición ($)]] -> 393600 | M22: =+L22*1.19 -> 468384 | N22: Contenedor
A23: FEBRERO | B23: 48961 | C23: 2026-02-02 | D23: PTAR | E23: Bogotá | F23: Lodos PTAR | G23: Disposición Final | H23: PLANETA SAS ESP | I23: Planeta S.A.S | J23: 5260 | K23: 96 | L23: =+J23*K23 -> 504960 | M23: =+L23*1.19 -> 600902.4 | N23: Contenedor
B24: 49062 | C24: 2026-02-03 | D24: PTAR | E24: Bogotá | F24: Lodos PTAR | G24: Disposición Final | H24: PLANETA SAS ESP | I24: Planeta S.A.S | J24: 5860 | K24: 96 | L24: =+J24*K24 -> 562560 | M24: =+L24*1.19 -> 669446.4 | N24: Contenedor
B25: 49174 | C25: 2026-02-04 | D25: PTAR | E25: Bogotá | F25: Lodos PTAR | G25: Disposición Final | H25: PLANETA SAS ESP | I25: Planeta S.A.S | J25: 4610 | K25: 96 | L25: =+J25*K25 -> 442560 | M25: =+L25*1.19 -> 526646.4 | N25: Contenedor
B26: 49123 | C26: 2026-02-04 | D26: PTAR | E26: Bogotá | F26: Lodos PTAR | G26: Disposición Final | H26: PLANETA SAS ESP | I26: Planeta S.A.S | J26: 5490 | K26: 96 | L26: =+J26*K26 -> 527040 | M26: =+L26*1.19 -> 627177.6 | N26: Contenedor
B27: 49096 | C27: 2026-02-04 | D27: PTAR | E27: Bogotá | F27: Lodos PTAR | G27: Disposición Final | H27: PLANETA SAS ESP | I27: Planeta S.A.S | J27: 5760 | K27: 96 | L27: =+J27*K27 -> 552960 | M27: =+L27*1.19 -> 658022.4 | N27: Contenedor
B28: 49143 | C28: 2026-02-05 | D28: PTAR | E28: Bogotá | F28: Lodos PTAR | G28: Disposición Final | H28: PLANETA SAS ESP | I28: Planeta S.A.S | J28: 5220 | K28: 96 | L28: =+J28*K28 -> 501120 | M28: =+L28*1.19 -> 596332.8 | N28: Contenedor
B29: 49211 | C29: 2026-02-06 | D29: PTAR | E29: Bogotá | F29: Lodos PTAR | G29: Disposición Final | H29: PLANETA SAS ESP | I29: Planeta S.A.S | J29: 4170 | K29: 96 | L29: =+J29*K29 -> 400320 | M29: =+L29*1.19 -> 476380.8 | N29: Contenedor
B30: 49265 | C30: 2026-02-07 | D30: PTAR | E30: Bogotá | F30: Lodos PTAR | G30: Disposición Final | H30: PLANETA SAS ESP | I30: Planeta S.A.S | J30: 4960 | K30: 96 | L30: =+J30*K30 -> 476160 | M30: =+L30*1.19 -> 566630.4 | N30: Contenedor
B31: 49345 | C31: 2026-02-09 | D31: PTAR | E31: Bogotá | F31: Lodos PTAR | G31: Disposición Final | H31: PLANETA SAS ESP | I31: Planeta S.A.S | J31: 4190 | K31: 96 | L31: =+J31*K31 -> 402240 | M31: =+L31*1.19 -> 478665.6 | N31: Contenedor
B32: 49470 | C32: 2026-02-11 | D32: PTAR | E32: Bogotá | F32: Lodos PTAR | G32: Disposición Final | H32: PLANETA SAS ESP | I32: Planeta S.A.S | J32: 5410 | K32: 96 | L32: =+J32*K32 -> 519360 | M32: =+L32*1.19 -> 618038.4 | N32: Contenedor
B33: 49555 | C33: 2026-02-12 | D33: PTAR | E33: Bogotá | F33: Lodos PTAR | G33: Disposición Final | H33: PLANETA SAS ESP | I33: Planeta S.A.S | J33: 4700 | K33: 96 | L33: =+J33*K33 -> 451200 | M33: =+L33*1.19 -> 536928 | N33: Contenedor
B34: 49513 | C34: 2026-02-12 | D34: PTAR | E34: Bogotá | F34: Lodos PTAR | G34: Disposición Final | H34: PLANETA SAS ESP | I34: Planeta S.A.S | J34: 2960 | K34: 96 | L34: =+J34*K34 -> 284160 | M34: =+L34*1.19 -> 338150.4 | N34: Contenedor
B35: 49663 | C35: 2026-02-14 | D35: PTAR | E35: Bogotá | F35: Lodos PTAR | G35: Disposición Final | H35: PLANETA SAS ESP | I35: Planeta S.A.S | J35: 4600 | K35: 96 | L35: =+J35*K35 -> 441600 | M35: =+L35*1.19 -> 525504 | N35: Contenedor
... B40: 50226 | C40: 2026-02-25 | D40: PTAR | E40: Bogotá | F40: Lodos PTAR | G40: Disposición Final | H40: PLANETA SAS ESP | I40: Planeta S.A.S | J40: 3916.6 | K40: 96 | L40: =+J40*K40 -> 375993.6 | M40: =+L40*1.19 -> 447432.38 | N40: Canecas
A41: MARZO | B41: 50531 | C41: 2026-03-02 | D41: PTAR | E41: Bogotá | F41: Lodos PTAR | G41: Disposición Final | H41: PLANETA SAS ESP | I41: Planeta S.A.S | J41: 5580 | K41: 96 | L41: =+J41*K41 -> 535680 | M41: =+L41*1.19 -> 637459.2 | N41: Contenedor
B42: 50730 | C42: 2026-03-05 | D42: PTAR | E42: Bogotá | F42: Lodos PTAR | G42: Disposición Final | H42: PLANETA SAS ESP | I42: Planeta S.A.S | J42: 4440 | K42: 96 | L42: =+J42*K42 -> 426240 | M42: =+L42*1.19 -> 507225.6 | N42: Contenedor
B43: 50684 | C43: 2026-03-05 | D43: PTAR | E43: Bogotá | F43: Lodos PTAR | G43: Disposición Final | H43: PLANETA SAS ESP | I43: Planeta S.A.S | J43: 2507 | K43: 96 | L43: =+J43*K43 -> 240672 | M43: =+L43*1.19 -> 286399.68 | N43: Canecas
B44: 50812 | C44: 2026-03-07 | D44: PTAR | E44: Bogotá | F44: Lodos PTAR | G44: Disposición Final | H44: PLANETA SAS ESP | I44: Planeta S.A.S | J44: 4530 | K44: 96 | L44: =+J44*K44 -> 434880 | M44: =+L44*1.19 -> 517507.2 | N44: Contenedor
B45: 50934 | C45: 2026-03-10 | D45: PTAR | E45: Bogotá | F45: Lodos PTAR | G45: Disposición Final | H45: PLANETA SAS ESP | I45: Planeta S.A.S | J45: 5060 | K45: 96 | L45: =+J45*K45 -> 485760 | M45: =+L45*1.19 -> 578054.4 | N45: Contenedor
B46: 51040 | C46: 2026-03-12 | D46: PTAR | E46: Bogotá | F46: Lodos PTAR | G46: Disposición Final | H46: PLANETA SAS ESP | I46: Planeta S.A.S | J46: 5490 | K46: 96 | L46: =+J46*K46 -> 527040 | M46: =+L46*1.19 -> 627177.6 | N46: Contenedor
B47: 51174 | C47: 2026-03-14 | D47: PTAR | E47: Bogotá | F47: Lodos PTAR | G47: Disposición Final | H47: PLANETA SAS ESP | I47: Planeta S.A.S | J47: 4580 | K47: 96 | L47: =+J47*K47 -> 439680 | M47: =+L47*1.19 -> 523219.2 | N47: Contenedor
B48: 51282 | C48: 2026-03-17 | D48: PTAR | E48: Bogotá | F48: Lodos PTAR | G48: Disposición Final | H48: PLANETA SAS ESP | I48: Planeta S.A.S | J48: 3770 | K48: 96 | L48: =+J48*K48 -> 361920 | M48: =+L48*1.19 -> 430684.8 | N48: Contenedor
B49: 51577 | C49: 2026-03-23 | D49: PTAR | E49: Bogotá | F49: Lodos PTAR | G49: Disposición Final | H49: PLANETA SAS ESP | I49: Planeta S.A.S | J49: 5080 | K49: 96 | L49: =+J49*K49 -> 487680 | M49: =+L49*1.19 -> 580339.2 | N49: Contenedor
B50: 51683 | C50: 2026-03-26 | D50: PTAR | E50: Bogotá | F50: Lodos PTAR | G50: Disposición Final | H50: PLANETA SAS ESP | I50: Planeta S.A.S | J50: 3570 | K50: 96 | L50: =+J50*K50 -> 342720 | M50: =+L50*1.19 -> 407836.8 | N50: Contenedor
...

Sheet consolidado diario
A1: FECHA | B1: N | C1: Kg | D1: GEM m3 | E1: kg/m3 | F1: factor Kg/m3 | G1: valor kg | H1: transporte | I1: $/dia | J1: $/kg | K1: factor $/kg | L1: ajuste de factor | M1: ajuste de transporte
A2: 45536 | B2: 1 | C2: 0 | D2: 0 | F2: 2.8 | K2: 283
A3: 45537 | B3: 2 | C3: 3730 | D3: 1520 | E3: =+C3/D3 -> 2.4539474 | F3: 2.8 | G3: =+C3*96 -> 358080 | H3: 750000 | I3: =+G3+H3 -> 1108080 | J3: =+I3/C3 -> 297.07239 | K3: 283
A4: 45538 | B4: 3 | C4: 5040 | D4: 1680 | E4: =+C4/D4 -> 3 | F4: 2.8 | G4: =+C4*96 -> 483840 | H4: 750000 | I4: =+G4+H4 -> 1233840 | J4: =+I4/C4 -> 244.80952 | K4: 283
A5: 45539 | B5: 4 | C5: =+$L$7*D5 -> 3582.24 | D5: 1360 | E5: =+C5/D5 -> 2.634 | F5: 2.8 | G5: =+C5*96 -> 343895.04 | H5: =+$M$7*C5 -> 353600 | I5: =+G5+H5 -> 697495.04 | J5: =+I5/C5 -> 194.70919 | K5: 283
A6: 45540 | B6: 5 | C6: =+$L$7*D6 -> 3582.24 | D6: 1360 | E6: =+C6/D6 -> 2.634 | F6: 2.8 | G6: =+C6*96 -> 343895.04 | H6: =+$M$7*C6 -> 353600 | I6: =+G6+H6 -> 697495.04 | J6: =+I6/C6 -> 194.70919 | K6: 283
A7: 45541 | B7: 6 | C7: =+$L$7*D7 -> 3371.52 | D7: 1280 | E7: =+C7/D7 -> 2.634 | F7: 2.8 | G7: =+C7*96 -> 323665.92 | H7: =+$M$7*C7 -> 332800 | I7: =+G7+H7 -> 656465.92 | J7: =+I7/C7 -> 194.70919 | K7: 283 | L7: =10536/4000 -> 2.634 | M7: =1040000/10536 -> 98.709188
A8: 45542 | B8: 7 | C8: 4040 | D8: 1520 | E8: =+C8/D8 -> 2.6578947 | F8: 2.8 | G8: =+C8*96 -> 387840 | H8: 750000 | I8: =+G8+H8 -> 1137840 | J8: =+I8/C8 -> 281.64356 | K8: 283
A9: 45543 | B9: 8 | C9: =+$L$9*D9 -> 2745 | D9: 1360 | E9: =+C9/D9 -> 2.0183824 | F9: 2.8 | G9: =+C9*96 -> 263520 | H9: =+$M$9*C9 -> 375000 | I9: =+G9+H9 -> 638520 | J9: =+I9/C9 -> 232.61202 | K9: 283 | L9: =5490/2720 -> 2.0183824 | M9: =750000/5490 -> 136.61202
A10: 45544 | B10: 9 | C10: =+$L$10*D10 -> 2745 | D10: 1360 | E10: =+C10/D10 -> 2.0183824 | F10: 2.8 | G10: =+C10*96 -> 263520 | H10: =+$M$9*C10 -> 375000 | I10: =+G10+H10 -> 638520 | J10: =+I10/C10 -> 232.61202 | K10: 283 | L10: =5490/2720 -> 2.0183824 | M10: =750000/5490 -> 136.61202
A11: 45545 | B11: 10 | C11: =+$L$11*D11 -> 3150 | D11: 1440 | E11: =+C11/D11 -> 2.1875 | F11: 2.8 | G11: =+C11*96 -> 302400 | H11: =+$M$11*C11 -> 355263.16 | I11: =+G11+H11 -> 657663.16 | J11: =+I11/C11 -> 208.78195 | K11: 283 | L11: =6650/3040 -> 2.1875 | M11: =750000/6650 -> 112.78195
A12: 45546 | B12: 11 | C12: =+$L$11*D12 -> 3500 | D12: 1600 | E12: =+C12/D12 -> 2.1875 | F12: 2.8 | G12: =+C12*96 -> 336000 | H12: =+$M$11*C12 -> 394736.84 | I12: =+G12+H12 -> 730736.84 | J12: =+I12/C12 -> 208.78195 | K12: 283 | L12: =6650/3040 -> 2.1875 | M12: =750000/6650 -> 112.78195
A13: 45547 | B13: 12 | C13: 3890 | D13: 1680 | E13: =+C13/D13 -> 2.3154762 | F13: 2.8 | G13: =+C13*96 -> 373440 | H13: 750000 | I13: =+G13+H13 -> 1123440 | J13: =+I13/C13 -> 288.80206 | K13: 283
A14: 45548 | B14: 13 | C14: 3920 | D14: 1920 | E14: =+C14/D14 -> 2.0416667 | F14: 2.8 | G14: =+C14*96 -> 376320 | H14: 750000 | I14: =+G14+H14 -> 1126320 | J14: =+I14/C14 -> 287.32653 | K14: 283
A15: 45549 | B15: 14 | C15: 0 | D15: 160 | E15: =+C15/D15 -> 0 | F15: 2.8 | G15: =+C15*96 -> 0 | H15: =+$M$14*C15 -> 0 | I15: =+G15+H15 -> 0 | J15: 0 | K15: 283
A16: 45550 | B16: 15 | C16: =+$L$14*D16 -> 0 | D16: 0 | E16: 0 | F16: 2.8 | G16: =+C16*96 -> 0 | H16: =+$M$14*C16 -> 0 | I16: =+G16+H16 -> 0 | J16: 0 | K16: 283
A17: 45551 | B17: 16 | C17: 1684 | D17: 1280 | E17: =+C17/D17 -> 1.315625 | F17: 2.8 | G17: =+C17*96 -> 161664 | H17: =+(750000*C17)/4000 -> 315750 | I17: =+G17+H17 -> 477414 | J17: =+I17/C17 -> 283.5 | K17: 283
A18: 45552 | B18: 17 | C18: =4000-C17 -> 2316 | D18: 1760 | E18: =+C18/D18 -> 1.3159091 | F18: 2.8 | G18: =+C18*96 -> 222336 | H18: =750000-H17 -> 434250 | I18: =+G18+H18 -> 656586 | J18: =+I18/C18 -> 283.5 | K18: 283
A19: 45553 | B19: 18 | C19: 4550 | D19: 1680 | E19: =+C19/D19 -> 2.7083333 | F19: 2.8 | G19: =+C19*96 -> 436800 | H19: 750000 | I19: =+G19+H19 -> 1186800 | J19: =+I19/C19 -> 260.83516 | K19: 283
A20: 45554 | B20: 19 | C20: 4330 | D20: 1520 | E20: =+C20/D20 -> 2.8486842 | F20: 2.8 | G20: =+C20*96 -> 415680 | H20: 750000 | I20: =+G20+H20 -> 1165680 | J20: =+I20/C20 -> 269.21016 | K20: 283
A21: 45555 | B21: 20 | C21: 3840 | D21: 1760 | E21: =+C21/D21 -> 2.1818182 | F21: 2.8 | G21: =+C21*96 -> 368640 | H21: 750000 | I21: =+G21+H21 -> 1118640 | J21: =+I21/C21 -> 291.3125 | K21: 283
A22: 45556 | B22: 21 | C22: 5340 | D22: 1760 | E22: =+C22/D22 -> 3.0340909 | F22: 2.8 | G22: =+C22*96 -> 512640 | H22: 750000 | I22: =+G22+H22 -> 1262640 | J22: =+I22/C22 -> 236.44944 | K22: 283
A23: 45557 | B23: 22 | C23: =L23*D23 -> 384.70588 | D23: 240 | E23: =+C23/D23 -> 1.6029412 | F23: 2.8 | G23: =+C23*96 -> 36931.765 | H23: =C23*M23 -> 66176.471 | I23: =+G23+H23 -> 103108.24 | J23: =+I23/C23 -> 268.01835 | K23: 283 | L23: =4360/2720 -> 1.6029412 | M23: =750000/4360 -> 172.01835
A24: 45558 | B24: 23 | C24: =L24*D24 -> 1795.2941 | D24: 1120 | E24: =+C24/D24 -> 1.6029412 | F24: 2.8 | G24: =+C24*96 -> 172348.24 | H24: =C24*M24 -> 308823.53 | I24: =+G24+H24 -> 481171.76 | J24: =+I24/C24 -> 268.01835 | K24: 283 | L24: =4360/2720 -> 1.6029412 | M24: =750000/4360 -> 172.01835
A25: 45559 | B25: 24 | C25: =L25*D25 -> 2180 | D25: 1360 | E25: =+C25/D25 -> 1.6029412 | F25: 2.8 | G25: =+C25*96 -> 209280 | H25: =C25*M25 -> 375000 | I25: =+G25+H25 -> 584280 | J25: =+I25/C25 -> 268.01835 | K25: 283 | L25: =4360/2720 -> 1.6029412 | M25: =750000/4360 -> 172.01835
A26: 45560 | B26: 25 | C26: 5220 | D26: 1680 | E26: =+C26/D26 -> 3.1071429 | F26: 2.8 | G26: =+C26*96 -> 501120 | H26: 750000 | I26: =+G26+H26 -> 1251120 | J26: =+I26/C26 -> 239.67816 | K26: 283
A27: 45561 | B27: 26 | C27: 3950 | D27: 1680 | E27: =+C27/D27 -> 2.3511905 | F27: 2.8 | G27: =+C27*96 -> 379200 | H27: 750000 | I27: =+G27+H27 -> 1129200 | J27: =+I27/C27 -> 285.87342 | K27: 283
A28: 45562 | B28: 27 | C28: 4560 | D28: 1600 | E28: =+C28/D28 -> 2.85 | F28: 2.8 | G28: =+C28*96 -> 437760 | H28: 750000 | I28: =+G28+H28 -> 1187760 | J28: =+I28/C28 -> 260.47368 | K28: 283
A29: 45563 | B29: 28 | C29: 4870 | D29: 1600 | E29: =+C29/D29 -> 3.04375 | F29: 2.8 | G29: =+C29*96 -> 467520 | H29: 750000 | I29: =+G29+H29 -> 1217520 | J29: =+I29/C29 -> 250.00411 | K29: 283
A30: 45564 | B30: 29 | C30: =+M31 -> 2779.6875 | D30: 1360 | E30: =+C30/D30 -> 2.0438879 | F30: 2.8 | G30: =+C30*96 -> 266850 | H30: =750000/2 -> 375000 | I30: =+G30+H30 -> 641850 | J30: =+I30/C30 -> 230.90725 | K30: 283
A31: 45565 | B31: 30 | C31: =+M31 -> 2779.6875 | D31: 1200 | E31: =+C31/D31 -> 2.3164062 | F31: 2.8 | G31: =+C31*96 -> 266850 | H31: =750000/2 -> 375000 | I31: =+G31+H31 -> 641850 | J31: =+I31/C31 -> 230.90725 | K31: 283 | L31: =5930/2560 -> 2.3164062 | M31: =+D31*L31 -> 2779.6875
C32: =SUM(C2:C31) -> 93875.375 | D32: =SUM(D2:D31) -> 39840 | E32: =+C32/D32 -> 2.3563096 | G32: =SUM(G3:G31) -> 9012036 | H32: =SUM(H3:H31) -> 14540000 | I32: =SUM(I3:I31) -> 23552036 | J32: =+I32/C32 -> 250.8862

Sheet consolidado diario (2)
A1: FECHA | B1: N | C1: Kg | D1: GEM m3 | E1: kg/m3 | F1: factor Kg/m3 | G1: valor kg | H1: transporte | I1: $/dia | J1: $/kg | K1: factor $/kg | L1: ajuste de factor | M1: ajuste de transporte
A2: 45566 | B2: 1 | C2: 2950 | D2: 960 | E2: =+C2/D2 -> 3.0729167 | F2: 2.8 | G2: =+C2*96 -> 283200 | H2: 750000 | I2: =+G2+H2 -> 1033200 | J2: =+I2/C2 -> 350.23729 | K2: 283
A3: 45567 | B3: 2 | C3: 4210 | D3: 1840 | E3: =+C3/D3 -> 2.2880435 | F3: 2.8 | G3: =+C3*96 -> 404160 | H3: 750000 | I3: =+G3+H3 -> 1154160 | J3: =+I3/C3 -> 274.14727 | K3: 283
A4: 45568 | B4: 3 | C4: =L5*D4 -> 2801.7391 | D4: 1920 | E4: =+C4/D4 -> 1.4592391 | F4: 2.8 | G4: =+C4*96 -> 268966.96 | H4: =+M5*C4 -> 391304.35 | I4: =+G4+H4 -> 660271.3 | J4: =+I4/C4 -> 235.6648 | K4: 283 | L4: 1.4592391 | M4: 139.6648
A5: 45569 | B5: 4 | C5: =D5*L5 -> 2568.2609 | D5: 1760 | E5: =+C5/D5 -> 1.4592391 | F5: 2.8 | G5: =+C5*96 -> 246553.04 | H5: =+M5*C5 -> 358695.65 | I5: =+G5+H5 -> 605248.7 | J5: =+I5/C5 -> 235.6648 | K5: 283 | L5: =5370/3680 -> 1.4592391 | M5: =750000/5370 -> 139.6648
A6: 45570 | B6: 5 | C6: 4970 | D6: 480 | E6: =+C6/D6 -> 10.354167 | F6: 2.8 | G6: =+C5*96 -> 246553.04 | H6: 750000 | I6: =+G6+H6 -> 996553.04 | J6: =+I6/C6 -> 200.51369 | K6: 283
A7: 45571 | B7: 6 | C7: 0 | D7: 0 | E7: =+C7/D7 -> #DIV/0! | F7: 2.8 | G7: =+C7*96 -> 0 | H7: =+$M$7*C6 -> 0 | I7: =+G7+H7 -> 0 | J7: =+I7/C7 -> #DIV/0! | K7: 283
A8: 45572 | B8: 7 | C8: =+D8*L9 -> 3330 | D8: 1440 | E8: =+C8/D8 -> 2.3125 | F8: 2.8 | G8: =+C8*96 -> 319680 | H8: 375000 | I8: =+G8+H8 -> 694680 | J8: =+I8/C8 -> 208.61261 | K8: 283 | L8: 2.31 | M8: 112.6
A9: 45573 | B9: 8 | C9: =+D9*L9 -> 3330 | D9: 1440 | E9: =+C9/D9 -> 2.3125 | F9: 2.8 | G9: =+C9*96 -> 319680 | H9: =+C9*M9 -> 375000 | I9: =+G9+H9 -> 694680 | J9: =+I9/C9 -> 208.61261 | K9: 283 | L9: 2.3125 | M9: =750000/6660 -> 112.61261
A10: 45574 | B10: 9 | C10: 4580 | D10: 1680 | E10: =+C10/D10 -> 2.7261905 | F10: 2.8 | G10: =+C10*96 -> 439680 | H10: 750000 | I10: =+G10+H10 -> 1189680 | J10: =+I10/C10 -> 259.75546 | K10: 283
A11: 45575 | B11: 10 | C11: 3630 | D11: 1840 | E11: =+C11/D11 -> 1.9728261 | F11: 2.8 | G11: =+C11*96 -> 348480 | H11: 750000 | I11: =+G11+H11 -> 1098480 | J11: =+I11/C11 -> 302.61157 | K11: 283
A12: 45576 | B12: 11 | C12: 4450 | D12: 1600 | E12: =+C12/D12 -> 2.78125 | F12: 2.8 | G12: =+C12*96 -> 427200 | H12: 750000 | I12: =+G12+H12 -> 1177200 | J12: =+I12/C12 -> 264.53933 | K12: 283
A13: 45577 | B13: 12 | C13: 5130 | D13: 1680 | E13: =+C13/D13 -> 3.0535714 | F13: 2.8 | G13: =+C13*96 -> 492480 | H13: 750000 | I13: =+G13+H13 -> 1242480 | J13: =+I13/C13 -> 242.19883 | K13: 283
A14: 45578 | B14: 13 | C14: =+D14*2 -> 640 | D14: 320 | E14: =+C14/D14 -> 2 | F14: 2.8 | G14: =+C14*96 -> 61440 | H14: =+C14*M14 -> 111111.11 | I14: =+G14+H14 -> 172551.11 | J14: =+I14/C14 -> 269.61111 | K14: 283 | L14: =+C14/D14 -> 2 | M14: =750000/4320 -> 173.61111
A15: 45579 | B15: 14 | C15: =+D15*2 -> 480 | D15: 240 | E15: =+C15/D15 -> 2 | F15: 2.8 | G15: =+C15*96 -> 46080 | H15: =+C15*M15 -> 83333.333 | I15: =+G15+H15 -> 129413.33 | J15: =+I15/C15 -> 269.61111 | K15: 283 | L15: =+C15/D15 -> 2 | M15: =750000/4320 -> 173.61111
A16: 45580 | B16: 15 | C16: =+D16*2 -> 3200 | D16: 1600 | E16: =+C16/D16 -> 2 | F16: 2.8 | G16: =+C16*96 -> 307200 | H16: =+C16*M16 -> 555555.56 | I16: =+G16+H16 -> 862755.56 | J16: =+I16/C16 -> 269.61111 | K16: 283 | L16: =+C16/D16 -> 2 | M16: =750000/4320 -> 173.61111
A17: 45581 | B17: 16 | C17: 5830 | D17: 1440 | E17: =+C17/D17 -> 4.0486111 | F17: 2.8 | G17: =+C17*96 -> 559680 | H17: 750000 | I17: =+G17+H17 -> 1309680 | J17: =+I17/C17 -> 224.64494 | K17: 283
A18: 45582 | B18: 17 | C18: 4530 | D18: 1360 | E18: =+C18/D18 -> 3.3308824 | F18: 2.8 | G18: =+C18*96 -> 434880 | H18: 750000 | I18: =+G18+H18 -> 1184880 | J18: =+I18/C18 -> 261.56291 | K18: 283
A19: 45583 | B19: 18 | C19: 0 | D19: 0 | E19: =+C19/D19 -> #DIV/0! | F19: 2.8 | G19: =+C19*96 -> 0 | H19: =+$M$7*C18 -> 0 | I19: =+G19+H19 -> 0 | J19: =+I19/C19 -> #DIV/0! | K19: 283
A20: 45584 | B20: 19 | C20: =+L22*D20 -> 1449.2308 | D20: 320 | E20: =+C20/D20 -> 4.5288462 | F20: 2.8 | G20: =+C20*96 -> 139126.15 | H20: =+M20*C20 -> 230769.23 | I20: =+G20+H20 -> 369895.38 | J20: =+I20/C20 -> 255.23567 | K20: 283 | L20: =4710/1040 -> 4.5288462 | M20: =750000/4710 -> 159.23567
A21: 45585 | B21: 20 | C21: 0 | D21: 0 | E21: =+C21/D21 -> #DIV/0! | F21: 2.8 | G21: =+C21*96 -> 0 | H21: =+$M$7*C20 -> 0 | I21: =+G21+H21 -> 0 | J21: =+I21/C21 -> #DIV/0! | K21: 283
A22: 45586 | B22: 21 | C22: =+D22*L22 -> 3260.7692 | D22: 720 | E22: =+C22/D22 -> 4.5288462 | F22: 2.8 | G22: =+C22*96 -> 313033.85 | H22: =+M22*C22 -> 519230.77 | I22: =+G22+H22 -> 832264.62 | J22: =+I22/C22 -> 255.23567 | K22: 283 | L22: =4710/1040 -> 4.5288462 | M22: =750000/4710 -> 159.23567
A23: 45587 | B23: 22 | C23: =+D23*L23 -> 3215.3846 | D23: 1760 | E23: =+C23/D23 -> 1.8269231 | F23: 2.8 | G23: =+C23*96 -> 308676.92 | H23: =+C23*M23 -> 423076.92 | I23: =+G23+H23 -> 731753.85 | J23: =+I23/C23 -> 227.57895 | K23: 283 | L23: 1.8269231 | M23: =750000/5700 -> 131.57895
A24: 45588 | B24: 23 | C24: =+D24*L24 -> 2484.6154 | D24: 1360 | E24: =+C24/D24 -> 1.8269231 | F24: 2.8 | G24: =+C24*96 -> 238523.08 | H24: =+C24*M24 -> 326923.08 | I24: =+G24+H24 -> 565446.15 | J24: =+I24/C24 -> 227.57895 | K24: 283 | L24: 1.8269231 | M24: =750000/5700 -> 131.57895
A25: 45589 | B25: 24 | C25: 4410 | D25: 400 | E25: =+C25/D25 -> 11.025 | F25: 2.8 | G25: =+C25*96 -> 423360 | H25: 750000 | I25: =+G25+H25 -> 1173360 | J25: =+I25/C25 -> 266.06803 | K25: 283
A26: 45590 | B26: 25 | C26: =+D26*L26 -> 2234.2857 | D26: 1360 | E26: =+C26/D26 -> 1.6428571 | F26: 2.8 | G26: =+C26*96 -> 214491.43 | H26: =+C26*M26 -> 364285.71 | I26: =+G26+H26 -> 578777.14 | J26: =+I26/C26 -> 259.04348 | K26: 283 | L26: =4600/2800 -> 1.6428571 | M26: =750000/4600 -> 163.04348
A27: 45591 | B27: 26 | C27: =+D27*L27 -> 2365.7143 | D27: 1440 | E27: =+C27/D27 -> 1.6428571 | F27: 2.8 | G27: =+C27*96 -> 227108.57 | H27: =+C27*M27 -> 385714.29 | I27: =+G27+H27 -> 612822.86 | J27: =+I27/C27 -> 259.04348 | K27: 283 | L27: =4600/2800 -> 1.6428571 | M27: =750000/4600 -> 163.04348
A28: 45592 | B28: 27 | C28: =7360 -> 7360 | D28: 480 | E28: =+C28/D28 -> 15.333333 | F28: 2.8 | G28: =+C28*96 -> 706560 | H28: =+C28*M28 -> 667876.59 | I28: =+G28+H28 -> 1374436.6 | J28: =+I28/C28 -> 186.7441 | K28: 283 | L28: =16530/960 -> 17.21875 | M28: =(750000+750000)/(C28+C29) -> 90.744102
A29: 45592 | B29: 28 | C29: 9170 | D29: 480 | E29: =+C29/D29 -> 19.104167 | F29: 2.8 | G29: =+C29*96 -> 880320 | H29: =+C29*M29 -> 832123.41 | I29: =+G29+H29 -> 1712443.4 | J29: =+I29/C29 -> 186.7441 | K29: 283 | L29: =16530/960 -> 17.21875 | M29: =(750000+750000)/(C28+C29) -> 90.744102
A30: 45593 | B30: 29 | C30: =6180 -> 6180 | D30: 760 | E30: =+C30/D30 -> 8.1315789 | F30: 2.8 | G30: =+C30*96 -> 593280 | H30: =+C30*M30 -> 1155860.3 | I30: =+G30+H30 -> 1749140.3 | J30: =+I30/C30 -> 283.03242 | K30: 283 | L30: 5.2763158 | M30: =(750000+750000)/(C30+C31) -> 187.03242
A31: 45593 | B31: 30 | C31: 1840 | D31: 760 | E31: =+C31/D31 -> 2.4210526 | F31: 2.8 | G31: =+C31*96 -> 176640 | H31: =+C31*M31 -> 344139.65 | I31: =+G31+H31 -> 520779.65 | J31: =+I31/C31 -> 283.03242 | K31: 283 | L31: 5.2763158 | M31: =(750000+750000)/(C30+C31) -> 187.03242
A32: 45594 | B32: 31 | C32: 5310 | D32: 1600 | E32: =+C32/D32 -> 3.31875 | F32: 2.8 | G32: =+C32*96 -> 509760 | H32: 750000 | I32: =+G32+H32 -> 1259760 | J32: =+I32/C32 -> 237.24294 | K32: 283
A33: 45595 | B33: 32 | C33: 4490 | D33: 1520 | E33: =+C33/D33 -> 2.9539474 | F33: 2.8 | G33: =+C33*96 -> 431040 | H33: 750000 | I33: =+G33+H33 -> 1181040 | J33: =+I33/C33 -> 263.03786 | K33: 283
A34: 45596 | B34: 33 | D34: 1760 | E34: =+C34/D34 -> 0 | F34: 2.8 | J34: =+I34/C34 -> #DIV/0!
C35: =SUM(C2:C33) -> 110400 | D35: 36320 | E35: =+C35/D35 -> 3.0396476 | G35: =SUM(G2:G33) -> 10367833 | H35: =SUM(H2:H33) -> 16500000 | I35: =SUM(I2:I33) -> 26867833 | J35: =+I35/C35 -> 243.36805 | K35: 283
D39: ACUMULADO LODOS
D40: Caudal | E40: Gene kg/m3 | F40: costo /m3
D41: =+D35 -> 36320 | E41: =+E35 -> 3.0396476 | F41: =+J35 -> 243.36805

Sheet consolidado diario (5)
A1: FECHA | B1: N | C1: Kg | D1: GEM m3 | E1: kg/m3 | F1: factor Kg/m3 | G1: valor kg | H1: transporte | I1: $/dia | J1: $/kg | K1: factor $/kg | L1: ajuste de factor | M1: ajuste de transporte
A3: 45629 | B3: =DAY(A3) -> 3 | C3: 6850 | D3: 1360 | E3: =+C3/D3 -> 5.0367647 | F3: 2.8 | G3: =+C3*96 -> 657600 | H3: 750000 | I3: =+G3+H3 -> 1407600 | J3: =+I3/C3 -> 205.48905 | K3: 283
A4: 45630 | B4: =DAY(A4) -> 4 | C4: 4970 | D4: 783.61611 | E4: =+C4/D4 -> 6.3423913 | F4: 2.8 | G4: =+C4*96 -> 477120 | H4: 750000 | I4: =+G4+H4 -> 1227120 | J4: =+I4/C4 -> 246.90543 | K4: 283
A5: 45630 | B5: =DAY(A5) -> 4 | C5: 6700 | D5: 1056.3839 | E5: =+C5/D5 -> 6.3423913 | F5: 2.8 | G5: =+C5*96 -> 643200 | H5: 750000 | I5: =+G5+H5 -> 1393200 | J5: =+I5/C5 -> 207.9403 | K5: 283
A6: 45631 | B6: =DAY(A6) -> 5 | C6: 4430 | D6: 1920 | E6: =+C6/D6 -> 2.3072917 | F6: 2.8 | G6: =+C6*96 -> 425280 | H6: 750000 | I6: =+G6+H6 -> 1175280 | J6: =+I6/C6 -> 265.30023 | K6: 283
A7: 45632 | B7: =DAY(A7) -> 6 | C7: 4850 | D7: 1760 | E7: =+C7/D7 -> 2.7556818 | F7: 2.8 | G7: =+C7*96 -> 465600 | H7: 750000 | I7: =+G7+H7 -> 1215600 | J7: =+I7/C7 -> 250.63918 | K7: 283
A8: 45635 | B8: =DAY(A8) -> 9 | C8: 1910 | D8: 1200 | E8: =+C8/D8 -> 1.5916667 | F8: 2.8 | G8: =+C8*96 -> 183360 | H8: 750000 | I8: =+G8+H8 -> 933360 | J8: =+I8/C8 -> 488.67016 | K8: 283
A9: 45636 | B9: =DAY(A9) -> 10 | C9: 4930 | D9: 1840 | E9: =+C9/D9 -> 2.6793478 | F9: 2.8 | G9: =+C9*96 -> 473280 | H9: 750000 | I9: =+G9+H9 -> 1223280 | J9: =+I9/C9 -> 248.12982 | K9: 283
A10: 45637 | B10: =DAY(A10) -> 11 | C10: 4510 | D10: 1840 | E10: =+C10/D10 -> 2.451087 | F10: 2.8 | G10: =+C10*96 -> 432960 | H10: 750000 | I10: =+G10+H10 -> 1182960 | J10: =+I10/C10 -> 262.29712 | K10: 283

Sheet consolidado diario (3)
A1: FECHA | B1: N | C1: Kg | D1: GEM m3 | E1: kg/m3 | F1: factor Kg/m3 | G1: valor kg | H1: transporte | I1: $/dia | J1: $/kg | K1: factor $/kg | L1: ajuste de factor | M1: ajuste de transporte
A2: 45598 | B2: =DAY(A2) -> 2 | C2: 6710 | D2: 1760 | E2: =+C2/D2 -> 3.8125 | F2: 2.8 | G2: =+C2*96 -> 644160 | H2: 750000 | I2: =+G2+H2 -> 1394160 | J2: =+I2/C2 -> 207.77347 | K2: 283
A3: 45599 | B3: =DAY(A3) -> 3 | C3: 6490 | D3: 0 | E3: =+C3/D3 -> #DIV/0! | F3: 2.8 | G3: =+C3*96 -> 623040 | H3: 750000 | I3: =+G3+H3 -> 1373040 | J3: =+I3/C3 -> 211.5624 | K3: 283
A4: 45601 | B4: =DAY(A4) -> 5 | C4: 2710 | D4: 1600 | E4: =+C4/D4 -> 1.69375 | F4: 2.8 | G4: =+C4*96 -> 260160 | H4: 750000 | I4: =+G4+H4 -> 1010160 | J4: =+I4/C4 -> 372.75277 | K4: 283
A5: 45602 | B5: =DAY(A5) -> 6 | C5: 4340 | D5: 1760 | E5: =+C5/D5 -> 2.4659091 | F5: 2.8 | G5: =+C5*96 -> 416640 | H5: 750000 | I5: =+G5+H5 -> 1166640 | J5: =+I5/C5 -> 268.81106 | K5: 283
A6: 45603 | B6: =DAY(A6) -> 7 | C6: 4700 | D6: 1680 | E6: =+C6/D6 -> 2.797619 | F6: 2.8 | G6: =+C6*96 -> 451200 | H6: 750000 | I6: =+G6+H6 -> 1201200 | J6: =+I6/C6 -> 255.57447 | K6: 283
A7: 45604 | B7: =DAY(A7) -> 8 | C7: 5910 | D7: 1840 | E7: =+C7/D7 -> 3.2119565 | F7: 2.8 | G7: =+C7*96 -> 567360 | H7: 750000 | I7: =+G7+H7 -> 1317360 | J7: =+I7/C7 -> 222.90355 | K7: 283
A8: 45605 | B8: =DAY(A8) -> 9 | C8: 3790 | D8: 1760 | E8: =+C8/D8 -> 2.1534091 | F8: 2.8 | G8: =+C8*96 -> 363840 | H8: 750000 | I8: =+G8+H8 -> 1113840 | J8: =+I8/C8 -> 293.88918 | K8: 283
A9: 45606 | B9: =DAY(A9) -> 10 | C9: 4300 | D9: 480 | E9: =+C9/D9 -> 8.9583333 | F9: 2.8 | G9: =+C9*96 -> 412800 | H9: 750000 | I9: =+G9+H9 -> 1162800 | J9: =+I9/C9 -> 270.4186 | K9: 283
A10: 45607 | B10: =DAY(A10) -> 11 | C10: 3502 | D10: 960 | E10: =+C10/D10 -> 3.6479167 | F10: 2.8 | G10: =+C10*96 -> 336192 | H10: 428467 | I10: =+G10+H10 -> 764659 | J10: =+I10/C10 -> 218.34923 | K10: 283
A11: 45608 | B11: =DAY(A11) -> 12 | C11: 2628 | D11: 720 | E11: =+C11/D11 -> 3.65 | F11: 2.8 | G11: =+C11*96 -> 252288 | H11: =750000-H10 -> 321533 | I11: =+G11+H11 -> 573821 | J11: =+I11/C11 -> 218.34893 | K11: 283
A12: 45609 | B12: =DAY(A12) -> 13 | C12: 0 | D12: 560 | E12: =+C12/D12 -> 0 | F12: 2.8 | G12: =+C12*96 -> 0 | H12: =+$M$11*C12 -> 0 | I12: =+G12+H12 -> 0 | J12: =+I12/C12 -> #DIV/0! | K12: 283
A13: 45610 | B13: =DAY(A13) -> 14 | C13: 4780 | D13: 1280 | E13: =+C13/D13 -> 3.734375 | F13: 2.8 | G13: =+C13*96 -> 458880 | H13: 750000 | I13: =+G13+H13 -> 1208880 | J13: =+I13/C13 -> 252.90377 | K13: 283
A14: 45611 | B14: =DAY(A14) -> 15 | C14: 797 | D14: 400 | E14: =+C14/D14 -> 1.9925 | F14: 2.8 | G14: =+C14*96 -> 76512 | H14: 129383 | I14: =+G14+H14 -> 205895 | J14: =+I14/C14 -> 258.33752 | K14: 283
A15: 45612 | B15: =DAY(A15) -> 16 | C15: 3823 | D15: 1920 | E15: =+C15/D15 -> 1.9911458 | F15: 2.8 | G15: =+C15*96 -> 367008 | H15: 620617 | I15: =+G15+H15 -> 987625 | J15: =+I15/C15 -> 258.33769 | K15: 283
A16: 45613 | B16: =DAY(A16) -> 17 | C16: 1402 | D16: 640 | E16: =+C16/D16 -> 2.190625 | F16: 2.8 | G16: =+C16*96 -> 134592 | H16: 206988 | I16: =+G16+H16 -> 341580 | J16: =+I16/C16 -> 243.63766 | K16: 283
A17: 45614 | B17: =DAY(A17) -> 18 | C17: 3678 | D17: 1680 | E17: =+C17/D17 -> 2.1892857 | F17: 2.8 | G17: =+C17*96 -> 353088 | H17: 543011 | I17: =+G17+H17 -> 896099 | J17: =+I17/C17 -> 243.63757 | K17: 283
A18: 45615 | B18: =DAY(A18) -> 19 | C18: 2960 | D18: 1680 | E18: =+C18/D18 -> 1.7619048 | F18: 2.8 | G18: =+C18*96 -> 284160 | H18: 750000 | I18: =+G18+H18 -> 1034160 | J18: =+I18/C18 -> 349.37838 | K18: 283
A19: 45617 | B19: =DAY(A19) -> 21 | C19: 2810 | D19: 1840 | E19: =+C19/D19 -> 1.5271739 | F19: 2.8 | G19: =+C19*96 -> 269760 | H19: 750000 | I19: =+G19+H19 -> 1019760 | J19: =+I19/C19 -> 362.90391 | K19: 283
A20: 45618 | B20: =DAY(A20) -> 22 | C20: 1385 | D20: 1840 | E20: =+C20/D20 -> 0.75271739 | F20: 2.8 | G20: =+C20*96 -> 132960 | H20: 375000 | I20: =+G20+H20 -> 507960 | J20: =+I20/C20 -> 366.75812 | K20: 283
A21: 45619 | B21: =DAY(A21) -> 23 | C21: 1385 | D21: 1840 | E21: =+C21/D21 -> 0.75271739 | F21: 2.8 | G21: =+C21*96 -> 132960 | H21: 375000 | I21: =+G21+H21 -> 507960 | J21: =+I21/C21 -> 366.75812 | K21: 283
A22: 45620 | B22: =DAY(A22) -> 24 | C22: 1661.5789 | D22: 560 | E22: =+C22/D22 -> 2.9671053 | F22: 2.8 | G22: =+C22*96 -> 159511.58 | H22: 276315.79 | I22: =+G22+H22 -> 435827.37 | J22: =+I22/C22 -> 262.29712 | K22: 283
A23: 45621 | B23: =DAY(A23) -> 25 | C23: 2848.4211 | D23: 960 | E23: =+C23/D23 -> 2.9671053 | F23: 2.8 | G23: =+C23*96 -> 273448.42 | H23: 473684.21 | I23: =+G23+H23 -> 747132.63 | J23: =+I23/C23 -> 262.29712 | K23: 283
A24: 45622 | B24: =DAY(A24) -> 26 | C24: 1525 | D24: 1760 | E24: =+C24/D24 -> 0.86647727 | F24: 2.8 | G24: =+C24*96 -> 146400 | H24: 375000 | I24: =+G24+H24 -> 521400 | J24: =+I24/C24 -> 341.90164 | K24: 283
... A28: 45626 | B28: =DAY(A28) -> 30 | C28: 6410 | D28: 1760 | E28: =+C28/D28 -> 3.6420455 | F28: 2.8 | G28: =+C28*96 -> 615360 | H28: 750000 | I28: =+G28+H28 -> 1365360 | J28: =+I28/C28 -> 213.00468 | K28: 283

Sheet ENERO
A1: FECHA | B1: Día | C1: HOROMETRO INICIAL | D1: HOROMETRO FINAL | E1: HORAS DE OPERACIÓN | F1: Q TRATAMIENTO | G1: VOLUMEN TRATADO (m3) | H1: KG GENERADOS | I1: $ Kg | J1: $ TRANSPORTE | K1: $ / KG | L1: $ AMPLIRROL | M1: ($/KG) | N1: FACTOR ($/KG) | O1: FACTOR 2024 KG/M3 | P1: FACTOR GENERACIÓN KG/M3 | Q1: $/ M3 | R1: FACTOR $/m3 2024 | S1: VOL TRATADO DIA | T1: $/M3
A2: 2026-01-03 | B2: =DAY(A2) -> 3 | C2: 16494 | D2: 16511 | E2: =D2-C2 -> 17 | F2: 88 | G2: =E2*F2 -> 1496 | H2: 6100 | I2: 96 | J2: 600000 | K2: =H2*I2 -> 585600 | L2: =K2+J2 -> 1185600 | M2: =L2/H2 -> 194.36066 | N2: 267 | O2: 2.3 | P2: =H2/G2 -> 4.0775401 | Q2: =L2/G2 -> 792.51337 | R2: 629 | S2: 2000 | T2: =L2/S2 -> 592.8
A3: 2026-01-06 | B3: =DAY(A3) -> 6 | C3: =+D2 -> 16511 | D3: 16528 | E3: =D3-C3 -> 17 | F3: 88 | G3: =E3*F3 -> 1496 | H3: 5830 | I3: 96 | J3: 600000 | K3: =H3*I3 -> 559680 | L3: =K3+J3 -> 1159680 | M3: =L3/H3 -> 198.91595 | N3: 267 | O3: 2.3 | P3: =H3/G3 -> 3.8970588 | Q3: =L3/G3 -> 775.18717 | R3: 629 | S3: 2000 | T3: =L3/S3 -> 579.84
A4: 2026-01-08 | B4: =DAY(A4) -> 8 | C4: =+D3 -> 16528 | D4: 16550 | E4: =D4-C4 -> 22 | F4: 88 | G4: =E4*F4 -> 1936 | H4: 5630 | I4: 96 | J4: 600000 | K4: =H4*I4 -> 540480 | L4: =K4+J4 -> 1140480 | M4: =L4/H4 -> 202.57194 | N4: 267 | O4: =+O3 -> 2.3 | P4: =H4/G4 -> 2.9080579 | Q4: =L4/G4 -> 589.09091 | R4: 629 | S4: 2000 | T4: =L4/S4 -> 570.24
A5: 2026-01-12 | B5: =DAY(A5) -> 12 | C5: =+D4 -> 16550 | D5: 16579 | E5: =D5-C5 -> 29 | F5: 88 | G5: =E5*F5 -> 2552 | H5: 3730 | I5: 96 | J5: 600000 | K5: =H5*I5 -> 358080 | L5: =K5+J5 -> 958080 | M5: =L5/H5 -> 256.85791 | N5: 267 | O5: =+O4 -> 2.3 | P5: =H5/G5 -> 1.4615987 | Q5: =L5/G5 -> 375.4232 | R5: 629 | S5: 2000 | T5: =L5/S5 -> 479.04
A6: 2026-01-13 | B6: =DAY(A6) -> 13 | C6: =+D5 -> 16579 | D6: 16588 | E6: =D6-C6 -> 9 | F6: 88 | G6: =E6*F6 -> 792 | H6: 5320 | I6: 96 | J6: 600000 | K6: =H6*I6 -> 510720 | L6: =K6+J6 -> 1110720 | M6: =L6/H6 -> 208.78195 | N6: 267 | O6: =+O5 -> 2.3 | P6: =H6/G6 -> 6.7171717 | Q6: =L6/G6 -> 1402.4242 | R6: 629 | S6: 2001 | T6: =L6/S6 -> 555.08246
