Workbook
Name SegmentaciónDeDatos_DIA: #N/A
Name SegmentaciónDeDatos_DIA1: #N/A
Name SegmentaciónDeDatos_FECHA: #N/A

Sheet DASH BH
M1: Meses (FECHA) | N1: (Todas) | AS1: Meses (FECHA) | AT1: (Todas) | AY1: Meses (FECHA) | AZ1: (Todas)
M2: Días (FECHA) | N2: (Todas) | AS2: Días (FECHA) | AT2: (Todas) | AY2: Días (FECHA) | AZ2: (Todas)
M3: FECHA | N3: (Todas) | U3: FECHA | V3: INDICADOR DIA PRODUCCIÓN | W3: VOLUMEN REAL ENVIADO A PRODUCCIÓN | X3: Mín. de PROMEDIO MIN INDICADOR | AA3: FECHA | AB3: TOTAL KG TEÑIDOS MS | AC3: INDICADOR CONSUMO DIA (L/Kg) | AD3: Promedio de PROMEDIO MIN INDICADOR | AF3: DIA | AG3: VOLUMEN ENVIO MULAS RESIDUAL | AH3: VOLUMEN EXTRAIDO PTAP | AI3: Numero de Viajes | AN3: Etiquetas de fila | AO3: TOTAL KG PROCESADOS | AP3: TOTAL KG + ERBATECH | AQ3: KG ERBATECH
U4: 1 | V4: 0 | W4: 1 | X4: 23 | AA4: 1 | AB4: 0 | AC4: 0 | AD4: 23 | AF4: 1 | AG4: 0 | AH4: 0 | AI4: 0 | AN4: 1 | AO4: 0 | AQ4: 0 | AS4: DIA | AT4: VOLUMEN INGRESO RO | AU4: VOLUMEN PERMEADO RO | AV4: VOLUMEN RECHAZO RO | AW4: EFICIENCIA RO | AY4: DIA | AZ4: VOLUMEN INGRESO A PTAR | BA4: VOLUMEN INGRESO RO | BB4: VOLUMEN PERMEADO RO | BC4: VOLUMEN RECHAZO RO
M5: FECHA | N5: VOLUMEN REPORTE CONSUMIDO PRODUCCIÓN | O5: VOLUMEN DE PTAP ENVIADO A PLANTA DE PRODUCCIÓN | P5: VOLUMEN POTABLE CARROTANQUES | Q5: VOLUMEN PERMEADO RO | R5: VOLUMEN REAL ENVIADO A PRODUCCIÓN | U5: 2 | V5: 0 | W5: 3 | X5: 23 | AA5: 2 | AB5: 0 | AC5: 0 | AD5: 23 | AF5: 2 | AG5: 0 | AH5: 46 | AI5: 0 | AN5: 2 | AO5: 0 | AQ5: 0 | AS5: 1 | AT5: 0 | AU5: 0 | AV5: 0 | AW5: 0 | AY5: 1 | AZ5: 0 | BA5: 0 | BB5: 0 | BC5: 0
M6: 1 | N6: 0 | O6: 1 | P6: 0 | Q6: 0 | R6: 1 | U6: 3 | V6: 0 | W6: 1 | X6: 23 | AA6: 3 | AB6: 0 | AC6: 0 | AD6: 23 | AF6: 3 | AG6: 0 | AH6: 99 | AI6: 0 | AN6: 3 | AO6: 0 | AQ6: 0 | AS6: 2 | AT6: 0 | AU6: 0 | AV6: 0 | AW6: 0 | AY6: 2 | AZ6: 0 | BA6: 0 | BB6: 0 | BC6: 0
M7: 2 | N7: 0 | O7: 3 | P7: 0 | Q7: 0 | R7: 3 | U7: 4 | V7: 0 | W7: 0 | X7: 23 | AA7: 4 | AB7: 0 | AC7: 0 | AD7: 23 | AF7: 4 | AG7: 0 | AH7: 53 | AI7: 0 | AN7: 4 | AO7: 0 | AQ7: 0 | AS7: 3 | AT7: 0 | AU7: 0 | AV7: 0 | AW7: 0 | AY7: 3 | AZ7: 0 | BA7: 0 | BB7: 0 | BC7: 0
M8: 3 | N8: 0 | O8: 1 | P8: 0 | Q8: 0 | R8: 1 | U8: 5 | V8: 0 | W8: 2 | X8: 23 | AA8: 5 | AB8: 0 | AC8: 0 | AD8: 23 | AF8: 5 | AG8: 0 | AH8: 50 | AI8: 0 | AN8: 5 | AO8: 0 | AQ8: 0 | AS8: 4 | AT8: 0 | AU8: 0 | AV8: 0 | AW8: 0 | AY8: 4 | AZ8: 0 | BA8: 0 | BB8: 0 | BC8: 0
M9: 4 | N9: 0 | O9: 0 | P9: 0 | Q9: 0 | R9: 0 | U9: 6 | V9: 0 | W9: 2 | X9: 23 | AA9: 6 | AB9: 0 | AC9: 0 | AD9: 23 | AF9: 6 | AG9: 0 | AH9: 0 | AI9: 0 | AN9: 6 | AO9: 0 | AQ9: 0 | AS9: 5 | AT9: 0 | AU9: 0 | AV9: 0 | AW9: 0 | AY9: 5 | AZ9: 0 | BA9: 0 | BB9: 0 | BC9: 0
M10: 5 | N10: 0 | O10: 2 | P10: 0 | Q10: 0 | R10: 2 | U10: 7 | V10: 0 | W10: 1 | X10: 23 | AA10: 7 | AB10: 0 | AC10: 0 | AD10: 23 | AF10: 7 | AG10: 0 | AH10: 20 | AI10: 0 | AN10: 7 | AO10: 0 | AQ10: 0 | AS10: 6 | AT10: 0 | AU10: 0 | AV10: 0 | AW10: 0 | AY10: 6 | AZ10: 0 | BA10: 0 | BB10: 0 | BC10: 0
M11: 6 | N11: 0 | O11: 2 | P11: 0 | Q11: 0 | R11: 2 | U11: 8 | V11: 0 | W11: 0 | X11: 23 | AA11: 8 | AB11: 0 | AC11: 0 | AD11: 23 | AF11: 8 | AG11: 0 | AH11: 0 | AI11: 0 | AN11: 8 | AO11: 0 | AQ11: 0 | AS11: 7 | AT11: 0 | AU11: 0 | AV11: 0 | AW11: 0 | AY11: 7 | AZ11: 0 | BA11: 0 | BB11: 0 | BC11: 0
M12: 7 | N12: 0 | O12: 1 | P12: 0 | Q12: 0 | R12: 1 | U12: 9 | V12: 0 | W12: 0 | X12: 23 | AA12: 9 | AB12: 0 | AC12: 0 | AD12: 23 | AF12: 9 | AG12: 0 | AH12: 41 | AI12: 0 | AN12: 9 | AO12: 0 | AQ12: 0 | AS12: 8 | AT12: 0 | AU12: 0 | AV12: 0 | AW12: 0 | AY12: 8 | AZ12: 0 | BA12: 0 | BB12: 0 | BC12: 0
M13: 8 | N13: 0 | O13: 0 | P13: 0 | Q13: 0 | R13: 0 | U13: 10 | V13: 0 | W13: 1 | X13: 23 | AA13: 10 | AB13: 0 | AC13: 0 | AD13: 23 | AF13: 10 | AG13: 0 | AH13: 53 | AI13: 0 | AN13: 10 | AO13: 0 | AQ13: 0 | AS13: 9 | AT13: 0 | AU13: 0 | AV13: 0 | AW13: 0 | AY13: 9 | AZ13: 0 | BA13: 0 | BB13: 0 | BC13: 0
M14: 9 | N14: 0 | O14: 0 | P14: 0 | Q14: 0 | R14: 0 | U14: 11 | V14: 0 | W14: 1 | X14: 23 | AA14: 11 | AB14: 0 | AC14: 0 | AD14: 23 | AF14: 11 | AG14: 10 | AH14: 62 | AI14: 1 | AN14: 11 | AO14: 0 | AQ14: 0 | AS14: 10 | AT14: 0 | AU14: 0 | AV14: 0 | AW14: 0 | AY14: 10 | AZ14: 0 | BA14: 0 | BB14: 0 | BC14: 0
M15: 10 | N15: 0 | O15: 1 | P15: 0 | Q15: 0 | R15: 1 | U15: 12 | V15: 0 | W15: 4 | X15: 23 | AA15: 12 | AB15: 0 | AC15: 0 | AD15: 23 | AF15: 12 | AG15: 0 | AH15: 39 | AI15: 0 | AN15: 12 | AO15: 0 | AQ15: 0 | AS15: 11 | AT15: 0 | AU15: 0 | AV15: 0 | AW15: 0 | AY15: 11 | AZ15: 0 | BA15: 0 | BB15: 0 | BC15: 0
M16: 11 | N16: 0 | O16: 1 | P16: 0 | Q16: 0 | R16: 1 | U16: 13 | V16: 0 | W16: 1 | X16: 23 | AA16: 13 | AB16: 0 | AC16: 0 | AD16: 23 | AF16: 13 | AG16: 0 | AH16: 54 | AI16: 0 | AN16: 13 | AO16: 0 | AQ16: 0 | AS16: 12 | AT16: 0 | AU16: 0 | AV16: 0 | AW16: 0 | AY16: 12 | AZ16: 0 | BA16: 0 | BB16: 0 | BC16: 0
M17: 12 | N17: 0 | O17: 4 | P17: 0 | Q17: 0 | R17: 4 | U17: 14 | V17: 0 | W17: 1 | X17: 23 | AA17: 14 | AB17: 0 | AC17: 0 | AD17: 23 | AF17: 14 | AG17: 0 | AH17: 42 | AI17: 0 | AN17: 14 | AO17: 0 | AQ17: 0 | AS17: 13 | AT17: 0 | AU17: 0 | AV17: 0 | AW17: 0 | AY17: 13 | AZ17: 0 | BA17: 0 | BB17: 0 | BC17: 0
... M34: 29 | N34: 0 | O34: 0 | P34: 0 | Q34: 0 | R34: 0 | U34: 31 | V34: 0 | W34: 3 | X34: 23 | AA34: 31 | AB34: 0 | AC34: 0 | AD34: 23 | AF34: 31 | AG34: 0 | AH34: 42 | AI34: 0 | AN34: 31 | AO34: 0 | AQ34: 0 | AS34: 30 | AT34: 0 | AU34: 0 | AV34: 0 | AW34: 0 | AY34: 30 | AZ34: 0 | BA34: 0 | BB34: 0 | BC34: 0
M35: 30 | N35: 0 | O35: 1 | P35: 0 | Q35: 0 | R35: 1 | U35: Total general | V35: 244.18605 | W35: 42 | X35: 23 | AA35: Total general | AB35: 172 | AC35: 244.18605 | AD35: 23 | AF35: Total general | AG35: 30 | AH35: 1008 | AI35: 3 | AN35: Total general | AO35: 172 | AQ35: -172 | AS35: 31 | AT35: 0 | AU35: 0 | AV35: 0 | AW35: 0 | AY35: 31 | AZ35: 0 | BA35: 0 | BB35: 0 | BC35: 0
M36: 31 | N36: 0 | O36: 3 | P36: 0 | Q36: 0 | R36: 3 | AS36: Total general | AT36: 0 | AU36: 0 | AV36: 0 | AW36: 0 | AY36: Total general | AZ36: -33560 | BA36: 0 | BB36: 0 | BC36: 0
M37: Total general | N37: 0 | O37: 42 | P37: 0 | Q37: 0 | R37: 42
K54: CONSOLIDADO INDICADOR
K55: CONSUMO (m3) | L55: =+GETPIVOTDATA(" VOLUMEN REAL ENVIADO A PRODUCCIÓN ",$U$3) -> 42
K56: Kg TELA | L56: =+GETPIVOTDATA(" TOTAL KG TEÑIDOS MS",$AA$3) -> 172
K57: INDICADOR L/Kg | L57: =(L55*1000)/L56 -> 244.18605
K58: DIAS EFECTIVOS | L58: 13
K59: KG/DIA | L59: =L56/L58 -> 13.230769
K60: M3/DIA | L60: =+L55/L58 -> 3.2307692
K64: MES | L64: INDICADOR L/Kg
K65: ENERO | L65: 41.2
K66: FEBRERO | L66: 39.1
K67: MARZO | L67: 48
K68: PROYECCIÓN ABRIL | L68: =AVERAGE(L65:L67) -> 42.766667 | M68: 7416 | N68: =(M68*L68)/1000 -> 317.1576
K71: INDICADOR L/Kg
K72: REPORTADO SCLAVOS | L72: REPORTADO BELLINI | M72: REPORTADO GLOBAL | N72: REAL GLOBAL
K73: 21.46 | L73: 26.16 | M73: 21.69 | N73: =L57 -> 244.18605
K88: CONSOLIDADO KG REPORTADOS
K89: KG (SCLAVOS + BELLINI + ERBATECH) | L89: KG PROCESADOS | M89: KG DIFERENCIA | N89: % DE DIFERENCIA
K90: =GETPIVOTDATA(" TOTAL KG + ERBATECH",$AN$3) -> 0 | L90: =GETPIVOTDATA(" TOTAL KG PROCESADOS",$AN$3) -> 172 | M90: =+K90-L90 -> -172 | N90: =+M90/L90 -> -1
B104: ABASTECIMIENTO | H104: CONSOLIDADO TRATABILIDAD | O104: CONSOLIDADO AGUA RESIDUAL | R104: BALANCE RO
...

Sheet BALANCE
A1: FECHA | B1: DIA | C1: TURNO | D1: VOLUMEN EXTRAIDO PTAP | E1: VOLUMEN ENVIADO PTAP | F1: VOLUMEN PERDIDAS!! | G1: VOLUMEN ENVIO MULAS | H1: VOLUMEN CONSUMIDO PRODUCCIÓN | I1: VOLUMEN POTABLE CARROTANQUES | J1: VOLUMEN INGRESO RO | K1: VOLUMEN PERMEADO RO | L1: VOLUMEN RECHAZO RO | M1: EFICIENCIA RO | N1: VOLUMEN REAL ENVIADO A PRODUCCIÓN | O1: VOLUMEN INGRESO A PTAR | P1: VOL m3 SCLAVOS | Q1: VOL m3 BELLINIS | R1: VOL m3 ERBATECH | S1: TOTAL KG TEÑIDOS | T1: Kg teñidos SCLAVOS | U1: Kg teñidos BELLINI | V1: Kg teñidos ERBATECH | W1: TOTAL KG TEÑIDOS MS | X1: INDICADOR PRODUCCIÓN | Y1: Numero de Viajes | Z1: PROMEDIO MIN INDICADOR
A2: 45870 | B2: =DAY(A2) -> 1 | C2: 1 | D2: ='REGISTRO DE DATOS'!T3 -> 0 | E2: =+N2-K2-I2 -> 0 | F2: =+D2-E2 -> 0 | G2: ='REGISTRO DE DATOS'!R3 -> 0 | H2: =P2+Q2+R2 -> 0 | I2: ='REGISTRO DE DATOS'!O3 -> 0 | J2: ='REGISTRO DE DATOS'!G3 -> 0 | K2: ='REGISTRO DE DATOS'!I3 -> 0 | L2: =+J2-K2 -> 0 | M2: =IF(ISERROR(K2/J2),"%",(K2/J2)) -> % | N2: ='REGISTRO DE DATOS'!D3 -> 0 | O2: ='REGISTRO DE DATOS'!X3 -> 0 | W2: =+T2+U2 -> 0 | X2: 23 | Y2: ='REGISTRO DE DATOS'!P3 -> 0 | Z2: 23
A3: 45870 | B3: =DAY(A3) -> 1 | C3: 2 | D3: ='REGISTRO DE DATOS'!T4 -> 0 | E3: =+N3-K3-I3 -> 1 | F3: =+D3-E3 -> -1 | G3: ='REGISTRO DE DATOS'!R4 -> 0 | H3: =P3+Q3+R3 -> 0 | I3: ='REGISTRO DE DATOS'!O4 -> 0 | J3: ='REGISTRO DE DATOS'!G4 -> 0 | K3: ='REGISTRO DE DATOS'!I4 -> 0 | L3: =+J3-K3 -> 0 | M3: =IF(ISERROR(K3/J3),"%",(K3/J3)) -> % | N3: ='REGISTRO DE DATOS'!D4 -> 1 | O3: ='[1]REGISTRO DE DATOS'!W4 -> 0 | W3: =+T3+U3 -> 0 | X3: 23 | Y3: ='REGISTRO DE DATOS'!P4 -> 0 | Z3: 23
A4: 45870 | B4: =DAY(A4) -> 1 | C4: 3 | D4: ='REGISTRO DE DATOS'!T5 -> 0 | E4: =+N4-K4-I4 -> 0 | F4: =+D4-E4 -> 0 | G4: ='REGISTRO DE DATOS'!R5 -> 0 | H4: =P4+Q4+R4 -> 0 | I4: ='REGISTRO DE DATOS'!O5 -> 0 | J4: ='REGISTRO DE DATOS'!G5 -> 0 | K4: ='REGISTRO DE DATOS'!I5 -> 0 | L4: =+J4-K4 -> 0 | M4: =IF(ISERROR(K4/J4),"%",(K4/J4)) -> % | N4: ='REGISTRO DE DATOS'!D5 -> 0 | O4: ='[1]REGISTRO DE DATOS'!W5 -> 0 | W4: =+T4+U4 -> 0 | X4: 23 | Y4: ='REGISTRO DE DATOS'!P5 -> 0 | Z4: 23
A5: 45871 | B5: =DAY(A5) -> 2 | C5: 1 | D5: ='REGISTRO DE DATOS'!T6 -> 0 | E5: =+N5-K5-I5 -> 0 | F5: =+D5-E5 -> 0 | G5: ='REGISTRO DE DATOS'!R6 -> 0 | H5: =P5+Q5+R5 -> 0 | I5: ='REGISTRO DE DATOS'!O6 -> 0 | J5: ='REGISTRO DE DATOS'!G6 -> 0 | K5: ='REGISTRO DE DATOS'!I6 -> 0 | L5: =+J5-K5 -> 0 | M5: =IF(ISERROR(K5/J5),"%",(K5/J5)) -> % | N5: ='REGISTRO DE DATOS'!D6 -> 0 | O5: ='[1]REGISTRO DE DATOS'!W6 -> 0 | W5: =+T5+U5 -> 0 | X5: 23 | Y5: ='REGISTRO DE DATOS'!P6 -> 0 | Z5: 23
A6: 45871 | B6: =DAY(A6) -> 2 | C6: 2 | D6: ='REGISTRO DE DATOS'!T7 -> 46 | E6: =+N6-K6-I6 -> 2 | F6: =+D6-E6 -> 44 | G6: ='REGISTRO DE DATOS'!R7 -> 0 | H6: =P6+Q6+R6 -> 0 | I6: ='REGISTRO DE DATOS'!O7 -> 0 | J6: ='REGISTRO DE DATOS'!G7 -> 0 | K6: ='REGISTRO DE DATOS'!I7 -> 0 | L6: =+J6-K6 -> 0 | M6: =IF(ISERROR(K6/J6),"%",(K6/J6)) -> % | N6: ='REGISTRO DE DATOS'!D7 -> 2 | O6: ='[1]REGISTRO DE DATOS'!W7 -> 0 | W6: =+T6+U6 -> 0 | X6: 23 | Y6: ='REGISTRO DE DATOS'!P7 -> 0 | Z6: 23
A7: 45871 | B7: =DAY(A7) -> 2 | C7: 3 | D7: ='REGISTRO DE DATOS'!T8 -> 0 | E7: =+N7-K7-I7 -> 1 | F7: =+D7-E7 -> -1 | G7: ='REGISTRO DE DATOS'!R8 -> 0 | H7: =P7+Q7+R7 -> 0 | I7: ='REGISTRO DE DATOS'!O8 -> 0 | J7: ='REGISTRO DE DATOS'!G8 -> 0 | K7: ='REGISTRO DE DATOS'!I8 -> 0 | L7: =+J7-K7 -> 0 | M7: =IF(ISERROR(K7/J7),"%",(K7/J7)) -> % | N7: ='REGISTRO DE DATOS'!D8 -> 1 | O7: ='[1]REGISTRO DE DATOS'!W8 -> 0 | W7: =+T7+U7 -> 0 | X7: 23 | Y7: ='REGISTRO DE DATOS'!P8 -> 0 | Z7: 23
A8: 45872 | B8: =DAY(A8) -> 3 | C8: 1 | D8: ='REGISTRO DE DATOS'!T9 -> 0 | E8: =+N8-K8-I8 -> 0 | F8: =+D8-E8 -> 0 | G8: ='REGISTRO DE DATOS'!R9 -> 0 | H8: =P8+Q8+R8 -> 0 | I8: ='REGISTRO DE DATOS'!O9 -> 0 | J8: ='REGISTRO DE DATOS'!G9 -> 0 | K8: ='REGISTRO DE DATOS'!I9 -> 0 | L8: =+J8-K8 -> 0 | M8: =IF(ISERROR(K8/J8),"%",(K8/J8)) -> % | N8: ='REGISTRO DE DATOS'!D9 -> 0 | O8: ='[1]REGISTRO DE DATOS'!W9 -> 0 | W8: =+T8+U8 -> 0 | X8: 23 | Y8: ='REGISTRO DE DATOS'!P9 -> 0 | Z8: 23
A9: 45872 | B9: =DAY(A9) -> 3 | C9: 2 | D9: ='REGISTRO DE DATOS'!T10 -> 64 | E9: =+N9-K9-I9 -> 1 | F9: =+D9-E9 -> 63 | G9: ='REGISTRO DE DATOS'!R10 -> 0 | H9: =P9+Q9+R9 -> 0 | I9: ='REGISTRO DE DATOS'!O10 -> 0 | J9: ='REGISTRO DE DATOS'!G10 -> 0 | K9: ='REGISTRO DE DATOS'!I10 -> 0 | L9: =+J9-K9 -> 0 | M9: =IF(ISERROR(K9/J9),"%",(K9/J9)) -> % | N9: ='REGISTRO DE DATOS'!D10 -> 1 | O9: ='[1]REGISTRO DE DATOS'!W10 -> 0 | W9: =+T9+U9 -> 0 | X9: 23 | Y9: ='REGISTRO DE DATOS'!P10 -> 0 | Z9: 23
A10: 45872 | B10: =DAY(A10) -> 3 | C10: 3 | D10: ='REGISTRO DE DATOS'!T11 -> 35 | E10: =+N10-K10-I10 -> 0 | F10: =+D10-E10 -> 35 | G10: ='REGISTRO DE DATOS'!R11 -> 0 | H10: =P10+Q10+R10 -> 0 | I10: ='REGISTRO DE DATOS'!O11 -> 0 | J10: ='REGISTRO DE DATOS'!G11 -> 0 | K10: ='REGISTRO DE DATOS'!I11 -> 0 | L10: =+J10-K10 -> 0 | M10: =IF(ISERROR(K10/J10),"%",(K10/J10)) -> % | N10: ='REGISTRO DE DATOS'!D11 -> 0 | O10: ='[1]REGISTRO DE DATOS'!W11 -> 0 | W10: =+T10+U10 -> 0 | X10: 23 | Y10: ='REGISTRO DE DATOS'!P11 -> 0 | Z10: 23
A11: 45873 | B11: =DAY(A11) -> 4 | C11: 1 | D11: ='REGISTRO DE DATOS'!T12 -> 0 | E11: =+N11-K11-I11 -> 0 | F11: =+D11-E11 -> 0 | G11: ='REGISTRO DE DATOS'!R12 -> 0 | H11: =P11+Q11+R11 -> 0 | I11: ='REGISTRO DE DATOS'!O12 -> 0 | J11: ='REGISTRO DE DATOS'!G12 -> 0 | K11: ='REGISTRO DE DATOS'!I12 -> 0 | L11: =+J11-K11 -> 0 | M11: =IF(ISERROR(K11/J11),"%",(K11/J11)) -> % | N11: ='REGISTRO DE DATOS'!D12 -> 0 | O11: ='[1]REGISTRO DE DATOS'!W12 -> 0 | W11: =+T11+U11 -> 0 | X11: 23 | Y11: ='REGISTRO DE DATOS'!P12 -> 0 | Z11: 23
A12: 45873 | B12: =DAY(A12) -> 4 | C12: 2 | D12: ='REGISTRO DE DATOS'!T13 -> 29 | E12: =+N12-K12-I12 -> 0 | F12: =+D12-E12 -> 29 | G12: ='REGISTRO DE DATOS'!R13 -> 0 | H12: =P12+Q12+R12 -> 0 | I12: ='REGISTRO DE DATOS'!O13 -> 0 | J12: ='REGISTRO DE DATOS'!G13 -> 0 | K12: ='REGISTRO DE DATOS'!I13 -> 0 | L12: =+J12-K12 -> 0 | M12: =IF(ISERROR(K12/J12),"%",(K12/J12)) -> % | N12: ='REGISTRO DE DATOS'!D13 -> 0 | O12: ='[1]REGISTRO DE DATOS'!W13 -> 0 | W12: =+T12+U12 -> 0 | X12: 23 | Y12: ='REGISTRO DE DATOS'!P13 -> 0 | Z12: 23
A13: 45873 | B13: =DAY(A13) -> 4 | C13: 3 | D13: ='REGISTRO DE DATOS'!T14 -> 24 | E13: =+N13-K13-I13 -> 0 | F13: =+D13-E13 -> 24 | G13: ='REGISTRO DE DATOS'!R14 -> 0 | H13: =P13+Q13+R13 -> 0 | I13: ='REGISTRO DE DATOS'!O14 -> 0 | J13: ='REGISTRO DE DATOS'!G14 -> 0 | K13: ='REGISTRO DE DATOS'!I14 -> 0 | L13: =+J13-K13 -> 0 | M13: =IF(ISERROR(K13/J13),"%",(K13/J13)) -> % | N13: ='REGISTRO DE DATOS'!D14 -> 0 | O13: ='[1]REGISTRO DE DATOS'!W14 -> 0 | W13: =+T13+U13 -> 0 | X13: 23 | Y13: ='REGISTRO DE DATOS'!P14 -> 0 | Z13: 23
A14: 45874 | B14: =DAY(A14) -> 5 | C14: 1 | D14: ='REGISTRO DE DATOS'!T15 -> 0 | E14: =+N14-K14-I14 -> 0 | F14: =+D14-E14 -> 0 | G14: ='REGISTRO DE DATOS'!R15 -> 0 | H14: =P14+Q14+R14 -> 0 | I14: ='REGISTRO DE DATOS'!O15 -> 0 | J14: ='REGISTRO DE DATOS'!G15 -> 0 | K14: ='REGISTRO DE DATOS'!I15 -> 0 | L14: =+J14-K14 -> 0 | M14: =IF(ISERROR(K14/J14),"%",(K14/J14)) -> % | N14: ='REGISTRO DE DATOS'!D15 -> 0 | O14: ='[1]REGISTRO DE DATOS'!W15 -> 0 | W14: =+T14+U14 -> 0 | X14: 23 | Y14: ='REGISTRO DE DATOS'!P15 -> 0 | Z14: 23
... A41: 45883 | B41: =DAY(A41) -> 14 | C41: 1 | D41: ='REGISTRO DE DATOS'!T42 -> 0 | E41: =+N41-K41-I41 -> 0 | F41: =+D41-E41 -> 0 | G41: ='REGISTRO DE DATOS'!R42 -> 0 | H41: =P41+Q41+R41 -> 0 | I41: ='REGISTRO DE DATOS'!O42 -> 0 | J41: ='REGISTRO DE DATOS'!G42 -> 0 | K41: ='REGISTRO DE DATOS'!I42 -> 0 | L41: =+J41-K41 -> 0 | M41: =IF(ISERROR(K41/J41),"%",(K41/J41)) -> % | N41: ='REGISTRO DE DATOS'!D42 -> 0 | O41: ='[1]REGISTRO DE DATOS'!W42 -> 0 | W41: =+T41+U41 -> 0 | X41: 23 | Y41: ='REGISTRO DE DATOS'!P42 -> 0 | Z41: 23
A42: 45883 | B42: =DAY(A42) -> 14 | C42: 2 | D42: ='REGISTRO DE DATOS'!T43 -> 18 | E42: =+N42-K42-I42 -> 1 | F42: 0 | G42: ='REGISTRO DE DATOS'!R43 -> 0 | H42: =P42+Q42+R42 -> 0 | I42: ='REGISTRO DE DATOS'!O43 -> 0 | J42: ='REGISTRO DE DATOS'!G43 -> 0 | K42: ='REGISTRO DE DATOS'!I43 -> 0 | L42: =+J42-K42 -> 0 | M42: =IF(ISERROR(K42/J42),"%",(K42/J42)) -> % | N42: ='REGISTRO DE DATOS'!D43 -> 1 | O42: ='[1]REGISTRO DE DATOS'!W43 -> 0 | W42: =+T42+U42 -> 0 | X42: 23 | Y42: ='REGISTRO DE DATOS'!P43 -> 0 | Z42: 23
A43: 45883 | B43: =DAY(A43) -> 14 | C43: 3 | D43: ='REGISTRO DE DATOS'!T44 -> 24 | E43: =+N43-K43-I43 -> 0 | F43: =+D43-E43 -> 24 | G43: ='REGISTRO DE DATOS'!R44 -> 0 | H43: =P43+Q43+R43 -> 0 | I43: ='REGISTRO DE DATOS'!O44 -> 0 | J43: ='REGISTRO DE DATOS'!G44 -> 0 | K43: ='REGISTRO DE DATOS'!I44 -> 0 | L43: =+J43-K43 -> 0 | M43: =IF(ISERROR(K43/J43),"%",(K43/J43)) -> % | N43: ='REGISTRO DE DATOS'!D44 -> 0 | O43: ='[1]REGISTRO DE DATOS'!W44 -> 0 | W43: =+T43+U43 -> 0 | X43: 23 | Y43: ='REGISTRO DE DATOS'!P44 -> 0 | Z43: 23
A44: 45884 | B44: =DAY(A44) -> 15 | C44: 1 | D44: ='REGISTRO DE DATOS'!T45 -> 0 | E44: =+N44-K44-I44 -> 0 | F44: =+D44-E44 -> 0 | G44: ='REGISTRO DE DATOS'!R45 -> 0 | H44: =P44+Q44+R44 -> 0 | I44: ='REGISTRO DE DATOS'!O45 -> 0 | J44: ='REGISTRO DE DATOS'!G45 -> 0 | K44: ='REGISTRO DE DATOS'!I45 -> 0 | L44: =+J44-K44 -> 0 | M44: =IF(ISERROR(K44/J44),"%",(K44/J44)) -> % | N44: ='REGISTRO DE DATOS'!D45 -> 0 | O44: ='[1]REGISTRO DE DATOS'!W45 -> 0 | W44: =+T44+U44 -> 0 | X44: 23 | Y44: ='REGISTRO DE DATOS'!P45 -> 0 | Z44: 23
A45: 45884 | B45: =DAY(A45) -> 15 | C45: 2 | D45: ='REGISTRO DE DATOS'!T46 -> 0 | E45: =+N45-K45-I45 -> 0 | F45: =+D45-E45 -> 0 | G45: ='REGISTRO DE DATOS'!R46 -> 0 | H45: =P45+Q45+R45 -> 0 | I45: ='REGISTRO DE DATOS'!O46 -> 0 | J45: ='REGISTRO DE DATOS'!G46 -> 0 | K45: ='REGISTRO DE DATOS'!I46 -> 0 | L45: =+J45-K45 -> 0 | M45: =IF(ISERROR(K45/J45),"%",(K45/J45)) -> % | N45: ='REGISTRO DE DATOS'!D46 -> 0 | O45: ='[1]REGISTRO DE DATOS'!W46 -> 0 | W45: =+T45+U45 -> 0 | X45: 23 | Y45: ='REGISTRO DE DATOS'!P46 -> 0 | Z45: 23
A46: 45884 | B46: =DAY(A46) -> 15 | C46: 3 | D46: ='REGISTRO DE DATOS'!T47 -> 0 | E46: =+N46-K46-I46 -> 0 | F46: =+D46-E46 -> 0 | G46: ='REGISTRO DE DATOS'!R47 -> 0 | H46: =P46+Q46+R46 -> 0 | I46: ='REGISTRO DE DATOS'!O47 -> 0 | J46: ='REGISTRO DE DATOS'!G47 -> 0 | K46: ='REGISTRO DE DATOS'!I47 -> 0 | L46: =+J46-K46 -> 0 | M46: =IF(ISERROR(K46/J46),"%",(K46/J46)) -> % | N46: ='REGISTRO DE DATOS'!D47 -> 0 | O46: ='[1]REGISTRO DE DATOS'!W47 -> 0 | W46: =+T46+U46 -> 0 | X46: 23 | Y46: ='REGISTRO DE DATOS'!P47 -> 0 | Z46: 23
A47: 45885 | B47: =DAY(A47) -> 16 | C47: 1 | D47: ='REGISTRO DE DATOS'!T48 -> 0 | E47: =+N47-K47-I47 -> 0 | F47: =+D47-E47 -> 0 | G47: ='REGISTRO DE DATOS'!R48 -> 0 | H47: =P47+Q47+R47 -> 0 | I47: ='REGISTRO DE DATOS'!O48 -> 0 | J47: ='REGISTRO DE DATOS'!G48 -> 0 | K47: ='REGISTRO DE DATOS'!I48 -> 0 | L47: =+J47-K47 -> 0 | M47: =IF(ISERROR(K47/J47),"%",(K47/J47)) -> % | N47: ='REGISTRO DE DATOS'!D48 -> 0 | O47: ='[1]REGISTRO DE DATOS'!W48 -> 0 | W47: =+T47+U47 -> 0 | X47: 23 | Y47: ='REGISTRO DE DATOS'!P48 -> 0 | Z47: 23
A48: 45885 | B48: =DAY(A48) -> 16 | C48: 2 | D48: ='REGISTRO DE DATOS'!T49 -> 48 | E48: =+N48-K48-I48 -> 2 | F48: =+D48-E48 -> 46 | G48: ='REGISTRO DE DATOS'!R49 -> 0 | H48: =P48+Q48+R48 -> 0 | I48: ='REGISTRO DE DATOS'!O49 -> 0 | J48: ='REGISTRO DE DATOS'!G49 -> 0 | K48: ='REGISTRO DE DATOS'!I49 -> 0 | L48: =+J48-K48 -> 0 | M48: =IF(ISERROR(K48/J48),"%",(K48/J48)) -> % | N48: ='REGISTRO DE DATOS'!D49 -> 2 | O48: ='[1]REGISTRO DE DATOS'!W49 -> 0 | W48: =+T48+U48 -> 0 | X48: 23 | Y48: ='REGISTRO DE DATOS'!P49 -> 0 | Z48: 23
A49: 45885 | B49: =DAY(A49) -> 16 | C49: 3 | D49: ='REGISTRO DE DATOS'!T50 -> 0 | E49: =+N49-K49-I49 -> 0 | F49: =+D49-E49 -> 0 | G49: ='REGISTRO DE DATOS'!R50 -> 0 | H49: =P49+Q49+R49 -> 0 | I49: ='REGISTRO DE DATOS'!O50 -> 0 | J49: ='REGISTRO DE DATOS'!G50 -> 0 | K49: ='REGISTRO DE DATOS'!I50 -> 0 | L49: =+J49-K49 -> 0 | M49: =IF(ISERROR(K49/J49),"%",(K49/J49)) -> % | N49: ='REGISTRO DE DATOS'!D50 -> 0 | O49: ='[1]REGISTRO DE DATOS'!W50 -> 0 | W49: =+T49+U49 -> 0 | X49: 23 | Y49: ='REGISTRO DE DATOS'!P50 -> 0 | Z49: 23
A50: 45886 | B50: =DAY(A50) -> 17 | C50: 1 | D50: ='REGISTRO DE DATOS'!T51 -> 0 | E50: =+N50-K50-I50 -> 0 | F50: =+D50-E50 -> 0 | G50: ='REGISTRO DE DATOS'!R51 -> 0 | H50: =P50+Q50+R50 -> 0 | I50: ='REGISTRO DE DATOS'!O51 -> 0 | J50: ='REGISTRO DE DATOS'!G51 -> 0 | K50: ='REGISTRO DE DATOS'!I51 -> 0 | L50: =+J50-K50 -> 0 | M50: =IF(ISERROR(K50/J50),"%",(K50/J50)) -> % | N50: ='REGISTRO DE DATOS'!D51 -> 0 | O50: ='[1]REGISTRO DE DATOS'!W51 -> 0 | W50: =+T50+U50 -> 0 | X50: 23 | Y50: ='REGISTRO DE DATOS'!P51 -> 0 | Z50: 23
A51: 45886 | B51: =DAY(A51) -> 17 | C51: 2 | D51: ='REGISTRO DE DATOS'!T52 -> 16 | E51: =+N51-K51-I51 -> 1 | F51: =+D51-E51 -> 15 | G51: ='REGISTRO DE DATOS'!R52 -> 0 | H51: =P51+Q51+R51 -> 0 | I51: ='REGISTRO DE DATOS'!O52 -> 0 | J51: ='REGISTRO DE DATOS'!G52 -> 0 | K51: ='REGISTRO DE DATOS'!I52 -> 0 | L51: =+J51-K51 -> 0 | M51: =IF(ISERROR(K51/J51),"%",(K51/J51)) -> % | N51: ='REGISTRO DE DATOS'!D52 -> 1 | O51: ='[1]REGISTRO DE DATOS'!W52 -> 0 | W51: 20 | X51: 23 | Y51: ='REGISTRO DE DATOS'!P52 -> 0 | Z51: 23
A52: 45886 | B52: =DAY(A52) -> 17 | C52: 3 | D52: ='REGISTRO DE DATOS'!T53 -> 52 | E52: =+N52-K52-I52 -> 1 | F52: =+D52-E52 -> 51 | G52: ='REGISTRO DE DATOS'!R53 -> 0 | H52: =P52+Q52+R52 -> 0 | I52: ='REGISTRO DE DATOS'!O53 -> 0 | J52: ='REGISTRO DE DATOS'!G53 -> 0 | K52: ='REGISTRO DE DATOS'!I53 -> 0 | L52: =+J52-K52 -> 0 | M52: =IF(ISERROR(K52/J52),"%",(K52/J52)) -> % | N52: ='REGISTRO DE DATOS'!D53 -> 1 | O52: ='[1]REGISTRO DE DATOS'!W53 -> 0 | W52: =+T52+U52 -> 0 | X52: 23 | Y52: ='REGISTRO DE DATOS'!P53 -> 0 | Z52: 23
A53: 45887 | B53: =DAY(A53) -> 18 | C53: 1 | D53: ='REGISTRO DE DATOS'!T54 -> 0 | E53: =+N53-K53-I53 -> 0 | F53: =+D53-E53 -> 0 | G53: ='REGISTRO DE DATOS'!R54 -> 0 | H53: =P53+Q53+R53 -> 0 | I53: ='REGISTRO DE DATOS'!O54 -> 0 | J53: ='REGISTRO DE DATOS'!G54 -> 0 | K53: ='REGISTRO DE DATOS'!I54 -> 0 | L53: =+J53-K53 -> 0 | M53: =IF(ISERROR(K53/J53),"%",(K53/J53)) -> % | N53: ='REGISTRO DE DATOS'!D54 -> 0 | O53: ='[1]REGISTRO DE DATOS'!W54 -> 0 | W53: =+T53+U53 -> 0 | X53: 23 | Y53: ='REGISTRO DE DATOS'!P54 -> 0 | Z53: 23
A54: 45887 | B54: =DAY(A54) -> 18 | C54: 2 | D54: ='REGISTRO DE DATOS'!T55 -> 0 | E54: =+N54-K54-I54 -> 1 | F54: =+D54-E54 -> -1 | G54: ='REGISTRO DE DATOS'!R55 -> 0 | H54: =P54+Q54+R54 -> 0 | I54: ='REGISTRO DE DATOS'!O55 -> 0 | J54: ='REGISTRO DE DATOS'!G55 -> 0 | K54: ='REGISTRO DE DATOS'!I55 -> 0 | L54: =+J54-K54 -> 0 | M54: =IF(ISERROR(K54/J54),"%",(K54/J54)) -> % | N54: ='REGISTRO DE DATOS'!D55 -> 1 | O54: ='[1]REGISTRO DE DATOS'!W55 -> 0 | W54: =+T54+U54 -> 0 | X54: 23 | Y54: ='REGISTRO DE DATOS'!P55 -> 0 | Z54: 23
A55: 45887 | B55: =DAY(A55) -> 18 | C55: 3 | D55: ='REGISTRO DE DATOS'!T56 -> 54 | E55: =+N55-K55-I55 -> 1 | F55: =+D55-E55 -> 53 | G55: ='REGISTRO DE DATOS'!R56 -> 0 | H55: =P55+Q55+R55 -> 0 | I55: ='REGISTRO DE DATOS'!O56 -> 0 | J55: ='REGISTRO DE DATOS'!G56 -> 0 | K55: ='REGISTRO DE DATOS'!I56 -> 0 | L55: =+J55-K55 -> 0 | M55: =IF(ISERROR(K55/J55),"%",(K55/J55)) -> % | N55: ='REGISTRO DE DATOS'!D56 -> 1 | O55: ='[1]REGISTRO DE DATOS'!W56 -> 0 | W55: =+T55+U55 -> 0 | X55: 23 | Y55: ='REGISTRO DE DATOS'!P56 -> 0 | Z55: 23
A56: 45888 | B56: =DAY(A56) -> 19 | C56: 1 | D56: ='REGISTRO DE DATOS'!T57 -> 0 | E56: =+N56-K56-I56 -> 0 | F56: =+D56-E56 -> 0 | G56: ='REGISTRO DE DATOS'!R57 -> 0 | H56: =P56+Q56+R56 -> 0 | I56: ='REGISTRO DE DATOS'!O57 -> 0 | J56: ='REGISTRO DE DATOS'!G57 -> 0 | K56: ='REGISTRO DE DATOS'!I57 -> 0 | L56: =+J56-K56 -> 0 | M56: =IF(ISERROR(K56/J56),"%",(K56/J56)) -> % | N56: ='REGISTRO DE DATOS'!D57 -> 0 | O56: ='[1]REGISTRO DE DATOS'!W57 -> 0 | W56: =+T56+U56 -> 0 | X56: 23 | Y56: ='REGISTRO DE DATOS'!P57 -> 0 | Z56: 23
A57: 45888 | B57: =DAY(A57) -> 19 | C57: 2 | D57: ='REGISTRO DE DATOS'!T58 -> 0 | E57: =+N57-K57-I57 -> 2 | F57: =+D57-E57 -> -2 | G57: ='REGISTRO DE DATOS'!R58 -> 0 | H57: =P57+Q57+R57 -> 0 | I57: ='REGISTRO DE DATOS'!O58 -> 0 | J57: ='REGISTRO DE DATOS'!G58 -> 0 | K57: ='REGISTRO DE DATOS'!I58 -> 0 | L57: =+J57-K57 -> 0 | M57: =IF(ISERROR(K57/J57),"%",(K57/J57)) -> % | N57: ='REGISTRO DE DATOS'!D58 -> 2 | O57: ='[1]REGISTRO DE DATOS'!W58 -> 0 | W57: 18 | X57: 23 | Y57: ='REGISTRO DE DATOS'!P58 -> 0 | Z57: 23
A58: 45888 | B58: =DAY(A58) -> 19 | C58: 3 | D58: ='REGISTRO DE DATOS'!T59 -> 94 | E58: =+N58-K58-I58 -> 0 | F58: =+D58-E58 -> 94 | G58: ='REGISTRO DE DATOS'!R59 -> 0 | H58: =P58+Q58+R58 -> 0 | I58: ='REGISTRO DE DATOS'!O59 -> 0 | J58: ='REGISTRO DE DATOS'!G59 -> 0 | K58: ='REGISTRO DE DATOS'!I59 -> 0 | L58: =+J58-K58 -> 0 | M58: =IF(ISERROR(K58/J58),"%",(K58/J58)) -> % | N58: ='REGISTRO DE DATOS'!D59 -> 0 | O58: ='[1]REGISTRO DE DATOS'!W59 -> 0 | W58: =+T58+U58 -> 0 | X58: 23 | Y58: ='REGISTRO DE DATOS'!P59 -> 0 | Z58: 23
A59: 45889 | B59: =DAY(A59) -> 20 | C59: 1 | D59: ='REGISTRO DE DATOS'!T60 -> 0 | E59: =+N59-K59-I59 -> 0 | F59: =+D59-E59 -> 0 | G59: ='REGISTRO DE DATOS'!R60 -> 0 | H59: =P59+Q59+R59 -> 0 | I59: ='REGISTRO DE DATOS'!O60 -> 0 | J59: ='REGISTRO DE DATOS'!G60 -> 0 | K59: ='REGISTRO DE DATOS'!I60 -> 0 | L59: =+J59-K59 -> 0 | M59: =IF(ISERROR(K59/J59),"%",(K59/J59)) -> % | N59: ='REGISTRO DE DATOS'!D60 -> 0 | O59: ='[1]REGISTRO DE DATOS'!W60 -> -33560 | W59: =+T59+U59 -> 0 | X59: 23 | Y59: ='REGISTRO DE DATOS'!P60 -> 0 | Z59: 23
A60: 45889 | B60: =DAY(A60) -> 20 | C60: 2 | D60: ='REGISTRO DE DATOS'!T61 -> 43 | E60: =+N60-K60-I60 -> 2 | F60: =+D60-E60 -> 41 | G60: ='REGISTRO DE DATOS'!R61 -> 0 | H60: =P60+Q60+R60 -> 0 | I60: ='REGISTRO DE DATOS'!O61 -> 0 | J60: ='REGISTRO DE DATOS'!G61 -> 0 | K60: ='REGISTRO DE DATOS'!I61 -> 0 | L60: =+J60-K60 -> 0 | M60: =IF(ISERROR(K60/J60),"%",(K60/J60)) -> % | N60: ='REGISTRO DE DATOS'!D61 -> 2 | O60: ='[1]REGISTRO DE DATOS'!W61 -> 0 | W60: 36 | X60: 23 | Y60: ='REGISTRO DE DATOS'!P61 -> 0 | Z60: 23
A61: 45889 | B61: =DAY(A61) -> 20 | C61: 3 | D61: ='REGISTRO DE DATOS'!T62 -> 27 | E61: =+N61-K61-I61 -> 1 | F61: =+D61-E61 -> 26 | G61: ='REGISTRO DE DATOS'!R62 -> 0 | H61: =P61+Q61+R61 -> 0 | I61: ='REGISTRO DE DATOS'!O62 -> 0 | J61: ='REGISTRO DE DATOS'!G62 -> 0 | K61: ='REGISTRO DE DATOS'!I62 -> 0 | L61: =+J61-K61 -> 0 | M61: =IF(ISERROR(K61/J61),"%",(K61/J61)) -> % | N61: ='REGISTRO DE DATOS'!D62 -> 1 | O61: ='[1]REGISTRO DE DATOS'!W62 -> 0 | W61: =+T61+U61 -> 0 | X61: 23 | Y61: ='REGISTRO DE DATOS'!P62 -> 0 | Z61: 23
A62: 45890 | B62: =DAY(A62) -> 21 | C62: 1 | D62: ='REGISTRO DE DATOS'!T63 -> 0 | E62: =+N62-K62-I62 -> 0 | F62: =+D62-E62 -> 0 | G62: ='REGISTRO DE DATOS'!R63 -> 0 | H62: =P62+Q62+R62 -> 0 | I62: ='REGISTRO DE DATOS'!O63 -> 0 | J62: ='REGISTRO DE DATOS'!G63 -> 0 | K62: ='REGISTRO DE DATOS'!I63 -> 0 | L62: =+J62-K62 -> 0 | M62: =IF(ISERROR(K62/J62),"%",(K62/J62)) -> % | N62: ='REGISTRO DE DATOS'!D63 -> 0 | O62: ='[1]REGISTRO DE DATOS'!W63 -> 0 | W62: =+T62+U62 -> 0 | X62: 23 | Y62: ='REGISTRO DE DATOS'!P63 -> 0 | Z62: 23
A63: 45890 | B63: =DAY(A63) -> 21 | C63: 2 | D63: ='REGISTRO DE DATOS'!T64 -> 16 | E63: =+N63-K63-I63 -> 0 | F63: =+D63-E63 -> 16 | G63: ='REGISTRO DE DATOS'!R64 -> 0 | H63: =P63+Q63+R63 -> 0 | I63: ='REGISTRO DE DATOS'!O64 -> 0 | J63: ='REGISTRO DE DATOS'!G64 -> 0 | K63: ='REGISTRO DE DATOS'!I64 -> 0 | L63: =+J63-K63 -> 0 | M63: =IF(ISERROR(K63/J63),"%",(K63/J63)) -> % | N63: ='REGISTRO DE DATOS'!D64 -> 0 | O63: ='[1]REGISTRO DE DATOS'!W64 -> 0 | W63: 24 | X63: 23 | Y63: ='REGISTRO DE DATOS'!P64 -> 0 | Z63: 23
A64: 45890 | B64: =DAY(A64) -> 21 | C64: 3 | D64: ='REGISTRO DE DATOS'!T65 -> 4 | E64: =+N64-K64-I64 -> 1 | F64: =+D64-E64 -> 3 | G64: ='REGISTRO DE DATOS'!R65 -> 10 | H64: =P64+Q64+R64 -> 0 | I64: ='REGISTRO DE DATOS'!O65 -> 0 | J64: ='REGISTRO DE DATOS'!G65 -> 0 | K64: ='REGISTRO DE DATOS'!I65 -> 0 | L64: =+J64-K64 -> 0 | M64: =IF(ISERROR(K64/J64),"%",(K64/J64)) -> % | N64: ='REGISTRO DE DATOS'!D65 -> 1 | O64: ='[1]REGISTRO DE DATOS'!W65 -> 0 | W64: =+T64+U64 -> 0 | X64: 23 | Y64: ='REGISTRO DE DATOS'!P65 -> 1 | Z64: 23
A65: 45891 | B65: =DAY(A65) -> 22 | C65: 1 | D65: ='REGISTRO DE DATOS'!T66 -> 0 | E65: =+N65-K65-I65 -> 0 | F65: =+D65-E65 -> 0 | G65: ='REGISTRO DE DATOS'!R66 -> 0 | H65: =P65+Q65+R65 -> 0 | I65: ='REGISTRO DE DATOS'!O66 -> 0 | J65: ='REGISTRO DE DATOS'!G66 -> 0 | K65: ='REGISTRO DE DATOS'!I66 -> 0 | L65: =+J65-K65 -> 0 | M65: =IF(ISERROR(K65/J65),"%",(K65/J65)) -> % | N65: ='REGISTRO DE DATOS'!D66 -> 0 | O65: ='[1]REGISTRO DE DATOS'!W66 -> 0 | W65: =+T65+U65 -> 0 | X65: 23 | Y65: ='REGISTRO DE DATOS'!P66 -> 0 | Z65: 23
A66: 45891 | B66: =DAY(A66) -> 22 | C66: 2 | D66: ='REGISTRO DE DATOS'!T67 -> 0 | E66: =+N66-K66-I66 -> 0 | F66: =+D66-E66 -> 0 | G66: ='REGISTRO DE DATOS'!R67 -> 0 | H66: =P66+Q66+R66 -> 0 | I66: ='REGISTRO DE DATOS'!O67 -> 0 | J66: ='REGISTRO DE DATOS'!G67 -> 0 | K66: ='REGISTRO DE DATOS'!I67 -> 0 | L66: =+J66-K66 -> 0 | M66: =IF(ISERROR(K66/J66),"%",(K66/J66)) -> % | N66: ='REGISTRO DE DATOS'!D67 -> 0 | O66: ='[1]REGISTRO DE DATOS'!W67 -> 0 | W66: =+T66+U66 -> 0 | X66: 23 | Y66: ='REGISTRO DE DATOS'!P67 -> 0 | Z66: 23
...

Sheet REGISTRO DE DATOS
C1: ENVIADO A PRODUCCIÓN | E1: INGRESO DE DATOS RO | K1: CARROTANQUES POTABLE | P1: MULAS RESIDUAL | S1: PTAP
A2: FECHA | B2: TURNO | C2: CONTADOR ENVIO A PRODUCCIÓN | D2: VOLUMEN ENVIADO A PRODUCCIÓN (m3) | E2: ROTAMETRO INGRESO RO (M3/H) | F2: TIEMPO DE TRABAJO (HORAS) | G2: VOLUMEN INGRESO A RO (M3) | H2: ROTAMETRO PERMEADO RO (M3/H) | I2: VOLUMEN PERMEO RO (M3) | J2: VOLUMEN RECHAZO RO (M3) | K2: CONTADOR CARROTANQUES FINAL DE TURNO | L2: VOLUMEN INGRESO CARROTANQUES (m3) | M2: VOLUMEN (40M3) | N2: NUMERO DE VIAJES (40M3) | O2: VOLUMEN INGRESO CARROTANQUES | P2: NUMERO DE MULAS 40 M3 | Q2: VOLUMEN REMISIÓN | R2: VOLUMEN SEGÚN TIPO DE VEHICULO | S2: CONTADOR (VOLUMEN EXTRAIDO POZO) | T2: VOLUMEN EXTRAIDO POZO | U2: ENVIO PILOTEADORA | V2: TRATADO | W2: CONTADOR ENTRADA PTAR | X2: CONTADOR ENTRADA PTAR | Y2: CONTADOR SALIDA PTAR | Z2: CONTADOR SALIDA PTAR | AA2: AGUA TRATADA | AB2: PERDIDAS TRATAMIENTO | AC2: OBSERVACIONES
A3: 46082 | B3: =DAY(A3) -> 1 | C3: 351712 | D3: 0 | E3: 0 | F3: 0 | G3: =+F3*E3 -> 0 | H3: 0 | I3: =+H3*F3 -> 0 | J3: =+G3-I3 -> 0 | K3: 888 | L3: 0 | M3: 40 | N3: 0 | O3: =+K3*J3 -> 0 | P3: 0 | Q3: 10 | R3: =(P3*Q3) -> 0 | S3: 93304 | T3: 0 | U3: 0 | V3: =T3-U3 -> 0 | X3: 0 | Z3: 0 | AA3: =X3-AB3 -> 0 | AB3: =X3-Z3 -> 0
A4: =A3 -> 46082 | B4: 2 | C4: 351713 | D4: =C4-C3 -> 1 | E4: 0 | F4: 0 | G4: =+F4*E4 -> 0 | H4: 0 | I4: =+H4*F4 -> 0 | J4: =+G4-I4 -> 0 | K4: 888 | L4: =+K4-K3 -> 0 | M4: 40 | N4: 0 | O4: =+K4*J4 -> 0 | P4: 0 | Q4: 10 | R4: =(P4*Q4) -> 0 | S4: 93304 | T4: =+S4-S3 -> 0 | U4: 0 | V4: =T4-U4 -> 0 | X4: =+W4-W3 -> 0 | Z4: =+Y4-Y3 -> 0 | AA4: =X4-AB4 -> 0 | AB4: =X4-Z4 -> 0
A5: =A4 -> 46082 | B5: 3 | C5: 351713 | D5: =C5-C4 -> 0 | E5: 0 | F5: 0 | G5: =+F5*E5 -> 0 | H5: 0 | I5: =+H5*F5 -> 0 | J5: =+G5-I5 -> 0 | K5: 888 | L5: =+K5-K4 -> 0 | M5: 40 | N5: 0 | O5: =+K5*J5 -> 0 | P5: 0 | Q5: 10 | R5: =(P5*Q5) -> 0 | S5: 93304 | T5: =+S5-S4 -> 0 | U5: 0 | V5: =T5-U5 -> 0 | X5: =+W5-W4 -> 0 | Z5: =+Y5-Y4 -> 0 | AA5: =X5-AB5 -> 0 | AB5: =X5-Z5 -> 0
A6: =A5+1 -> 46083 | B6: 1 | C6: 351713 | D6: =+C6-C5 -> 0 | E6: 0 | F6: 0 | G6: =+F6*E6 -> 0 | H6: 0 | I6: =+H6*F6 -> 0 | J6: =+G6-I6 -> 0 | K6: 888 | L6: =+K6-K5 -> 0 | M6: 40 | N6: 0 | O6: =+K6*J6 -> 0 | P6: 0 | Q6: 10 | R6: =(P6*Q6) -> 0 | S6: 93304 | T6: =+S6-S5 -> 0 | U6: 0 | V6: =T6-U6 -> 0 | X6: =+W6-W5 -> 0 | Z6: =+Y6-Y5 -> 0 | AA6: =X6-AB6 -> 0 | AB6: =X6-Z6 -> 0
A7: =A6 -> 46083 | B7: 2 | C7: 351715 | D7: =+C7-C6 -> 2 | E7: 0 | F7: 0 | G7: =+F7*E7 -> 0 | H7: 0 | I7: =+H7*F7 -> 0 | J7: =+G7-I7 -> 0 | K7: 888 | L7: =+K7-K6 -> 0 | M7: 40 | N7: =+K7/M7 -> 22.2 | O7: =+K7*J7 -> 0 | P7: 0 | Q7: 10 | R7: =(P7*Q7) -> 0 | S7: 93350 | T7: =+S7-S6 -> 46 | U7: 46 | V7: =T7-U7 -> 0 | X7: =+W7-W6 -> 0 | Z7: =+Y7-Y6 -> 0 | AA7: =X7-AB7 -> 0 | AB7: =X7-Z7 -> 0
A8: =A7 -> 46083 | B8: 3 | C8: 351716 | D8: =+C8-C7 -> 1 | E8: 0 | F8: 0 | G8: =+F8*E8 -> 0 | H8: 0 | I8: =+H8*F8 -> 0 | J8: =+G8-I8 -> 0 | K8: 888 | L8: =+K8-K7 -> 0 | M8: 40 | N8: =+K8/M8 -> 22.2 | O8: =+K8*J8 -> 0 | P8: 0 | Q8: 10 | R8: =(P8*Q8) -> 0 | S8: 93350 | T8: =+S8-S7 -> 0 | U8: 0 | V8: =T8-U8 -> 0 | X8: =+W8-W7 -> 0 | Z8: =+Y8-Y7 -> 0 | AA8: =X8-AB8 -> 0 | AB8: =X8-Z8 -> 0
A9: =A8+1 -> 46084 | B9: 1 | C9: 351716 | D9: =+C9-C8 -> 0 | E9: 0 | F9: 0 | G9: =+F9*E9 -> 0 | H9: 0 | I9: =+H9*F9 -> 0 | J9: =+G9-I9 -> 0 | K9: 888 | L9: =+K9-K8 -> 0 | M9: 40 | N9: =+K9/M9 -> 22.2 | O9: =+K9*J9 -> 0 | P9: 0 | Q9: 10 | R9: =(P9*Q9) -> 0 | S9: 93350 | T9: =+S9-S8 -> 0 | U9: 0 | V9: =T9-U9 -> 0 | X9: =+W9-W8 -> 0 | Z9: =+Y9-Y8 -> 0 | AA9: =X9-AB9 -> 0 | AB9: =X9-Z9 -> 0
A10: =A9 -> 46084 | B10: 2 | C10: 351717 | D10: =+C10-C9 -> 1 | E10: 0 | F10: 0 | G10: =+F10*E10 -> 0 | H10: 0 | I10: =+H10*F10 -> 0 | J10: =+G10-I10 -> 0 | K10: 888 | L10: =+K10-K9 -> 0 | M10: 40 | N10: =+K10/M10 -> 22.2 | O10: =+K10*J10 -> 0 | P10: 0 | Q10: 10 | R10: =(P10*Q10) -> 0 | S10: 93414 | T10: =+S10-S9 -> 64 | U10: 64 | V10: =T10-U10 -> 0 | X10: =+W10-W9 -> 0 | Z10: =+Y10-Y9 -> 0 | AA10: =X10-AB10 -> 0 | AB10: =X10-Z10 -> 0
A11: =A10 -> 46084 | B11: 3 | C11: 351717 | D11: =+C11-C10 -> 0 | E11: 0 | F11: 0 | G11: =+F11*E11 -> 0 | H11: 0 | I11: =+H11*F11 -> 0 | J11: =+G11-I11 -> 0 | K11: 888 | L11: =+K11-K10 -> 0 | M11: 40 | N11: =+K11/M11 -> 22.2 | O11: =+K11*J11 -> 0 | P11: 0 | Q11: 10 | R11: =(P11*Q11) -> 0 | S11: 93449 | T11: =+S11-S10 -> 35 | U11: 18 | V11: =T11-U11 -> 17 | X11: =+W11-W10 -> 0 | Z11: =+Y11-Y10 -> 0 | AA11: =X11-AB11 -> 0 | AB11: =X11-Z11 -> 0
A12: =A11+1 -> 46085 | B12: 1 | C12: 351717 | D12: =+C12-C11 -> 0 | E12: 0 | F12: 0 | G12: =+F12*E12 -> 0 | H12: 0 | I12: =+H12*F12 -> 0 | J12: =+G12-I12 -> 0 | K12: 888 | L12: =+K12-K11 -> 0 | M12: 40 | N12: =+K12/M12 -> 22.2 | O12: =+K12*J12 -> 0 | P12: 0 | Q12: 10 | R12: =(P12*Q12) -> 0 | S12: 93449 | T12: =+S12-S11 -> 0 | U12: 0 | V12: =T12-U12 -> 0 | X12: =+W12-W11 -> 0 | Z12: =+Y12-Y11 -> 0 | AA12: =X12-AB12 -> 0 | AB12: =X12-Z12 -> 0
A13: =A12 -> 46085 | B13: 2 | C13: 351717 | D13: =+C13-C12 -> 0 | E13: 0 | F13: 0 | G13: =+F13*E13 -> 0 | H13: 0 | I13: =+H13*F13 -> 0 | J13: =+G13-I13 -> 0 | K13: 888 | L13: =+K13-K12 -> 0 | M13: 40 | N13: =+K13/M13 -> 22.2 | O13: =+K13*J13 -> 0 | P13: 0 | Q13: 10 | R13: =(P13*Q13) -> 0 | S13: 93478 | T13: =+S13-S12 -> 29 | U13: 29 | V13: =T13-U13 -> 0 | X13: =+W13-W12 -> 0 | Z13: =+Y13-Y12 -> 0 | AA13: =X13-AB13 -> 0 | AB13: =X13-Z13 -> 0
A14: =A13 -> 46085 | B14: 3 | C14: 351717 | D14: =+C14-C13 -> 0 | E14: 0 | F14: 0 | G14: =+F14*E14 -> 0 | H14: 0 | I14: =+H14*F14 -> 0 | J14: =+G14-I14 -> 0 | K14: 888 | L14: =+K14-K13 -> 0 | M14: 40 | N14: 0 | O14: =+K14*J14 -> 0 | P14: 0 | Q14: 10 | R14: =(P14*Q14) -> 0 | S14: 93502 | T14: =+S14-S13 -> 24 | U14: 24 | V14: =T14-U14 -> 0 | X14: =+W14-W13 -> 0 | Z14: =+Y14-Y13 -> 0 | AA14: =X14-AB14 -> 0 | AB14: =X14-Z14 -> 0
A15: =A14+1 -> 46086 | B15: 1 | C15: 351717 | D15: =+C15-C14 -> 0 | E15: 0 | F15: 0 | G15: =+F15*E15 -> 0 | H15: 0 | I15: =+H15*F15 -> 0 | J15: =+G15-I15 -> 0 | K15: 888 | L15: =+K15-K14 -> 0 | M15: 40 | N15: =+K15/M15 -> 22.2 | O15: =+K15*J15 -> 0 | P15: 0 | Q15: 10 | R15: =(P15*Q15) -> 0 | S15: 93502 | T15: =+S15-S14 -> 0 | U15: 0 | V15: =T15-U15 -> 0 | X15: =+W15-W14 -> 0 | Z15: =+Y15-Y14 -> 0 | AA15: =X15-AB15 -> 0 | AB15: =X15-Z15 -> 0
A16: =A15 -> 46086 | B16: 2 | C16: 351717 | D16: =+C16-C15 -> 0 | E16: 0 | F16: 0 | G16: =+F16*E16 -> 0 | H16: 0 | I16: =+H16*F16 -> 0 | J16: =+G16-I16 -> 0 | K16: 888 | L16: =+K16-K15 -> 0 | M16: 40 | N16: =+K16/M16 -> 22.2 | O16: =+K16*J16 -> 0 | P16: 0 | Q16: 10 | R16: =(P16*Q16) -> 0 | S16: 93524 | T16: =+S16-S15 -> 22 | U16: 22 | V16: =T16-U16 -> 0 | X16: =+W16-W15 -> 0 | Z16: =+Y16-Y15 -> 0 | AA16: =X16-AB16 -> 0 | AB16: =X16-Z16 -> 0
A17: =A16 -> 46086 | B17: 3 | C17: 351719 | D17: =+C17-C16 -> 2 | E17: 0 | F17: 0 | G17: =+F17*E17 -> 0 | H17: 0 | I17: =+H17*F17 -> 0 | J17: =+G17-I17 -> 0 | K17: 888 | L17: =+K17-K16 -> 0 | M17: 40 | N17: =+K17/M17 -> 22.2 | O17: =+K17*J17 -> 0 | P17: 0 | Q17: 10 | R17: =(P17*Q17) -> 0 | S17: 93552 | T17: =+S17-S16 -> 28 | U17: 28 | V17: =T17-U17 -> 0 | X17: =+W17-W16 -> 0 | Z17: =+Y17-Y16 -> 0 | AA17: =X17-AB17 -> 0 | AB17: =X17-Z17 -> 0
A18: =A17+1 -> 46087 | B18: 1 | C18: 351719 | D18: =+C18-C17 -> 0 | E18: 0 | F18: 0 | G18: =+F18*E18 -> 0 | H18: 0 | I18: =+H18*F18 -> 0 | J18: =+G18-I18 -> 0 | K18: 888 | L18: =+K18-K17 -> 0 | M18: 40 | N18: =+K18/M18 -> 22.2 | O18: =+K18*J18 -> 0 | P18: 0 | Q18: 10 | R18: =(P18*Q18) -> 0 | S18: 93552 | T18: =+S18-S17 -> 0 | U18: 0 | V18: =T18-U18 -> 0 | X18: =+W18-W17 -> 0 | Z18: =+Y18-Y17 -> 0 | AA18: =X18-AB18 -> 0 | AB18: =X18-Z18 -> 0
A19: =A18 -> 46087 | B19: 2 | C19: 351721 | D19: =+C19-C18 -> 2 | E19: 0 | F19: 0 | G19: =+F19*E19 -> 0 | H19: 0 | I19: =+H19*F19 -> 0 | J19: =+G19-I19 -> 0 | K19: 888 | L19: =+K19-K18 -> 0 | M19: 40 | N19: =+K19/M19 -> 22.2 | O19: =+K19*J19 -> 0 | P19: 0 | Q19: 10 | R19: =(P19*Q19) -> 0 | S19: 93552 | T19: =+S19-S18 -> 0 | U19: 0 | V19: =T19-U19 -> 0 | X19: =+W19-W18 -> 0 | Z19: =+Y19-Y18 -> 0 | AA19: =X19-AB19 -> 0 | AB19: =X19-Z19 -> 0
A20: =A19 -> 46087 | B20: 3 | C20: 351721 | D20: =+C20-C19 -> 0 | E20: 0 | F20: 0 | G20: =+F20*E20 -> 0 | H20: 0 | I20: =+H20*F20 -> 0 | J20: =+G20-I20 -> 0 | K20: 888 | L20: =+K20-K19 -> 0 | M20: 40 | N20: =+K20/M20 -> 22.2 | O20: =+K20*J20 -> 0 | P20: 0 | Q20: 10 | R20: =(P20*Q20) -> 0 | S20: 93552 | T20: =+S20-S19 -> 0 | U20: 0 | V20: =T20-U20 -> 0 | X20: =+W20-W19 -> 0 | Z20: =+Y20-Y19 -> 0 | AA20: =X20-AB20 -> 0 | AB20: =X20-Z20 -> 0
A21: =A20+1 -> 46088 | B21: 1 | C21: 351721 | D21: =+C21-C20 -> 0 | E21: 0 | F21: 0 | G21: =+F21*E21 -> 0 | H21: 0 | I21: =+H21*F21 -> 0 | J21: =+G21-I21 -> 0 | K21: 888 | L21: =+K21-K20 -> 0 | M21: 40 | N21: =+K21/M21 -> 22.2 | O21: =+K21*J21 -> 0 | P21: 0 | Q21: 10 | R21: =(P21*Q21) -> 0 | S21: 93552 | T21: =+S21-S20 -> 0 | U21: 0 | V21: =T21-U21 -> 0 | X21: =+W21-W20 -> 0 | Z21: =+Y21-Y20 -> 0 | AA21: =X21-AB21 -> 0 | AB21: =X21-Z21 -> 0
A22: =A21 -> 46088 | B22: 2 | C22: 351722 | D22: =+C22-C21 -> 1 | E22: 0 | F22: 0 | G22: =+F22*E22 -> 0 | H22: 0 | I22: =+H22*F22 -> 0 | J22: =+G22-I22 -> 0 | K22: 888 | L22: =+K22-K21 -> 0 | M22: 40 | N22: =+K22/M22 -> 22.2 | O22: =+K22*J22 -> 0 | P22: 0 | Q22: 10 | R22: =(P22*Q22) -> 0 | S22: 93552 | T22: =+S22-S21 -> 0 | U22: 0 | V22: =T22-U22 -> 0 | X22: =+W22-W21 -> 0 | Z22: =+Y22-Y21 -> 0 | AA22: =X22-AB22 -> 0 | AB22: =X22-Z22 -> 0
A23: =A22 -> 46088 | B23: 3 | C23: 351722 | D23: =+C23-C22 -> 0 | E23: 0 | F23: 0 | G23: =+F23*E23 -> 0 | H23: 0 | I23: =+H23*F23 -> 0 | J23: =+G23-I23 -> 0 | K23: 888 | L23: =+K23-K22 -> 0 | M23: 40 | N23: =+K23/M23 -> 22.2 | O23: =+K23*J23 -> 0 | P23: 0 | Q23: 10 | R23: =(P23*Q23) -> 0 | S23: 93572 | T23: =+S23-S22 -> 20 | U23: 20 | V23: =T23-U23 -> 0 | X23: =+W23-W22 -> 0 | Z23: =+Y23-Y22 -> 0 | AA23: =X23-AB23 -> 0 | AB23: =X23-Z23 -> 0
A24: =A23+1 -> 46089 | B24: 1 | C24: 351722 | D24: =+C24-C23 -> 0 | E24: 0 | F24: 0 | G24: =+F24*E24 -> 0 | H24: 0 | I24: =+H24*F24 -> 0 | J24: =+G24-I24 -> 0 | K24: 888 | L24: =+K24-K23 -> 0 | M24: 40 | N24: =+K24/M24 -> 22.2 | O24: =+K24*J24 -> 0 | P24: 0 | Q24: 10 | R24: =(P24*Q24) -> 0 | S24: 93572 | T24: =+S24-S23 -> 0 | U24: 0 | V24: =T24-U24 -> 0 | X24: =+W24-W23 -> 0 | Z24: =+Y24-Y23 -> 0 | AA24: =X24-AB24 -> 0 | AB24: =X24-Z24 -> 0
A25: =A24 -> 46089 | B25: 2 | C25: 351722 | D25: =+C25-C24 -> 0 | E25: 0 | F25: 0 | G25: =+F25*E25 -> 0 | H25: 0 | I25: =+H25*F25 -> 0 | J25: =+G25-I25 -> 0 | K25: 888 | L25: =+K25-K24 -> 0 | M25: 40 | N25: =+K25/M25 -> 22.2 | O25: =+K25*J25 -> 0 | P25: 0 | Q25: 10 | R25: =(P25*Q25) -> 0 | S25: 93572 | T25: =+S25-S24 -> 0 | U25: 0 | V25: =T25-U25 -> 0 | X25: =+W25-W24 -> 0 | Z25: =+Y25-Y24 -> 0 | AA25: =X25-AB25 -> 0 | AB25: =X25-Z25 -> 0
A26: =A25 -> 46089 | B26: 3 | C26: 351722 | D26: =+C26-C25 -> 0 | E26: 0 | F26: 0 | G26: =+F26*E26 -> 0 | H26: 0 | I26: =+H26*F26 -> 0 | J26: =+G26-I26 -> 0 | K26: 888 | L26: =+K26-K25 -> 0 | M26: 40 | N26: =+K26/M26 -> 22.2 | O26: =+K26*J26 -> 0 | P26: 0 | Q26: 10 | R26: =(P26*Q26) -> 0 | S26: 93572 | T26: =+S26-S25 -> 0 | U26: 0 | V26: =T26-U26 -> 0 | X26: =+W26-W25 -> 0 | Z26: =+Y26-Y25 -> 0 | AA26: =X26-AB26 -> 0 | AB26: =X26-Z26 -> 0
A27: =A26+1 -> 46090 | B27: 1 | C27: 351722 | D27: =+C27-C26 -> 0 | E27: 0 | F27: 0 | G27: =+F27*E27 -> 0 | H27: 0 | I27: =+H27*F27 -> 0 | J27: =+G27-I27 -> 0 | K27: 888 | L27: =+K27-K26 -> 0 | M27: 40 | N27: =+K27/M27 -> 22.2 | O27: =+K27*J27 -> 0 | P27: 0 | Q27: 10 | R27: =(P27*Q27) -> 0 | S27: 93572 | T27: =+S27-S26 -> 0 | U27: 0 | V27: =T27-U27 -> 0 | X27: =+W27-W26 -> 0 | Z27: =+Y27-Y26 -> 0 | AA27: =X27-AB27 -> 0 | AB27: =X27-Z27 -> 0
A28: =A27 -> 46090 | B28: 2 | C28: 351722 | D28: =+C28-C27 -> 0 | E28: 0 | F28: 0 | G28: =+F28*E28 -> 0 | H28: 0 | I28: =+H28*F28 -> 0 | J28: =+G28-I28 -> 0 | K28: 888 | L28: =+K28-K27 -> 0 | M28: 40 | N28: =+K28/M28 -> 22.2 | O28: =+K28*J28 -> 0 | P28: 0 | Q28: 10 | R28: =(P28*Q28) -> 0 | S28: 93590 | T28: =+S28-S27 -> 18 | U28: 18 | V28: =T28-U28 -> 0 | X28: =+W28-W27 -> 0 | Z28: =+Y28-Y27 -> 0 | AA28: =X28-AB28 -> 0 | AB28: =X28-Z28 -> 0
A29: =A28 -> 46090 | B29: 3 | C29: 351722 | D29: =+C29-C28 -> 0 | E29: 0 | F29: 0 | G29: =+F29*E29 -> 0 | H29: 0 | I29: =+H29*F29 -> 0 | J29: =+G29-I29 -> 0 | K29: 888 | L29: =+K29-K28 -> 0 | M29: 40 | N29: =+K29/M29 -> 22.2 | O29: =+K29*J29 -> 0 | P29: 0 | Q29: 10 | R29: =(P29*Q29) -> 0 | S29: 93613 | T29: =+S29-S28 -> 23 | U29: 23 | V29: =T29-U29 -> 0 | X29: =+W29-W28 -> 0 | Z29: =+Y29-Y28 -> 0 | AA29: =X29-AB29 -> 0 | AB29: =X29-Z29 -> 0
A30: =A29+1 -> 46091 | B30: 1 | C30: 351722 | D30: =+C30-C29 -> 0 | E30: 0 | F30: 0 | G30: =+F30*E30 -> 0 | H30: 0 | I30: =+H30*F30 -> 0 | J30: =+G30-I30 -> 0 | K30: 888 | L30: =+K30-K29 -> 0 | M30: 40 | N30: =+K30/M30 -> 22.2 | O30: =+K30*J30 -> 0 | P30: 0 | Q30: 10 | R30: =(P30*Q30) -> 0 | S30: 93613 | T30: =+S30-S29 -> 0 | U30: 0 | V30: =T30-U30 -> 0 | X30: =+W30-W29 -> 0 | Z30: =+Y30-Y29 -> 0 | AA30: =X30-AB30 -> 0 | AB30: =X30-Z30 -> 0
A31: =A30 -> 46091 | B31: 2 | C31: 351723 | D31: =+C31-C30 -> 1 | E31: 0 | F31: 0 | G31: =+F31*E31 -> 0 | H31: 0 | I31: =+H31*F31 -> 0 | J31: =+G31-I31 -> 0 | K31: 888 | L31: =+K31-K30 -> 0 | M31: 40 | N31: =+K31/M31 -> 22.2 | O31: =+K31*J31 -> 0 | P31: 0 | Q31: 10 | R31: =(P31*Q31) -> 0 | S31: 93666 | T31: =+S31-S30 -> 53 | U31: 53 | V31: =T31-U31 -> 0 | X31: =+W31-W30 -> 0 | Z31: =+Y31-Y30 -> 0 | AA31: =X31-AB31 -> 0 | AB31: =X31-Z31 -> 0
A32: =A31 -> 46091 | B32: 3 | C32: 351723 | D32: =+C32-C31 -> 0 | E32: 0 | F32: 0 | G32: =+F32*E32 -> 0 | H32: 0 | I32: =+H32*F32 -> 0 | J32: =+G32-I32 -> 0 | K32: 888 | L32: =+K32-K31 -> 0 | M32: 40 | N32: =+K32/M32 -> 22.2 | O32: =+K32*J32 -> 0 | P32: 0 | Q32: 10 | R32: =(P32*Q32) -> 0 | S32: 93666 | T32: =+S32-S31 -> 0 | U32: 0 | V32: =T32-U32 -> 0 | X32: =+W32-W31 -> 0 | Z32: =+Y32-Y31 -> 0 | AA32: =X32-AB32 -> 0 | AB32: =X32-Z32 -> 0
A33: =A32+1 -> 46092 | B33: 1 | C33: 351723 | D33: =+C33-C32 -> 0 | E33: 0 | F33: 0 | G33: =+F33*E33 -> 0 | H33: 0 | I33: =+H33*F33 -> 0 | J33: =+G33-I33 -> 0 | K33: 888 | L33: =+K33-K32 -> 0 | M33: 40 | N33: =+K33/M33 -> 22.2 | O33: =+K33*J33 -> 0 | P33: 0 | Q33: 10 | R33: =(P33*Q33) -> 0 | S33: 93666 | T33: =+S33-S32 -> 0 | U33: 0 | V33: =T33-U33 -> 0 | X33: =+W33-W32 -> 0 | Z33: =+Y33-Y32 -> 0 | AA33: =X33-AB33 -> 0 | AB33: =X33-Z33 -> 0
A34: =A33 -> 46092 | B34: 2 | C34: 351724 | D34: =+C34-C33 -> 1 | E34: 0 | F34: 0 | G34: =+F34*E34 -> 0 | H34: 0 | I34: =+H34*F34 -> 0 | J34: =+G34-I34 -> 0 | K34: 888 | L34: =+K34-K33 -> 0 | M34: 40 | N34: =+K34/M34 -> 22.2 | O34: =+K34*J34 -> 0 | P34: 0 | Q34: 10 | R34: =(P34*Q34) -> 0 | S34: 93690 | T34: =+S34-S33 -> 24 | U34: 24 | V34: =T34-U34 -> 0 | X34: =+W34-W33 -> 0 | Z34: =+Y34-Y33 -> 0 | AA34: =X34-AB34 -> 0 | AB34: =X34-Z34 -> 0
A35: =A33 -> 46092 | B35: 3 | C35: 351724 | D35: =+C35-C34 -> 0 | E35: 0 | F35: 0 | G35: =+F35*E35 -> 0 | H35: 0 | I35: =+H35*F35 -> 0 | J35: =+G35-I35 -> 0 | K35: 888 | L35: =+K35-K34 -> 0 | M35: 40 | N35: =+K35/M35 -> 22.2 | O35: =+K35*J35 -> 0 | P35: 1 | Q35: 10 | R35: =(P35*Q35) -> 10 | S35: 93728 | T35: =+S35-S34 -> 38 | U35: 38 | V35: =T35-U35 -> 0 | X35: =+W35-W34 -> 0 | Z35: =+Y35-Y34 -> 0 | AA35: =X35-AB35 -> 0 | AB35: =X35-Z35 -> 0
A36: =A33+1 -> 46093 | B36: 1 | C36: 351724 | D36: =+C36-C35 -> 0 | E36: 0 | F36: 0 | G36: =+F36*E36 -> 0 | H36: 0 | I36: =+H36*F36 -> 0 | J36: =+G36-I36 -> 0 | K36: 888 | L36: =+K36-K35 -> 0 | M36: 40 | N36: =+K36/M36 -> 22.2 | O36: =+K36*J36 -> 0 | P36: 0 | Q36: 10 | R36: =(P36*Q36) -> 0 | S36: 93728 | T36: =+S36-S35 -> 0 | U36: 0 | V36: =T36-U36 -> 0 | X36: =+W36-W35 -> 0 | Z36: =+Y36-Y35 -> 0 | AA36: =X36-AB36 -> 0 | AB36: =X36-Z36 -> 0
A37: =A36 -> 46093 | B37: 2 | C37: 351728 | D37: =+C37-C36 -> 4 | E37: 0 | F37: 0 | G37: =+F37*E37 -> 0 | H37: 0 | I37: =+H37*F37 -> 0 | J37: =+G37-I37 -> 0 | K37: 888 | L37: =+K37-K36 -> 0 | M37: 40 | N37: =+K37/M37 -> 22.2 | O37: =+K37*J37 -> 0 | P37: 0 | Q37: 10 | R37: =(P37*Q37) -> 0 | S37: 93728 | T37: =+S37-S36 -> 0 | U37: 0 | V37: =T37-U37 -> 0 | X37: =+W37-W36 -> 0 | Z37: =+Y37-Y36 -> 0 | AA37: =X37-AB37 -> 0 | AB37: =X37-Z37 -> 0
A38: =A36 -> 46093 | B38: 3 | C38: 351728 | D38: =+C38-C37 -> 0 | E38: 0 | F38: 0 | G38: =+F38*E38 -> 0 | H38: 0 | I38: =+H38*F38 -> 0 | J38: =+G38-I38 -> 0 | K38: 888 | L38: =+K38-K37 -> 0 | M38: 40 | N38: =+K38/M38 -> 22.2 | O38: =+K38*J38 -> 0 | P38: 0 | Q38: 10 | R38: =(P38*Q38) -> 0 | S38: 93767 | T38: =+S38-S37 -> 39 | U38: 39 | V38: =T38-U38 -> 0 | X38: =+W38-W37 -> 0 | Z38: =+Y38-Y37 -> 0 | AA38: =X38-AB38 -> 0 | AB38: =X38-Z38 -> 0
A39: =A38+1 -> 46094 | B39: 1 | C39: 351728 | D39: =+C39-C38 -> 0 | E39: 0 | F39: 0 | G39: =+F39*E39 -> 0 | H39: 0 | I39: =+H39*F39 -> 0 | J39: =+G39-I39 -> 0 | K39: 888 | L39: =+K39-K38 -> 0 | M39: 40 | N39: =+K39/M39 -> 22.2 | O39: =(N40-N39)*M39 -> 0 | P39: 0 | Q39: 10 | R39: =(P39*Q39) -> 0 | S39: 93767 | T39: =+S39-S38 -> 0 | U39: 0 | V39: =T39-U39 -> 0 | X39: =+W39-W38 -> 0 | Z39: =+Y39-Y38 -> 0 | AA39: =X39-AB39 -> 0 | AB39: =X39-Z39 -> 0
A40: =A39 -> 46094 | B40: 2 | C40: 351728 | D40: =+C40-C39 -> 0 | E40: 0 | F40: 0 | G40: =+F40*E40 -> 0 | H40: 0 | I40: =+H40*F40 -> 0 | J40: =+G40-I40 -> 0 | K40: 888 | L40: =+K40-K39 -> 0 | M40: 40 | N40: =+K40/M40 -> 22.2 | O40: =(N41-N40)*M40 -> 0 | P40: 0 | Q40: 10 | R40: =(P40*Q40) -> 0 | S40: 93797 | T40: =+S40-S39 -> 30 | U40: 30 | V40: =T40-U40 -> 0 | X40: =+W40-W39 -> 0 | Z40: =+Y40-Y39 -> 0 | AA40: =X40-AB40 -> 0 | AB40: =X40-Z40 -> 0
...
