Workbook
Name SegmentaciónDeDatos_FECHA: #N/A
Name SegmentaciónDeDatos_FECHA1: #N/A

Sheet PTAP INVENTARIO
A1: FECHA | B1: DIA | C1: ANALISIS TURNO | D1: # TURNO | E1: DILIGENCIAR BITACORA | F1: INV FINAL ACIDO (L) | G1: INV FINAL COAGULANTE (L) | H1: INV FINAL POL ANIONICO (KG) | I1: CONSUMO SOLUCIÓN OXIDANTE (L) | J1: Lectura Medidor de flujo pozo profundo | K1: CAUDAL TOTAL ENVIADO PTAP | L1: CONSUMO LITROS ACIDO (L) | M1: CONSUMO LITROS COAGULANTE (L) | N1: CONSUMO POL ANIONICO (KG) | O1: CONSUMO OXIDANTE SOLUCIÓN(L) | P1: KG ACIDO | Q1: KG COAGULANTE | R1: KG POL ANIONICO | S1: KG OXIDANTE | T1: PPM ACIDO | U1: PPM COAGULANTE | V1: PPM POL ANIONICO | W1: PPM POL OXIDANTE | X1: DENSIDAD ACIDO | Y1: DENSIDAD COAGULANTE | Z1: DENSIDAD ANIONICO | AA1: DENSIDAD OXIDANTE | AB1: PRECIO (KG) ACIDO | AC1: PRECIO (KG) COAGULANTE | AD1: PRECIO (KG) ANIONICO | AE1: PRECIO (KG) OXIDANTE | AF1: COSTO OPERATIVO ACIDO | AG1: COSTO OPERATIVO COAGULANTE | AH1: COSTO OPERATIVO ANIONICO | AI1: COSTO OPERATIVO OXIDANTE | AJ1: COSTO QUIMICA TOTAL CAUDAL TRATADO | AK1: LIMITE INDICADOR M3 | AL1: $ m3
A2: 46023 | B2: =DAY(Tabla1[[#This Row],[FECHA]]) -> 1 | C2: 1 (NOCHE) | D2: 1 | E2: FINAL TURNO 3 | F2: 1351 | G2: 1800 | H2: 93.539 | I2: 0 | J2: 92468 | K2: 0 | L2: 0 | M2: =G2-G3 -> 0 | N2: =H2-H3 -> 0 | O2: 0 | P2: =(L2*$X$2)/1000000 -> 0 | Q2: =(M2*$Y$2)/1000000 -> 0 | R2: =Tabla1[[#This Row],[CONSUMO POL ANIONICO (KG)]] -> 0 | S2: =Tabla1[[#This Row],[CONSUMO OXIDANTE SOLUCIÓN(L)]]*Tabla1[[#This Row],[DENSIDAD OXIDANTE]] -> 0 | T2: =(P2*1000)/K2 -> #DIV/0! | U2: =(Q2*1000)/K2 -> #DIV/0! | V2: =(R2*1000)/K2 -> #DIV/0! | W2: =(S2*1000)/K2 -> #DIV/0! | X2: 1240000 | Y2: 1325000 | Z2: 2500 | AA2: 0.042 | AB2: 2446 | AC2: 2498 | AD2: 23800 | AE2: 3010 | AF2: =P2*AB2 -> 0 | AG2: =Q2*AC2 -> 0 | AH2: =R2*AD2 -> 0 | AI2: =S2*AE2 -> 0 | AJ2: =SUM(Tabla1[[#This Row],[COSTO OPERATIVO ACIDO]:[COSTO OPERATIVO OXIDANTE]]) -> 0 | AK2: 2500 | AL2: =AJ2/K2 -> #DIV/0!
A3: =A2 -> 46023 | B3: =DAY(Tabla1[[#This Row],[FECHA]]) -> 1 | C3: 2 (MAÑANA) | D3: 2 | E3: FINAL TURNO 1 | F3: =F2 -> 1351 | G3: 1800 | H3: =H2 -> 93.539 | I3: 0 | J3: 92468 | K3: 0 | L3: 0 | M3: =G3-G4 -> 0 | N3: =H3-H4 -> 0 | O3: =Tabla1[[#This Row],[CONSUMO SOLUCIÓN OXIDANTE (L)]] -> 0 | P3: =(L3*$X$2)/1000000 -> 0 | Q3: =(M3*$Y$2)/1000000 -> 0 | R3: =Tabla1[[#This Row],[CONSUMO POL ANIONICO (KG)]] -> 0 | S3: =Tabla1[[#This Row],[CONSUMO OXIDANTE SOLUCIÓN(L)]]*Tabla1[[#This Row],[DENSIDAD OXIDANTE]] -> 0 | T3: =(P3*1000)/K3 -> #DIV/0! | U3: =(Q3*1000)/K3 -> #DIV/0! | V3: =(R3*1000)/K3 -> #DIV/0! | W3: =(S3*1000)/K3 -> #DIV/0! | X3: 1240000 | Y3: 1325000 | Z3: 2500 | AA3: 0.042 | AB3: 2446 | AC3: 2498 | AD3: 23800 | AE3: 3010 | AF3: =P3*AB3 -> 0 | AG3: =Q3*AC3 -> 0 | AH3: =R3*AD3 -> 0 | AI3: =S3*AE3 -> 0 | AJ3: =SUM(Tabla1[[#This Row],[COSTO OPERATIVO ACIDO]:[COSTO OPERATIVO OXIDANTE]]) -> 0 | AK3: 2500 | AL3: =AJ3/K3 -> #DIV/0!
A4: =A3 -> 46023 | B4: =DAY(Tabla1[[#This Row],[FECHA]]) -> 1 | C4: 3(TARDE) | D4: 3 | E4: FINAL TURNO 2 | F4: =F3 -> 1351 | G4: 1800 | H4: =H3 -> 93.539 | I4: 0 | J4: 92468 | K4: 0 | L4: =F4-F5 -> 0 | M4: =G4-G5 -> 0 | N4: =H4-H5 -> 0 | O4: =Tabla1[[#This Row],[CONSUMO SOLUCIÓN OXIDANTE (L)]] -> 0 | P4: =(L4*$X$2)/1000000 -> 0 | Q4: =(M4*$Y$2)/1000000 -> 0 | R4: =Tabla1[[#This Row],[CONSUMO POL ANIONICO (KG)]] -> 0 | S4: =Tabla1[[#This Row],[CONSUMO OXIDANTE SOLUCIÓN(L)]]*Tabla1[[#This Row],[DENSIDAD OXIDANTE]] -> 0 | T4: =(P4*1000)/K4 -> #DIV/0! | U4: =(Q4*1000)/K4 -> #DIV/0! | V4: =(R4*1000)/K4 -> #DIV/0! | W4: =(S4*1000)/K4 -> #DIV/0! | X4: 1240000 | Y4: 1325000 | Z4: 2500 | AA4: 0.042 | AB4: 2446 | AC4: 2498 | AD4: 23800 | AE4: 3010 | AF4: =P4*AB4 -> 0 | AG4: =Q4*AC4 -> 0 | AH4: =R4*AD4 -> 0 | AI4: =S4*AE4 -> 0 | AJ4: =SUM(Tabla1[[#This Row],[COSTO OPERATIVO ACIDO]:[COSTO OPERATIVO OXIDANTE]]) -> 0 | AK4: 2500 | AL4: =AJ4/K4 -> #DIV/0!
A5: =A4+1 -> 46024 | B5: =DAY(Tabla1[[#This Row],[FECHA]]) -> 2 | C5: 1 (NOCHE) | D5: 1 | E5: FINAL TURNO 3 | F5: =F4 -> 1351 | G5: =G4 -> 1800 | H5: =H4 -> 93.539 | I5: 6 | J5: 92468 | K5: 0 | L5: =F5-F6 -> 6 | M5: =G5-G6 -> 8 | N5: =H5-H6 -> 0.019 | O5: =Tabla1[[#This Row],[CONSUMO SOLUCIÓN OXIDANTE (L)]] -> 6 | P5: =(L5*$X$2)/1000000 -> 7.44 | Q5: =(M5*$Y$2)/1000000 -> 10.6 | R5: =Tabla1[[#This Row],[CONSUMO POL ANIONICO (KG)]] -> 0.019 | S5: =Tabla1[[#This Row],[CONSUMO OXIDANTE SOLUCIÓN(L)]]*Tabla1[[#This Row],[DENSIDAD OXIDANTE]] -> 0.252 | T5: =(P5*1000)/K5 -> #DIV/0! | U5: =(Q5*1000)/K5 -> #DIV/0! | V5: =(R5*1000)/K5 -> #DIV/0! | W5: =(S5*1000)/K5 -> #DIV/0! | X5: 1240000 | Y5: 1325000 | Z5: 2500 | AA5: 0.042 | AB5: 2446 | AC5: 2498 | AD5: 23800 | AE5: 3010 | AF5: =P5*AB5 -> 18198.24 | AG5: =Q5*AC5 -> 26478.8 | AH5: =R5*AD5 -> 452.2 | AI5: =S5*AE5 -> 758.52 | AJ5: =SUM(Tabla1[[#This Row],[COSTO OPERATIVO ACIDO]:[COSTO OPERATIVO OXIDANTE]]) -> 45887.76 | AK5: 2500 | AL5: =AJ5/K5 -> #DIV/0!
A6: =A5 -> 46024 | B6: =DAY(Tabla1[[#This Row],[FECHA]]) -> 2 | C6: 2 (MAÑANA) | D6: 2 | E6: FINAL TURNO 1 | F6: 1345 | G6: 1792 | H6: 93.52 | I6: 0 | J6: 92468 | K6: 0 | L6: =F6-F7 -> 0 | M6: =G6-G7 -> 0 | N6: =H6-H7 -> 0 | O6: =Tabla1[[#This Row],[CONSUMO SOLUCIÓN OXIDANTE (L)]] -> 0 | P6: =(L6*$X$2)/1000000 -> 0 | Q6: =(M6*$Y$2)/1000000 -> 0 | R6: =Tabla1[[#This Row],[CONSUMO POL ANIONICO (KG)]] -> 0 | S6: =Tabla1[[#This Row],[CONSUMO OXIDANTE SOLUCIÓN(L)]]*Tabla1[[#This Row],[DENSIDAD OXIDANTE]] -> 0 | T6: =(P6*1000)/K6 -> #DIV/0! | U6: =(Q6*1000)/K6 -> #DIV/0! | V6: =(R6*1000)/K6 -> #DIV/0! | W6: =(S6*1000)/K6 -> #DIV/0! | X6: 1240000 | Y6: 1325000 | Z6: 2500 | AA6: 0.042 | AB6: 2446 | AC6: 2498 | AD6: 23800 | AE6: 3010 | AF6: =P6*AB6 -> 0 | AG6: =Q6*AC6 -> 0 | AH6: =R6*AD6 -> 0 | AI6: =S6*AE6 -> 0 | AJ6: =SUM(Tabla1[[#This Row],[COSTO OPERATIVO ACIDO]:[COSTO OPERATIVO OXIDANTE]]) -> 0 | AK6: 2500 | AL6: =AJ6/K6 -> #DIV/0!
A7: =A6 -> 46024 | B7: =DAY(Tabla1[[#This Row],[FECHA]]) -> 2 | C7: 3(TARDE) | D7: 3 | E7: FINAL TURNO 2 | F7: 1345 | G7: 1792 | H7: 93.52 | I7: 0 | J7: 92468 | K7: 18 | L7: =F7-F8 -> 0 | M7: =G7-G8 -> 0 | N7: =H7-H8 -> 0 | O7: =Tabla1[[#This Row],[CONSUMO SOLUCIÓN OXIDANTE (L)]] -> 0 | P7: =(L7*$X$2)/1000000 -> 0 | Q7: =(M7*$Y$2)/1000000 -> 0 | R7: =Tabla1[[#This Row],[CONSUMO POL ANIONICO (KG)]] -> 0 | S7: =Tabla1[[#This Row],[CONSUMO OXIDANTE SOLUCIÓN(L)]]*Tabla1[[#This Row],[DENSIDAD OXIDANTE]] -> 0 | T7: =(P7*1000)/K7 -> 0 | U7: =(Q7*1000)/K7 -> 0 | V7: =(R7*1000)/K7 -> 0 | W7: =(S7*1000)/K7 -> 0 | X7: 1240000 | Y7: 1325000 | Z7: 2500 | AA7: 0.042 | AB7: 2446 | AC7: 2498 | AD7: 23800 | AE7: 3010 | AF7: =P7*AB7 -> 0 | AG7: =Q7*AC7 -> 0 | AH7: =R7*AD7 -> 0 | AI7: =S7*AE7 -> 0 | AJ7: =SUM(Tabla1[[#This Row],[COSTO OPERATIVO ACIDO]:[COSTO OPERATIVO OXIDANTE]]) -> 0 | AK7: 2500 | AL7: =AJ7/K7 -> 0
A8: =A7+1 -> 46025 | B8: =DAY(Tabla1[[#This Row],[FECHA]]) -> 3 | C8: 1 (NOCHE) | D8: 1 | E8: FINAL TURNO 3 | F8: 1345 | G8: 1792 | H8: 93.52 | I8: 9 | J8: 92486 | K8: 0 | L8: =F8-F9 -> 10 | M8: =G8-G9 -> 14 | N8: =H8-H9 -> 0.02 | O8: =Tabla1[[#This Row],[CONSUMO SOLUCIÓN OXIDANTE (L)]] -> 9 | P8: =(L8*$X$2)/1000000 -> 12.4 | Q8: =(M8*$Y$2)/1000000 -> 18.55 | R8: =Tabla1[[#This Row],[CONSUMO POL ANIONICO (KG)]] -> 0.02 | S8: =Tabla1[[#This Row],[CONSUMO OXIDANTE SOLUCIÓN(L)]]*Tabla1[[#This Row],[DENSIDAD OXIDANTE]] -> 0.378 | T8: =(P8*1000)/K8 -> #DIV/0! | U8: =(Q8*1000)/K8 -> #DIV/0! | V8: =(R8*1000)/K8 -> #DIV/0! | W8: =(S8*1000)/K8 -> #DIV/0! | X8: 1240000 | Y8: 1325000 | Z8: 2500 | AA8: 0.042 | AB8: 2446 | AC8: 2498 | AD8: 23800 | AE8: 3010 | AF8: =P8*AB8 -> 30330.4 | AG8: =Q8*AC8 -> 46337.9 | AH8: =R8*AD8 -> 476 | AI8: =S8*AE8 -> 1137.78 | AJ8: =SUM(Tabla1[[#This Row],[COSTO OPERATIVO ACIDO]:[COSTO OPERATIVO OXIDANTE]]) -> 78282.08 | AK8: 2500 | AL8: =AJ8/K8 -> #DIV/0!
A9: =A8 -> 46025 | B9: =DAY(Tabla1[[#This Row],[FECHA]]) -> 3 | C9: 2 (MAÑANA) | D9: 2 | E9: FINAL TURNO 1 | F9: 1335 | G9: 1778 | H9: 93.5 | I9: 0 | J9: 92486 | K9: 0 | L9: =F9-F10 -> 0 | M9: =G9-G10 -> 0 | N9: =H9-H10 -> 0 | O9: =Tabla1[[#This Row],[CONSUMO SOLUCIÓN OXIDANTE (L)]] -> 0 | P9: =(L9*$X$2)/1000000 -> 0 | Q9: =(M9*$Y$2)/1000000 -> 0 | R9: =Tabla1[[#This Row],[CONSUMO POL ANIONICO (KG)]] -> 0 | S9: =Tabla1[[#This Row],[CONSUMO OXIDANTE SOLUCIÓN(L)]]*Tabla1[[#This Row],[DENSIDAD OXIDANTE]] -> 0 | T9: =(P9*1000)/K9 -> #DIV/0! | U9: =(Q9*1000)/K9 -> #DIV/0! | V9: =(R9*1000)/K9 -> #DIV/0! | W9: =(S9*1000)/K9 -> #DIV/0! | X9: 1240000 | Y9: 1325000 | Z9: 2500 | AA9: 0.042 | AB9: 2446 | AC9: 2498 | AD9: 23800 | AE9: 3010 | AF9: =P9*AB9 -> 0 | AG9: =Q9*AC9 -> 0 | AH9: =R9*AD9 -> 0 | AI9: =S9*AE9 -> 0 | AJ9: =SUM(Tabla1[[#This Row],[COSTO OPERATIVO ACIDO]:[COSTO OPERATIVO OXIDANTE]]) -> 0 | AK9: 2500 | AL9: =AJ9/K9 -> #DIV/0!
A10: =A9 -> 46025 | B10: =DAY(Tabla1[[#This Row],[FECHA]]) -> 3 | C10: 3(TARDE) | D10: 3 | E10: FINAL TURNO 2 | F10: =F9 -> 1335 | G10: 1778 | H10: =H9 -> 93.5 | I10: 0 | J10: 92486 | K10: 30 | L10: =F10-F11 -> 0 | M10: =G10-G11 -> 0 | N10: =H10-H11 -> 0 | O10: =Tabla1[[#This Row],[CONSUMO SOLUCIÓN OXIDANTE (L)]] -> 0 | P10: =(L10*$X$2)/1000000 -> 0 | Q10: =(M10*$Y$2)/1000000 -> 0 | R10: =Tabla1[[#This Row],[CONSUMO POL ANIONICO (KG)]] -> 0 | S10: =Tabla1[[#This Row],[CONSUMO OXIDANTE SOLUCIÓN(L)]]*Tabla1[[#This Row],[DENSIDAD OXIDANTE]] -> 0 | T10: =(P10*1000)/K10 -> 0 | U10: =(Q10*1000)/K10 -> 0 | V10: =(R10*1000)/K10 -> 0 | W10: =(S10*1000)/K10 -> 0 | X10: 1240000 | Y10: 1325000 | Z10: 2500 | AA10: 0.042 | AB10: 2446 | AC10: 2498 | AD10: 23800 | AE10: 3010 | AF10: =P10*AB10 -> 0 | AG10: =Q10*AC10 -> 0 | AH10: =R10*AD10 -> 0 | AI10: =S10*AE10 -> 0 | AJ10: =SUM(Tabla1[[#This Row],[COSTO OPERATIVO ACIDO]:[COSTO OPERATIVO OXIDANTE]]) -> 0 | AK10: 2500 | AL10: =AJ10/K10 -> 0
A11: =A10+1 -> 46026 | B11: =DAY(Tabla1[[#This Row],[FECHA]]) -> 4 | C11: 1 (NOCHE) | D11: 1 | E11: FINAL TURNO 3 | F11: =F10 -> 1335 | G11: 1778 | H11: =H10 -> 93.5 | I11: 0 | J11: 92516 | K11: 0 | L11: =F11-F12 -> 0 | M11: =G11-G12 -> 0 | N11: =H11-H12 -> 0 | O11: =Tabla1[[#This Row],[CONSUMO SOLUCIÓN OXIDANTE (L)]] -> 0 | P11: =(L11*$X$2)/1000000 -> 0 | Q11: =(M11*$Y$2)/1000000 -> 0 | R11: =Tabla1[[#This Row],[CONSUMO POL ANIONICO (KG)]] -> 0 | S11: =Tabla1[[#This Row],[CONSUMO OXIDANTE SOLUCIÓN(L)]]*Tabla1[[#This Row],[DENSIDAD OXIDANTE]] -> 0 | T11: =(P11*1000)/K11 -> #DIV/0! | U11: =(Q11*1000)/K11 -> #DIV/0! | V11: =(R11*1000)/K11 -> #DIV/0! | W11: =(S11*1000)/K11 -> #DIV/0! | X11: 1240000 | Y11: 1325000 | Z11: 2500 | AA11: 0.042 | AB11: 2446 | AC11: 2498 | AD11: 23800 | AE11: 3010 | AF11: =P11*AB11 -> 0 | AG11: =Q11*AC11 -> 0 | AH11: =R11*AD11 -> 0 | AI11: =S11*AE11 -> 0 | AJ11: =SUM(Tabla1[[#This Row],[COSTO OPERATIVO ACIDO]:[COSTO OPERATIVO OXIDANTE]]) -> 0 | AK11: 2500 | AL11: =AJ11/K11 -> #DIV/0!
A12: =A11 -> 46026 | B12: =DAY(Tabla1[[#This Row],[FECHA]]) -> 4 | C12: 2 (MAÑANA) | D12: 2 | E12: FINAL TURNO 1 | F12: =F11 -> 1335 | G12: 1778 | H12: =H11 -> 93.5 | I12: 0 | J12: 92516 | K12: 0 | L12: =F12-F13 -> 0 | M12: =G12-G13 -> 0 | N12: =H12-H13 -> 0 | O12: =Tabla1[[#This Row],[CONSUMO SOLUCIÓN OXIDANTE (L)]] -> 0 | P12: =(L12*$X$2)/1000000 -> 0 | Q12: =(M12*$Y$2)/1000000 -> 0 | R12: =Tabla1[[#This Row],[CONSUMO POL ANIONICO (KG)]] -> 0 | S12: =Tabla1[[#This Row],[CONSUMO OXIDANTE SOLUCIÓN(L)]]*Tabla1[[#This Row],[DENSIDAD OXIDANTE]] -> 0 | T12: =(P12*1000)/K12 -> #DIV/0! | U12: =(Q12*1000)/K12 -> #DIV/0! | V12: =(R12*1000)/K12 -> #DIV/0! | W12: =(S12*1000)/K12 -> #DIV/0! | X12: 1240000 | Y12: 1325000 | Z12: 2500 | AA12: 0.042 | AB12: 2446 | AC12: 2498 | AD12: 23800 | AE12: 3010 | AF12: =P12*AB12 -> 0 | AG12: =Q12*AC12 -> 0 | AH12: =R12*AD12 -> 0 | AI12: =S12*AE12 -> 0 | AJ12: =SUM(Tabla1[[#This Row],[COSTO OPERATIVO ACIDO]:[COSTO OPERATIVO OXIDANTE]]) -> 0 | AK12: 2500 | AL12: =AJ12/K12 -> #DIV/0!
A13: =A12 -> 46026 | B13: =DAY(Tabla1[[#This Row],[FECHA]]) -> 4 | C13: 3(TARDE) | D13: 3 | E13: FINAL TURNO 2 | F13: =F12 -> 1335 | G13: 1778 | H13: =H12 -> 93.5 | I13: 0 | J13: 92516 | K13: 0 | L13: =F13-F14 -> 0 | M13: =G13-G14 -> 0 | N13: =H13-H14 -> 0 | O13: =Tabla1[[#This Row],[CONSUMO SOLUCIÓN OXIDANTE (L)]] -> 0 | P13: =(L13*$X$2)/1000000 -> 0 | Q13: =(M13*$Y$2)/1000000 -> 0 | R13: =Tabla1[[#This Row],[CONSUMO POL ANIONICO (KG)]] -> 0 | S13: =Tabla1[[#This Row],[CONSUMO OXIDANTE SOLUCIÓN(L)]]*Tabla1[[#This Row],[DENSIDAD OXIDANTE]] -> 0 | T13: =(P13*1000)/K13 -> #DIV/0! | U13: =(Q13*1000)/K13 -> #DIV/0! | V13: =(R13*1000)/K13 -> #DIV/0! | W13: =(S13*1000)/K13 -> #DIV/0! | X13: 1240000 | Y13: 1325000 | Z13: 2500 | AA13: 0.042 | AB13: 2446 | AC13: 2498 | AD13: 23800 | AE13: 3010 | AF13: =P13*AB13 -> 0 | AG13: =Q13*AC13 -> 0 | AH13: =R13*AD13 -> 0 | AI13: =S13*AE13 -> 0 | AJ13: =SUM(Tabla1[[#This Row],[COSTO OPERATIVO ACIDO]:[COSTO OPERATIVO OXIDANTE]]) -> 0 | AK13: 2500 | AL13: =AJ13/K13 -> #DIV/0!
A14: =A13+1 -> 46027 | B14: =DAY(Tabla1[[#This Row],[FECHA]]) -> 5 | C14: 1 (NOCHE) | D14: 1 | E14: FINAL TURNO 3 | F14: =F13 -> 1335 | G14: 1778 | H14: =H13 -> 93.5 | I14: 0 | J14: 92516 | K14: 0 | L14: =F14-F15 -> 0 | M14: =G14-G15 -> 0 | N14: =H14-H15 -> 0 | O14: =Tabla1[[#This Row],[CONSUMO SOLUCIÓN OXIDANTE (L)]] -> 0 | P14: =(L14*$X$2)/1000000 -> 0 | Q14: =(M14*$Y$2)/1000000 -> 0 | R14: =Tabla1[[#This Row],[CONSUMO POL ANIONICO (KG)]] -> 0 | S14: =Tabla1[[#This Row],[CONSUMO OXIDANTE SOLUCIÓN(L)]]*Tabla1[[#This Row],[DENSIDAD OXIDANTE]] -> 0 | T14: =(P14*1000)/K14 -> #DIV/0! | U14: =(Q14*1000)/K14 -> #DIV/0! | V14: =(R14*1000)/K14 -> #DIV/0! | W14: =(S14*1000)/K14 -> #DIV/0! | X14: 1240000 | Y14: 1325000 | Z14: 2500 | AA14: 0.042 | AB14: 2446 | AC14: 2498 | AD14: 23800 | AE14: 3010 | AF14: =P14*AB14 -> 0 | AG14: =Q14*AC14 -> 0 | AH14: =R14*AD14 -> 0 | AI14: =S14*AE14 -> 0 | AJ14: =SUM(Tabla1[[#This Row],[COSTO OPERATIVO ACIDO]:[COSTO OPERATIVO OXIDANTE]]) -> 0 | AK14: 2500 | AL14: =AJ14/K14 -> #DIV/0!
A15: =A14 -> 46027 | B15: =DAY(Tabla1[[#This Row],[FECHA]]) -> 5 | C15: 2 (MAÑANA) | D15: 2 | E15: FINAL TURNO 1 | F15: =F14 -> 1335 | G15: 1778 | H15: =H14 -> 93.5 | I15: 0 | J15: 92516 | K15: 0 | L15: =F15-F16 -> 0 | M15: =G15-G16 -> 0 | N15: =H15-H16 -> 0 | O15: =Tabla1[[#This Row],[CONSUMO SOLUCIÓN OXIDANTE (L)]] -> 0 | P15: =(L15*$X$2)/1000000 -> 0 | Q15: =(M15*$Y$2)/1000000 -> 0 | R15: =Tabla1[[#This Row],[CONSUMO POL ANIONICO (KG)]] -> 0 | S15: =Tabla1[[#This Row],[CONSUMO OXIDANTE SOLUCIÓN(L)]]*Tabla1[[#This Row],[DENSIDAD OXIDANTE]] -> 0 | T15: =(P15*1000)/K15 -> #DIV/0! | U15: =(Q15*1000)/K15 -> #DIV/0! | V15: =(R15*1000)/K15 -> #DIV/0! | W15: =(S15*1000)/K15 -> #DIV/0! | X15: 1240000 | Y15: 1325000 | Z15: 2500 | AA15: 0.042 | AB15: 2446 | AC15: 2498 | AD15: 23800 | AE15: 3010 | AF15: =P15*AB15 -> 0 | AG15: =Q15*AC15 -> 0 | AH15: =R15*AD15 -> 0 | AI15: =S15*AE15 -> 0 | AJ15: =SUM(Tabla1[[#This Row],[COSTO OPERATIVO ACIDO]:[COSTO OPERATIVO OXIDANTE]]) -> 0 | AK15: 2500 | AL15: =AJ15/K15 -> #DIV/0!
A16: =A15 -> 46027 | B16: =DAY(Tabla1[[#This Row],[FECHA]]) -> 5 | C16: 3(TARDE) | D16: 3 | E16: FINAL TURNO 2 | F16: =F15 -> 1335 | G16: 1778 | H16: =H15 -> 93.5 | I16: 0 | J16: 92516 | K16: 0 | L16: =F16-F17 -> 0 | M16: =G16-G17 -> 0 | N16: =H16-H17 -> 0 | O16: =Tabla1[[#This Row],[CONSUMO SOLUCIÓN OXIDANTE (L)]] -> 0 | P16: =(L16*$X$2)/1000000 -> 0 | Q16: =(M16*$Y$2)/1000000 -> 0 | R16: =Tabla1[[#This Row],[CONSUMO POL ANIONICO (KG)]] -> 0 | S16: =Tabla1[[#This Row],[CONSUMO OXIDANTE SOLUCIÓN(L)]]*Tabla1[[#This Row],[DENSIDAD OXIDANTE]] -> 0 | T16: =(P16*1000)/K16 -> #DIV/0! | U16: =(Q16*1000)/K16 -> #DIV/0! | V16: =(R16*1000)/K16 -> #DIV/0! | W16: =(S16*1000)/K16 -> #DIV/0! | X16: 1240000 | Y16: 1325000 | Z16: 2500 | AA16: 0.042 | AB16: 2446 | AC16: 2498 | AD16: 23800 | AE16: 3010 | AF16: =P16*AB16 -> 0 | AG16: =Q16*AC16 -> 0 | AH16: =R16*AD16 -> 0 | AI16: =S16*AE16 -> 0 | AJ16: =SUM(Tabla1[[#This Row],[COSTO OPERATIVO ACIDO]:[COSTO OPERATIVO OXIDANTE]]) -> 0 | AK16: 2500 | AL16: =AJ16/K16 -> #DIV/0!
A17: =A16+1 -> 46028 | B17: =DAY(Tabla1[[#This Row],[FECHA]]) -> 6 | C17: 1 (NOCHE) | D17: 1 | E17: FINAL TURNO 3 | F17: 1335 | G17: 1778 | H17: =H16 -> 93.5 | I17: 0 | J17: 92516 | K17: 0 | L17: =F17-F18 -> 0 | M17: =G17-G18 -> 0 | N17: =H17-H18 -> 0 | O17: =Tabla1[[#This Row],[CONSUMO SOLUCIÓN OXIDANTE (L)]] -> 0 | P17: =(L17*$X$2)/1000000 -> 0 | Q17: =(M17*$Y$2)/1000000 -> 0 | R17: =Tabla1[[#This Row],[CONSUMO POL ANIONICO (KG)]] -> 0 | S17: =Tabla1[[#This Row],[CONSUMO OXIDANTE SOLUCIÓN(L)]]*Tabla1[[#This Row],[DENSIDAD OXIDANTE]] -> 0 | T17: =(P17*1000)/K17 -> #DIV/0! | U17: =(Q17*1000)/K17 -> #DIV/0! | V17: =(R17*1000)/K17 -> #DIV/0! | W17: =(S17*1000)/K17 -> #DIV/0! | X17: 1240000 | Y17: 1325000 | Z17: 2500 | AA17: 0.042 | AB17: 2446 | AC17: 2498 | AD17: 23800 | AE17: 3010 | AF17: =P17*AB17 -> 0 | AG17: =Q17*AC17 -> 0 | AH17: =R17*AD17 -> 0 | AI17: =S17*AE17 -> 0 | AJ17: =SUM(Tabla1[[#This Row],[COSTO OPERATIVO ACIDO]:[COSTO OPERATIVO OXIDANTE]]) -> 0 | AK17: 2500 | AL17: =AJ17/K17 -> #DIV/0!
A18: =A17 -> 46028 | B18: =DAY(Tabla1[[#This Row],[FECHA]]) -> 6 | C18: 2 (MAÑANA) | D18: 2 | E18: FINAL TURNO 1 | F18: 1335 | G18: 1778 | H18: =H17 -> 93.5 | I18: 0 | J18: 92516 | K18: 0 | L18: =F18-F19 -> 0 | M18: =G18-G19 -> 0 | N18: =H18-H19 -> 0 | O18: =Tabla1[[#This Row],[CONSUMO SOLUCIÓN OXIDANTE (L)]] -> 0 | P18: =(L18*$X$2)/1000000 -> 0 | Q18: =(M18*$Y$2)/1000000 -> 0 | R18: =Tabla1[[#This Row],[CONSUMO POL ANIONICO (KG)]] -> 0 | S18: =Tabla1[[#This Row],[CONSUMO OXIDANTE SOLUCIÓN(L)]]*Tabla1[[#This Row],[DENSIDAD OXIDANTE]] -> 0 | T18: =(P18*1000)/K18 -> #DIV/0! | U18: =(Q18*1000)/K18 -> #DIV/0! | V18: =(R18*1000)/K18 -> #DIV/0! | W18: =(S18*1000)/K18 -> #DIV/0! | X18: 1240000 | Y18: 1325000 | Z18: 2500 | AA18: 0.042 | AB18: 2446 | AC18: 2498 | AD18: 23800 | AE18: 3010 | AF18: =P18*AB18 -> 0 | AG18: =Q18*AC18 -> 0 | AH18: =R18*AD18 -> 0 | AI18: =S18*AE18 -> 0 | AJ18: =SUM(Tabla1[[#This Row],[COSTO OPERATIVO ACIDO]:[COSTO OPERATIVO OXIDANTE]]) -> 0 | AK18: 2500 | AL18: =AJ18/K18 -> #DIV/0!
A19: =A18 -> 46028 | B19: =DAY(Tabla1[[#This Row],[FECHA]]) -> 6 | C19: 3(TARDE) | D19: 3 | E19: FINAL TURNO 2 | F19: 1335 | G19: 1778 | H19: =H18 -> 93.5 | I19: 0 | J19: 92516 | K19: 0 | L19: =F19-F20 -> 0 | M19: =G19-G20 -> 0 | N19: =H19-H20 -> 0 | O19: =Tabla1[[#This Row],[CONSUMO SOLUCIÓN OXIDANTE (L)]] -> 0 | P19: =(L19*$X$2)/1000000 -> 0 | Q19: =(M19*$Y$2)/1000000 -> 0 | R19: =Tabla1[[#This Row],[CONSUMO POL ANIONICO (KG)]] -> 0 | S19: =Tabla1[[#This Row],[CONSUMO OXIDANTE SOLUCIÓN(L)]]*Tabla1[[#This Row],[DENSIDAD OXIDANTE]] -> 0 | T19: =(P19*1000)/K19 -> #DIV/0! | U19: =(Q19*1000)/K19 -> #DIV/0! | V19: =(R19*1000)/K19 -> #DIV/0! | W19: =(S19*1000)/K19 -> #DIV/0! | X19: 1240000 | Y19: 1325000 | Z19: 2500 | AA19: 0.042 | AB19: 2446 | AC19: 2498 | AD19: 23800 | AE19: 3010 | AF19: =P19*AB19 -> 0 | AG19: =Q19*AC19 -> 0 | AH19: =R19*AD19 -> 0 | AI19: =S19*AE19 -> 0 | AJ19: =SUM(Tabla1[[#This Row],[COSTO OPERATIVO ACIDO]:[COSTO OPERATIVO OXIDANTE]]) -> 0 | AK19: 2500 | AL19: =AJ19/K19 -> #DIV/0!
A20: =A19+1 -> 46029 | B20: =DAY(Tabla1[[#This Row],[FECHA]]) -> 7 | C20: 1 (NOCHE) | D20: 1 | E20: FINAL TURNO 3 | F20: 1335 | G20: 1778 | H20: 93.5 | I20: 0 | J20: 92516 | K20: 0 | L20: =F20-F21 -> 0 | M20: =G20-G21 -> 0 | N20: =H20-H21 -> 0 | O20: =Tabla1[[#This Row],[CONSUMO SOLUCIÓN OXIDANTE (L)]] -> 0 | P20: =(L20*$X$2)/1000000 -> 0 | Q20: =(M20*$Y$2)/1000000 -> 0 | R20: =Tabla1[[#This Row],[CONSUMO POL ANIONICO (KG)]] -> 0 | S20: =Tabla1[[#This Row],[CONSUMO OXIDANTE SOLUCIÓN(L)]]*Tabla1[[#This Row],[DENSIDAD OXIDANTE]] -> 0 | T20: =(P20*1000)/K20 -> #DIV/0! | U20: =(Q20*1000)/K20 -> #DIV/0! | V20: =(R20*1000)/K20 -> #DIV/0! | W20: =(S20*1000)/K20 -> #DIV/0! | X20: 1240000 | Y20: 1325000 | Z20: 2500 | AA20: 0.042 | AB20: 2446 | AC20: 2498 | AD20: 23800 | AE20: 3010 | AF20: =P20*AB20 -> 0 | AG20: =Q20*AC20 -> 0 | AH20: =R20*AD20 -> 0 | AI20: =S20*AE20 -> 0 | AJ20: =SUM(Tabla1[[#This Row],[COSTO OPERATIVO ACIDO]:[COSTO OPERATIVO OXIDANTE]]) -> 0 | AK20: 2500 | AL20: =AJ20/K20 -> #DIV/0!
A21: =A20 -> 46029 | B21: =DAY(Tabla1[[#This Row],[FECHA]]) -> 7 | C21: 2 (MAÑANA) | D21: 2 | E21: FINAL TURNO 1 | F21: 1335 | G21: 1778 | H21: 93.5 | I21: 0 | J21: 92516 | K21: 0 | L21: =F21-F22 -> 0 | M21: =G21-G22 -> 0 | N21: =H21-H22 -> 0 | O21: =Tabla1[[#This Row],[CONSUMO SOLUCIÓN OXIDANTE (L)]] -> 0 | P21: =(L21*$X$2)/1000000 -> 0 | Q21: =(M21*$Y$2)/1000000 -> 0 | R21: =Tabla1[[#This Row],[CONSUMO POL ANIONICO (KG)]] -> 0 | S21: =Tabla1[[#This Row],[CONSUMO OXIDANTE SOLUCIÓN(L)]]*Tabla1[[#This Row],[DENSIDAD OXIDANTE]] -> 0 | T21: =(P21*1000)/K21 -> #DIV/0! | U21: =(Q21*1000)/K21 -> #DIV/0! | V21: =(R21*1000)/K21 -> #DIV/0! | W21: =(S21*1000)/K21 -> #DIV/0! | X21: 1240000 | Y21: 1325000 | Z21: 2500 | AA21: 0.042 | AB21: 2446 | AC21: 2498 | AD21: 23800 | AE21: 3010 | AF21: =P21*AB21 -> 0 | AG21: =Q21*AC21 -> 0 | AH21: =R21*AD21 -> 0 | AI21: =S21*AE21 -> 0 | AJ21: =SUM(Tabla1[[#This Row],[COSTO OPERATIVO ACIDO]:[COSTO OPERATIVO OXIDANTE]]) -> 0 | AK21: 2500 | AL21: =AJ21/K21 -> #DIV/0!
A22: =A21 -> 46029 | B22: =DAY(Tabla1[[#This Row],[FECHA]]) -> 7 | C22: 3(TARDE) | D22: 3 | E22: FINAL TURNO 2 | F22: 1335 | G22: 1778 | H22: 93.5 | I22: 0 | J22: 92516 | K22: 0 | L22: =F22-F23 -> 0 | M22: =G22-G23 -> 0 | N22: =H22-H23 -> 0 | O22: =Tabla1[[#This Row],[CONSUMO SOLUCIÓN OXIDANTE (L)]] -> 0 | P22: =(L22*$X$2)/1000000 -> 0 | Q22: =(M22*$Y$2)/1000000 -> 0 | R22: =Tabla1[[#This Row],[CONSUMO POL ANIONICO (KG)]] -> 0 | S22: =Tabla1[[#This Row],[CONSUMO OXIDANTE SOLUCIÓN(L)]]*Tabla1[[#This Row],[DENSIDAD OXIDANTE]] -> 0 | T22: =(P22*1000)/K22 -> #DIV/0! | U22: =(Q22*1000)/K22 -> #DIV/0! | V22: =(R22*1000)/K22 -> #DIV/0! | W22: =(S22*1000)/K22 -> #DIV/0! | X22: 1240000 | Y22: 1325000 | Z22: 2500 | AA22: 0.042 | AB22: 2446 | AC22: 2498 | AD22: 23800 | AE22: 3010 | AF22: =P22*AB22 -> 0 | AG22: =Q22*AC22 -> 0 | AH22: =R22*AD22 -> 0 | AI22: =S22*AE22 -> 0 | AJ22: =SUM(Tabla1[[#This Row],[COSTO OPERATIVO ACIDO]:[COSTO OPERATIVO OXIDANTE]]) -> 0 | AK22: 2500 | AL22: =AJ22/K22 -> #DIV/0!
A23: =A22+1 -> 46030 | B23: =DAY(Tabla1[[#This Row],[FECHA]]) -> 8 | C23: 1 (NOCHE) | D23: 1 | E23: FINAL TURNO 3 | F23: 1335 | G23: 1778 | H23: 93.5 | I23: 0 | J23: 92516 | K23: 0 | L23: =F23-F24 -> 0 | M23: =G23-G24 -> 0 | N23: =H23-H24 -> 0 | O23: =Tabla1[[#This Row],[CONSUMO SOLUCIÓN OXIDANTE (L)]] -> 0 | P23: =(L23*$X$2)/1000000 -> 0 | Q23: =(M23*$Y$2)/1000000 -> 0 | R23: =Tabla1[[#This Row],[CONSUMO POL ANIONICO (KG)]] -> 0 | S23: =Tabla1[[#This Row],[CONSUMO OXIDANTE SOLUCIÓN(L)]]*Tabla1[[#This Row],[DENSIDAD OXIDANTE]] -> 0 | T23: =(P23*1000)/K23 -> #DIV/0! | U23: =(Q23*1000)/K23 -> #DIV/0! | V23: =(R23*1000)/K23 -> #DIV/0! | W23: =(S23*1000)/K23 -> #DIV/0! | X23: 1240000 | Y23: 1325000 | Z23: 2500 | AA23: 0.042 | AB23: 2446 | AC23: 2498 | AD23: 23800 | AE23: 3010 | AF23: =P23*AB23 -> 0 | AG23: =Q23*AC23 -> 0 | AH23: =R23*AD23 -> 0 | AI23: =S23*AE23 -> 0 | AJ23: =SUM(Tabla1[[#This Row],[COSTO OPERATIVO ACIDO]:[COSTO OPERATIVO OXIDANTE]]) -> 0 | AK23: 2500 | AL23: =AJ23/K23 -> #DIV/0!
A24: =A23 -> 46030 | B24: =DAY(Tabla1[[#This Row],[FECHA]]) -> 8 | C24: 2 (MAÑANA) | D24: 2 | E24: FINAL TURNO 1 | F24: 1335 | G24: 1778 | H24: 93.5 | I24: 0 | J24: 92516 | K24: 0 | L24: =F24-F25 -> 0 | M24: =G24-G25 -> 0 | N24: =H24-H25 -> 0 | O24: =Tabla1[[#This Row],[CONSUMO SOLUCIÓN OXIDANTE (L)]] -> 0 | P24: =(L24*$X$2)/1000000 -> 0 | Q24: =(M24*$Y$2)/1000000 -> 0 | R24: =Tabla1[[#This Row],[CONSUMO POL ANIONICO (KG)]] -> 0 | S24: =Tabla1[[#This Row],[CONSUMO OXIDANTE SOLUCIÓN(L)]]*Tabla1[[#This Row],[DENSIDAD OXIDANTE]] -> 0 | T24: =(P24*1000)/K24 -> #DIV/0! | U24: =(Q24*1000)/K24 -> #DIV/0! | V24: =(R24*1000)/K24 -> #DIV/0! | W24: =(S24*1000)/K24 -> #DIV/0! | X24: 1240000 | Y24: 1325000 | Z24: 2500 | AA24: 0.042 | AB24: 2446 | AC24: 2498 | AD24: 23800 | AE24: 3010 | AF24: =P24*AB24 -> 0 | AG24: =Q24*AC24 -> 0 | AH24: =R24*AD24 -> 0 | AI24: =S24*AE24 -> 0 | AJ24: =SUM(Tabla1[[#This Row],[COSTO OPERATIVO ACIDO]:[COSTO OPERATIVO OXIDANTE]]) -> 0 | AK24: 2500 | AL24: =AJ24/K24 -> #DIV/0!
A25: =A24 -> 46030 | B25: =DAY(Tabla1[[#This Row],[FECHA]]) -> 8 | C25: 3(TARDE) | D25: 3 | E25: FINAL TURNO 2 | F25: 1335 | G25: 1778 | H25: 93.5 | I25: 0 | J25: 92516 | K25: 0 | L25: =F25-F26 -> 0 | M25: =G25-G26 -> 0 | N25: =H25-H26 -> 0 | O25: =Tabla1[[#This Row],[CONSUMO SOLUCIÓN OXIDANTE (L)]] -> 0 | P25: =(L25*$X$2)/1000000 -> 0 | Q25: =(M25*$Y$2)/1000000 -> 0 | R25: =Tabla1[[#This Row],[CONSUMO POL ANIONICO (KG)]] -> 0 | S25: =Tabla1[[#This Row],[CONSUMO OXIDANTE SOLUCIÓN(L)]]*Tabla1[[#This Row],[DENSIDAD OXIDANTE]] -> 0 | T25: =(P25*1000)/K25 -> #DIV/0! | U25: =(Q25*1000)/K25 -> #DIV/0! | V25: =(R25*1000)/K25 -> #DIV/0! | W25: =(S25*1000)/K25 -> #DIV/0! | X25: 1240000 | Y25: 1325000 | Z25: 2500 | AA25: 0.042 | AB25: 2446 | AC25: 2498 | AD25: 23800 | AE25: 3010 | AF25: =P25*AB25 -> 0 | AG25: =Q25*AC25 -> 0 | AH25: =R25*AD25 -> 0 | AI25: =S25*AE25 -> 0 | AJ25: =SUM(Tabla1[[#This Row],[COSTO OPERATIVO ACIDO]:[COSTO OPERATIVO OXIDANTE]]) -> 0 | AK25: 2500 | AL25: =AJ25/K25 -> #DIV/0!
A26: =A25+1 -> 46031 | B26: =DAY(Tabla1[[#This Row],[FECHA]]) -> 9 | C26: 1 (NOCHE) | D26: 1 | E26: FINAL TURNO 3 | F26: 1335 | G26: 1778 | H26: 93.5 | I26: 0 | J26: 92516 | K26: 0 | L26: =F26-F27 -> 0 | M26: =G26-G27 -> 0 | N26: =H26-H27 -> 0 | O26: =Tabla1[[#This Row],[CONSUMO SOLUCIÓN OXIDANTE (L)]] -> 0 | P26: =(L26*$X$2)/1000000 -> 0 | Q26: =(M26*$Y$2)/1000000 -> 0 | R26: =Tabla1[[#This Row],[CONSUMO POL ANIONICO (KG)]] -> 0 | S26: =Tabla1[[#This Row],[CONSUMO OXIDANTE SOLUCIÓN(L)]]*Tabla1[[#This Row],[DENSIDAD OXIDANTE]] -> 0 | T26: =(P26*1000)/K26 -> #DIV/0! | U26: =(Q26*1000)/K26 -> #DIV/0! | V26: =(R26*1000)/K26 -> #DIV/0! | W26: =(S26*1000)/K26 -> #DIV/0! | X26: 1240000 | Y26: 1325000 | Z26: 2500 | AA26: 0.042 | AB26: 2446 | AC26: 2498 | AD26: 23800 | AE26: 3010 | AF26: =P26*AB26 -> 0 | AG26: =Q26*AC26 -> 0 | AH26: =R26*AD26 -> 0 | AI26: =S26*AE26 -> 0 | AJ26: =SUM(Tabla1[[#This Row],[COSTO OPERATIVO ACIDO]:[COSTO OPERATIVO OXIDANTE]]) -> 0 | AK26: 2500 | AL26: =AJ26/K26 -> #DIV/0!
A27: =A26 -> 46031 | B27: =DAY(Tabla1[[#This Row],[FECHA]]) -> 9 | C27: 2 (MAÑANA) | D27: 2 | E27: FINAL TURNO 1 | F27: 1335 | G27: 1778 | H27: 93.5 | I27: 0 | J27: 92516 | K27: 0 | L27: =F27-F28 -> 0 | M27: =G27-G28 -> 0 | N27: =H27-H28 -> 0 | O27: =Tabla1[[#This Row],[CONSUMO SOLUCIÓN OXIDANTE (L)]] -> 0 | P27: =(L27*$X$2)/1000000 -> 0 | Q27: =(M27*$Y$2)/1000000 -> 0 | R27: =Tabla1[[#This Row],[CONSUMO POL ANIONICO (KG)]] -> 0 | S27: =Tabla1[[#This Row],[CONSUMO OXIDANTE SOLUCIÓN(L)]]*Tabla1[[#This Row],[DENSIDAD OXIDANTE]] -> 0 | T27: =(P27*1000)/K27 -> #DIV/0! | U27: =(Q27*1000)/K27 -> #DIV/0! | V27: =(R27*1000)/K27 -> #DIV/0! | W27: =(S27*1000)/K27 -> #DIV/0! | X27: 1240000 | Y27: 1325000 | Z27: 2500 | AA27: 0.042 | AB27: 2446 | AC27: 2498 | AD27: 23800 | AE27: 3010 | AF27: =P27*AB27 -> 0 | AG27: =Q27*AC27 -> 0 | AH27: =R27*AD27 -> 0 | AI27: =S27*AE27 -> 0 | AJ27: =SUM(Tabla1[[#This Row],[COSTO OPERATIVO ACIDO]:[COSTO OPERATIVO OXIDANTE]]) -> 0 | AK27: 2500 | AL27: =AJ27/K27 -> #DIV/0!
A28: =A27 -> 46031 | B28: =DAY(Tabla1[[#This Row],[FECHA]]) -> 9 | C28: 3(TARDE) | D28: 3 | E28: FINAL TURNO 2 | F28: 1335 | G28: 1778 | H28: 93.5 | I28: 0 | J28: 92516 | K28: 0 | L28: =F28-F29 -> 0 | M28: =G28-G29 -> 0 | N28: =H28-H29 -> 0 | O28: =Tabla1[[#This Row],[CONSUMO SOLUCIÓN OXIDANTE (L)]] -> 0 | P28: =(L28*$X$2)/1000000 -> 0 | Q28: =(M28*$Y$2)/1000000 -> 0 | R28: =Tabla1[[#This Row],[CONSUMO POL ANIONICO (KG)]] -> 0 | S28: =Tabla1[[#This Row],[CONSUMO OXIDANTE SOLUCIÓN(L)]]*Tabla1[[#This Row],[DENSIDAD OXIDANTE]] -> 0 | T28: =(P28*1000)/K28 -> #DIV/0! | U28: =(Q28*1000)/K28 -> #DIV/0! | V28: =(R28*1000)/K28 -> #DIV/0! | W28: =(S28*1000)/K28 -> #DIV/0! | X28: 1240000 | Y28: 1325000 | Z28: 2500 | AA28: 0.042 | AB28: 2446 | AC28: 2498 | AD28: 23800 | AE28: 3010 | AF28: =P28*AB28 -> 0 | AG28: =Q28*AC28 -> 0 | AH28: =R28*AD28 -> 0 | AI28: =S28*AE28 -> 0 | AJ28: =SUM(Tabla1[[#This Row],[COSTO OPERATIVO ACIDO]:[COSTO OPERATIVO OXIDANTE]]) -> 0 | AK28: 2500 | AL28: =AJ28/K28 -> #DIV/0!
A29: =A28+1 -> 46032 | B29: =DAY(Tabla1[[#This Row],[FECHA]]) -> 10 | C29: 1 (NOCHE) | D29: 1 | E29: FINAL TURNO 3 | F29: 1335 | G29: 1778 | H29: 93.5 | I29: 0 | J29: 92516 | K29: 0 | L29: =F29-F30 -> 0 | M29: =G29-G30 -> 0 | N29: =H29-H30 -> 0 | O29: =Tabla1[[#This Row],[CONSUMO SOLUCIÓN OXIDANTE (L)]] -> 0 | P29: =(L29*$X$2)/1000000 -> 0 | Q29: =(M29*$Y$2)/1000000 -> 0 | R29: =Tabla1[[#This Row],[CONSUMO POL ANIONICO (KG)]] -> 0 | S29: =Tabla1[[#This Row],[CONSUMO OXIDANTE SOLUCIÓN(L)]]*Tabla1[[#This Row],[DENSIDAD OXIDANTE]] -> 0 | T29: =(P29*1000)/K29 -> #DIV/0! | U29: =(Q29*1000)/K29 -> #DIV/0! | V29: =(R29*1000)/K29 -> #DIV/0! | W29: =(S29*1000)/K29 -> #DIV/0! | X29: 1240000 | Y29: 1325000 | Z29: 2500 | AA29: 0.042 | AB29: 2446 | AC29: 2498 | AD29: 23800 | AE29: 3010 | AF29: =P29*AB29 -> 0 | AG29: =Q29*AC29 -> 0 | AH29: =R29*AD29 -> 0 | AI29: =S29*AE29 -> 0 | AJ29: =SUM(Tabla1[[#This Row],[COSTO OPERATIVO ACIDO]:[COSTO OPERATIVO OXIDANTE]]) -> 0 | AK29: 2500 | AL29: =AJ29/K29 -> #DIV/0!
A30: =A29 -> 46032 | B30: =DAY(Tabla1[[#This Row],[FECHA]]) -> 10 | C30: 2 (MAÑANA) | D30: 2 | E30: FINAL TURNO 1 | F30: 1335 | G30: 1778 | H30: 93.5 | I30: 0 | J30: 92516 | K30: 0 | L30: =F30-F31 -> 0 | M30: =G30-G31 -> 0 | N30: =H30-H31 -> 0 | O30: =Tabla1[[#This Row],[CONSUMO SOLUCIÓN OXIDANTE (L)]] -> 0 | P30: =(L30*$X$2)/1000000 -> 0 | Q30: =(M30*$Y$2)/1000000 -> 0 | R30: =Tabla1[[#This Row],[CONSUMO POL ANIONICO (KG)]] -> 0 | S30: =Tabla1[[#This Row],[CONSUMO OXIDANTE SOLUCIÓN(L)]]*Tabla1[[#This Row],[DENSIDAD OXIDANTE]] -> 0 | T30: =(P30*1000)/K30 -> #DIV/0! | U30: =(Q30*1000)/K30 -> #DIV/0! | V30: =(R30*1000)/K30 -> #DIV/0! | W30: =(S30*1000)/K30 -> #DIV/0! | X30: 1240000 | Y30: 1325000 | Z30: 2500 | AA30: 0.042 | AB30: 2446 | AC30: 2498 | AD30: 23800 | AE30: 3010 | AF30: =P30*AB30 -> 0 | AG30: =Q30*AC30 -> 0 | AH30: =R30*AD30 -> 0 | AI30: =S30*AE30 -> 0 | AJ30: =SUM(Tabla1[[#This Row],[COSTO OPERATIVO ACIDO]:[COSTO OPERATIVO OXIDANTE]]) -> 0 | AK30: 2500 | AL30: =AJ30/K30 -> #DIV/0!
A31: =A30 -> 46032 | B31: =DAY(Tabla1[[#This Row],[FECHA]]) -> 10 | C31: 3(TARDE) | D31: 3 | E31: FINAL TURNO 2 | F31: 1335 | G31: 1778 | H31: 93.5 | I31: 0 | J31: 92516 | K31: 0 | L31: =F31-F32 -> 0 | M31: =G31-G32 -> 0 | N31: =H31-H32 -> 0 | O31: =Tabla1[[#This Row],[CONSUMO SOLUCIÓN OXIDANTE (L)]] -> 0 | P31: =(L31*$X$2)/1000000 -> 0 | Q31: =(M31*$Y$2)/1000000 -> 0 | R31: =Tabla1[[#This Row],[CONSUMO POL ANIONICO (KG)]] -> 0 | S31: =Tabla1[[#This Row],[CONSUMO OXIDANTE SOLUCIÓN(L)]]*Tabla1[[#This Row],[DENSIDAD OXIDANTE]] -> 0 | T31: =(P31*1000)/K31 -> #DIV/0! | U31: =(Q31*1000)/K31 -> #DIV/0! | V31: =(R31*1000)/K31 -> #DIV/0! | W31: =(S31*1000)/K31 -> #DIV/0! | X31: 1240000 | Y31: 1325000 | Z31: 2500 | AA31: 0.042 | AB31: 2446 | AC31: 2498 | AD31: 23800 | AE31: 3010 | AF31: =P31*AB31 -> 0 | AG31: =Q31*AC31 -> 0 | AH31: =R31*AD31 -> 0 | AI31: =S31*AE31 -> 0 | AJ31: =SUM(Tabla1[[#This Row],[COSTO OPERATIVO ACIDO]:[COSTO OPERATIVO OXIDANTE]]) -> 0 | AK31: 2500 | AL31: =AJ31/K31 -> #DIV/0!
A32: =A31+1 -> 46033 | B32: =DAY(Tabla1[[#This Row],[FECHA]]) -> 11 | C32: 1 (NOCHE) | D32: 1 | E32: FINAL TURNO 3 | F32: 1335 | G32: 1778 | H32: 93.5 | I32: 0 | J32: 92516 | K32: 0 | L32: =F32-F33 -> 0 | M32: =G32-G33 -> 0 | N32: =H32-H33 -> 0 | O32: =Tabla1[[#This Row],[CONSUMO SOLUCIÓN OXIDANTE (L)]] -> 0 | P32: =(L32*$X$2)/1000000 -> 0 | Q32: =(M32*$Y$2)/1000000 -> 0 | R32: =Tabla1[[#This Row],[CONSUMO POL ANIONICO (KG)]] -> 0 | S32: =Tabla1[[#This Row],[CONSUMO OXIDANTE SOLUCIÓN(L)]]*Tabla1[[#This Row],[DENSIDAD OXIDANTE]] -> 0 | T32: =(P32*1000)/K32 -> #DIV/0! | U32: =(Q32*1000)/K32 -> #DIV/0! | V32: =(R32*1000)/K32 -> #DIV/0! | W32: =(S32*1000)/K32 -> #DIV/0! | X32: 1240000 | Y32: 1325000 | Z32: 2500 | AA32: 0.042 | AB32: 2446 | AC32: 2498 | AD32: 23800 | AE32: 3010 | AF32: =P32*AB32 -> 0 | AG32: =Q32*AC32 -> 0 | AH32: =R32*AD32 -> 0 | AI32: =S32*AE32 -> 0 | AJ32: =SUM(Tabla1[[#This Row],[COSTO OPERATIVO ACIDO]:[COSTO OPERATIVO OXIDANTE]]) -> 0 | AK32: 2500 | AL32: =AJ32/K32 -> #DIV/0!
A33: =A32 -> 46033 | B33: =DAY(Tabla1[[#This Row],[FECHA]]) -> 11 | C33: 2 (MAÑANA) | D33: 2 | E33: FINAL TURNO 1 | F33: 1335 | G33: 1778 | H33: 93.5 | I33: 0 | J33: 92516 | K33: 0 | L33: =F33-F34 -> 0 | M33: =G33-G34 -> 0 | N33: =H33-H34 -> 0 | O33: =Tabla1[[#This Row],[CONSUMO SOLUCIÓN OXIDANTE (L)]] -> 0 | P33: =(L33*$X$2)/1000000 -> 0 | Q33: =(M33*$Y$2)/1000000 -> 0 | R33: =Tabla1[[#This Row],[CONSUMO POL ANIONICO (KG)]] -> 0 | S33: =Tabla1[[#This Row],[CONSUMO OXIDANTE SOLUCIÓN(L)]]*Tabla1[[#This Row],[DENSIDAD OXIDANTE]] -> 0 | T33: =(P33*1000)/K33 -> #DIV/0! | U33: =(Q33*1000)/K33 -> #DIV/0! | V33: =(R33*1000)/K33 -> #DIV/0! | W33: =(S33*1000)/K33 -> #DIV/0! | X33: 1240000 | Y33: 1325000 | Z33: 2500 | AA33: 0.042 | AB33: 2446 | AC33: 2498 | AD33: 23800 | AE33: 3010 | AF33: =P33*AB33 -> 0 | AG33: =Q33*AC33 -> 0 | AH33: =R33*AD33 -> 0 | AI33: =S33*AE33 -> 0 | AJ33: =SUM(Tabla1[[#This Row],[COSTO OPERATIVO ACIDO]:[COSTO OPERATIVO OXIDANTE]]) -> 0 | AK33: 2500 | AL33: =AJ33/K33 -> #DIV/0!
A34: =A33 -> 46033 | B34: =DAY(Tabla1[[#This Row],[FECHA]]) -> 11 | C34: 3(TARDE) | D34: 3 | E34: FINAL TURNO 2 | F34: 1335 | G34: 1778 | H34: 93.5 | I34: 0 | J34: 92516 | K34: 0 | L34: =F34-F35 -> 0 | M34: =G34-G35 -> 0 | N34: =H34-H35 -> 0 | O34: =Tabla1[[#This Row],[CONSUMO SOLUCIÓN OXIDANTE (L)]] -> 0 | P34: =(L34*$X$2)/1000000 -> 0 | Q34: =(M34*$Y$2)/1000000 -> 0 | R34: =Tabla1[[#This Row],[CONSUMO POL ANIONICO (KG)]] -> 0 | S34: =Tabla1[[#This Row],[CONSUMO OXIDANTE SOLUCIÓN(L)]]*Tabla1[[#This Row],[DENSIDAD OXIDANTE]] -> 0 | T34: =(P34*1000)/K34 -> #DIV/0! | U34: =(Q34*1000)/K34 -> #DIV/0! | V34: =(R34*1000)/K34 -> #DIV/0! | W34: =(S34*1000)/K34 -> #DIV/0! | X34: 1240000 | Y34: 1325000 | Z34: 2500 | AA34: 0.042 | AB34: 2446 | AC34: 2498 | AD34: 23800 | AE34: 3010 | AF34: =P34*AB34 -> 0 | AG34: =Q34*AC34 -> 0 | AH34: =R34*AD34 -> 0 | AI34: =S34*AE34 -> 0 | AJ34: =SUM(Tabla1[[#This Row],[COSTO OPERATIVO ACIDO]:[COSTO OPERATIVO OXIDANTE]]) -> 0 | AK34: 2500 | AL34: =AJ34/K34 -> #DIV/0!
A35: =A34+1 -> 46034 | B35: =DAY(Tabla1[[#This Row],[FECHA]]) -> 12 | C35: 1 (NOCHE) | D35: 1 | E35: FINAL TURNO 3 | F35: 1335 | G35: 1778 | H35: 93.5 | I35: 0 | J35: 92516 | K35: 0 | L35: =F35-F36 -> 0 | M35: =G35-G36 -> 0 | N35: =H35-H36 -> 0 | O35: =Tabla1[[#This Row],[CONSUMO SOLUCIÓN OXIDANTE (L)]] -> 0 | P35: =(L35*$X$2)/1000000 -> 0 | Q35: =(M35*$Y$2)/1000000 -> 0 | R35: =Tabla1[[#This Row],[CONSUMO POL ANIONICO (KG)]] -> 0 | S35: =Tabla1[[#This Row],[CONSUMO OXIDANTE SOLUCIÓN(L)]]*Tabla1[[#This Row],[DENSIDAD OXIDANTE]] -> 0 | T35: =(P35*1000)/K35 -> #DIV/0! | U35: =(Q35*1000)/K35 -> #DIV/0! | V35: =(R35*1000)/K35 -> #DIV/0! | W35: =(S35*1000)/K35 -> #DIV/0! | X35: 1240000 | Y35: 1325000 | Z35: 2500 | AA35: 0.042 | AB35: 2446 | AC35: 2498 | AD35: 23800 | AE35: 3010 | AF35: =P35*AB35 -> 0 | AG35: =Q35*AC35 -> 0 | AH35: =R35*AD35 -> 0 | AI35: =S35*AE35 -> 0 | AJ35: =SUM(Tabla1[[#This Row],[COSTO OPERATIVO ACIDO]:[COSTO OPERATIVO OXIDANTE]]) -> 0 | AK35: 2500 | AL35: =AJ35/K35 -> #DIV/0!
A36: =A35 -> 46034 | B36: =DAY(Tabla1[[#This Row],[FECHA]]) -> 12 | C36: 2 (MAÑANA) | D36: 2 | E36: FINAL TURNO 1 | F36: 1335 | G36: 1778 | H36: 93.5 | I36: 0 | J36: 92516 | K36: 0 | L36: =F36-F37 -> 0 | M36: =G36-G37 -> 0 | N36: =H36-H37 -> 0 | O36: =Tabla1[[#This Row],[CONSUMO SOLUCIÓN OXIDANTE (L)]] -> 0 | P36: =(L36*$X$2)/1000000 -> 0 | Q36: =(M36*$Y$2)/1000000 -> 0 | R36: =Tabla1[[#This Row],[CONSUMO POL ANIONICO (KG)]] -> 0 | S36: =Tabla1[[#This Row],[CONSUMO OXIDANTE SOLUCIÓN(L)]]*Tabla1[[#This Row],[DENSIDAD OXIDANTE]] -> 0 | T36: =(P36*1000)/K36 -> #DIV/0! | U36: =(Q36*1000)/K36 -> #DIV/0! | V36: =(R36*1000)/K36 -> #DIV/0! | W36: =(S36*1000)/K36 -> #DIV/0! | X36: 1240000 | Y36: 1325000 | Z36: 2500 | AA36: 0.042 | AB36: 2446 | AC36: 2498 | AD36: 23800 | AE36: 3010 | AF36: =P36*AB36 -> 0 | AG36: =Q36*AC36 -> 0 | AH36: =R36*AD36 -> 0 | AI36: =S36*AE36 -> 0 | AJ36: =SUM(Tabla1[[#This Row],[COSTO OPERATIVO ACIDO]:[COSTO OPERATIVO OXIDANTE]]) -> 0 | AK36: 2500 | AL36: =AJ36/K36 -> #DIV/0!
A37: =A36 -> 46034 | B37: =DAY(Tabla1[[#This Row],[FECHA]]) -> 12 | C37: 3(TARDE) | D37: 3 | E37: FINAL TURNO 2 | F37: 1335 | G37: 1778 | H37: 93.5 | I37: 0 | J37: 92516 | K37: 0 | L37: =F37-F38 -> 0 | M37: =G37-G38 -> 0 | N37: =H37-H38 -> 0 | O37: 10 | P37: =(L37*$X$2)/1000000 -> 0 | Q37: =(M37*$Y$2)/1000000 -> 0 | R37: =Tabla1[[#This Row],[CONSUMO POL ANIONICO (KG)]] -> 0 | S37: =Tabla1[[#This Row],[CONSUMO OXIDANTE SOLUCIÓN(L)]]*Tabla1[[#This Row],[DENSIDAD OXIDANTE]] -> 0.42 | T37: =(P37*1000)/K37 -> #DIV/0! | U37: =(Q37*1000)/K37 -> #DIV/0! | V37: =(R37*1000)/K37 -> #DIV/0! | W37: =(S37*1000)/K37 -> #DIV/0! | X37: 1240000 | Y37: 1325000 | Z37: 2500 | AA37: 0.042 | AB37: 2446 | AC37: 2498 | AD37: 23800 | AE37: 3010 | AF37: =P37*AB37 -> 0 | AG37: =Q37*AC37 -> 0 | AH37: =R37*AD37 -> 0 | AI37: =S37*AE37 -> 1264.2 | AJ37: =SUM(Tabla1[[#This Row],[COSTO OPERATIVO ACIDO]:[COSTO OPERATIVO OXIDANTE]]) -> 1264.2 | AK37: 2500 | AL37: =AJ37/K37 -> #DIV/0!
A38: =A37+1 -> 46035 | B38: =DAY(Tabla1[[#This Row],[FECHA]]) -> 13 | C38: 1 (NOCHE) | D38: 1 | E38: FINAL TURNO 3 | F38: 1335 | G38: 1778 | H38: 93.5 | I38: 0 | J38: 92516 | K38: 0 | L38: =F38-F39 -> 0 | M38: =G38-G39 -> 0 | N38: =H38-H39 -> 0 | O38: =Tabla1[[#This Row],[CONSUMO SOLUCIÓN OXIDANTE (L)]] -> 0 | P38: =(L38*$X$2)/1000000 -> 0 | Q38: =(M38*$Y$2)/1000000 -> 0 | R38: =Tabla1[[#This Row],[CONSUMO POL ANIONICO (KG)]] -> 0 | S38: =Tabla1[[#This Row],[CONSUMO OXIDANTE SOLUCIÓN(L)]]*Tabla1[[#This Row],[DENSIDAD OXIDANTE]] -> 0 | T38: =(P38*1000)/K38 -> #DIV/0! | U38: =(Q38*1000)/K38 -> #DIV/0! | V38: =(R38*1000)/K38 -> #DIV/0! | W38: =(S38*1000)/K38 -> #DIV/0! | X38: 1240000 | Y38: 1325000 | Z38: 2500 | AA38: 0.042 | AB38: 2446 | AC38: 2498 | AD38: 23800 | AE38: 3010 | AF38: =P38*AB38 -> 0 | AG38: =Q38*AC38 -> 0 | AH38: =R38*AD38 -> 0 | AI38: =S38*AE38 -> 0 | AJ38: =SUM(Tabla1[[#This Row],[COSTO OPERATIVO ACIDO]:[COSTO OPERATIVO OXIDANTE]]) -> 0 | AK38: 2500 | AL38: =AJ38/K38 -> #DIV/0!
A39: =A38 -> 46035 | B39: =DAY(Tabla1[[#This Row],[FECHA]]) -> 13 | C39: 2 (MAÑANA) | D39: 2 | E39: FINAL TURNO 1 | F39: 1335 | G39: 1778 | H39: 93.5 | I39: 0 | J39: 92516 | K39: 0 | L39: =F39-F40 -> 0 | M39: =G39-G40 -> 0 | N39: =H39-H40 -> 0 | O39: =Tabla1[[#This Row],[CONSUMO SOLUCIÓN OXIDANTE (L)]] -> 0 | P39: =(L39*$X$2)/1000000 -> 0 | Q39: =(M39*$Y$2)/1000000 -> 0 | R39: =Tabla1[[#This Row],[CONSUMO POL ANIONICO (KG)]] -> 0 | S39: =Tabla1[[#This Row],[CONSUMO OXIDANTE SOLUCIÓN(L)]]*Tabla1[[#This Row],[DENSIDAD OXIDANTE]] -> 0 | T39: =(P39*1000)/K39 -> #DIV/0! | U39: =(Q39*1000)/K39 -> #DIV/0! | V39: =(R39*1000)/K39 -> #DIV/0! | W39: =(S39*1000)/K39 -> #DIV/0! | X39: 1240000 | Y39: 1325000 | Z39: 2500 | AA39: 0.042 | AB39: 2446 | AC39: 2498 | AD39: 23800 | AE39: 3010 | AF39: =P39*AB39 -> 0 | AG39: =Q39*AC39 -> 0 | AH39: =R39*AD39 -> 0 | AI39: =S39*AE39 -> 0 | AJ39: =SUM(Tabla1[[#This Row],[COSTO OPERATIVO ACIDO]:[COSTO OPERATIVO OXIDANTE]]) -> 0 | AK39: 2500 | AL39: =AJ39/K39 -> #DIV/0!
A40: =A39 -> 46035 | B40: =DAY(Tabla1[[#This Row],[FECHA]]) -> 13 | C40: 3(TARDE) | D40: 3 | E40: FINAL TURNO 2 | F40: 1335 | G40: 1778 | H40: 93.5 | I40: 0 | J40: 92516 | K40: 0 | L40: =F40-F41 -> 0 | M40: =G40-G41 -> 0 | N40: =H40-H41 -> 0 | O40: =Tabla1[[#This Row],[CONSUMO SOLUCIÓN OXIDANTE (L)]] -> 0 | P40: =(L40*$X$2)/1000000 -> 0 | Q40: =(M40*$Y$2)/1000000 -> 0 | R40: =Tabla1[[#This Row],[CONSUMO POL ANIONICO (KG)]] -> 0 | S40: =Tabla1[[#This Row],[CONSUMO OXIDANTE SOLUCIÓN(L)]]*Tabla1[[#This Row],[DENSIDAD OXIDANTE]] -> 0 | T40: =(P40*1000)/K40 -> #DIV/0! | U40: =(Q40*1000)/K40 -> #DIV/0! | V40: =(R40*1000)/K40 -> #DIV/0! | W40: =(S40*1000)/K40 -> #DIV/0! | X40: 1240000 | Y40: 1325000 | Z40: 2500 | AA40: 0.042 | AB40: 2446 | AC40: 2498 | AD40: 23800 | AE40: 3010 | AF40: =P40*AB40 -> 0 | AG40: =Q40*AC40 -> 0 | AH40: =R40*AD40 -> 0 | AI40: =S40*AE40 -> 0 | AJ40: =SUM(Tabla1[[#This Row],[COSTO OPERATIVO ACIDO]:[COSTO OPERATIVO OXIDANTE]]) -> 0 | AK40: 2500 | AL40: =AJ40/K40 -> #DIV/0!
...

Sheet DB QUIMICA
A1: CONSUMO DE QUIMICO | M1: TABLA GRAFICA 1 Y 2 . CONSUMO QUIMICO DETALLADO | U1: TABLA GRAFICA 2. COSTO CONSUMO QUIMICO VS $M3
A2: PTAP-PTAR FUNZA
B3: CONSUMO QUIMICO PPM
L4: FECHA | M4: COF 235 - PPM COAGULANTE | N4: COF 280 - PPM ACIDO | O4: COF 440 - PPM POL ANIONICO | P4: COF 494 - PPM POL CATIONICO | U4: DIA | V4: LIMITE INDICADOR M3 | W4: INDICADOR $M3. | X4: CAUDAL TOTAL TRATADO PTAP
L5: 46023 | M5: 0 | N5: 0 | O5: 0 | P5: 0 | U5: 1 | V5: 2500 | W5: 0 | X5: 0
L6: 46024 | M6: 0 | N6: 0 | O6: 0 | P6: 0 | U6: 2 | V6: 2500 | W6: 2549.32 | X6: 18
L7: 46025 | M7: 0 | N7: 0 | O7: 0 | P7: 0 | U7: 3 | V7: 2500 | W7: 2609.4027 | X7: 30
L8: 46026 | M8: 0 | N8: 0 | O8: 0 | P8: 0 | U8: 4 | V8: 2500 | W8: 0 | X8: 0
L9: 46027 | M9: 0 | N9: 0 | O9: 0 | P9: 0 | U9: 5 | V9: 2500 | W9: 0 | X9: 0
L10: 46028 | M10: 0 | N10: 0 | O10: 0 | P10: 0 | U10: 6 | V10: 2500 | W10: 0 | X10: 0
L11: 46029 | M11: 0 | N11: 0 | O11: 0 | P11: 0 | U11: 7 | V11: 2500 | W11: 0 | X11: 0
L12: 46030 | M12: 0 | N12: 0 | O12: 0 | P12: 0 | U12: 8 | V12: 2500 | W12: 0 | X12: 0
L13: 46031 | M13: 0 | N13: 0 | O13: 0 | P13: 0 | U13: 9 | V13: 2500 | W13: 0 | X13: 0
L14: 46032 | M14: 0 | N14: 0 | O14: 0 | P14: 0 | U14: 10 | V14: 2500 | W14: 0 | X14: 0
L15: 46033 | M15: 0 | N15: 0 | O15: 0 | P15: 0 | U15: 11 | V15: 2500 | W15: 0 | X15: 0
L16: 46034 | M16: 0 | N16: 0 | O16: 0 | P16: 0 | U16: 12 | V16: 2500 | W16: 0 | X16: 0
... L27: 46045 | M27: 0 | N27: 0 | O27: 0 | P27: 0 | U27: 23 | V27: 2500 | W27: 0 | X27: 0
B28: COSTO TTO - CAUDAL TRATADO PTAP FUNZA Vs $M3 | L28: 46046 | M28: 0 | N28: 0 | O28: 0 | P28: 0 | U28: 24 | V28: 2500 | W28: 0 | X28: 0
L29: 46047 | M29: 0 | N29: 0 | O29: 0 | P29: 0 | U29: 25 | V29: 2500 | W29: 0 | X29: 0
A30: s | L30: 46048 | M30: 0 | N30: 0 | O30: 0 | P30: 0 | U30: 26 | V30: 2500 | W30: 0 | X30: 0
L31: 46049 | M31: 0 | N31: 0 | O31: 0 | P31: 0 | U31: 27 | V31: 2500 | W31: 0 | X31: 0
L32: 46050 | M32: 0 | N32: 0 | O32: 0 | P32: 0 | U32: 28 | V32: 2500 | W32: 0 | X32: 0
L33: 46051 | M33: 0 | N33: 0 | O33: 0 | P33: 0 | U33: 29 | V33: 2500 | W33: 0 | X33: 0
L34: 46052 | M34: 0 | N34: 0 | O34: 0 | P34: 0 | U34: 30 | V34: 2500 | W34: 0 | X34: 0
L35: 46053 | M35: 0 | N35: 0 | O35: 0 | P35: 0 | U35: 31 | V35: 2500 | W35: 0 | X35: 0
L36: Total general | M36: 0 | N36: 0 | O36: 0 | P36: 0 | U36: Total general | V36: 2500 | W36: 36921.15 | X36: 333
B51: CONSOLIDADO COSTO TTO - CAUDAL TRATADO PTAP Vs $M3
B53: ACUMULADO CAUDAL TRATADO
B54: TOTAL CAUDAL TRATADO | C54: $m3 | D54: 872310
B55: =GETPIVOTDATA("CAUDAL TOTAL TRATADO PTAP ",$U$4) -> 333 | C55: =D54/B55 -> 2619.5495 | D55: =C55*B55 -> 872310
D56: =C55*B55 -> 872310

Sheet CONSUMO QUÍMICA-CAUDALES GEM  
A1: CONSOLIDADO CONSUMO DIARIO QUÍMICA (Litros)
B2: DIAS
A3: PRODUCTOS QUÍMICOS | B3: 1 | C3: 2 | D3: 3 | E3: 4 | F3: 5 | G3: 6 | H3: 7 | I3: 8 | J3: 9 | K3: 10 | L3: 11 | M3: 12 | N3: 13 | O3: 14 | P3: 15 | Q3: 16 | R3: 17 | S3: 18 | T3: 19 | U3: 20 | V3: 21 | W3: 22 | X3: 23 | Y3: 24 | Z3: 25 | AA3: 26 | AB3: 27 | AC3: 28 | AD3: 29 | AE3: 30 | AF3: 31 | AG3: Total general
A4: COF 280 ACIDO (L) | B4: 0 | C4: 6 | D4: 10 | E4: 0 | F4: 0 | G4: 0 | H4: 0 | I4: 0 | J4: 0 | K4: 0 | L4: 0 | M4: 0 | N4: 0 | O4: 0 | P4: 0 | Q4: 28 | R4: 0 | S4: 0 | T4: 0 | U4: 0 | V4: 29 | W4: 46 | X4: 0 | Y4: 0 | Z4: 0 | AA4: 0 | AB4: 0 | AC4: 0 | AD4: 0 | AE4: 0 | AF4: 1232 | AG4: 1351
A5: COF 235 COAGULANTE (L) | B5: 0 | C5: 8 | D5: 14 | E5: 0 | F5: 0 | G5: 0 | H5: 0 | I5: 0 | J5: 0 | K5: 0 | L5: 0 | M5: 0 | N5: 0 | O5: 0 | P5: 0 | Q5: 29 | R5: 0 | S5: 0 | T5: 0 | U5: 0 | V5: 36 | W5: 58 | X5: 0 | Y5: 0 | Z5: 0 | AA5: 0 | AB5: 0 | AC5: 0 | AD5: 0 | AE5: 0 | AF5: 1655 | AG5: 1800
A6: COF 440 POL ANIONICO (KG) | B6: 0 | C6: 0.019 | D6: 0.02 | E6: 0 | F6: 0 | G6: 0 | H6: 0 | I6: 0 | J6: 0 | K6: 0 | L6: 0 | M6: 0 | N6: 0 | O6: 0 | P6: 0 | Q6: 0.2 | R6: 0 | S6: 0 | T6: 0 | U6: 0 | V6: 0.2 | W6: 0.33 | X6: 0 | Y6: 0 | Z6: 0 | AA6: 0 | AB6: 0 | AC6: 0 | AD6: 0 | AE6: 0 | AF6: 92.77 | AG6: 93.539
A7: OXIDANTE SOLUCIÓN(L) | B7: 0 | C7: 6 | D7: 9 | E7: 0 | F7: 0 | G7: 0 | H7: 0 | I7: 0 | J7: 0 | K7: 0 | L7: 0 | M7: 10 | N7: 0 | O7: 0 | P7: 0 | Q7: 17 | R7: 0 | S7: 0 | T7: 0 | U7: 0 | V7: 24 | W7: 38 | X7: 0 | Y7: 0 | Z7: 0 | AA7: 0 | AB7: 0 | AC7: 0 | AD7: 0 | AE7: 0 | AF7: 0 | AG7: 104
A10: CONSOLIDADO CONSUMO DIARIO QUÍMICA (Kg)
B11: DIAS
A12: PRODUCTOS QUÍMICOS | B12: 1 | C12: 2 | D12: 3 | E12: 4 | F12: 5 | G12: 6 | H12: 7 | I12: 8 | J12: 9 | K12: 10 | L12: 11 | M12: 12 | N12: 13 | O12: 14 | P12: 15 | Q12: 16 | R12: 17 | S12: 18 | T12: 19 | U12: 20 | V12: 21 | W12: 22 | X12: 23 | Y12: 24 | Z12: 25 | AA12: 26 | AB12: 27 | AC12: 28 | AD12: 29 | AE12: 30 | AF12: 31 | AG12: Total general
A13: COF 280 - KG ACIDO | B13: 0 | C13: 7.44 | D13: 12.4 | E13: 0 | F13: 0 | G13: 0 | H13: 0 | I13: 0 | J13: 0 | K13: 0 | L13: 0 | M13: 0 | N13: 0 | O13: 0 | P13: 0 | Q13: 34.72 | R13: 0 | S13: 0 | T13: 0 | U13: 0 | V13: 35.96 | W13: 57.04 | X13: 0 | Y13: 0 | Z13: 0 | AA13: 0 | AB13: 0 | AC13: 0 | AD13: 0 | AE13: 0 | AF13: 1527.68 | AG13: 1675.24
A14: COF 235 - KG COAGULANTE | B14: 0 | C14: 10.6 | D14: 18.55 | E14: 0 | F14: 0 | G14: 0 | H14: 0 | I14: 0 | J14: 0 | K14: 0 | L14: 0 | M14: 0 | N14: 0 | O14: 0 | P14: 0 | Q14: 38.425 | R14: 0 | S14: 0 | T14: 0 | U14: 0 | V14: 47.7 | W14: 76.85 | X14: 0 | Y14: 0 | Z14: 0 | AA14: 0 | AB14: 0 | AC14: 0 | AD14: 0 | AE14: 0 | AF14: 2192.875 | AG14: 2385
A15: COF 440 - KG POL ANIONICO | B15: 0 | C15: 0.019 | D15: 0.02 | E15: 0 | F15: 0 | G15: 0 | H15: 0 | I15: 0 | J15: 0 | K15: 0 | L15: 0 | M15: 0 | N15: 0 | O15: 0 | P15: 0 | Q15: 0.2 | R15: 0 | S15: 0 | T15: 0 | U15: 0 | V15: 0.2 | W15: 0.33 | X15: 0 | Y15: 0 | Z15: 0 | AA15: 0 | AB15: 0 | AC15: 0 | AD15: 0 | AE15: 0 | AF15: 92.77 | AG15: 93.539
A16: KG OXIDANTE | B16: 0 | C16: 0.252 | D16: 0.378 | E16: 0 | F16: 0 | G16: 0 | H16: 0 | I16: 0 | J16: 0 | K16: 0 | L16: 0 | M16: 0.42 | N16: 0 | O16: 0 | P16: 0 | Q16: 0.714 | R16: 0 | S16: 0 | T16: 0 | U16: 0 | V16: 1.008 | W16: 1.596 | X16: 0 | Y16: 0 | Z16: 0 | AA16: 0 | AB16: 0 | AC16: 0 | AD16: 0 | AE16: 0 | AF16: 0 | AG16: 4.368
A19: CONSOLIDADO DOSIFICACIÓN QUÍMICA PPM (mg/L)
B20: DIAS
A21: PRODUCTOS QUÍMICOS | B21: 1 | C21: 2 | D21: 3 | E21: 4 | F21: 5 | G21: 6 | H21: 7 | I21: 8 | J21: 9 | K21: 10 | L21: 11 | M21: 12 | N21: 13 | O21: 14 | P21: 15 | Q21: 16 | R21: 17 | S21: 18 | T21: 19 | U21: 20 | V21: 21 | W21: 22 | X21: 23 | Y21: 24 | Z21: 25 | AA21: 26 | AB21: 27 | AC21: 28 | AD21: 29 | AE21: 30 | AF21: 31
A22: COF 280 - PPM ACIDO | B22: #NAME? | C22: #NAME? | D22: #NAME? | E22: #NAME? | F22: #NAME? | G22: #NAME? | H22: #NAME? | I22: #NAME? | J22: #NAME? | K22: #NAME? | L22: #NAME? | M22: #NAME? | N22: #NAME? | O22: #NAME? | P22: #NAME? | Q22: #NAME? | R22: #NAME? | S22: #NAME? | T22: #NAME? | U22: #NAME? | V22: #NAME? | W22: #NAME? | X22: #NAME? | Y22: #NAME? | Z22: #NAME? | AA22: #NAME? | AB22: #NAME? | AC22: #NAME? | AD22: #NAME? | AE22: #NAME? | AF22: #NAME?
A23: COF 235 - PPM COAGULANTE | B23: #NAME? | C23: #NAME? | D23: #NAME? | E23: #NAME? | F23: #NAME? | G23: #NAME? | H23: #NAME? | I23: #NAME? | J23: #NAME? | K23: #NAME? | L23: #NAME? | M23: #NAME? | N23: #NAME? | O23: #NAME? | P23: #NAME? | Q23: #NAME? | R23: #NAME? | S23: #NAME? | T23: #NAME? | U23: #NAME? | V23: #NAME? | W23: #NAME? | X23: #NAME? | Y23: #NAME? | Z23: #NAME? | AA23: #NAME? | AB23: #NAME? | AC23: #NAME? | AD23: #NAME? | AE23: #NAME? | AF23: #NAME?
A24: COF 255 - PPM DECOLORANTE | B24: #NAME? | C24: #NAME? | D24: #NAME? | E24: #NAME? | F24: #NAME? | G24: #NAME? | H24: #NAME? | I24: #NAME? | J24: #NAME? | K24: #NAME? | L24: #NAME? | M24: #NAME? | N24: #NAME? | O24: #NAME? | P24: #NAME? | Q24: #NAME? | R24: #NAME? | S24: #NAME? | T24: #NAME? | U24: #NAME? | V24: #NAME? | W24: #NAME? | X24: #NAME? | Y24: #NAME? | Z24: #NAME? | AA24: #NAME? | AB24: #NAME? | AC24: #NAME? | AD24: #NAME? | AE24: #NAME? | AF24: #NAME?
A25: COF 440 - PPM POL ANIONICO | B25: #NAME? | C25: #NAME? | D25: #NAME? | E25: #NAME? | F25: #NAME? | G25: #NAME? | H25: #NAME? | I25: #NAME? | J25: #NAME? | K25: #NAME? | L25: #NAME? | M25: #NAME? | N25: #NAME? | O25: #NAME? | P25: #NAME? | Q25: #NAME? | R25: #NAME? | S25: #NAME? | T25: #NAME? | U25: #NAME? | V25: #NAME? | W25: #NAME? | X25: #NAME? | Y25: #NAME? | Z25: #NAME? | AA25: #NAME? | AB25: #NAME? | AC25: #NAME? | AD25: #NAME? | AE25: #NAME? | AF25: #NAME?
A26: COF 494 - PPM POL CATIONICO | B26: #NAME? | C26: #NAME? | D26: #NAME? | E26: #NAME? | F26: #NAME? | G26: #NAME? | H26: #NAME? | I26: #NAME? | J26: #NAME? | K26: #NAME? | L26: #NAME? | M26: #NAME? | N26: #NAME? | O26: #NAME? | P26: #NAME? | Q26: #NAME? | R26: #NAME? | S26: #NAME? | T26: #NAME? | U26: #NAME? | V26: #NAME? | W26: #NAME? | X26: #NAME? | Y26: #NAME? | Z26: #NAME? | AA26: #NAME? | AB26: #NAME? | AC26: #NAME? | AD26: #NAME? | AE26: #NAME? | AF26: #NAME?
A29: DIAS
A30: 1 | B30: 2 | C30: 3 | D30: 4 | E30: 5 | F30: 6 | G30: 7 | H30: 8 | I30: 9 | J30: 10 | K30: 11 | L30: 12 | M30: 13 | N30: 14 | O30: 15 | P30: 16 | Q30: 17 | R30: 18 | S30: 19 | T30: 20 | U30: 21 | V30: 22 | W30: 23 | X30: 24 | Y30: 25 | Z30: 26 | AA30: 27 | AB30: 28 | AC30: 29 | AD30: 30 | AE30: 31 | AF30: Total general

Sheet INVENTARIO INSUMOS QUÍMICOS GEM
B2: PRODUCTOS QUÍMICOS | C2: Densidad (g/ml) | D2: INVENTARIO INICIO DE MES | F2: CONSOLIDADO CONSUMO QUÍMICA MENSUAL | H2: TOTAL SUMINISTRO QUÍMICOS (PROVEEDOR) | J2: INVENTARIO ACTUALIZADO | L2: TOTAL EXTRA PROVEDOR | N2: INVENTARIO ACTUALIZADO REAL
D3: Litros | E3: Kg | F3: Litros | G3: Kg | H3: Litros | I3: Kg | J3: Litros | K3: Kg | L3: Litros | M3: Kg | N3: Litros | O3: Kg
B4: Ácido COF280 | C4: 1.24 | D4: 1430 | E4: =D4*C4 -> 1773.2 | F4: =GETPIVOTDATA("COF 280 ACIDO (L)",'CONSUMO QUÍMICA-CAUDALES GEM '!$A$2) -> 1351 | G4: =GETPIVOTDATA("COF 280 - KG ACIDO",'CONSUMO QUÍMICA-CAUDALES GEM '!$A$11) -> 1675.24 | H4: =(+C14+E14+G14+I14+K14+M14+O14+Q14+S14) -> 3000 | I4: =H4*C4 -> 3720 | J4: =(D4+H4)-F4 -> 3079 | K4: =J4*$C4 -> 3817.96 | L4: 0 | M4: =L4*$C4 -> 0 | N4: 0 | O4: =N4*$C4 -> 0
B5: Coagulante COF235 | C5: 1.325 | D5: 770 | E5: =D5*C5 -> 1020.25 | F5: =GETPIVOTDATA("COF 235 COAGULANTE (L)",'CONSUMO QUÍMICA-CAUDALES GEM '!$A$2) -> 1800 | G5: =GETPIVOTDATA("COF 235 - KG COAGULANTE",'CONSUMO QUÍMICA-CAUDALES GEM '!$A$11) -> 2385 | H5: =(+C15+E15+G15+I15+K15+M15+O15+Q15+S15) -> 4000 | I5: =H5*C5 -> 5300 | J5: =(D5+H5)-F5 -> 2970 | K5: =J5*$C5 -> 3935.25 | L5: 0 | M5: =L5*$C5 -> 0 | N5: =J5-L5 -> 2970 | O5: =N5*$C5 -> 3935.25
B6: Polimero COF440 (Aniónico) | C6: 0.0025 | D6: 7700 | E6: =D6*C6 -> 19.25 | F6: =(GETPIVOTDATA("COF 440 POL ANIONICO (KG)",'CONSUMO QUÍMICA-CAUDALES GEM '!$A$2)/C6) -> 37415.6 | G6: =GETPIVOTDATA("COF 440 - KG POL ANIONICO ",'CONSUMO QUÍMICA-CAUDALES GEM '!$A$11) -> 93.539 | H6: =(+C16+E16+G16+I16+K16+M16+O16+Q16+S16) -> 20000 | I6: =H6*C6 -> 50 | J6: =(D6+H6)-F6 -> -9715.6 | K6: =J6*$C6 -> -24.289 | L6: 0 | M6: =L6*$C6 -> 0 | N6: =J6-L6 -> -9715.6 | O6: =N6*$C6 -> -24.289
B7: OXIDANTE | C7: 0.0025 | D7: 0 | E7: =D7*C7 -> 0 | F7: =(GETPIVOTDATA("COF 440 POL ANIONICO (KG)",'CONSUMO QUÍMICA-CAUDALES GEM '!$A$2)/C7) -> 37415.6 | G7: =GETPIVOTDATA("COF 440 - KG POL ANIONICO ",'CONSUMO QUÍMICA-CAUDALES GEM '!$A$11) -> 93.539 | H7: =(+C17+E17+G17+I17+K17+M17+O17+Q17+S17) -> 0 | I7: =H7*C7 -> 0 | J7: =(D7+H7)-F7 -> -37415.6 | K7: =J7*$C7 -> -93.539 | L7: 0 | M7: =L7*$C7 -> 0 | N7: =J7-L7 -> -37415.6 | O7: =N7*$C7 -> -93.539
B9: PRODUCTOS QUÍMICOS | C9: ENTREGAS DE INSUMOS QUÍMICOS PROVEEEDOR COFAI (FECHA)
C10: 45694
C11: REM No | D11: O T | E11: REM No | F11: O T | G11: REM No | H11: O T | I11: REM No | J11: O T | K11: REM No | L11: O T | M11: REM No | N11: O T | O11: REM No | P11: O T | Q11: REM No | R11: O T | S11: REM No | T11: O T
C13: Litros | D13: Kg | E13: Litros | F13: Kg | G13: Litros | H13: Kg | I13: Litros | J13: Kg | K13: Litros | L13: Kg | M13: Litros | N13: Kg | O13: Litros | P13: Kg | Q13: Litros | R13: Kg | S13: Litros | T13: Kg
B14: Ácido COF280 | C14: 3000 | D14: =C14*$C$4 -> 3720 | F14: =E14*$C$4 -> 0 | H14: =G14*$C$4 -> 0
B15: Coagulante COF235 | C15: 4000 | D15: =+C15*$C$5 -> 5300 | F15: =+E15*$C$5 -> 0 | H15: =+G15*$C$5 -> 0
B16: Polimero COF440 (Aniónico) | C16: 20000 | D16: =+C16*$C$6 -> 50 | F16: =+E16*$C$6 -> 0 | H16: =+G16*$C$6 -> 0
B17: OXIDANTE | D17: =+C17*$C$7 -> 0 | F17: =+E17*$C$7 -> 0 | H17: =+G17*$C$7 -> 0
B19: PRODUCTOS QUÍMICOS | C19: REGISTRO DENSIDADES DE INSUMOS QUÍMICOS PROVEEEDOR COFAI (FECHA)
C21: Litros | D21: Densidad (g/ml) | E21: Kg | F21: Litros | G21: Densidad (g/ml) | H21: Kg | I21: Litros | J21: Densidad (g/ml) | K21: Kg | L21: Litros | M21: Densidad (g/ml) | N21: Kg | O21: Litros | P21: Densidad (g/ml) | Q21: Kg | R21: Litros | S21: Densidad (g/ml) | T21: Kg | U21: Litros | V21: Densidad (g/ml) | W21: Kg
B22: Ácido COF280 | E22: =C22*D22 -> 0 | H22: =F22*G22 -> 0 | K22: =I22*J22 -> 0 | N22: =L22*M22 -> 0 | Q22: =O22*P22 -> 0 | T22: =R22*S22 -> 0 | W22: =U22*V22 -> 0
B23: Coagulante COF235 | E23: =C23*D23 -> 0 | H23: =F23*G23 -> 0 | K23: =I23*J23 -> 0 | N23: =L23*M23 -> 0 | Q23: =O23*P23 -> 0 | T23: =R23*S23 -> 0 | W23: =U23*V23 -> 0
B24: Polimero COF440 (Aniónico) | E24: =C24*D24 -> 0 | H24: =F24*G24 -> 0 | K24: =I24*J24 -> 0 | N24: =L24*M24 -> 0 | Q24: =O24*P24 -> 0 | T24: =R24*S24 -> 0 | W24: =U24*V24 -> 0
B25: OXIDANTE | E25: =C25*D25 -> 0 | H25: =F25*G25 -> 0 | K25: =I25*J25 -> 0 | N25: =L25*M25 -> 0 | Q25: =O25*P25 -> 0 | T25: =R25*S25 -> 0 | W25: =U25*V25 -> 0
